<?xml version="1.0" encoding="utf-8"?>
<!-- =================================================================================== -->
<!-- |    This document was autogenerated by xacro from /home/developer/subt_ws/install/share/husky_description/urdf/husky.urdf.xacro | -->
<!-- |    EDITING THIS FILE BY HAND IS NOT RECOMMENDED                                 | -->
<!-- =================================================================================== -->
<!--
Software License Agreement (BSD)

\file      husky.urdf.xacro
\authors   Paul Bovbel <pbovbel@clearpathrobotics.com>, Devon Ash <dash@clearpathrobotics.com>
\copyright Copyright (c) 2015, Clearpath Robotics, Inc., All rights reserved.

Redistribution and use in source and binary forms, with or without modification, are permitted provided that
the following conditions are met:
 * Redistributions of source code must retain the above copyright notice, this list of conditions and the
   following disclaimer.
 * Redistributions in binary form must reproduce the above copyright notice, this list of conditions and the
   following disclaimer in the documentation and/or other materials provided with the distribution.
 * Neither the name of Clearpath Robotics nor the names of its contributors may be used to endorse or promote
   products derived from this software without specific prior written permission.

THIS SOFTWARE IS PROVIDED BY THE COPYRIGHT HOLDERS AND CONTRIBUTORS "AS IS" AND ANY EXPRESS OR IMPLIED WAR-
RANTIES, INCLUDING, BUT NOT LIMITED TO, THE IMPLIED WARRANTIES OF MERCHANTABILITY AND FITNESS FOR A PARTICULAR
PURPOSE ARE DISCLAIMED. IN NO EVENT SHALL THE COPYRIGHT HOLDER OR CONTRIBUTORS BE LIABLE FOR ANY DIRECT, IN-
DIRECT, INCIDENTAL, SPECIAL, EXEMPLARY, OR CONSEQUENTIAL DAMAGES (INCLUDING, BUT NOT LIMITED TO, PROCUREMENT
OF SUBSTITUTE GOODS OR SERVICES; LOSS OF USE, DATA, OR PROFITS; OR BUSINESS INTERRUPTION) HOWEVER CAUSED AND
ON ANY THEORY OF LIABILITY, WHETHER IN CONTRACT, STRICT LIABILITY, OR TORT (INCLUDING NEGLIGENCE OR OTHERWISE)
ARISING IN ANY WAY OUT OF THE USE OF THIS SOFTWARE, EVEN IF ADVISED OF THE POSSIBILITY OF SUCH DAMAGE.
-->
<robot name="husky" xmlns:xacro="http://ros.org/wiki/xacro">
  <!-- Base link is the center of the robot's bottom plate -->
  <link name="base_link">
    <visual>
      <origin rpy="0 0 0" xyz="0 0 0"/>
      <geometry>
        <mesh filename="package://husky_description/meshes/base_link.dae"/>
      </geometry>
    </visual>
    <collision>
      <origin rpy="0 0 0" xyz="0 0 0.061875"/>
      <geometry>
        <box size="0.9874 0.5709 0.12375"/>
      </geometry>
    </collision>
    <collision>
      <origin rpy="0 0 0" xyz="0 0 0.185625"/>
      <geometry>
        <box size="0.78992 0.5709 0.12375"/>
      </geometry>
    </collision>
  </link>
  <!-- Base footprint is on the ground under the robot -->
  <link name="base_footprint"/>
  <joint name="base_footprint_joint" type="fixed">
    <origin rpy="0 0 0" xyz="0 0 -0.13228"/>
    <parent link="base_link"/>
    <child link="base_footprint"/>
  </joint>
  <!-- Interial link stores the robot's inertial information -->
  <link name="inertial_link">
    <inertial>
      <mass value="46.034"/>
      <origin xyz="-0.00065 -0.085 0.062"/>
      <inertia ixx="0.6022" ixy="-0.02364" ixz="-0.1197" iyy="1.7386" iyz="-0.001544" izz="2.0296"/>
    </inertial>
  </link>
  <joint name="inertial_joint" type="fixed">
    <origin rpy="0 0 0" xyz="0 0 0"/>
    <parent link="base_link"/>
    <child link="inertial_link"/>
  </joint>
  <!-- IMU Link is the standard mounting position for the UM6 IMU.-->
  <!-- Can be modified with environment variables in /etc/ros/setup.bash -->
  <link name="imu_link"/>
  <joint name="imu_joint" type="fixed">
    <origin rpy="0 -1.5708 3.1416" xyz="0.19 0 0.149"/>
    <parent link="base_link"/>
    <child link="imu_link"/>
  </joint>
  <gazebo reference="imu_link">
  </gazebo>
  <link name="front_left_wheel_link">
    <inertial>
      <mass value="2.637"/>
      <origin xyz="0 0 0"/>
      <inertia ixx="0.02467" ixy="0" ixz="0" iyy="0.04411" iyz="0" izz="0.02467"/>
    </inertial>
    <visual>
      <origin rpy="0 0 0" xyz="0 0 0"/>
      <geometry>
        <mesh filename="package://husky_description/meshes/wheel.dae"/>
      </geometry>
    </visual>
    <collision>
      <origin rpy="1.570795 0 0" xyz="0 0 0"/>
      <geometry>
        <cylinder length="0.1143" radius="0.1651"/>
      </geometry>
    </collision>
  </link>
  <gazebo reference="front_left_wheel_link">
    <mu1 value="1.0"/>
    <mu2 value="1.0"/>
    <kp value="10000000.0"/>
    <kd value="1.0"/>
    <fdir1 value="1 0 0"/>
  </gazebo>
  <joint name="front_left_wheel" type="continuous">
    <parent link="base_link"/>
    <child link="front_left_wheel_link"/>
    <origin rpy="0 0 0" xyz="0.256 0.2854 0.03282"/>
    <axis rpy="0 0 0" xyz="0 1 0"/>
  </joint>
  <transmission name="front_left_wheel_trans" type="SimpleTransmission">
    <type>transmission_interface/SimpleTransmission</type>
    <actuator name="front_left_wheel_motor">
      <mechanicalReduction>1</mechanicalReduction>
    </actuator>
    <joint name="front_left_wheel">
      <hardwareInterface>hardware_interface/VelocityJointInterface</hardwareInterface>
    </joint>
  </transmission>
  <link name="front_right_wheel_link">
    <inertial>
      <mass value="2.637"/>
      <origin xyz="0 0 0"/>
      <inertia ixx="0.02467" ixy="0" ixz="0" iyy="0.04411" iyz="0" izz="0.02467"/>
    </inertial>
    <visual>
      <origin rpy="0 0 0" xyz="0 0 0"/>
      <geometry>
        <mesh filename="package://husky_description/meshes/wheel.dae"/>
      </geometry>
    </visual>
    <collision>
      <origin rpy="1.570795 0 0" xyz="0 0 0"/>
      <geometry>
        <cylinder length="0.1143" radius="0.1651"/>
      </geometry>
    </collision>
  </link>
  <gazebo reference="front_right_wheel_link">
    <mu1 value="1.0"/>
    <mu2 value="1.0"/>
    <kp value="10000000.0"/>
    <kd value="1.0"/>
    <fdir1 value="1 0 0"/>
  </gazebo>
  <joint name="front_right_wheel" type="continuous">
    <parent link="base_link"/>
    <child link="front_right_wheel_link"/>
    <origin rpy="0 0 0" xyz="0.256 -0.2854 0.03282"/>
    <axis rpy="0 0 0" xyz="0 1 0"/>
  </joint>
  <transmission name="front_right_wheel_trans" type="SimpleTransmission">
    <type>transmission_interface/SimpleTransmission</type>
    <actuator name="front_right_wheel_motor">
      <mechanicalReduction>1</mechanicalReduction>
    </actuator>
    <joint name="front_right_wheel">
      <hardwareInterface>hardware_interface/VelocityJointInterface</hardwareInterface>
    </joint>
  </transmission>
  <link name="rear_left_wheel_link">
    <inertial>
      <mass value="2.637"/>
      <origin xyz="0 0 0"/>
      <inertia ixx="0.02467" ixy="0" ixz="0" iyy="0.04411" iyz="0" izz="0.02467"/>
    </inertial>
    <visual>
      <origin rpy="0 0 0" xyz="0 0 0"/>
      <geometry>
        <mesh filename="package://husky_description/meshes/wheel.dae"/>
      </geometry>
    </visual>
    <collision>
      <origin rpy="1.570795 0 0" xyz="0 0 0"/>
      <geometry>
        <cylinder length="0.1143" radius="0.1651"/>
      </geometry>
    </collision>
  </link>
  <gazebo reference="rear_left_wheel_link">
    <mu1 value="1.0"/>
    <mu2 value="1.0"/>
    <kp value="10000000.0"/>
    <kd value="1.0"/>
    <fdir1 value="1 0 0"/>
  </gazebo>
  <joint name="rear_left_wheel" type="continuous">
    <parent link="base_link"/>
    <child link="rear_left_wheel_link"/>
    <origin rpy="0 0 0" xyz="-0.256 0.2854 0.03282"/>
    <axis rpy="0 0 0" xyz="0 1 0"/>
  </joint>
  <transmission name="rear_left_wheel_trans" type="SimpleTransmission">
    <type>transmission_interface/SimpleTransmission</type>
    <actuator name="rear_left_wheel_motor">
      <mechanicalReduction>1</mechanicalReduction>
    </actuator>
    <joint name="rear_left_wheel">
      <hardwareInterface>hardware_interface/VelocityJointInterface</hardwareInterface>
    </joint>
  </transmission>
  <link name="rear_right_wheel_link">
    <inertial>
      <mass value="2.637"/>
      <origin xyz="0 0 0"/>
      <inertia ixx="0.02467" ixy="0" ixz="0" iyy="0.04411" iyz="0" izz="0.02467"/>
    </inertial>
    <visual>
      <origin rpy="0 0 0" xyz="0 0 0"/>
      <geometry>
        <mesh filename="package://husky_description/meshes/wheel.dae"/>
      </geometry>
    </visual>
    <collision>
      <origin rpy="1.570795 0 0" xyz="0 0 0"/>
      <geometry>
        <cylinder length="0.1143" radius="0.1651"/>
      </geometry>
    </collision>
  </link>
  <gazebo reference="rear_right_wheel_link">
    <mu1 value="1.0"/>
    <mu2 value="1.0"/>
    <kp value="10000000.0"/>
    <kd value="1.0"/>
    <fdir1 value="1 0 0"/>
  </gazebo>
  <joint name="rear_right_wheel" type="continuous">
    <parent link="base_link"/>
    <child link="rear_right_wheel_link"/>
    <origin rpy="0 0 0" xyz="-0.256 -0.2854 0.03282"/>
    <axis rpy="0 0 0" xyz="0 1 0"/>
  </joint>
  <transmission name="rear_right_wheel_trans" type="SimpleTransmission">
    <type>transmission_interface/SimpleTransmission</type>
    <actuator name="rear_right_wheel_motor">
      <mechanicalReduction>1</mechanicalReduction>
    </actuator>
    <joint name="rear_right_wheel">
      <hardwareInterface>hardware_interface/VelocityJointInterface</hardwareInterface>
    </joint>
  </transmission>
  <!-- Spawn Husky chassis -->
  <link name="top_chassis_link">
    <visual>
      <origin rpy="0 0 0" xyz="0 0 0"/>
      <geometry>
        <mesh filename="package://husky_description/meshes/top_chassis.dae"/>
      </geometry>
    </visual>
  </link>
  <!-- Attach chassis to the robot -->
  <joint name="top_chassis_joint" type="fixed">
    <parent link="base_link"/>
    <child link="top_chassis_link"/>
  </joint>
  <!-- Spawn user rails -->
  <link name="user_rail_link">
    <visual>
      <geometry>
        <mesh filename="package://husky_description/meshes/user_rail.dae"/>
      </geometry>
    </visual>
  </link>
  <!-- Attach user rails to base link -->
  <joint name="user_rail" type="fixed">
    <origin rpy="0 0 0" xyz="0.272 0 0.245"/>
    <parent link="base_link"/>
    <child link="user_rail_link"/>
  </joint>
  <!-- Spawn front bumper link -->
  <link name="front_bumper_link">
    <visual>
      <geometry>
        <mesh filename="package://husky_description/meshes/bumper.dae"/>
      </geometry>
    </visual>
  </link>
  <!-- Attach front bumper -->
  <joint name="front_bumper" type="fixed">
    <origin rpy="0 0 0" xyz="0.48 0 0.091"/>
    <parent link="base_link"/>
    <child link="front_bumper_link"/>
  </joint>
  <!-- Spawn rear bumper link -->
  <link name="rear_bumper_link">
    <visual>
      <geometry>
        <mesh filename="package://husky_description/meshes/bumper.dae"/>
      </geometry>
    </visual>
  </link>
  <!-- Attach rear bumper -->
  <joint name="rear_bumper" type="fixed">
    <origin rpy="0 0 3.14159" xyz="-0.48 0 0.091"/>
    <parent link="base_link"/>
    <child link="rear_bumper_link"/>
  </joint>
  <link name="top_plate_link">
    <visual>
      <origin rpy="0 0 0" xyz="0 0 0"/>
      <geometry>
        <mesh filename="package://husky_description/meshes/top_plate.dae"/>
      </geometry>
    </visual>
    <collision>
      <origin rpy="0 0 0" xyz="0 0 0"/>
      <geometry>
        <mesh filename="package://husky_description/meshes/top_plate.dae"/>
      </geometry>
    </collision>
    <collision>
      <!-- Extra collision tag for widgets on top plate -->
      <geometry>
        <box rpy="0 0 0" size="0.32 0.41 0.09"/>
      </geometry>
    </collision>
  </link>
  <!-- Attach top plate -->
  <joint name="top_plate_joint" type="fixed">
    <parent link="base_link"/>
    <child link="top_plate_link"/>
    <origin rpy="0 0 0" xyz="0.0812 0 0.245"/>
  </joint>
  <gazebo>
    <plugin filename="libgazebo_ros_control.so" name="gazebo_ros_control">
      <robotNamespace>husky_custom</robotNamespace>
    </plugin>
  </gazebo>
  <gazebo>
    <plugin filename="libhector_gazebo_ros_imu.so" name="imu_controller">
      <robotNamespace>husky_custom</robotNamespace>
      <updateRate>50.0</updateRate>
      <bodyName>base_link</bodyName>
      <topicName>imu/data</topicName>
      <accelDrift>0.005 0.005 0.005</accelDrift>
      <accelGaussianNoise>0.005 0.005 0.005</accelGaussianNoise>
      <rateDrift>0.005 0.005 0.005 </rateDrift>
      <rateGaussianNoise>0.005 0.005 0.005 </rateGaussianNoise>
      <headingDrift>0.005</headingDrift>
      <headingGaussianNoise>0.005</headingGaussianNoise>
    </plugin>
  </gazebo>
  <gazebo>
    <plugin filename="libhector_gazebo_ros_gps.so" name="gps_controller">
      <robotNamespace>husky_custom</robotNamespace>
      <updateRate>40</updateRate>
      <bodyName>base_link</bodyName>
      <frameId>base_link</frameId>
      <topicName>navsat/fix</topicName>
      <velocityTopicName>navsat/vel</velocityTopicName>
      <referenceLatitude>49.9</referenceLatitude>
      <referenceLongitude>8.9</referenceLongitude>
      <referenceHeading>0</referenceHeading>
      <referenceAltitude>0</referenceAltitude>
      <drift>0.0001 0.0001 0.0001</drift>
    </plugin>
  </gazebo>
  <!-- Arch -->
  <link name="arch">
    <visual>
      <geometry>
        <mesh filename="package://husky_custom_description/meshes/jpl04_arch_nosensor.stl"/>
      </geometry>
      <material name="black">
        <color rgba="0.15 0.15 0.15 1"/>
      </material>
    </visual>
  </link>
  <joint name="top_plate_link_to_arch" type="fixed">
    <parent link="top_plate_link"/>
    <child link="arch"/>
    <origin rpy="0 0 0" xyz="-0.08 0 0.006"/>
  </joint>
  <joint name="velodyne_base_mount_joint" type="fixed">
    <origin rpy="0                  0                  0" xyz="0                  0                  0.4273"/>
    <parent link="arch"/>
    <child link="velodyne_base_link"/>
  </joint>
  <link name="velodyne_base_link">
    <inertial>
      <mass value="0.83"/>
      <origin xyz="0 0 0.03585"/>
      <inertia ixx="0.000908059425" ixy="0" ixz="0" iyy="0.000908059425" iyz="0" izz="0.0011049624"/>
    </inertial>
    <visual>
      <geometry>
        <mesh filename="package://velodyne_description/meshes/VLP16_base_1.dae"/>
      </geometry>
    </visual>
    <visual>
      <geometry>
        <mesh filename="package://velodyne_description/meshes/VLP16_base_2.dae"/>
      </geometry>
    </visual>
    <collision>
      <origin rpy="0 0 0" xyz="0 0 0.03585"/>
      <geometry>
        <cylinder length="0.0717" radius="0.0516"/>
      </geometry>
    </collision>
  </link>
  <joint name="velodyne_base_scan_joint" type="fixed">
    <origin rpy="0 0 0" xyz="0 0 0.0377"/>
    <parent link="velodyne_base_link"/>
    <child link="velodyne"/>
  </joint>
  <link name="velodyne">
    <inertial>
      <mass value="0.01"/>
      <origin xyz="0 0 0"/>
      <inertia ixx="1e-7" ixy="0" ixz="0" iyy="1e-7" iyz="0" izz="1e-7"/>
    </inertial>
    <visual>
      <origin xyz="0 0 -0.0377"/>
      <geometry>
        <mesh filename="package://velodyne_description/meshes/VLP16_scan.dae"/>
      </geometry>
    </visual>
  </link>
  <!-- Gazebo requires the velodyne_gazebo_plugins package -->
  <gazebo reference="velodyne">
    <sensor name="velodyne-VLP16" type="gpu_ray">
      <pose>0 0 0 0 0 0</pose>
      <visualize>false</visualize>
      <update_rate>10</update_rate>
      <ray>
        <scan>
          <horizontal>
            <samples>440</samples>
            <resolution>1</resolution>
            <min_angle>-3.14159265359</min_angle>
            <max_angle>3.14159265359</max_angle>
          </horizontal>
          <vertical>
            <samples>16</samples>
            <resolution>1</resolution>
            <min_angle>-0.261799387799</min_angle>
            <max_angle> 0.261799387799</max_angle>
          </vertical>
        </scan>
        <range>
          <min>0.3</min>
          <max>131.0</max>
          <resolution>0.001</resolution>
        </range>
        <noise>
          <type>gaussian</type>
          <mean>0.0</mean>
          <stddev>0.0</stddev>
        </noise>
      </ray>
      <plugin filename="libgazebo_ros_velodyne_gpu_laser.so" name="gazebo_ros_laser_controller">
        <topicName>velodyne_points</topicName>
        <frameName>velodyne</frameName>
        <min_range>0.9</min_range>
        <max_range>130.0</max_range>
        <gaussianNoise>0.008</gaussianNoise>
      </plugin>
    </sensor>
  </gazebo>
  <!-- Camera link -->
  <link name="camera/camera_link">
    <visual>
      <origin rpy="0 0 0" xyz="0 0 0"/>
      <geometry>
        <mesh filename="package://realsense_description/gazebo_realsense/models/realsense_camera/meshes/realsense.dae" scale="0.01 0.01 0.01"/>
      </geometry>
    </visual>
    <collision>
      <geometry>
        <box size="0.0078 0.130 0.0192"/>
      </geometry>
    </collision>
    <inertial>
      <!-- <mass value="0.0615752"/> -->
      <mass value="0.01"/>
      <origin rpy="0 0 0" xyz="0 0 0"/>
      <inertia ixx="9.108e-05" ixy="0" ixz="0" iyy="2.51e-06" iyz="0" izz="8.931e-05"/>
    </inertial>
  </link>
  <!-- Connect camera to parent frame-->
  <joint name="camera/realsense_joint" type="fixed">
    <parent link="base_link"/>
    <child link="camera/camera_link"/>
    <origin rpy="0                  0                  0" xyz="0.488                  0                  0.272"/>
  </joint>
  <!-- Virtual links representing the cameras positons and orientations-->
  <link name="camera/camera_color_frame"/>
  <link name="camera/camera_depth_frame"/>
  <link name="camera/camera_ir_frame"/>
  <link name="camera/camera_ir2_frame"/>
  <link name="camera/camera_color_optical_frame"/>
  <link name="camera/camera_depth_optical_frame"/>
  <link name="camera/camera_ir_optical_frame"/>
  <link name="camera/camera_ir2_optical_frame"/>
  <!-- Joints positioning the virtual links with respect to the camera main link-->
  <joint name="camera/color_joint" type="fixed">
    <parent link="camera/camera_link"/>
    <child link="camera/camera_color_frame"/>
    <origin rpy="0 0 0" xyz="0 0.0325 0.000"/>
  </joint>
  <joint name="camera/color_optical_joint" type="fixed">
    <parent link="camera/camera_color_frame"/>
    <child link="camera/camera_color_optical_frame"/>
    <origin rpy="-1.57079632679 0 -1.57079632679" xyz="0 0 0"/>
  </joint>
  <joint name="camera/depth_joint" type="fixed">
    <parent link="camera/camera_link"/>
    <child link="camera/camera_depth_frame"/>
    <!--origin xyz="0 -0.03 0.004" rpy="0 0 0"/-->
    <origin rpy="0 0 0" xyz="0 0.0325 0.000"/>
    <!-- aligned with rgb -->
  </joint>
  <joint name="camera/depth_optical_joint" type="fixed">
    <parent link="camera/camera_depth_frame"/>
    <child link="camera/camera_depth_optical_frame"/>
    <origin rpy="-1.57079632679 0 -1.57079632679" xyz="0 0 0"/>
  </joint>
  <joint name="camera/ired1_joint" type="fixed">
    <parent link="camera/camera_link"/>
    <child link="camera/camera_ir_frame"/>
    <!--origin xyz="0 -0.06 0.004" rpy="0 0 0"/-->
    <origin rpy="0 0 0" xyz="0 0.0325 0.000"/>
    <!-- aligned with rgb -->
  </joint>
  <joint name="camera/ired1_optical_joint" type="fixed">
    <parent link="camera/camera_ir_frame"/>
    <child link="camera/camera_ir_optical_frame"/>
    <origin rpy="-1.57079632679 0 -1.57079632679" xyz="0 0 0"/>
  </joint>
  <joint name="camera/ired2_joint" type="fixed">
    <parent link="camera/camera_link"/>
    <child link="camera/camera_ir2_frame"/>
    <!--origin xyz="0 0.01 0.004" rpy="0 0 0"/-->
    <origin rpy="0 0 0" xyz="0 0.0325 0.000"/>
    <!-- ligned with rgb -->
  </joint>
  <joint name="camera/ired2_optical_joint" type="fixed">
    <parent link="camera/camera_ir2_frame"/>
    <child link="camera/camera_ir2_optical_frame"/>
    <origin rpy="-1.57079632679 0 -1.57079632679" xyz="0 0 0"/>
  </joint>
  <!-- **********************************************************-->
  <!-- GAZEBO DEFINITIONS ***************************************-->
  <!-- Load plugin to the model ("robot" in urdf format)-->
  <gazebo>
    <plugin filename="librealsense_gazebo_plugin.so" name="realsense_plugin">
      <robotNamespace>husky_custom</robotNamespace>
      <cameraName>camera</cameraName>
    </plugin>
  </gazebo>
  <!-- Load parameters to model's main link-->
  <gazebo reference="camera/camera_link">
    <self_collide>0</self_collide>
    <enable_wind>0</enable_wind>
    <kinematic>0</kinematic>
    <gravity>1</gravity>
    <!--<mu>1</mu>-->
    <mu2>1</mu2>
    <fdir1>0 0 0</fdir1>
    <!--<slip1>0</slip1>
        <slip2>0</slip2>-->
    <kp>1e+13</kp>
    <kd>1</kd>
    <!--<max_vel>0.01</max_vel>
        <min_depth>0</min_depth>-->
    <sensor name="camera/color" type="camera">
      <pose frame="">0 -0.046 0.004 0 0 0</pose>
      <camera name="camera/rs200_camera">
        <horizontal_fov>1.047</horizontal_fov>
        <image>
          <width>424</width>
          <height>240</height>
          <format>RGB_INT8</format>
        </image>
        <clip>
          <near>0.1</near>
          <far>100</far>
        </clip>
        <distortion>
          <k1>0.0</k1>
          <k2>0.0</k2>
          <k3>0.0</k3>
          <p1>0.0</p1>
          <p2>0.0</p2>
          <center>0.5 0.5</center>
        </distortion>
        <noise>
          <type>gaussian</type>
          <mean>0.0</mean>
          <stddev>0.007</stddev>
        </noise>
      </camera>
      <always_on>1</always_on>
      <update_rate>10</update_rate>
      <visualize>0</visualize>
    </sensor>
    <sensor name="camera/ired1" type="camera">
      <pose frame="">0 -0.06 0.004 0 0 0</pose>
      <camera name="camera/rs200_camera">
        <horizontal_fov>1.047</horizontal_fov>
        <image>
          <width>424</width>
          <height>240</height>
          <format>L_INT8</format>
        </image>
        <clip>
          <near>0.1</near>
          <far>100</far>
        </clip>
        <distortion>
          <k1>0.0</k1>
          <k2>0.0</k2>
          <k3>0.0</k3>
          <p1>0.0</p1>
          <p2>0.0</p2>
          <center>0.5 0.5</center>
        </distortion>
        <noise>
          <type>gaussian</type>
          <mean>0.0</mean>
          <stddev>0.05</stddev>
        </noise>
      </camera>
      <always_on>1</always_on>
      <update_rate>10</update_rate>
      <visualize>0</visualize>
    </sensor>
    <sensor name="camera/ired2" type="camera">
      <pose frame="">0 0.01 0.004 0 0 0</pose>
      <camera name="camera/rs200_camera">
        <horizontal_fov>1.047</horizontal_fov>
        <image>
          <width>424</width>
          <height>240</height>
          <format>L_INT8</format>
        </image>
        <clip>
          <near>0.1</near>
          <far>100</far>
        </clip>
        <distortion>
          <k1>0.0</k1>
          <k2>0.0</k2>
          <k3>0.0</k3>
          <p1>0.0</p1>
          <p2>0.0</p2>
          <center>0.5 0.5</center>
        </distortion>
        <noise>
          <type>gaussian</type>
          <mean>0.0</mean>
          <stddev>0.05</stddev>
        </noise>
      </camera>
      <always_on>1</always_on>
      <update_rate>10</update_rate>
      <visualize>0</visualize>
    </sensor>
    <sensor name="camera/depth" type="depth">
      <pose frame="">0 -0.03 0.004 0 0 0</pose>
      <camera name="camera/rs200_camera">
        <horizontal_fov>1.047</horizontal_fov>
        <image>
          <width>424</width>
          <height>240</height>
        </image>
        <clip>
          <near>0.1</near>
          <far>100</far>
        </clip>
        <distortion>
          <k1>0.0</k1>
          <k2>0.0</k2>
          <k3>0.0</k3>
          <p1>0.0</p1>
          <p2>0.0</p2>
          <center>0.5 0.5</center>
        </distortion>
        <noise>
          <type>gaussian</type>
          <mean>0.0</mean>
          <stddev>0.100</stddev>
        </noise>
      </camera>
      <always_on>1</always_on>
      <update_rate>10</update_rate>
      <visualize>0</visualize>
    </sensor>
  </gazebo>
  <!-- Ground truth pose -->
  <gazebo>
    <plugin filename="libgazebo_ros_p3d.so" name="p3d_base_controller">
      <robotNamespace>husky_custom</robotNamespace>
      <alwaysOn>true</alwaysOn>
      <updateRate>50.0</updateRate>
      <bodyName>base_link</bodyName>
      <topicName>ground_truth/odom</topicName>
      <gaussianNoise>0.01</gaussianNoise>
      <frameName>map</frameName>
      <xyzOffsets>0 0 0</xyzOffsets>
      <rpyOffsets>0 0 0</rpyOffsets>
    </plugin>
  </gazebo>
  <link name="husky_custom/flashlight_flashlight_link">
    <visual>
      <origin rpy="0 0 -1.57" xyz="0 0.0 0"/>
      <geometry>
        :
          
        <mesh filename="package://subt_description/meshes/spotlight.dae" scale="0.005 0.005 0.005"/>
      </geometry>
    </visual>
    <inertial>
      <origin rpy="0 0 0" xyz="0 0 0"/>
      <mass value="0.000001"/>
      <inertia ixx="0.001" ixy="0.0" ixz="0.0" iyy="0.001" iyz="0.0" izz="0.001"/>
    </inertial>
  </link>
  <joint name="flashlight_flashlight" type="fixed">
    <parent link="arch"/>
    <child link="husky_custom/flashlight_flashlight_link"/>
    <origin rpy="0            0            3.14" xyz="0.43            0.08            0.02"/>
  </joint>
  <gazebo>
    <model name="flashlight_flashlight">
      <pose>0.43            0.08            0.02 0            0            3.14</pose>
      <link name="light_source">
        <pose>0 0 0 0.0 1.57079632679 0</pose>
        <inertial>
          <mass>0.0025</mass>
          <inertia>
            <ixx>1.0e-05</ixx>
            <ixy>0</ixy>
            <ixz>0</ixz>
            <iyy>1.0e-05</iyy>
            <iyz>0</iyz>
            <izz>1.0e-05</izz>
          </inertia>
        </inertial>
        <light name="lamp" type="spot">
          <range>15</range>
          <pose>0 0 0 0 0 0</pose>
          <attenuation>
            <linear>0</linear>
            <constant>0.05</constant>
            <quadratic>0.0</quadratic>
          </attenuation>
          <diffuse>1.0 1.0 1.0 1</diffuse>
          <specular>1.0 1.0 1.0 1</specular>
          <spot>
            <inner_angle>2.0</inner_angle>
            <outer_angle>2.8</outer_angle>
            <falloff>1</falloff>
          </spot>
          <direction>0 0 -1</direction>
        </light>
        <visual name="lamp">
          <geometry>
            <cylinder>
              <radius>0.019</radius>
              <length>0.005</length>
            </cylinder>
          </geometry>
          <transparency>0.0</transparency>
          <material>
            <ambient>1 1 1 1</ambient>
            <diffuse>1 1 1 1</diffuse>
            <specular>1 1 1 1</specular>
            <emissive>1.0 1.0 1.0 1</emissive>
          </material>
          <plugin filename="libLightVisualPlugin.so" name="light_source_visualize">
            <light>
              <id>lamp</id>
              <visualize>false</visualize>
            </light>
          </plugin>
        </visual>
      </link>
    </model>
  </gazebo>
  <gazebo>
    <joint name="flashlight_flashlight_joint" type="fixed">
      <parent>arch</parent>
      <child>flashlight_flashlight::light_source</child>
    </joint>
  </gazebo>
  <link name="husky_custom/overhead_light_led_link">
    <visual name="marker">
      <origin rpy="0 0 0" xyz="0 0 0"/>
      <geometry>
        <sphere radius="0.0001"/>
      </geometry>
    </visual>
    <inertial>
      <origin rpy="0 0 0" xyz="0 0 0"/>
      <mass value="0.000001"/>
      <inertia ixx="0.001" ixy="0.0" ixz="0.0" iyy="0.001" iyz="0.0" izz="0.001"/>
    </inertial>
  </link>
  <joint name="overhead_light_led" type="fixed">
    <parent link="arch"/>
    <child link="husky_custom/overhead_light_led_link"/>
    <origin rpy="0            0            0" xyz="0            0            2.0"/>
  </joint>
  <gazebo>
    <model name="overhead_light_led">
      <pose>0            0            2.0 0            0            0</pose>
      <link name="led_body">
        <inertial>
          <mass>0.00001</mass>
          <inertia>
            <ixx>1.0e-05</ixx>
            <ixy>0</ixy>
            <ixz>0</ixz>
            <iyy>1.0e-05</iyy>
            <iyz>0</iyz>
            <izz>1.0e-05</izz>
          </inertia>
        </inertial>
        <visual name="marker">
          <pose>0 0 0.008 0 0 0</pose>
          <geometry>
            <sphere>
              <radius>0.015</radius>
            </sphere>
          </geometry>
          <transparency>1</transparency>
          <material>
            <ambient>1 1 1 1</ambient>
            <diffuse>1 1 1 1</diffuse>
            <specular>1 1 1 1</specular>
            <emissive>1.0 1.0 1.0 1</emissive>
          </material>
          <plugin filename="libLightVisualPlugin.so" name="light_source_visualize">
            <light>
              <id>marker</id>
              <visualize>false</visualize>
            </light>
          </plugin>
        </visual>
        <light name="marker" type="point">
          <pose>0 0 0 0 3.14159265359 0</pose>
          <range>20</range>
          <attenuation>
            <constant>0.05</constant>
            <linear>0.02</linear>
            <quadratic>0.02</quadratic>
          </attenuation>
          <diffuse>1.0 1.0 1.0 1</diffuse>
          <specular>1.0 1.0 1.0 1</specular>
        </light>
      </link>
      <!-- <plugin name='light_control' filename='libRosFlashLightPlugin.so'>
          <service_name>enable</service_name>
          <light>
            <id>led_body/marker</id>
            <xacro:insert_block name="plugin_params"/>
            <enable>false</enable>
          </light>
        </plugin> -->
    </model>
  </gazebo>
  <gazebo>
    <joint name="overhead_light_led_joint" type="fixed">
      <parent>arch</parent>
      <child>overhead_light_led::led_body</child>
    </joint>
  </gazebo>
  <link name="evo_64px_link">
    <visual>
      <origin rpy="1.57079632679 0 -1.57079632679" xyz="0 0 0"/>
      <geometry>
        :
          
        <cylinder length="0.02" radius="0.005"/>
      </geometry>
    </visual>
    <inertial>
      <origin rpy="0 0 0" xyz="0 0 0"/>
      <mass value="0.000001"/>
      <inertia ixx="0.001" ixy="0.0" ixz="0.0" iyy="0.001" iyz="0.0" izz="0.001"/>
    </inertial>
  </link>
  <joint name="evo_64px_joint" type="fixed">
    <parent link="base_link"/>
    <child link="evo_64px_link"/>
    <origin rpy="0                  3.92699081699                  0" xyz="0.435                  0                  0.235"/>
  </joint>
  <!-- Virtual links representing the sensor positons and orientations-->
  <link name="evo_64px_frame"/>
  <!-- Joints positioning the virtual links with respect to the sensor main link-->
  <joint name="evo_64px_virtual_joint" type="fixed">
    <parent link="evo_64px_link"/>
    <child link="evo_64px_frame"/>
    <origin rpy="0 -3.1416018366025518 0" xyz="0 0 0"/>
  </joint>
  <gazebo reference="evo_64px_frame">
    <sensor name="evo_64px" type="ray">
      <pose>0 0 0 0 0 0</pose>
      <visualize>0</visualize>
      <update_rate>10</update_rate>
      <ray>
        <scan>
          <horizontal>
            <samples>8</samples>
            <resolution>1</resolution>
            <min_angle>-0.025</min_angle>
            <max_angle>0.025</max_angle>
          </horizontal>
          <vertical>
            <samples>8</samples>
            <resolution>1</resolution>
            <min_angle>-0.025</min_angle>
            <max_angle>0.025</max_angle>
          </vertical>
        </scan>
        <range>
          <min>0.1</min>
          <max>5.0</max>
          <resolution>0.01</resolution>
        </range>
      </ray>
      <plugin filename="libgazebo_ros_range.so" name="evo_64px_range">
        <alwaysOn>true</alwaysOn>
        <topicName>cliff_detector</topicName>
        <frameName>evo_64px_link</frameName>
        <gaussianNoise>0.005</gaussianNoise>
        <fov>0.05</fov>
        <radiation>INFRARED</radiation>
      </plugin>
    </sensor>
  </gazebo>
</robot>


