<?xml version='1.0' encoding='utf-8'?>
<robot name="husky" xmlns:xacro="http://ros.org/wiki/xacro">
  <xacro:arg name="name" default="X1"/>
  <xacro:property name="robot_namespace" value="$(arg name)"/>
  <link name='${robot_namespace}/base_link'>
    <inertial>
      <origin xyz='0.00723 -0.083016 0.06774' rpy='0 -0 0'/>
      <mass value='47.134'/>
      <inertia ixx='0.678021' ixy='-0.0544735' ixz='-0.208918' iyy='1.9292' iyz='-0.0240036' izz='2.16181'/>
    </inertial>
    <collision name='base_link_collision'>
      <origin xyz='0 0 0.061875' rpy='0 -0 0'/>
      <geometry>
        <box size='0.9874 0.5709 0.12375'/>
      </geometry>
    </collision>
    <collision name='base_link_collision_1'>
      <origin xyz='0 0 0.185625' rpy='0 -0 0'/>
      <geometry>
        <box size='0.78992 0.5709 0.12375'/>
      </geometry>
    </collision>
    <collision name='base_link_fixed_joint_lump__top_plate_link_collision_2'>
      <origin xyz='0.0812 0 0.245' rpy='0 -0 0'/>
      <geometry>
        <mesh filename='package://husky_migration_sensor_config_1/meshes/top_plate.dae' scale='1 1 1'/>
      </geometry>
    </collision>
    <collision name='base_link_fixed_joint_lump__top_plate_link_collision_3'>
      <origin xyz='0.0812 0 0.245' rpy='0 -0 0'/>
      <geometry>
        <box size='0.32 0.41 0.09'/>
      </geometry>
    </collision>
    <collision name='base_link_fixed_joint_lump__base_laser_mount_collision_4'>
      <origin xyz='0.3018 0 0.30985' rpy='0 -0 0'/>
      <geometry>
        <box size='0.1 0.108 0.117'/>
      </geometry>
    </collision>
    <collision name='base_link_fixed_joint_lump__base_laser_collision_5'>
      <origin xyz='0.337 0 0.35795' rpy='3.14159 -0 0'/>
      <geometry>
        <box size='0.105 0.1 0.1'/>
      </geometry>
    </collision>
    <visual name='base_link_visual'>
      <origin xyz='0 0 0' rpy='0 -0 0'/>
      <geometry>
        <mesh filename='package://husky_migration_sensor_config_1/meshes/base_link.dae' scale='1 1 1'/>
      </geometry>
    </visual>
    <visual name='base_link_fixed_joint_lump__front_bumper_link_visual_1'>
      <origin xyz='0.48 0 0.091' rpy='0 -0 0'/>
      <geometry>
        <mesh filename='package://husky_migration_sensor_config_1/meshes/bumper.dae' scale='1 1 1'/>
      </geometry>
    </visual>
    <visual name='base_link_fixed_joint_lump__rear_bumper_link_visual_2'>
      <origin xyz='-0.48 0 0.091' rpy='0 -0 3.14159'/>
      <geometry>
        <mesh filename='package://husky_migration_sensor_config_1/meshes/bumper.dae' scale='1 1 1'/>
      </geometry>
    </visual>
    <visual name='base_link_fixed_joint_lump__top_chassis_link_visual_3'>
      <origin xyz='0 0 0' rpy='0 -0 0'/>
      <geometry>
        <mesh filename='package://husky_migration_sensor_config_1/meshes/top_chassis.dae' scale='1 1 1'/>
      </geometry>
    </visual>
    <visual name='base_link_fixed_joint_lump__top_plate_link_visual_4'>
      <origin xyz='0.0812 0 0.245' rpy='0 -0 0'/>
      <geometry>
        <mesh filename='package://husky_migration_sensor_config_1/meshes/top_plate.dae' scale='1 1 1'/>
      </geometry>
    </visual>
    <visual name='base_link_fixed_joint_lump__base_laser_mount_visual_5'>
      <origin xyz='0.3018 0 0.25135' rpy='0 0 -1.5708'/>
      <geometry>
        <mesh filename='package://husky_migration_sensor_config_1/meshes/lms1xx_mount.dae' scale='1 1 1'/>
      </geometry>
    </visual>
    <visual name='base_link_fixed_joint_lump__base_laser_visual_6'>
      <origin xyz='0.337 0 0.30795' rpy='3.14159 -0 0'/>
      <geometry>
        <mesh filename='package://husky_migration_sensor_config_1/meshes/sick-lms1xx.dae' scale='1 1 1'/>
      </geometry>
    </visual>
    <visual name='base_link_fixed_joint_lump__user_rail_link_visual_7'>
      <origin xyz='0.272 0 0.245' rpy='0 -0 0'/>
      <geometry>
        <mesh filename='package://husky_migration_sensor_config_1/meshes/user_rail.dae' scale='1 1 1'/>
      </geometry>
    </visual>
  </link>
  <sensor name='front_laser' update_rate='50'>
    <parent link='${robot_namespace}/base_link'/>
    <origin xyz='0.337 0 0.30795' rpy='3.14159 -0 0'/>
  </sensor>
  <sensor name='imu_sensor' update_rate='50'>
    <parent link='${robot_namespace}/base_link'/>
    <origin xyz='0 0 0' rpy='0 -0 0'/>
  </sensor>
  <link name='${robot_namespace}/front_left_wheel_link'>
    <inertial>
      <origin xyz='0 0 0' rpy='0 -0 0'/>
      <mass value='2.637'/>
      <inertia ixx='0.02467' ixy='0' ixz='0' iyy='0.04411' iyz='0' izz='0.02467'/>
    </inertial>
    <collision name='front_left_wheel_link_collision'>
      <origin xyz='0 0 0' rpy='1.5708 -0 0'/>
      <geometry>
        <cylinder radius='0.1651' length='0.1143'/>
      </geometry>
    </collision>
    <visual name='front_left_wheel_link_visual'>
      <origin xyz='0 0 0' rpy='0 -0 0'/>
      <geometry>
        <mesh filename='package://husky_migration_sensor_config_1/meshes/wheel.dae' scale='1 1 1'/>
      </geometry>
    </visual>
  </link>
  <link name='${robot_namespace}/front_right_wheel_link'>
    <inertial>
      <origin xyz='0 0 0' rpy='0 -0 0'/>
      <mass value='2.637'/>
      <inertia ixx='0.02467' ixy='0' ixz='0' iyy='0.04411' iyz='0' izz='0.02467'/>
    </inertial>
    <collision name='front_right_wheel_link_collision'>
      <origin xyz='0 0 0' rpy='1.5708 -0 0'/>
      <geometry>
        <cylinder radius='0.1651' length='0.1143'/>
      </geometry>
    </collision>
    <visual name='front_right_wheel_link_visual'>
      <origin xyz='0 0 0' rpy='0 -0 0'/>
      <geometry>
        <mesh filename='package://husky_migration_sensor_config_1/meshes/wheel.dae' scale='1 1 1'/>
      </geometry>
    </visual>
  </link>
  <link name='${robot_namespace}/rear_left_wheel_link'>
    <inertial>
      <origin xyz='0 0 0' rpy='0 -0 0'/>
      <mass value='2.637'/>
      <inertia ixx='0.02467' ixy='0' ixz='0' iyy='0.04411' iyz='0' izz='0.02467'/>
    </inertial>
    <collision name='rear_left_wheel_link_collision'>
      <origin xyz='0 0 0' rpy='1.5708 -0 0'/>
      <geometry>
        <cylinder radius='0.1651' length='0.1143'/>
      </geometry>
    </collision>
    <visual name='rear_left_wheel_link_visual'>
      <origin xyz='0 0 0' rpy='0 -0 0'/>
      <geometry>
        <mesh filename='package://husky_migration_sensor_config_1/meshes/wheel.dae' scale='1 1 1'/>
      </geometry>
    </visual>
  </link>
  <link name='${robot_namespace}/rear_right_wheel_link'>
    <inertial>
      <origin xyz='0 0 0' rpy='0 -0 0'/>
      <mass value='2.637'/>
      <inertia ixx='0.02467' ixy='0' ixz='0' iyy='0.04411' iyz='0' izz='0.02467'/>
    </inertial>
    <collision name='rear_right_wheel_link_collision'>
      <origin xyz='0 0 0' rpy='1.5708 -0 0'/>
      <geometry>
        <cylinder radius='0.1651' length='0.1143'/>
      </geometry>
    </collision>
    <visual name='rear_right_wheel_link_visual'>
      <origin xyz='0 0 0' rpy='0 -0 0'/>
      <geometry>
        <mesh filename='package://husky_migration_sensor_config_1/meshes/wheel.dae' scale='1 1 1'/>
      </geometry>
    </visual>
  </link>
  <joint name='front_left_wheel' type='revolute'>
    <origin xyz='0.256 0.2854 0.03282' rpy='0 -0 0'/>
    <parent link='${robot_namespace}/base_link'/>
    <child link='${robot_namespace}/front_left_wheel_link'/>
    <dynamics damping='0' friction='0' />
    <axis xyz='0 1 0'/>
    <limit lower='-1e+16' upper='1e+16' effort='-1' velocity='-1'/>
  </joint>
  <joint name='front_right_wheel' type='revolute'>
    <origin xyz='0.256 -0.2854 0.03282' rpy='0 -0 0'/>
    <parent link='${robot_namespace}/base_link'/>
    <child link='${robot_namespace}/front_right_wheel_link'/>
    <dynamics damping='0' friction='0' />
    <axis xyz='0 1 0'/>
    <limit lower='-1e+16' upper='1e+16' effort='-1' velocity='-1'/>
  </joint>
  <joint name='rear_left_wheel' type='revolute'>
    <origin xyz='-0.256 0.2854 0.03282' rpy='0 -0 0'/>
    <parent link='${robot_namespace}/base_link'/>
    <child link='${robot_namespace}/rear_left_wheel_link'/>
    <dynamics damping='0' friction='0' />
    <axis xyz='0 1 0'/>
    <limit lower='-1e+16' upper='1e+16' effort='-1' velocity='-1'/>
  </joint>
  <joint name='rear_right_wheel' type='revolute'>
    <origin xyz='-0.256 -0.2854 0.03282' rpy='0 -0 0'/>
    <parent link='${robot_namespace}/base_link'/>
    <child link='${robot_namespace}/rear_right_wheel_link'/>
    <dynamics damping='0' friction='0' />
    <axis xyz='0 1 0'/>
    <limit lower='-1e+16' upper='1e+16' effort='-1' velocity='-1'/>
  </joint>
</robot>
