<?xml version='1.0' encoding='utf-8'?>
<robot name='coro_jeanine_sensor_config_1' xmlns:xacro="http://ros.org/wiki/xacro">
  <xacro:arg name="name" default="coro_jeanine_sensor_config_1"/>
  <xacro:property name="robot_namespace" value="$(arg name)"/>
  <link name='${robot_namespace}/base_link'>
    <inertial>
      <origin xyz='0 0 0.09' rpy='0 -0 0'/>
      <mass value='26.6'/>
      <inertia ixx='0.387' ixy='0' ixz='0' iyy='0.79' iyz='0' izz='0.962'/>
    </inertial>
    <collision name='chassis_collision'>
      <origin xyz='0 0 0.05' rpy='0 -0 0'/>
      <geometry>
        <box size='0.555 0.355 0.13'/>
      </geometry>
    </collision>
    <collision name='tower_collision'>
      <origin xyz='0.13 0 0.27' rpy='0 -0 0'/>
      <geometry>
        <box size='0.2 0.2 0.34'/>
      </geometry>
    </collision>
    <visual name='chassis_main_visual'>
      <origin xyz='0 0 0.07' rpy='0 -0 0'/>
      <geometry>
        <box size='0.38 0.3 0.13'/>
      </geometry>
    </visual>
    <visual name='wheel_mount_visual_front_left'>
      <origin xyz='0.17 0.12 0' rpy='0 -0 0'/>
      <geometry>
        <box size='0.03 0.06 0.02'/>
      </geometry>
    </visual>
    <visual name='wheel_mount_visual_front_right'>
      <origin xyz='0.17 -0.12 0' rpy='0 -0 0'/>
      <geometry>
        <box size='0.03 0.06 0.02'/>
      </geometry>
    </visual>
    <visual name='wheel_mount_visual_rear_left'>
      <origin xyz='-0.17 0.12 0' rpy='0 -0 0'/>
      <geometry>
        <box size='0.03 0.06 0.02'/>
      </geometry>
    </visual>
    <visual name='wheel_mount_visual_rear_right'>
      <origin xyz='-0.17 -0.12 0' rpy='0 -0 0'/>
      <geometry>
        <box size='0.03 0.06 0.02'/>
      </geometry>
    </visual>
    <visual name='emergency_stop_bottom_visual'>
      <origin xyz='0.11 0.125 0.145' rpy='0 -0 0'/>
      <geometry>
        <cylinder radius='0.015' length='0.015'/>
      </geometry>
    </visual>
    <visual name='emergency_stop_top_visual'>
      <origin xyz='0.11 0.125 0.155' rpy='0 -0 0'/>
      <geometry>
        <cylinder radius='0.02' length='0.005'/>
      </geometry>
    </visual>
    <visual name='plate1_visual'>
      <origin xyz='0 0 0.435' rpy='0 -0 0'/>
      <geometry>
        <box size='0.2 0.2 0.005'/>
      </geometry>
    </visual>
    <visual name='plate2_visual'>
      <origin xyz='0 0 0.325' rpy='0 -0 0'/>
      <geometry>
        <box size='0.2 0.2 0.005'/>
      </geometry>
    </visual>
    <visual name='plate3_visual_was12'>
      <origin xyz='0 0 0.135' rpy='0 -0 0'/>
      <geometry>
        <box size='0.2 0.2 0.005'/>
      </geometry>
    </visual>
    <visual name='beam1_visual'>
      <origin xyz='0.091 0.091 0.285' rpy='0 -0 0'/>
      <geometry>
        <box size='0.02 0.02 0.3'/>
      </geometry>
    </visual>
    <visual name='beam2_visual'>
      <origin xyz='0.091 -0.091 0.285' rpy='0 -0 0'/>
      <geometry>
        <box size='0.02 0.02 0.3'/>
      </geometry>
    </visual>
    <visual name='beam3_visual'>
      <origin xyz='-0.091 0.091 0.285' rpy='0 -0 0'/>
      <geometry>
        <box size='0.02 0.02 0.3'/>
      </geometry>
    </visual>
    <visual name='beam4_visual'>
      <origin xyz='-0.091 -0.091 0.285' rpy='0 -0 0'/>
      <geometry>
        <box size='0.02 0.02 0.3'/>
      </geometry>
    </visual>
    <visual name='d435i_realsense_camera_visual'>
      <origin xyz='0.08 0 0.408' rpy='0 0.52 0'/>
      <geometry>
        <mesh filename='package://coro_jeanine_sensor_config_1/meshes/realsense_d435.dae' scale='0.001 0.001 0.001'/>
      </geometry>
    </visual>
    <visual name='vlp16_visual1'>
      <origin xyz='0 0 0.327' rpy='0 -0 0'/>
      <geometry>
        <mesh filename='package://coro_jeanine_sensor_config_1/meshes/VLP16_base_1.dae' scale='1 1 1'/>
      </geometry>
    </visual>
    <visual name='vlp_visual2'>
      <origin xyz='0 0 0.327' rpy='0 -0 0'/>
      <geometry>
        <mesh filename='package://coro_jeanine_sensor_config_1/meshes/VLP16_base_2.dae' scale='1 1 1'/>
      </geometry>
    </visual>
    <visual name='vlp_visual3'>
      <origin xyz='0 0 0.327' rpy='0 -0 0'/>
      <geometry>
        <mesh filename='package://coro_jeanine_sensor_config_1/meshes/VLP16_scan.dae' scale='1 1 1'/>
      </geometry>
    </visual>
    <visual name='camera_front_visual'>
      <origin xyz='0.09 0.06 0.42' rpy='0 -0 0'/>
      <geometry>
        <box size='0.01 0.03 0.03'/>
      </geometry>
    </visual>
    <visual name='camera_lens_front_visual'>
      <origin xyz='0.1 0.06 0.42' rpy='0 1.5708 0'/>
      <geometry>
        <cylinder radius='0.005' length='0.011'/>
      </geometry>
    </visual>
    <visual name='camera_rear_visual'>
      <origin xyz='-0.09 0 0.42' rpy='0 -0 0'/>
      <geometry>
        <box size='0.01 0.03 0.03'/>
      </geometry>
    </visual>
    <visual name='camera_lens_rear_visual'>
      <origin xyz='-0.1 0 0.42' rpy='0 1.5708 0'/>
      <geometry>
        <cylinder radius='0.005' length='0.011'/>
      </geometry>
    </visual>
    <visual name='camera_left_visual'>
      <origin xyz='0 0.09 0.42' rpy='0 -0 0'/>
      <geometry>
        <box size='0.03 0.01 0.03'/>
      </geometry>
    </visual>
    <visual name='camera_lens_left_visual'>
      <origin xyz='0 0.1 0.42' rpy='1.5708 -0 0'/>
      <geometry>
        <cylinder radius='0.005' length='0.011'/>
      </geometry>
    </visual>
    <visual name='camera_right_visual'>
      <origin xyz='0 -0.09 0.42' rpy='0 -0 0'/>
      <geometry>
        <box size='0.03 0.01 0.03'/>
      </geometry>
    </visual>
    <visual name='camera_lens_right_visual'>
      <origin xyz='0 -0.1 0.42' rpy='1.5708 -0 0'/>
      <geometry>
        <cylinder radius='0.005' length='0.011'/>
      </geometry>
    </visual>
    <visual name='light_front_visual'>
      <origin xyz='0.09 0 0.457' rpy='0 -0 0'/>
      <geometry>
        <box size='0.04 0.13 0.04'/>
      </geometry>
    </visual>
    <visual name='light_rear_visual'>
      <origin xyz='-0.09 0 0.457' rpy='0 -0 0'/>
      <geometry>
        <box size='0.04 0.12 0.04'/>
      </geometry>
    </visual>
    <visual name='light_left_visual'>
      <origin xyz='0 0.09 0.457' rpy='0 -0 0'/>
      <geometry>
        <box size='0.12 0.04 0.04'/>
      </geometry>
    </visual>
    <visual name='light_right_visual'>
      <origin xyz='0 -0.09 0.457' rpy='0 -0 0'/>
      <geometry>
        <box size='0.12 0.04 0.04'/>
      </geometry>
    </visual>
  </link>
  <sensor name='imu_sensor' update_rate='50'>
    <parent link='${robot_namespace}/base_link'/>
    <origin xyz='0 0 0' rpy='0 -0 0'/>
  </sensor>
  <sensor name='magnetometer' update_rate='50'>
    <parent link='${robot_namespace}/base_link'/>
    <origin xyz='0 0 0' rpy='0 -0 0'/>
  </sensor>
  <sensor name='rgbd_front' update_rate='30'>
    <parent link='${robot_namespace}/base_link'/>
    <origin xyz='0.11 0 0.408' rpy='0 0.52 0'/>
    <camera>
      <image width='640' height='360' format='R8G8B8' hfov='1.50098' near='0.01' far='300' />
    </camera>
  </sensor>
  <sensor name='camera_front' update_rate='25'>
    <parent link='${robot_namespace}/base_link'/>
    <origin xyz='0.11 0.06 0.42' rpy='0 -0 0'/>
    <camera>
      <image width='720' height='1080' format='R8G8B8' hfov='1.658' near='0.01' far='300' />
    </camera>
  </sensor>
  <sensor name='camera_rear' update_rate='25'>
    <parent link='${robot_namespace}/base_link'/>
    <origin xyz='-0.11 0 0.42' rpy='0 -0 3.14159'/>
    <camera>
      <image width='720' height='1080' format='R8G8B8' hfov='1.658' near='0.01' far='300' />
    </camera>
  </sensor>
  <sensor name='camera_left' update_rate='25'>
    <parent link='${robot_namespace}/base_link'/>
    <origin xyz='0 0.11 0.42' rpy='0 -0 1.5708'/>
    <camera>
      <image width='720' height='1080' format='R8G8B8' hfov='1.658' near='0.01' far='300' />
    </camera>
  </sensor>
  <sensor name='camera_right' update_rate='25'>
    <parent link='${robot_namespace}/base_link'/>
    <origin xyz='0 -0.11 0.42' rpy='0 0 -1.5708'/>
    <camera>
      <image width='720' height='1080' format='R8G8B8' hfov='1.658' near='0.01' far='300' />
    </camera>
  </sensor>
  <sensor name='front_laser' update_rate='10'>
    <parent link='${robot_namespace}/base_link'/>
    <origin xyz='0 0 0.365' rpy='0 -0 0'/>
  </sensor>
  <link name='${robot_namespace}/front_left_wheel'>
    <inertial>
      <origin xyz='0 0 0' rpy='0 -0 0'/>
      <mass value='5'/>
      <inertia ixx='0.0153' ixy='0' ixz='0' iyy='0.025' iyz='0' izz='0.0153'/>
    </inertial>
    <collision name='front_left_wheel_collision'>
      <origin xyz='0 0 0' rpy='-1.5708 0 0'/>
      <geometry>
        <cylinder radius='0.1275' length='0.075'/>
      </geometry>
    </collision>
    <visual name='front_left_wheel_tire_visual'>
      <origin xyz='0 0 0' rpy='1.5708 -0 0'/>
      <geometry>
        <mesh filename='package://coro_jeanine_sensor_config_1/meshes/wheel_left.dae' scale='1.22 1.22 1.71'/>
      </geometry>
    </visual>
    <visual name='front_left_wheel_axle_visual'>
      <origin xyz='0 -0.055 0' rpy='1.5708 -0 0'/>
      <geometry>
        <cylinder radius='0.007' length='0.05'/>
      </geometry>
    </visual>
  </link>
  <link name='${robot_namespace}/front_right_wheel'>
    <inertial>
      <origin xyz='0 0 0' rpy='0 -0 0'/>
      <mass value='5'/>
      <inertia ixx='0.0153' ixy='0' ixz='0' iyy='0.025' iyz='0' izz='0.0153'/>
    </inertial>
    <collision name='front_right_wheel_collision'>
      <origin xyz='0 0 0' rpy='1.5708 -0 0'/>
      <geometry>
        <cylinder radius='0.1275' length='0.075'/>
      </geometry>
    </collision>
    <visual name='front_right_wheel_tire_visual'>
      <origin xyz='0 0 0' rpy='1.5708 -0 0'/>
      <geometry>
        <mesh filename='package://coro_jeanine_sensor_config_1/meshes/wheel_right.dae' scale='1.22 1.22 1.71'/>
      </geometry>
    </visual>
    <visual name='front_right_wheel_axle_visual'>
      <origin xyz='0 0.055 0' rpy='1.5708 -0 0'/>
      <geometry>
        <cylinder radius='0.007' length='0.05'/>
      </geometry>
    </visual>
  </link>
  <link name='${robot_namespace}/rear_left_wheel'>
    <inertial>
      <origin xyz='0 0 0' rpy='0 -0 0'/>
      <mass value='5'/>
      <inertia ixx='0.0153' ixy='0' ixz='0' iyy='0.025' iyz='0' izz='0.0153'/>
    </inertial>
    <collision name='rear_left_wheel_collision'>
      <origin xyz='0 0 0' rpy='-1.5708 0 0'/>
      <geometry>
        <cylinder radius='0.1275' length='0.075'/>
      </geometry>
    </collision>
    <visual name='rear_left_wheel_tire_visual'>
      <origin xyz='0 0 0' rpy='1.5708 -0 0'/>
      <geometry>
        <mesh filename='package://coro_jeanine_sensor_config_1/meshes/wheel_left.dae' scale='1.22 1.22 1.71'/>
      </geometry>
    </visual>
    <visual name='rear_left_wheel_axle_visual'>
      <origin xyz='0 -0.055 0' rpy='1.5708 -0 0'/>
      <geometry>
        <cylinder radius='0.007' length='0.05'/>
      </geometry>
    </visual>
  </link>
  <link name='${robot_namespace}/rear_right_wheel'>
    <inertial>
      <origin xyz='0 0 0' rpy='0 -0 0'/>
      <mass value='5'/>
      <inertia ixx='0.0153' ixy='0' ixz='0' iyy='0.025' iyz='0' izz='0.0153'/>
    </inertial>
    <collision name='rear_right_wheel_collision'>
      <origin xyz='0 0 0' rpy='1.5708 -0 0'/>
      <geometry>
        <cylinder radius='0.1275' length='0.075'/>
      </geometry>
    </collision>
    <visual name='rear_right_wheel_tire_visual'>
      <origin xyz='0 0 0' rpy='1.5708 -0 0'/>
      <geometry>
        <mesh filename='package://coro_jeanine_sensor_config_1/meshes/wheel_right.dae' scale='1.22 1.22 1.71'/>
      </geometry>
    </visual>
    <visual name='rear_right_wheel_axle_visual'>
      <origin xyz='0 0.055 0' rpy='1.5708 -0 0'/>
      <geometry>
        <cylinder radius='0.007' length='0.05'/>
      </geometry>
    </visual>
  </link>
  <joint name='front_left_wheel_joint' type='revolute'>
    <origin xyz='0.17 0.21 0' rpy='0 -0 0'/>
    <parent link='${robot_namespace}/base_link'/>
    <child link='${robot_namespace}/front_left_wheel'/>
    <axis xyz='0 1 0'/>
    <limit lower='-1.79769e+308' upper='1.79769e+308' effort='10' velocity='19.61'/>
  </joint>
  <joint name='rear_left_wheel_joint' type='revolute'>
    <origin xyz='-0.17 0.21 0' rpy='0 -0 0'/>
    <parent link='${robot_namespace}/base_link'/>
    <child link='${robot_namespace}/rear_left_wheel'/>
    <axis xyz='0 1 0'/>
    <limit lower='-1.79769e+308' upper='1.79769e+308' effort='10' velocity='19.61'/>
  </joint>
  <joint name='rear_right_wheel_joint' type='revolute'>
    <origin xyz='-0.17 -0.21 0' rpy='0 -0 0'/>
    <parent link='${robot_namespace}/base_link'/>
    <child link='${robot_namespace}/rear_right_wheel'/>
    <axis xyz='0 1 0'/>
    <limit lower='-1.79769e+308' upper='1.79769e+308' effort='10' velocity='19.61'/>
  </joint>
  <joint name='front_right_wheel_joint' type='revolute'>
    <origin xyz='0.17 -0.21 0' rpy='0 -0 0'/>
    <parent link='${robot_namespace}/base_link'/>
    <child link='${robot_namespace}/front_right_wheel'/>
    <axis xyz='0 1 0'/>
    <limit lower='-1.79769e+308' upper='1.79769e+308' effort='10' velocity='19.61'/>
  </joint>
</robot>
