<?xml version="1.0" ?>
<robot name="Pam">
  <joint name="Pam__rotor_0_joint" type="revolute">
    <parent link="Pam__base_link"/>
    <child link="Pam__rotor_0"/>
    <origin rpy="0 0 0" xyz="0.2  -0.18  0.05"/>
    <axis xyz="0 0 1"/>
    <limit effort="0.0" lower="-1e+16" upper="1e+16" velocity="0.0"/>
  </joint>
  <joint name="Pam__rotor_1_joint" type="revolute">
    <parent link="Pam__base_link"/>
    <child link="Pam__rotor_1"/>
    <origin rpy="0 0 0" xyz="-0.2   0.18  0.05"/>
    <axis xyz="0 0 1"/>
    <limit effort="0.0" lower="-1e+16" upper="1e+16" velocity="0.0"/>
  </joint>
  <joint name="Pam__rotor_2_joint" type="revolute">
    <parent link="Pam__base_link"/>
    <child link="Pam__rotor_2"/>
    <origin rpy="0 0 0" xyz="0.2  0.18 0.05"/>
    <axis xyz="0 0 1"/>
    <limit effort="0.0" lower="-1e+16" upper="1e+16" velocity="0.0"/>
  </joint>
  <joint name="Pam__rotor_3_joint" type="revolute">
    <parent link="Pam__base_link"/>
    <child link="Pam__rotor_3"/>
    <origin rpy="0 0 0" xyz="-0.2  -0.18  0.05"/>
    <axis xyz="0 0 1"/>
    <limit effort="0.0" lower="-1e+16" upper="1e+16" velocity="0.0"/>
  </joint>
  <link name="Pam__base_link">
    <inertial>
      <mass value="3.461"/>
      <origin rpy="0 0 0" xyz="0 0 0"/>
      <inertia ixx="0.0324" ixy="0" ixz="0" iyy="0.0324" iyz="0" izz="0.0519"/>
    </inertial>
    <collision name="Pam__base_link_inertia_collision">
      <origin rpy="0 0 0" xyz="0    0   -0.05"/>
      <geometry>
        <box size="0.76 0.72 0.3"/>
      </geometry>
    </collision>
    <visual name="Pam__plate1_visual">
      <origin rpy="0 0 0" xyz="0 0 0"/>
      <geometry>
        <box size="0.14 0.14 0.001"/>
      </geometry>
    </visual>
    <visual name="Pam__plate2_visual">
      <origin rpy="0 0 0" xyz="0    0   -0.04"/>
      <geometry>
        <box size="0.14 0.14 0.001"/>
      </geometry>
    </visual>
    <visual name="Pam__plate3_visual">
      <origin rpy="0 0 0" xyz="0    0   -0.09"/>
      <geometry>
        <box size="0.14 0.14 0.001"/>
      </geometry>
    </visual>
    <visual name="Pam__plate4_visual">
      <origin rpy="0 0 0" xyz="0.015  0    -0.13"/>
      <geometry>
        <box size="0.17 0.14 0.001"/>
      </geometry>
    </visual>
    <visual name="Pam__brix_visual">
      <origin rpy="0 0 0" xyz="0     0    -0.065"/>
      <geometry>
        <box size="0.12 0.12 0.05"/>
      </geometry>
    </visual>
    <visual name="Pam__battery_visual">
      <origin rpy="0 0 0" xyz="0    0   -0.11"/>
      <geometry>
        <box size="0.14 0.08 0.04"/>
      </geometry>
    </visual>
    <visual name="Pam__leg1_visual">
      <origin rpy="-0.6  0   0" xyz="0.08   0.11  -0.158"/>
      <geometry>
        <box size="0.04 0.1 0.001"/>
      </geometry>
    </visual>
    <visual name="Pam__leg2_visual">
      <origin rpy="0.6 0  0" xyz="0.08  -0.11  -0.158"/>
      <geometry>
        <box size="0.04 0.1 0.001"/>
      </geometry>
    </visual>
    <visual name="Pam__leg3_visual">
      <origin rpy="-0.6  0   0" xyz="-0.05   0.11  -0.158"/>
      <geometry>
        <box size="0.04 0.1 0.001"/>
      </geometry>
    </visual>
    <visual name="Pam__leg4_visual">
      <origin rpy="0.6 0  0" xyz="-0.05  -0.11  -0.158"/>
      <geometry>
        <box size="0.04 0.1 0.001"/>
      </geometry>
    </visual>
    <visual name="Pam__antenna1_visual">
      <origin rpy="0 0 0" xyz="0.05 -0.05  0.05"/>
      <geometry>
        <cylinder length="0.1" radius="0.005"/>
      </geometry>
    </visual>
    <visual name="Pam__antenna2_visual">
      <origin rpy="0 0 0" xyz="-0.05 -0.05  0.05"/>
      <geometry>
        <cylinder length="0.1" radius="0.005"/>
      </geometry>
    </visual>
    <visual name="Pam__prop_guard1_visual">
      <origin rpy="1.57079 0      0" xyz="0.38 0   0.05"/>
      <geometry>
        <cylinder length="0.48" radius="0.002"/>
      </geometry>
    </visual>
    <visual name="Pam__prop_guard2_visual">
      <origin rpy="3.14159 1.57079 3.14159" xyz="0   0.36 0.05"/>
      <geometry>
        <cylinder length="0.52" radius="0.002"/>
      </geometry>
    </visual>
    <visual name="Pam__prop_guard3_visual">
      <origin rpy="1.57079 0      0" xyz="-0.38  0    0.05"/>
      <geometry>
        <cylinder length="0.48" radius="0.002"/>
      </geometry>
    </visual>
    <visual name="Pam__prop_guard4_visual">
      <origin rpy="3.14159 1.57079 3.14159" xyz="0   -0.36  0.05"/>
      <geometry>
        <cylinder length="0.52" radius="0.002"/>
      </geometry>
    </visual>
    <visual name="Pam__prop_guard5_visual">
      <origin rpy="1.57079 0      0.7854" xyz="0.32 0.3  0.05"/>
      <geometry>
        <cylinder length="0.17" radius="0.002"/>
      </geometry>
    </visual>
    <visual name="Pam__prop_guard6_visual">
      <origin rpy="1.57079 0      0.7854" xyz="-0.32 -0.3   0.05"/>
      <geometry>
        <cylinder length="0.17" radius="0.002"/>
      </geometry>
    </visual>
    <visual name="Pam__prop_guard7_visual">
      <origin rpy="1.57079  0      -0.7854" xyz="-0.32  0.3   0.05"/>
      <geometry>
        <cylinder length="0.17" radius="0.002"/>
      </geometry>
    </visual>
    <visual name="Pam__prop_guard8_visual">
      <origin rpy="1.57079  0      -0.7854" xyz="0.32 -0.3   0.05"/>
      <geometry>
        <cylinder length="0.17" radius="0.002"/>
      </geometry>
    </visual>
    <visual name="Pam__prop_guard9_visual">
      <origin rpy="0 0 0" xyz="0.32  0.3   0.025"/>
      <geometry>
        <cylinder length="0.055" radius="0.004"/>
      </geometry>
    </visual>
    <visual name="Pam__prop_guard10_visual">
      <origin rpy="0 0 0" xyz="-0.32   0.3    0.025"/>
      <geometry>
        <cylinder length="0.055" radius="0.004"/>
      </geometry>
    </visual>
    <visual name="Pam__prop_guard11_visual">
      <origin rpy="0 0 0" xyz="0.32  -0.3    0.025"/>
      <geometry>
        <cylinder length="0.055" radius="0.004"/>
      </geometry>
    </visual>
    <visual name="Pam__prop_guard12_visual">
      <origin rpy="0 0 0" xyz="-0.32  -0.3    0.025"/>
      <geometry>
        <cylinder length="0.055" radius="0.004"/>
      </geometry>
    </visual>
    <visual name="Pam__prop_guard13_visual">
      <origin rpy="1.57079  0      -0.7854" xyz="0.265  0.245 -0.005"/>
      <geometry>
        <cylinder length="0.16" radius="0.004"/>
      </geometry>
    </visual>
    <visual name="Pam__prop_guard14_visual">
      <origin rpy="1.57079  0      -0.7854" xyz="-0.265 -0.245 -0.005"/>
      <geometry>
        <cylinder length="0.16" radius="0.004"/>
      </geometry>
    </visual>
    <visual name="Pam__prop_guard15_visual">
      <origin rpy="1.57079 0      0.7854" xyz="-0.265  0.245 -0.005"/>
      <geometry>
        <cylinder length="0.16" radius="0.004"/>
      </geometry>
    </visual>
    <visual name="Pam__prop_guard16_visual">
      <origin rpy="1.57079 0      0.7854" xyz="0.265 -0.245 -0.005"/>
      <geometry>
        <cylinder length="0.16" radius="0.004"/>
      </geometry>
    </visual>
    <visual name="Pam__arm1_visual">
      <origin rpy="0   0   0.74" xyz="0.13   0.12  -0.005"/>
      <geometry>
        <box size="0.21 0.03 0.01"/>
      </geometry>
    </visual>
    <visual name="Pam__arm2_visual">
      <origin rpy="0    0   -0.74" xyz="0.13  -0.12  -0.005"/>
      <geometry>
        <box size="0.21 0.03 0.01"/>
      </geometry>
    </visual>
    <visual name="Pam__arm3_visual">
      <origin rpy="0    0   -0.74" xyz="-0.13   0.12  -0.005"/>
      <geometry>
        <box size="0.21 0.03 0.01"/>
      </geometry>
    </visual>
    <visual name="Pam__arm4_visual">
      <origin rpy="0   0   0.74" xyz="-0.13  -0.12  -0.005"/>
      <geometry>
        <box size="0.21 0.03 0.01"/>
      </geometry>
    </visual>
    <visual name="Pam__arm1a_visual">
      <origin rpy="0   0   0.02" xyz="0.06   0.06  -0.025"/>
      <geometry>
        <box size="0.02 0.02 0.03"/>
      </geometry>
    </visual>
    <visual name="Pam__arm2a_visual">
      <origin rpy="0   0   0.02" xyz="0.06  -0.06  -0.025"/>
      <geometry>
        <box size="0.02 0.02 0.03"/>
      </geometry>
    </visual>
    <visual name="Pam__arm3a_visual">
      <origin rpy="0   0   0.02" xyz="-0.06   0.06  -0.025"/>
      <geometry>
        <box size="0.02 0.02 0.03"/>
      </geometry>
    </visual>
    <visual name="Pam__arm4a_visual">
      <origin rpy="0   0   0.02" xyz="-0.06  -0.06  -0.025"/>
      <geometry>
        <box size="0.02 0.02 0.03"/>
      </geometry>
    </visual>
    <visual name="Pam__motor1_visual">
      <origin rpy="0 0 0" xyz="0.2  0.18 0.02"/>
      <geometry>
        <cylinder length="0.04" radius="0.02"/>
      </geometry>
    </visual>
    <visual name="Pam__motor2_visual">
      <origin rpy="0 0 0" xyz="-0.2   0.18  0.02"/>
      <geometry>
        <cylinder length="0.04" radius="0.02"/>
      </geometry>
    </visual>
    <visual name="Pam__motor3_visual">
      <origin rpy="0 0 0" xyz="0.2  -0.18  0.02"/>
      <geometry>
        <cylinder length="0.04" radius="0.02"/>
      </geometry>
    </visual>
    <visual name="Pam__motor4_visual">
      <origin rpy="0 0 0" xyz="-0.2  -0.18  0.02"/>
      <geometry>
        <cylinder length="0.04" radius="0.02"/>
      </geometry>
    </visual>
    <visual name="Pam__lightbar_visual">
      <origin rpy="0 0 0" xyz="0.095 -0.06  -0.1"/>
      <geometry>
        <box size="0.001 0.02 0.06"/>
      </geometry>
    </visual>
    <visual name="Pam__t265_visual">
      <origin rpy="0   0.75 0" xyz="0.09     0      -0.14299"/>
      <geometry>
        <box size="0.013 0.108 0.025"/>
      </geometry>
    </visual>
    <visual name="Pam__d435_dae_front_visual">
      <origin rpy="0 0 0" xyz="0.075  0    -0.13"/>
      <geometry>
        <mesh filename="package://coro_pam_sensor_config_1/meshes/realsense_d435.dae" scale="0.001 0.001 0.001"/>
      </geometry>
    </visual>
    <visual name="Pam__d435_dae_left_visual">
      <origin rpy="1.57079 0      1.57079" xyz="0     0.07  -0.117"/>
      <geometry>
        <mesh filename="package://coro_pam_sensor_config_1/meshes/realsense_d435.dae" scale="0.001 0.001 0.001"/>
      </geometry>
    </visual>
    <visual name="Pam__d435_dae_right_visual">
      <origin rpy="1.57079  0      -1.57079" xyz="0.02  -0.07  -0.117"/>
      <geometry>
        <mesh filename="package://coro_pam_sensor_config_1/meshes/realsense_d435.dae" scale="0.001 0.001 0.001"/>
      </geometry>
    </visual>
  </link>
  <link name="Pam__rotor_0">
    <inertial>
      <mass value="0.024"/>
      <origin rpy="0 0 0" xyz="0 0 0"/>
      <inertia ixx="1e-05" ixy="0" ixz="0" iyy="4e-04" iyz="0" izz="4e-04"/>
    </inertial>
    <collision name="Pam__rotor_0_collision">
      <origin rpy="0 0 0" xyz="0 0 0"/>
      <geometry>
        <cylinder length="0.01" radius="0.165"/>
      </geometry>
    </collision>
    <visual name="Pam__rotor_0_visual">
      <origin rpy="0 0 0" xyz="0 0 0"/>
      <geometry>
        <mesh filename="package://coro_pam_sensor_config_1/meshes/propeller_ccw.dae" scale="0.165 0.165 0.165"/>
      </geometry>
    </visual>
  </link>
  <link name="Pam__rotor_1">
    <inertial>
      <mass value="0.024"/>
      <origin rpy="0 0 0" xyz="0 0 0"/>
      <inertia ixx="1e-05" ixy="0" ixz="0" iyy="4e-04" iyz="0" izz="4e-04"/>
    </inertial>
    <collision name="Pam__rotor_1_collision">
      <origin rpy="0 0 0" xyz="0 0 0"/>
      <geometry>
        <cylinder length="0.01" radius="0.165"/>
      </geometry>
    </collision>
    <visual name="Pam__rotor_1_visual">
      <origin rpy="0 0 0" xyz="0 0 0"/>
      <geometry>
        <mesh filename="package://coro_pam_sensor_config_1/meshes/propeller_ccw.dae" scale="0.165 0.165 0.165"/>
      </geometry>
    </visual>
  </link>
  <link name="Pam__rotor_2">
    <inertial>
      <mass value="0.024"/>
      <origin rpy="0 0 0" xyz="0 0 0"/>
      <inertia ixx="1e-05" ixy="0" ixz="0" iyy="4e-04" iyz="0" izz="4e-04"/>
    </inertial>
    <collision name="Pam__rotor_2_collision">
      <origin rpy="0 0 0" xyz="0 0 0"/>
      <geometry>
        <cylinder length="0.01" radius="0.165"/>
      </geometry>
    </collision>
    <visual name="Pam__rotor_2_visual">
      <origin rpy="0 0 0" xyz="0 0 0"/>
      <geometry>
        <mesh filename="package://coro_pam_sensor_config_1/meshes/propeller_cw.dae" scale="0.165 0.165 0.165"/>
      </geometry>
    </visual>
  </link>
  <link name="Pam__rotor_3">
    <inertial>
      <mass value="0.024"/>
      <origin rpy="0 0 0" xyz="0 0 0"/>
      <inertia ixx="1e-05" ixy="0" ixz="0" iyy="4e-04" iyz="0" izz="4e-04"/>
    </inertial>
    <collision name="Pam__rotor_3_collision">
      <origin rpy="0 0 0" xyz="0 0 0"/>
      <geometry>
        <cylinder length="0.01" radius="0.165"/>
      </geometry>
    </collision>
    <visual name="Pam__rotor_3_visual">
      <origin rpy="0 0 0" xyz="0 0 0"/>
      <geometry>
        <mesh filename="package://coro_pam_sensor_config_1/meshes/propeller_cw.dae" scale="0.165 0.165 0.165"/>
      </geometry>
    </visual>
  </link>
</robot>
