<?xml version='1.0' encoding='utf-8'?>
<sdf version="1.6">  <!-- CAUTION: This is an autogenerated file, DO NOT EDIT IT!  It was generated by script update_robot_sdf and is based on urdf/trailer.xacro source file.  Do all modifications there and then run the update script to regenerate the SDF. -->
  <model name="ctu_cras_norlab_trailer_sensor_config_1">
    <link name="base_link">
      <inertial>
        <mass>0.1</mass>
        <inertia>
          <ixx>1.66667e-08</ixx>
          <ixy>0</ixy>
          <ixz>0</ixz>
          <iyy>1.66667e-08</iyy>
          <iyz>0</iyz>
          <izz>1.66667e-08</izz>
        </inertia>
      </inertial>
    </link>
    <link name="intermediate">
      <pose>0 0 0 0 0 -3.1415926535897931</pose>
      <inertial>
        <mass>0.1</mass>
        <inertia>
          <ixx>1.66667e-08</ixx>
          <ixy>0</ixy>
          <ixz>0</ixz>
          <iyy>1.66667e-08</iyy>
          <iyz>0</iyz>
          <izz>1.66667e-08</izz>
        </inertia>
      </inertial>
    </link>
    <joint name="marsup_z_j" type="revolute">
      <child>intermediate</child>
      <parent>base_link</parent>
      <axis>
        <xyz>0 0 1</xyz>
        <limit>
          <lower>-1.5708</lower>
          <upper>1.5708</upper>
          <effort>10000</effort>
          <velocity>2</velocity>
        </limit>
        <dynamics>
          <spring_reference>0</spring_reference>
          <spring_stiffness>0</spring_stiffness>
        </dynamics>
        <use_parent_model_frame>0</use_parent_model_frame>
      </axis>
    </joint>
    <link name="dragging_rod">
      <pose>0 0 0 0 0 -3.1415926535897931</pose>
      <inertial>
        <pose>0.25 0 0 0 1.5707963267948966 0</pose>
        <mass>0.5</mass>
        <inertia>
          <ixx>0.0104667</ixx>
          <ixy>0</ixy>
          <ixz>0</ixz>
          <iyy>0.0104667</iyy>
          <iyz>0</iyz>
          <izz>0.0001</izz>
        </inertia>
      </inertial>
      <collision name="dragging_rod_collision">
        <pose>0.25 0 0 0 1.5707963267948966 0</pose>
        <geometry>
          <cylinder>
            <length>0.5</length>
            <radius>0.02</radius>
          </cylinder>
        </geometry>
      </collision>
      <visual name="dragging_rod_visual">
        <pose>0.25 0 0 0 1.5707963267948966 0</pose>
        <geometry>
          <cylinder>
            <length>0.5</length>
            <radius>0.02</radius>
          </cylinder>
        </geometry>
      </visual>
    </link>
    <joint name="marsup_y_j" type="revolute">
      <child>dragging_rod</child>
      <parent>intermediate</parent>
      <axis>
        <xyz>0 1 0</xyz>
        <limit>
          <lower>-0.785398</lower>
          <upper>0.785398</upper>
          <effort>10000</effort>
          <velocity>2</velocity>
        </limit>
        <dynamics>
          <spring_reference>0</spring_reference>
          <spring_stiffness>0</spring_stiffness>
        </dynamics>
        <use_parent_model_frame>0</use_parent_model_frame>
      </axis>
    </joint>
    <link name="chassis">
      <pose>-0.75 -0 0 0 0 -3.1415926535897931</pose>
      <inertial>
        <mass>2</mass>
        <inertia>
          <ixx>0.00833333</ixx>
          <ixy>0</ixy>
          <ixz>0</ixz>
          <iyy>0.0433333</iyy>
          <iyz>0</iyz>
          <izz>0.0483333</izz>
        </inertia>
      </inertial>
      <collision name="chassis_collision">
        <geometry>
          <box>
            <size>0.5 0.2 0.1</size>
          </box>
        </geometry>
      </collision>
      <collision name="chassis_fixed_joint_lump__antenna_1_collision_1">
        <pose>0.2 0.06 0.2 0 -0 0</pose>
        <geometry>
          <cylinder>
            <length>0.4</length>
            <radius>0.01</radius>
          </cylinder>
        </geometry>
      </collision>
      <collision name="chassis_fixed_joint_lump__antenna_2_collision_2">
        <pose>0.2 -0.06 0.2 0 -0 0</pose>
        <geometry>
          <cylinder>
            <length>0.4</length>
            <radius>0.01</radius>
          </cylinder>
        </geometry>
      </collision>
      <visual name="chassis_visual">
        <geometry>
          <box>
            <size>0.5 0.2 0.1</size>
          </box>
        </geometry>
        <material>
          <ambient>0 0 0 0</ambient>
          <specular>0 0 0 0</specular>
          <emissive>0 0 0 0</emissive>
        </material>
      </visual>
      <visual name="chassis_fixed_joint_lump__antenna_1_visual_1">
        <pose>0.2 0.06 0.2 0 -0 0</pose>
        <geometry>
          <cylinder>
            <length>0.4</length>
            <radius>0.01</radius>
          </cylinder>
        </geometry>
      </visual>
      <visual name="chassis_fixed_joint_lump__antenna_2_visual_2">
        <pose>0.2 -0.06 0.2 0 -0 0</pose>
        <geometry>
          <cylinder>
            <length>0.4</length>
            <radius>0.01</radius>
          </cylinder>
        </geometry>
      </visual>
    </link>
    <joint name="rod_j" type="fixed">
      <child>chassis</child>
      <parent>dragging_rod</parent>
      <axis>
        <dynamics>
          <spring_reference>0</spring_reference>
          <spring_stiffness>0</spring_stiffness>
        </dynamics>
        <xyz>0 0 1</xyz>
        <use_parent_model_frame>0</use_parent_model_frame>
        <limit>
          <lower>-1e+16</lower>
          <upper>1e+16</upper>
        </limit>
      </axis>
      <physics>
        <ode>
          <limit>
            <cfm>0</cfm>
            <erp>0.2</erp>
          </limit>
        </ode>
      </physics>
    </joint>
    <link name="left_wheel">
      <pose>-0.75 0.12 0 0 0 -3.1415926535897931</pose>
      <inertial>
        <pose>0 0 0 1.5707963267948966 -0 0</pose>
        <mass>1</mass>
        <inertia>
          <ixx>0.010075</ixx>
          <ixy>0</ixy>
          <ixz>0</ixz>
          <iyy>0.010075</iyy>
          <iyz>0</iyz>
          <izz>0.02</izz>
        </inertia>
      </inertial>
      <collision name="left_wheel_collision">
        <pose>0 0 0 1.5707963267948966 -0 0</pose>
        <geometry>
          <cylinder>
            <length>0.03</length>
            <radius>0.2</radius>
          </cylinder>
        </geometry>
      </collision>
      <visual name="left_wheel_visual">
        <geometry>
          <mesh>
            <uri>meshes/wheel.dae</uri>
          </mesh>
        </geometry>
      </visual>
    </link>
    <joint name="left_wheel_j" type="revolute">
      <child>left_wheel</child>
      <parent>chassis</parent>
      <axis>
        <xyz>0 1 0</xyz>
        <limit>
          <lower>-1e+16</lower>
          <upper>1e+16</upper>
        </limit>
        <dynamics>
          <spring_reference>0</spring_reference>
          <spring_stiffness>0</spring_stiffness>
        </dynamics>
        <use_parent_model_frame>0</use_parent_model_frame>
      </axis>
    </joint>
    <link name="right_wheel">
      <pose>-0.75 -0.12 0 0 0 -3.1415926535897931</pose>
      <inertial>
        <pose>0 0 0 1.5707963267948966 -0 0</pose>
        <mass>1</mass>
        <inertia>
          <ixx>0.010075</ixx>
          <ixy>0</ixy>
          <ixz>0</ixz>
          <iyy>0.010075</iyy>
          <iyz>0</iyz>
          <izz>0.02</izz>
        </inertia>
      </inertial>
      <collision name="right_wheel_collision">
        <pose>0 0 0 1.5707963267948966 -0 0</pose>
        <geometry>
          <cylinder>
            <length>0.03</length>
            <radius>0.2</radius>
          </cylinder>
        </geometry>
      </collision>
      <visual name="right_wheel_visual">
        <geometry>
          <mesh>
            <uri>meshes/wheel.dae</uri>
          </mesh>
        </geometry>
      </visual>
    </link>
    <joint name="right_wheel_j" type="revolute">
      <child>right_wheel</child>
      <parent>chassis</parent>
      <axis>
        <xyz>0 1 0</xyz>
        <limit>
          <lower>-1e+16</lower>
          <upper>1e+16</upper>
        </limit>
        <dynamics>
          <spring_reference>0</spring_reference>
          <spring_stiffness>0</spring_stiffness>
        </dynamics>
        <use_parent_model_frame>0</use_parent_model_frame>
      </axis>
    </joint>
  </model>
</sdf>

