<?xml version='1.0' encoding='utf-8'?>
<robot name='marble_hd2_sensor_config_3' xmlns:xacro='http://ros.org/wiki/xacro'>
  <xacro:arg name="name" default="marble_hd2_sensor_config_3"/>
  <xacro:property name="robot_namespace" value="$(arg name)"/>
  <link name='${robot_namespace}/base_link'>
    <inertial>
      <origin xyz='-0.000649 -0.084945 0.062329' rpy='0 -0 0'/>
      <mass value='21.8194'/>
      <inertia ixx='0.615397' ixy='-0.0240585' ixz='-0.120749' iyy='1.75388' iyz='-0.0028322' izz='2.03641'/>
    </inertial>
    <collision name='base_link_collision'>
      <origin xyz='0 0 0.12' rpy='0 -0 0'/>
      <geometry>
        <box size='0.9874 0.5709 0.05'/>
      </geometry>
    </collision>
    <collision name='base_link_collision_bottom'>
      <origin xyz='0 0 0.046' rpy='0 -0 0'/>
      <geometry>
        <box size='0.8 0.5709 0.2'/>
      </geometry>
    </collision>
    <collision name='base_link_collision_1'>
      <origin xyz='0 0 0.185625' rpy='0 -0 0'/>
      <geometry>
        <box size='0.78992 0.5709 0.12375'/>
      </geometry>
    </collision>
    <collision name='base_link_fixed_joint_lump__camera/camera_link_collision_1'>
      <origin xyz='0 0 0.05' rpy='0 -0 0'/>
      <geometry>
        <box size='0.0078 0.13 0.0192'/>
      </geometry>
    </collision>
    <collision name='base_link_fixed_joint_lump__camera/camera_link_collision_2'>
      <origin xyz='0.485 0 0.31' rpy='0 -0 0'/>
      <geometry>
        <box size='0.0078 0.13 0.0192'/>
      </geometry>
    </collision>
    <collision name='base_link_fixed_joint_lump__camera/camera_link_collision_3'>
      <origin xyz='0.473 0 0.26' rpy='0 0.5236 0'/>
      <geometry>
        <box size='0.0078 0.13 0.0192'/>
      </geometry>
    </collision>
    <collision name='base_link_fixed_joint_lump__velodyne_base_link_collision_6'>
      <origin xyz='0.403 0 0.36' rpy='0 -0 0'/>
      <geometry>
        <cylinder radius='0.0516' length='0.0717'/>
      </geometry>
    </collision>
    <collision name='base_link_fixed_joint_lump__velodyne_gimbal_plate_base_link_collision_7'>
      <origin xyz='0.403 0 0.41' rpy='0 -0 0'/>
      <geometry>
        <box size='0.1 0.1 0.01'/>
      </geometry>
    </collision>
    <collision name='base_link_fixed_joint_lump__sensor_tower_8'>
      <origin xyz='0.374 0 0.215' rpy='0 -0 0'/>
      <geometry>
        <box size='0.2 0.25 0.225'/>
      </geometry>
    </collision>
    <collision name='base_link_fixed_joint_lump__computer_block_9'>
      <origin xyz='0.05 0 0.155' rpy='0 -0 0'/>
      <geometry>
        <box size='0.3 0.355 0.16'/>
      </geometry>
    </collision>
    <visual name='Body_visual'>
      <origin xyz='0 0 -0.135' rpy='0 -0 1.57'/>
      <geometry>
        <mesh filename='package://marble_hd2_sensor_config_3/meshes/hd2.dae' scale='1 1 1'/>
      </geometry>
    </visual>
  </link>
  <sensor name='camera_down' update_rate='30'>
    <parent link='${robot_namespace}/base_link'/>
    <origin xyz='0.473 0 0.26' rpy='0 0.5236 0'/>
    <camera>
      <image width='320' height='240' format='R8G8B8' hfov='1.5184' near='0.01' far='300' />
    </camera>
  </sensor>
  <sensor name='planar_laser' update_rate='10'>
    <parent link='${robot_namespace}/base_link'/>
    <origin xyz='0.403 0 0.127' rpy='0 -0 0'/>
  </sensor>
  <sensor name='imu_sensor' update_rate='50'>
    <parent link='${robot_namespace}/base_link'/>
    <origin xyz='0 0 0' rpy='0 -0 0'/>
  </sensor>
  <link name='${robot_namespace}/sensor_head_link'>
    <inertial>
      <origin xyz='0 0 0' rpy='0 -0 0'/>
      <mass value='0.1'/>
      <inertia ixx='0.01' ixy='0' ixz='0' iyy='0.01' iyz='0' izz='0.01'/>
    </inertial>
    <visual name='sensor_head_visual'>
      <origin xyz='0 0 0' rpy='0 -0 0'/>
      <geometry>
        <box size='0.1 0.1 0.1'/>
      </geometry>
    </visual>
    <visual name='base_link_fixed_joint_lump__velodyne_base_link_visual_10'>
      <origin xyz='0 0 0.086' rpy='0 -0 0'/>
      <geometry>
        <mesh filename='package://marble_hd2_sensor_config_3/meshes/VLP16_base_1.dae' scale='1 1 1'/>
      </geometry>
    </visual>
    <visual name='base_link_fixed_joint_lump__velodyne_base_link_visual_11'>
      <origin xyz='0 0 0.086' rpy='0 -0 0'/>
      <geometry>
        <mesh filename='package://marble_hd2_sensor_config_3/meshes/VLP16_base_2.dae' scale='1 1 1'/>
      </geometry>
    </visual>
    <visual name='base_link_fixed_joint_lump__velodyne_visual_12'>
      <origin xyz='0 0 0.086' rpy='0 -0 0'/>
      <geometry>
        <mesh filename='package://marble_hd2_sensor_config_3/meshes/VLP16_scan.dae' scale='1 1 1'/>
      </geometry>
    </visual>
    <visual name='base_link_fixed_joint_lump__velodyne_base_link_visual_13'>
      <origin xyz='-0.158 0 -0.086' rpy='3.14159 1.57079 3.14159'/>
      <geometry>
        <mesh filename='package://marble_hd2_sensor_config_3/meshes/VLP16_base_1.dae' scale='1 1 1'/>
      </geometry>
    </visual>
    <visual name='base_link_fixed_joint_lump__velodyne_base_link_visual_14'>
      <origin xyz='-0.158 0 -0.086' rpy='3.14159 1.57079 3.14159'/>
      <geometry>
        <mesh filename='package://marble_hd2_sensor_config_3/meshes/VLP16_base_2.dae' scale='1 1 1'/>
      </geometry>
    </visual>
    <visual name='base_link_fixed_joint_lump__velodyne_visual_15'>
      <origin xyz='-0.158 0 -0.086' rpy='3.14159 1.57079 3.14159'/>
      <geometry>
        <mesh filename='package://marble_hd2_sensor_config_3/meshes/VLP16_scan.dae' scale='1 1 1'/>
      </geometry>
    </visual>
    <visual name='camera_front_visual'>
      <origin xyz='0.1 0 0.013' rpy='0 -0 0'/>
      <geometry>
        <box size='0.02 0.02 0.02'/>
      </geometry>
    </visual>
    <visual name='camera_back_visual'>
      <origin xyz='-0.1 0 0.013' rpy='0 -0 0'/>
      <geometry>
        <box size='0.02 0.02 0.02'/>
      </geometry>
    </visual>
  </link>
  <sensor name='horiz_laser' update_rate='20'>
    <parent link='${robot_namespace}/sensor_head_link'/>
    <origin xyz='0 0 0.086' rpy='0 -0 0'/>
  </sensor>
  <sensor name='vert_laser' update_rate='20'>
    <parent link='${robot_namespace}/sensor_head_link'/>
    <origin xyz='-0.158 0 -0.086' rpy='3.14159 1.57079 3.14159'/>
  </sensor>
  <sensor name='camera_front' update_rate='15'>
    <parent link='${robot_namespace}/sensor_head_link'/>
    <origin xyz='0.12 0 0.013' rpy='0 -0 0'/>
    <camera>
      <image width='1280' height='960' format='R8G8B8' hfov='1.0472' near='0.01' far='300' />
    </camera>
  </sensor>
  <sensor name='camera_back' update_rate='15'>
    <parent link='${robot_namespace}/sensor_head_link'/>
    <origin xyz='-0.12 0 0.013' rpy='0 -0 3.14159'/>
    <camera>
      <image width='1280' height='960' format='R8G8B8' hfov='1.0472' near='0.01' far='300' />
    </camera>
  </sensor>
  <link name='${robot_namespace}/front_left_wheel_link'>
    <inertial>
      <origin xyz='0 0 0' rpy='0 -0 0'/>
      <mass value='1.5'/>
      <inertia ixx='0.02467' ixy='0' ixz='0' iyy='0.04411' iyz='0' izz='0.02467'/>
    </inertial>
    <collision name='front_left_wheel_link_collision'>
      <origin xyz='0 0 0' rpy='1.5708 -0 0'/>
      <geometry>
        <cylinder radius='0.129' length='0.1'/>
      </geometry>
    </collision>
  </link>
  <link name='${robot_namespace}/front_middle_left_wheel_link'>
    <inertial>
      <origin xyz='0 0 0' rpy='0 -0 0'/>
      <mass value='1.5'/>
      <inertia ixx='0.02467' ixy='0' ixz='0' iyy='0.04411' iyz='0' izz='0.02467'/>
    </inertial>
    <collision name='front_middle_left_wheel_link_collision'>
      <origin xyz='0 0 0' rpy='1.5708 -0 0'/>
      <geometry>
        <cylinder radius='0.129' length='0.1'/>
      </geometry>
    </collision>
  </link>
  <link name='${robot_namespace}/rear_middle_left_wheel_link'>
    <inertial>
      <origin xyz='0 0 0' rpy='0 -0 0'/>
      <mass value='1.5'/>
      <inertia ixx='0.02467' ixy='0' ixz='0' iyy='0.04411' iyz='0' izz='0.02467'/>
    </inertial>
    <collision name='rear_middle_left_wheel_link_collision'>
      <origin xyz='0 0 0' rpy='1.5708 -0 0'/>
      <geometry>
        <cylinder radius='0.129' length='0.1'/>
      </geometry>
    </collision>
  </link>
  <link name='${robot_namespace}/rear_left_wheel_link'>
    <inertial>
      <origin xyz='0 0 0' rpy='0 -0 0'/>
      <mass value='1.5'/>
      <inertia ixx='0.02467' ixy='0' ixz='0' iyy='0.04411' iyz='0' izz='0.02467'/>
    </inertial>
    <collision name='rear_left_wheel_link_collision'>
      <origin xyz='0 0 0' rpy='1.5708 -0 0'/>
      <geometry>
        <cylinder radius='0.1651' length='0.1143'/>
      </geometry>
    </collision>
  </link>
  <link name='${robot_namespace}/front_right_wheel_link'>
    <inertial>
      <origin xyz='0 0 0' rpy='0 -0 0'/>
      <mass value='1.5'/>
      <inertia ixx='0.02467' ixy='0' ixz='0' iyy='0.04411' iyz='0' izz='0.02467'/>
    </inertial>
    <collision name='front_right_wheel_link_collision'>
      <origin xyz='0 0 0' rpy='1.5708 -0 0'/>
      <geometry>
        <cylinder radius='0.129' length='0.1'/>
      </geometry>
    </collision>
  </link>
  <link name='${robot_namespace}/front_middle_right_wheel_link'>
    <inertial>
      <origin xyz='0 0 0' rpy='0 -0 0'/>
      <mass value='1.5'/>
      <inertia ixx='0.02467' ixy='0' ixz='0' iyy='0.04411' iyz='0' izz='0.02467'/>
    </inertial>
    <collision name='front_middle_right_wheel_link_collision'>
      <origin xyz='0 0 0' rpy='1.5708 -0 0'/>
      <geometry>
        <cylinder radius='0.129' length='0.1'/>
      </geometry>
    </collision>
  </link>
  <link name='${robot_namespace}/rear_middle_right_wheel_link'>
    <inertial>
      <origin xyz='0 0 0' rpy='0 -0 0'/>
      <mass value='1.5'/>
      <inertia ixx='0.02467' ixy='0' ixz='0' iyy='0.04411' iyz='0' izz='0.02467'/>
    </inertial>
    <collision name='rear_middle_right_wheel_link_collision'>
      <origin xyz='0 0 0' rpy='1.5708 -0 0'/>
      <geometry>
        <cylinder radius='0.129' length='0.1'/>
      </geometry>
    </collision>
  </link>
  <link name='${robot_namespace}/rear_right_wheel_link'>
    <inertial>
      <origin xyz='0 0 0' rpy='0 -0 0'/>
      <mass value='1.5'/>
      <inertia ixx='0.02467' ixy='0' ixz='0' iyy='0.04411' iyz='0' izz='0.02467'/>
    </inertial>
    <collision name='rear_right_wheel_link_collision'>
      <origin xyz='0 0 0' rpy='1.5708 -0 0'/>
      <geometry>
        <cylinder radius='0.1651' length='0.1143'/>
      </geometry>
    </collision>
  </link>
  <joint name='sensor_head_joint' type='fixed'>
    <origin xyz='0.4379 0 0.52418' rpy='0 -0 0'/>
    <parent link='${robot_namespace}/base_link'/>
    <child link='${robot_namespace}/sensor_head_link'/>
    <axis xyz='0 0 1'/>
    <limit lower='-1e+16' upper='1e+16' effort='-1' velocity='-1'/>
  </joint>
  <joint name='front_left_wheel_joint' type='revolute'>
    <origin xyz='0.36 0.26 0' rpy='0 -0 0'/>
    <parent link='${robot_namespace}/base_link'/>
    <child link='${robot_namespace}/front_left_wheel_link'/>
    <dynamics damping='0' friction='0' />
    <axis xyz='0 1 0'/>
    <limit lower='-1e+16' upper='1e+16' effort='-1' velocity='-1'/>
  </joint>
  <joint name='front_middle_left_wheel_joint' type='revolute'>
    <origin xyz='0.12 0.26 0' rpy='0 -0 0'/>
    <parent link='${robot_namespace}/base_link'/>
    <child link='${robot_namespace}/front_middle_left_wheel_link'/>
    <dynamics damping='0' friction='0' />
    <axis xyz='0 1 0'/>
    <limit lower='-1e+16' upper='1e+16' effort='-1' velocity='-1'/>
  </joint>
  <joint name='rear_middle_left_wheel_joint' type='revolute'>
    <origin xyz='-0.12 0.26 0' rpy='0 -0 0'/>
    <parent link='${robot_namespace}/base_link'/>
    <child link='${robot_namespace}/rear_middle_left_wheel_link'/>
    <dynamics damping='0' friction='0' />
    <axis xyz='0 1 0'/>
    <limit lower='-1e+16' upper='1e+16' effort='-1' velocity='-1'/>
  </joint>
  <joint name='rear_left_wheel_joint' type='revolute'>
    <origin xyz='-0.36 0.26 0' rpy='0 -0 0'/>
    <parent link='${robot_namespace}/base_link'/>
    <child link='${robot_namespace}/rear_left_wheel_link'/>
    <dynamics damping='0' friction='0' />
    <axis xyz='0 1 0'/>
    <limit lower='-1e+16' upper='1e+16' effort='-1' velocity='-1'/>
  </joint>
  <joint name='front_right_wheel_joint' type='revolute'>
    <origin xyz='0.36 -0.26 0' rpy='0 -0 0'/>
    <parent link='${robot_namespace}/base_link'/>
    <child link='${robot_namespace}/front_right_wheel_link'/>
    <dynamics damping='0' friction='0' />
    <axis xyz='0 1 0'/>
    <limit lower='-1e+16' upper='1e+16' effort='-1' velocity='-1'/>
  </joint>
  <joint name='front_middle_right_wheel_joint' type='revolute'>
    <origin xyz='0.12 -0.26 0' rpy='0 -0 0'/>
    <parent link='${robot_namespace}/base_link'/>
    <child link='${robot_namespace}/front_middle_right_wheel_link'/>
    <dynamics damping='0' friction='0' />
    <axis xyz='0 1 0'/>
    <limit lower='-1e+16' upper='1e+16' effort='-1' velocity='-1'/>
  </joint>
  <joint name='rear_middle_right_wheel_joint' type='revolute'>
    <origin xyz='-0.12 -0.26 0' rpy='0 -0 0'/>
    <parent link='${robot_namespace}/base_link'/>
    <child link='${robot_namespace}/rear_middle_right_wheel_link'/>
    <dynamics damping='0' friction='0' />
    <axis xyz='0 1 0'/>
    <limit lower='-1e+16' upper='1e+16' effort='-1' velocity='-1'/>
  </joint>
  <joint name='rear_right_wheel_joint' type='revolute'>
    <origin xyz='-0.36 -0.26 0' rpy='0 -0 0'/>
    <parent link='${robot_namespace}/base_link'/>
    <child link='${robot_namespace}/rear_right_wheel_link'/>
    <dynamics damping='0' friction='0' />
    <axis xyz='0 1 0'/>
    <limit lower='-1e+16' upper='1e+16' effort='-1' velocity='-1'/>
  </joint>
</robot>
