<?xml version="1.0"?>
<sdf version="1.6">
    <model name="canary1">
        <pose>0 0 0.051 0 0 0</pose>
        <link name="base_link">
            <pose frame="">0 0 0 0 -0 0</pose>
            <inertial>
                <pose frame="">0 0 0 0 -0 0</pose>
                <mass>1.55</mass>
                <inertia>
                    <ixx>0.025</ixx>
                    <ixy>0</ixy>
                    <ixz>0</ixz>
                    <iyy>0.009</iyy>
                    <iyz>0</iyz>
                    <izz>0.033</izz>
                </inertia>
            </inertial>
            <collision name="base_link_inertia_collision">
                <pose frame="">0 0 0.019 0 0 0</pose>
                <geometry>
                    <mesh>
                        <scale>1 1 1</scale>
                        <uri>meshes/canary1_collision.stl</uri>
                    </mesh>
                </geometry>
            </collision>
            <visual name="base_link_inertia_visual">
                <pose frame="">0 0 0 0 -0 0</pose>
                <geometry>
                    <mesh>
                        <scale>1 1 1</scale>
                        <uri>meshes/canary1_no_props.dae</uri>
                    </mesh>
                </geometry>
            </visual>
            <!-- Camera Visual -->
	    
	    <visual name="camera_front_visual">
              <pose>0.09 0.0 0.3 0 0 0</pose>
              <geometry>
		<box>
		  <size>0.01 0.03 0.03</size>
		</box>
              </geometry>
              <material>
		<ambient>0.0 0.0 0.0 1.0</ambient>
		<diffuse>0.0 0.0 0.0 1.0</diffuse>
              </material>
	    </visual>
	    <visual name="camera_lens_front_visual">
              <pose>0.1 0.0 0.3 0 1.5707963267948966 0</pose>
              <geometry>
		<cylinder>
		  <length>0.011</length>
		  <radius>0.005</radius>
		</cylinder>
              </geometry>
              <material>
		<ambient>0.0 0.0 0.0 1.0</ambient>
		<diffuse>0.0 0.0 0.0 1.0</diffuse>
              </material>
	    </visual>

	    <visual name="camera_rear_visual">
              <pose>-0.09 0 0.3 0 0 0</pose>
              <geometry>
		<box>
		  <size>0.01 0.03 0.03</size>
		</box>
              </geometry>
              <material>
		<ambient>0.0 0.0 0.0 1.0</ambient>
		<diffuse>0.0 0.0 0.0 1.0</diffuse>
              </material>
	    </visual>
	    <visual name="camera_lens_rear_visual">
              <pose>-0.1 0 0.3 0 1.5707963267948966 0</pose>
              <geometry>
		<cylinder>
		  <length>0.011</length>
		  <radius>0.005</radius>
		</cylinder>
              </geometry>
              <material>
		<ambient>0.0 0.0 0.0 1.0</ambient>
		<diffuse>0.0 0.0 0.0 1.0</diffuse>
              </material>
	    </visual>

	    <visual name="camera_left_visual">
              <pose>0 0.09 0.3 0 0 0</pose>
              <geometry>
		<box>
		  <size>0.03 0.01 0.03</size>
		</box>
              </geometry>
              <material>
		<ambient>0.0 0.0 0.0 1.0</ambient>
		<diffuse>0.0 0.0 0.0 1.0</diffuse>
              </material>
	    </visual>
	    <visual name="camera_lens_left_visual">
              <pose>0 0.1 0.3 1.5707963267948966 0 0</pose>
              <geometry>
		<cylinder>
		  <length>0.011</length>
		  <radius>0.005</radius>
		</cylinder>
              </geometry>
              <material>
		<ambient>0.0 0.0 0.0 1.0</ambient>
		<diffuse>0.0 0.0 0.0 1.0</diffuse>
              </material>
	    </visual>

	    <visual name="camera_right_visual">
              <pose>0 -0.09 0.3 0 0 0</pose>
              <geometry>
		<box>
		  <size>0.03 0.01 0.03</size>
		</box>
              </geometry>
              <material>
		<ambient>0.0 0.0 0.0 1.0</ambient>
		<diffuse>0.0 0.0 0.0 1.0</diffuse>
              </material>
	    </visual>
	    <visual name="camera_lens_right_visual">
              <pose>0 -0.1 0.3 1.5707963267948966 0 0</pose>
              <geometry>
		<cylinder>
		  <length>0.011</length>
		  <radius>0.005</radius>
		</cylinder>
              </geometry>
              <material>
		<ambient>0.0 0.0 0.0 1.0</ambient>
		<diffuse>0.0 0.0 0.0 1.0</diffuse>
              </material>
	    </visual>

	    
            <!-- Leds Visual -->
            <visual name="front_left_led">
                <pose frame="">0.38 -0.37 0.14 0 1.57079632679 -0.785398163</pose>
                <geometry>
                    <mesh>
                        <scale>0.5 0.5 0.5</scale>
                        <uri>meshes/led.dae</uri>
                    </mesh>
                </geometry>
            </visual>
            <visual name="front_right_led">
                <pose frame="">0.38 0.37 0.14 0 1.57079632679 0.785398163</pose>
                <geometry>
                    <mesh>
                        <scale>0.5 0.5 0.5</scale>
                        <uri>meshes/led.dae</uri>
                    </mesh>
                </geometry>
            </visual>
            <visual name="back_left_led">
                <pose frame="">-0.38 -0.37 0.14 0 1.57079632679 -2.35619449</pose>
                <geometry>
                    <mesh>
                        <scale>0.5 0.5 0.5</scale>
                        <uri>meshes/led.dae</uri>
                    </mesh>
                </geometry>
            </visual>
            <visual name="back_right_led">
                <pose frame="">-0.38 0.37 0.14 0 1.57079632679 2.35619449</pose>
                <geometry>
                    <mesh>
                        <scale>0.5 0.5 0.5</scale>
                        <uri>meshes/led.dae</uri>
                    </mesh>
                </geometry>
            </visual>

            <light name="front_left_flashlight_source" type="spot">
                <pose frame="">0.39 -0.38 0.14 0 1.57079632679 2.35619449</pose>
                <attenuation>
                    <range>50</range>
                    <linear>0</linear>
                    <constant>0.1</constant>
                    <quadratic>0.0025</quadratic>
                </attenuation>
                <diffuse>0.8 0.8 0.5 1</diffuse>
                <specular>0.8 0.8 0.5 1</specular>
                <spot>
                    <inner_angle>2.6</inner_angle>
                    <outer_angle>2.8</outer_angle>
                    <falloff>1</falloff>
                </spot>
                <direction>0 0 -1</direction>
                <cast_shadows>1</cast_shadows>
            </light>        

            <light name="front_right_flashlight_source" type="spot">
                <pose frame="">0.39 0.38 0.14 0 1.57079632679 -2.35619449</pose>
                <attenuation>
                    <range>50</range>
                    <linear>0</linear>
                    <constant>0.1</constant>
                    <quadratic>0.0025</quadratic>
                </attenuation>
                <diffuse>0.8 0.8 0.5 1</diffuse>
                <specular>0.8 0.8 0.5 1</specular>
                <spot>
                    <inner_angle>2.6</inner_angle>
                    <outer_angle>2.8</outer_angle>
                    <falloff>1</falloff>
                </spot>
                <direction>0 0 -1</direction>
                <cast_shadows>1</cast_shadows>
            </light>

	    
            <light name="back_left_flashlight_source" type="spot">
                <pose frame="">-0.39 -0.38 0.14 0 1.57079632679 0.785398163</pose>
                <attenuation>
                    <range>50</range>
                    <linear>0</linear>
                    <constant>0.1</constant>
                    <quadratic>0.0025</quadratic>
                </attenuation>
                <diffuse>0.8 0.8 0.5 1</diffuse>
                <specular>0.8 0.8 0.5 1</specular>
                <spot>
                    <inner_angle>2.6</inner_angle>
                    <outer_angle>2.8</outer_angle>
                    <falloff>1</falloff>
                </spot>
                <direction>0 0 -1</direction>
                <cast_shadows>1</cast_shadows>
            </light>        

            <light name="back_right_flashlight_source" type="spot">
                <pose frame="">-0.39 0.38 0.14 0 1.57079632679 -0.785398163</pose>
                <attenuation>
                    <range>50</range>
                    <linear>0</linear>
                    <constant>0.1</constant>
                    <quadratic>0.0025</quadratic>
                </attenuation>
                <diffuse>0.8 0.8 0.5 1</diffuse>
                <specular>0.8 0.8 0.5 1</specular>
                <spot>
                    <inner_angle>2.6</inner_angle>
                    <outer_angle>2.8</outer_angle>
                    <falloff>1</falloff>
                </spot>
                <direction>0 0 -1</direction>
                <cast_shadows>1</cast_shadows>
            </light>

            <sensor name="imu_sensor" type="imu">
                <always_on>1</always_on>
                <update_rate>250</update_rate>
                <imu>
                    <angular_velocity>
                        <x>
                            <noise type="gaussian">
                                <mean>0</mean>
                                <stddev>0.009</stddev>
                                <bias_mean>0.00075</bias_mean>
                                <bias_stddev>0.005</bias_stddev>
                                <dynamic_bias_stddev>0.00002</dynamic_bias_stddev>
                                <dynamic_bias_correlation_time>400.0</dynamic_bias_correlation_time>
                                <precision>0.00025</precision>
                            </noise>
                        </x>
                        <y>
                            <noise type="gaussian">
                                <mean>0</mean>
                                <stddev>0.009</stddev>
                                <bias_mean>0.00075</bias_mean>
                                <bias_stddev>0.005</bias_stddev>
                                <dynamic_bias_stddev>0.00002</dynamic_bias_stddev>
                                <dynamic_bias_correlation_time>400.0</dynamic_bias_correlation_time>
                                <precision>0.00025</precision>
                            </noise>
                        </y>
                        <z>
                            <noise type="gaussian">
                                <mean>0</mean>
                                <stddev>0.009</stddev>
                                <bias_mean>0.00075</bias_mean>
                                <bias_stddev>0.005</bias_stddev>
                                <dynamic_bias_stddev>0.00002</dynamic_bias_stddev>
                                <dynamic_bias_correlation_time>400.0</dynamic_bias_correlation_time>
                                <precision>0.00025</precision>
                            </noise>
                        </z>
                    </angular_velocity>
                    <linear_acceleration>
                        <x>
                            <noise type="gaussian">
                                <mean>0</mean>
                                <stddev>0.021</stddev>
                                <bias_mean>0.05</bias_mean>
                                <bias_stddev>0.0075</bias_stddev>
                                <dynamic_bias_stddev>0.000375</dynamic_bias_stddev>
                                <dynamic_bias_correlation_time>175.0</dynamic_bias_correlation_time>
                                <precision>0.005</precision>
                            </noise>
                        </x>
                        <y>
                            <noise type="gaussian">
                                <mean>0</mean>
                                <stddev>0.021</stddev>
                                <bias_mean>0.05</bias_mean>
                                <bias_stddev>0.0075</bias_stddev>
                                <dynamic_bias_stddev>0.000375</dynamic_bias_stddev>
                                <dynamic_bias_correlation_time>175.0</dynamic_bias_correlation_time>
                                <precision>0.005</precision>
                            </noise>
                        </y>
                        <z>
                            <noise type="gaussian">
                                <mean>0</mean>
                                <stddev>0.021</stddev>
                                <bias_mean>0.05</bias_mean>
                                <bias_stddev>0.0075</bias_stddev>
                                <dynamic_bias_stddev>0.000375</dynamic_bias_stddev>
                                <dynamic_bias_correlation_time>175.0</dynamic_bias_correlation_time>
                                <precision>0.005</precision>
                            </noise>
                        </z>
                    </linear_acceleration>
                </imu>
            </sensor>
            <sensor name="air_pressure" type="air_pressure">
                <always_on>1</always_on>
                <update_rate>20</update_rate>
                <air_pressure>
                    <reference_altitude>0</reference_altitude>
                    <noise type="gaussian">
                        <mean>0.00000008</mean>
                    </noise>
                </air_pressure>
            </sensor>
            <sensor name="magnetometer" type="magnetometer">
                <always_on>1</always_on>
                <update_rate>20</update_rate>
                <magnetometer>
                    <x>
                        <noise type="gaussian">
                            <mean>0.000000080</mean>
                            <bias_mean>0.000000400</bias_mean>
                        </noise>
                    </x>
                    <y>
                        <noise type="gaussian">
                            <mean>0.000000080</mean>
                            <bias_mean>0.000000400</bias_mean>
                        </noise>
                    </y>
                    <z>
                        <noise type="gaussian">
                            <mean>0.000000080</mean>
                            <bias_mean>0.000000400</bias_mean>
                        </noise>
                    </z>
                </magnetometer>
            </sensor>
            

	    <!-- Camera Sensors -->
	    <sensor name="camera_front" type="camera">
              <pose>0.11 0.0 0.3 0 0 0</pose>
              <always_on>1</always_on>
              <update_rate>25</update_rate>
              <camera name="camera_front">
		<horizontal_fov>1.658</horizontal_fov>
		<lens>
		  <intrinsics>
		    <!-- fx = fy = width / ( 2 * tan (hfov / 2 ) ) -->
		    <fx>329.9</fx>
		    <fy>329.9</fy>
		    <!-- cx = ( width - 1 ) / 2 -->
		    <cx>359.5</cx>
		    <!-- cy = ( height - 1 ) / 2 -->
		    <cy>539.5</cy>
		    <s>0</s>
		  </intrinsics>
		</lens>
		<distortion>
		  <k1>0.0</k1>
		  <k2>0.0</k2>
		  <k3>0.0</k3>
		  <p1>0.0</p1>
		  <p2>0.0</p2>
		  <center>0.5 0.5</center>
		</distortion>
		<image>
		  <width>720</width>
		  <height>1080</height>
		  <format>R8G8B8</format>
		</image>
		<clip>
		  <near>0.01</near>
		  <far>300</far>
		</clip>
		<noise>
		  <type>gaussian</type>
		  <mean>0</mean>
		  <stddev>0.007</stddev>
		</noise>
              </camera>
	    </sensor>

	    <sensor name="camera_rear" type="camera">
              <pose>-0.11 0 0.3 0 0 3.141592653589793</pose>
              <always_on>1</always_on>
              <update_rate>25</update_rate>
              <camera name="camera_front">
		<horizontal_fov>1.658</horizontal_fov>
		<lens>
		  <intrinsics>
		    <!-- fx = fy = width / ( 2 * tan (hfov / 2 ) ) -->
		    <fx>329.9</fx>
		    <fy>329.9</fy>
		    <!-- cx = ( width - 1 ) / 2 -->
		    <cx>359.5</cx>
		    <!-- cy = ( height - 1 ) / 2 -->
		    <cy>539.5</cy>
		    <s>0</s>
		  </intrinsics>
		</lens>
		<distortion>
		  <k1>0.0</k1>
		  <k2>0.0</k2>
		  <k3>0.0</k3>
		  <p1>0.0</p1>
		  <p2>0.0</p2>
		  <center>0.5 0.5</center>
		</distortion>
		<image>
		  <width>720</width>
		  <height>1080</height>
		  <format>R8G8B8</format>
		</image>
		<clip>
		  <near>0.01</near>
		  <far>300</far>
		</clip>
		<noise>
		  <type>gaussian</type>
		  <mean>0</mean>
		  <stddev>0.007</stddev>
		</noise>
              </camera>
	    </sensor>

	    <sensor name="camera_left" type="camera">
              <pose>0 0.11 0.3 0 0 1.5707963267948966</pose>
              <always_on>1</always_on>
              <update_rate>25</update_rate>
              <camera name="camera_front">
		<horizontal_fov>1.658</horizontal_fov>
		<lens>
		  <intrinsics>
		    <!-- fx = fy = width / ( 2 * tan (hfov / 2 ) ) -->
		    <fx>329.9</fx>
		    <fy>329.9</fy>
		    <!-- cx = ( width - 1 ) / 2 -->
		    <cx>359.5</cx>
		    <!-- cy = ( height - 1 ) / 2 -->
		    <cy>539.5</cy>
		    <s>0</s>
		  </intrinsics>
		</lens>
		<distortion>
		  <k1>0.0</k1>
		  <k2>0.0</k2>
		  <k3>0.0</k3>
		  <p1>0.0</p1>
		  <p2>0.0</p2>
		  <center>0.5 0.5</center>
		</distortion>
		<image>
		  <width>720</width>
		  <height>1080</height>
		  <format>R8G8B8</format>
		</image>
		<clip>
		  <near>0.01</near>
		  <far>300</far>
		</clip>
		<noise>
		  <type>gaussian</type>
		  <mean>0</mean>
		  <stddev>0.007</stddev>
		</noise>
              </camera>
	    </sensor>

	    <sensor name="camera_right" type="camera">
              <pose>0 -0.11 0.3 0 0 -1.5707963267948966</pose>
              <always_on>1</always_on>
              <update_rate>25</update_rate>
              <camera name="camera_front">
		<horizontal_fov>1.658</horizontal_fov>
		<lens>
		  <intrinsics>
		    <!-- fx = fy = width / ( 2 * tan (hfov / 2 ) ) -->
		    <fx>329.9</fx>
		    <fy>329.9</fy>
		    <!-- cx = ( width - 1 ) / 2 -->
		    <cx>359.5</cx>
		    <!-- cy = ( height - 1 ) / 2 -->
		    <cy>539.5</cy>
		    <s>0</s>
		  </intrinsics>
		</lens>
		<distortion>
		  <k1>0.0</k1>
		  <k2>0.0</k2>
		  <k3>0.0</k3>
		  <p1>0.0</p1>
		  <p2>0.0</p2>
		  <center>0.5 0.5</center>
		</distortion>
		<image>
		  <width>720</width>
		  <height>1080</height>
		  <format>R8G8B8</format>
		</image>
		<clip>
		  <near>0.01</near>
		  <far>300</far>
		</clip>
		<noise>
		  <type>gaussian</type>
		  <mean>0</mean>
		  <stddev>0.007</stddev>
		</noise>
              </camera>
	    </sensor>


            <visual name="laser_visual_base1">
                <pose>0 0 0.33 0 0 0</pose>
                <geometry>
                    <mesh>
                        <scale>1 1 1</scale>
                        <uri>meshes/VLP16_base_1.dae</uri>
                    </mesh>
                </geometry>
            </visual>
            <visual name="laser_visual_base2">
                <pose>0 0 0.33 0 0 0</pose>
                <geometry>
                    <mesh>
                        <scale>1 1 1</scale>
                        <uri>meshes/VLP16_base_2.dae</uri>
                    </mesh>
                </geometry>
            </visual>
            <visual name="laser_visual_scan">
                <pose>0 0 0.33 0 0 0</pose>
                <geometry>
                    <mesh>
                        <scale>1 1 1</scale>
                        <uri>meshes/VLP16_scan.dae</uri>
                    </mesh>
                </geometry>
            </visual>

            <sensor name="front_laser" type="gpu_lidar">
                <pose>0 0 0.33 5e-06 0 0 -0 0</pose>
                <always_on>1</always_on>
                <update_rate>10</update_rate>
                <ray>
                    <scan>
                        <horizontal>
                        <samples>1800</samples>
                        <resolution>1</resolution>
                        <min_angle>-3.14159</min_angle>
                        <max_angle>3.14159</max_angle>
                        </horizontal>
                        <vertical>
                        <samples>16</samples>
                        <resolution>1</resolution>
                        <min_angle>-0.261799</min_angle>
                        <max_angle>0.261799</max_angle>
                        </vertical>
                    </scan>
                    <range>
                        <min>0.05</min>
                        <max>100</max>
                    </range>
                    <noise>
                        <type>gaussian</type>
                        <mean>0</mean>
                        <stddev>0.01</stddev>
                    </noise>
                </ray>    
            </sensor>
	    <!--
	    <visual name="up_laser_visual_base1">
              <pose>-0.11 0 0.24 0 -1.5708 0</pose>
              <geometry>
                <mesh>
                  <scale>1 1 1</scale>
                  <uri>meshes/VLP16_base_1.dae</uri>
                </mesh>
              </geometry>
            </visual>
            <visual name="up_laser_visual_base2">
              <pose>-0.11 0 0.24 0 -1.5708 0</pose>
              <geometry>
                <mesh>
                  <scale>1 1 1</scale>
                  <uri>meshes/VLP16_base_2.dae</uri>
                </mesh>
              </geometry>
            </visual>
            <visual name="up_laser_visual_scan">
              <pose>-0.11 0 0.24 0 -1.5708 0</pose>
              <geometry>
                <mesh>
                  <scale>1 1 1</scale>
                  <uri>meshes/VLP16_scan.dae</uri>
                </mesh>
              </geometry>
            </visual>
	    -->

	    <visual name="up_laser_visual_ouster">
	      <pose>-0.11 0 0.24 0 -1.5708 0</pose>
              <geometry>
		<mesh>
		  <uri>meshes/ouster-os0.dae</uri>
		</mesh>
              </geometry>
	    </visual>
	    
	    <sensor name="up_laser" type="gpu_lidar">
                <pose>-0.11 0 0.24 0 -1.5708 0</pose> <!-- 0 1.5708 3.14159 -->
                <always_on>1</always_on>
                <update_rate>10</update_rate>
                <ray>
                    <scan>
                        <horizontal>
                        <samples>2048</samples>
                        <resolution>1</resolution>
                        <min_angle>-3.14159</min_angle>
                        <max_angle>3.14159</max_angle>
                        </horizontal>
                        <vertical>
                        <samples>128</samples>
                        <resolution>1</resolution>
                        <min_angle>-0.785398</min_angle>
                        <max_angle>0.785398</max_angle>
                        </vertical>
                    </scan>
                    <range>
                        <min>0.1</min>
                        <max>50</max>
                    </range>
                    <noise>
                        <type>gaussian</type>
                        <mean>0</mean>
                        <stddev>0.01</stddev>
                    </noise>
                </ray>    
            </sensor>
        </link>

        <link name="rotor_0">
            <pose frame="">0.23 -0.23 0.123 0 -0 0</pose>
            <inertial>
                <pose frame="">0 0 0 0 -0 0</pose>
                <mass>0.005</mass>
                <inertia>
                    <ixx>9.75e-07</ixx>
                    <ixy>0</ixy>
                    <ixz>0</ixz>
                    <iyy>4.17041e-05</iyy>
                    <iyz>0</iyz>
                    <izz>4.26041e-05</izz>
                </inertia>
            </inertial>
            <visual name="rotor_0_visual">
                <pose frame="">0 0 0 0 -0 0</pose>
                <geometry>
                    <mesh>
                        <scale>0.15 0.15 0.15</scale>
                        <uri>meshes/propeller_ccw.dae</uri>
                    </mesh>
                </geometry>
                <material>
                    <diffuse>0 0 0 1</diffuse>
                    <script>
                        <name>Gazebo/Black</name>
                        <uri>file://media/materials/scripts/gazebo.material</uri>
                    </script>
                </material>
                <cast_shadows>0</cast_shadows>
            </visual>
            <gravity>1</gravity>
            <velocity_decay/>
        </link>
        <joint name="rotor_0_joint" type="revolute">
            <child>rotor_0</child>
            <parent>base_link</parent>
            <axis>
                <xyz>0 0 1</xyz>
                <limit>
                    <lower>-1e+16</lower>
                    <upper>1e+16</upper>
                </limit>
                <dynamics>
                    <spring_reference>0</spring_reference>
                    <spring_stiffness>0</spring_stiffness>
                </dynamics>
                <use_parent_model_frame>1</use_parent_model_frame>
            </axis>
        </joint>

        <link name="rotor_1">
            <pose frame="">-0.23 0.23 0.123 0 -0 0</pose>
            <inertial>
                <pose frame="">0 0 0 0 -0 0</pose>
                <mass>0.005</mass>
                <inertia>
                    <ixx>9.75e-07</ixx>
                    <ixy>0</ixy>
                    <ixz>0</ixz>
                    <iyy>4.17041e-05</iyy>
                    <iyz>0</iyz>
                    <izz>4.26041e-05</izz>
                </inertia>
            </inertial>
            <visual name="rotor_1_visual">
                <pose frame="">0 0 0 0 -0 0</pose>
                <geometry>
                    <mesh>
                        <scale>0.15 0.15 0.15</scale>
                        <uri>meshes/propeller_ccw.dae</uri>
                    </mesh>
                </geometry>
                <material>
                    <diffuse>0 0 0 1</diffuse>
                    <script>
                        <name>Gazebo/Black</name>
                        <uri>file://media/materials/scripts/gazebo.material</uri>
                    </script>
                </material>
                <cast_shadows>0</cast_shadows>
            </visual>
            <gravity>1</gravity>
            <velocity_decay/>
        </link>
        <joint name="rotor_1_joint" type="revolute">
            <child>rotor_1</child>
            <parent>base_link</parent>
            <axis>
                <xyz>0 0 1</xyz>
                <limit>
                    <lower>-1e+16</lower>
                    <upper>1e+16</upper>
                </limit>
                <dynamics>
                    <spring_reference>0</spring_reference>
                    <spring_stiffness>0</spring_stiffness>
                </dynamics>
                <use_parent_model_frame>1</use_parent_model_frame>
            </axis>
        </joint>
        
        <link name="rotor_2">
            <pose frame="">0.23 0.23 0.123 0 -0 0</pose>
            <inertial>
                <pose frame="">0 0 0 0 -0 0</pose>
                <mass>0.005</mass>
                <inertia>
                    <ixx>9.75e-07</ixx>
                    <ixy>0</ixy>
                    <ixz>0</ixz>
                    <iyy>4.17041e-05</iyy>
                    <iyz>0</iyz>
                    <izz>4.26041e-05</izz>
                </inertia>
            </inertial>
            <visual name="rotor_2_visual">
                <pose frame="">0 0 0 0 -0 0</pose>
                <geometry>
                    <mesh>
                        <scale>0.15 0.15 0.15</scale>
                        <uri>meshes/propeller_cw.dae</uri>
                    </mesh>
                </geometry>
                <material>
                    <diffuse>0 0 0 1</diffuse>
                    <script>
                        <name>Gazebo/Black</name>
                        <uri>file://media/materials/scripts/gazebo.material</uri>
                    </script>
                </material>
                <cast_shadows>0</cast_shadows>
            </visual>
            <gravity>1</gravity>
            <velocity_decay/>
        </link>
        <joint name="rotor_2_joint" type="revolute">
            <child>rotor_2</child>
            <parent>base_link</parent>
            <axis>
                <xyz>0 0 1</xyz>
                <limit>
                    <lower>-1e+16</lower>
                    <upper>1e+16</upper>
                </limit>
                <dynamics>
                    <spring_reference>0</spring_reference>
                    <spring_stiffness>0</spring_stiffness>
                </dynamics>
                <use_parent_model_frame>1</use_parent_model_frame>
            </axis>
        </joint>

        <link name="rotor_3">
            <pose frame="">-0.23 -0.23 0.123 0 -0 0</pose>
            <inertial>
                <pose frame="">0 0 0 0 -0 0</pose>
                <mass>0.005</mass>
                <inertia>
                    <ixx>9.75e-07</ixx>
                    <ixy>0</ixy>
                    <ixz>0</ixz>
                    <iyy>4.17041e-05</iyy>
                    <iyz>0</iyz>
                    <izz>4.26041e-05</izz>
                </inertia>
            </inertial>
            <visual name="rotor_3_visual">
                <pose frame="">0 0 0 0 -0 0</pose>
                <geometry>
                    <mesh>
                        <scale>0.15 0.15 0.15</scale>
                        <uri>meshes/propeller_cw.dae</uri>
                    </mesh>
                </geometry>
                <material>
                    <diffuse>0 0 0 1</diffuse>
                    <script>
                        <name>Gazebo/Black</name>
                        <uri>file://media/materials/scripts/gazebo.material</uri>
                    </script>
                </material>
                <cast_shadows>0</cast_shadows>
            </visual>
            <gravity>1</gravity>
            <velocity_decay/>
        </link>
        <joint name="rotor_3_joint" type="revolute">
            <child>rotor_3</child>
            <parent>base_link</parent>
            <axis>
                <xyz>0 0 1</xyz>
                <limit>
                    <lower>-1e+16</lower>
                    <upper>1e+16</upper>
                </limit>
                <dynamics>
                    <spring_reference>0</spring_reference>
                    <spring_stiffness>0</spring_stiffness>
                </dynamics>
                <use_parent_model_frame>1</use_parent_model_frame>
            </axis>
        </joint>

    </model>
</sdf>
