<?xml version="1.0"?>
<sdf version="1.6">
    <model name="ROBOTIKA_X2">
        <pose>0 0 0.063494 0 0 0</pose>
        <enable_wind>1</enable_wind>
        <link name="base_link">
            <inertial>
                <pose>0.011999 0.002 0.066996 0 -0 0</pose>
                <mass>16.524</mass>
                <inertia>
                    <ixx>0.320605</ixx>
                    <ixy>-0.000800023</ixy>
                    <ixz>0.0163992</ixz>
                    <iyy>0.399205</iyy>
                    <iyz>-0.000900133</iyz>
                    <izz>0.455501</izz>
                </inertia>
            </inertial>
            <collision name="chassis_collision">
                <pose>0 0 0.092 0 -0 0</pose>
                <geometry>
                    <box>
                        <size>0.42 0.31 0.184</size>
                    </box>
                </geometry>
            </collision>
            <visual name="chassis_visual">
                <pose>0 0 -0.0655 1.5708 0 -1.5708</pose>
                <geometry>
                    <mesh>
                        <uri>meshes/x2_chassis.dae</uri>
                    </mesh>
                </geometry>
            </visual>
            <visual name="navsat_visual_1">
                <pose>-0.18 0.126 0.1895 0 -0 0</pose>
                <geometry>
                    <cylinder>
                        <length>0.016</length>
                        <radius>0.026</radius>
                    </cylinder>
                </geometry>
            </visual>
            <visual name="center_left_headlight_visual">
                <pose>0.22 0.05 0.0845 0 -0 -3.14159</pose>
                <geometry>
                    <mesh>
                        <uri>meshes/headlight.dae</uri>
                    </mesh>
                </geometry>
            </visual>
            <visual name="left_headlight_visual">
                <pose>0.22 0.145 0.0845 0 -0 -3.14159</pose>
                <geometry>
                    <mesh>
                        <uri>meshes/headlight.dae</uri>
                    </mesh>
                </geometry>
            </visual>
            <visual name="center_right_headlight_visual">
                <pose>0.22 -0.05 0.0845 0 -0 -3.14159</pose>
                <geometry>
                    <mesh>
                        <uri>meshes/headlight.dae</uri>
                    </mesh>
                </geometry>
            </visual>
            <visual name="right_headlight_visual">
                <pose>0.22 -0.145 0.0845 0 -0 -3.14159</pose>
                <geometry>
                    <mesh>
                        <uri>meshes/headlight.dae</uri>
                    </mesh>
                </geometry>
            </visual>

            <light name="left_light_source" type="spot">
                <pose>0.273 0.145 0.141 3.14159 1.56859 0</pose>
                <attenuation>
                    <range>25</range>
                    <linear>0</linear>
                    <constant>0.1</constant>
                    <quadratic>0.005</quadratic>
                </attenuation>
                <diffuse>0.8 0.8 0.5 1</diffuse>
                <specular>0.8 0.8 0.5 1</specular>
                <spot>
                    <inner_angle>1</inner_angle>
                    <outer_angle>1.1</outer_angle>
                    <falloff>1</falloff>
                </spot>
                <direction>0 0 -1</direction>
                <cast_shadows>1</cast_shadows>
            </light>

            <light name="right_light_source" type="spot">
                <pose>0.273 -0.145 0.141 3.14159 1.56859 0</pose>
                <attenuation>
                    <range>25</range>
                    <linear>0</linear>
                    <constant>0.1</constant>
                    <quadratic>0.005</quadratic>
                </attenuation>
                <diffuse>0.8 0.8 0.5 1</diffuse>
                <specular>0.8 0.8 0.5 1</specular>
                <spot>
                    <inner_angle>1</inner_angle>
                    <outer_angle>1.1</outer_angle>
                    <falloff>1</falloff>
                </spot>
                <direction>0 0 -1</direction>
                <cast_shadows>1</cast_shadows>
            </light>

            <light name="center_left_light_source" type="spot">
                <pose>0.273 0.05 0.141 3.14159 1.56859 0</pose>
                <attenuation>
                    <range>25</range>
                    <linear>0</linear>
                    <constant>0.1</constant>
                    <quadratic>0.005</quadratic>
                </attenuation>
                <diffuse>0.8 0.8 0.5 1</diffuse>
                <specular>0.8 0.8 0.5 1</specular>
                <spot>
                    <inner_angle>1</inner_angle>
                    <outer_angle>1.1</outer_angle>
                    <falloff>1</falloff>
                </spot>
                <direction>0 0 -1</direction>
                <cast_shadows>1</cast_shadows>
            </light>

            <light name="center_right_light_source" type="spot">
                <pose>0.273 -0.05 0.141 3.14159 1.56859 0</pose>
                <attenuation>
                    <range>25</range>
                    <linear>0</linear>
                    <constant>0.1</constant>
                    <quadratic>0.005</quadratic>
                </attenuation>
                <diffuse>0.8 0.8 0.5 1</diffuse>
                <specular>0.8 0.8 0.5 1</specular>
                <spot>
                    <inner_angle>1</inner_angle>
                    <outer_angle>1.1</outer_angle>
                    <falloff>1</falloff>
                </spot>
                <direction>0 0 -1</direction>
                <cast_shadows>1</cast_shadows>
            </light>
            <sensor name="imu_sensor" type="imu">
                <always_on>1</always_on>
                <update_rate>50</update_rate>
                <imu>
                    <angular_velocity>
                        <x>
                            <noise type="gaussian">
                                <mean>0</mean>
                                <stddev>0.009</stddev>
                                <bias_mean>0.00075</bias_mean>
                                <bias_stddev>0.005</bias_stddev>
                                <dynamic_bias_stddev>0.00002</dynamic_bias_stddev>
                                <dynamic_bias_correlation_time>400.0</dynamic_bias_correlation_time>
                                <precision>0.00025</precision>
                            </noise>
                        </x>
                        <y>
                            <noise type="gaussian">
                                <mean>0</mean>
                                <stddev>0.009</stddev>
                                <bias_mean>0.00075</bias_mean>
                                <bias_stddev>0.005</bias_stddev>
                                <dynamic_bias_stddev>0.00002</dynamic_bias_stddev>
                                <dynamic_bias_correlation_time>400.0</dynamic_bias_correlation_time>
                                <precision>0.00025</precision>
                            </noise>
                        </y>
                        <z>
                            <noise type="gaussian">
                                <mean>0</mean>
                                <stddev>0.009</stddev>
                                <bias_mean>0.00075</bias_mean>
                                <bias_stddev>0.005</bias_stddev>
                                <dynamic_bias_stddev>0.00002</dynamic_bias_stddev>
                                <dynamic_bias_correlation_time>400.0</dynamic_bias_correlation_time>
                                <precision>0.00025</precision>
                            </noise>
                        </z>
                    </angular_velocity>
                    <linear_acceleration>
                        <x>
                            <noise type="gaussian">
                                <mean>0</mean>
                                <stddev>0.021</stddev>
                                <bias_mean>0.05</bias_mean>
                                <bias_stddev>0.0075</bias_stddev>
                                <dynamic_bias_stddev>0.000375</dynamic_bias_stddev>
                                <dynamic_bias_correlation_time>175.0</dynamic_bias_correlation_time>
                                <precision>0.005</precision>
                            </noise>
                        </x>
                        <y>
                            <noise type="gaussian">
                                <mean>0</mean>
                                <stddev>0.021</stddev>
                                <bias_mean>0.05</bias_mean>
                                <bias_stddev>0.0075</bias_stddev>
                                <dynamic_bias_stddev>0.000375</dynamic_bias_stddev>
                                <dynamic_bias_correlation_time>175.0</dynamic_bias_correlation_time>
                                <precision>0.005</precision>
                            </noise>
                        </y>
                        <z>
                            <noise type="gaussian">
                                <mean>0</mean>
                                <stddev>0.021</stddev>
                                <bias_mean>0.05</bias_mean>
                                <bias_stddev>0.0075</bias_stddev>
                                <dynamic_bias_stddev>0.000375</dynamic_bias_stddev>
                                <dynamic_bias_correlation_time>175.0</dynamic_bias_correlation_time>
                                <precision>0.005</precision>
                            </noise>
                        </z>
                    </linear_acceleration>
                </imu>
            </sensor>

            <visual name="camera_visual">
                <pose>0.23 0 0.19 0 0 0</pose>
                <geometry>
                    <box>
                        <size>0.02 0.02 0.02</size>
                    </box>
                </geometry>
            </visual>
            <sensor name="camera_front" type="rgbd_camera">
                <pose>0.23 0 0.19 0 0 0</pose>
                <always_on>1</always_on>
                <update_rate>20</update_rate>
                <camera name="camera_front">
                    <!--<cameraInfoTopicName>camera_info</cameraInfoTopicName>-->
                    <!--<hackBaseline>0.07</hackBaseline>-->
                    <pose frame="">0 0 0 0 -1.5707 1.5707</pose>
                    <horizontal_fov>1.2113</horizontal_fov>
                    <lens>
                        <intrinsics>
                          <!-- fx = fy = width / ( 2 * tan (hfov / 2 ) ) -->
                          <fx>462.1</fx>
                          <fy>462.1</fy>
                          <!-- cx = ( width + 1 ) / 2 -->
                          <cx>320.5</cx>
                          <!-- cy = ( height + 1 ) / 2 -->
                          <cy>180.5</cy>
                          <s>0</s>
                        </intrinsics>
                    </lens>
                    <distortion>
                        <k1>0.0</k1>
                        <k2>0.0</k2>
                        <k3>0.0</k3>
                        <p1>0.0</p1>
                        <p2>0.0</p2>
                        <center>0.5 0.5</center>
                    </distortion>
                    <image>
                        <width>640</width>
                        <height>360</height>
                        <format>R8G8B8</format>
                    </image>
                    <clip>
                        <near>0.01</near>
                        <far>300</far>
                    </clip>
                    <depth_camera>
                      <clip>
                        <near>0.1</near>
                        <far>10</far>
                      </clip>
                    </depth_camera>
                    <noise>
                        <type>gaussian</type>
                        <mean>0</mean>
                        <stddev>0.007</stddev>
                    </noise>
                </camera>
            </sensor>
            <visual name="laser_visual">
                <pose>0.0 0 0.23 0 -0 0</pose>
                <geometry>
                    <cylinder>
                        <radius>0.03</radius>
                        <length>0.1</length>
                    </cylinder>
                </geometry>
            </visual>
            <sensor name="front_laser" type="gpu_ray">
                <pose>0.0 0 0.23 0 -0 0</pose>
                <update_rate>20</update_rate>
                <lidar>
                    <scan>
                        <horizontal>
                            <samples>720</samples>
                            <resolution>1</resolution>
                            <min_angle>-2.3562</min_angle>
                            <max_angle>2.3562</max_angle>
                        </horizontal>
                    </scan>
                    <range>
                        <min>0.04</min>
                        <max>30</max>
                        <resolution>0.01</resolution>
                    </range>
                    <noise>
                        <type>gaussian</type>
                        <mean>0</mean>
                        <stddev>0.01</stddev>
                    </noise>
                </lidar>
            </sensor>
        </link>

        <link name="front_left_wheel">
            <pose>0.131 0.187795 0.0345 0 -0 0</pose>
            <inertial>
                <mass>0.477</mass>
                <inertia>
                    <ixx>0.0013</ixx>
                    <ixy>0</ixy>
                    <ixz>0</ixz>
                    <iyy>0.0024</iyy>
                    <iyz>0</iyz>
                    <izz>0.0013</izz>
                </inertia>
            </inertial>
            <collision name="collision">
                <pose>0 0 0 1.5707963267948966 -0 0</pose>
                <geometry>
                    <cylinder>
                        <length>0.04</length>
                        <radius>0.098</radius>
                    </cylinder>
                </geometry>
                <surface>
                  <friction>
                    <ode>
                      <mu>1</mu>
                      <mu2>1</mu2>
                      <slip1>0.0026</slip1>
                      <slip2>0</slip2>
                      <fdir1>0 0 1</fdir1>
                    </ode>
                  </friction>
                </surface>
            </collision>
            <visual name="visual">
                <pose>0 0 0 1.5708 -0 0</pose>
                <geometry>
                    <mesh>
                        <uri>meshes/x2_wheel_left.dae</uri>
                    </mesh>
                </geometry>
            </visual>
        </link>

        <link name="front_right_wheel">
            <pose>0.131 -0.187795 0.0345 0 -0 0</pose>
            <inertial>
                <mass>0.477</mass>
                <inertia>
                    <ixx>0.0013</ixx>
                    <ixy>0</ixy>
                    <ixz>0</ixz>
                    <iyy>0.0024</iyy>
                    <iyz>0</iyz>
                    <izz>0.0013</izz>
                </inertia>
            </inertial>
            <collision name="collision">
                <pose>0 0 0 1.5707963267948966 -0 0</pose>
                <geometry>
                    <cylinder>
                        <length>0.04</length>
                        <radius>0.098</radius>
                    </cylinder>
                </geometry>
                <surface>
                  <friction>
                    <ode>
                      <mu>1</mu>
                      <mu2>1</mu2>
                      <slip1>0.0026</slip1>
                      <slip2>0</slip2>
                      <fdir1>0 0 1</fdir1>
                    </ode>
                  </friction>
                </surface>
            </collision>
            <visual name="visual">
                <pose>0 0 0 1.5708 -0 0</pose>
                <geometry>
                    <mesh>
                        <uri>meshes/x2_wheel_right.dae</uri>
                    </mesh>
                </geometry>
            </visual>
        </link>

        <link name="rear_left_wheel">
            <pose>-0.131 0.187795 0.0345 0 -0 0</pose>
            <inertial>
                <mass>0.477</mass>
                <inertia>
                    <ixx>0.0013</ixx>
                    <ixy>0</ixy>
                    <ixz>0</ixz>
                    <iyy>0.0024</iyy>
                    <iyz>0</iyz>
                    <izz>0.0013</izz>
                </inertia>
            </inertial>
            <collision name="collision">
                <pose>0 0 0 1.5707963267948966 -0 0</pose>
                <geometry>
                    <cylinder>
                        <length>0.04</length>
                        <radius>0.098</radius>
                    </cylinder>
                </geometry>
                <surface>
                  <friction>
                    <ode>
                      <mu>1</mu>
                      <mu2>1</mu2>
                      <slip1>0.0026</slip1>
                      <slip2>0</slip2>
                      <fdir1>0 0 1</fdir1>
                    </ode>
                  </friction>
                </surface>
            </collision>
            <visual name="visual">
                <pose>0 0 0 1.5708 -0 0</pose>
                <geometry>
                    <mesh>
                        <uri>meshes/x2_wheel_left.dae</uri>
                    </mesh>
                </geometry>
            </visual>
        </link>

        <link name="rear_right_wheel">
            <pose>-0.131 -0.187795 0.0345 0 -0 0</pose>
            <inertial>
                <mass>0.477</mass>
                <inertia>
                    <ixx>0.0013</ixx>
                    <ixy>0</ixy>
                    <ixz>0</ixz>
                    <iyy>0.0024</iyy>
                    <iyz>0</iyz>
                    <izz>0.0013</izz>
                </inertia>
            </inertial>
            <collision name="collision">
                <pose>0 0 0 1.5707963267948966 -0 0</pose>
                <geometry>
                    <cylinder>
                        <length>0.04</length>
                        <radius>0.098</radius>
                    </cylinder>
                </geometry>
                <surface>
                  <friction>
                    <ode>
                      <mu>1</mu>
                      <mu2>1</mu2>
                      <slip1>0.0026</slip1>
                      <slip2>0</slip2>
                      <fdir1>0 0 1</fdir1>
                    </ode>
                  </friction>
                </surface>
            </collision>
            <visual name="visual">
                <pose>0 0 0 1.5708 -0 0</pose>
                <geometry>
                    <mesh>
                        <uri>meshes/x2_wheel_right.dae</uri>
                    </mesh>
                </geometry>
            </visual>
        </link>

        <joint name="front_left_wheel_joint" type="revolute">
            <child>front_left_wheel</child>
            <parent>base_link</parent>
            <axis>
                <xyz>0 1 0</xyz>
                <limit>
                    <lower>-1e+16</lower>
                    <upper>1e+16</upper>
                </limit>
                <use_parent_model_frame>1</use_parent_model_frame>
            </axis>
        </joint>

        <joint name="rear_left_wheel_joint" type="revolute">
            <parent>base_link</parent>
            <child>rear_left_wheel</child>
            <axis>
                <xyz>0 1 0</xyz>
                <limit>
                    <lower>-1.79769e+308</lower>
                    <upper>+1.79769e+308</upper>
                </limit>
            </axis>
        </joint>

        <joint name="rear_right_wheel_joint" type="revolute">
            <parent>base_link</parent>
            <child>rear_right_wheel</child>
            <axis>
                <xyz>0 1 0</xyz>
                <limit>
                    <lower>-1.79769e+308</lower>
                    <upper>+1.79769e+308</upper>
                </limit>
            </axis>
        </joint>

        <joint name="front_right_wheel_joint" type="revolute">
            <parent>base_link</parent>
            <child>front_right_wheel</child>
            <axis>
                <xyz>0 1 0</xyz>
                <limit>
                    <lower>-1.79769e+308</lower>
                    <upper>+1.79769e+308</upper>
                </limit>
            </axis>
        </joint>
    </model>
</sdf>
