<?xml version='1.0' encoding='utf-8'?>
<robot name="canary1" xmlns:xacro="http://ros.org/wiki/xacro">

  <xacro:arg name="name" default="canary1"/>
  <xacro:property name="name" value="$(arg name)"/>

  <link name='${name}/base_link'>
    <inertial>
      <origin xyz='0 0 0' rpy='0 -0 0'/>
      <mass value='1.5'/>
      <inertia ixx='0.025' ixy='0' ixz='0' iyy='0.009' iyz='0' izz='0.033'/>
    </inertial>
    <collision name='base_link_inertia_collision'>
      <origin xyz='0 0 0' rpy='0 -0 0'/>
      <geometry>
        <mesh filename='package://explorer_canary1_sensor_config_1/meshes/canary1_collision.stl' scale='1 1 1'/>
      </geometry>
    </collision>

    <visual name='base_link_inertia_visual'>
      <origin xyz='0 0 0' rpy='0 -0 0'/>
      <geometry>
        <mesh filename='package://explorer_canary1_sensor_config_1/meshes/canary1_no_props.dae' scale='1 1 1'/>
      </geometry>
    </visual>
    <!-- camera_visual -->

    <visual name='camera_front_visual'>
      <origin xyz='0.09 0.0 0.3' rpy='0 -0 0'/>
      <geometry>
        <box size='0.01 0.03 0.03'/>
      </geometry>
    </visual>
    <visual name='camera_lens_front_visual'>
      <origin xyz='0.1 0.0 0.3' rpy='0 1.5708 0'/>
      <geometry>
        <cylinder radius='0.005' length='0.011'/>
      </geometry>
    </visual>
    <visual name='camera_rear_visual'>
      <origin xyz='-0.09 0 0.3' rpy='0 -0 0'/>
      <geometry>
        <box size='0.01 0.03 0.03'/>
      </geometry>
    </visual>
    <visual name='camera_lens_rear_visual'>
      <origin xyz='-0.1 0 0.3' rpy='0 1.5708 0'/>
      <geometry>
        <cylinder radius='0.005' length='0.011'/>
      </geometry>
    </visual>
    <visual name='camera_left_visual'>
      <origin xyz='0 0.09 0.3' rpy='0 -0 0'/>
      <geometry>
        <box size='0.03 0.01 0.03'/>
      </geometry>
    </visual>
    <visual name='camera_lens_left_visual'>
      <origin xyz='0 0.1 0.3' rpy='1.5708 -0 0'/>
      <geometry>
        <cylinder radius='0.005' length='0.011'/>
      </geometry>
    </visual>
    <visual name='camera_right_visual'>
      <origin xyz='0 -0.09 0.3' rpy='0 -0 0'/>
      <geometry>
        <box size='0.03 0.01 0.03'/>
      </geometry>
    </visual>
    <visual name='camera_lens_right_visual'>
      <origin xyz='0 -0.1 0.3' rpy='1.5708 -0 0'/>
      <geometry>
        <cylinder radius='0.005' length='0.011'/>
      </geometry>
    </visual>

    
    <!-- Lidar visual -->
    <visual name='laser_visual_base1'>
      <origin xyz='0 0 0.33' rpy='0 -0 0'/>
      <geometry>
        <mesh filename="package://explorer_canary1_sensor_config_1/meshes/VLP16_base_1.dae" />
      </geometry>
    </visual>
    <visual name='laser_visual_base2'>
      <origin xyz='0 0 0.33' rpy='0 -0 0'/>
      <geometry>
        <mesh filename="package://explorer_canary1_sensor_config_1/meshes/VLP16_base_2.dae" />
      </geometry>
    </visual>
    <visual name='laser_visual_scan'>
      <origin xyz='0 0 0.33' rpy='0 -0 0'/>
      <geometry>
        <mesh filename="package://explorer_canary1_sensor_config_1/meshes/VLP16_scan.dae" />
      </geometry>
    </visual>

    <!--
    <visual name='up_laser_visual_base1'>
      <origin xyz='-0.11 0 0.24' rpy='0 -0 0'/>
      <geometry>
        <mesh filename="package://explorer_canary1_sensor_config_1/meshes/VLP16_base_1.dae" />
      </geometry>
    </visual>
    <visual name='up_laser_visual_base2'>
      <origin xyz='-0.11 0 0.24' rpy='0 -0 0'/>
      <geometry>
        <mesh filename="package://explorer_canary1_sensor_config_1/meshes/VLP16_base_2.dae" />
      </geometry>
    </visual>
    <visual name='up_laser_visual_scan'>
      <origin xyz='-0.11 0 0.24' rpy='0 -0 0'/>
      <geometry>
        <mesh filename="package://explorer_canary1_sensor_config_1/meshes/VLP16_scan.dae" />
      </geometry>
    </visual>
    -->
    <visual name='up_laser_visual_ouster'>
      <origin xyz='-0.11 0 0.24' rpy='0 -1.5708 0'/>
      <geometry>
        <mesh filename="package://explorer_canary1_sensor_config_1/meshes/ouster-os0.dae" />
      </geometry>
    </visual>
  </link>

  <sensor name='imu_sensor' update_rate='250'>
    <parent link='${name}/base_link'/>
    <origin xyz='0 0 0' rpy='0 -0 0'/>
  </sensor>
  
  <sensor name='air_pressure' update_rate='20'>
    <parent link='${name}/base_link'/>
    <origin xyz='0 0 0' rpy='0 -0 0'/>
  </sensor>

  <sensor name='magnetometer' update_rate='20'>
    <parent link='${name}/base_link'/>
    <origin xyz='0 0 0' rpy='0 -0 0'/>
  </sensor>

  <sensor name='camera_front' update_rate='25'>
    <parent link='${robot_namespace}/base_link'/>
    <origin xyz='0.11 0.0 0' rpy='0 -0 0'/>
    <camera>
      <image width='720' height='1080' format='R8G8B8' hfov='1.658' near='0.01' far='300' />
    </camera>
  </sensor>
  <sensor name='camera_rear' update_rate='25'>
    <parent link='${robot_namespace}/base_link'/>
    <origin xyz='-0.11 0 0' rpy='0 -0 3.14159'/>
    <camera>
      <image width='720' height='1080' format='R8G8B8' hfov='1.658' near='0.01' far='300' />
    </camera>
  </sensor>
  <sensor name='camera_left' update_rate='25'>
    <parent link='${robot_namespace}/base_link'/>
    <origin xyz='0 0.11 0' rpy='0 -0 1.5708'/>
    <camera>
      <image width='720' height='1080' format='R8G8B8' hfov='1.658' near='0.01' far='300' />
    </camera>
  </sensor>
  <sensor name='camera_right' update_rate='25'>
    <parent link='${robot_namespace}/base_link'/>
    <origin xyz='0 -0.11 0' rpy='0 0 -1.5708'/>
    <camera>
      <image width='720' height='1080' format='R8G8B8' hfov='1.658' near='0.01' far='300' />
    </camera>
  </sensor>

  
  <sensor name='front_laser' update_rate='15'>
    <parent link='${name}/base_link'/>
    <origin xyz='0 0 0.33' rpy='0 -0 0'/>
  </sensor>
  <sensor name='up_laser' update_rate='15'>
    <parent link='${name}/base_link'/>
    <origin xyz='-0.11 0 0.24' rpy='3.14159 -1.57079 3.14159'/>
  </sensor>

  <link name='${name}/rotor_0'>
    <inertial>
      <origin xyz='0 0 0' rpy='0 -0 0'/>
      <mass value='0.005'/>
      <inertia ixx='9.75e-07' ixy='0' ixz='0' iyy='4.17041e-05' iyz='0' izz='4.26041e-05'/>
    </inertial>
    <visual name='rotor_0_visual'>
      <origin xyz='0 0 0' rpy='0 -0 0'/>
      <geometry>
        <mesh filename='package://explorer_canary1_sensor_config_1/meshes/propeller_ccw.dae' scale='0.15 0.15 0.15'/>
      </geometry>
    </visual>
  </link>

  <link name='${name}/rotor_1'>
    <inertial>
      <origin xyz='0 0 0' rpy='0 -0 0'/>
      <mass value='0.005'/>
      <inertia ixx='9.75e-07' ixy='0' ixz='0' iyy='4.17041e-05' iyz='0' izz='4.26041e-05'/>
    </inertial>
    <visual name='rotor_1_visual'>
      <origin xyz='0 0 0' rpy='0 -0 0'/>
      <geometry>
        <mesh filename='package://explorer_canary1_sensor_config_1/meshes/propeller_ccw.dae' scale='0.15 0.15 0.15'/>
      </geometry>
    </visual>
  </link>

  <link name='${name}/rotor_2'>
    <inertial>
      <origin xyz='0 0 0' rpy='0 -0 0'/>
      <mass value='0.005'/>
      <inertia ixx='9.75e-07' ixy='0' ixz='0' iyy='4.17041e-05' iyz='0' izz='4.26041e-05'/>
    </inertial>
    <visual name='rotor_2_visual'>
      <origin xyz='0 0 0' rpy='0 -0 0'/>
      <geometry>
        <mesh filename='package://explorer_canary1_sensor_config_1/meshes/propeller_cw.dae' scale='0.15 0.15 0.15'/>
      </geometry>
    </visual>
  </link>

  <link name='${name}/rotor_3'>
    <inertial>
      <origin xyz='0 0 0' rpy='0 -0 0'/>
      <mass value='0.005'/>
      <inertia ixx='9.75e-07' ixy='0' ixz='0' iyy='4.17041e-05' iyz='0' izz='4.26041e-05'/>
    </inertial>
    <visual name='rotor_3_visual'>
      <origin xyz='0 0 0' rpy='0 -0 0'/>
      <geometry>
        <mesh filename='package://explorer_canary1_sensor_config_1/meshes/propeller_cw.dae' scale='0.15 0.15 0.15'/>
      </geometry>
    </visual>
  </link>

  <joint name='rotor_0_joint' type='revolute'>
    <origin xyz='0.23 -0.23 0.123' rpy='0 -0 0'/>
    <parent link='${name}/base_link'/>
    <child link='${name}/rotor_0'/>
    <dynamics damping='0' friction='0' />
    <axis xyz='0 0 1'/>
    <limit lower='-1e+16' upper='1e+16' effort='-1' velocity='-1'/>
  </joint>

  <joint name='rotor_1_joint' type='revolute'>
    <origin xyz='-0.23 0.23 0.123' rpy='0 -0 0'/>
    <parent link='${name}/base_link'/>
    <child link='${name}/rotor_1'/>
    <dynamics damping='0' friction='0' />
    <axis xyz='0 0 1'/>
    <limit lower='-1e+16' upper='1e+16' effort='-1' velocity='-1'/>
  </joint>

  <joint name='rotor_2_joint' type='revolute'>
    <origin xyz='0.23 0.23 0.123' rpy='0 -0 0'/>
    <parent link='${name}/base_link'/>
    <child link='${name}/rotor_2'/>
    <dynamics damping='0' friction='0' />
    <axis xyz='0 0 1'/>
    <limit lower='-1e+16' upper='1e+16' effort='-1' velocity='-1'/>
  </joint>
  
  <joint name='rotor_3_joint' type='revolute'>
    <origin xyz='-0.23 -0.23 0.123' rpy='0 -0 0'/>
    <parent link='${name}/base_link'/>
    <child link='${name}/rotor_3'/>
    <dynamics damping='0' friction='0' />
    <axis xyz='0 0 1'/>
    <limit lower='-1e+16' upper='1e+16' effort='-1' velocity='-1'/>
  </joint>
</robot>
