<?xml version='1.0' encoding='utf-8'?>
<robot name='ROBOTIKA_KLOUBAK'>
  <link name='chassis_front'>
    <inertial>
      <origin xyz='-0.05 0 0.28' rpy='0 -0 0'/>
      <mass value='8'/>
      <inertia ixx='0.1119' ixy='0' ixz='0' iyy='0.1286' iyz='0' izz='0.2159'/>
    </inertial>
    <collision name='collision_front_box'>
      <origin xyz='0 0 0.28' rpy='0 -0 0'/>
      <geometry>
        <box size='0.3 0.4 0.16'/>
      </geometry>
    </collision>
    <collision name='collision_bar'>
      <origin xyz='-0.17 0 0.22' rpy='0 -0 0'/>
      <geometry>
        <box size='0.3 0.04 0.04'/>
      </geometry>
    </collision>
    <collision name='collision_joint_upper'>
      <origin xyz='-0.335 0 0.25' rpy='0 -0 0'/>
      <geometry>
        <box size='0.07 0.06 0.02'/>
      </geometry>
    </collision>
    <collision name='collision_joint_bottom'>
      <origin xyz='-0.335 0 0.19' rpy='0 -0 0'/>
      <geometry>
        <box size='0.07 0.06 0.02'/>
      </geometry>
    </collision>
    <collision name='collision_wheel_hinge_left'>
      <origin xyz='0 0.18 0.18' rpy='0 -0 0'/>
      <geometry>
        <box size='0.04 0.06 0.04'/>
      </geometry>
    </collision>
    <collision name='collision_wheel_hinge_right'>
      <origin xyz='0 -0.18 0.18' rpy='0 -0 0'/>
      <geometry>
        <box size='0.04 0.06 0.04'/>
      </geometry>
    </collision>
    <collision name='collision_light_lidar_camera'>
      <origin xyz='0.05 0 0.4325' rpy='0 -0 0'/>
      <geometry>
        <box size='0.2 0.15 0.145'/>
      </geometry>
    </collision>
    <collision name='collision_depth_camera_front'>
      <origin xyz='0.165 0 0.31' rpy='0 -0 0'/>
      <geometry>
        <box size='0.03 0.2 0.06'/>
      </geometry>
    </collision>
    <visual name='visual_chassis'>
      <origin xyz='-0.34 0 0.03' rpy='0 -0 0'/>
      <geometry>
        <mesh filename='meshes/k2.dae' scale='1 1 1'/>
      </geometry>
    </visual>
  </link>
  <sensor name='imu_sensor_front' update_rate='50'>
    <parent link='chassis_front'/>
    <origin xyz='0 0 0' rpy='0 -0 0'/>
  </sensor>
  <sensor name='magnetometer_front' update_rate='50'>
    <parent link='chassis_front'/>
    <origin xyz='0 0 0' rpy='0 -0 0'/>
  </sensor>
  <sensor name='air_pressure' update_rate='20'>
    <parent link='chassis_front'/>
    <origin xyz='0 0 0' rpy='0 -0 0'/>
  </sensor>
  <sensor name='lidar_front' update_rate='15'>
    <parent link='chassis_front'/>
    <origin xyz='0.08 0 0.25' rpy='0 -0 0'/>
  </sensor>
  <sensor name='camera_front' update_rate='10'>
    <parent link='chassis_front'/>
    <origin xyz='0.155 -0.0075 0.193' rpy='0 -0 0'/>
    <camera>
      <image width='640' height='360' format='R8G8B8' hfov='2.27' near='0.01' far='300' />
    </camera>
  </sensor>
  <sensor name='depth_camera_front' update_rate='20'>
    <parent link='chassis_front'/>
    <origin xyz='0.18 0 0.113' rpy='0 -0 0'/>
    <camera>
      <image width='640' height='360' format='R8G8B8' hfov='1.5184' near='0.01' far='300' />
    </camera>
  </sensor>
  <link name='chassis_back'>
    <inertial>
      <origin xyz='-0.325 0 0.096' rpy='0 -0 0'/>
      <mass value='7.2'/>
      <inertia ixx='0.0468' ixy='0' ixz='0' iyy='0.1117' iyz='0' izz='0.1228'/>
    </inertial>
    <collision name='collision_back_box'>
      <origin xyz='-0.35 0 0.11' rpy='0 -0 0'/>
      <geometry>
        <box size='0.34 0.24 0.18'/>
      </geometry>
    </collision>
    <collision name='collision_bar'>
      <origin xyz='-0.225 0 0' rpy='0 -0 0'/>
      <geometry>
        <box size='0.45 0.04 0.04'/>
      </geometry>
    </collision>
    <collision name='collision_light_lidar_camera'>
      <origin xyz='-0.42 0 0.2725' rpy='0 -0 0'/>
      <geometry>
        <box size='0.2 0.15 0.145'/>
      </geometry>
    </collision>
    <collision name='collision_depth_camera_back'>
      <origin xyz='-0.535 0 0.09' rpy='0 -0 0'/>
      <geometry>
        <box size='0.03 0.2 0.06'/>
      </geometry>
    </collision>
    <visual name='visual_chassis'>
      <origin xyz='-0.01 0 -0.19' rpy='0 -0 0'/>
      <geometry>
        <mesh filename='meshes/k2.dae' scale='1 1 1'/>
      </geometry>
    </visual>
  </link>
  <sensor name='imu_sensor_back' update_rate='50'>
    <parent link='chassis_back'/>
    <origin xyz='0 0 0' rpy='0 -0 0'/>
  </sensor>
  <sensor name='magnetometer_back' update_rate='50'>
    <parent link='chassis_back'/>
    <origin xyz='0 0 0' rpy='0 -0 0'/>
  </sensor>
  <sensor name='lidar_back' update_rate='15'>
    <parent link='chassis_back'/>
    <origin xyz='-0.08 0 0.345' rpy='0 -0 -3.14159'/>
  </sensor>
  <sensor name='camera_back' update_rate='10'>
    <parent link='chassis_back'/>
    <origin xyz='-0.185 -0.001 0.269' rpy='0 -0 -3.14159'/>
    <camera>
      <image width='640' height='360' format='R8G8B8' hfov='2.27' near='0.01' far='300' />
    </camera>
  </sensor>
  <sensor name='depth_camera_back' update_rate='20'>
    <parent link='chassis_back'/>
    <origin xyz='-0.2 0 0.113' rpy='0 -0 -3.14159'/>
    <camera>
      <image width='640' height='360' format='R8G8B8' hfov='1.5184' near='0.01' far='300' />
    </camera>
  </sensor>
  <link name='axle_back'>
    <inertial>
      <origin xyz='0 0 0' rpy='0 -0 0'/>
      <mass value='0.8'/>
      <inertia ixx='0.0119' ixy='0' ixz='0' iyy='0.00021' iyz='0' izz='0.0119'/>
    </inertial>
    <collision name='collision'>
      <origin xyz='0 0 0' rpy='0 -0 0'/>
      <geometry>
        <box size='0.04 0.42 0.04'/>
      </geometry>
    </collision>
    <visual name='visual'>
      <origin xyz='-0.0132 0 0' rpy='0 -0 0'/>
      <geometry>
        <mesh filename='meshes/k2.dae' scale='1 1 1'/>
      </geometry>
    </visual>
  </link>
  <link name='front_left_wheel'>
    <inertial>
      <origin xyz='0 0 0' rpy='0 -0 0'/>
      <mass value='3.5'/>
      <inertia ixx='0.0145' ixy='0' ixz='0' iyy='0.0252' iyz='0' izz='0.0145'/>
    </inertial>
    <collision name='collision'>
      <origin xyz='0 0 0' rpy='-1.5708 0 0'/>
      <geometry>
        <cylinder radius='0.147' length='0.08'/>
      </geometry>
    </collision>
    <visual name='tire_visual'>
      <origin xyz='0 0 0' rpy='0 -0 0'/>
      <geometry>
        <mesh filename='meshes/k2.dae' scale='1 1 1'/>
      </geometry>
    </visual>
  </link>
  <link name='front_right_wheel'>
    <inertial>
      <origin xyz='0 0 0' rpy='0 -0 0'/>
      <mass value='3.5'/>
      <inertia ixx='0.0145' ixy='0' ixz='0' iyy='0.0252' iyz='0' izz='0.0145'/>
    </inertial>
    <collision name='collision'>
      <origin xyz='0 0 0' rpy='1.5708 -0 0'/>
      <geometry>
        <cylinder radius='0.147' length='0.08'/>
      </geometry>
    </collision>
    <visual name='tire_visual'>
      <origin xyz='0 0 0' rpy='0 -0 0'/>
      <geometry>
        <mesh filename='meshes/k2.dae' scale='1 1 1'/>
      </geometry>
    </visual>
  </link>
  <link name='rear_left_wheel'>
    <inertial>
      <origin xyz='0 0 0' rpy='0 -0 0'/>
      <mass value='3.5'/>
      <inertia ixx='0.0145' ixy='0' ixz='0' iyy='0.0252' iyz='0' izz='0.0145'/>
    </inertial>
    <collision name='collision'>
      <origin xyz='0 0 0' rpy='-1.5708 0 0'/>
      <geometry>
        <cylinder radius='0.147' length='0.08'/>
      </geometry>
    </collision>
    <visual name='tire_visual'>
      <origin xyz='0 0 0' rpy='0 -0 0'/>
      <geometry>
        <mesh filename='meshes/k2.dae' scale='1 1 1'/>
      </geometry>
    </visual>
  </link>
  <link name='rear_right_wheel'>
    <inertial>
      <origin xyz='0 0 0' rpy='0 -0 0'/>
      <mass value='3.5'/>
      <inertia ixx='0.0145' ixy='0' ixz='0' iyy='0.0252' iyz='0' izz='0.0145'/>
    </inertial>
    <collision name='collision'>
      <origin xyz='0 0 0' rpy='1.5708 -0 0'/>
      <geometry>
        <cylinder radius='0.147' length='0.08'/>
      </geometry>
    </collision>
    <visual name='tire_visual'>
      <origin xyz='0 0 0' rpy='0 -0 0'/>
      <geometry>
        <mesh filename='meshes/k2.dae' scale='1 1 1'/>
      </geometry>
    </visual>
  </link>
  <joint name='front_left_wheel_joint' type='revolute'>
    <origin xyz='0 0.25 0.172' rpy='0 -0 0'/>
    <parent link='chassis_front'/>
    <child link='front_left_wheel'/>
    <axis xyz='0 1 0'/>
    <limit lower='-1.79769e+308' upper='1.79769e+308' effort='10' velocity='13.333'/>
  </joint>
  <joint name='front_right_wheel_joint' type='revolute'>
    <origin xyz='0 -0.25 0.172' rpy='0 -0 0'/>
    <parent link='chassis_front'/>
    <child link='front_right_wheel'/>
    <axis xyz='0 1 0'/>
    <limit lower='-1.79769e+308' upper='1.79769e+308' effort='10' velocity='13.333'/>
  </joint>
  <joint name='rear_left_wheel_joint' type='revolute'>
    <origin xyz='-0.7 0.25 0.172' rpy='0 -0 0'/>
    <parent link='axle_back'/>
    <child link='rear_left_wheel'/>
    <axis xyz='0 1 0'/>
    <limit lower='-1.79769e+308' upper='1.79769e+308' effort='10' velocity='13.333'/>
  </joint>
  <joint name='rear_right_wheel_joint' type='revolute'>
    <origin xyz='-0.7 -0.25 0.172' rpy='0 -0 0'/>
    <parent link='axle_back'/>
    <child link='rear_right_wheel'/>
    <axis xyz='0 1 0'/>
    <limit lower='-1.79769e+308' upper='1.79769e+308' effort='10' velocity='13.333'/>
  </joint>
  <joint name='main_joint' type='revolute'>
    <origin xyz='-0.321 0 0.22' rpy='0 -0 0'/>
    <parent link='chassis_front'/>
    <child link='chassis_back'/>
    <axis xyz='0 0 1'/>
    <limit lower='-1.222' upper='1.222' effort='-1' velocity='-1'/>
  </joint>
  <joint name='axle_joint' type='revolute'>
    <origin xyz='-0.7 0 0.183' rpy='0 -0 0'/>
    <parent link='chassis_back'/>
    <child link='axle_back'/>
    <axis xyz='1 0 0'/>
    <limit lower='-0.436' upper='0.436' effort='-1' velocity='-1'/>
  </joint>
</robot>
