<?xml version='1.0' encoding='utf-8'?>
<robot name="X4" xmlns:xacro="http://ros.org/wiki/xacro">
  <xacro:arg name="name" default="X4"/>
  <xacro:property name="robot_namespace" value="$(arg name)"/>

  <link name='${robot_namespace}/base_link'>
    <inertial>
      <origin xyz='0 0 0' rpy='0 -0 0'/>
      <mass value='3.42'/>
      <inertia ixx='0.075' ixy='0' ixz='0' iyy='0.075' iyz='0' izz='0.148916'/>
    </inertial>
    <collision name='base_link_inertia_collision'>
      <origin xyz='0 0 0' rpy='0 -0 0'/>
      <geometry>
        <box size='0.3 0.3 0.25'/>
      </geometry>
    </collision>
    <visual name='base_link_inertia_visual'>
      <origin xyz='0 0 0' rpy='0 -0 0'/>
      <geometry>
        <mesh filename='package://ssci_x4_sensor_config_6/meshes/x4.dae' scale='1 1 1'/>
      </geometry>
    </visual>
    <visual name='camera_mount_base_visual'>
      <origin xyz='0.05 0 -0.03' rpy='0 -0 0'/>
      <geometry>
        <box size='0.06 0.06 0.006'/>
      </geometry>
    </visual>
    <visual name='camera_mount_arm_visual'>
      <origin xyz='0.08 0 -0.04' rpy='0 -0 0'/>
      <geometry>
        <cylinder radius='0.005' length='0.08'/>
      </geometry>
    </visual>
    <visual name='camera_mount_arm2_visual'>
      <origin xyz='0.08 0 -0.08' rpy='0 1.57 0'/>
      <geometry>
        <cylinder radius='0.01' length='0.025'/>
      </geometry>
    </visual>
    <visual name='camera_visual'>
      <origin xyz='0.1 0 -0.08' rpy='0 -0 0'/>
      <geometry>
        <box size='0.02 0.025 0.025'/>
      </geometry>
    </visual>
  </link>
  <sensor name='imu_sensor' update_rate='1000'>
    <parent link='${robot_namespace}/base_link'/>
    <origin xyz='0 0 0' rpy='0 -0 0'/>
  </sensor>
  <sensor name='air_pressure' update_rate='20'>
    <parent link='base_link'/>
    <origin xyz='0 0 0' rpy='0 -0 0'/>
  </sensor>
  <sensor name='magnetometer' update_rate='20'>
    <parent link='base_link'/>
    <origin xyz='0 0 0' rpy='0 -0 0'/>
  </sensor>
  <sensor name='front_laser' update_rate='20'>
    <parent link='base_link'/>
    <origin xyz='0.43 0 0.26' rpy='0 -0 0'/>
  </sensor>
  <sensor name='top_laser' update_rate='20'>
    <parent link='base_link'/>
    <origin xyz='0.43 0 0.26' rpy='0 1.57 0'/>
  </sensor>
  <sensor name='bottom_laser' update_rate='20'>
    <parent link='base_link'/>
    <origin xyz='0.43 0 0' rpy='0 -1.57 0'/>
  </sensor>
  <sensor name='camera_front' update_rate='20'>
    <parent link='base_link'/>
    <origin xyz='0.1 0 -0.08' rpy='0 -0 0'/>
    <camera>
      <image width='640' height='480' format='R8G8B8' hfov='1.0472' near='0.01' far='300' />
    </camera>
  </sensor>
  <link name='${robot_namespace}/rotor_0'>
    <inertial>
      <origin xyz='0 0 0' rpy='0 -0 0'/>
      <mass value='0.005'/>
      <inertia ixx='9.75e-07' ixy='0' ixz='0' iyy='8.13545e-05' iyz='0' izz='8.22545e-05'/>
    </inertial>
    <collision name='rotor_0_collision'>
      <origin xyz='0 0 0' rpy='0 -0 0'/>
      <geometry>
        <cylinder radius='0.1397' length='0.005'/>
      </geometry>
    </collision>
    <visual name='rotor_0_visual'>
      <origin xyz='0 0 0' rpy='0 -0 0'/>
      <geometry>
        <mesh filename='package://ssci_x4_sensor_config_6/meshes/neo11_propeller_ccw.dae' scale='1 1 1'/>
      </geometry>
    </visual>
  </link>
  <link name='${robot_namespace}/rotor_1'>
    <inertial>
      <origin xyz='0 0 0' rpy='0 -0 0'/>
      <mass value='0.005'/>
      <inertia ixx='9.75e-07' ixy='0' ixz='0' iyy='8.13545e-05' iyz='0' izz='8.22545e-05'/>
    </inertial>
    <collision name='rotor_1_collision'>
      <origin xyz='0 0 0' rpy='0 -0 0'/>
      <geometry>
        <cylinder radius='0.1397' length='0.005'/>
      </geometry>
    </collision>
    <visual name='rotor_1_visual'>
      <origin xyz='0 0 0' rpy='0 -0 0'/>
      <geometry>
        <mesh filename='package://ssci_x4_sensor_config_6/meshes/neo11_propeller_cw.dae' scale='1 1 1'/>
      </geometry>
    </visual>
  </link>
  <link name='${robot_namespace}/rotor_2'>
    <inertial>
      <origin xyz='0 0 0' rpy='0 -0 0'/>
      <mass value='0.005'/>
      <inertia ixx='9.75e-07' ixy='0' ixz='0' iyy='8.13545e-05' iyz='0' izz='8.22545e-05'/>
    </inertial>
    <collision name='rotor_2_collision'>
      <origin xyz='0 0 0' rpy='0 -0 0'/>
      <geometry>
        <cylinder radius='0.1397' length='0.005'/>
      </geometry>
    </collision>
    <visual name='rotor_2_visual'>
      <origin xyz='0 0 0' rpy='0 -0 0'/>
      <geometry>
        <mesh filename='package://ssci_x4_sensor_config_6/meshes/neo11_propeller_ccw.dae' scale='1 1 1'/>
      </geometry>
    </visual>
  </link>
  <link name='${robot_namespace}/rotor_3'>
    <inertial>
      <origin xyz='0 0 0' rpy='0 -0 0'/>
      <mass value='0.005'/>
      <inertia ixx='9.75e-07' ixy='0' ixz='0' iyy='8.13545e-05' iyz='0' izz='8.22545e-05'/>
    </inertial>
    <collision name='rotor_3_collision'>
      <origin xyz='0 0 0' rpy='0 -0 0'/>
      <geometry>
        <cylinder radius='0.1397' length='0.005'/>
      </geometry>
    </collision>
    <visual name='rotor_3_visual'>
      <origin xyz='0 0 0' rpy='0 -0 0'/>
      <geometry>
        <mesh filename='package://ssci_x4_sensor_config_6/meshes/neo11_propeller_cw.dae' scale='1 1 1'/>
      </geometry>
    </visual>
  </link>
  <link name='${robot_namespace}/rotor_4'>
    <inertial>
      <origin xyz='0 0 0' rpy='-0 -0 -0'/>
      <mass value='0.005'/>
      <inertia ixx='9.75e-07' ixy='0' ixz='0' iyy='8.13545e-05' iyz='0' izz='8.22545e-05'/>
    </inertial>
    <collision name='rotor_4_collision'>
      <origin xyz='0 0 0' rpy='-0 -0 -0'/>
      <geometry>
        <cylinder radius='0.1397' length='0.005'/>
      </geometry>
    </collision>
    <visual name='rotor_4_visual'>
      <origin xyz='0 0 0' rpy='-0 -0 -0'/>
      <geometry>
        <mesh filename='package://ssci_x4_sensor_config_6/meshes/neo11_propeller_ccw.dae' scale='1 1 1'/>
      </geometry>
    </visual>
  </link>
  <link name='${robot_namespace}/rotor_5'>
    <inertial>
      <origin xyz='0 0 0' rpy='0 -0 0'/>
      <mass value='0.005'/>
      <inertia ixx='9.75e-07' ixy='0' ixz='0' iyy='8.13545e-05' iyz='0' izz='8.22545e-05'/>
    </inertial>
    <collision name='rotor_5_collision'>
      <origin xyz='0 0 0' rpy='0 -0 0'/>
      <geometry>
        <cylinder radius='0.1397' length='0.005'/>
      </geometry>
    </collision>
    <visual name='rotor_5_visual'>
      <origin xyz='0 0 0' rpy='0 -0 0'/>
      <geometry>
        <mesh filename='package://ssci_x4_sensor_config_6/meshes/neo11_propeller_cw.dae' scale='1 1 1'/>
      </geometry>
    </visual>
  </link>
  <joint name='rotor_0_joint' type='revolute'>
    <origin xyz='0.247 0.1506 0.028' rpy='0.087267 0 0.523599'/>
    <parent link='${robot_namespace}/base_link'/>
    <child link='${robot_namespace}/rotor_0'/>
    <dynamics damping='0' friction='0' />
    <axis xyz='0 1e-06 1'/>
    <limit lower='-1e+16' upper='1e+16' effort='-1' velocity='-1'/>
  </joint>
  <joint name='rotor_1_joint' type='revolute'>
    <origin xyz='-0.00067 0.28929 0.028' rpy='0 -0.087267 0'/>
    <parent link='${robot_namespace}/base_link'/>
    <child link='${robot_namespace}/rotor_1'/>
    <dynamics damping='0' friction='0' />
    <axis xyz='0 0 1'/>
    <limit lower='-1e+16' upper='1e+16' effort='-1' velocity='-1'/>
  </joint>
  <joint name='rotor_2_joint' type='revolute'>
    <origin xyz='-0.2501 0.1454 0.028' rpy='0.087267 -0 2.61799'/>
    <parent link='${robot_namespace}/base_link'/>
    <child link='${robot_namespace}/rotor_2'/>
    <dynamics damping='0' friction='0' />
    <axis xyz='0 1e-06 1'/>
    <limit lower='-1e+16' upper='1e+16' effort='-1' velocity='-1'/>
  </joint>
  <joint name='rotor_3_joint' type='revolute'>
    <origin xyz='-0.2501 -0.1454 0.028' rpy='-0.087267 -0 -2.61799'/>
    <parent link='${robot_namespace}/base_link'/>
    <child link='${robot_namespace}/rotor_3'/>
    <dynamics damping='0' friction='0' />
    <axis xyz='0 -1e-06 1'/>
    <limit lower='-1e+16' upper='1e+16' effort='-1' velocity='-1'/>
  </joint>
  <joint name='rotor_4_joint' type='revolute'>
    <origin xyz='-0.00067 -0.28929 0.028' rpy='-0 0.087267 -3.14159'/>
    <parent link='${robot_namespace}/base_link'/>
    <child link='${robot_namespace}/rotor_4'/>
    <dynamics damping='0' friction='0' />
    <axis xyz='-0 -0 1'/>
    <limit lower='-1e+16' upper='1e+16' effort='-1' velocity='-1'/>
  </joint>
  <joint name='rotor_5_joint' type='revolute'>
    <origin xyz='0.247 -0.1506 0.028' rpy='-0.087267 0 -0.523599'/>
    <parent link='${robot_namespace}/base_link'/>
    <child link='${robot_namespace}/rotor_5'/>
    <dynamics damping='0' friction='0' />
    <axis xyz='0 -1e-06 1'/>
    <limit lower='-1e+16' upper='1e+16' effort='-1' velocity='-1'/>
  </joint>
</robot>
