<?xml version='1.0' encoding='utf-8'?>
<sdf version="1.7">  <!-- CAUTION: This is an autogenerated file, DO NOT EDIT IT!  It was generated by script update_robot_sdf and is based on urdf/trailer.xacro source file.  Do all modifications there and then run the update script to regenerate the SDF. -->
  <model name="ctu_cras_norlab_balloon_sensor_config_1">
    <link name="base_link">
      <inertial>
        <mass>0.001</mass>
        <inertia>
          <ixx>1.66667e-10</ixx>
          <ixy>0</ixy>
          <ixz>0</ixz>
          <iyy>1.66667e-10</iyy>
          <iyz>0</iyz>
          <izz>1.66667e-10</izz>
        </inertia>
      </inertial>
    </link>
    <joint name="intermediate_j" type="fixed">
      <pose relative_to="base_link">-0.05 0 -0.35 0 -0 0</pose>
      <parent>base_link</parent>
      <child>reel</child>
      <axis>
        <dynamics>
          <spring_reference>0</spring_reference>
          <spring_stiffness>0</spring_stiffness>
        </dynamics>
        <xyz>0 0 1</xyz>
        <limit>
          <lower>-1e+16</lower>
          <upper>1e+16</upper>
        </limit>
      </axis>
      <physics>
        <ode>
          <limit>
            <cfm>0</cfm>
            <erp>0.2</erp>
          </limit>
        </ode>
      </physics>
    </joint>
    <link name="reel">
      <pose relative_to="intermediate_j">0 0 0 0 -0 0</pose>
      <inertial>
        <mass>1</mass>
        <inertia>
          <ixx>1.66667e-07</ixx>
          <ixy>0</ixy>
          <ixz>0</ixz>
          <iyy>1.66667e-07</iyy>
          <iyz>0</iyz>
          <izz>1.66667e-07</izz>
        </inertia>
      </inertial>
      <collision name="reel_collision">
        <pose>0 0 0 -1.5707963267948966 1.5707963267948966 0</pose>
        <geometry>
          <cylinder>
            <length>0.15</length>
            <radius>0.07</radius>
          </cylinder>
        </geometry>
      </collision>
      <visual name="reel_visual">
        <pose>0 0 0 -1.5707963267948966 1.5707963267948966 0</pose>
        <geometry>
          <cylinder>
            <length>0.15</length>
            <radius>0.07</radius>
          </cylinder>
        </geometry>
      </visual>
      <visual name="reel_visual_1">
        <pose>0.03 0 0.08 0 -0 0</pose>
        <geometry>
          <mesh>
            <scale>2 2 1</scale>
            <uri>meshes/apriltag.dae</uri>
          </mesh>
        </geometry>
      </visual>
    </link>
    <joint name="ball_j_x_j" type="revolute">
      <pose relative_to="reel">0 0 0 0 -0 0</pose>
      <parent>reel</parent>
      <child>ball_j_x</child>
      <axis>
        <xyz>1 0 0</xyz>
        <limit>
          <lower>-0.3</lower>
          <upper>0.3</upper>
          <effort>1</effort>
          <velocity>1</velocity>
        </limit>
        <dynamics>
          <damping>0</damping>
          <friction>0.05</friction>
          <spring_reference>0</spring_reference>
          <spring_stiffness>0</spring_stiffness>
        </dynamics>
      </axis>
    </joint>
    <link name="ball_j_x">
      <pose relative_to="ball_j_x_j">0 0 0 0 -0 0</pose>
      <inertial>
        <mass>0.001</mass>
        <inertia>
          <ixx>1.66667e-10</ixx>
          <ixy>0</ixy>
          <ixz>0</ixz>
          <iyy>1.66667e-10</iyy>
          <iyz>0</iyz>
          <izz>1.66667e-10</izz>
        </inertia>
      </inertial>
    </link>
    <joint name="ball_j_y_j" type="revolute">
      <pose relative_to="ball_j_x">0 0 0 0 -0 0</pose>
      <parent>ball_j_x</parent>
      <child>ball_j_y</child>
      <axis>
        <xyz>0 1 0</xyz>
        <limit>
          <lower>-0.3</lower>
          <upper>0.3</upper>
          <effort>1</effort>
          <velocity>1</velocity>
        </limit>
        <dynamics>
          <damping>0</damping>
          <friction>0.05</friction>
          <spring_reference>0</spring_reference>
          <spring_stiffness>0</spring_stiffness>
        </dynamics>
      </axis>
    </joint>
    <link name="ball_j_y">
      <pose relative_to="ball_j_y_j">0 0 0 0 -0 0</pose>
      <inertial>
        <mass>0.001</mass>
        <inertia>
          <ixx>1.66667e-10</ixx>
          <ixy>0</ixy>
          <ixz>0</ixz>
          <iyy>1.66667e-10</iyy>
          <iyz>0</iyz>
          <izz>1.66667e-10</izz>
        </inertia>
      </inertial>
    </link>
    <joint name="ball_j_z_j" type="revolute">
      <pose relative_to="ball_j_y">0 0 0 0 -0 0</pose>
      <parent>ball_j_y</parent>
      <child>string</child>
      <axis>
        <xyz>0 0 1</xyz>
        <limit>
          <lower>-1e+16</lower>
          <upper>1e+16</upper>
        </limit>
        <dynamics>
          <damping>0</damping>
          <friction>0.05</friction>
          <spring_reference>0</spring_reference>
          <spring_stiffness>0</spring_stiffness>
        </dynamics>
      </axis>
    </joint>
    <link name="string">
      <pose relative_to="ball_j_z_j">0 0 0 0 -0 0</pose>
      <inertial>
        <mass>0.001</mass>
        <inertia>
          <ixx>1.66667e-10</ixx>
          <ixy>0</ixy>
          <ixz>0</ixz>
          <iyy>1.66667e-10</iyy>
          <iyz>0</iyz>
          <izz>1.66667e-10</izz>
        </inertia>
      </inertial>
    </link>
    <joint name="string_prismatic_j" type="prismatic">
      <pose relative_to="string">0 0 0.465 0 -0 0</pose>
      <parent>string</parent>
      <child>balloon</child>
      <axis>
        <xyz>0 0 1</xyz>
        <limit>
          <lower>0</lower>
          <upper>15</upper>
          <effort>1</effort>
          <velocity>0.5</velocity>
        </limit>
        <dynamics>
          <spring_reference>0</spring_reference>
          <spring_stiffness>0</spring_stiffness>
        </dynamics>
      </axis>
    </joint>
    <link name="balloon">
      <pose relative_to="string_prismatic_j">0 0 0 0 -0 0</pose>
      <inertial>
        <mass>0.05</mass>
        <inertia>
          <ixx>0.0014045</ixx>
          <ixy>0</ixy>
          <ixz>0</ixz>
          <iyy>0.0014045</iyy>
          <iyz>0</iyz>
          <izz>0.0014045</izz>
        </inertia>
      </inertial>
      <collision name="balloon_collision">
        <geometry>
          <sphere>
            <radius>0.265</radius>
          </sphere>
        </geometry>
      </collision>
      <visual name="balloon_visual">
        <geometry>
          <sphere>
            <radius>0.265</radius>
          </sphere>
        </geometry>
        <material>
          <ambient>0 0 0 0</ambient>
          <diffuse>0.8 0.8 0.8 1</diffuse>
          <specular>1 1 1 0.5</specular>
          <emissive>1 1 1 0.1</emissive>
        </material>
      </visual>
    </link>
    <joint name="camera_j" type="fixed">
      <pose relative_to="balloon">0 0 -0.275 -3.1415926535897931 0 0</pose>
      <parent>balloon</parent>
      <child>camera</child>
      <axis>
        <dynamics>
          <spring_reference>0</spring_reference>
          <spring_stiffness>0</spring_stiffness>
        </dynamics>
        <xyz>0 0 1</xyz>
        <limit>
          <lower>-1e+16</lower>
          <upper>1e+16</upper>
        </limit>
      </axis>
      <physics>
        <ode>
          <limit>
            <cfm>0</cfm>
            <erp>0.2</erp>
          </limit>
        </ode>
      </physics>
    </joint>
    <link name="camera">
      <pose relative_to="camera_j">0 0 0 0 -0 0</pose>
      <inertial>
        <mass>0.022</mass>
        <inertia>
          <ixx>1.08533e-06</ixx>
          <ixy>0</ixy>
          <ixz>0</ixz>
          <iyy>1.08533e-06</iyy>
          <iyz>0</iyz>
          <izz>7.04e-07</izz>
        </inertia>
      </inertial>
      <collision name="camera_collision">
        <geometry>
          <cylinder>
            <length>0.02</length>
            <radius>0.008</radius>
          </cylinder>
        </geometry>
      </collision>
      <visual name="camera_visual">
        <geometry>
          <cylinder>
            <length>0.02</length>
            <radius>0.008</radius>
          </cylinder>
        </geometry>
      </visual>
      <light name="light_0" type="spot">
        <pose>0.02 0 0 3.1415926535897931 -0.392699 3.1415926535897931</pose>
        <attenuation>
          <range>20</range>
          <linear>0</linear>
          <constant>0.1</constant>
          <quadratic>0.0025</quadratic>
        </attenuation>
        <diffuse>0.8 0.8 0.5 1</diffuse>
        <specular>0.8 0.8 0.5 1</specular>
        <spot>
          <inner_angle>1.0472</inner_angle>
          <outer_angle>1.5708</outer_angle>
          <falloff>1</falloff>
        </spot>
        <direction>0 0 -1</direction>
      </light>
      <light name="light_1" type="spot">
        <pose>0.02 0 0 3.1415926535897931 -0.392699 -1.0472</pose>
        <attenuation>
          <range>20</range>
          <linear>0</linear>
          <constant>0.1</constant>
          <quadratic>0.0025</quadratic>
        </attenuation>
        <diffuse>0.8 0.8 0.5 1</diffuse>
        <specular>0.8 0.8 0.5 1</specular>
        <spot>
          <inner_angle>1.0472</inner_angle>
          <outer_angle>1.5708</outer_angle>
          <falloff>1</falloff>
        </spot>
        <direction>0 0 -1</direction>
      </light>
      <light name="light_2" type="spot">
        <pose>0.02 0 0 3.1415926535897931 -0.392699 1.0472</pose>
        <attenuation>
          <range>20</range>
          <linear>0</linear>
          <constant>0.1</constant>
          <quadratic>0.0025</quadratic>
        </attenuation>
        <diffuse>0.8 0.8 0.5 1</diffuse>
        <specular>0.8 0.8 0.5 1</specular>
        <spot>
          <inner_angle>1.0472</inner_angle>
          <outer_angle>1.5708</outer_angle>
          <falloff>1</falloff>
        </spot>
        <direction>0 0 -1</direction>
      </light>
    </link>
    <joint name="camera_0_j" type="fixed">
      <pose relative_to="camera">0.02 0 0 0 -0.785398 0</pose>
      <parent>camera</parent>
      <child>camera_0</child>
      <axis>
        <dynamics>
          <spring_reference>0</spring_reference>
          <spring_stiffness>0</spring_stiffness>
        </dynamics>
        <xyz>0 0 1</xyz>
        <limit>
          <lower>-1e+16</lower>
          <upper>1e+16</upper>
        </limit>
      </axis>
      <physics>
        <ode>
          <limit>
            <cfm>0</cfm>
            <erp>0.2</erp>
          </limit>
        </ode>
      </physics>
    </joint>
    <link name="camera_0">
      <pose relative_to="camera_0_j">0 0 0 0 -0 0</pose>
      <inertial>
        <mass>1e-05</mass>
        <inertia>
          <ixx>1.66667e-12</ixx>
          <ixy>0</ixy>
          <ixz>0</ixz>
          <iyy>1.66667e-12</iyy>
          <iyz>0</iyz>
          <izz>1.66667e-12</izz>
        </inertia>
      </inertial>
      <sensor name="camera" type="camera">
        <update_rate>3</update_rate>
        <camera>
          <horizontal_fov>1.5708</horizontal_fov>
          <image>
            <width>800</width>
            <height>600</height>
            <format>R8G8B8</format>
          </image>
          <clip>
            <near>0.05</near>
            <far>50</far>
          </clip>
          <noise>
            <type>gaussian</type>
            <mean>0</mean>
            <stddev>0.007</stddev>
          </noise>
        </camera>
      </sensor>
    </link>
    <joint name="camera_1_j" type="fixed">
      <pose relative_to="camera">0.02 0 0 -0 -0.785398 -1.5707963267948966</pose>
      <parent>camera</parent>
      <child>camera_1</child>
      <axis>
        <dynamics>
          <spring_reference>0</spring_reference>
          <spring_stiffness>0</spring_stiffness>
        </dynamics>
        <xyz>0 0 1</xyz>
        <limit>
          <lower>-1e+16</lower>
          <upper>1e+16</upper>
        </limit>
      </axis>
      <physics>
        <ode>
          <limit>
            <cfm>0</cfm>
            <erp>0.2</erp>
          </limit>
        </ode>
      </physics>
    </joint>
    <link name="camera_1">
      <pose relative_to="camera_1_j">0 0 0 0 -0 0</pose>
      <inertial>
        <mass>1e-05</mass>
        <inertia>
          <ixx>1.66667e-12</ixx>
          <ixy>0</ixy>
          <ixz>0</ixz>
          <iyy>1.66667e-12</iyy>
          <iyz>0</iyz>
          <izz>1.66667e-12</izz>
        </inertia>
      </inertial>
      <sensor name="camera" type="camera">
        <update_rate>3</update_rate>
        <camera>
          <horizontal_fov>1.5708</horizontal_fov>
          <image>
            <width>800</width>
            <height>600</height>
            <format>R8G8B8</format>
          </image>
          <clip>
            <near>0.05</near>
            <far>50</far>
          </clip>
          <noise>
            <type>gaussian</type>
            <mean>0</mean>
            <stddev>0.007</stddev>
          </noise>
        </camera>
      </sensor>
    </link>
    <joint name="camera_2_j" type="fixed">
      <pose relative_to="camera">0.02 0 0 0 -0.785398 -3.1415926535897931</pose>
      <parent>camera</parent>
      <child>camera_2</child>
      <axis>
        <dynamics>
          <spring_reference>0</spring_reference>
          <spring_stiffness>0</spring_stiffness>
        </dynamics>
        <xyz>0 0 1</xyz>
        <limit>
          <lower>-1e+16</lower>
          <upper>1e+16</upper>
        </limit>
      </axis>
      <physics>
        <ode>
          <limit>
            <cfm>0</cfm>
            <erp>0.2</erp>
          </limit>
        </ode>
      </physics>
    </joint>
    <link name="camera_2">
      <pose relative_to="camera_2_j">0 0 0 0 -0 0</pose>
      <inertial>
        <mass>1e-05</mass>
        <inertia>
          <ixx>1.66667e-12</ixx>
          <ixy>0</ixy>
          <ixz>0</ixz>
          <iyy>1.66667e-12</iyy>
          <iyz>0</iyz>
          <izz>1.66667e-12</izz>
        </inertia>
      </inertial>
      <sensor name="camera" type="camera">
        <update_rate>3</update_rate>
        <camera>
          <horizontal_fov>1.5708</horizontal_fov>
          <image>
            <width>800</width>
            <height>600</height>
            <format>R8G8B8</format>
          </image>
          <clip>
            <near>0.05</near>
            <far>50</far>
          </clip>
          <noise>
            <type>gaussian</type>
            <mean>0</mean>
            <stddev>0.007</stddev>
          </noise>
        </camera>
      </sensor>
    </link>
    <joint name="camera_3_j" type="fixed">
      <pose relative_to="camera">0.02 0 0 0 -0.785398 1.5707963267948966</pose>
      <parent>camera</parent>
      <child>camera_3</child>
      <axis>
        <dynamics>
          <spring_reference>0</spring_reference>
          <spring_stiffness>0</spring_stiffness>
        </dynamics>
        <xyz>0 0 1</xyz>
        <limit>
          <lower>-1e+16</lower>
          <upper>1e+16</upper>
        </limit>
      </axis>
      <physics>
        <ode>
          <limit>
            <cfm>0</cfm>
            <erp>0.2</erp>
          </limit>
        </ode>
      </physics>
    </joint>
    <link name="camera_3">
      <pose relative_to="camera_3_j">0 0 0 0 -0 0</pose>
      <inertial>
        <mass>1e-05</mass>
        <inertia>
          <ixx>1.66667e-12</ixx>
          <ixy>0</ixy>
          <ixz>0</ixz>
          <iyy>1.66667e-12</iyy>
          <iyz>0</iyz>
          <izz>1.66667e-12</izz>
        </inertia>
      </inertial>
      <sensor name="camera" type="camera">
        <update_rate>3</update_rate>
        <camera>
          <horizontal_fov>1.5708</horizontal_fov>
          <image>
            <width>800</width>
            <height>600</height>
            <format>R8G8B8</format>
          </image>
          <clip>
            <near>0.05</near>
            <far>50</far>
          </clip>
          <noise>
            <type>gaussian</type>
            <mean>0</mean>
            <stddev>0.007</stddev>
          </noise>
        </camera>
      </sensor>
    </link>
    <joint name="camera_4_j" type="fixed">
      <pose relative_to="camera">0.02 0 0 0 -1.5707963267948966 0</pose>
      <parent>camera</parent>
      <child>camera_4</child>
      <axis>
        <dynamics>
          <spring_reference>0</spring_reference>
          <spring_stiffness>0</spring_stiffness>
        </dynamics>
        <xyz>0 0 1</xyz>
        <limit>
          <lower>-1e+16</lower>
          <upper>1e+16</upper>
        </limit>
      </axis>
      <physics>
        <ode>
          <limit>
            <cfm>0</cfm>
            <erp>0.2</erp>
          </limit>
        </ode>
      </physics>
    </joint>
    <link name="camera_4">
      <pose relative_to="camera_4_j">0 0 0 0 -0 0</pose>
      <inertial>
        <mass>1e-05</mass>
        <inertia>
          <ixx>1.66667e-12</ixx>
          <ixy>0</ixy>
          <ixz>0</ixz>
          <iyy>1.66667e-12</iyy>
          <iyz>0</iyz>
          <izz>1.66667e-12</izz>
        </inertia>
      </inertial>
      <sensor name="camera" type="camera">
        <update_rate>3</update_rate>
        <camera>
          <horizontal_fov>1.5708</horizontal_fov>
          <image>
            <width>800</width>
            <height>600</height>
            <format>R8G8B8</format>
          </image>
          <clip>
            <near>0.05</near>
            <far>50</far>
          </clip>
          <noise>
            <type>gaussian</type>
            <mean>0</mean>
            <stddev>0.007</stddev>
          </noise>
        </camera>
      </sensor>
    </link>
  </model>
</sdf>

