<?xml version="1.0"?>
<sdf version="1.6">
  <model name="coro_crystal_sensor_config_1">
    <pose>0 0 0 0 0 0</pose>
    <link name="base_link">
      <pose frame="">0 0 0 0 -0 0</pose>
      <inertial>
        <pose frame="">0 0 0.037 0 -0 0</pose>
        <mass>1.5</mass>
        <inertia>
          <ixx>0.0120</ixx>
          <iyy>0.0089</iyy>
          <izz>0.0113</izz>
        </inertia>
      </inertial>
      <collision name="base_link_inertia_collision">
        <pose frame="">0 0 0.037 0 -0 0</pose>
        <geometry>
          <box>
            <size>0.18 0.24 0.196</size>
          </box>
        </geometry>
      </collision>
      
      
      <visual name="body_visual">
        <pose>0.0 0.0 0.014 0 0 0</pose>
        <geometry>
	  <box>
	    <size>0.15 0.03 0.04</size>
	  </box>
        </geometry>
        <material>
	  <ambient>0.08 0.08 0.08 1</ambient>
	  <diffuse>0.08 0.08 0.08 1</diffuse>
        </material>
      </visual>

      <visual name="jetson_nano_visual">
        <pose>-0.02 0.0 -0.016 0 0 0</pose>
        <geometry>
	  <box>
	    <size>0.1 0.1 0.02</size>
	  </box>
        </geometry>
        <material>
	  <ambient>0.01 0.01 0.01 1</ambient>
	  <diffuse>0.01 0.01 0.01 1</diffuse>
        </material>
      </visual>
      <visual name="battery_visual">
        <pose>0.0 0.0 0.06 0 0 0</pose>
        <geometry>
	  <box>
	    <size>0.15 0.03 0.05</size>
	  </box>
        </geometry>
        <material>
	  <ambient>0.01 0.01 0.8 1</ambient>
	  <diffuse>0.01 0.01 0.8 1</diffuse>
        </material>
      </visual>
      
      
      <visual name="antenna1_visual">
        <pose>0.03 -0.02 0.085 0 0 0</pose>
        <geometry>
	  <cylinder>
            <length>0.1</length>
            <radius>0.005</radius>
	  </cylinder>
        </geometry>
      </visual>
      <visual name="antenna2_visual">
        <pose>-0.06 -0.02 0.085 0 0 0</pose>
        <geometry>
	  <cylinder>
            <length>0.1</length>
            <radius>0.005</radius>
	  </cylinder>
        </geometry>
        <material>
	  <ambient>0.06 0.06 0.06 1</ambient>
	  <diffuse>0.06 0.06 0.06 1</diffuse>
        </material>
      </visual>


      <visual name="landing_gear1_visual">
        <pose>0.09 0.12 -0.033 0 0 0</pose>
        <geometry>
	  <cylinder>
            <length>0.055</length>
            <radius>0.004</radius>
	  </cylinder>
        </geometry>
        <material>
	  <ambient>0.06 0.06 0.06 1</ambient>
	  <diffuse>0.06 0.06 0.06 1</diffuse>
        </material>
      </visual>
      <visual name="landing_gear2_visual">
        <pose>0.09 -0.12 -0.033 0 0 0</pose>
        <geometry>
	  <cylinder>
            <length>0.055</length>
            <radius>0.004</radius>
	  </cylinder>
        </geometry>
        <material>
	  <ambient>0.06 0.06 0.06 1</ambient>
	  <diffuse>0.06 0.06 0.06 1</diffuse>
        </material>
      </visual>
      <visual name="landing_gear3_visual">
        <pose>-0.09 0.12 -0.033 0 0 0</pose>
        <geometry>
	  <cylinder>
            <length>0.055</length>
            <radius>0.004</radius>
	  </cylinder>
        </geometry>
        <material>
	  <ambient>0.06 0.06 0.06 1</ambient>
	  <diffuse>0.06 0.06 0.06 1</diffuse>
        </material>
      </visual>
      <visual name="landing_gear4_visual">
        <pose>-0.09 -0.12 -0.033 0 0 0</pose>
        <geometry>
	  <cylinder>
            <length>0.055</length>
            <radius>0.004</radius>
	  </cylinder>
        </geometry>
        <material>
	  <ambient>0.06 0.06 0.06 1</ambient>
	  <diffuse>0.06 0.06 0.06 1</diffuse>
        </material>
      </visual>



      <visual name="arm1_visual">
        <pose>0.057 0.067 -0.003 0 0 1</pose>
        <geometry>
	  <box>
	    <size>0.15 0.015 0.006</size>
	  </box>
        </geometry>
        <material>
	  <ambient>0.06 0.06 0.06 1</ambient>
	  <diffuse>0.06 0.06 0.06 1</diffuse>
        </material>
      </visual>
      <visual name="arm2_visual">
        <pose>0.057 -0.067 -0.003 0 0 -1</pose>
        <geometry>
	  <box>
	    <size>0.15 0.015 0.006</size>
	  </box>
        </geometry>
        <material>
	  <ambient>0.06 0.06 0.06 1</ambient>
	  <diffuse>0.06 0.06 0.06 1</diffuse>
        </material>
      </visual>
      <visual name="arm3_visual">
        <pose>-0.057 0.067 -0.003 0 0 -1</pose>
        <geometry>
	  <box>
	    <size>0.15 0.015 0.006</size>
	  </box>
        </geometry>
        <material>
	  <ambient>0.06 0.06 0.06 1</ambient>
	  <diffuse>0.06 0.06 0.06 1</diffuse>
        </material>
      </visual>
      <visual name="arm4_visual">
        <pose>-0.057 -0.067 -0.003 0 0 1</pose>
        <geometry>
	  <box>
	    <size>0.15 0.015 0.006</size>
	  </box>
        </geometry>
        <material>
	  <ambient>0.06 0.06 0.06 1</ambient>
	  <diffuse>0.06 0.06 0.06 1</diffuse>
        </material>
      </visual>


      <visual name="motor1_visual">
        <pose>0.09 0.12 0.01 0 0 0</pose>
        <geometry>
	  <cylinder>
            <length>0.02</length>
            <radius>0.015</radius>
	  </cylinder>
        </geometry>
        <material>
	  <ambient>0.08 0.08 0.08 1</ambient>
	  <diffuse>0.08 0.08 0.08 1</diffuse>
        </material>
      </visual>
      <visual name="motor2_visual">
        <pose>-0.09 0.12 0.01 0 0 0</pose>
        <geometry>
	  <cylinder>
            <length>0.02</length>
            <radius>0.015</radius>
	  </cylinder>
        </geometry>
        <material>
	  <ambient>0.08 0.08 0.08 1</ambient>
	  <diffuse>0.08 0.08 0.08 1</diffuse>
        </material>
      </visual>
      <visual name="motor3_visual">
        <pose>0.09 -0.12 0.01 0 0 0</pose>
        <geometry>
	  <cylinder>
            <length>0.02</length>
            <radius>0.015</radius>
	  </cylinder>
        </geometry>
        <material>
	  <ambient>0.08 0.08 0.08 1</ambient>
	  <diffuse>0.08 0.08 0.08 1</diffuse>
        </material>
      </visual>
      <visual name="motor4_visual">
        <pose>-0.09 -0.12 0.01 0 0 0</pose>
        <geometry>
	  <cylinder>
            <length>0.02</length>
            <radius>0.015</radius>
	  </cylinder>
        </geometry>
        <material>
	  <ambient>0.08 0.08 0.08 1</ambient>
	  <diffuse>0.08 0.08 0.08 1</diffuse>
        </material>
      </visual>


      <visual name="lightbar_visual">
        <pose>0.076 0.0 0.065 0 0 0</pose>
        <geometry>
	  <box>
	    <size>0.001 0.02 0.04</size>
	  </box>
        </geometry>
        <material>
	  <ambient>0.8 0.8 0.8 1</ambient>
	  <diffuse>0.8 0.8 0.8 1</diffuse>
        </material>
      </visual>

	    
      <light name="light_source1" type="spot">
        <pose frame="">0.09 0.01 0.065 -0.01 -1.570796327 0.75</pose>
        <attenuation>
          <range>15</range>
          <linear>0</linear>
          <constant>0.1</constant>
          <quadratic>0.01</quadratic>
        </attenuation>
        <diffuse>0.8 0.8 0.5 1</diffuse>
        <specular>0.8 0.8 0.5 1</specular>
        <spot>
          <inner_angle>1.5</inner_angle>
          <outer_angle>2.5</outer_angle>
          <falloff>1</falloff>
        </spot>
        <direction>0 0 -1</direction>
        <cast_shadows>1</cast_shadows>
      </light>
      <light name="light_source2" type="spot">
        <pose frame="">0.09 -0.01 0.065 -0.01 -1.570796327 -0.750</pose>
        <attenuation>
          <range>15</range>
          <linear>0</linear>
          <constant>0.1</constant>
          <quadratic>0.01</quadratic>
        </attenuation>
        <diffuse>0.8 0.8 0.5 1</diffuse>
        <specular>0.8 0.8 0.5 1</specular>
        <spot>
          <inner_angle>1.5</inner_angle>
          <outer_angle>2.5</outer_angle>
          <falloff>1</falloff>
        </spot>
        <direction>0 0 -1</direction>
        <cast_shadows>1</cast_shadows>
      </light>

      <sensor name="imu_sensor" type="imu">
        <always_on>1</always_on>
        <update_rate>250</update_rate>
        <imu>
          <angular_velocity>
            <x>
              <noise type="gaussian">
                <mean>0</mean>
                <stddev>0.009</stddev>
                <bias_mean>0.00075</bias_mean>
                <bias_stddev>0.005</bias_stddev>
                <dynamic_bias_stddev>0.00002</dynamic_bias_stddev>
                <dynamic_bias_correlation_time>400.0</dynamic_bias_correlation_time>
                <precision>0.00025</precision>
              </noise>
            </x>
            <y>
              <noise type="gaussian">
                <mean>0</mean>
                <stddev>0.009</stddev>
                <bias_mean>0.00075</bias_mean>
                <bias_stddev>0.005</bias_stddev>
                <dynamic_bias_stddev>0.00002</dynamic_bias_stddev>
                <dynamic_bias_correlation_time>400.0</dynamic_bias_correlation_time>
                <precision>0.00025</precision>
              </noise>
            </y>
            <z>
              <noise type="gaussian">
                <mean>0</mean>
                <stddev>0.009</stddev>
                <bias_mean>0.00075</bias_mean>
                <bias_stddev>0.005</bias_stddev>
                <dynamic_bias_stddev>0.00002</dynamic_bias_stddev>
                <dynamic_bias_correlation_time>400.0</dynamic_bias_correlation_time>
                <precision>0.00025</precision>
              </noise>
            </z>
          </angular_velocity>
          <linear_acceleration>
            <x>
              <noise type="gaussian">
                <mean>0</mean>
                <stddev>0.021</stddev>
                <bias_mean>0.05</bias_mean>
                <bias_stddev>0.0075</bias_stddev>
                <dynamic_bias_stddev>0.000375</dynamic_bias_stddev>
                <dynamic_bias_correlation_time>175.0</dynamic_bias_correlation_time>
                <precision>0.005</precision>
              </noise>
            </x>
            <y>
              <noise type="gaussian">
                <mean>0</mean>
                <stddev>0.021</stddev>
                <bias_mean>0.05</bias_mean>
                <bias_stddev>0.0075</bias_stddev>
                <dynamic_bias_stddev>0.000375</dynamic_bias_stddev>
                <dynamic_bias_correlation_time>175.0</dynamic_bias_correlation_time>
                <precision>0.005</precision>
              </noise>
            </y>
            <z>
              <noise type="gaussian">
                <mean>0</mean>
                <stddev>0.021</stddev>
                <bias_mean>0.05</bias_mean>
                <bias_stddev>0.0075</bias_stddev>
                <dynamic_bias_stddev>0.000375</dynamic_bias_stddev>
                <dynamic_bias_correlation_time>175.0</dynamic_bias_correlation_time>
                <precision>0.005</precision>
              </noise>
            </z>
          </linear_acceleration>
        </imu>
      </sensor>
      <sensor name="air_pressure" type="air_pressure">
        <always_on>1</always_on>
        <update_rate>20</update_rate>
        <air_pressure>
          <reference_altitude>0</reference_altitude>
          <noise type="gaussian">
            <mean>0.00000008</mean>
          </noise>
        </air_pressure>
      </sensor>
      <sensor name="magnetometer" type="magnetometer">
        <always_on>1</always_on>
        <update_rate>20</update_rate>
        <magnetometer>
          <x>
            <noise type="gaussian">
              <mean>0.000000080</mean>
              <bias_mean>0.000000400</bias_mean>
            </noise>
          </x>
          <y>
            <noise type="gaussian">
              <mean>0.000000080</mean>
              <bias_mean>0.000000400</bias_mean>
            </noise>
          </y>
          <z>
            <noise type="gaussian">
              <mean>0.000000080</mean>
              <bias_mean>0.000000400</bias_mean>
            </noise>
          </z>
        </magnetometer>
      </sensor>


      <visual name="d435_dae_front_visual">
        <pose>0.075 0 -0.03 0 0 0</pose>
        <geometry>
	  <mesh>
	    <scale>0.001 0.001 0.001</scale>
	    <uri>meshes/realsense_d435.dae</uri>
	  </mesh>
        </geometry>
      </visual>
	    
      <sensor name="rgbd_front" type="rgbd_camera">
        <pose>0.102 0 -0.018 0 0 0</pose>
        <always_on>1</always_on>
        <update_rate>30</update_rate>
        <camera name="rgbd_front">
          <horizontal_fov>1.50098</horizontal_fov>
          <lens>
            <intrinsics>
              <!-- fx = fy = width / ( 2 * tan (hfov / 2 ) ) -->
              <fx>343.159</fx>
              <fy>343.159</fy>
              <!-- cx = ( width - 1 ) / 2 -->
              <cx>319.5</cx>
              <!-- cy = ( height - 1 ) / 2 -->
              <cy>179.5</cy>
              <s>0</s>
            </intrinsics>
          </lens>
          <distortion>
            <k1>0.0</k1>
            <k2>0.0</k2>
            <k3>0.0</k3>
            <p1>0.0</p1>
            <p2>0.0</p2>
            <center>0.5 0.5</center>
          </distortion>
          <image>
            <width>640</width>
            <height>360</height>
            <format>R8G8B8</format>
          </image>
          <clip>
            <near>0.01</near>
            <far>300</far>
          </clip>
          <depth_camera>
            <clip>
              <near>0.1</near>
              <far>10</far>
            </clip>
          </depth_camera>
          <noise>
            <type>gaussian</type>
            <mean>0</mean>
            <stddev>0.007</stddev>
          </noise>
        </camera>
      </sensor>


      <visual name="camera_left_visual">
        <pose>0.085 -0.015 0.03 0 0 0.785398163</pose>
        <geometry>
          <box>
            <size>0.01 0.02 0.02</size>
          </box>
        </geometry>
        <material>
          <ambient>0.0 0.2 0.0 1.0</ambient>
          <diffuse>0.0 0.2 0.0 1.0</diffuse>
        </material>
      </visual>
      <visual name="camera_lens_left_visual">
        <pose>0.092 -0.008 0.03 0 1.5707963267948966 0.785398163</pose>
        <geometry>
          <cylinder>
            <length>0.011</length>
            <radius>0.005</radius>
          </cylinder>
        </geometry>
        <material>
          <ambient>0.0 0.0 0.0 1.0</ambient>
          <diffuse>0.0 0.0 0.0 1.0</diffuse>
        </material>
      </visual>

      <visual name="camera_right_visual">
        <pose>0.085 0.015 0.03 0 0 -0.785398163</pose>
        <geometry>
          <box>
            <size>0.01 0.02 0.02</size>
          </box>
        </geometry>
        <material>
          <ambient>0.0 0.2 0.0 1.0</ambient>
          <diffuse>0.0 0.2 0.0 1.0</diffuse>
        </material>
      </visual>
      <visual name="camera_lens_right_visual">
        <pose>0.092 0.008 0.03 0 1.5707963267948966 -0.785398163</pose>
        <geometry>
          <cylinder>
            <length>0.011</length>
            <radius>0.005</radius>
          </cylinder>
        </geometry>
        <material>
          <ambient>0.0 0.0 0.0 1.0</ambient>
          <diffuse>0.0 0.0 0.0 1.0</diffuse>
        </material>
      </visual>


      <!-- Physical robot has B0247 with LN008 with a 180 deg hor x 130 deg vert FOV
           Since fisheye cameras are not modeled, two cameras are used in the model -->
      <sensor name="camera_left" type="camera">
        <pose>0.098 -0.002 0.03 0 0 0.785398163</pose>
        <always_on>1</always_on>
        <update_rate>25</update_rate>
        <camera name="camera_left">
          <horizontal_fov>1.658</horizontal_fov>
          <lens>
            <intrinsics>
              <!-- fx = fy = width / ( 2 * tan (hfov / 2 ) ) -->
              <fx>329.9</fx>
              <fy>329.9</fy>
              <!-- cx = ( width - 1 ) / 2 -->
              <cx>359.5</cx>
              <!-- cy = ( height - 1 ) / 2 -->
              <cy>539.5</cy>
              <s>0</s>
            </intrinsics>
          </lens>
          <distortion>
            <k1>0.0</k1>
            <k2>0.0</k2>
            <k3>0.0</k3>
            <p1>0.0</p1>
            <p2>0.0</p2>
            <center>0.5 0.5</center>
          </distortion>
          <image>
            <width>720</width>
            <height>1080</height>
            <format>R8G8B8</format>
          </image>
          <clip>
            <near>0.01</near>
            <far>300</far>
          </clip>
          <noise>
            <type>gaussian</type>
            <mean>0</mean>
            <stddev>0.007</stddev>
          </noise>
        </camera>
      </sensor>

      <sensor name="camera_right" type="camera">
        <pose>0.098 0.002 0.03 0 0 -0.785398163</pose>
        <always_on>1</always_on>
        <update_rate>25</update_rate>
        <camera name="camera_right">
          <horizontal_fov>1.658</horizontal_fov>
          <lens>
            <intrinsics>
              <!-- fx = fy = width / ( 2 * tan (hfov / 2 ) ) -->
              <fx>329.9</fx>
              <fy>329.9</fy>
              <!-- cx = ( width - 1 ) / 2 -->
              <cx>359.5</cx>
              <!-- cy = ( height - 1 ) / 2 -->
              <cy>539.5</cy>
              <s>0</s>
            </intrinsics>
          </lens>
          <distortion>
            <k1>0.0</k1>
            <k2>0.0</k2>
            <k3>0.0</k3>
            <p1>0.0</p1>
            <p2>0.0</p2>
            <center>0.5 0.5</center>
          </distortion>
          <image>
            <width>720</width>
            <height>1080</height>
            <format>R8G8B8</format>
          </image>
          <clip>
            <near>0.01</near>
            <far>300</far>
          </clip>
          <noise>
            <type>gaussian</type>
            <mean>0</mean>
            <stddev>0.007</stddev>
          </noise>
        </camera>
      </sensor>


      <sensor name="bottom_laser" type="gpu_ray">
        <pose>-0.065 -0.08 -0.01 0 -1.57 0</pose>
        <update_rate>50</update_rate>
        <lidar>
          <scan>
            <horizontal>
              <samples>1</samples>
              <resolution>1</resolution>
              <min_angle>3.141592654</min_angle>
              <max_angle>3.141592654</max_angle>
            </horizontal>
          </scan>
          <range>
            <min>0.05</min>
            <max>40</max>
            <resolution>0.01</resolution>
          </range>
          <noise>
            <type>gaussian</type>
            <mean>0</mean>
            <stddev>0.01</stddev>
          </noise>
        </lidar>
      </sensor>
    </link>
	  
    <link name="rotor_0">
      <pose frame="">0.09 -0.12 0.03 0 -0 0</pose>
      <inertial>
        <pose frame="">0 0 0 0 -0 0</pose>
        <mass>0.008</mass>
        <inertia>
          <ixx>1e-07</ixx>
          <ixy>0</ixy>
          <ixz>0</ixz>
          <iyy>5e-06</iyy>
          <iyz>0</iyz>
          <izz>5e-06</izz>
        </inertia>
      </inertial>
      <collision name="rotor_0_collision">
        <pose frame="">0 0 0 0 -0 0</pose>
        <geometry>
          <cylinder>
            <length>0.01</length>
            <radius>0.09</radius>
          </cylinder>
        </geometry>
        <surface>
          <contact>
            <ode/>
          </contact>
          <friction>
            <ode/>
          </friction>
        </surface>
      </collision>
      <visual name="rotor_0_visual">
        <pose frame="">0 0 0 0 -0 0</pose>
        <geometry>
          <mesh>
            <scale>0.09 0.09 0.09</scale>
            <uri>meshes/propeller_ccw.dae</uri>
          </mesh>
        </geometry>
        <material>
          <diffuse>0.5 0.5 0.5 1</diffuse>
          <script>
            <name>Gazebo/Grey</name>
            <uri>file://media/materials/scripts/gazebo.material</uri>
          </script>
        </material>
        <cast_shadows>0</cast_shadows>
      </visual>
      <gravity>1</gravity>
      <velocity_decay/>
    </link>
    <joint name="rotor_0_joint" type="revolute">
      <child>rotor_0</child>
      <parent>base_link</parent>
      <axis>
        <xyz>0 0 1</xyz>
        <limit>
          <lower>-1e+16</lower>
          <upper>1e+16</upper>
        </limit>
        <dynamics>
          <spring_reference>0</spring_reference>
          <spring_stiffness>0</spring_stiffness>
        </dynamics>
        <use_parent_model_frame>1</use_parent_model_frame>
      </axis>
    </joint>
    <link name="rotor_1">
      <pose frame="">-0.09 0.12 0.03 0 -0 0</pose>
      <inertial>
        <pose frame="">0 0 0 0 -0 0</pose>
        <mass>0.008</mass>
        <inertia>
          <ixx>1e-07</ixx>
          <ixy>0</ixy>
          <ixz>0</ixz>
          <iyy>5e-06</iyy>
          <iyz>0</iyz>
          <izz>5e-06</izz>
        </inertia>
      </inertial>
      <collision name="rotor_1_collision">
        <pose frame="">0 0 0 0 -0 0</pose>
        <geometry>
          <cylinder>
            <length>0.01</length>
            <radius>0.09</radius>
          </cylinder>
        </geometry>
        <surface>
          <contact>
            <ode/>
          </contact>
          <friction>
            <ode/>
          </friction>
        </surface>
      </collision>
      <visual name="rotor_1_visual">
        <pose frame="">0 0 0 0 -0 0</pose>
        <geometry>
          <mesh>
            <scale>0.09 0.09 0.09</scale>
            <uri>meshes/propeller_ccw.dae</uri>
          </mesh>
        </geometry>
        <material>
          <diffuse>0.5 0.5 0.5 1</diffuse>
          <script>
            <name>Gazebo/Grey</name>
            <uri>file://media/materials/scripts/gazebo.material</uri>
          </script>
        </material>
        <cast_shadows>0</cast_shadows>
      </visual>
      <gravity>1</gravity>
      <velocity_decay/>
    </link>
    <joint name="rotor_1_joint" type="revolute">
      <child>rotor_1</child>
      <parent>base_link</parent>
      <axis>
        <xyz>0 0 1</xyz>
        <limit>
          <lower>-1e+16</lower>
          <upper>1e+16</upper>
        </limit>
        <dynamics>
          <spring_reference>0</spring_reference>
          <spring_stiffness>0</spring_stiffness>
        </dynamics>
        <use_parent_model_frame>1</use_parent_model_frame>
      </axis>
    </joint>
    <link name="rotor_2">
      <pose frame="">0.09 0.12 0.03 0 -0 0</pose>
      <inertial>
        <pose frame="">0 0 0 0 -0 0</pose>
        <mass>0.008</mass>
        <inertia>
          <ixx>1e-07</ixx>
          <ixy>0</ixy>
          <ixz>0</ixz>
          <iyy>5e-06</iyy>
          <iyz>0</iyz>
          <izz>5e-06</izz>
        </inertia>
      </inertial>
      <collision name="rotor_2_collision">
        <pose frame="">0 0 0 0 -0 0</pose>
        <geometry>
          <cylinder>
            <length>0.01</length>
            <radius>0.09</radius>
          </cylinder>
        </geometry>
        <surface>
          <contact>
            <ode/>
          </contact>
          <friction>
            <ode/>
          </friction>
        </surface>
      </collision>
      <visual name="rotor_2_visual">
        <pose frame="">0 0 0 0 -0 0</pose>
        <geometry>
          <mesh>
            <scale>0.09 0.09 0.09</scale>
            <uri>meshes/propeller_cw.dae</uri>
          </mesh>
        </geometry>
        <material>
          <diffuse>0.5 0.5 0.5 1</diffuse>
          <script>
            <name>Gazebo/Grey</name>
            <uri>file://media/materials/scripts/gazebo.material</uri>
          </script>
        </material>
        <cast_shadows>0</cast_shadows>
      </visual>
      <gravity>1</gravity>
      <velocity_decay/>
    </link>
    <joint name="rotor_2_joint" type="revolute">
      <child>rotor_2</child>
      <parent>base_link</parent>
      <axis>
        <xyz>0 0 1</xyz>
        <limit>
          <lower>-1e+16</lower>
          <upper>1e+16</upper>
        </limit>
        <dynamics>
          <spring_reference>0</spring_reference>
          <spring_stiffness>0</spring_stiffness>
        </dynamics>
        <use_parent_model_frame>1</use_parent_model_frame>
      </axis>
    </joint>
    <link name="rotor_3">
      <pose frame="">-0.09 -0.12 0.03 0 -0 0</pose>
      <inertial>
        <pose frame="">0 0 0 0 -0 0</pose>
        <mass>0.008</mass>
        <inertia>
          <ixx>1e-07</ixx>
          <ixy>0</ixy>
          <ixz>0</ixz>
          <iyy>5e-06</iyy>
          <iyz>0</iyz>
          <izz>5e-06</izz>
        </inertia>
      </inertial>
      <collision name="rotor_3_collision">
        <pose frame="">0 0 0 0 -0 0</pose>
        <geometry>
          <cylinder>
            <length>0.01</length>
            <radius>0.09</radius>
          </cylinder>
        </geometry>
        <surface>
          <contact>
            <ode/>
          </contact>
          <friction>
            <ode/>
          </friction>
        </surface>
      </collision>
      <visual name="rotor_3_visual">
        <pose frame="">0 0 0 0 -0 0</pose>
        <geometry>
          <mesh>
            <scale>0.09 0.09 0.09</scale>
            <uri>meshes/propeller_cw.dae</uri>
          </mesh>
        </geometry>
        <material>
          <diffuse>0.5 0.5 0.5 1</diffuse>
          <script>
            <name>Gazebo/Grey</name>
            <uri>file://media/materials/scripts/gazebo.material</uri>
          </script>
        </material>
        <cast_shadows>0</cast_shadows>
      </visual>
      <gravity>1</gravity>
      <velocity_decay/>
    </link>
    <joint name="rotor_3_joint" type="revolute">
      <child>rotor_3</child>
      <parent>base_link</parent>
      <axis>
        <xyz>0 0 1</xyz>
        <limit>
          <lower>-1e+16</lower>
          <upper>1e+16</upper>
        </limit>
        <dynamics>
          <spring_reference>0</spring_reference>
          <spring_stiffness>0</spring_stiffness>
        </dynamics>
        <use_parent_model_frame>1</use_parent_model_frame>
      </axis>
    </joint>
  </model>
</sdf>
