<?xml version='1.0' encoding='utf-8'?>
<robot name="ds1" xmlns:xacro="http://ros.org/wiki/xacro">

  <xacro:arg name="name" default="ds1"/>
  <xacro:property name="name" value="$(arg name)"/>

  <link name='${name}/base_link'>
    <inertial>
      <origin xyz='0 0 0' rpy='0 -0 0'/>
      <mass value='1.5'/>
      <inertia ixx='0.025' ixy='0' ixz='0' iyy='0.009' iyz='0' izz='0.033'/>
    </inertial>
    <collision name='base_link_inertia_collision'>
      <origin xyz='0 0 0' rpy='0 -0 0'/>
      <geometry>
        <mesh filename='package://explorer_ds1_sensor_config_1/meshes/DS1_COLLISION.STL' scale='1 1 1'/>
      </geometry>
    </collision>

    <visual name='base_link_inertia_visual'>
      <origin xyz='0 0 0' rpy='0 -0 0'/>
      <geometry>
        <mesh filename='package://explorer_ds1_sensor_config_1/meshes/DS1.dae' scale='1 1 1'/>
      </geometry>
    </visual>
    <!-- camera_visual -->
    <visual name='rs_up_visual'>
      <origin xyz='0.305 0 0.11' rpy='-1.57079632679 0 1.57079632679'/>
      <geometry>
        <mesh filename='package://explorer_ds1_sensor_config_1/meshes/realsense.dae' scale='1 1 1'/>
      </geometry>
    </visual>
    <visual name='rs_down_visual'>
      <origin xyz='0.305 0 0.03' rpy='1.57079632679 0 1.57079632679'/>
      <geometry>
        <mesh filename='package://explorer_ds1_sensor_config_1/meshes/realsense.dae' scale='1 1 1'/>
      </geometry>
    </visual>
    <visual name='rs_front_visual'>
      <origin xyz='0.325 0 0.07' rpy='0 -0 1.57079632679'/>
      <geometry>
        <mesh filename='package://explorer_ds1_sensor_config_1/meshes/realsense.dae' scale='1 1 1'/>
      </geometry>
    </visual>
    <!-- Lidar visual -->
    <visual name='laser_visual_base1'>
      <origin xyz='0.18 0 0.19' rpy='0 -0 0'/>
      <geometry>
        <mesh filename="package://explorer_ds1_sensor_config_1/meshes/VLP16_base_1.dae" />
      </geometry>
    </visual>
    <visual name='laser_visual_base2'>
      <origin xyz='0.18 0 0.19' rpy='0 -0 0'/>
      <geometry>
        <mesh filename="package://explorer_ds1_sensor_config_1/meshes/VLP16_base_2.dae" />
      </geometry>
    </visual>
    <visual name='laser_visual_scan'>
      <origin xyz='0.18 0 0.19' rpy='0 -0 0'/>
      <geometry>
        <mesh filename="package://explorer_ds1_sensor_config_1/meshes/VLP16_scan.dae" />
      </geometry>
    </visual>
  </link>

  <sensor name='imu_sensor' update_rate='250'>
    <parent link='${name}/base_link'/>
    <origin xyz='0 0 0' rpy='0 -0 0'/>
  </sensor>
  
  <sensor name='air_pressure' update_rate='20'>
    <parent link='${name}/base_link'/>
    <origin xyz='0 0 0' rpy='0 -0 0'/>
  </sensor>

  <sensor name='magnetometer' update_rate='20'>
    <parent link='${name}/base_link'/>
    <origin xyz='0 0 0' rpy='0 -0 0'/>
  </sensor>

  <sensor name='rs_up' update_rate='20'>
    <parent link='${name}/base_link'/>
    <origin xyz='0.305 0 0.11' rpy='0 -1.57079632679 0'/>
    <camera>
      <image width='640' height='480' format='R8G8B8' hfov='1.0472' near='0.01' far='300' />
    </camera>
  </sensor>

  <sensor name='rs_down' update_rate='20'>
    <parent link='${name}/base_link'/>
    <origin xyz='0.305 0 0.03' rpy='0 1.57079632679 0'/>
    <camera>
      <image width='640' height='480' format='R8G8B8' hfov='1.0472' near='0.01' far='300' />
    </camera>
  </sensor>

  <sensor name='rs_front' update_rate='20'>
    <parent link='${name}/base_link'/>
    <origin xyz='0.325 0 0.07' rpy='0 -0 0'/>
    <camera>
      <image width='640' height='480' format='R8G8B8' hfov='1.0472' near='0.01' far='300' />
    </camera>
  </sensor>

  <sensor name='front_laser' update_rate='15'>
    <parent link='${name}/base_link'/>
    <origin xyz='0.18 0 0.284' rpy='0 -0 0'/>
  </sensor>

  <link name='${name}/rotor_0'>
    <inertial>
      <origin xyz='0 0 0' rpy='0 -0 0'/>
      <mass value='0.005'/>
      <inertia ixx='9.75e-07' ixy='0' ixz='0' iyy='4.17041e-05' iyz='0' izz='4.26041e-05'/>
    </inertial>
    <visual name='rotor_0_visual'>
      <origin xyz='0 0 0' rpy='0 -0 0'/>
      <geometry>
        <mesh filename='package://explorer_ds1_sensor_config_1/meshes/propeller_ccw.dae' scale='0.12 0.12 0.12'/>
      </geometry>
    </visual>
  </link>

  <link name='${name}/rotor_1'>
    <inertial>
      <origin xyz='0 0 0' rpy='0 -0 0'/>
      <mass value='0.005'/>
      <inertia ixx='9.75e-07' ixy='0' ixz='0' iyy='4.17041e-05' iyz='0' izz='4.26041e-05'/>
    </inertial>
    <visual name='rotor_1_visual'>
      <origin xyz='0 0 0' rpy='0 -0 0'/>
      <geometry>
        <mesh filename='package://explorer_ds1_sensor_config_1/meshes/propeller_ccw.dae' scale='0.12 0.12 0.12'/>
      </geometry>
    </visual>
  </link>

  <link name='${name}/rotor_2'>
    <inertial>
      <origin xyz='0 0 0' rpy='0 -0 0'/>
      <mass value='0.005'/>
      <inertia ixx='9.75e-07' ixy='0' ixz='0' iyy='4.17041e-05' iyz='0' izz='4.26041e-05'/>
    </inertial>
    <visual name='rotor_2_visual'>
      <origin xyz='0 0 0' rpy='0 -0 0'/>
      <geometry>
        <mesh filename='package://explorer_ds1_sensor_config_1/meshes/propeller_cw.dae' scale='0.12 0.12 0.12'/>
      </geometry>
    </visual>
  </link>

  <link name='${name}/rotor_3'>
    <inertial>
      <origin xyz='0 0 0' rpy='0 -0 0'/>
      <mass value='0.005'/>
      <inertia ixx='9.75e-07' ixy='0' ixz='0' iyy='4.17041e-05' iyz='0' izz='4.26041e-05'/>
    </inertial>
    <visual name='rotor_3_visual'>
      <origin xyz='0 0 0' rpy='0 -0 0'/>
      <geometry>
        <mesh filename='package://explorer_ds1_sensor_config_1/meshes/propeller_cw.dae' scale='0.12 0.12 0.12'/>
      </geometry>
    </visual>
  </link>

  <joint name='rotor_0_joint' type='revolute'>
    <origin xyz='0.1644 -0.166 0.023' rpy='0 -0 0'/>
    <parent link='${name}/base_link'/>
    <child link='${name}/rotor_0'/>
    <dynamics damping='0' friction='0' />
    <axis xyz='0 0 1'/>
    <limit lower='-1e+16' upper='1e+16' effort='-1' velocity='-1'/>
  </joint>

  <joint name='rotor_1_joint' type='revolute'>
    <origin xyz='-0.16443 0.1661 0.023' rpy='0 -0 0'/>
    <parent link='${name}/base_link'/>
    <child link='${name}/rotor_1'/>
    <dynamics damping='0' friction='0' />
    <axis xyz='0 0 1'/>
    <limit lower='-1e+16' upper='1e+16' effort='-1' velocity='-1'/>
  </joint>

  <joint name='rotor_2_joint' type='revolute'>
    <origin xyz='0.16443 0.1661 0.023' rpy='0 -0 0'/>
    <parent link='${name}/base_link'/>
    <child link='${name}/rotor_2'/>
    <dynamics damping='0' friction='0' />
    <axis xyz='0 0 1'/>
    <limit lower='-1e+16' upper='1e+16' effort='-1' velocity='-1'/>
  </joint>
  
  <joint name='rotor_3_joint' type='revolute'>
    <origin xyz='-0.16443 -0.1661 0.023' rpy='0 -0 0'/>
    <parent link='${name}/base_link'/>
    <child link='${name}/rotor_3'/>
    <dynamics damping='0' friction='0' />
    <axis xyz='0 0 1'/>
    <limit lower='-1e+16' upper='1e+16' effort='-1' velocity='-1'/>
  </joint>
</robot>
