<?xml version="1.0"?>
<sdf version="1.6">
  <model name="explorer_x1_sensor_config_1">
    <link name="base_link">
      <pose frame="">0 0 0 0 -0 0</pose>
      <inertial>
        <pose frame="">-0.000649 -0.084999 0.062001 0 -0 0</pose>
        <mass>46.0344</mass>
        <inertia>
          <ixx>0.63323</ixx>
          <ixy>-0.0236421</ixy>
          <ixz>-0.119707</ixz>
          <iyy>1.76965</iyy>
          <iyz>-0.00154755</iyz>
          <izz>2.06066</izz>
        </inertia>
      </inertial>
      <collision name="base_link_collision">
        <pose frame="">0 0 0.12 0 0 0</pose>
        <geometry>
          <box>
            <size>0.9874 0.5709 0.05</size>
          </box>
        </geometry>
      </collision>
      <collision name="base_link_collision_bottom">
        <pose frame="">0 0 0.046 0 0 0</pose>
        <geometry>
          <box>
            <size>0.80 0.5709 0.095</size>
          </box>
        </geometry>
      </collision>
      <collision name="base_link_collision_1">
        <pose frame="">0 0 0.185625 0 -0 0</pose>
        <geometry>
          <box>
            <size>0.78992 0.5709 0.12375</size>
          </box>
        </geometry>
      </collision>
      <collision name="base_link_fixed_joint_lump__front_realsense_link_collision_2">
        <pose frame="">0.4 0 0.3 0 -0 0</pose>
        <geometry>
          <box>
            <size>0.07 0.3 0.09</size>
          </box>
        </geometry>
        <surface>
          <contact>
            <ode/>
          </contact>
          <friction>
            <ode/>
          </friction>
        </surface>
      </collision>
      <collision name="base_link_fixed_joint_lump__left_realsense_link_collision_3">
        <pose frame="">0.3 0.2 0.3 0 -0 1.57</pose>
        <geometry>
          <box>
            <size>0.07 0.3 0.09</size>
          </box>
        </geometry>
        <surface>
          <contact>
            <ode/>
          </contact>
          <friction>
            <ode/>
          </friction>
        </surface>
      </collision>
      <collision name="base_link_fixed_joint_lump__rear_realsense_link_collision_4">
        <pose frame="">0.2 0 0.3 0 -0 3.14</pose>
        <geometry>
          <box>
            <size>0.07 0.3 0.09</size>
          </box>
        </geometry>
        <surface>
          <contact>
            <ode/>
          </contact>
          <friction>
            <ode/>
          </friction>
        </surface>
      </collision>
      <collision name="base_link_fixed_joint_lump__right_realsense_link_collision_5">
        <pose frame="">0.3 -0.2 0.3 0 0 -1.57</pose>
        <geometry>
          <box>
            <size>0.07 0.3 0.09</size>
          </box>
        </geometry>
        <surface>
          <contact>
            <ode/>
          </contact>
          <friction>
            <ode/>
          </friction>
        </surface>
      </collision>
      <collision name="base_link_fixed_joint_lump__top_plate_link_collision_6">
        <pose frame="">0.0812 0 0.245 0 -0 0</pose>
        <geometry>
          <mesh>
            <scale>1 1 1</scale>
            <uri>meshes/top_plate.dae</uri>
          </mesh>
        </geometry>
      </collision>
      <collision name="base_link_fixed_joint_lump__top_plate_link_collision_7">
        <pose frame="">0.0812 0 0.245 0 -0 0</pose>
        <geometry>
          <box>
            <size>0.32 0.41 0.09</size>
          </box>
        </geometry>
      </collision>
      <visual name="base_link_visual">
        <pose frame="">0 0 0 1.57 0 1.57</pose>
        <material>
                    <diffuse>0.5 0.5 0.5 1</diffuse>
                    <ambient>.5 .5 .5 1</ambient>

                    <!-- <script>
                        <name>Gazebo/Blue</name>
                        <uri>file://media/materials/scripts/gazebo.material</uri>
                    </script> -->
                </material>
        <geometry>
          <mesh>
            <scale>1 1 1</scale>
            <uri>meshes/HD2_Urban_Assembly.stl</uri>
          </mesh>
        </geometry>
      </visual>
      <velocity_decay/>
      <!-- Based on Intel realsense D435 (intrinsics and distortion not modeled)-->
      <sensor name="camera_front" type="rgbd_camera">
        <camera name="camera_front">
            <horizontal_fov>1.5184</horizontal_fov>
            <lens>
                <intrinsics>
                    <!-- fx = fy = width / ( 2 * tan (hfov / 2 ) ) -->
                    <fx>277.1</fx>
                    <fy>277.1</fy>
                    <!-- cx = ( width + 1 ) / 2 -->
                    <cx>640.5</cx>
                    <!-- cy = ( height + 1 ) / 2 -->
                    <cy>360.5</cy>
                    <s>0</s>
                </intrinsics>
            </lens>
            <distortion>
                <k1>0.0</k1>
                <k2>0.0</k2>
                <k3>0.0</k3>
                <p1>0.0</p1>
                <p2>0.0</p2>
                <center>0.5 0.5</center>
            </distortion>
            <image>
                <width>1280</width>
                <height>720</height>
                <format>R8G8B8</format>
            </image>
            <clip>
                <near>0.01</near>
                <far>300</far>
            </clip>
            <depth_camera>
              <clip>
                <near>0.1</near>
                <far>10</far>
              </clip>
            </depth_camera>
            <noise>
                <type>gaussian</type>
                <mean>0</mean>
                <stddev>0.007</stddev>
            </noise>
        </camera>
        <always_on>1</always_on>
        <update_rate>30</update_rate>
        <visualize>0</visualize>
        <pose frame="">0.468 0 0.360 0 -0 0</pose>
      </sensor>
      <gravity>1</gravity>
      <velocity_decay/>
      <!-- Based on Intel realsense D435 (intrinsics and distortion not modeled)-->
      <sensor name="camera_down" type="rgbd_camera">
        <camera name="camera_down">
            <horizontal_fov>1.5184</horizontal_fov>
            <lens>
                <intrinsics>
                    <!-- fx = fy = width / ( 2 * tan (hfov / 2 ) ) -->
                    <fx>277.1</fx>
                    <fy>277.1</fy>
                    <!-- cx = ( width + 1 ) / 2 -->
                    <cx>640.5</cx>
                    <!-- cy = ( height + 1 ) / 2 -->
                    <cy>360.5</cy>
                    <s>0</s>
                </intrinsics>
            </lens>
            <distortion>
                <k1>0.0</k1>
                <k2>0.0</k2>
                <k3>0.0</k3>
                <p1>0.0</p1>
                <p2>0.0</p2>
                <center>0.5 0.5</center>
            </distortion>
            <image>
                <width>1280</width>
                <height>720</height>
                <format>R8G8B8</format>
            </image>
            <clip>
                <near>0.01</near>
                <far>300</far>
            </clip>
            <depth_camera>
              <clip>
                <near>0.1</near>
                <far>10</far>
              </clip>
            </depth_camera>
            <noise>
                <type>gaussian</type>
                <mean>0</mean>
                <stddev>0.007</stddev>
            </noise>
        </camera>
        <always_on>1</always_on>
        <update_rate>30</update_rate>
        <visualize>0</visualize>
        <pose frame="">0.473 0 0.335 0 0.5236 0</pose> <!-- 30 degree download look-->
      </sensor>
      <gravity>1</gravity>
      <velocity_decay/>
      <!-- Based on RPLidar S1 -->
      <sensor name="planar_laser" type="gpu_ray">
          <pose>0.474 0 0.127 0 -0 0</pose>
          <update_rate>10</update_rate>
          <lidar>
              <scan>
                  <horizontal>
                      <samples>920</samples>
                      <resolution>1</resolution>
                      <min_angle>-3.14159</min_angle>
                      <max_angle>3.14159</max_angle>
                  </horizontal>
              </scan>
              <range>
                  <min>0.04</min>
                  <max>25</max>
                  <resolution>0.03</resolution>
              </range>
              <noise>
                  <type>gaussian</type>
                  <mean>0</mean>
                  <stddev>0.01</stddev>
              </noise>
          </lidar>
      </sensor>
      <gravity>1</gravity>
      <velocity_decay/>

      <!-- OS1-64 3D Laser Configuration (10x2048 or 10x1024 or 20x1024 or 20x512 as possible (rate) x (hor. res.) configs)-->
      <sensor name="front_laser" type="gpu_lidar">
        <visualize>0</visualize>
        <update_rate>20</update_rate>
        <lidar>
          <scan>
            <horizontal>
              <!-- Resolution can't be above 16k, see
              https://bitbucket.org/ignitionrobotics/ign-sensors/issues/8 -->
              <samples>1024</samples>
              <resolution>0.1</resolution>
              <min_angle>-3.1459</min_angle>
              <max_angle>3.1459</max_angle>
            </horizontal>
            <vertical>
              <samples>64</samples>
              <resolution>1</resolution>
              <min_angle>-0.3927</min_angle>
              <max_angle>0.3927</max_angle>
            </vertical>
          </scan>
          <range>
            <min>0.025</min>
            <max>120</max>
            <resolution>0.01</resolution>
          </range>
          <noise>
            <type>gaussian</type>
            <mean>0</mean>
            <stddev>0.01</stddev>
          </noise>
        </lidar>
        <pose frame="">0.424 0 0.402 0 -0 0</pose>
      </sensor>
      <sensor name="imu_sensor" type="imu">
        <always_on>1</always_on>
        <update_rate>50</update_rate>
        <imu>
          <angular_velocity>
            <x>
              <noise type="gaussian">
                <mean>0</mean>
                <stddev>2e-4</stddev>
                <bias_mean>0.0000075</bias_mean>
                <bias_stddev>0.0000008</bias_stddev>
                <dynamic_bias_stddev>0.0000004</dynamic_bias_stddev>
                <dynamic_bias_correlation_time>1000.0</dynamic_bias_correlation_time>
              </noise>
            </x>
            <y>
              <noise type="gaussian">
                <mean>0</mean>
                <stddev>2e-4</stddev>
                <bias_mean>0.0000075</bias_mean>
                <bias_stddev>0.0000008</bias_stddev>
                <dynamic_bias_stddev>0.0000004</dynamic_bias_stddev>
                <dynamic_bias_correlation_time>1000.0</dynamic_bias_correlation_time>
              </noise>
            </y>
            <z>
              <noise type="gaussian">
                <mean>0</mean>
                <stddev>2e-4</stddev>
                <bias_mean>0.0000075</bias_mean>
                <bias_stddev>0.0000008</bias_stddev>
                <dynamic_bias_stddev>0.0000004</dynamic_bias_stddev>
                <dynamic_bias_correlation_time>1000.0</dynamic_bias_correlation_time>
              </noise>
            </z>
          </angular_velocity>
          <linear_acceleration>
            <x>
              <noise type="gaussian">
                <mean>0</mean>
                <stddev>1e-2</stddev>
                <bias_mean>0.1</bias_mean>
                <bias_stddev>0.001</bias_stddev>
                <dynamic_bias_stddev>0.002</dynamic_bias_stddev>
                <dynamic_bias_correlation_time>300.0</dynamic_bias_correlation_time>
              </noise>
            </x>
            <y>
              <noise type="gaussian">
                <mean>0</mean>
                <stddev>1e-2</stddev>
                <bias_mean>0.1</bias_mean>
                <bias_stddev>0.001</bias_stddev>
                <dynamic_bias_stddev>0.002</dynamic_bias_stddev>
                <dynamic_bias_correlation_time>300.0</dynamic_bias_correlation_time>
              </noise>
            </y>
            <z>
              <noise type="gaussian">
                <mean>0</mean>
                <stddev>1e-2</stddev>
                <bias_mean>0.1</bias_mean>
                <bias_stddev>0.001</bias_stddev>
                <dynamic_bias_stddev>0.002</dynamic_bias_stddev>
                <dynamic_bias_correlation_time>300.0</dynamic_bias_correlation_time>
              </noise>
            </z>
          </linear_acceleration>
        </imu>
      </sensor>
      <light name="left_headlight_body_light_source_light" type="spot">
        <pose frame="">0.514147 0.216803 0.180 3.14159 1.56859 0</pose>
        <attenuation>
          <range>50</range>
          <linear>0</linear>
          <constant>0.1</constant>
          <quadratic>0.0025</quadratic>
        </attenuation>
        <diffuse>1.0 1.0 0.63 1</diffuse>
        <specular>1.0 1.0 0.63 1</specular>
        <spot>
          <inner_angle>1</inner_angle>
          <outer_angle>1.1</outer_angle>
          <falloff>1</falloff>
        </spot>
        <direction>0 0 -1</direction>
        <cast_shadows>1</cast_shadows>
      </light>
      <light name="right_headlight_body_light_source_light" type="spot">
        <pose frame="">0.514147 -0.216803 0.180 3.14159 1.56859 0</pose>
        <attenuation>
          <range>50</range>
          <linear>0</linear>
          <constant>0.1</constant>
          <quadratic>0.0025</quadratic>
        </attenuation>
        <diffuse>1.0 1.0 0.63 1</diffuse>
        <specular>1.0 1.0 0.63 1</specular>
        <spot>
          <inner_angle>1</inner_angle>
          <outer_angle>1.1</outer_angle>
          <falloff>1</falloff>
        </spot>
        <direction>0 0 -1</direction>
        <cast_shadows>1</cast_shadows>
      </light>
      <light name="lateral_left_front_headlight_body_light_source_light" type="spot">
        <pose frame="">0.2499796936688763 0.334 0.155 3.14159 1.56859 1.5715899999999998</pose>
        <attenuation>
          <range>50</range>
          <linear>0</linear>
          <constant>0.1</constant>
          <quadratic>0.0025</quadratic>
        </attenuation>
        <diffuse>0.8 0.8 0.5 1</diffuse>
        <specular>0.8 0.8 0.5 1</specular>
        <spot>
          <inner_angle>1</inner_angle>
          <outer_angle>1.1</outer_angle>
          <falloff>1</falloff>
        </spot>
        <direction>0 0 -1</direction>
        <cast_shadows>1</cast_shadows>
      </light>
      <light name="lateral_left_rear_headlight_body_light_source_light" type="spot">
        <pose frame="">-0.2500203063311236 0.334 0.155 3.14159 1.56859 1.5715899999999998</pose>
        <attenuation>
          <range>50</range>
          <linear>0</linear>
          <constant>0.1</constant>
          <quadratic>0.0025</quadratic>
        </attenuation>
        <diffuse>0.8 0.8 0.5 1</diffuse>
        <specular>0.8 0.8 0.5 1</specular>
        <spot>
          <inner_angle>1</inner_angle>
          <outer_angle>1.1</outer_angle>
          <falloff>1</falloff>
        </spot>
        <direction>0 0 -1</direction>
        <cast_shadows>1</cast_shadows>
      </light>
      <light name="lateral_right_front_headlight_body_light_source_light" type="spot">
        <pose frame="">0.2499796936688763 -0.334 0.155 3.14159 1.56859 -1.5715953071795865</pose>
        <attenuation>
          <range>50</range>
          <linear>0</linear>
          <constant>0.1</constant>
          <quadratic>0.0025</quadratic>
        </attenuation>
        <diffuse>0.8 0.8 0.5 1</diffuse>
        <specular>0.8 0.8 0.5 1</specular>
        <spot>
          <inner_angle>1</inner_angle>
          <outer_angle>1.1</outer_angle>
          <falloff>1</falloff>
        </spot>
        <direction>0 0 -1</direction>
        <cast_shadows>1</cast_shadows>
      </light>
      <light name="lateral_right_rear_headlight_body_light_source_light" type="spot">
        <pose frame="">-0.2500203063311236 -0.334 0.155 3.14159 1.56859 -1.5715953071795865</pose>
        <attenuation>
          <range>50</range>
          <linear>0</linear>
          <constant>0.1</constant>
          <quadratic>0.0025</quadratic>
        </attenuation>
        <diffuse>0.8 0.8 0.5 1</diffuse>
        <specular>0.8 0.8 0.5 1</specular>
        <spot>
          <inner_angle>1</inner_angle>
          <outer_angle>1.1</outer_angle>
          <falloff>1</falloff>
        </spot>
        <direction>0 0 -1</direction>
        <cast_shadows>1</cast_shadows>
      </light>
      <light name="left_rear_headlight_body_light_source_light" type="spot">
        <pose frame="">-0.514147 0.216803 0.180 3.14159 1.56859 3.14159</pose>
        <attenuation>
          <range>50</range>
          <linear>0</linear>
          <constant>0.1</constant>
          <quadratic>0.0025</quadratic>
        </attenuation>
        <diffuse>1.0 1.0 0.63 1</diffuse>
        <specular>1.0 1.0 0.63 1</specular>
        <spot>
          <inner_angle>1</inner_angle>
          <outer_angle>1.1</outer_angle>
          <falloff>1</falloff>
        </spot>
        <direction>0 0 -1</direction>
        <cast_shadows>1</cast_shadows>
      </light>
      <light name="right_rear_headlight_body_light_source_light" type="spot">
        <pose frame="">-0.514147 -0.216803 0.180 3.14159 1.56859 3.14159</pose>
        <attenuation>
          <range>50</range>
          <linear>0</linear>
          <constant>0.1</constant>
          <quadratic>0.0025</quadratic>
        </attenuation>
        <diffuse>1.0 1.0 0.63 1</diffuse>
        <specular>1.0 1.0 0.63 1</specular>
        <spot>
          <inner_angle>1</inner_angle>
          <outer_angle>1.1</outer_angle>
          <falloff>1</falloff>
        </spot>
        <direction>0 0 -1</direction>
        <cast_shadows>1</cast_shadows>
      </light>
    </link>
    <link name="pan_gimbal_link">
      <pose frame="">0.424 0 0.427 0 -0 0</pose>
      <inertial>
        <pose frame="">0 0 0 0 -0 0</pose>
        <mass>0.1</mass>
      </inertial>
      <collision name="pan_gimbal_link_collision">
      <pose frame="">0.0 0 0.0 0 -0 0</pose>
      <geometry>
        <cylinder>
          <length>0.045</length>
          <radius>0.014</radius>
        </cylinder>
      </geometry>
      <surface>
        <contact>
          <ode>
            <kp>1e+07</kp>
            <kd>1</kd>
          </ode>
        </contact>
        <!-- <friction>
          <ode>
            <mu>1</mu>
            <mu2>1</mu2>
            <fdir1>0 0 1</fdir1>
          </ode>
        </friction> -->
      </surface>
      </collision>
      <visual name="pan_gimbal_link_visual">
        <pose frame="">0.0 0 0.0 0 -0 0</pose>
        <geometry>
          <cylinder>
            <length>0.045</length>
            <radius>0.014</radius>
          </cylinder>
        </geometry>
      </visual>
      <!-- Based on Intel realsense D435 (intrinsics and distortion not modeled)-->
      <!-- <sensor name="camera_pan_tilt" type="rgbd_camera">
        <camera name="camera_pan_tilt">
            <horizontal_fov>1.5184</horizontal_fov>
            <lens>
                <intrinsics>
                    <fx>277.1</fx>
                    <fy>277.1</fy>
                    <cx>640.5</cx>
                    <cy>360.5</cy>
                    <s>0</s>
                </intrinsics>
            </lens>
            <distortion>
                <k1>0.0</k1>
                <k2>0.0</k2>
                <k3>0.0</k3>
                <p1>0.0</p1>
                <p2>0.0</p2>
                <center>0.5 0.5</center>
            </distortion>
            <image>
                <width>1280</width>
                <height>720</height>
                <format>R8G8B8</format>
            </image>
            <clip>
                <near>0.01</near>
                <far>300</far>
            </clip>
            <depth_camera>
              <clip>
                <near>0.1</near>
                <far>10</far>
              </clip>
            </depth_camera>
            <noise>
                <type>gaussian</type>
                <mean>0</mean>
                <stddev>0.007</stddev>
            </noise>
        </camera>
        <always_on>1</always_on>
        <update_rate>30</update_rate>
        <visualize>0</visualize>
        <pose frame="">0.0 0 0.05 0 0.0 0</pose> 
      </sensor> -->
      <!-- <gravity>1</gravity>
      <velocity_decay/> -->
      <!-- <visual name="base_link_fixed_joint_lump__camera/camera_link_visual_0">
        <pose frame="">0 0 0.05 0 0.0 0</pose>
        <geometry>
          <mesh>
            <uri>meshes/realsense.dae</uri>
          </mesh>
        </geometry>
      </visual> -->
    </link>
    <link name="tilt_gimbal_link">
      <pose frame="">0.424 0 0.460 0 -0 0</pose>
      <inertial>
        <pose frame="">0 0 0 1.570796 -0 0</pose>
        <mass>0.1</mass>
      </inertial>
      <collision name="tilt_gimbal_link_collision">
      <pose frame="">0.0 0 0.0 1.570796 -0 0</pose>
      <geometry>
        <cylinder>
          <length>0.045</length>
          <radius>0.014</radius>
        </cylinder>
      </geometry>
      <surface>
        <contact>
          <ode>
            <kp>1e+07</kp>
            <kd>1</kd>
          </ode>
        </contact>
        <!-- <friction>
          <ode>
            <mu>1</mu>
            <mu2>1</mu2>
            <fdir1>0 0 1</fdir1>
          </ode>
        </friction> -->
      </surface>
      </collision>
      <visual name="tilt_gimbal_link_visual">
        <pose frame="">0.0 0 0.0 1.570796 -0 0</pose>
        <geometry>
          <cylinder>
            <length>0.045</length>
            <radius>0.014</radius>
          </cylinder>
        </geometry>
      </visual>
      <!-- Based on Intel realsense D435 (intrinsics and distortion not modeled)-->
      <sensor name="camera_pan_tilt" type="rgbd_camera">
        <camera name="camera_pan_tilt">
            <horizontal_fov>1.5184</horizontal_fov>
            <lens>
                <intrinsics>
                    <!-- fx = fy = width / ( 2 * tan (hfov / 2 ) ) -->
                    <fx>277.1</fx>
                    <fy>277.1</fy>
                    <!-- cx = ( width + 1 ) / 2 -->
                    <cx>640.5</cx>
                    <!-- cy = ( height + 1 ) / 2 -->
                    <cy>360.5</cy>
                    <s>0</s>
                </intrinsics>
            </lens>
            <distortion>
                <k1>0.0</k1>
                <k2>0.0</k2>
                <k3>0.0</k3>
                <p1>0.0</p1>
                <p2>0.0</p2>
                <center>0.5 0.5</center>
            </distortion>
            <image>
                <width>1280</width>
                <height>720</height>
                <format>R8G8B8</format>
            </image>
            <clip>
                <near>0.01</near>
                <far>300</far>
            </clip>
            <depth_camera>
              <clip>
                <near>0.1</near>
                <far>10</far>
              </clip>
            </depth_camera>
            <noise>
                <type>gaussian</type>
                <mean>0</mean>
                <stddev>0.007</stddev>
            </noise>
        </camera>
        <always_on>1</always_on>
        <update_rate>30</update_rate>
        <visualize>0</visualize>
        <!-- <pose frame="">0.424 0 0.542 0 0.0 0</pose>  -->
        <pose frame="">0.0 0 0.03 0 0.0 0</pose> 
      </sensor>
      <gravity>1</gravity>
      <velocity_decay/>
      <visual name="tilt_gimbal_link_fixed_joint_lump__camera/camera_link_visual_0">
        <pose frame="">0 0 0.03 0 0.0 0</pose>
        <geometry>
          <mesh>
            <uri>meshes/realsense.dae</uri>
          </mesh>
        </geometry>
      </visual>
      <visual name="tilt_gimbal_link_fixed_joint_lump_bot_camera_plate_link_visual_1">
       <pose frame="">0 0 0.017 0 -0 0</pose>
        <geometry>
          <box>
            <size>0.025 0.13 0.007</size>
          </box>
        </geometry>
      </visual>
      <visual name="tilt_gimbal_link_fixed_joint_lump_bot_camera_plate_link_visual_2">
       <pose frame="">0 0 0.042 0 -0 0</pose>
        <geometry>
          <box>
            <size>0.025 0.13 0.007</size>
          </box>
        </geometry>
      </visual>
    </link>
    <link name="front_left_wheel_link">
      <pose frame="">0.256 0.2854 0.03282 0 -0 0</pose>
      <inertial>
        <pose frame="">0 0 0 0 -0 0</pose>
        <mass>2.637</mass>
        <inertia>
          <ixx>0.02467</ixx>
          <ixy>0</ixy>
          <ixz>0</ixz>
          <iyy>0.04411</iyy>
          <iyz>0</iyz>
          <izz>0.02467</izz>
        </inertia>
      </inertial>
      <collision name="front_left_wheel_link_collision">
        <pose frame="">0 0 0 1.5707963267948966 -0 0</pose>
        <geometry>
          <cylinder>
            <length>0.1143</length>
            <radius>0.1651</radius>
          </cylinder>
        </geometry>
        <surface>
          <friction>
            <ode>
              <mu>1</mu>
              <mu2>1</mu2>
              <slip1>0.035</slip1>
              <slip2>0</slip2>
              <fdir1>0 0 1</fdir1>
            </ode>
          </friction>
          <contact>
            <ode>
              <kp>1e+07</kp>
              <kd>1</kd>
            </ode>
          </contact>
        </surface>
      </collision>
      <!-- <visual name="front_left_wheel_link_visual">
        <pose frame="">0 0 0 0 -0 0</pose>
        <geometry>
          <mesh>
            <scale>1 1 1</scale>
            <uri>meshes/wheel.dae</uri>
          </mesh>
        </geometry>
      </visual> -->
      <gravity>1</gravity>
      <velocity_decay/>
    </link>
    <joint name="front_left_wheel_joint" type="revolute">
      <child>front_left_wheel_link</child>
      <parent>base_link</parent>
      <axis>
        <xyz>0 1 0</xyz>
        <limit>
          <lower>-1e+16</lower>
          <upper>1e+16</upper>
        </limit>
        <dynamics>
          <spring_reference>0</spring_reference>
          <spring_stiffness>0</spring_stiffness>
        </dynamics>
        <use_parent_model_frame>1</use_parent_model_frame>
      </axis>
    </joint>
    <link name="front_right_wheel_link">
      <pose frame="">0.256 -0.2854 0.03282 0 -0 0</pose>
      <inertial>
        <pose frame="">0 0 0 0 -0 0</pose>
        <mass>2.637</mass>
        <inertia>
          <ixx>0.02467</ixx>
          <ixy>0</ixy>
          <ixz>0</ixz>
          <iyy>0.04411</iyy>
          <iyz>0</iyz>
          <izz>0.02467</izz>
        </inertia>
      </inertial>
      <collision name="front_right_wheel_link_collision">
        <pose frame="">0 0 0 1.5707963267948966 -0 0</pose>
        <geometry>
          <cylinder>
            <length>0.1143</length>
            <radius>0.1651</radius>
          </cylinder>
        </geometry>
        <surface>
          <friction>
            <ode>
              <mu>1</mu>
              <mu2>1</mu2>
              <slip1>0.035</slip1>
              <slip2>0</slip2>
              <fdir1>0 0 1</fdir1>
            </ode>
          </friction>
          <contact>
            <ode>
              <kp>1e+07</kp>
              <kd>1</kd>
            </ode>
          </contact>
        </surface>
      </collision>
      <!-- <visual name="front_right_wheel_link_visual">
        <pose frame="">0 0 0 0 -0 0</pose>
        <geometry>
          <mesh>
            <scale>1 1 1</scale>
            <uri>meshes/wheel.dae</uri>
          </mesh>
        </geometry>
      </visual> -->
      <gravity>1</gravity>
      <velocity_decay/>
    </link>
    <joint name="front_right_wheel_joint" type="revolute">
      <child>front_right_wheel_link</child>
      <parent>base_link</parent>
      <axis>
        <xyz>0 1 0</xyz>
        <limit>
          <lower>-1e+16</lower>
          <upper>1e+16</upper>
        </limit>
        <dynamics>
          <spring_reference>0</spring_reference>
          <spring_stiffness>0</spring_stiffness>
        </dynamics>
        <use_parent_model_frame>1</use_parent_model_frame>
      </axis>
    </joint>
    <link name="rear_left_wheel_link">
      <pose frame="">-0.256 0.2854 0.03282 0 -0 0</pose>
      <inertial>
        <pose frame="">0 0 0 0 -0 0</pose>
        <mass>2.637</mass>
        <inertia>
          <ixx>0.02467</ixx>
          <ixy>0</ixy>
          <ixz>0</ixz>
          <iyy>0.04411</iyy>
          <iyz>0</iyz>
          <izz>0.02467</izz>
        </inertia>
      </inertial>
      <collision name="rear_left_wheel_link_collision">
        <pose frame="">0 0 0 1.5707963267948966 -0 0</pose>
        <geometry>
          <cylinder>
            <length>0.1143</length>
            <radius>0.1651</radius>
          </cylinder>
        </geometry>
        <surface>
          <friction>
            <ode>
              <mu>1</mu>
              <mu2>1</mu2>
              <slip1>0.035</slip1>
              <slip2>0</slip2>
              <fdir1>0 0 1</fdir1>
            </ode>
          </friction>
          <contact>
            <ode>
              <kp>1e+07</kp>
              <kd>1</kd>
            </ode>
          </contact>
        </surface>
      </collision>
      <!-- <visual name="rear_left_wheel_link_visual">
        <pose frame="">0 0 0 0 -0 0</pose>
        <geometry>
          <mesh>
            <scale>1 1 1</scale>
            <uri>meshes/wheel.dae</uri>
          </mesh>
        </geometry>
      </visual> -->
      <gravity>1</gravity>
      <velocity_decay/>
    </link>
    <joint name="rear_left_wheel_joint" type="revolute">
      <child>rear_left_wheel_link</child>
      <parent>base_link</parent>
      <axis>
        <xyz>0 1 0</xyz>
        <limit>
          <lower>-1e+16</lower>
          <upper>1e+16</upper>
        </limit>
        <dynamics>
          <spring_reference>0</spring_reference>
          <spring_stiffness>0</spring_stiffness>
        </dynamics>
        <use_parent_model_frame>1</use_parent_model_frame>
      </axis>
    </joint>
    <link name="rear_right_wheel_link">
      <pose frame="">-0.256 -0.2854 0.03282 0 -0 0</pose>
      <inertial>
        <pose frame="">0 0 0 0 -0 0</pose>
        <mass>2.637</mass>
        <inertia>
          <ixx>0.02467</ixx>
          <ixy>0</ixy>
          <ixz>0</ixz>
          <iyy>0.04411</iyy>
          <iyz>0</iyz>
          <izz>0.02467</izz>
        </inertia>
      </inertial>
      <collision name="rear_right_wheel_link_collision">
        <pose frame="">0 0 0 1.5707963267948966 -0 0</pose>
        <geometry>
          <cylinder>
            <length>0.1143</length>
            <radius>0.1651</radius>
          </cylinder>
        </geometry>
        <surface>
          <friction>
            <ode>
              <mu>1</mu>
              <mu2>1</mu2>
              <slip1>0.035</slip1>
              <slip2>0</slip2>
              <fdir1>0 0 1</fdir1>
            </ode>
          </friction>
          <contact>
            <ode>
              <kp>1e+07</kp>
              <kd>1</kd>
            </ode>
          </contact>
        </surface>
      </collision>
      <!-- <visual name="rear_right_wheel_link_visual">
        <pose frame="">0 0 0 0 -0 0</pose>
        <geometry>
          <mesh>
            <scale>1 1 1</scale>
            <uri>meshes/wheel.dae</uri>
          </mesh>
        </geometry>
      </visual> -->
      <gravity>1</gravity>
      <velocity_decay/>
    </link>
    <joint name="rear_right_wheel_joint" type="revolute">
      <child>rear_right_wheel_link</child>
      <parent>base_link</parent>
      <axis>
        <xyz>0 1 0</xyz>
        <limit>
          <lower>-1e+16</lower>
          <upper>1e+16</upper>
        </limit>
        <dynamics>
          <spring_reference>0</spring_reference>
          <spring_stiffness>0</spring_stiffness>
        </dynamics>
        <use_parent_model_frame>1</use_parent_model_frame>
      </axis>
    </joint>
    <joint name="pan_gimbal_joint" type="revolute">
      <child>pan_gimbal_link</child>
      <parent>base_link</parent>
      <axis>
        <xyz>0 0 1</xyz>
        <limit>
          <lower>-1e+16</lower>
          <upper>1e+16</upper>
        </limit>
        <dynamics>
          <spring_reference>0</spring_reference>
          <spring_stiffness>0</spring_stiffness>
        </dynamics>
        <use_parent_model_frame>1</use_parent_model_frame>
      </axis>
    </joint>
    <joint name="tilt_gimbal_joint" type="revolute">
      <child>tilt_gimbal_link</child>
      <parent>pan_gimbal_link</parent>
      <axis>
        <xyz>0 1 0</xyz>
        <limit>
          <lower>-2.79253</lower> <!-- 160 degrees both direction (mechanical interference)-->
          <upper>2.79253</upper>
        </limit>
        <dynamics>
          <spring_reference>0</spring_reference>
          <spring_stiffness>0</spring_stiffness>
        </dynamics>
        <use_parent_model_frame>1</use_parent_model_frame>
      </axis>
    </joint>
    <!-- Gimbal Joints Plugins --> 
    <plugin
      filename="libignition-gazebo-joint-controller-system.so"
      name="ignition::gazebo::systems::JointController">
      <joint_name>pan_gimbal_joint</joint_name>
    </plugin>
    <plugin
      filename="libignition-gazebo-joint-controller-system.so"
      name="ignition::gazebo::systems::JointController">
      <joint_name>tilt_gimbal_joint</joint_name>
    </plugin>
    <plugin
      filename="libignition-gazebo-joint-state-publisher-system.so"
      name="ignition::gazebo::systems::JointStatePublisher">
    </plugin>
    <static>0</static>
  </model>
</sdf>

