<?xml version='1.0' encoding='utf-8'?>
<sdf version="1.6">
  <model name="marble_hd2_sensor_config_1">
    <link name="base_link">
      <pose frame="">0 0 0 0 -0 0</pose>
      <inertial>
        <pose frame="">-0.000649 -0.084945 0.062329 0 -0 0</pose>
        <mass>34.02</mass>
        <inertia>
          <ixx>0.615397</ixx>
          <ixy>-0.0240585</ixy>
          <ixz>-0.120749</ixz>
          <iyy>1.75388</iyy>
          <iyz>-0.0028322</iyz>
          <izz>2.03641</izz>
        </inertia>
      </inertial>
      <collision name="base_link_collision">
        <pose frame="">0 0 0.12 0 0 0</pose>
        <geometry>
          <box>
            <size>0.9874 0.5709 0.05</size>
          </box>
        </geometry>
      </collision>
      <collision name="base_link_collision_bottom">
        <pose frame="">0 0 0.046 0 0 0</pose>
        <geometry>
          <box>
            <size>0.80 0.5709 0.2</size>
          </box>
        </geometry>
      </collision>
      <collision name="base_link_collision_1">
        <pose frame="">0 0 0.185625 0 -0 0</pose>
        <geometry>
          <box>
            <size>0.78992 0.5709 0.12375</size>
          </box>
        </geometry>
      </collision>
      <collision name="base_link_fixed_joint_lump__camera/camera_link_collision_1">
        <pose frame="pan_gimbal_link">0 0 0.05 0 0.0 0</pose>
        <geometry>
          <box>
            <size>0.0078 0.13 0.0192</size>
          </box>
        </geometry>
        <surface>
          <contact>
            <ode>
              <kp>1e+13</kp>
              <kd>1</kd>
            </ode>
          </contact>
          <friction>
            <ode>
              <mu2>1</mu2>
              <fdir1>0 0 0</fdir1>
            </ode>
          </friction>
        </surface>
      </collision>
      <collision name="base_link_fixed_joint_lump__camera/camera_link_collision_2">
        <pose frame="">0.478 0 0.285 0 -0 0</pose>
        <geometry>
          <box>
            <size>0.0078 0.13 0.0192</size>
          </box>
        </geometry>
        <surface>
          <contact>
            <ode>
              <kp>1e+13</kp>
              <kd>1</kd>
            </ode>
          </contact>
          <friction>
            <ode>
              <mu2>1</mu2>
              <fdir1>0 0 0</fdir1>
            </ode>
          </friction>
        </surface>
      </collision>
      <collision name="base_link_fixed_joint_lump__camera/camera_link_collision_3">
        <pose frame="">0.473 0 0.260 0 0.5236 0</pose>
        <geometry>
          <box>
            <size>0.0078 0.13 0.0192</size>
          </box>
        </geometry>
        <surface>
          <contact>
            <ode>
              <kp>1e+13</kp>
              <kd>1</kd>
            </ode>
          </contact>
          <friction>
            <ode>
              <mu2>1</mu2>
              <fdir1>0 0 0</fdir1>
            </ode>
          </friction>
        </surface>
      </collision>
      <collision name="base_link_fixed_joint_lump__velodyne_base_link_collision_6">
        <pose frame="">0.424 0 0.327 0 -0 0</pose>
        <geometry>
          <cylinder>
            <length>0.0717</length>
            <radius>0.0516</radius>
          </cylinder>
        </geometry>
      </collision>
      <collision name="base_link_fixed_joint_lump__velodyne_gimbal_plate_base_link_collision_7">
        <pose frame="">0.424 0 0.400 0 -0 0</pose>
        <geometry>
          <box>
            <size>0.1 0.1 0.01</size>
          </box>
        </geometry>
      </collision>
      <collision name="base_link_fixed_joint_lump__sensor_tower_8">
       <pose frame="">0.374 0 0.215 0 -0 0</pose>
        <geometry>
          <box>
            <size>0.2 0.25 0.225</size>
          </box>
        </geometry>
      </collision>
      <collision name="base_link_fixed_joint_lump__computer_block_9">
       <pose frame="">0.050 0 0.155 0 -0 0</pose>
        <geometry>
          <box>
            <size>0.30 0.355 0.160</size>
          </box>
        </geometry>
      </collision>
      <visual name="base_link_visual">
        <pose frame="">0 0 0 1.57 0 1.57</pose>
        <material>
                    <diffuse>0.5 0.5 0.5 1</diffuse>
                    <ambient>.5 .5 .5 1</ambient>

                    <!-- <script>
                        <name>Gazebo/Blue</name>
                        <uri>file://media/materials/scripts/gazebo.material</uri>
                    </script> -->
                </material>
        <geometry>
          <mesh>
            <scale>1 1 1</scale>
            <uri>meshes/hd2_chassis.stl</uri>
          </mesh>
        </geometry>
      </visual>
      <visual name="track_left_visual">
        <pose frame="">0 0.2625 0 1.57 0 1.57</pose>
        <material>
                    <diffuse>0 0 0 1</diffuse>
                    <ambient>0 0 0 1</ambient>
                    <specular>0 0 0 1</specular>
                    <emissive>0 0 0 1</emissive>

                    <!-- <script>
                        <name>Gazebo/Blue</name>
                        <uri>file://media/materials/scripts/gazebo.material</uri>
                    </script> -->
                </material>
        <geometry>
          <mesh>
            <scale>1 1 1</scale>
            <uri>meshes/track.stl</uri>
          </mesh>
        </geometry>
      </visual>
      <visual name="track_right_visual">
        <pose frame="">0 -0.2625 0 1.57 0 1.57</pose>
        <material>
                    <diffuse>0 0 0 1</diffuse>
                    <ambient>0 0 0 1</ambient>
                    <specular>0 0 0 1</specular>
                    <emissive>0 0 0 1</emissive>

                    <!-- <script>
                        <name>Gazebo/Blue</name>
                        <uri>file://media/materials/scripts/gazebo.material</uri>
                    </script> -->
                </material>
        <geometry>
          <mesh>
            <scale>1 1 1</scale>
            <uri>meshes/track.stl</uri>
          </mesh>
        </geometry>
      </visual>
      <visual name="base_link_fixed_joint_lump__camera/camera_link_visual_1">
        <pose frame="">0.44 0 0.260 0 0.5236 0</pose>
        <geometry>
          <mesh>
            <uri>meshes/realsense.dae</uri>
          </mesh>
        </geometry>
      </visual>
      <visual name="base_link_fixed_joint_lump__camera/camera_link_visual_2">
        <pose frame="">0.44 0 0.295 0 -0 0</pose>
        <geometry>
          <mesh>
            <uri>meshes/realsense.dae</uri>
          </mesh>
        </geometry>
      </visual>
<!--
      <visual name="base_link_fixed_joint_lump__front_bumper_link_visual_3">
        <pose frame="">0.48 0 0.091 0 -0 0</pose>
        <geometry>
          <mesh>
            <scale>1 1 1</scale>
            <uri>meshes/bumper.dae</uri>
          </mesh>
        </geometry>
      </visual>

      <visual name="base_link_fixed_joint_lump__rear_bumper_link_visual_4">
        <pose frame="">-0.48 0 0.091 0 -0 3.14159</pose>
        <geometry>
          <mesh>
            <scale>1 1 1</scale>
            <uri>meshes/bumper.dae</uri>
          </mesh>
        </geometry>
      </visual>
      <visual name="base_link_fixed_joint_lump__top_chassis_link_visual_5">
        <pose frame="">0 0 0 0 -0 0</pose>
        <geometry>
          <mesh>
            <scale>1 1 1</scale>
            <uri>meshes/top_chassis.dae</uri>
          </mesh>
        </geometry>
      </visual>
-->
      <!-- Bottom cylinder of Ouster/Velodyne 3D Lidar -->
      <visual name="base_link_fixed_joint_lump__velodyne_base_link_visual_10">
        <pose frame="">0.354 0 0.327 0 -0 0</pose>
        <geometry>
          <mesh>
            <scale>1 1 1</scale>
            <uri>meshes/VLP16_base_1.dae</uri>
          </mesh>
        </geometry>
      </visual>
      <!-- Top cylinder of Ouster/Velodyne 3D Lidar -->
      <visual name="base_link_fixed_joint_lump__velodyne_base_link_visual_11">
        <pose frame="">0.354 0 0.327 0 -0 0</pose>
        <geometry>
          <mesh>
            <scale>1 1 1</scale>
            <uri>meshes/VLP16_base_2.dae</uri>
          </mesh>
        </geometry>
      </visual>
      <!-- Main cylinder of Ouster/Velodyne 3D Lidar -->
      <visual name="base_link_fixed_joint_lump__velodyne_visual_12">
        <pose frame="">0.354 0 0.327 0 -0 0</pose>
        <geometry>
          <mesh>
            <scale>1 1 1</scale>
            <uri>meshes/VLP16_scan.dae</uri>
          </mesh>
        </geometry>
      </visual>
      <!-- Rail on top of husky -->
<!--
      <visual name="base_link_fixed_joint_lump__user_rail_link_visual_13">
        <pose frame="">0.272 0 0.245 0 -0 0</pose>
        <geometry>
          <mesh>
            <scale>1 1 1</scale>
            <uri>meshes/user_rail.dae</uri>
          </mesh>
        </geometry>
      </visual>
-->
      <!-- 2D planar lidar at bottom of sensor suite -->
      <visual name="base_link_fixed_joint_lump__planar_lidar_link_visual_14">
        <pose frame="">0.354 0 0.127 0 -0 0</pose>
        <geometry>
          <cylinder>
              <radius>0.045</radius>
              <length>0.05</length>
          </cylinder>
        </geometry>
      </visual>
      <visual name="base_link_fixed_joint_lump__velodyne_gimbal_plate_15">
       <pose frame="">0.354 0 0.400 0 -0 0</pose>
        <geometry>
          <box>
            <size>0.06 0.06 0.01</size>
          </box>
        </geometry>
      </visual>
      <visual name="base_link_fixed_joint_lump__sensor_tower_16">
       <pose frame="">0.354 0 0.19 0 -0 0</pose>
        <geometry>
          <box>
            <size>0.18 0.25 0.275</size>
          </box>
        </geometry>
      </visual>
      <visual name="base_link_fixed_joint_lump__computer_block_17">
       <pose frame="">0.050 0 0.135 0 -0 0</pose>
        <geometry>
          <box>
            <size>0.30 0.355 0.175</size>
          </box>
        </geometry>
      </visual>
      <visual name="base_link_fixed_joint_lid_18">
       <pose frame="">0 0 0.05 0 -0 0</pose>
        <geometry>
          <box>
            <size>0.7 0.35 0.02</size>
          </box>
        </geometry>
      </visual>
      <velocity_decay/>
      <self_collide>0</self_collide>
      <enable_wind>0</enable_wind>
      <kinematic>0</kinematic>
      <!-- Based on Intel realsense D435 (intrinsics and distortion not modeled)-->
      <sensor name="camera_front" type="rgbd_camera">
        <camera name="camera_front">
            <horizontal_fov>1.5184</horizontal_fov>
            <lens>
                <intrinsics>
                    <!-- fx = fy = width / ( 2 * tan (hfov / 2 ) ) -->
                    <fx>277.1</fx>
                    <fy>277.1</fy>
                    <!-- cx = ( width + 1 ) / 2 -->
                    <cx>320.5</cx>
                    <!-- cy = ( height + 1 ) / 2 -->
                    <cy>240.5</cy>
                    <s>0</s>
                </intrinsics>
            </lens>
            <distortion>
                <k1>0.0</k1>
                <k2>0.0</k2>
                <k3>0.0</k3>
                <p1>0.0</p1>
                <p2>0.0</p2>
                <center>0.5 0.5</center>
            </distortion>
            <image>
                <width>640</width>
                <height>480</height>
                <format>R8G8B8</format>
            </image>
            <clip>
                <near>0.01</near>
                <far>300</far>
            </clip>
            <depth_camera>
              <clip>
                <near>0.1</near>
                <far>10</far>
              </clip>
            </depth_camera>
            <noise>
                <type>gaussian</type>
                <mean>0</mean>
                <stddev>0.007</stddev>
            </noise>
        </camera>
        <always_on>1</always_on>
        <update_rate>30</update_rate>
        <visualize>0</visualize>
        <pose frame="">0.44 0 0.360 0 -0 0</pose>
      </sensor>
      <gravity>1</gravity>
      <velocity_decay/>
      <!-- Based on Intel realsense D435 (intrinsics and distortion not modeled)-->
      <sensor name="camera_down" type="rgbd_camera">
        <camera name="camera_down">
            <horizontal_fov>1.5184</horizontal_fov>
            <lens>
                <intrinsics>
                    <!-- fx = fy = width / ( 2 * tan (hfov / 2 ) ) -->
                    <fx>277.1</fx>
                    <fy>277.1</fy>
                    <!-- cx = ( width + 1 ) / 2 -->
                    <cx>320.5</cx>
                    <!-- cy = ( height + 1 ) / 2 -->
                    <cy>240.5</cy>
                    <s>0</s>
                </intrinsics>
            </lens>
            <distortion>
                <k1>0.0</k1>
                <k2>0.0</k2>
                <k3>0.0</k3>
                <p1>0.0</p1>
                <p2>0.0</p2>
                <center>0.5 0.5</center>
            </distortion>
            <image>
                <width>640</width>
                <height>480</height>
                <format>R8G8B8</format>
            </image>
            <clip>
                <near>0.01</near>
                <far>300</far>
            </clip>
            <depth_camera>
              <clip>
                <near>0.1</near>
                <far>10</far>
              </clip>
            </depth_camera>
            <noise>
                <type>gaussian</type>
                <mean>0</mean>
                <stddev>0.007</stddev>
            </noise>
        </camera>
        <always_on>1</always_on>
        <update_rate>30</update_rate>
        <visualize>0</visualize>
        <pose frame="">0.44 0 0.335 0 0.5236 0</pose> <!-- 30 degree download look-->
      </sensor>
      <gravity>1</gravity>
      <velocity_decay/>
      <!-- Based on RPLidar S1 -->
      <sensor name="planar_laser" type="gpu_ray">
          <pose>0.354 0 0.127 0 -0 0</pose>
          <update_rate>10</update_rate>
          <lidar>
              <scan>
                  <horizontal>
                      <samples>920</samples>
                      <resolution>1</resolution>
                      <min_angle>-3.14159</min_angle>
                      <max_angle>3.14159</max_angle>
                  </horizontal>
              </scan>
              <range>
                  <min>0.04</min>
                  <max>25</max>
                  <resolution>0.03</resolution>
              </range>
              <noise>
                  <type>gaussian</type>
                  <mean>0</mean>
                  <stddev>0.01</stddev>
              </noise>
          </lidar>
      </sensor>
      <gravity>1</gravity>
      <velocity_decay/>

      <!-- OS1-64 3D Laser Configuration (10x2048 or 10x1024 or 20x1024 or 20x512 as possible (rate) x (hor. res.) configs)-->
      <sensor name="front_laser" type="gpu_lidar">
        <visualize>0</visualize>
        <update_rate>20</update_rate>
        <lidar>
          <scan>
            <horizontal>
              <!-- Resolution can't be above 16k, see
              https://bitbucket.org/ignitionrobotics/ign-sensors/issues/8 -->
              <samples>1024</samples>
              <resolution>0.1</resolution>
              <min_angle>-3.1459</min_angle>
              <max_angle>3.1459</max_angle>
            </horizontal>
            <vertical>
              <samples>64</samples>
              <resolution>1</resolution>
              <min_angle>-0.3927</min_angle>
              <max_angle>0.3927</max_angle>
            </vertical>
          </scan>
          <range>
            <min>0.09</min>
            <max>120</max>
            <resolution>0.003</resolution>
          </range>
          <noise>
            <type>gaussian</type>
            <mean>0</mean>
            <stddev>0.03</stddev>
          </noise>
        </lidar>
        <pose frame="">0.354 0 0.387 0 -0 0</pose>
      </sensor>
      <!-- MARBLE HD2 and Husky use the Lord Microstrain 3DM-GX5-25 IMU/AHRS with 
	the following noise density terms:
	Datasheet: https://www.microstrain.com/sites/default/files/applications/files/3dm-gx5-25_datasheet_8400-0093_rev_n.pdf
	
	We derived the stddev terms as follows:

	accelerometer noise density = 0.00002 g/sqrt(Hz) 
		=> convert to m/s^2 => 1.962e-4 m/s^2
	gyro noise density = 0.005 deg/s/sqrt(Hz)
		=> convert to rad/sec => 8.72664e-5 radians

	Other terms are difficult to extract from datasheet, so we used similar terms to previous IMU models proposed (of similar or worse quality) such as the ADIS 16448 (which has worse performance than this IMU). 
	-->
      <sensor name="imu_sensor" type="imu">
        <always_on>1</always_on>
        <update_rate>250</update_rate>
	
        <imu>
          <angular_velocity>
            <x>
              <noise type="gaussian">
                <mean>0</mean>
                 <stddev>0.0000872664</stddev>
                 <bias_mean>0.0000075</bias_mean>
                 <bias_stddev>0.00000080</bias_stddev>
                 <dynamic_bias_stddev>0.0000004</dynamic_bias_stddev>
                 <dynamic_bias_correlation_time>1000.0</dynamic_bias_correlation_time>
              </noise>
            </x>
            <y>
              <noise type="gaussian">
                <mean>0</mean>
                 <stddev>0.0000872664</stddev>
                 <bias_mean>0.0000075</bias_mean>
                 <bias_stddev>0.00000080</bias_stddev>
                 <dynamic_bias_stddev>0.0000004</dynamic_bias_stddev>
                 <dynamic_bias_correlation_time>1000.0</dynamic_bias_correlation_time>
                <dynamic_bias_correlation_time>1000.0</dynamic_bias_correlation_time>
              </noise>
            </y>
            <z>
              <noise type="gaussian">
                <mean>0</mean>
                 <stddev>0.0000872664</stddev>
                 <bias_mean>0.0000075</bias_mean>
                 <bias_stddev>0.00000080</bias_stddev>
                 <dynamic_bias_stddev>0.0000004</dynamic_bias_stddev>
                 <dynamic_bias_correlation_time>1000.0</dynamic_bias_correlation_time>
                <dynamic_bias_correlation_time>1000.0</dynamic_bias_correlation_time>
              </noise>
            </z>
          </angular_velocity>
          <linear_acceleration>
            <x>
              <noise type="gaussian">
                <mean>0</mean>
                 <stddev>0.0001962</stddev>
                 <bias_mean>0.001</bias_mean>
                 <bias_stddev>0.0001</bias_stddev>
                 <dynamic_bias_stddev>0.001</dynamic_bias_stddev>
                <dynamic_bias_correlation_time>300.0</dynamic_bias_correlation_time>
              </noise>
            </x>
            <y>
              <noise type="gaussian">
                <mean>0</mean>
                 <stddev>0.0001962</stddev>
                 <bias_mean>0.001</bias_mean>
                 <bias_stddev>0.0001</bias_stddev>
                 <dynamic_bias_stddev>0.001</dynamic_bias_stddev>
                <dynamic_bias_correlation_time>300.0</dynamic_bias_correlation_time>
              </noise>
            </y>
            <z>
              <noise type="gaussian">
                <mean>0</mean>
                 <stddev>0.0001962</stddev>
                 <bias_mean>0.001</bias_mean>
                 <bias_stddev>0.0001</bias_stddev>
                 <dynamic_bias_stddev>0.001</dynamic_bias_stddev>
                <dynamic_bias_correlation_time>300.0</dynamic_bias_correlation_time>
              </noise>
            </z>
          </linear_acceleration>
        </imu>
      </sensor>
    </link>
    <!-- Left Side Wheels  -->
    <link name="front_left_wheel_link">
      <pose frame="">0.360 0.26 0.00 0 -0 0</pose>
      <inertial>
        <pose frame="">0 0 0 0 -0 0</pose>
        <mass>2.637</mass>
        <inertia>
          <ixx>0.02467</ixx>
          <ixy>0</ixy>
          <ixz>0</ixz>
          <iyy>0.04411</iyy>
          <iyz>0</iyz>
          <izz>0.02467</izz>
        </inertia>
      </inertial>
      <collision name="front_left_wheel_link_collision">
        <pose frame="">0 0 0 1.5707963267948966 -0 0</pose>
        <geometry>
          <cylinder>
            <length>0.1</length>
            <radius>0.129</radius>
          </cylinder>
        </geometry>
        <surface>
          <contact>
            <ode>
              <kp>1e+07</kp>
              <kd>1</kd>
            </ode>
          </contact>
          <friction>
            <ode>
              <mu>1</mu>
              <mu2>1</mu2>
              <slip1>0.035</slip1>
              <slip2>0</slip2>
              <fdir1>0 0 1</fdir1>
            </ode>
          </friction>
        </surface>
      </collision>

      <visual name="front_left_wheel_link_visual">
        <pose frame="">0 0 0 1.5707963267948966 -0 0</pose>
        <geometry>
          <cylinder>
            <length>0.1</length>
            <radius>0.129</radius>
          </cylinder>
        </geometry>
      </visual>

      <gravity>1</gravity>
      <velocity_decay/>
    </link>
    <joint name="front_left_wheel_joint" type="revolute">
      <child>front_left_wheel_link</child>
      <parent>base_link</parent>
      <axis>
        <xyz>0 1 0</xyz>
        <limit>
          <lower>-1e+16</lower>
          <upper>1e+16</upper>
        </limit>
        <dynamics>
          <spring_reference>0</spring_reference>
          <spring_stiffness>0</spring_stiffness>
        </dynamics>
        <use_parent_model_frame>1</use_parent_model_frame>
      </axis>
    </joint>
    <link name="front_middle_left_wheel_link">
      <pose frame="">0.120 0.26 0.00 0 -0 0</pose>
      <inertial>
        <pose frame="">0 0 0 0 -0 0</pose>
        <mass>2.637</mass>
        <inertia>
          <ixx>0.02467</ixx>
          <ixy>0</ixy>
          <ixz>0</ixz>
          <iyy>0.04411</iyy>
          <iyz>0</iyz>
          <izz>0.02467</izz>
        </inertia>
      </inertial>
      <collision name="front_middle_left_wheel_link_collision">
        <pose frame="">0 0 0 1.5707963267948966 -0 0</pose>
        <geometry>
          <cylinder>
            <length>0.1</length>
            <radius>0.129</radius>
          </cylinder>
        </geometry>
        <surface>
          <contact>
            <ode>
              <kp>1e+07</kp>
              <kd>1</kd>
            </ode>
          </contact>
          <friction>
            <ode>
              <mu>1</mu>
              <mu2>1</mu2>
              <slip1>0.035</slip1>
              <slip2>0</slip2>
              <fdir1>0 0 1</fdir1>
            </ode>
          </friction>
        </surface>
      </collision>

      <visual name="front_middle_left_wheel_link_visual">
        <pose frame="">0 0 0 1.5707963267948966 -0 0</pose>
        <geometry>
          <cylinder>
            <length>0.1</length>
            <radius>0.129</radius>
          </cylinder>
        </geometry>
      </visual>

      <gravity>1</gravity>
      <velocity_decay/>
    </link>
    <joint name="front_middle_left_wheel_joint" type="revolute">
      <child>front_middle_left_wheel_link</child>
      <parent>base_link</parent>
      <axis>
        <xyz>0 1 0</xyz>
        <limit>
          <lower>-1e+16</lower>
          <upper>1e+16</upper>
        </limit>
        <dynamics>
          <spring_reference>0</spring_reference>
          <spring_stiffness>0</spring_stiffness>
        </dynamics>
        <use_parent_model_frame>1</use_parent_model_frame>
      </axis>
    </joint>
    <link name="rear_middle_left_wheel_link">
      <pose frame="">-0.120 0.26 0.00 0 -0 0</pose>
      <inertial>
        <pose frame="">0 0 0 0 -0 0</pose>
        <mass>2.637</mass>
        <inertia>
          <ixx>0.02467</ixx>
          <ixy>0</ixy>
          <ixz>0</ixz>
          <iyy>0.04411</iyy>
          <iyz>0</iyz>
          <izz>0.02467</izz>
        </inertia>
      </inertial>
      <collision name="rear_middle_left_wheel_link_collision">
        <pose frame="">0 0 0 1.5707963267948966 -0 0</pose>
        <geometry>
          <cylinder>
            <length>0.1</length>
            <radius>0.129</radius>
          </cylinder>
        </geometry>
        <surface>
          <contact>
            <ode>
              <kp>1e+07</kp>
              <kd>1</kd>
            </ode>
          </contact>
          <friction>
            <ode>
              <mu>1</mu>
              <mu2>1</mu2>
              <slip1>0.035</slip1>
              <slip2>0</slip2>
              <fdir1>0 0 1</fdir1>
            </ode>
          </friction>
        </surface>
      </collision>

      <visual name="rear_middle_left_wheel_link_visual">
        <pose frame="">0 0 0 1.5707963267948966 -0 0</pose>
        <geometry>
          <cylinder>
            <length>0.1</length>
            <radius>0.129</radius>
          </cylinder>
        </geometry>
      </visual>

      <gravity>1</gravity>
      <velocity_decay/>
    </link>
    <joint name="rear_middle_left_wheel_joint" type="revolute">
      <child>rear_middle_left_wheel_link</child>
      <parent>base_link</parent>
      <axis>
        <xyz>0 1 0</xyz>
        <limit>
          <lower>-1e+16</lower>
          <upper>1e+16</upper>
        </limit>
        <dynamics>
          <spring_reference>0</spring_reference>
          <spring_stiffness>0</spring_stiffness>
        </dynamics>
        <use_parent_model_frame>1</use_parent_model_frame>
      </axis>
    </joint>
    <link name="rear_left_wheel_link">
      <pose frame="">-0.36 0.26 0.0 0 -0 0</pose>
      <inertial>
        <pose frame="">0 0 0 0 -0 0</pose>
        <mass>2.637</mass>
        <inertia>
          <ixx>0.02467</ixx>
          <ixy>0</ixy>
          <ixz>0</ixz>
          <iyy>0.04411</iyy>
          <iyz>0</iyz>
          <izz>0.02467</izz>
        </inertia>
      </inertial>
      <collision name="rear_left_wheel_link_collision">
        <pose frame="">0 0 0 1.5707963267948966 -0 0</pose>
        <geometry>
          <cylinder>
            <length>0.1143</length>
            <radius>0.1651</radius>
          </cylinder>
        </geometry>
        <surface>
          <contact>
            <ode>
              <kp>1e+07</kp>
              <kd>1</kd>
            </ode>
          </contact>
          <friction>
            <ode>
              <mu>1</mu>
              <mu2>1</mu2>
              <slip1>0.035</slip1>
              <slip2>0</slip2>
              <fdir1>0 0 1</fdir1>
            </ode>
          </friction>
        </surface>
      </collision>

      <visual name="rear_left_wheel_link_visual">
        <pose frame="">0 0 0 1.5707963267948966 -0 0</pose>
        <geometry>
          <cylinder>
            <length>0.1</length>
            <radius>0.129</radius>
          </cylinder>
        </geometry>
      </visual>

      <gravity>1</gravity>
      <velocity_decay/>
    </link>
    <joint name="rear_left_wheel_joint" type="revolute">
      <child>rear_left_wheel_link</child>
      <parent>base_link</parent>
      <axis>
        <xyz>0 1 0</xyz>
        <limit>
          <lower>-1e+16</lower>
          <upper>1e+16</upper>
        </limit>
        <dynamics>
          <spring_reference>0</spring_reference>
          <spring_stiffness>0</spring_stiffness>
        </dynamics>
        <use_parent_model_frame>1</use_parent_model_frame>
      </axis>
    </joint>
    <!-- Right Side Wheels -->
    <link name="front_right_wheel_link">
      <pose frame="">0.360 -0.26 0.00 0 -0 0</pose>
      <inertial>
        <pose frame="">0 0 0 0 -0 0</pose>
        <mass>2.637</mass>
        <inertia>
          <ixx>0.02467</ixx>
          <ixy>0</ixy>
          <ixz>0</ixz>
          <iyy>0.04411</iyy>
          <iyz>0</iyz>
          <izz>0.02467</izz>
        </inertia>
      </inertial>
      <collision name="front_right_wheel_link_collision">
        <pose frame="">0 0 0 1.5707963267948966 -0 0</pose>
        <geometry>
          <cylinder>
            <length>0.1</length>
            <radius>0.129</radius>
          </cylinder>
        </geometry>
        <surface>
          <contact>
            <ode>
              <kp>1e+07</kp>
              <kd>1</kd>
            </ode>
          </contact>
          <friction>
            <ode>
              <mu>1</mu>
              <mu2>1</mu2>
              <slip1>0.035</slip1>
              <slip2>0</slip2>
              <fdir1>0 0 1</fdir1>
            </ode>
          </friction>
        </surface>
      </collision>

      <visual name="front_right_wheel_link_visual">
        <pose frame="">0 0 0 1.5707963267948966 -0 0</pose>
        <geometry>
          <cylinder>
            <length>0.1</length>
            <radius>0.129</radius>
          </cylinder>
        </geometry>
      </visual>

      <gravity>1</gravity>
      <velocity_decay/>
    </link>
    <joint name="front_right_wheel_joint" type="revolute">
      <child>front_right_wheel_link</child>
      <parent>base_link</parent>
      <axis>
        <xyz>0 1 0</xyz>
        <limit>
          <lower>-1e+16</lower>
          <upper>1e+16</upper>
        </limit>
        <dynamics>
          <spring_reference>0</spring_reference>
          <spring_stiffness>0</spring_stiffness>
        </dynamics>
        <use_parent_model_frame>1</use_parent_model_frame>
      </axis>
    </joint>
    <link name="front_middle_right_wheel_link">
      <pose frame="">0.120 -0.26 0.00 0 -0 0</pose>
      <inertial>
        <pose frame="">0 0 0 0 -0 0</pose>
        <mass>2.637</mass>
        <inertia>
          <ixx>0.02467</ixx>
          <ixy>0</ixy>
          <ixz>0</ixz>
          <iyy>0.04411</iyy>
          <iyz>0</iyz>
          <izz>0.02467</izz>
        </inertia>
      </inertial>
      <collision name="front_middle_right_wheel_link_collision">
        <pose frame="">0 0 0 1.5707963267948966 -0 0</pose>
        <geometry>
          <cylinder>
            <length>0.1</length>
            <radius>0.129</radius>
          </cylinder>
        </geometry>
        <surface>
          <contact>
            <ode>
              <kp>1e+07</kp>
              <kd>1</kd>
            </ode>
          </contact>
          <friction>
            <ode>
              <mu>1</mu>
              <mu2>1</mu2>
              <slip1>0.035</slip1>
              <slip2>0</slip2>
              <fdir1>0 0 1</fdir1>
            </ode>
          </friction>
        </surface>
      </collision>

      <visual name="front_middle_right_wheel_link_visual">
        <pose frame="">0 0 0 1.5707963267948966 -0 0</pose>
        <geometry>
          <cylinder>
            <length>0.1</length>
            <radius>0.129</radius>
          </cylinder>
        </geometry>
      </visual>

      <gravity>1</gravity>
      <velocity_decay/>
    </link>
    <joint name="front_middle_right_wheel_joint" type="revolute">
      <child>front_middle_right_wheel_link</child>
      <parent>base_link</parent>
      <axis>
        <xyz>0 1 0</xyz>
        <limit>
          <lower>-1e+16</lower>
          <upper>1e+16</upper>
        </limit>
        <dynamics>
          <spring_reference>0</spring_reference>
          <spring_stiffness>0</spring_stiffness>
        </dynamics>
        <use_parent_model_frame>1</use_parent_model_frame>
      </axis>
    </joint>
    <link name="rear_middle_right_wheel_link">
      <pose frame="">-0.120 -0.26 0.00 0 -0 0</pose>
      <inertial>
        <pose frame="">0 0 0 0 -0 0</pose>
        <mass>2.637</mass>
        <inertia>
          <ixx>0.02467</ixx>
          <ixy>0</ixy>
          <ixz>0</ixz>
          <iyy>0.04411</iyy>
          <iyz>0</iyz>
          <izz>0.02467</izz>
        </inertia>
      </inertial>
      <collision name="rear_middle_right_wheel_link_collision">
        <pose frame="">0 0 0 1.5707963267948966 -0 0</pose>
        <geometry>
          <cylinder>
            <length>0.1</length>
            <radius>0.129</radius>
          </cylinder>
        </geometry>
        <surface>
          <contact>
            <ode>
              <kp>1e+07</kp>
              <kd>1</kd>
            </ode>
          </contact>
          <friction>
            <ode>
              <mu>1</mu>
              <mu2>1</mu2>
              <slip1>0.035</slip1>
              <slip2>0</slip2>
              <fdir1>0 0 1</fdir1>
            </ode>
          </friction>
        </surface>
      </collision>

      <visual name="rear_middle_right_wheel_link_visual">
        <pose frame="">0 0 0 1.5707963267948966 -0 0</pose>
        <geometry>
          <cylinder>
            <length>0.1</length>
            <radius>0.129</radius>
          </cylinder>
        </geometry>
      </visual>

      <gravity>1</gravity>
      <velocity_decay/>
    </link>
    <joint name="rear_middle_right_wheel_joint" type="revolute">
      <child>rear_middle_right_wheel_link</child>
      <parent>base_link</parent>
      <axis>
        <xyz>0 1 0</xyz>
        <limit>
          <lower>-1e+16</lower>
          <upper>1e+16</upper>
        </limit>
        <dynamics>
          <spring_reference>0</spring_reference>
          <spring_stiffness>0</spring_stiffness>
        </dynamics>
        <use_parent_model_frame>1</use_parent_model_frame>
      </axis>
    </joint>
    <link name="rear_right_wheel_link">
      <pose frame="">-0.36 -0.26 0.0 0 -0 0</pose>
      <inertial>
        <pose frame="">0 0 0 0 -0 0</pose>
        <mass>2.637</mass>
        <inertia>
          <ixx>0.02467</ixx>
          <ixy>0</ixy>
          <ixz>0</ixz>
          <iyy>0.04411</iyy>
          <iyz>0</iyz>
          <izz>0.02467</izz>
        </inertia>
      </inertial>
      <collision name="rear_right_wheel_link_collision">
        <pose frame="">0 0 0 1.5707963267948966 -0 0</pose>
        <geometry>
          <cylinder>
            <length>0.1143</length>
            <radius>0.1651</radius>
          </cylinder>
        </geometry>
        <surface>
          <contact>
            <ode>
              <kp>1e+07</kp>
              <kd>1</kd>
            </ode>
          </contact>
          <friction>
            <ode>
              <mu>1</mu>
              <mu2>1</mu2>
              <slip1>0.035</slip1>
              <slip2>0</slip2>
              <fdir1>0 0 1</fdir1>
            </ode>
          </friction>
        </surface>
      </collision>

      <visual name="rear_right_wheel_link_visual">
        <pose frame="">0 0 0 1.5707963267948966 -0 0</pose>
        <geometry>
          <cylinder>
            <length>0.1</length>
            <radius>0.129</radius>
          </cylinder>
        </geometry>
      </visual>

      <gravity>1</gravity>
      <velocity_decay/>
    </link>
    <joint name="rear_right_wheel_joint" type="revolute">
      <child>rear_right_wheel_link</child>
      <parent>base_link</parent>
      <axis>
        <xyz>0 1 0</xyz>
        <limit>
          <lower>-1e+16</lower>
          <upper>1e+16</upper>
        </limit>
        <dynamics>
          <spring_reference>0</spring_reference>
          <spring_stiffness>0</spring_stiffness>
        </dynamics>
        <use_parent_model_frame>1</use_parent_model_frame>
      </axis>
    </joint>
    <!-- Gimbal Links + Joints -->
    <link name="pan_gimbal_link">
      <pose frame="">0.354 0 0.427 0 -0 0</pose>
      <inertial>
        <pose frame="">0 0 0 0 -0 0</pose>
        <mass>0.1</mass>
        <inertia>
            <ixx>0.000016875</ixx>
            <ixy>0</ixy>
            <ixz>0</ixz>
            <iyy>0.00000001</iyy>
            <iyz>0</iyz>
            <izz>0.000016875</izz>
        </inertia>
      </inertial>
      <collision name="pan_gimbal_link_collision">
      <pose frame="">0.0 0 0.0 0 -0 0</pose>
      <geometry>
        <cylinder>
          <length>0.045</length>
          <radius>0.014</radius>
        </cylinder>
      </geometry>
      <surface>
        <contact>
          <ode>
            <kp>1e+07</kp>
            <kd>1</kd>
          </ode>
        </contact>
      </surface>
      </collision>
      <visual name="pan_gimbal_link_visual">
        <pose frame="">0.0 0 0.0 0 -0 0</pose>
        <geometry>
          <cylinder>
            <length>0.045</length>
            <radius>0.014</radius>
          </cylinder>
        </geometry>
      </visual>
    </link>
    <link name="tilt_gimbal_link">
      <pose frame="">0.354 0 0.460 0 -0 0</pose>
      <inertial>
        <pose frame="">0 0 0 1.570796 -0 0</pose>
        <mass>0.1</mass>
        <inertia>
          <ixx>0.000016875</ixx>
          <ixy>0</ixy>
          <ixz>0</ixz>
          <iyy>0.00000001</iyy>
          <iyz>0</iyz>
          <izz>0.000016875</izz>
        </inertia>
      </inertial>
      <collision name="tilt_gimbal_link_collision">
      <pose frame="">0.0 0 0.0 1.570796 -0 0</pose>
      <geometry>
        <cylinder>
          <length>0.045</length>
          <radius>0.014</radius>
        </cylinder>
      </geometry>
      <surface>
        <contact>
          <ode>
            <kp>1e+07</kp>
            <kd>1</kd>
          </ode>
        </contact>
      </surface>
      </collision>
      <visual name="tilt_gimbal_link_visual">
        <pose frame="">0.0 0 0.0 1.570796 -0 0</pose>
        <geometry>
          <cylinder>
            <length>0.045</length>
            <radius>0.014</radius>
          </cylinder>
        </geometry>
      </visual>
      <!-- Based on Intel realsense D435 (intrinsics and distortion not modeled)-->
      <sensor name="camera_pan_tilt" type="rgbd_camera">
        <camera name="camera_pan_tilt">
            <horizontal_fov>1.5184</horizontal_fov>
            <lens>
                <intrinsics>
                    <!-- fx = fy = width / ( 2 * tan (hfov / 2 ) ) -->
                    <fx>277.1</fx>
                    <fy>277.1</fy>
                    <!-- cx = ( width + 1 ) / 2 -->
                    <cx>320.5</cx>
                    <!-- cy = ( height + 1 ) / 2 -->
                    <cy>240.5</cy>
                    <s>0</s>
                </intrinsics>
            </lens>
            <distortion>
                <k1>0.0</k1>
                <k2>0.0</k2>
                <k3>0.0</k3>
                <p1>0.0</p1>
                <p2>0.0</p2>
                <center>0.5 0.5</center>
            </distortion>
            <image>
                <width>640</width>
                <height>480</height>
                <format>R8G8B8</format>
            </image>
            <clip>
                <near>0.01</near>
                <far>300</far>
            </clip>
            <depth_camera>
              <clip>
                <near>0.1</near>
                <far>10</far>
              </clip>
            </depth_camera>
            <noise>
                <type>gaussian</type>
                <mean>0</mean>
                <stddev>0.007</stddev>
            </noise>
        </camera>
        <always_on>1</always_on>
        <update_rate>30</update_rate>
        <visualize>0</visualize>
        <!-- <pose frame="">0.424 0 0.542 0 0.0 0</pose>  -->
        <pose frame="">0.0 0 0.03 0 0.0 0</pose> 
      </sensor>
      <gravity>1</gravity>
      <velocity_decay/>
      <visual name="tilt_gimbal_link_fixed_joint_lump__camera/camera_link_visual_0">
        <pose frame="">0 0 0.03 0 0.0 0</pose>
        <geometry>
          <mesh>
            <uri>meshes/realsense.dae</uri>
          </mesh>
        </geometry>
      </visual>
      <visual name="tilt_gimbal_link_fixed_joint_lump_bot_camera_plate_link_visual_1">
       <pose frame="">0 0 0.017 0 -0 0</pose>
        <geometry>
          <box>
            <size>0.025 0.13 0.007</size>
          </box>
        </geometry>
      </visual>
      <visual name="tilt_gimbal_link_fixed_joint_lump_bot_camera_plate_link_visual_2">
       <pose frame="">0 0 0.042 0 -0 0</pose>
        <geometry>
          <box>
            <size>0.025 0.13 0.007</size>
          </box>
        </geometry>
      </visual>
      <light name="flashlight_flashlight_light_source_lamp_light" type="spot">
        <pose frame="">0.0 0.0 0.065 3.141592653589793 1.8207926535897934 -0.0015926535897931</pose>
        <attenuation>
          <range>50</range>
          <linear>0</linear>
          <constant>0.1</constant>
          <quadratic>0.0025</quadratic>
        </attenuation>
        <diffuse>0.8 0.8 0.5 1</diffuse>
        <specular>0.8 0.8 0.5 1</specular>
        <spot>
          <inner_angle>1.2</inner_angle>
          <outer_angle>1.3</outer_angle>
          <falloff>1</falloff>
        </spot>
        <direction>0 0 -1</direction>
      </light>
      <visual name="flashlight_flashlight_light_source_lamp_viz_visual">
        <pose>0.0 0.0 0.065 3.141592653589793 1.8207926535897934 -0.0015926535897931</pose>
        <geometry>
          <cylinder>
            <radius>0.019</radius>
            <length>0.005</length>
          </cylinder>
        </geometry>
        <transparency>0</transparency>
        <material>
          <ambient>1 1 1 1</ambient>
          <diffuse>1 1 1 1</diffuse>
          <specular>1 1 1 1</specular>
          <emissive>1 1 1 1</emissive>
        </material>
      </visual>
    </link>
    <joint name="pan_gimbal_joint" type="revolute">
      <child>pan_gimbal_link</child>
      <parent>base_link</parent>
      <axis>
        <xyz>0 0 1</xyz>
        <limit>
          <lower>-1e+16</lower>
          <upper>1e+16</upper>
        </limit>
        <dynamics>
          <spring_reference>0</spring_reference>
          <spring_stiffness>0</spring_stiffness>
        </dynamics>
        <use_parent_model_frame>1</use_parent_model_frame>
      </axis>
    </joint>
    <joint name="tilt_gimbal_joint" type="revolute">
      <child>tilt_gimbal_link</child>
      <parent>pan_gimbal_link</parent>
      <axis>
        <xyz>0 1 0</xyz>
        <limit>
          <lower>-2.79253</lower> <!-- 160 degrees both direction (mechanical interference)-->
          <upper>2.79253</upper>
        </limit>
        <dynamics>
          <spring_reference>0</spring_reference>
          <spring_stiffness>0</spring_stiffness>
        </dynamics>
        <use_parent_model_frame>1</use_parent_model_frame>
      </axis>
    </joint>
    <!-- Gimbal Joints Plugins --> 
    <plugin
      filename="libignition-gazebo-joint-controller-system.so"
      name="ignition::gazebo::systems::JointController">
      <joint_name>pan_gimbal_joint</joint_name>
    </plugin>
    <plugin
      filename="libignition-gazebo-joint-controller-system.so"
      name="ignition::gazebo::systems::JointController">
      <joint_name>tilt_gimbal_joint</joint_name>
    </plugin>
    <plugin
      filename="libignition-gazebo-joint-state-publisher-system.so"
      name="ignition::gazebo::systems::JointStatePublisher">
    </plugin>
    <static>0</static>
  </model>
</sdf>

