<?xml version='1.0'?>
<sdf version='1.6'>
  <model name='ctu_cras_norlab_absolem_sensor_config_1'>
    <link name='ctu_cras_norlab_absolem_sensor_config_1/base_link'>
      <pose>0 0 0 0 -0 0</pose>
      <inertial>
        <pose>-0.066916 -0.007121 0.159422 0 -0 0</pose>
        <mass>21.9141</mass>
        <inertia>
          <ixx>0.117218</ixx>
          <ixy>0.0191964</ixy>
          <ixz>-0.0488577</ixz>
          <iyy>0.341695</iyy>
          <iyz>0.0179603</iyz>
          <izz>0.296202</izz>
        </inertia>
      </inertial>
      <collision name='ctu_cras_norlab_absolem_sensor_config_1/base_link_collision'>
        <pose>-0.122 0 0.118 0 -0 0</pose>
        <geometry>
          <box>
            <size>0.50017 0.24093 0.139</size>
          </box>
        </geometry>
        <surface>
          <contact>
            <ode/>
          </contact>
          <friction>
            <ode/>
          </friction>
        </surface>
      </collision>
      <collision name='ctu_cras_norlab_absolem_sensor_config_1/base_link_collision_1'>
        <pose>0.157 0 0.118 0 -0 0</pose>
        <geometry>
          <box>
            <size>0.056 0.12093 0.139</size>
          </box>
        </geometry>
        <surface>
          <contact>
            <ode/>
          </contact>
          <friction>
            <ode/>
          </friction>
        </surface>
      </collision>
      <collision name='ctu_cras_norlab_absolem_sensor_config_1/base_link_collision_2'>
        <pose>0.144 -0.076 0.118 0 -0 0.785398</pose>
        <geometry>
          <box>
            <size>0.083 0.04 0.139</size>
          </box>
        </geometry>
        <surface>
          <contact>
            <ode/>
          </contact>
          <friction>
            <ode/>
          </friction>
        </surface>
      </collision>
      <collision name='ctu_cras_norlab_absolem_sensor_config_1/base_link_collision_3'>
        <pose>0.144 0.076 0.118 0 0 -0.785398</pose>
        <geometry>
          <box>
            <size>0.083 0.04 0.139</size>
          </box>
        </geometry>
        <surface>
          <contact>
            <ode/>
          </contact>
          <friction>
            <ode/>
          </friction>
        </surface>
      </collision>
      <collision name='ctu_cras_norlab_absolem_sensor_config_1/base_link_collision_4'>
        <pose>0 0.135 0.09 0 -0 0</pose>
        <geometry>
          <box>
            <size>0.055 0.04 0.08</size>
          </box>
        </geometry>
        <surface>
          <contact>
            <ode/>
          </contact>
          <friction>
            <ode/>
          </friction>
        </surface>
      </collision>
      <collision name='ctu_cras_norlab_absolem_sensor_config_1/base_link_collision_5'>
        <pose>0 0.155 0.013 0 -0 0</pose>
        <geometry>
          <box>
            <size>0.055 0.02 0.075</size>
          </box>
        </geometry>
        <surface>
          <contact>
            <ode/>
          </contact>
          <friction>
            <ode/>
          </friction>
        </surface>
      </collision>
      <collision name='ctu_cras_norlab_absolem_sensor_config_1/base_link_collision_6'>
        <pose>0 -0.135 0.09 0 -0 0</pose>
        <geometry>
          <box>
            <size>0.055 0.04 0.08</size>
          </box>
        </geometry>
        <surface>
          <contact>
            <ode/>
          </contact>
          <friction>
            <ode/>
          </friction>
        </surface>
      </collision>
      <collision name='ctu_cras_norlab_absolem_sensor_config_1/base_link_collision_7'>
        <pose>0 -0.155 0.013 0 -0 0</pose>
        <geometry>
          <box>
            <size>0.055 0.02 0.075</size>
          </box>
        </geometry>
        <surface>
          <contact>
            <ode/>
          </contact>
          <friction>
            <ode/>
          </friction>
        </surface>
      </collision>
      <collision name='ctu_cras_norlab_absolem_sensor_config_1/base_link_fixed_joint_lump__big_collision_box_collision_8'>
        <pose>-0.1 0 0.33 0 -0 0</pose>
        <geometry>
          <box>
            <size>0.65 0.5 0.5</size>
          </box>
        </geometry>
      </collision>
      <collision name='ctu_cras_norlab_absolem_sensor_config_1/base_link_fixed_joint_lump__ctu_cras_norlab_absolem_sensor_config_1/antenna_collision_9'>
        <pose>-0.39064 0.0789 0.1551 0 1.5708 0</pose>
        <geometry>
          <cylinder>
            <length>0.03718</length>
            <radius>0.008</radius>
          </cylinder>
        </geometry>
      </collision>
      <collision name='ctu_cras_norlab_absolem_sensor_config_1/base_link_fixed_joint_lump__ctu_cras_norlab_absolem_sensor_config_1/antenna_collision_10'>
        <pose>-0.402 0.0789 0.34563 0 -0 0</pose>
        <geometry>
          <cylinder>
            <length>0.38107</length>
            <radius>0.008</radius>
          </cylinder>
        </geometry>
      </collision>
      <collision name='ctu_cras_norlab_absolem_sensor_config_1/base_link_fixed_joint_lump__ctu_cras_norlab_absolem_sensor_config_1/battery_collision_11'>
        <pose>-0.2836 -0.0221 0.1132 0 -0 0</pose>
        <geometry>
          <box>
            <size>0.145 0.135 0.082</size>
          </box>
        </geometry>
      </collision>
      <collision name='ctu_cras_norlab_absolem_sensor_config_1/base_link_fixed_joint_lump__ctu_cras_norlab_absolem_sensor_config_1/jetson_collision_12'>
        <pose>0.136 0.0435 0.2125 0 -0 0</pose>
        <geometry>
          <box>
            <size>0.07 0.1 0.055</size>
          </box>
        </geometry>
      </collision>
      <collision name='ctu_cras_norlab_absolem_sensor_config_1/base_link_fixed_joint_lump__ctu_cras_norlab_absolem_sensor_config_1/rear_sensor_item_collision_13'>
        <pose>-0.295 -0.1065 0.36 0 -0 0</pose>
        <geometry>
          <box>
            <size>0.02 0.02 0.35</size>
          </box>
        </geometry>
      </collision>
      <collision name='ctu_cras_norlab_absolem_sensor_config_1/base_link_fixed_joint_lump__ctu_cras_norlab_absolem_sensor_config_1/mobilicom_collision_14'>
        <pose>-0.295121 -0.064 0.385106 -1.56579 -0.858407 -7.3e-05</pose>
        <geometry>
          <box>
            <size>0.2 0.095 0.065</size>
          </box>
        </geometry>
      </collision>
      <collision name='ctu_cras_norlab_absolem_sensor_config_1/base_link_fixed_joint_lump__ctu_cras_norlab_absolem_sensor_config_1/mobilicom_antenna_l_collision_15'>
        <pose>-0.139117 -0.02338 0.465445 -1.29704 -0.418237 -1.17028</pose>
        <geometry>
          <cylinder>
            <length>0.17</length>
            <radius>0.025</radius>
          </cylinder>
        </geometry>
      </collision>
      <collision name='ctu_cras_norlab_absolem_sensor_config_1/base_link_fixed_joint_lump__ctu_cras_norlab_absolem_sensor_config_1/mobilicom_antenna_r_collision_16'>
        <pose>-0.193116 -0.064558 0.541453 -0.7124 0.007057 -1.57035</pose>
        <geometry>
          <cylinder>
            <length>0.17</length>
            <radius>0.025</radius>
          </cylinder>
        </geometry>
      </collision>
      <collision name='ctu_cras_norlab_absolem_sensor_config_1/base_link_fixed_joint_lump__ctu_cras_norlab_absolem_sensor_config_1/top_box_collision_17'>
        <pose>-0.007 -0.0557 0.2165 0 -0 0</pose>
        <geometry>
          <box>
            <size>0.2 0.133 0.06252</size>
          </box>
        </geometry>
      </collision>
      <collision name='ctu_cras_norlab_absolem_sensor_config_1/base_link_fixed_joint_lump__ctu_cras_norlab_absolem_sensor_config_1/top_box_collision_18'>
        <pose>-0.07624 -0.01443 0.254 0 -0 0</pose>
        <geometry>
          <box>
            <size>0.044 0.044 0.01303</size>
          </box>
        </geometry>
      </collision>
      <collision name='ctu_cras_norlab_absolem_sensor_config_1/base_link_fixed_joint_lump__ctu_cras_norlab_absolem_sensor_config_1/top_box_collision_19'>
        <pose>-0.05183 -0.09792 0.26496 0 -0 0</pose>
        <geometry>
          <box>
            <size>0.03732 0.03523 0.03489</size>
          </box>
        </geometry>
      </collision>
      <collision name='ctu_cras_norlab_absolem_sensor_config_1/base_link_fixed_joint_lump__ctu_cras_norlab_absolem_sensor_config_1/omnicam_collision_20'>
        <pose>0.020991 -0.05685 0.3172 0 0 -0.628319</pose>
        <geometry>
          <cylinder>
            <length>0.137</length>
            <radius>0.068</radius>
          </cylinder>
        </geometry>
      </collision>
      <collision name='ctu_cras_norlab_absolem_sensor_config_1/base_link_fixed_joint_lump__ctu_cras_norlab_absolem_sensor_config_1/omnicam_sensor_mount_collision_21'>
        <pose>0.0243 -0.0574 0.3732 0 0 -0.000319</pose>
        <geometry>
          <cylinder>
            <length>0.044</length>
            <radius>0.095</radius>
          </cylinder>
        </geometry>
      </collision>
      <collision name='ctu_cras_norlab_absolem_sensor_config_1/base_link_fixed_joint_lump__ctu_cras_norlab_absolem_sensor_config_1/realsense_holder_part2_collision_22'>
        <pose>0.111811 -0.018928 0.440133 0 0.504467 -0.000319</pose>
        <geometry>
          <box>
            <size>0.008 0.075 0.025</size>
          </box>
        </geometry>
        <surface>
          <contact>
            <ode/>
          </contact>
          <friction>
            <ode/>
          </friction>
        </surface>
      </collision>
      <collision name='ctu_cras_norlab_absolem_sensor_config_1/base_link_fixed_joint_lump__ctu_cras_norlab_absolem_sensor_config_1/realsense_holder_part2_collision_23'>
        <pose>0.099551 -0.028924 0.4469 0 0.504467 -0.000319</pose>
        <geometry>
          <box>
            <size>0.035 0.01 0.028</size>
          </box>
        </geometry>
        <surface>
          <contact>
            <ode/>
          </contact>
          <friction>
            <ode/>
          </friction>
        </surface>
      </collision>
      <collision name='ctu_cras_norlab_absolem_sensor_config_1/base_link_fixed_joint_lump__ctu_cras_norlab_absolem_sensor_config_1/realsense_holder_part2_collision_24'>
        <pose>0.074085 -0.043916 0.415266 -0 0.004467 -0.000319</pose>
        <geometry>
          <box>
            <size>0.035 0.045 0.073</size>
          </box>
        </geometry>
        <surface>
          <contact>
            <ode/>
          </contact>
          <friction>
            <ode/>
          </friction>
        </surface>
      </collision>
      <collision name='ctu_cras_norlab_absolem_sensor_config_1/base_link_fixed_joint_lump__ctu_cras_norlab_absolem_sensor_config_1/camera_link_collision_25'>
        <pose>0.124976 -0.017932 0.432945 0.015 0.499467 -0.000319</pose>
        <geometry>
          <box>
            <size>0.15 0.2 0.05</size>
          </box>
        </geometry>
        <surface>
          <contact>
            <ode/>
          </contact>
          <friction>
            <ode/>
          </friction>
        </surface>
      </collision>
      <visual name='ctu_cras_norlab_absolem_sensor_config_1/base_link_visual'>
        <pose>0 0 0 0 -0 0</pose>
        <geometry>
          <mesh>
            <scale>1 1 1</scale>
            <uri>model://ctu_cras_norlab_absolem_sensor_config_1/meshes/body.dae</uri>
          </mesh>
        </geometry>
      </visual>
      <visual name='ctu_cras_norlab_absolem_sensor_config_1/base_link_fixed_joint_lump__ctu_cras_norlab_absolem_sensor_config_1/antenna_visual_1'>
        <pose>-0.372 0.0789 0.1551 0 -0 0</pose>
        <geometry>
          <mesh>
            <scale>1 1 1</scale>
            <uri>model://ctu_cras_norlab_absolem_sensor_config_1/meshes/antenna.dae</uri>
          </mesh>
        </geometry>
      </visual>
      <visual name='ctu_cras_norlab_absolem_sensor_config_1/base_link_fixed_joint_lump__ctu_cras_norlab_absolem_sensor_config_1/battery_visual_2'>
        <pose>-0.2836 -0.0221 0.0722 0 -0 0</pose>
        <geometry>
          <mesh>
            <scale>1 1 1</scale>
            <uri>model://ctu_cras_norlab_absolem_sensor_config_1/meshes/battery.dae</uri>
          </mesh>
        </geometry>
      </visual>
      <visual name='ctu_cras_norlab_absolem_sensor_config_1/base_link_fixed_joint_lump__ctu_cras_norlab_absolem_sensor_config_1/imu_visual_3'>
        <pose>0 0 0.15 -3.14159 0 0</pose>
        <geometry>
          <box>
            <size>0.005 0.005 0.005</size>
          </box>
        </geometry>
      </visual>
      <visual name='ctu_cras_norlab_absolem_sensor_config_1/base_link_fixed_joint_lump__ctu_cras_norlab_absolem_sensor_config_1/laser_base_visual_4'>
        <pose>0.2502 0 0.1407 0 -0 0</pose>
        <geometry>
          <box>
            <size>0.005 0.005 0.005</size>
          </box>
        </geometry>
      </visual>
      <visual name='ctu_cras_norlab_absolem_sensor_config_1/base_link_fixed_joint_lump__ctu_cras_norlab_absolem_sensor_config_1/jetson_visual_5'>
        <pose>0.136 0.0435 0.2125 0 -0 0</pose>
        <geometry>
          <box>
            <size>0.07 0.1 0.055</size>
          </box>
        </geometry>
      </visual>
      <visual name='ctu_cras_norlab_absolem_sensor_config_1/base_link_fixed_joint_lump__ctu_cras_norlab_absolem_sensor_config_1/rear_sensor_item_visual_6'>
        <pose>-0.295 -0.1065 0.36 0 -0 0</pose>
        <geometry>
          <box>
            <size>0.02 0.02 0.35</size>
          </box>
        </geometry>
      </visual>
      <visual name='ctu_cras_norlab_absolem_sensor_config_1/base_link_fixed_joint_lump__ctu_cras_norlab_absolem_sensor_config_1/mobilicom_visual_7'>
        <pose>-0.275459 -0.078002 0.407765 -1.56579 -0.858407 -7.3e-05</pose>
        <geometry>
          <box>
            <size>0.12 0.075 0.037</size>
          </box>
        </geometry>
      </visual>
      <visual name='ctu_cras_norlab_absolem_sensor_config_1/base_link_fixed_joint_lump__ctu_cras_norlab_absolem_sensor_config_1/mobilicom_antenna_l_visual_8'>
        <pose>-0.139117 -0.02338 0.465445 -1.29704 -0.418237 -1.17028</pose>
        <geometry>
          <cylinder>
            <length>0.17</length>
            <radius>0.015</radius>
          </cylinder>
        </geometry>
      </visual>
      <visual name='ctu_cras_norlab_absolem_sensor_config_1/base_link_fixed_joint_lump__ctu_cras_norlab_absolem_sensor_config_1/mobilicom_antenna_r_visual_9'>
        <pose>-0.193116 -0.064558 0.541453 -0.7124 0.007057 -1.57035</pose>
        <geometry>
          <cylinder>
            <length>0.17</length>
            <radius>0.015</radius>
          </cylinder>
        </geometry>
      </visual>
      <visual name='ctu_cras_norlab_absolem_sensor_config_1/base_link_fixed_joint_lump__ctu_cras_norlab_absolem_sensor_config_1/top_box_visual_10'>
        <pose>0.022 -0.0557 0.185 0 -0 0</pose>
        <geometry>
          <mesh>
            <scale>1 1 1</scale>
            <uri>model://ctu_cras_norlab_absolem_sensor_config_1/meshes/top_box.dae</uri>
          </mesh>
        </geometry>
      </visual>
      <visual name='ctu_cras_norlab_absolem_sensor_config_1/base_link_fixed_joint_lump__ctu_cras_norlab_absolem_sensor_config_1/omnicam_visual_11'>
        <pose>0.0243 -0.0574 0.3142 0 0 -0.628319</pose>
        <geometry>
          <mesh>
            <scale>1 1 1</scale>
            <uri>model://ctu_cras_norlab_absolem_sensor_config_1/meshes/omnicam.dae</uri>
          </mesh>
        </geometry>
      </visual>
      <visual name='ctu_cras_norlab_absolem_sensor_config_1/base_link_fixed_joint_lump__ctu_cras_norlab_absolem_sensor_config_1/camera_0_visual_12'>
        <pose>0.057346 -0.083518 0.313841 -1.57174 -0.000784 -2.19802</pose>
        <geometry>
          <box>
            <size>0.005 0.005 0.005</size>
          </box>
        </geometry>
      </visual>
      <visual name='ctu_cras_norlab_absolem_sensor_config_1/base_link_fixed_joint_lump__ctu_cras_norlab_absolem_sensor_config_1/camera_1_visual_13'>
        <pose>0.009992 -0.096606 0.314114 -1.57187 0.000853 2.82791</pose>
        <geometry>
          <box>
            <size>0.005 0.005 0.005</size>
          </box>
        </geometry>
      </visual>
      <visual name='ctu_cras_norlab_absolem_sensor_config_1/base_link_fixed_joint_lump__ctu_cras_norlab_absolem_sensor_config_1/camera_2_visual_14'>
        <pose>-0.01735 -0.055429 0.314721 -1.5725 0.00415 1.56974</pose>
        <geometry>
          <box>
            <size>0.005 0.005 0.005</size>
          </box>
        </geometry>
      </visual>
      <visual name='ctu_cras_norlab_absolem_sensor_config_1/base_link_fixed_joint_lump__ctu_cras_norlab_absolem_sensor_config_1/camera_3_visual_15'>
        <pose>0.012561 -0.017068 0.314417 -1.57137 0.005611 0.313689</pose>
        <geometry>
          <box>
            <size>0.005 0.005 0.005</size>
          </box>
        </geometry>
      </visual>
      <visual name='ctu_cras_norlab_absolem_sensor_config_1/base_link_fixed_joint_lump__ctu_cras_norlab_absolem_sensor_config_1/camera_4_visual_16'>
        <pose>0.058951 -0.03438 0.313899 -1.58161 0.001034 -0.943109</pose>
        <geometry>
          <box>
            <size>0.005 0.005 0.005</size>
          </box>
        </geometry>
      </visual>
      <visual name='ctu_cras_norlab_absolem_sensor_config_1/base_link_fixed_joint_lump__ctu_cras_norlab_absolem_sensor_config_1/camera_5_visual_17'>
        <pose>0.024083 -0.058382 0.376328 0.003778 0.000786 -2.20023</pose>
        <geometry>
          <box>
            <size>0.005 0.005 0.005</size>
          </box>
        </geometry>
      </visual>
      <visual name='ctu_cras_norlab_absolem_sensor_config_1/base_link_fixed_joint_lump__ctu_cras_norlab_absolem_sensor_config_1/omnicam_forward_visual_18'>
        <pose>0.0243 -0.0574 0.3142 0 0 -0.000319</pose>
        <geometry>
          <box>
            <size>0.005 0.005 0.005</size>
          </box>
        </geometry>
      </visual>
      <visual name='ctu_cras_norlab_absolem_sensor_config_1/base_link_fixed_joint_lump__ctu_cras_norlab_absolem_sensor_config_1/omnicam_bottom_visual_19'>
        <pose>0.0243 -0.0574 0.2482 0 0 -0.000319</pose>
        <geometry>
          <box>
            <size>0.005 0.005 0.005</size>
          </box>
        </geometry>
      </visual>
      <visual name='ctu_cras_norlab_absolem_sensor_config_1/base_link_fixed_joint_lump__ctu_cras_norlab_absolem_sensor_config_1/omnicam_top_visual_20'>
        <pose>0.0243 -0.0574 0.3882 0 0 -0.000319</pose>
        <geometry>
          <box>
            <size>0.005 0.005 0.005</size>
          </box>
        </geometry>
      </visual>
      <visual name='ctu_cras_norlab_absolem_sensor_config_1/base_link_fixed_joint_lump__ctu_cras_norlab_absolem_sensor_config_1/omnicam_sensor_mount_visual_21'>
        <pose>0.021299 -0.059399 0.3882 3.14152 -0 -0.000319</pose>
        <geometry>
          <mesh>
            <scale>0.001 0.001 0.001</scale>
            <uri>model://ctu_cras_norlab_absolem_sensor_config_1/meshes/lb3_mount_2.stl</uri>
          </mesh>
        </geometry>
      </visual>
      <visual name='ctu_cras_norlab_absolem_sensor_config_1/base_link_fixed_joint_lump__ctu_cras_norlab_absolem_sensor_config_1/omnicam_sensor_mount_visual_22'>
        <pose>0.0198 -0.057399 0.2482 0 0 -0.000319</pose>
        <geometry>
          <mesh>
            <scale>0.001 0.001 0.001</scale>
            <uri>model://ctu_cras_norlab_absolem_sensor_config_1/meshes/lb3_mount_bottom.stl</uri>
          </mesh>
        </geometry>
      </visual>
      <visual name='ctu_cras_norlab_absolem_sensor_config_1/base_link_fixed_joint_lump__ctu_cras_norlab_absolem_sensor_config_1/realsense_holder_part2_visual_23'>
        <pose>0.088893 -0.073921 0.39452 -5e-06 -0.002418 1.57486</pose>
        <geometry>
          <mesh>
            <scale>0.001 0.001 0.001</scale>
            <uri>model://ctu_cras_norlab_absolem_sensor_config_1/meshes/d435_holder_combined.stl</uri>
          </mesh>
        </geometry>
        <material>
          <diffuse>0.5 0.5 0.5 1</diffuse>
          <ambient>0.1 0.1 0.1 1</ambient>
        </material>
      </visual>
      <visual name='ctu_cras_norlab_absolem_sensor_config_1/base_link_fixed_joint_lump__ctu_cras_norlab_absolem_sensor_config_1/camera_back_mounting_plane_visual_24'>
        <pose>0.115312 -0.018929 0.4382 0.015 0.499467 -0.000319</pose>
        <geometry>
          <box>
            <size>0.005 0.005 0.005</size>
          </box>
        </geometry>
      </visual>
      <visual name='ctu_cras_norlab_absolem_sensor_config_1/base_link_fixed_joint_lump__ctu_cras_norlab_absolem_sensor_config_1/camera_tripod_screw_link_visual_25'>
        <pose>0.119362 -0.010781 0.424738 0.015 0.499467 -0.000319</pose>
        <geometry>
          <box>
            <size>0.005 0.005 0.005</size>
          </box>
        </geometry>
      </visual>
      <visual name='ctu_cras_norlab_absolem_sensor_config_1/base_link_fixed_joint_lump__ctu_cras_norlab_absolem_sensor_config_1/camera_link_visual_26'>
        <pose>0.133882 -0.000937 0.428379 2.07031 -0.013169 1.5633</pose>
        <geometry>
          <mesh>
            <scale>1 1 1</scale>
            <uri>model://ctu_cras_norlab_absolem_sensor_config_1/meshes/realsense_d435.dae</uri>
          </mesh>
        </geometry>
        <material>
          <diffuse>0.5 0.5 0.5 1</diffuse>
          <ambient>0.1 0.1 0.1 1</ambient>
        </material>
      </visual>
      <velocity_decay/>
      <velocity_decay/>
      <light name='light_left' type='spot'>
        <pose>0 0.13 0.2 1.5708 1.5708 0</pose>
        <attenuation>
          <range>50</range>
          <linear>0</linear>
          <constant>0.1</constant>
          <quadratic>0.0025</quadratic>
        </attenuation>
        <diffuse>0.8 0.8 0.5 1</diffuse>
        <specular>0.8 0.8 0.5 1</specular>
        <spot>
          <inner_angle>2.8</inner_angle>
          <outer_angle>2.9</outer_angle>
          <falloff>1</falloff>
        </spot>
        <direction>1 0 0</direction>
      </light>
      <light name='light_right' type='spot'>
        <pose>0 -0.13 0.2 -1.5708 1.5708 0</pose>
        <attenuation>
          <range>50</range>
          <linear>0</linear>
          <constant>0.1</constant>
          <quadratic>0.0025</quadratic>
        </attenuation>
        <diffuse>0.8 0.8 0.5 1</diffuse>
        <specular>0.8 0.8 0.5 1</specular>
        <spot>
          <inner_angle>2.8</inner_angle>
          <outer_angle>2.9</outer_angle>
          <falloff>1</falloff>
        </spot>
        <direction>1 0 0</direction>
      </light>
      <light name='light_front_left' type='spot'>
        <pose>0.3 0.13 0.2 2.74889 1.5708 0</pose>
        <attenuation>
          <range>30</range>
          <linear>0</linear>
          <constant>0.2</constant>
          <quadratic>0.0025</quadratic>
        </attenuation>
        <diffuse>0.8 0.8 0.5 1</diffuse>
        <specular>0.8 0.8 0.5 1</specular>
        <spot>
          <inner_angle>1.5</inner_angle>
          <outer_angle>1.6</outer_angle>
          <falloff>1</falloff>
        </spot>
        <direction>1 0 0</direction>
      </light>
      <light name='light_front_right' type='spot'>
        <pose>0.3 -0.13 0.2 -2.74889 1.5708 0</pose>
        <attenuation>
          <range>30</range>
          <linear>0</linear>
          <constant>0.2</constant>
          <quadratic>0.0025</quadratic>
        </attenuation>
        <diffuse>0.8 0.8 0.5 1</diffuse>
        <specular>0.8 0.8 0.5 1</specular>
        <spot>
          <inner_angle>1.5</inner_angle>
          <outer_angle>1.6</outer_angle>
          <falloff>1</falloff>
        </spot>
        <direction>1 0 0</direction>
      </light>
      <light name='light_rear' type='spot'>
        <pose>-0.4 0 0.2 0 1.5708 0</pose>
        <attenuation>
          <range>30</range>
          <linear>0</linear>
          <constant>0.2</constant>
          <quadratic>0.0025</quadratic>
        </attenuation>
        <diffuse>0.8 0.8 0.5 1</diffuse>
        <specular>0.8 0.8 0.5 1</specular>
        <spot>
          <inner_angle>1.5</inner_angle>
          <outer_angle>1.8</outer_angle>
          <falloff>1</falloff>
        </spot>
        <direction>1 0 0</direction>
      </light>
      <velocity_decay/>
      <self_collide>0</self_collide>
      <sensor name='imu' type='imu'>
        <always_on>1</always_on>
        <update_rate>50</update_rate>
        <imu>
          <angular_velocity>
            <x>
              <noise type='gaussian'>
                <mean>0</mean>
                <stddev>0.009</stddev>
                <bias_mean>0.00075</bias_mean>
                <bias_stddev>0.005</bias_stddev>
                <dynamic_bias_stddev>2e-05</dynamic_bias_stddev>
                <dynamic_bias_correlation_time>400</dynamic_bias_correlation_time>
                <precision>0.00025</precision>
              </noise>
            </x>
            <y>
              <noise type='gaussian'>
                <mean>0</mean>
                <stddev>0.009</stddev>
                <bias_mean>0.00075</bias_mean>
                <bias_stddev>0.005</bias_stddev>
                <dynamic_bias_stddev>2e-05</dynamic_bias_stddev>
                <dynamic_bias_correlation_time>400</dynamic_bias_correlation_time>
                <precision>0.00025</precision>
              </noise>
            </y>
            <z>
              <noise type='gaussian'>
                <mean>0</mean>
                <stddev>0.009</stddev>
                <bias_mean>0.00075</bias_mean>
                <bias_stddev>0.005</bias_stddev>
                <dynamic_bias_stddev>2e-05</dynamic_bias_stddev>
                <dynamic_bias_correlation_time>400</dynamic_bias_correlation_time>
                <precision>0.00025</precision>
              </noise>
            </z>
          </angular_velocity>
          <linear_acceleration>
            <x>
              <noise type='gaussian'>
                <mean>0</mean>
                <stddev>0.021</stddev>
                <bias_mean>0.05</bias_mean>
                <bias_stddev>0.0075</bias_stddev>
                <dynamic_bias_stddev>0.000375</dynamic_bias_stddev>
                <dynamic_bias_correlation_time>175</dynamic_bias_correlation_time>
                <precision>0.005</precision>
              </noise>
            </x>
            <y>
              <noise type='gaussian'>
                <mean>0</mean>
                <stddev>0.021</stddev>
                <bias_mean>0.05</bias_mean>
                <bias_stddev>0.0075</bias_stddev>
                <dynamic_bias_stddev>0.000375</dynamic_bias_stddev>
                <dynamic_bias_correlation_time>175</dynamic_bias_correlation_time>
                <precision>0.005</precision>
              </noise>
            </y>
            <z>
              <noise type='gaussian'>
                <mean>0</mean>
                <stddev>0.021</stddev>
                <bias_mean>0.05</bias_mean>
                <bias_stddev>0.0075</bias_stddev>
                <dynamic_bias_stddev>0.000375</dynamic_bias_stddev>
                <dynamic_bias_correlation_time>175</dynamic_bias_correlation_time>
                <precision>0.005</precision>
              </noise>
            </z>
          </linear_acceleration>
          <angular_velocity/>
          <linear_acceleration/>
        </imu>
        <pose>0 0 0.15 -3.14159 -0 0</pose>
      </sensor>
      <velocity_decay/>
      <velocity_decay/>
      <gravity>1</gravity>
      <velocity_decay/>
      <sensor name='camera' type='rgbd_camera'>
        <camera name='camera_camera'>
          <horizontal_fov>1.5184</horizontal_fov>
          <lens>
            <intrinsics>
              <fx>337.222</fx>
              <fy>337.222</fy>
              <cx>320.5</cx>
              <cy>240.5</cy>
              <s>0</s>
            </intrinsics>
            <type>stereographic</type>
            <scale_to_hfov>1</scale_to_hfov>
          </lens>
          <distortion>
            <k1>0</k1>
            <k2>0</k2>
            <k3>0</k3>
            <p1>0</p1>
            <p2>0</p2>
            <center>0.5 0.5</center>
          </distortion>
          <image>
            <width>848</width>
            <height>480</height>
            <format>RGB_INT8</format>
          </image>
          <clip>
            <near>0.01</near>
            <far>100</far>
          </clip>
          <depth_camera>
            <clip>
              <near>0.1</near>
              <far>10</far>
            </clip>
            <output>depths</output>
          </depth_camera>
          <noise>
            <type>gaussian</type>
            <mean>0</mean>
            <stddev>0.007</stddev>
          </noise>
        </camera>
        <always_on>1</always_on>
        <update_rate>6</update_rate>
        <pose>0.144322 -0.023803 0.412034 0.015 0.499467 -0.000319</pose>
      </sensor>
    </link>
    <link name='ctu_cras_norlab_absolem_sensor_config_1/laser'>
      <pose>0.2502 0 0.1407 -3.14159 0 0</pose>
      <inertial>
        <pose>0 0 -0.04 0 -0 0</pose>
        <mass>1.1</mass>
        <inertia>
          <ixx>0.0031194</ixx>
          <ixy>-2.221e-06</ixy>
          <ixz>-1.1577e-06</ixz>
          <iyy>0.0031389</iyy>
          <iyz>-1.153e-05</iyz>
          <izz>0.0017656</izz>
        </inertia>
      </inertial>
      <collision name='ctu_cras_norlab_absolem_sensor_config_1/laser_collision'>
        <pose>0 0 -0.04 1.5708 0 -1.5708</pose>
        <geometry>
          <box>
            <size>0.1159 0.16826 0.1159</size>
          </box>
        </geometry>
        <surface>
          <contact>
            <ode/>
          </contact>
          <friction>
            <ode/>
          </friction>
        </surface>
      </collision>
      <visual name='ctu_cras_norlab_absolem_sensor_config_1/laser_visual'>
        <pose>0 0 0 1.5708 0 -1.5708</pose>
        <geometry>
          <mesh>
            <scale>1 1 1</scale>
            <uri>model://ctu_cras_norlab_absolem_sensor_config_1/meshes/laser.dae</uri>
          </mesh>
        </geometry>
      </visual>
      <gravity>1</gravity>
      <velocity_decay/>
      <kinematic>0</kinematic>
      <sensor name='laser' type='gpu_lidar'>
        <pose>0 0 0 0 -0 0</pose>
        <update_rate>50</update_rate>
        <always_on>1</always_on>
        <lidar>
          <scan>
            <horizontal>
              <samples>541</samples>
              <resolution>1</resolution>
              <min_angle>-2.35619</min_angle>
              <max_angle>2.35619</max_angle>
            </horizontal>
          </scan>
          <range>
            <min>0.2</min>
            <max>50</max>
            <resolution>0.01</resolution>
          </range>
          <noise>
            <type>gaussian</type>
            <mean>0</mean>
            <stddev>0.01</stddev>
          </noise>
        </lidar>
      </sensor>
    </link>
    <joint name='laser_j' type='revolute'>
      <child>ctu_cras_norlab_absolem_sensor_config_1/laser</child>
      <parent>ctu_cras_norlab_absolem_sensor_config_1/base_link</parent>
      <axis>
        <xyz>1 0 0</xyz>
        <limit>
          <lower>-2.35619</lower>
          <upper>2.35619</upper>
          <effort>10</effort>
          <velocity>1.2</velocity>
        </limit>
        <dynamics>
          <spring_reference>0</spring_reference>
          <spring_stiffness>0</spring_stiffness>
        </dynamics>
        <use_parent_model_frame>0</use_parent_model_frame>
      </axis>
      <physics>
        <ode>
          <implicit_spring_damper>1</implicit_spring_damper>
          <cfm_damping>1</cfm_damping>
          <limit>
            <cfm>0</cfm>
            <erp>0.2</erp>
          </limit>
        </ode>
      </physics>
    </joint>
    <link name='ctu_cras_norlab_absolem_sensor_config_1/left_track'>
      <pose>0 0.1985 0 0 -0 0</pose>
      <inertial>
        <pose>0 0 0 0 -0 0</pose>
        <mass>1e-05</mass>
        <inertia>
          <ixx>0.001</ixx>
          <ixy>1e-06</ixy>
          <ixz>1e-06</ixz>
          <iyy>0.001</iyy>
          <iyz>1e-06</iyz>
          <izz>0.001</izz>
        </inertia>
      </inertial>
      <collision name='ctu_cras_norlab_absolem_sensor_config_1/left_track_collision'>
        <pose>0 0 0 0 -0 0</pose>
        <geometry>
          <box>
            <size>0.01 0.01 0.01</size>
          </box>
        </geometry>
        <surface>
          <friction>
            <ode>
              <mu>0.7</mu>
              <mu2>150</mu2>
              <fdir1>0 0 1</fdir1>
            </ode>
          </friction>
          <contact>
            <ode/>
          </contact>
        </surface>
      </collision>
      <visual name='ctu_cras_norlab_absolem_sensor_config_1/left_track_visual'>
        <pose>0 0 -0.0705 1.57 -0 1.57</pose>
        <geometry>
          <mesh>
            <scale>1 1 1</scale>
            <uri>model://ctu_cras_norlab_absolem_sensor_config_1/meshes/bogie.dae</uri>
          </mesh>
        </geometry>
      </visual>
      <gravity>1</gravity>
      <velocity_decay/>
      <kinematic>0</kinematic>
    </link>
    <joint name='left_track_j' type='revolute'>
      <child>ctu_cras_norlab_absolem_sensor_config_1/left_track</child>
      <parent>ctu_cras_norlab_absolem_sensor_config_1/base_link</parent>
      <axis>
        <xyz>0 1 0</xyz>
        <limit>
          <lower>-0.7</lower>
          <upper>0.7</upper>
          <effort>0</effort>
          <velocity>4</velocity>
        </limit>
        <dynamics>
          <spring_reference>0</spring_reference>
          <spring_stiffness>0</spring_stiffness>
        </dynamics>
        <use_parent_model_frame>0</use_parent_model_frame>
      </axis>
      <physics>
        <ode>
          <limit>
            <cfm>0</cfm>
            <erp>0.2</erp>
          </limit>
        </ode>
      </physics>
      <physics>
        <ode>
          <implicit_spring_damper>1</implicit_spring_damper>
          <cfm>0</cfm>
          <erp>0.95</erp>
        </ode>
      </physics>
    </joint>
    <link name='ctu_cras_norlab_absolem_sensor_config_1/front_left_flipper'>
      <pose>0.25 0.272 0.0195 0 0.193732 0</pose>
      <inertial>
        <pose>0 0 0 0 -0 0</pose>
        <mass>1e-05</mass>
        <inertia>
          <ixx>0.001</ixx>
          <ixy>1e-06</ixy>
          <ixz>1e-06</ixz>
          <iyy>0.001</iyy>
          <iyz>1e-06</iyz>
          <izz>0.001</izz>
        </inertia>
      </inertial>
      <collision name='ctu_cras_norlab_absolem_sensor_config_1/front_left_flipper_collision'>
        <pose>0 0 0 0 -0 0</pose>
        <geometry>
          <box>
            <size>0.01 0.01 0.01</size>
          </box>
        </geometry>
        <surface>
          <friction>
            <ode>
              <mu>0.7</mu>
              <mu2>150</mu2>
              <fdir1>0 0 1</fdir1>
            </ode>
          </friction>
          <contact>
            <ode/>
          </contact>
        </surface>
      </collision>
      <visual name='ctu_cras_norlab_absolem_sensor_config_1/front_left_flipper_visual'>
        <pose>0 0 0 -2.95743 -0 1.5708</pose>
        <geometry>
          <mesh>
            <scale>1 1 1</scale>
            <uri>model://ctu_cras_norlab_absolem_sensor_config_1/meshes/flipper.dae</uri>
          </mesh>
        </geometry>
      </visual>
      <gravity>1</gravity>
      <velocity_decay/>
      <kinematic>0</kinematic>
    </link>
    <joint name='front_left_flipper_j' type='revolute'>
      <child>ctu_cras_norlab_absolem_sensor_config_1/front_left_flipper</child>
      <parent>ctu_cras_norlab_absolem_sensor_config_1/left_track</parent>
      <axis>
        <xyz>0 1 0</xyz>
        <limit>
          <lower>-1e+16</lower>
          <upper>1e+16</upper>
          <effort>20</effort>
          <velocity>0.785398</velocity>
        </limit>
        <dynamics>
          <spring_reference>0</spring_reference>
          <spring_stiffness>0</spring_stiffness>
        </dynamics>
        <use_parent_model_frame>0</use_parent_model_frame>
      </axis>
      <physics>
        <ode>
          <implicit_spring_damper>1</implicit_spring_damper>
          <cfm_damping>1</cfm_damping>
          <limit>
            <cfm>0</cfm>
            <erp>0.2</erp>
          </limit>
        </ode>
      </physics>
    </joint>
    <link name='ctu_cras_norlab_absolem_sensor_config_1/front_left_flipper_wheel1'>
      <pose>0.25 0.2535 0.0195 0 0.193732 0</pose>
      <inertial>
        <pose>0.08 0 0 0 -0 0</pose>
        <mass>0.15</mass>
        <inertia>
          <ixx>0.0017491</ixx>
          <ixy>2.8512e-07</ixy>
          <ixz>0.0018277</ixz>
          <iyy>0.012277</iyy>
          <iyz>-3.6288e-07</iyz>
          <izz>0.010941</izz>
        </inertia>
      </inertial>
      <collision name='ctu_cras_norlab_absolem_sensor_config_1/front_left_flipper_wheel1_fixed_joint_lump__front_left_flipper_wheel1_collision_collision'>
        <pose>0 0 0 1.5708 -0 0</pose>
        <geometry>
          <cylinder>
            <length>0.08681</length>
            <radius>0.1157</radius>
          </cylinder>
        </geometry>
      </collision>
      <gravity>1</gravity>
      <velocity_decay/>
      <kinematic>0</kinematic>
    </link>
    <joint name='front_left_flipper_wheel1_j' type='revolute'>
      <child>ctu_cras_norlab_absolem_sensor_config_1/front_left_flipper_wheel1</child>
      <parent>ctu_cras_norlab_absolem_sensor_config_1/front_left_flipper</parent>
      <axis>
        <xyz>0 1 0</xyz>
        <limit>
          <lower>-1e+16</lower>
          <upper>1e+16</upper>
        </limit>
        <dynamics>
          <spring_reference>0</spring_reference>
          <spring_stiffness>0</spring_stiffness>
        </dynamics>
        <use_parent_model_frame>0</use_parent_model_frame>
      </axis>
    </joint>
    <link name='ctu_cras_norlab_absolem_sensor_config_1/front_left_flipper_wheel2'>
      <pose>0.330957 0.2535 0.003617 0 0.193732 0</pose>
      <inertial>
        <pose>0.08 0 0 0 -0 0</pose>
        <mass>0.15</mass>
        <inertia>
          <ixx>0.0017491</ixx>
          <ixy>2.8512e-07</ixy>
          <ixz>0.0018277</ixz>
          <iyy>0.012277</iyy>
          <iyz>-3.6288e-07</iyz>
          <izz>0.010941</izz>
        </inertia>
      </inertial>
      <collision name='ctu_cras_norlab_absolem_sensor_config_1/front_left_flipper_wheel2_fixed_joint_lump__front_left_flipper_wheel2_collision_collision'>
        <pose>0 0 0 1.5708 -0 0</pose>
        <geometry>
          <cylinder>
            <length>0.08681</length>
            <radius>0.0962</radius>
          </cylinder>
        </geometry>
      </collision>
      <gravity>1</gravity>
      <velocity_decay/>
      <kinematic>0</kinematic>
    </link>
    <joint name='front_left_flipper_wheel2_j' type='revolute'>
      <child>ctu_cras_norlab_absolem_sensor_config_1/front_left_flipper_wheel2</child>
      <parent>ctu_cras_norlab_absolem_sensor_config_1/front_left_flipper</parent>
      <axis>
        <xyz>0 1 0</xyz>
        <limit>
          <lower>-1e+16</lower>
          <upper>1e+16</upper>
        </limit>
        <dynamics>
          <spring_reference>0</spring_reference>
          <spring_stiffness>0</spring_stiffness>
        </dynamics>
        <use_parent_model_frame>0</use_parent_model_frame>
      </axis>
    </joint>
    <link name='ctu_cras_norlab_absolem_sensor_config_1/front_left_flipper_wheel3'>
      <pose>0.411913 0.2535 -0.012266 0 0.193732 0</pose>
      <inertial>
        <pose>0.08 0 0 0 -0 0</pose>
        <mass>0.15</mass>
        <inertia>
          <ixx>0.0017491</ixx>
          <ixy>2.8512e-07</ixy>
          <ixz>0.0018277</ixz>
          <iyy>0.012277</iyy>
          <iyz>-3.6288e-07</iyz>
          <izz>0.010941</izz>
        </inertia>
      </inertial>
      <collision name='ctu_cras_norlab_absolem_sensor_config_1/front_left_flipper_wheel3_fixed_joint_lump__front_left_flipper_wheel3_collision_collision'>
        <pose>0 0 0 1.5708 -0 0</pose>
        <geometry>
          <cylinder>
            <length>0.08681</length>
            <radius>0.0767</radius>
          </cylinder>
        </geometry>
      </collision>
      <gravity>1</gravity>
      <velocity_decay/>
      <kinematic>0</kinematic>
    </link>
    <joint name='front_left_flipper_wheel3_j' type='revolute'>
      <child>ctu_cras_norlab_absolem_sensor_config_1/front_left_flipper_wheel3</child>
      <parent>ctu_cras_norlab_absolem_sensor_config_1/front_left_flipper</parent>
      <axis>
        <xyz>0 1 0</xyz>
        <limit>
          <lower>-1e+16</lower>
          <upper>1e+16</upper>
        </limit>
        <dynamics>
          <spring_reference>0</spring_reference>
          <spring_stiffness>0</spring_stiffness>
        </dynamics>
        <use_parent_model_frame>0</use_parent_model_frame>
      </axis>
    </joint>
    <link name='ctu_cras_norlab_absolem_sensor_config_1/front_left_flipper_wheel4'>
      <pose>0.49287 0.2535 -0.028149 0 0.193732 0</pose>
      <inertial>
        <pose>0.08 0 0 0 -0 0</pose>
        <mass>0.15</mass>
        <inertia>
          <ixx>0.0017491</ixx>
          <ixy>2.8512e-07</ixy>
          <ixz>0.0018277</ixz>
          <iyy>0.012277</iyy>
          <iyz>-3.6288e-07</iyz>
          <izz>0.010941</izz>
        </inertia>
      </inertial>
      <collision name='ctu_cras_norlab_absolem_sensor_config_1/front_left_flipper_wheel4_fixed_joint_lump__front_left_flipper_wheel4_collision_collision'>
        <pose>0 0 0 1.5708 -0 0</pose>
        <geometry>
          <cylinder>
            <length>0.08681</length>
            <radius>0.0572</radius>
          </cylinder>
        </geometry>
      </collision>
      <gravity>1</gravity>
      <velocity_decay/>
      <kinematic>0</kinematic>
    </link>
    <joint name='front_left_flipper_wheel4_j' type='revolute'>
      <child>ctu_cras_norlab_absolem_sensor_config_1/front_left_flipper_wheel4</child>
      <parent>ctu_cras_norlab_absolem_sensor_config_1/front_left_flipper</parent>
      <axis>
        <xyz>0 1 0</xyz>
        <limit>
          <lower>-1e+16</lower>
          <upper>1e+16</upper>
        </limit>
        <dynamics>
          <spring_reference>0</spring_reference>
          <spring_stiffness>0</spring_stiffness>
        </dynamics>
        <use_parent_model_frame>0</use_parent_model_frame>
      </axis>
    </joint>
    <link name='ctu_cras_norlab_absolem_sensor_config_1/front_left_flipper_wheel5'>
      <pose>0.573827 0.2535 -0.044032 0 0.193732 0</pose>
      <inertial>
        <pose>0.08 0 0 0 -0 0</pose>
        <mass>0.15</mass>
        <inertia>
          <ixx>0.0017491</ixx>
          <ixy>2.8512e-07</ixy>
          <ixz>0.0018277</ixz>
          <iyy>0.012277</iyy>
          <iyz>-3.6288e-07</iyz>
          <izz>0.010941</izz>
        </inertia>
      </inertial>
      <collision name='ctu_cras_norlab_absolem_sensor_config_1/front_left_flipper_wheel5_fixed_joint_lump__front_left_flipper_wheel5_collision_collision'>
        <pose>0 0 0 1.5708 -0 0</pose>
        <geometry>
          <cylinder>
            <length>0.08681</length>
            <radius>0.0377</radius>
          </cylinder>
        </geometry>
      </collision>
      <gravity>1</gravity>
      <velocity_decay/>
      <kinematic>0</kinematic>
    </link>
    <joint name='front_left_flipper_wheel5_j' type='revolute'>
      <child>ctu_cras_norlab_absolem_sensor_config_1/front_left_flipper_wheel5</child>
      <parent>ctu_cras_norlab_absolem_sensor_config_1/front_left_flipper</parent>
      <axis>
        <xyz>0 1 0</xyz>
        <limit>
          <lower>-1e+16</lower>
          <upper>1e+16</upper>
        </limit>
        <dynamics>
          <spring_reference>0</spring_reference>
          <spring_stiffness>0</spring_stiffness>
        </dynamics>
        <use_parent_model_frame>0</use_parent_model_frame>
      </axis>
    </joint>
    <link name='ctu_cras_norlab_absolem_sensor_config_1/left_track_wheel1'>
      <pose>0.25 0.1985 0.01855 0 -0 0</pose>
      <inertial>
        <pose>0 0 0.0141 0 -0 0</pose>
        <mass>0.7575</mass>
        <inertia>
          <ixx>0.002731</ixx>
          <ixy>0</ixy>
          <ixz>0</ixz>
          <iyy>0.032554</iyy>
          <iyz>1.5e-05</iyz>
          <izz>0.031391</izz>
        </inertia>
      </inertial>
      <collision name='ctu_cras_norlab_absolem_sensor_config_1/left_track_wheel1_collision'>
        <pose>0 -0.015 0 1.5708 -0 0</pose>
        <geometry>
          <cylinder>
            <length>0.112</length>
            <radius>0.089</radius>
          </cylinder>
        </geometry>
        <surface>
          <contact>
            <ode>
              <kp>1e+07</kp>
              <kd>1</kd>
            </ode>
          </contact>
          <friction>
            <ode>
              <mu>0.5</mu>
              <mu2>1</mu2>
              <slip1>0.00092</slip1>
              <slip2>0</slip2>
              <fdir1>0 0 1</fdir1>
            </ode>
          </friction>
        </surface>
      </collision>
      <gravity>1</gravity>
      <velocity_decay/>
      <kinematic>0</kinematic>
    </link>
    <joint name='left_track_wheel1_j' type='revolute'>
      <child>ctu_cras_norlab_absolem_sensor_config_1/left_track_wheel1</child>
      <parent>ctu_cras_norlab_absolem_sensor_config_1/left_track</parent>
      <axis>
        <xyz>0 1 0</xyz>
        <limit>
          <lower>-1e+16</lower>
          <upper>1e+16</upper>
        </limit>
        <dynamics>
          <spring_reference>0</spring_reference>
          <spring_stiffness>0</spring_stiffness>
        </dynamics>
        <use_parent_model_frame>0</use_parent_model_frame>
      </axis>
    </joint>
    <link name='ctu_cras_norlab_absolem_sensor_config_1/left_track_wheel2'>
      <pose>0.178571 0.1985 0.01855 0 -0 0</pose>
      <inertial>
        <pose>0 0 0.0141 0 -0 0</pose>
        <mass>0.7575</mass>
        <inertia>
          <ixx>0.002731</ixx>
          <ixy>0</ixy>
          <ixz>0</ixz>
          <iyy>0.032554</iyy>
          <iyz>1.5e-05</iyz>
          <izz>0.031391</izz>
        </inertia>
      </inertial>
      <collision name='ctu_cras_norlab_absolem_sensor_config_1/left_track_wheel2_collision'>
        <pose>0 0 0 1.5708 -0 0</pose>
        <geometry>
          <cylinder>
            <length>0.097</length>
            <radius>0.089</radius>
          </cylinder>
        </geometry>
        <surface>
          <contact>
            <ode>
              <kp>1e+07</kp>
              <kd>1</kd>
            </ode>
          </contact>
          <friction>
            <ode>
              <mu>0.5</mu>
              <mu2>1</mu2>
              <slip1>0.00092</slip1>
              <slip2>0</slip2>
              <fdir1>0 0 1</fdir1>
            </ode>
          </friction>
        </surface>
      </collision>
      <gravity>1</gravity>
      <velocity_decay/>
      <kinematic>0</kinematic>
    </link>
    <joint name='left_track_wheel2_j' type='revolute'>
      <child>ctu_cras_norlab_absolem_sensor_config_1/left_track_wheel2</child>
      <parent>ctu_cras_norlab_absolem_sensor_config_1/left_track</parent>
      <axis>
        <xyz>0 1 0</xyz>
        <limit>
          <lower>-1e+16</lower>
          <upper>1e+16</upper>
        </limit>
        <dynamics>
          <spring_reference>0</spring_reference>
          <spring_stiffness>0</spring_stiffness>
        </dynamics>
        <use_parent_model_frame>0</use_parent_model_frame>
      </axis>
    </joint>
    <link name='ctu_cras_norlab_absolem_sensor_config_1/left_track_wheel3'>
      <pose>0.107143 0.1985 0.01855 0 -0 0</pose>
      <inertial>
        <pose>0 0 0.0141 0 -0 0</pose>
        <mass>0.7575</mass>
        <inertia>
          <ixx>0.002731</ixx>
          <ixy>0</ixy>
          <ixz>0</ixz>
          <iyy>0.032554</iyy>
          <iyz>1.5e-05</iyz>
          <izz>0.031391</izz>
        </inertia>
      </inertial>
      <collision name='ctu_cras_norlab_absolem_sensor_config_1/left_track_wheel3_collision'>
        <pose>0 0 0 1.5708 -0 0</pose>
        <geometry>
          <cylinder>
            <length>0.097</length>
            <radius>0.089</radius>
          </cylinder>
        </geometry>
        <surface>
          <contact>
            <ode>
              <kp>1e+07</kp>
              <kd>1</kd>
            </ode>
          </contact>
          <friction>
            <ode>
              <mu>0.5</mu>
              <mu2>1</mu2>
              <slip1>0.00092</slip1>
              <slip2>0</slip2>
              <fdir1>0 0 1</fdir1>
            </ode>
          </friction>
        </surface>
      </collision>
      <gravity>1</gravity>
      <velocity_decay/>
      <kinematic>0</kinematic>
    </link>
    <joint name='left_track_wheel3_j' type='revolute'>
      <child>ctu_cras_norlab_absolem_sensor_config_1/left_track_wheel3</child>
      <parent>ctu_cras_norlab_absolem_sensor_config_1/left_track</parent>
      <axis>
        <xyz>0 1 0</xyz>
        <limit>
          <lower>-1e+16</lower>
          <upper>1e+16</upper>
        </limit>
        <dynamics>
          <spring_reference>0</spring_reference>
          <spring_stiffness>0</spring_stiffness>
        </dynamics>
        <use_parent_model_frame>0</use_parent_model_frame>
      </axis>
    </joint>
    <link name='ctu_cras_norlab_absolem_sensor_config_1/left_track_wheel4'>
      <pose>0.035714 0.1985 0.01855 0 -0 0</pose>
      <inertial>
        <pose>0 0 0.0141 0 -0 0</pose>
        <mass>0.7575</mass>
        <inertia>
          <ixx>0.002731</ixx>
          <ixy>0</ixy>
          <ixz>0</ixz>
          <iyy>0.032554</iyy>
          <iyz>1.5e-05</iyz>
          <izz>0.031391</izz>
        </inertia>
      </inertial>
      <collision name='ctu_cras_norlab_absolem_sensor_config_1/left_track_wheel4_collision'>
        <pose>0 0 0 1.5708 -0 0</pose>
        <geometry>
          <cylinder>
            <length>0.097</length>
            <radius>0.089</radius>
          </cylinder>
        </geometry>
        <surface>
          <contact>
            <ode>
              <kp>1e+07</kp>
              <kd>1</kd>
            </ode>
          </contact>
          <friction>
            <ode>
              <mu>0.5</mu>
              <mu2>1</mu2>
              <slip1>0.00092</slip1>
              <slip2>0</slip2>
              <fdir1>0 0 1</fdir1>
            </ode>
          </friction>
        </surface>
      </collision>
      <gravity>1</gravity>
      <velocity_decay/>
      <kinematic>0</kinematic>
    </link>
    <joint name='left_track_wheel4_j' type='revolute'>
      <child>ctu_cras_norlab_absolem_sensor_config_1/left_track_wheel4</child>
      <parent>ctu_cras_norlab_absolem_sensor_config_1/left_track</parent>
      <axis>
        <xyz>0 1 0</xyz>
        <limit>
          <lower>-1e+16</lower>
          <upper>1e+16</upper>
        </limit>
        <dynamics>
          <spring_reference>0</spring_reference>
          <spring_stiffness>0</spring_stiffness>
        </dynamics>
        <use_parent_model_frame>0</use_parent_model_frame>
      </axis>
    </joint>
    <link name='ctu_cras_norlab_absolem_sensor_config_1/left_track_wheel5'>
      <pose>-0.035714 0.1985 0.01855 0 -0 0</pose>
      <inertial>
        <pose>0 0 0.0141 0 -0 0</pose>
        <mass>0.7575</mass>
        <inertia>
          <ixx>0.002731</ixx>
          <ixy>0</ixy>
          <ixz>0</ixz>
          <iyy>0.032554</iyy>
          <iyz>1.5e-05</iyz>
          <izz>0.031391</izz>
        </inertia>
      </inertial>
      <collision name='ctu_cras_norlab_absolem_sensor_config_1/left_track_wheel5_collision'>
        <pose>0 0 0 1.5708 -0 0</pose>
        <geometry>
          <cylinder>
            <length>0.097</length>
            <radius>0.089</radius>
          </cylinder>
        </geometry>
        <surface>
          <contact>
            <ode>
              <kp>1e+07</kp>
              <kd>1</kd>
            </ode>
          </contact>
          <friction>
            <ode>
              <mu>0.5</mu>
              <mu2>1</mu2>
              <slip1>0.00092</slip1>
              <slip2>0</slip2>
              <fdir1>0 0 1</fdir1>
            </ode>
          </friction>
        </surface>
      </collision>
      <gravity>1</gravity>
      <velocity_decay/>
      <kinematic>0</kinematic>
    </link>
    <joint name='left_track_wheel5_j' type='revolute'>
      <child>ctu_cras_norlab_absolem_sensor_config_1/left_track_wheel5</child>
      <parent>ctu_cras_norlab_absolem_sensor_config_1/left_track</parent>
      <axis>
        <xyz>0 1 0</xyz>
        <limit>
          <lower>-1e+16</lower>
          <upper>1e+16</upper>
        </limit>
        <dynamics>
          <spring_reference>0</spring_reference>
          <spring_stiffness>0</spring_stiffness>
        </dynamics>
        <use_parent_model_frame>0</use_parent_model_frame>
      </axis>
    </joint>
    <link name='ctu_cras_norlab_absolem_sensor_config_1/left_track_wheel6'>
      <pose>-0.107143 0.1985 0.01855 0 -0 0</pose>
      <inertial>
        <pose>0 0 0.0141 0 -0 0</pose>
        <mass>0.7575</mass>
        <inertia>
          <ixx>0.002731</ixx>
          <ixy>0</ixy>
          <ixz>0</ixz>
          <iyy>0.032554</iyy>
          <iyz>1.5e-05</iyz>
          <izz>0.031391</izz>
        </inertia>
      </inertial>
      <collision name='ctu_cras_norlab_absolem_sensor_config_1/left_track_wheel6_collision'>
        <pose>0 0 0 1.5708 -0 0</pose>
        <geometry>
          <cylinder>
            <length>0.097</length>
            <radius>0.089</radius>
          </cylinder>
        </geometry>
        <surface>
          <contact>
            <ode>
              <kp>1e+07</kp>
              <kd>1</kd>
            </ode>
          </contact>
          <friction>
            <ode>
              <mu>0.5</mu>
              <mu2>1</mu2>
              <slip1>0.00092</slip1>
              <slip2>0</slip2>
              <fdir1>0 0 1</fdir1>
            </ode>
          </friction>
        </surface>
      </collision>
      <gravity>1</gravity>
      <velocity_decay/>
      <kinematic>0</kinematic>
    </link>
    <joint name='left_track_wheel6_j' type='revolute'>
      <child>ctu_cras_norlab_absolem_sensor_config_1/left_track_wheel6</child>
      <parent>ctu_cras_norlab_absolem_sensor_config_1/left_track</parent>
      <axis>
        <xyz>0 1 0</xyz>
        <limit>
          <lower>-1e+16</lower>
          <upper>1e+16</upper>
        </limit>
        <dynamics>
          <spring_reference>0</spring_reference>
          <spring_stiffness>0</spring_stiffness>
        </dynamics>
        <use_parent_model_frame>0</use_parent_model_frame>
      </axis>
    </joint>
    <link name='ctu_cras_norlab_absolem_sensor_config_1/left_track_wheel7'>
      <pose>-0.178571 0.1985 0.01855 0 -0 0</pose>
      <inertial>
        <pose>0 0 0.0141 0 -0 0</pose>
        <mass>0.7575</mass>
        <inertia>
          <ixx>0.002731</ixx>
          <ixy>0</ixy>
          <ixz>0</ixz>
          <iyy>0.032554</iyy>
          <iyz>1.5e-05</iyz>
          <izz>0.031391</izz>
        </inertia>
      </inertial>
      <collision name='ctu_cras_norlab_absolem_sensor_config_1/left_track_wheel7_collision'>
        <pose>0 0 0 1.5708 -0 0</pose>
        <geometry>
          <cylinder>
            <length>0.097</length>
            <radius>0.089</radius>
          </cylinder>
        </geometry>
        <surface>
          <contact>
            <ode>
              <kp>1e+07</kp>
              <kd>1</kd>
            </ode>
          </contact>
          <friction>
            <ode>
              <mu>0.5</mu>
              <mu2>1</mu2>
              <slip1>0.00092</slip1>
              <slip2>0</slip2>
              <fdir1>0 0 1</fdir1>
            </ode>
          </friction>
        </surface>
      </collision>
      <gravity>1</gravity>
      <velocity_decay/>
      <kinematic>0</kinematic>
    </link>
    <joint name='left_track_wheel7_j' type='revolute'>
      <child>ctu_cras_norlab_absolem_sensor_config_1/left_track_wheel7</child>
      <parent>ctu_cras_norlab_absolem_sensor_config_1/left_track</parent>
      <axis>
        <xyz>0 1 0</xyz>
        <limit>
          <lower>-1e+16</lower>
          <upper>1e+16</upper>
        </limit>
        <dynamics>
          <spring_reference>0</spring_reference>
          <spring_stiffness>0</spring_stiffness>
        </dynamics>
        <use_parent_model_frame>0</use_parent_model_frame>
      </axis>
    </joint>
    <link name='ctu_cras_norlab_absolem_sensor_config_1/left_track_wheel8'>
      <pose>-0.25 0.1985 0.01855 0 -0 0</pose>
      <inertial>
        <pose>0 0 0.0141 0 -0 0</pose>
        <mass>0.7575</mass>
        <inertia>
          <ixx>0.002731</ixx>
          <ixy>0</ixy>
          <ixz>0</ixz>
          <iyy>0.032554</iyy>
          <iyz>1.5e-05</iyz>
          <izz>0.031391</izz>
        </inertia>
      </inertial>
      <collision name='ctu_cras_norlab_absolem_sensor_config_1/left_track_wheel8_collision'>
        <pose>0 0 0 1.5708 -0 0</pose>
        <geometry>
          <cylinder>
            <length>0.097</length>
            <radius>0.089</radius>
          </cylinder>
        </geometry>
        <surface>
          <contact>
            <ode>
              <kp>1e+07</kp>
              <kd>1</kd>
            </ode>
          </contact>
          <friction>
            <ode>
              <mu>0.5</mu>
              <mu2>1</mu2>
              <slip1>0.00092</slip1>
              <slip2>0</slip2>
              <fdir1>0 0 1</fdir1>
            </ode>
          </friction>
        </surface>
      </collision>
      <gravity>1</gravity>
      <velocity_decay/>
      <kinematic>0</kinematic>
    </link>
    <joint name='left_track_wheel8_j' type='revolute'>
      <child>ctu_cras_norlab_absolem_sensor_config_1/left_track_wheel8</child>
      <parent>ctu_cras_norlab_absolem_sensor_config_1/left_track</parent>
      <axis>
        <xyz>0 1 0</xyz>
        <limit>
          <lower>-1e+16</lower>
          <upper>1e+16</upper>
        </limit>
        <dynamics>
          <spring_reference>0</spring_reference>
          <spring_stiffness>0</spring_stiffness>
        </dynamics>
        <use_parent_model_frame>0</use_parent_model_frame>
      </axis>
    </joint>
    <link name='ctu_cras_norlab_absolem_sensor_config_1/rear_left_flipper'>
      <pose>-0.25 0.272 0.0195 3.14159 0.193732 3.14159</pose>
      <inertial>
        <pose>0 0 0 0 -0 0</pose>
        <mass>1e-05</mass>
        <inertia>
          <ixx>0.001</ixx>
          <ixy>1e-06</ixy>
          <ixz>1e-06</ixz>
          <iyy>0.001</iyy>
          <iyz>1e-06</iyz>
          <izz>0.001</izz>
        </inertia>
      </inertial>
      <collision name='ctu_cras_norlab_absolem_sensor_config_1/rear_left_flipper_collision'>
        <pose>0 0 0 0 -0 0</pose>
        <geometry>
          <box>
            <size>0.01 0.01 0.01</size>
          </box>
        </geometry>
        <surface>
          <friction>
            <ode>
              <mu>0.7</mu>
              <mu2>150</mu2>
              <fdir1>0 0 1</fdir1>
            </ode>
          </friction>
          <contact>
            <ode/>
          </contact>
        </surface>
      </collision>
      <visual name='ctu_cras_norlab_absolem_sensor_config_1/rear_left_flipper_visual'>
        <pose>0 0 0 -2.95743 -0 1.5708</pose>
        <geometry>
          <mesh>
            <scale>1 1 1</scale>
            <uri>model://ctu_cras_norlab_absolem_sensor_config_1/meshes/flipper.dae</uri>
          </mesh>
        </geometry>
      </visual>
      <gravity>1</gravity>
      <velocity_decay/>
      <kinematic>0</kinematic>
    </link>
    <joint name='rear_left_flipper_j' type='revolute'>
      <child>ctu_cras_norlab_absolem_sensor_config_1/rear_left_flipper</child>
      <parent>ctu_cras_norlab_absolem_sensor_config_1/left_track</parent>
      <axis>
        <xyz>0 1 0</xyz>
        <limit>
          <lower>-1e+16</lower>
          <upper>1e+16</upper>
          <effort>20</effort>
          <velocity>0.785398</velocity>
        </limit>
        <dynamics>
          <spring_reference>0</spring_reference>
          <spring_stiffness>0</spring_stiffness>
        </dynamics>
        <use_parent_model_frame>0</use_parent_model_frame>
      </axis>
      <physics>
        <ode>
          <implicit_spring_damper>1</implicit_spring_damper>
          <cfm_damping>1</cfm_damping>
          <limit>
            <cfm>0</cfm>
            <erp>0.2</erp>
          </limit>
        </ode>
      </physics>
    </joint>
    <link name='ctu_cras_norlab_absolem_sensor_config_1/rear_left_flipper_wheel1'>
      <pose>-0.25 0.272 0.0195 3.14159 0.193732 3.14159</pose>
      <inertial>
        <pose>0.08 0 0 0 -0 0</pose>
        <mass>0.15</mass>
        <inertia>
          <ixx>0.0017491</ixx>
          <ixy>2.8512e-07</ixy>
          <ixz>0.0018277</ixz>
          <iyy>0.012277</iyy>
          <iyz>-3.6288e-07</iyz>
          <izz>0.010941</izz>
        </inertia>
      </inertial>
      <collision name='ctu_cras_norlab_absolem_sensor_config_1/rear_left_flipper_wheel1_fixed_joint_lump__rear_left_flipper_wheel1_collision_collision'>
        <pose>0 0 0 1.5708 -0 0</pose>
        <geometry>
          <cylinder>
            <length>0.04981</length>
            <radius>0.089</radius>
          </cylinder>
        </geometry>
      </collision>
      <gravity>1</gravity>
      <velocity_decay/>
      <kinematic>0</kinematic>
    </link>
    <joint name='rear_left_flipper_wheel1_j' type='revolute'>
      <child>ctu_cras_norlab_absolem_sensor_config_1/rear_left_flipper_wheel1</child>
      <parent>ctu_cras_norlab_absolem_sensor_config_1/rear_left_flipper</parent>
      <axis>
        <xyz>0 1 0</xyz>
        <limit>
          <lower>-1e+16</lower>
          <upper>1e+16</upper>
        </limit>
        <dynamics>
          <spring_reference>0</spring_reference>
          <spring_stiffness>0</spring_stiffness>
        </dynamics>
        <use_parent_model_frame>0</use_parent_model_frame>
      </axis>
    </joint>
    <link name='ctu_cras_norlab_absolem_sensor_config_1/rear_left_flipper_wheel2'>
      <pose>-0.330957 0.272 0.003617 3.14159 0.193732 3.14159</pose>
      <inertial>
        <pose>0.08 0 0 0 -0 0</pose>
        <mass>0.15</mass>
        <inertia>
          <ixx>0.0017491</ixx>
          <ixy>2.8512e-07</ixy>
          <ixz>0.0018277</ixz>
          <iyy>0.012277</iyy>
          <iyz>-3.6288e-07</iyz>
          <izz>0.010941</izz>
        </inertia>
      </inertial>
      <collision name='ctu_cras_norlab_absolem_sensor_config_1/rear_left_flipper_wheel2_fixed_joint_lump__rear_left_flipper_wheel2_collision_collision'>
        <pose>0 0 0 1.5708 -0 0</pose>
        <geometry>
          <cylinder>
            <length>0.04981</length>
            <radius>0.074</radius>
          </cylinder>
        </geometry>
      </collision>
      <gravity>1</gravity>
      <velocity_decay/>
      <kinematic>0</kinematic>
    </link>
    <joint name='rear_left_flipper_wheel2_j' type='revolute'>
      <child>ctu_cras_norlab_absolem_sensor_config_1/rear_left_flipper_wheel2</child>
      <parent>ctu_cras_norlab_absolem_sensor_config_1/rear_left_flipper</parent>
      <axis>
        <xyz>0 1 0</xyz>
        <limit>
          <lower>-1e+16</lower>
          <upper>1e+16</upper>
        </limit>
        <dynamics>
          <spring_reference>0</spring_reference>
          <spring_stiffness>0</spring_stiffness>
        </dynamics>
        <use_parent_model_frame>0</use_parent_model_frame>
      </axis>
    </joint>
    <link name='ctu_cras_norlab_absolem_sensor_config_1/rear_left_flipper_wheel3'>
      <pose>-0.411913 0.272 -0.012266 3.14159 0.193732 3.14159</pose>
      <inertial>
        <pose>0.08 0 0 0 -0 0</pose>
        <mass>0.15</mass>
        <inertia>
          <ixx>0.0017491</ixx>
          <ixy>2.8512e-07</ixy>
          <ixz>0.0018277</ixz>
          <iyy>0.012277</iyy>
          <iyz>-3.6288e-07</iyz>
          <izz>0.010941</izz>
        </inertia>
      </inertial>
      <collision name='ctu_cras_norlab_absolem_sensor_config_1/rear_left_flipper_wheel3_fixed_joint_lump__rear_left_flipper_wheel3_collision_collision'>
        <pose>0 0 0 1.5708 -0 0</pose>
        <geometry>
          <cylinder>
            <length>0.04981</length>
            <radius>0.059</radius>
          </cylinder>
        </geometry>
      </collision>
      <gravity>1</gravity>
      <velocity_decay/>
      <kinematic>0</kinematic>
    </link>
    <joint name='rear_left_flipper_wheel3_j' type='revolute'>
      <child>ctu_cras_norlab_absolem_sensor_config_1/rear_left_flipper_wheel3</child>
      <parent>ctu_cras_norlab_absolem_sensor_config_1/rear_left_flipper</parent>
      <axis>
        <xyz>0 1 0</xyz>
        <limit>
          <lower>-1e+16</lower>
          <upper>1e+16</upper>
        </limit>
        <dynamics>
          <spring_reference>0</spring_reference>
          <spring_stiffness>0</spring_stiffness>
        </dynamics>
        <use_parent_model_frame>0</use_parent_model_frame>
      </axis>
    </joint>
    <link name='ctu_cras_norlab_absolem_sensor_config_1/rear_left_flipper_wheel4'>
      <pose>-0.49287 0.272 -0.028149 3.14159 0.193732 3.14159</pose>
      <inertial>
        <pose>0.08 0 0 0 -0 0</pose>
        <mass>0.15</mass>
        <inertia>
          <ixx>0.0017491</ixx>
          <ixy>2.8512e-07</ixy>
          <ixz>0.0018277</ixz>
          <iyy>0.012277</iyy>
          <iyz>-3.6288e-07</iyz>
          <izz>0.010941</izz>
        </inertia>
      </inertial>
      <collision name='ctu_cras_norlab_absolem_sensor_config_1/rear_left_flipper_wheel4_fixed_joint_lump__rear_left_flipper_wheel4_collision_collision'>
        <pose>0 0 0 1.5708 -0 0</pose>
        <geometry>
          <cylinder>
            <length>0.04981</length>
            <radius>0.044</radius>
          </cylinder>
        </geometry>
      </collision>
      <gravity>1</gravity>
      <velocity_decay/>
      <kinematic>0</kinematic>
    </link>
    <joint name='rear_left_flipper_wheel4_j' type='revolute'>
      <child>ctu_cras_norlab_absolem_sensor_config_1/rear_left_flipper_wheel4</child>
      <parent>ctu_cras_norlab_absolem_sensor_config_1/rear_left_flipper</parent>
      <axis>
        <xyz>0 1 0</xyz>
        <limit>
          <lower>-1e+16</lower>
          <upper>1e+16</upper>
        </limit>
        <dynamics>
          <spring_reference>0</spring_reference>
          <spring_stiffness>0</spring_stiffness>
        </dynamics>
        <use_parent_model_frame>0</use_parent_model_frame>
      </axis>
    </joint>
    <link name='ctu_cras_norlab_absolem_sensor_config_1/rear_left_flipper_wheel5'>
      <pose>-0.573827 0.272 -0.044032 3.14159 0.193732 3.14159</pose>
      <inertial>
        <pose>0.08 0 0 0 -0 0</pose>
        <mass>0.15</mass>
        <inertia>
          <ixx>0.0017491</ixx>
          <ixy>2.8512e-07</ixy>
          <ixz>0.0018277</ixz>
          <iyy>0.012277</iyy>
          <iyz>-3.6288e-07</iyz>
          <izz>0.010941</izz>
        </inertia>
      </inertial>
      <collision name='ctu_cras_norlab_absolem_sensor_config_1/rear_left_flipper_wheel5_fixed_joint_lump__rear_left_flipper_wheel5_collision_collision'>
        <pose>0 0 0 1.5708 -0 0</pose>
        <geometry>
          <cylinder>
            <length>0.04981</length>
            <radius>0.029</radius>
          </cylinder>
        </geometry>
      </collision>
      <gravity>1</gravity>
      <velocity_decay/>
      <kinematic>0</kinematic>
    </link>
    <joint name='rear_left_flipper_wheel5_j' type='revolute'>
      <child>ctu_cras_norlab_absolem_sensor_config_1/rear_left_flipper_wheel5</child>
      <parent>ctu_cras_norlab_absolem_sensor_config_1/rear_left_flipper</parent>
      <axis>
        <xyz>0 1 0</xyz>
        <limit>
          <lower>-1e+16</lower>
          <upper>1e+16</upper>
        </limit>
        <dynamics>
          <spring_reference>0</spring_reference>
          <spring_stiffness>0</spring_stiffness>
        </dynamics>
        <use_parent_model_frame>0</use_parent_model_frame>
      </axis>
    </joint>
    <link name='ctu_cras_norlab_absolem_sensor_config_1/right_track'>
      <pose>0 -0.1985 0 0 -0 0</pose>
      <inertial>
        <pose>0 0 0 0 -0 0</pose>
        <mass>1e-05</mass>
        <inertia>
          <ixx>0.001</ixx>
          <ixy>1e-06</ixy>
          <ixz>1e-06</ixz>
          <iyy>0.001</iyy>
          <iyz>1e-06</iyz>
          <izz>0.001</izz>
        </inertia>
      </inertial>
      <collision name='ctu_cras_norlab_absolem_sensor_config_1/right_track_collision'>
        <pose>0 0 0 0 -0 0</pose>
        <geometry>
          <box>
            <size>0.01 0.01 0.01</size>
          </box>
        </geometry>
        <surface>
          <friction>
            <ode>
              <mu>0.7</mu>
              <mu2>150</mu2>
              <fdir1>0 0 1</fdir1>
            </ode>
          </friction>
          <contact>
            <ode/>
          </contact>
        </surface>
      </collision>
      <visual name='ctu_cras_norlab_absolem_sensor_config_1/right_track_visual'>
        <pose>0 0 -0.0705 1.57 0 -1.57</pose>
        <geometry>
          <mesh>
            <scale>1 1 1</scale>
            <uri>model://ctu_cras_norlab_absolem_sensor_config_1/meshes/bogie.dae</uri>
          </mesh>
        </geometry>
      </visual>
      <gravity>1</gravity>
      <velocity_decay/>
      <kinematic>0</kinematic>
    </link>
    <joint name='right_track_j' type='revolute'>
      <child>ctu_cras_norlab_absolem_sensor_config_1/right_track</child>
      <parent>ctu_cras_norlab_absolem_sensor_config_1/base_link</parent>
      <axis>
        <xyz>0 1 0</xyz>
        <limit>
          <lower>-0.7</lower>
          <upper>0.7</upper>
          <effort>0</effort>
          <velocity>4</velocity>
        </limit>
        <dynamics>
          <spring_reference>0</spring_reference>
          <spring_stiffness>0</spring_stiffness>
        </dynamics>
        <use_parent_model_frame>0</use_parent_model_frame>
      </axis>
      <physics>
        <ode>
          <limit>
            <cfm>0</cfm>
            <erp>0.2</erp>
          </limit>
        </ode>
      </physics>
      <physics>
        <ode>
          <implicit_spring_damper>1</implicit_spring_damper>
          <cfm>0</cfm>
          <erp>0.95</erp>
        </ode>
      </physics>
    </joint>
    <link name='ctu_cras_norlab_absolem_sensor_config_1/front_right_flipper'>
      <pose>0.25 -0.272 0.0195 3.14159 -0.193732 3.14159</pose>
      <inertial>
        <pose>0 0 0 0 -0 0</pose>
        <mass>1e-05</mass>
        <inertia>
          <ixx>0.001</ixx>
          <ixy>1e-06</ixy>
          <ixz>1e-06</ixz>
          <iyy>0.001</iyy>
          <iyz>1e-06</iyz>
          <izz>0.001</izz>
        </inertia>
      </inertial>
      <collision name='ctu_cras_norlab_absolem_sensor_config_1/front_right_flipper_collision'>
        <pose>0 0 0 0 -0 0</pose>
        <geometry>
          <box>
            <size>0.01 0.01 0.01</size>
          </box>
        </geometry>
        <surface>
          <friction>
            <ode>
              <mu>0.7</mu>
              <mu2>150</mu2>
              <fdir1>0 0 1</fdir1>
            </ode>
          </friction>
          <contact>
            <ode/>
          </contact>
        </surface>
      </collision>
      <visual name='ctu_cras_norlab_absolem_sensor_config_1/front_right_flipper_visual'>
        <pose>0 0 0 -2.95743 -0 -1.5708</pose>
        <geometry>
          <mesh>
            <scale>1 1 1</scale>
            <uri>model://ctu_cras_norlab_absolem_sensor_config_1/meshes/flipper.dae</uri>
          </mesh>
        </geometry>
      </visual>
      <gravity>1</gravity>
      <velocity_decay/>
      <kinematic>0</kinematic>
    </link>
    <joint name='front_right_flipper_j' type='revolute'>
      <child>ctu_cras_norlab_absolem_sensor_config_1/front_right_flipper</child>
      <parent>ctu_cras_norlab_absolem_sensor_config_1/right_track</parent>
      <axis>
        <xyz>0 1 0</xyz>
        <limit>
          <lower>-1e+16</lower>
          <upper>1e+16</upper>
          <effort>20</effort>
          <velocity>0.785398</velocity>
        </limit>
        <dynamics>
          <spring_reference>0</spring_reference>
          <spring_stiffness>0</spring_stiffness>
        </dynamics>
        <use_parent_model_frame>0</use_parent_model_frame>
      </axis>
      <physics>
        <ode>
          <implicit_spring_damper>1</implicit_spring_damper>
          <cfm_damping>1</cfm_damping>
          <limit>
            <cfm>0</cfm>
            <erp>0.2</erp>
          </limit>
        </ode>
      </physics>
    </joint>
    <link name='ctu_cras_norlab_absolem_sensor_config_1/front_right_flipper_wheel1'>
      <pose>0.25 -0.2535 0.0195 3.14159 -0.193732 3.14159</pose>
      <inertial>
        <pose>-0.08 0 0 0 -0 0</pose>
        <mass>0.15</mass>
        <inertia>
          <ixx>0.0017491</ixx>
          <ixy>2.8512e-07</ixy>
          <ixz>0.0018277</ixz>
          <iyy>0.012277</iyy>
          <iyz>-3.6288e-07</iyz>
          <izz>0.010941</izz>
        </inertia>
      </inertial>
      <collision name='ctu_cras_norlab_absolem_sensor_config_1/front_right_flipper_wheel1_fixed_joint_lump__front_right_flipper_wheel1_collision_collision'>
        <pose>0 0 0 1.5708 -0 0</pose>
        <geometry>
          <cylinder>
            <length>0.08681</length>
            <radius>0.1157</radius>
          </cylinder>
        </geometry>
      </collision>
      <gravity>1</gravity>
      <velocity_decay/>
      <kinematic>0</kinematic>
    </link>
    <joint name='front_right_flipper_wheel1_j' type='revolute'>
      <child>ctu_cras_norlab_absolem_sensor_config_1/front_right_flipper_wheel1</child>
      <parent>ctu_cras_norlab_absolem_sensor_config_1/front_right_flipper</parent>
      <axis>
        <xyz>0 1 0</xyz>
        <limit>
          <lower>-1e+16</lower>
          <upper>1e+16</upper>
        </limit>
        <dynamics>
          <spring_reference>0</spring_reference>
          <spring_stiffness>0</spring_stiffness>
        </dynamics>
        <use_parent_model_frame>0</use_parent_model_frame>
      </axis>
    </joint>
    <link name='ctu_cras_norlab_absolem_sensor_config_1/front_right_flipper_wheel2'>
      <pose>0.330957 -0.2535 0.003617 3.14159 -0.193732 3.14159</pose>
      <inertial>
        <pose>-0.08 0 0 0 -0 0</pose>
        <mass>0.15</mass>
        <inertia>
          <ixx>0.0017491</ixx>
          <ixy>2.8512e-07</ixy>
          <ixz>0.0018277</ixz>
          <iyy>0.012277</iyy>
          <iyz>-3.6288e-07</iyz>
          <izz>0.010941</izz>
        </inertia>
      </inertial>
      <collision name='ctu_cras_norlab_absolem_sensor_config_1/front_right_flipper_wheel2_fixed_joint_lump__front_right_flipper_wheel2_collision_collision'>
        <pose>0 0 0 1.5708 -0 0</pose>
        <geometry>
          <cylinder>
            <length>0.08681</length>
            <radius>0.0962</radius>
          </cylinder>
        </geometry>
      </collision>
      <gravity>1</gravity>
      <velocity_decay/>
      <kinematic>0</kinematic>
    </link>
    <joint name='front_right_flipper_wheel2_j' type='revolute'>
      <child>ctu_cras_norlab_absolem_sensor_config_1/front_right_flipper_wheel2</child>
      <parent>ctu_cras_norlab_absolem_sensor_config_1/front_right_flipper</parent>
      <axis>
        <xyz>0 1 0</xyz>
        <limit>
          <lower>-1e+16</lower>
          <upper>1e+16</upper>
        </limit>
        <dynamics>
          <spring_reference>0</spring_reference>
          <spring_stiffness>0</spring_stiffness>
        </dynamics>
        <use_parent_model_frame>0</use_parent_model_frame>
      </axis>
    </joint>
    <link name='ctu_cras_norlab_absolem_sensor_config_1/front_right_flipper_wheel3'>
      <pose>0.411913 -0.2535 -0.012266 3.14159 -0.193732 3.14159</pose>
      <inertial>
        <pose>-0.08 0 0 0 -0 0</pose>
        <mass>0.15</mass>
        <inertia>
          <ixx>0.0017491</ixx>
          <ixy>2.8512e-07</ixy>
          <ixz>0.0018277</ixz>
          <iyy>0.012277</iyy>
          <iyz>-3.6288e-07</iyz>
          <izz>0.010941</izz>
        </inertia>
      </inertial>
      <collision name='ctu_cras_norlab_absolem_sensor_config_1/front_right_flipper_wheel3_fixed_joint_lump__front_right_flipper_wheel3_collision_collision'>
        <pose>0 0 0 1.5708 -0 0</pose>
        <geometry>
          <cylinder>
            <length>0.08681</length>
            <radius>0.0767</radius>
          </cylinder>
        </geometry>
      </collision>
      <gravity>1</gravity>
      <velocity_decay/>
      <kinematic>0</kinematic>
    </link>
    <joint name='front_right_flipper_wheel3_j' type='revolute'>
      <child>ctu_cras_norlab_absolem_sensor_config_1/front_right_flipper_wheel3</child>
      <parent>ctu_cras_norlab_absolem_sensor_config_1/front_right_flipper</parent>
      <axis>
        <xyz>0 1 0</xyz>
        <limit>
          <lower>-1e+16</lower>
          <upper>1e+16</upper>
        </limit>
        <dynamics>
          <spring_reference>0</spring_reference>
          <spring_stiffness>0</spring_stiffness>
        </dynamics>
        <use_parent_model_frame>0</use_parent_model_frame>
      </axis>
    </joint>
    <link name='ctu_cras_norlab_absolem_sensor_config_1/front_right_flipper_wheel4'>
      <pose>0.49287 -0.2535 -0.028149 3.14159 -0.193732 3.14159</pose>
      <inertial>
        <pose>-0.08 0 0 0 -0 0</pose>
        <mass>0.15</mass>
        <inertia>
          <ixx>0.0017491</ixx>
          <ixy>2.8512e-07</ixy>
          <ixz>0.0018277</ixz>
          <iyy>0.012277</iyy>
          <iyz>-3.6288e-07</iyz>
          <izz>0.010941</izz>
        </inertia>
      </inertial>
      <collision name='ctu_cras_norlab_absolem_sensor_config_1/front_right_flipper_wheel4_fixed_joint_lump__front_right_flipper_wheel4_collision_collision'>
        <pose>0 0 0 1.5708 -0 0</pose>
        <geometry>
          <cylinder>
            <length>0.08681</length>
            <radius>0.0572</radius>
          </cylinder>
        </geometry>
      </collision>
      <gravity>1</gravity>
      <velocity_decay/>
      <kinematic>0</kinematic>
    </link>
    <joint name='front_right_flipper_wheel4_j' type='revolute'>
      <child>ctu_cras_norlab_absolem_sensor_config_1/front_right_flipper_wheel4</child>
      <parent>ctu_cras_norlab_absolem_sensor_config_1/front_right_flipper</parent>
      <axis>
        <xyz>0 1 0</xyz>
        <limit>
          <lower>-1e+16</lower>
          <upper>1e+16</upper>
        </limit>
        <dynamics>
          <spring_reference>0</spring_reference>
          <spring_stiffness>0</spring_stiffness>
        </dynamics>
        <use_parent_model_frame>0</use_parent_model_frame>
      </axis>
    </joint>
    <link name='ctu_cras_norlab_absolem_sensor_config_1/front_right_flipper_wheel5'>
      <pose>0.573827 -0.2535 -0.044032 3.14159 -0.193732 3.14159</pose>
      <inertial>
        <pose>-0.08 0 0 0 -0 0</pose>
        <mass>0.15</mass>
        <inertia>
          <ixx>0.0017491</ixx>
          <ixy>2.8512e-07</ixy>
          <ixz>0.0018277</ixz>
          <iyy>0.012277</iyy>
          <iyz>-3.6288e-07</iyz>
          <izz>0.010941</izz>
        </inertia>
      </inertial>
      <collision name='ctu_cras_norlab_absolem_sensor_config_1/front_right_flipper_wheel5_fixed_joint_lump__front_right_flipper_wheel5_collision_collision'>
        <pose>0 0 0 1.5708 -0 0</pose>
        <geometry>
          <cylinder>
            <length>0.08681</length>
            <radius>0.0377</radius>
          </cylinder>
        </geometry>
      </collision>
      <gravity>1</gravity>
      <velocity_decay/>
      <kinematic>0</kinematic>
    </link>
    <joint name='front_right_flipper_wheel5_j' type='revolute'>
      <child>ctu_cras_norlab_absolem_sensor_config_1/front_right_flipper_wheel5</child>
      <parent>ctu_cras_norlab_absolem_sensor_config_1/front_right_flipper</parent>
      <axis>
        <xyz>0 1 0</xyz>
        <limit>
          <lower>-1e+16</lower>
          <upper>1e+16</upper>
        </limit>
        <dynamics>
          <spring_reference>0</spring_reference>
          <spring_stiffness>0</spring_stiffness>
        </dynamics>
        <use_parent_model_frame>0</use_parent_model_frame>
      </axis>
    </joint>
    <link name='ctu_cras_norlab_absolem_sensor_config_1/rear_right_flipper'>
      <pose>-0.25 -0.272 0.0195 0 -0.193732 0</pose>
      <inertial>
        <pose>0 0 0 0 -0 0</pose>
        <mass>1e-05</mass>
        <inertia>
          <ixx>0.001</ixx>
          <ixy>1e-06</ixy>
          <ixz>1e-06</ixz>
          <iyy>0.001</iyy>
          <iyz>1e-06</iyz>
          <izz>0.001</izz>
        </inertia>
      </inertial>
      <collision name='ctu_cras_norlab_absolem_sensor_config_1/rear_right_flipper_collision'>
        <pose>0 0 0 0 -0 0</pose>
        <geometry>
          <box>
            <size>0.01 0.01 0.01</size>
          </box>
        </geometry>
        <surface>
          <friction>
            <ode>
              <mu>0.7</mu>
              <mu2>150</mu2>
              <fdir1>0 0 1</fdir1>
            </ode>
          </friction>
          <contact>
            <ode/>
          </contact>
        </surface>
      </collision>
      <visual name='ctu_cras_norlab_absolem_sensor_config_1/rear_right_flipper_visual'>
        <pose>0 0 0 -2.95743 -0 -1.5708</pose>
        <geometry>
          <mesh>
            <scale>1 1 1</scale>
            <uri>model://ctu_cras_norlab_absolem_sensor_config_1/meshes/flipper.dae</uri>
          </mesh>
        </geometry>
      </visual>
      <gravity>1</gravity>
      <velocity_decay/>
      <kinematic>0</kinematic>
    </link>
    <joint name='rear_right_flipper_j' type='revolute'>
      <child>ctu_cras_norlab_absolem_sensor_config_1/rear_right_flipper</child>
      <parent>ctu_cras_norlab_absolem_sensor_config_1/right_track</parent>
      <axis>
        <xyz>0 1 0</xyz>
        <limit>
          <lower>-1e+16</lower>
          <upper>1e+16</upper>
          <effort>20</effort>
          <velocity>0.785398</velocity>
        </limit>
        <dynamics>
          <spring_reference>0</spring_reference>
          <spring_stiffness>0</spring_stiffness>
        </dynamics>
        <use_parent_model_frame>0</use_parent_model_frame>
      </axis>
      <physics>
        <ode>
          <implicit_spring_damper>1</implicit_spring_damper>
          <cfm_damping>1</cfm_damping>
          <limit>
            <cfm>0</cfm>
            <erp>0.2</erp>
          </limit>
        </ode>
      </physics>
    </joint>
    <link name='ctu_cras_norlab_absolem_sensor_config_1/rear_right_flipper_wheel1'>
      <pose>-0.25 -0.272 0.0195 0 -0.193732 0</pose>
      <inertial>
        <pose>-0.08 0 0 0 -0 0</pose>
        <mass>0.15</mass>
        <inertia>
          <ixx>0.0017491</ixx>
          <ixy>2.8512e-07</ixy>
          <ixz>0.0018277</ixz>
          <iyy>0.012277</iyy>
          <iyz>-3.6288e-07</iyz>
          <izz>0.010941</izz>
        </inertia>
      </inertial>
      <collision name='ctu_cras_norlab_absolem_sensor_config_1/rear_right_flipper_wheel1_fixed_joint_lump__rear_right_flipper_wheel1_collision_collision'>
        <pose>0 0 0 1.5708 -0 0</pose>
        <geometry>
          <cylinder>
            <length>0.04981</length>
            <radius>0.089</radius>
          </cylinder>
        </geometry>
      </collision>
      <gravity>1</gravity>
      <velocity_decay/>
      <kinematic>0</kinematic>
    </link>
    <joint name='rear_right_flipper_wheel1_j' type='revolute'>
      <child>ctu_cras_norlab_absolem_sensor_config_1/rear_right_flipper_wheel1</child>
      <parent>ctu_cras_norlab_absolem_sensor_config_1/rear_right_flipper</parent>
      <axis>
        <xyz>0 1 0</xyz>
        <limit>
          <lower>-1e+16</lower>
          <upper>1e+16</upper>
        </limit>
        <dynamics>
          <spring_reference>0</spring_reference>
          <spring_stiffness>0</spring_stiffness>
        </dynamics>
        <use_parent_model_frame>0</use_parent_model_frame>
      </axis>
    </joint>
    <link name='ctu_cras_norlab_absolem_sensor_config_1/rear_right_flipper_wheel2'>
      <pose>-0.330957 -0.272 0.003617 0 -0.193732 0</pose>
      <inertial>
        <pose>-0.08 0 0 0 -0 0</pose>
        <mass>0.15</mass>
        <inertia>
          <ixx>0.0017491</ixx>
          <ixy>2.8512e-07</ixy>
          <ixz>0.0018277</ixz>
          <iyy>0.012277</iyy>
          <iyz>-3.6288e-07</iyz>
          <izz>0.010941</izz>
        </inertia>
      </inertial>
      <collision name='ctu_cras_norlab_absolem_sensor_config_1/rear_right_flipper_wheel2_fixed_joint_lump__rear_right_flipper_wheel2_collision_collision'>
        <pose>0 0 0 1.5708 -0 0</pose>
        <geometry>
          <cylinder>
            <length>0.04981</length>
            <radius>0.074</radius>
          </cylinder>
        </geometry>
      </collision>
      <gravity>1</gravity>
      <velocity_decay/>
      <kinematic>0</kinematic>
    </link>
    <joint name='rear_right_flipper_wheel2_j' type='revolute'>
      <child>ctu_cras_norlab_absolem_sensor_config_1/rear_right_flipper_wheel2</child>
      <parent>ctu_cras_norlab_absolem_sensor_config_1/rear_right_flipper</parent>
      <axis>
        <xyz>0 1 0</xyz>
        <limit>
          <lower>-1e+16</lower>
          <upper>1e+16</upper>
        </limit>
        <dynamics>
          <spring_reference>0</spring_reference>
          <spring_stiffness>0</spring_stiffness>
        </dynamics>
        <use_parent_model_frame>0</use_parent_model_frame>
      </axis>
    </joint>
    <link name='ctu_cras_norlab_absolem_sensor_config_1/rear_right_flipper_wheel3'>
      <pose>-0.411913 -0.272 -0.012266 0 -0.193732 0</pose>
      <inertial>
        <pose>-0.08 0 0 0 -0 0</pose>
        <mass>0.15</mass>
        <inertia>
          <ixx>0.0017491</ixx>
          <ixy>2.8512e-07</ixy>
          <ixz>0.0018277</ixz>
          <iyy>0.012277</iyy>
          <iyz>-3.6288e-07</iyz>
          <izz>0.010941</izz>
        </inertia>
      </inertial>
      <collision name='ctu_cras_norlab_absolem_sensor_config_1/rear_right_flipper_wheel3_fixed_joint_lump__rear_right_flipper_wheel3_collision_collision'>
        <pose>0 0 0 1.5708 -0 0</pose>
        <geometry>
          <cylinder>
            <length>0.04981</length>
            <radius>0.059</radius>
          </cylinder>
        </geometry>
      </collision>
      <gravity>1</gravity>
      <velocity_decay/>
      <kinematic>0</kinematic>
    </link>
    <joint name='rear_right_flipper_wheel3_j' type='revolute'>
      <child>ctu_cras_norlab_absolem_sensor_config_1/rear_right_flipper_wheel3</child>
      <parent>ctu_cras_norlab_absolem_sensor_config_1/rear_right_flipper</parent>
      <axis>
        <xyz>0 1 0</xyz>
        <limit>
          <lower>-1e+16</lower>
          <upper>1e+16</upper>
        </limit>
        <dynamics>
          <spring_reference>0</spring_reference>
          <spring_stiffness>0</spring_stiffness>
        </dynamics>
        <use_parent_model_frame>0</use_parent_model_frame>
      </axis>
    </joint>
    <link name='ctu_cras_norlab_absolem_sensor_config_1/rear_right_flipper_wheel4'>
      <pose>-0.49287 -0.272 -0.028149 0 -0.193732 0</pose>
      <inertial>
        <pose>-0.08 0 0 0 -0 0</pose>
        <mass>0.15</mass>
        <inertia>
          <ixx>0.0017491</ixx>
          <ixy>2.8512e-07</ixy>
          <ixz>0.0018277</ixz>
          <iyy>0.012277</iyy>
          <iyz>-3.6288e-07</iyz>
          <izz>0.010941</izz>
        </inertia>
      </inertial>
      <collision name='ctu_cras_norlab_absolem_sensor_config_1/rear_right_flipper_wheel4_fixed_joint_lump__rear_right_flipper_wheel4_collision_collision'>
        <pose>0 0 0 1.5708 -0 0</pose>
        <geometry>
          <cylinder>
            <length>0.04981</length>
            <radius>0.044</radius>
          </cylinder>
        </geometry>
      </collision>
      <gravity>1</gravity>
      <velocity_decay/>
      <kinematic>0</kinematic>
    </link>
    <joint name='rear_right_flipper_wheel4_j' type='revolute'>
      <child>ctu_cras_norlab_absolem_sensor_config_1/rear_right_flipper_wheel4</child>
      <parent>ctu_cras_norlab_absolem_sensor_config_1/rear_right_flipper</parent>
      <axis>
        <xyz>0 1 0</xyz>
        <limit>
          <lower>-1e+16</lower>
          <upper>1e+16</upper>
        </limit>
        <dynamics>
          <spring_reference>0</spring_reference>
          <spring_stiffness>0</spring_stiffness>
        </dynamics>
        <use_parent_model_frame>0</use_parent_model_frame>
      </axis>
    </joint>
    <link name='ctu_cras_norlab_absolem_sensor_config_1/rear_right_flipper_wheel5'>
      <pose>-0.573827 -0.272 -0.044032 0 -0.193732 0</pose>
      <inertial>
        <pose>-0.08 0 0 0 -0 0</pose>
        <mass>0.15</mass>
        <inertia>
          <ixx>0.0017491</ixx>
          <ixy>2.8512e-07</ixy>
          <ixz>0.0018277</ixz>
          <iyy>0.012277</iyy>
          <iyz>-3.6288e-07</iyz>
          <izz>0.010941</izz>
        </inertia>
      </inertial>
      <collision name='ctu_cras_norlab_absolem_sensor_config_1/rear_right_flipper_wheel5_fixed_joint_lump__rear_right_flipper_wheel5_collision_collision'>
        <pose>0 0 0 1.5708 -0 0</pose>
        <geometry>
          <cylinder>
            <length>0.04981</length>
            <radius>0.029</radius>
          </cylinder>
        </geometry>
      </collision>
      <gravity>1</gravity>
      <velocity_decay/>
      <kinematic>0</kinematic>
    </link>
    <joint name='rear_right_flipper_wheel5_j' type='revolute'>
      <child>ctu_cras_norlab_absolem_sensor_config_1/rear_right_flipper_wheel5</child>
      <parent>ctu_cras_norlab_absolem_sensor_config_1/rear_right_flipper</parent>
      <axis>
        <xyz>0 1 0</xyz>
        <limit>
          <lower>-1e+16</lower>
          <upper>1e+16</upper>
        </limit>
        <dynamics>
          <spring_reference>0</spring_reference>
          <spring_stiffness>0</spring_stiffness>
        </dynamics>
        <use_parent_model_frame>0</use_parent_model_frame>
      </axis>
    </joint>
    <link name='ctu_cras_norlab_absolem_sensor_config_1/right_track_wheel1'>
      <pose>0.25 -0.1985 0.01855 0 -0 0</pose>
      <inertial>
        <pose>0 0 0.0141 0 -0 0</pose>
        <mass>0.7575</mass>
        <inertia>
          <ixx>0.002731</ixx>
          <ixy>0</ixy>
          <ixz>0</ixz>
          <iyy>0.032554</iyy>
          <iyz>1.5e-05</iyz>
          <izz>0.031391</izz>
        </inertia>
      </inertial>
      <collision name='ctu_cras_norlab_absolem_sensor_config_1/right_track_wheel1_collision'>
        <pose>0 0.015 0 1.5708 -0 0</pose>
        <geometry>
          <cylinder>
            <length>0.112</length>
            <radius>0.089</radius>
          </cylinder>
        </geometry>
        <surface>
          <contact>
            <ode>
              <kp>1e+07</kp>
              <kd>1</kd>
            </ode>
          </contact>
          <friction>
            <ode>
              <mu>0.5</mu>
              <mu2>1</mu2>
              <slip1>0.00092</slip1>
              <slip2>0</slip2>
              <fdir1>0 0 1</fdir1>
            </ode>
          </friction>
        </surface>
      </collision>
      <gravity>1</gravity>
      <velocity_decay/>
      <kinematic>0</kinematic>
    </link>
    <joint name='right_track_wheel1_j' type='revolute'>
      <child>ctu_cras_norlab_absolem_sensor_config_1/right_track_wheel1</child>
      <parent>ctu_cras_norlab_absolem_sensor_config_1/right_track</parent>
      <axis>
        <xyz>0 1 0</xyz>
        <limit>
          <lower>-1e+16</lower>
          <upper>1e+16</upper>
        </limit>
        <dynamics>
          <spring_reference>0</spring_reference>
          <spring_stiffness>0</spring_stiffness>
        </dynamics>
        <use_parent_model_frame>0</use_parent_model_frame>
      </axis>
    </joint>
    <link name='ctu_cras_norlab_absolem_sensor_config_1/right_track_wheel2'>
      <pose>0.178571 -0.1985 0.01855 0 -0 0</pose>
      <inertial>
        <pose>0 0 0.0141 0 -0 0</pose>
        <mass>0.7575</mass>
        <inertia>
          <ixx>0.002731</ixx>
          <ixy>0</ixy>
          <ixz>0</ixz>
          <iyy>0.032554</iyy>
          <iyz>1.5e-05</iyz>
          <izz>0.031391</izz>
        </inertia>
      </inertial>
      <collision name='ctu_cras_norlab_absolem_sensor_config_1/right_track_wheel2_collision'>
        <pose>0 0 0 1.5708 -0 0</pose>
        <geometry>
          <cylinder>
            <length>0.097</length>
            <radius>0.089</radius>
          </cylinder>
        </geometry>
        <surface>
          <contact>
            <ode>
              <kp>1e+07</kp>
              <kd>1</kd>
            </ode>
          </contact>
          <friction>
            <ode>
              <mu>0.5</mu>
              <mu2>1</mu2>
              <slip1>0.00092</slip1>
              <slip2>0</slip2>
              <fdir1>0 0 1</fdir1>
            </ode>
          </friction>
        </surface>
      </collision>
      <gravity>1</gravity>
      <velocity_decay/>
      <kinematic>0</kinematic>
    </link>
    <joint name='right_track_wheel2_j' type='revolute'>
      <child>ctu_cras_norlab_absolem_sensor_config_1/right_track_wheel2</child>
      <parent>ctu_cras_norlab_absolem_sensor_config_1/right_track</parent>
      <axis>
        <xyz>0 1 0</xyz>
        <limit>
          <lower>-1e+16</lower>
          <upper>1e+16</upper>
        </limit>
        <dynamics>
          <spring_reference>0</spring_reference>
          <spring_stiffness>0</spring_stiffness>
        </dynamics>
        <use_parent_model_frame>0</use_parent_model_frame>
      </axis>
    </joint>
    <link name='ctu_cras_norlab_absolem_sensor_config_1/right_track_wheel3'>
      <pose>0.107143 -0.1985 0.01855 0 -0 0</pose>
      <inertial>
        <pose>0 0 0.0141 0 -0 0</pose>
        <mass>0.7575</mass>
        <inertia>
          <ixx>0.002731</ixx>
          <ixy>0</ixy>
          <ixz>0</ixz>
          <iyy>0.032554</iyy>
          <iyz>1.5e-05</iyz>
          <izz>0.031391</izz>
        </inertia>
      </inertial>
      <collision name='ctu_cras_norlab_absolem_sensor_config_1/right_track_wheel3_collision'>
        <pose>0 0 0 1.5708 -0 0</pose>
        <geometry>
          <cylinder>
            <length>0.097</length>
            <radius>0.089</radius>
          </cylinder>
        </geometry>
        <surface>
          <contact>
            <ode>
              <kp>1e+07</kp>
              <kd>1</kd>
            </ode>
          </contact>
          <friction>
            <ode>
              <mu>0.5</mu>
              <mu2>1</mu2>
              <slip1>0.00092</slip1>
              <slip2>0</slip2>
              <fdir1>0 0 1</fdir1>
            </ode>
          </friction>
        </surface>
      </collision>
      <gravity>1</gravity>
      <velocity_decay/>
      <kinematic>0</kinematic>
    </link>
    <joint name='right_track_wheel3_j' type='revolute'>
      <child>ctu_cras_norlab_absolem_sensor_config_1/right_track_wheel3</child>
      <parent>ctu_cras_norlab_absolem_sensor_config_1/right_track</parent>
      <axis>
        <xyz>0 1 0</xyz>
        <limit>
          <lower>-1e+16</lower>
          <upper>1e+16</upper>
        </limit>
        <dynamics>
          <spring_reference>0</spring_reference>
          <spring_stiffness>0</spring_stiffness>
        </dynamics>
        <use_parent_model_frame>0</use_parent_model_frame>
      </axis>
    </joint>
    <link name='ctu_cras_norlab_absolem_sensor_config_1/right_track_wheel4'>
      <pose>0.035714 -0.1985 0.01855 0 -0 0</pose>
      <inertial>
        <pose>0 0 0.0141 0 -0 0</pose>
        <mass>0.7575</mass>
        <inertia>
          <ixx>0.002731</ixx>
          <ixy>0</ixy>
          <ixz>0</ixz>
          <iyy>0.032554</iyy>
          <iyz>1.5e-05</iyz>
          <izz>0.031391</izz>
        </inertia>
      </inertial>
      <collision name='ctu_cras_norlab_absolem_sensor_config_1/right_track_wheel4_collision'>
        <pose>0 0 0 1.5708 -0 0</pose>
        <geometry>
          <cylinder>
            <length>0.097</length>
            <radius>0.089</radius>
          </cylinder>
        </geometry>
        <surface>
          <contact>
            <ode>
              <kp>1e+07</kp>
              <kd>1</kd>
            </ode>
          </contact>
          <friction>
            <ode>
              <mu>0.5</mu>
              <mu2>1</mu2>
              <slip1>0.00092</slip1>
              <slip2>0</slip2>
              <fdir1>0 0 1</fdir1>
            </ode>
          </friction>
        </surface>
      </collision>
      <gravity>1</gravity>
      <velocity_decay/>
      <kinematic>0</kinematic>
    </link>
    <joint name='right_track_wheel4_j' type='revolute'>
      <child>ctu_cras_norlab_absolem_sensor_config_1/right_track_wheel4</child>
      <parent>ctu_cras_norlab_absolem_sensor_config_1/right_track</parent>
      <axis>
        <xyz>0 1 0</xyz>
        <limit>
          <lower>-1e+16</lower>
          <upper>1e+16</upper>
        </limit>
        <dynamics>
          <spring_reference>0</spring_reference>
          <spring_stiffness>0</spring_stiffness>
        </dynamics>
        <use_parent_model_frame>0</use_parent_model_frame>
      </axis>
    </joint>
    <link name='ctu_cras_norlab_absolem_sensor_config_1/right_track_wheel5'>
      <pose>-0.035714 -0.1985 0.01855 0 -0 0</pose>
      <inertial>
        <pose>0 0 0.0141 0 -0 0</pose>
        <mass>0.7575</mass>
        <inertia>
          <ixx>0.002731</ixx>
          <ixy>0</ixy>
          <ixz>0</ixz>
          <iyy>0.032554</iyy>
          <iyz>1.5e-05</iyz>
          <izz>0.031391</izz>
        </inertia>
      </inertial>
      <collision name='ctu_cras_norlab_absolem_sensor_config_1/right_track_wheel5_collision'>
        <pose>0 0 0 1.5708 -0 0</pose>
        <geometry>
          <cylinder>
            <length>0.097</length>
            <radius>0.089</radius>
          </cylinder>
        </geometry>
        <surface>
          <contact>
            <ode>
              <kp>1e+07</kp>
              <kd>1</kd>
            </ode>
          </contact>
          <friction>
            <ode>
              <mu>0.5</mu>
              <mu2>1</mu2>
              <slip1>0.00092</slip1>
              <slip2>0</slip2>
              <fdir1>0 0 1</fdir1>
            </ode>
          </friction>
        </surface>
      </collision>
      <gravity>1</gravity>
      <velocity_decay/>
      <kinematic>0</kinematic>
    </link>
    <joint name='right_track_wheel5_j' type='revolute'>
      <child>ctu_cras_norlab_absolem_sensor_config_1/right_track_wheel5</child>
      <parent>ctu_cras_norlab_absolem_sensor_config_1/right_track</parent>
      <axis>
        <xyz>0 1 0</xyz>
        <limit>
          <lower>-1e+16</lower>
          <upper>1e+16</upper>
        </limit>
        <dynamics>
          <spring_reference>0</spring_reference>
          <spring_stiffness>0</spring_stiffness>
        </dynamics>
        <use_parent_model_frame>0</use_parent_model_frame>
      </axis>
    </joint>
    <link name='ctu_cras_norlab_absolem_sensor_config_1/right_track_wheel6'>
      <pose>-0.107143 -0.1985 0.01855 0 -0 0</pose>
      <inertial>
        <pose>0 0 0.0141 0 -0 0</pose>
        <mass>0.7575</mass>
        <inertia>
          <ixx>0.002731</ixx>
          <ixy>0</ixy>
          <ixz>0</ixz>
          <iyy>0.032554</iyy>
          <iyz>1.5e-05</iyz>
          <izz>0.031391</izz>
        </inertia>
      </inertial>
      <collision name='ctu_cras_norlab_absolem_sensor_config_1/right_track_wheel6_collision'>
        <pose>0 0 0 1.5708 -0 0</pose>
        <geometry>
          <cylinder>
            <length>0.097</length>
            <radius>0.089</radius>
          </cylinder>
        </geometry>
        <surface>
          <contact>
            <ode>
              <kp>1e+07</kp>
              <kd>1</kd>
            </ode>
          </contact>
          <friction>
            <ode>
              <mu>0.5</mu>
              <mu2>1</mu2>
              <slip1>0.00092</slip1>
              <slip2>0</slip2>
              <fdir1>0 0 1</fdir1>
            </ode>
          </friction>
        </surface>
      </collision>
      <gravity>1</gravity>
      <velocity_decay/>
      <kinematic>0</kinematic>
    </link>
    <joint name='right_track_wheel6_j' type='revolute'>
      <child>ctu_cras_norlab_absolem_sensor_config_1/right_track_wheel6</child>
      <parent>ctu_cras_norlab_absolem_sensor_config_1/right_track</parent>
      <axis>
        <xyz>0 1 0</xyz>
        <limit>
          <lower>-1e+16</lower>
          <upper>1e+16</upper>
        </limit>
        <dynamics>
          <spring_reference>0</spring_reference>
          <spring_stiffness>0</spring_stiffness>
        </dynamics>
        <use_parent_model_frame>0</use_parent_model_frame>
      </axis>
    </joint>
    <link name='ctu_cras_norlab_absolem_sensor_config_1/right_track_wheel7'>
      <pose>-0.178571 -0.1985 0.01855 0 -0 0</pose>
      <inertial>
        <pose>0 0 0.0141 0 -0 0</pose>
        <mass>0.7575</mass>
        <inertia>
          <ixx>0.002731</ixx>
          <ixy>0</ixy>
          <ixz>0</ixz>
          <iyy>0.032554</iyy>
          <iyz>1.5e-05</iyz>
          <izz>0.031391</izz>
        </inertia>
      </inertial>
      <collision name='ctu_cras_norlab_absolem_sensor_config_1/right_track_wheel7_collision'>
        <pose>0 0 0 1.5708 -0 0</pose>
        <geometry>
          <cylinder>
            <length>0.097</length>
            <radius>0.089</radius>
          </cylinder>
        </geometry>
        <surface>
          <contact>
            <ode>
              <kp>1e+07</kp>
              <kd>1</kd>
            </ode>
          </contact>
          <friction>
            <ode>
              <mu>0.5</mu>
              <mu2>1</mu2>
              <slip1>0.00092</slip1>
              <slip2>0</slip2>
              <fdir1>0 0 1</fdir1>
            </ode>
          </friction>
        </surface>
      </collision>
      <gravity>1</gravity>
      <velocity_decay/>
      <kinematic>0</kinematic>
    </link>
    <joint name='right_track_wheel7_j' type='revolute'>
      <child>ctu_cras_norlab_absolem_sensor_config_1/right_track_wheel7</child>
      <parent>ctu_cras_norlab_absolem_sensor_config_1/right_track</parent>
      <axis>
        <xyz>0 1 0</xyz>
        <limit>
          <lower>-1e+16</lower>
          <upper>1e+16</upper>
        </limit>
        <dynamics>
          <spring_reference>0</spring_reference>
          <spring_stiffness>0</spring_stiffness>
        </dynamics>
        <use_parent_model_frame>0</use_parent_model_frame>
      </axis>
    </joint>
    <link name='ctu_cras_norlab_absolem_sensor_config_1/right_track_wheel8'>
      <pose>-0.25 -0.1985 0.01855 0 -0 0</pose>
      <inertial>
        <pose>0 0 0.0141 0 -0 0</pose>
        <mass>0.7575</mass>
        <inertia>
          <ixx>0.002731</ixx>
          <ixy>0</ixy>
          <ixz>0</ixz>
          <iyy>0.032554</iyy>
          <iyz>1.5e-05</iyz>
          <izz>0.031391</izz>
        </inertia>
      </inertial>
      <collision name='ctu_cras_norlab_absolem_sensor_config_1/right_track_wheel8_collision'>
        <pose>0 0 0 1.5708 -0 0</pose>
        <geometry>
          <cylinder>
            <length>0.097</length>
            <radius>0.089</radius>
          </cylinder>
        </geometry>
        <surface>
          <contact>
            <ode>
              <kp>1e+07</kp>
              <kd>1</kd>
            </ode>
          </contact>
          <friction>
            <ode>
              <mu>0.5</mu>
              <mu2>1</mu2>
              <slip1>0.00092</slip1>
              <slip2>0</slip2>
              <fdir1>0 0 1</fdir1>
            </ode>
          </friction>
        </surface>
      </collision>
      <gravity>1</gravity>
      <velocity_decay/>
      <kinematic>0</kinematic>
    </link>
    <joint name='right_track_wheel8_j' type='revolute'>
      <child>ctu_cras_norlab_absolem_sensor_config_1/right_track_wheel8</child>
      <parent>ctu_cras_norlab_absolem_sensor_config_1/right_track</parent>
      <axis>
        <xyz>0 1 0</xyz>
        <limit>
          <lower>-1e+16</lower>
          <upper>1e+16</upper>
        </limit>
        <dynamics>
          <spring_reference>0</spring_reference>
          <spring_stiffness>0</spring_stiffness>
        </dynamics>
        <use_parent_model_frame>0</use_parent_model_frame>
      </axis>
    </joint>
    <static>0</static>
    <plugin name='cras::FlipperControlPlugin' filename='libflipper_control_plugin.so'>
      <joint_name>front_left_flipper_j</joint_name>
      <max_velocity>0.8</max_velocity>
    </plugin>
    <plugin name='cras::FlipperControlPlugin' filename='libflipper_control_plugin.so'>
      <joint_name>front_right_flipper_j</joint_name>
      <max_velocity>0.8</max_velocity>
    </plugin>
    <plugin name='cras::FlipperControlPlugin' filename='libflipper_control_plugin.so'>
      <joint_name>rear_left_flipper_j</joint_name>
      <max_velocity>0.8</max_velocity>
    </plugin>
    <plugin name='cras::FlipperControlPlugin' filename='libflipper_control_plugin.so'>
      <joint_name>rear_right_flipper_j</joint_name>
      <max_velocity>0.8</max_velocity>
    </plugin>
    <plugin name='cras::LaserRotatePlugin' filename='liblaser_rotate_plugin.so'>
      <joint_name>laser_j</joint_name>
      <initial_velocity>0.0</initial_velocity>
      <rotation_angular_limit>1.618994</rotation_angular_limit>
    </plugin>
    <plugin name='ignition::gazebo::systems::JointStatePublisher' filename='libignition-gazebo-joint-state-publisher-system.so'>
      <joint_name>front_left_flipper_j</joint_name>
      <joint_name>front_right_flipper_j</joint_name>
      <joint_name>rear_left_flipper_j</joint_name>
      <joint_name>rear_right_flipper_j</joint_name>
      <joint_name>laser_j</joint_name>
    </plugin>
  </model>
</sdf>
