<?xml version="1.0" encoding="utf-8"?>
<!-- =================================================================================== -->
<!--   Copyright 2020 ANYbotics, https://www.anybotics.com                               -->
<!-- =================================================================================== -->
<!-- This file contains the description of the ANYmal C robot. -->
<robot name="anymal">
    <material name="anymal_material">
      <color rgba="0.7 0.7 0.7 1.0"/>
    </material>
    <!-- Base link -->
    <link name="base">
        <visual>
            <origin rpy="0 0 0" xyz="0 0 0"/>
            <geometry>
                <mesh filename="package://anymal_c_simple_description/meshes/base.dae" scale="1.0 1.0 1.0"/>
            </geometry>
        </visual>
        <collision>
            <origin rpy="0 0 0" xyz="0 0 0"/>
            <geometry>
                <box size="0.58 0.14 0.18"/>
            </geometry>
        </collision>
        <collision>
            <origin rpy="0 1.57079632679 0" xyz="0.2175 0.07 0"/>
            <geometry>
                <cylinder length="0.145" radius="0.09"/>
            </geometry>
        </collision>
        <collision>
            <origin rpy="0 1.57079632679 0" xyz="-0.2175 0.07 0"/>
            <geometry>
                <cylinder length="0.145" radius="0.09"/>
            </geometry>
        </collision>
        <collision>
            <origin rpy="0 1.57079632679 0" xyz="0.2175 -0.07 0"/>
            <geometry>
                <cylinder length="0.145" radius="0.09"/>
            </geometry>
        </collision>
        <collision>
            <origin rpy="0 1.57079632679 0" xyz="-0.2175 -0.07 0"/>
            <geometry>
                <cylinder length="0.145" radius="0.09"/>
            </geometry>
        </collision>
        <!-- Shell self filtering -->
        <self_filter>
            <origin rpy="0 0 0" xyz="0 0 0"/>
            <geometry>
                <box size="1.05 0.5 0.5"/>
            </geometry>
        </self_filter>
    </link>
    <!-- Fixed joint to add dummy inertia link -->
    <joint name="base_to_base_inertia" type="fixed">
        <parent link="base"/>
        <child link="base_inertia"/>
        <origin rpy="0 0 0" xyz="0 0 0"/>
    </joint>
    <!-- Dummy inertia link, because KDL cannot have inertia on the base link -->
    <link name="base_inertia">
        <inertial>
            <origin rpy="0 0 0" xyz="-0.018 -0.002 0.024"/>
            <mass value="6.222"/>
            <inertia ixx="0.017938806" ixy="0.00387963" ixz="0.001500772" iyy="0.370887745" iyz="6.8963e-05" izz="0.372497653"/>
        </inertial>
    </link>
    <!-- Fixed joint base topshell -->
    <joint name="base_top_shell" type="fixed">
        <parent link="base"/>
        <child link="top_shell"/>
        <origin rpy="0 0 0" xyz="0 0 0"/>
    </joint>
    <!-- Top shell link -->
    <link name="top_shell">
        <visual>
            <origin rpy="0 0 0" xyz="0 0 0"/>
            <geometry>
                <mesh filename="package://anymal_c_simple_description/meshes/top_shell.dae" scale="1.0 1.0 1.0"/>
            </geometry>
        </visual>
        <inertial>
            <origin rpy="0 0 0" xyz="-0.00777 -0.00013 0.06523"/>
            <mass value="0.534"/>
            <inertia ixx="0.00664789486" ixy="1.247923e-05" ixz="0.00053990097" iyy="0.02587392411" iyz="3.7614e-07" izz="0.03152303792"/>
        </inertial>
    </link>
    <!-- Fixed joint base topshell -->
    <joint name="base_bottom_shell" type="fixed">
        <parent link="base"/>
        <child link="bottom_shell"/>
        <origin rpy="0 0 0" xyz="0 0 0"/>
    </joint>
    <!-- Bottom shell link -->
    <link name="bottom_shell">
        <visual>
            <origin rpy="0 0 0" xyz="0 0 0"/>
            <geometry>
                <mesh filename="package://anymal_c_simple_description/meshes/bottom_shell.dae" scale="1.0 1.0 1.0"/>
            </geometry>
        </visual>
        <inertial>
            <origin rpy="0 0 0" xyz="-0.00333 1e-05 -0.07705"/>
            <mass value="1.15"/>
            <inertia ixx="0.00927353677" ixy="5.41222e-06" ixz="9.039821e-05" iyy="0.06134388239" iyz="2.3042e-07" izz="0.06853531465"/>
        </inertial>
    </link>
    <!-- Fixed joint base remote -->
    <joint name="base_remote" type="fixed">
        <parent link="base"/>
        <child link="remote"/>
        <origin rpy="0 0 0" xyz="0 0 0"/>
    </joint>
    <!-- Remote link -->
    <link name="remote">
        <visual>
            <origin rpy="0 0 0" xyz="0 0 0"/>
            <geometry>
                <mesh filename="package://anymal_c_simple_description/meshes/remote.dae" scale="1.0 1.0 1.0"/>
            </geometry>
        </visual>
        <inertial>
            <origin rpy="0 0 0" xyz="-0.171 0.002 0.096"/>
            <mass value="0.3262"/>
            <inertia ixx="0.000528486" ixy="4.547e-05" ixz="1.10327e-05" iyy="0.001165035" iyz="7.4e-07" izz="0.00124026"/>
        </inertial>
    </link>
    <!-- Fixed joint base handle -->
    <joint name="base_handle" type="fixed">
        <parent link="base"/>
        <child link="handle"/>
        <origin rpy="0 0 0" xyz="0 0 0"/>
    </joint>
    <!-- Handle link -->
    <link name="handle">
        <visual>
            <origin rpy="0 0 0" xyz="0 0 0"/>
            <geometry>
                <mesh filename="package://anymal_c_simple_description/meshes/handle.dae" scale="1.0 1.0 1.0"/>
            </geometry>
        </visual>
        <inertial>
            <origin rpy="0 0 0" xyz="0.37801 0.0 0.1372"/>
            <mass value="0.314"/>
            <inertia ixx="0.001525739" ixy="0.0" ixz="6.272e-05" iyy="0.00071584" iyz="1e-09" izz="0.001164779"/>
        </inertial>
    </link>
    <!-- Fixed joint base battery -->
    <joint name="base_battery" type="fixed">
        <parent link="base"/>
        <child link="battery"/>
        <origin rpy="0 0 0" xyz="0 0 0"/>
    </joint>
    <!-- Shell link -->
    <link name="battery">
        <visual>
            <origin rpy="0 0 0" xyz="0 0 0"/>
            <geometry>
                <mesh filename="package://anymal_c_simple_description/meshes/battery.dae" scale="1.0 1.0 1.0"/>
            </geometry>
        </visual>
        <inertial>
            <origin rpy="0 0 0" xyz="-0.00067 -0.00023 -0.03362"/>
            <mass value="5.53425"/>
            <inertia ixx="0.00749474794" ixy="0.00016686282" ixz="7.82763e-05" iyy="0.0722338913" iyz="1.42902e-06" izz="0.07482717535"/>
        </inertial>
    </link>
    <!-- Fixed joint to add docking  -->
    <joint name="base_to_docking_hatch_cover" type="fixed">
        <parent link="base"/>
        <child link="docking_hatch_cover"/>
        <origin rpy="0 0 0" xyz="0.343 0.0 -0.07"/>
    </joint>
    <!-- Hatch cover link -->
    <link name="docking_hatch_cover">
        <!--  TODO(fgiraldez): add visual    -->
        <inertial>
            <origin rpy="0 0 0" xyz="-0.003 0.0 0.005"/>
            <mass value="0.065"/>
            <inertia ixx="0.00063283" ixy="0.0" ixz="3.45e-07" iyy="0.00110971" iyz="0.0" izz="0.00171883"/>
        </inertial>
    </link>
    <link name="imu_link">
        <visual>
            <origin rpy="0 0 0" xyz="0 0 0.005"/>
            <geometry>
                <box size="0.024 0.024 0.01"/>
            </geometry>
            <material name="orange"/>
        </visual>
        <collision>
            <origin rpy="0 0 0" xyz="0 0 0.005"/>
            <geometry>
                <box size="0.024 0.024 0.01"/>
            </geometry>
        </collision>
        <inertial>
            <mass value="0.01"/>
            <origin xyz="0 0 0"/>
            <inertia ixx="5.63333333333e-07" ixy="0.0" ixz="0.0" iyy="9.6e-07" iyz="0.0" izz="5.63333333333e-07"/>
        </inertial>
    </link>
    <joint name="imu_joint" type="fixed">
        <parent link="base"/>
        <child link="imu_link"/>
        <origin rpy="0.0 0.0 1.57079632679" xyz="0.2488 0.00835 0.04628"/>
    </joint>
    <!-- Front Bpearl & Protection Bars -->
    <joint name="base_to_bpearl_front" type="fixed">
      <origin rpy="-2.5761172 0.2448429 -1.9356696" xyz="0.47 0.0 0.035"/>
      <parent link="base"/>
      <child link="bpearl_front"/>
    </joint>
    <!-- Frame used by point cloud messages -->
    <link name="bpearl_front">
      <visual>
        <!-- From the manual: X and Y axis in ROS convention are rotated of -90 deg w.r.t. rslidar's convention -->
        <origin rpy="0 0 -1.57079632679" xyz="0 0 0"/>
        <geometry>
          <mesh filename="package://anymal_c_simple_description/meshes/rslidar_bpearl.stl" scale=".001 .001 .001"/>
        </geometry>
        <material name="anymal_material"/>
      </visual>
      <collision>
        <!-- From the manual: X and Y axis in ROS convention are rotated of -90 deg w.r.t. rslidar's convention -->
        <origin rpy="0 0 -1.57079632679" xyz="0 0 0.055"/>
        <geometry>
          <box size="0.1 0.1 0.11"/>
        </geometry>
      </collision>
      <!-- Product of inertia are computed in the same frame as the rslidar's manual -->
      <inertial>
        <mass value="0.95"/>
        <origin xyz="-0.00002729                      -0.000960602                      0.035445923"/>
        <inertia ixx="0.00278457" ixy="-0.00000809" ixz="0.000000099" iyy="0.002730237" iyz="-0.000001661" izz="0.00168635"/>
      </inertial>
    </link>
    <!-- Frame used for self filter -->
    <joint name="bpearl_front_to_bpearl_front_beam_origin" type="fixed">
      <parent link="bpearl_front"/>
      <child link="bpearl_front_beam_origin"/>
      <origin rpy="0 0 0" xyz="0 0 0.09427"/>
    </joint>
    <link name="bpearl_front_beam_origin"/>
    <joint name="base_to_bpearl_front_protection_bars" type="fixed">
      <origin rpy="0 0 0.0" xyz="0.414495 0.0 0.0"/>
      <parent link="base"/>
      <child link="bpearl_front_protection_bars"/>
    </joint>
    <link name="bpearl_front_protection_bars">
      <visual>
        <origin rpy="0 0 3.14159265359" xyz="0 0 0"/>
        <geometry>
          <mesh filename="package://anymal_c_simple_description/meshes/bpearl_protection_bars.stl" scale=".001 .001 .001"/>
        </geometry>
        <material name="anymal_material"/>
      </visual>
      <inertial>
        <mass value="0.499717559"/>
        <origin xyz=" 0.079340318484                       0.000069247487                       -0.019714498477"/>
        <inertia ixx="0.002744694191342" ixy="-0.000001651758707" ixz="0.000767436360485" iyy="0.006272427155836" iyz="0.000001335278093" izz="0.006200897129667"/>
      </inertial>
    </link>
    <joint name="$bpearl_front_beam_origin_to_bpearl_front_protection_bars_collision" type="fixed">
      <!-- <xacro:insert_block name="origin" /> -->
      <parent link="bpearl_front_beam_origin"/>
      <child link="bpearl_front_protection_bars_collision"/>
      <origin rpy="0 0 0" xyz="0 0 0"/>
    </joint>
    <link name="bpearl_front_protection_bars_collision">
      <collision>
        <origin rpy="0.0 -0.282743338823 1.1344640138 " xyz="0.0380356435567 0.0815677008333 -0.02"/>
        <geometry>
          <box size="0.030 0.018 0.1"/>
        </geometry>
      </collision>
      <collision>
        <origin rpy="0.0  -1.00530964915 1.1344640138 " xyz="0.024511859181 0.0525658516481 0.053"/>
        <geometry>
          <box size="0.030 0.017 0.068"/>
        </geometry>
      </collision>
      <collision>
        <origin rpy="0.0 -0.282743338823 -1.1344640138 " xyz="0.0380356435567 -0.0815677008333 -0.02"/>
        <geometry>
          <box size="0.030 0.005 0.1"/>
        </geometry>
      </collision>
      <collision>
        <origin rpy="0.0  -1.00530964915 -1.1344640138 " xyz="0.024511859181 -0.0525658516481 0.053"/>
        <geometry>
          <box size="0.030 0.016 0.068"/>
        </geometry>
      </collision>
      <collision>
        <origin rpy="0.0 -0.282743338823 3.35103216383 " xyz="-0.088033284066 -0.0187120521736 -0.02"/>
        <geometry>
          <box size="0.030 0.005 0.1"/>
        </geometry>
      </collision>
      <collision>
        <origin rpy="0.0  -1.00530964915 3.35103216383 " xyz="-0.0567325608426 -0.0120588780674 0.053"/>
        <geometry>
          <box size="0.030 0.016 0.068"/>
        </geometry>
      </collision>
    </link>
    <!-- Rear Bpearl & Protection Bars -->
    <joint name="base_to_bpearl_rear" type="fixed">
      <origin rpy="-2.5761172 0.2448429 1.20592305359" xyz="-0.47 0.0 0.035"/>
      <parent link="base"/>
      <child link="bpearl_rear"/>
    </joint>
    <!-- Frame used by point cloud messages -->
    <link name="bpearl_rear">
      <visual>
        <!-- From the manual: X and Y axis in ROS convention are rotated of -90 deg w.r.t. rslidar's convention -->
        <origin rpy="0 0 -1.57079632679" xyz="0 0 0"/>
        <geometry>
          <mesh filename="package://anymal_c_simple_description/meshes/rslidar_bpearl.stl" scale=".001 .001 .001"/>
        </geometry>
        <material name="anymal_material"/>
      </visual>
      <collision>
        <!-- From the manual: X and Y axis in ROS convention are rotated of -90 deg w.r.t. rslidar's convention -->
        <origin rpy="0 0 -1.57079632679" xyz="0 0 0.055"/>
        <geometry>
          <box size="0.1 0.1 0.11"/>
        </geometry>
      </collision>
      <!-- Product of inertia are computed in the same frame as the rslidar's manual -->
      <inertial>
        <mass value="0.95"/>
        <origin xyz="-0.00002729                      -0.000960602                      0.035445923"/>
        <inertia ixx="0.00278457" ixy="-0.00000809" ixz="0.000000099" iyy="0.002730237" iyz="-0.000001661" izz="0.00168635"/>
      </inertial>
    </link>
    <!-- Frame used for self filter -->
    <joint name="bpearl_rear_to_bpearl_rear_beam_origin" type="fixed">
      <parent link="bpearl_rear"/>
      <child link="bpearl_rear_beam_origin"/>
      <origin rpy="0 0 0" xyz="0 0 0.09427"/>
    </joint>
    <link name="bpearl_rear_beam_origin"/>
    <joint name="base_to_bpearl_rear_protection_bars" type="fixed">
      <origin rpy="0 0 3.14159265359" xyz="-0.414495 0.0 0.0"/>
      <parent link="base"/>
      <child link="bpearl_rear_protection_bars"/>
    </joint>
    <link name="bpearl_rear_protection_bars">
      <visual>
        <origin rpy="0 0 3.14159265359" xyz="0 0 0"/>
        <geometry>
          <mesh filename="package://anymal_c_simple_description/meshes/bpearl_protection_bars.stl" scale=".001 .001 .001"/>
        </geometry>
        <material name="anymal_material"/>
      </visual>
      <inertial>
        <mass value="0.499717559"/>
        <origin xyz=" 0.079340318484                       0.000069247487                       -0.019714498477"/>
        <inertia ixx="0.002744694191342" ixy="-0.000001651758707" ixz="0.000767436360485" iyy="0.006272427155836" iyz="0.000001335278093" izz="0.006200897129667"/>
      </inertial>
    </link>
    <joint name="$bpearl_rear_beam_origin_to_bpearl_rear_protection_bars_collision" type="fixed">
      <!-- <xacro:insert_block name="origin" /> -->
      <parent link="bpearl_rear_beam_origin"/>
      <child link="bpearl_rear_protection_bars_collision"/>
      <origin rpy="0 0 0" xyz="0 0 0"/>
    </joint>
    <link name="bpearl_rear_protection_bars_collision">
      <collision>
        <origin rpy="0.0 -0.282743338823 1.1344640138 " xyz="0.0380356435567 0.0815677008333 -0.02"/>
        <geometry>
          <box size="0.030 0.018 0.1"/>
        </geometry>
      </collision>
      <collision>
        <origin rpy="0.0  -1.00530964915 1.1344640138 " xyz="0.024511859181 0.0525658516481 0.053"/>
        <geometry>
          <box size="0.030 0.017 0.068"/>
        </geometry>
      </collision>
      <collision>
        <origin rpy="0.0 -0.282743338823 -1.23918376892 " xyz="0.0293011339011 -0.0850966718039 -0.02"/>
        <geometry>
          <box size="0.030 0.005 0.1"/>
        </geometry>
      </collision>
      <collision>
        <origin rpy="0.0  -1.00530964915 -1.23918376892 " xyz="0.0188829529585 -0.0548400773848 0.053"/>
        <geometry>
          <box size="0.030 0.016 0.068"/>
        </geometry>
      </collision>
      <collision>
        <origin rpy="0.0 -0.282743338823 3.29867228627 " xyz="-0.0888919506536 -0.0140791018536 -0.02"/>
        <geometry>
          <box size="0.030 0.005 0.1"/>
        </geometry>
      </collision>
      <collision>
        <origin rpy="0.0  -1.00530964915 3.29867228627 " xyz="-0.0572859237545 -0.00907319897233 0.053"/>
        <geometry>
          <box size="0.030 0.016 0.068"/>
        </geometry>
      </collision>
    </link>
    <!-- Percpetion Head Cage -->
    <!-- Parent to cage joint, located between mounting plate on trunk and the cage -->
    <joint name="base_to_perception_head_cage" type="fixed">
      <parent link="base"/>
      <child link="perception_head_cage"/>
      <origin rpy="0 0 0" xyz="-0.364 0.0 0.0"/>
    </joint>
    <!-- Velodyne cage link -->
    <link name="perception_head_cage">
      <visual>
        <origin rpy="0.0 0.0 0.0" xyz="0.0 0.0 0.0"/>
        <geometry>
          <mesh filename="package://anymal_c_simple_description/meshes/perception_head.stl" scale=".001 .001 .001"/>
        </geometry>
        <material name="anymal_material"/>
      </visual>
      <collision>
        <origin rpy="0 0 0" xyz="0.0080435 0.0 0.1614"/>
        <geometry>
          <box size="0.14151 0.21544 0.1768"/>
        </geometry>
      </collision>
      <inertial>
        <mass value="0.3879"/>
        <origin xyz="-0.01163                      -0.0000109                      0.15412"/>
        <inertia ixx="0.011412" ixy="-0.00000037" ixz="-0.00086643" iyy="0.010402" iyz="0.00000038" izz="0.001749"/>
      </inertial>
    </link>
    <!-- [kg * m^2] -->
    <!-- parent to sensor joint -->
    <joint name="perception_head_cage_to_lidar" type="fixed">
      <parent link="perception_head_cage"/>
      <child link="lidar"/>
      <origin rpy="0.0 0.0 -1.57079632679" xyz="0.0 0.0 0.1422"/>
    </joint>
    <!-- Velodyne sensor link -->
    <link name="lidar">
        <inertial>
            <origin rpy="0.0 0.0 0.0" xyz="-0.012 0.001 -0.008"/>
            <mass value="0.695"/>
            <inertia ixx="0.000846765" ixy="6.9565e-05" ixz="0.00027111" iyy="0.001367583" iyz="5.8984e-05" izz="0.001363673"/>
        </inertial>
        <visual>
            <origin xyz="0 0 0"/>
            <geometry>
                <mesh filename="package://anymal_c_simple_description/meshes/lidar.dae"/>
            </geometry>
        </visual>
    </link>
    <!-- Alphasense -->
    <link name="imu_sensor_frame"/>
    <joint name="lidar_to_alphasense" type="fixed">
      <parent link="lidar"/>
      <child link="imu_sensor_frame"/>
      <origin rpy="0.0 0.0 0.0" xyz="0.005303 0.03734 0.063319"/>
    </joint>
    <!-- Visualization & Crash Box -->
    <link name="alphasense_mesh">
      <visual>
        <origin rpy="0 0 0" xyz="0 0 0"/>
        <geometry>
          <mesh filename="package://anymal_c_simple_description/meshes/alphasense.stl" scale=".001 .001 .001"/>
        </geometry>
        <material name="anymal_material"/>
      </visual>
      <collision>
        <origin rpy="0 0 0" xyz="0.0144025 0.0 0.235"/>
        <geometry>
          <box size="0.128 0.165 0.098"/>
        </geometry>
      </collision>
      <inertial>
        <mass value="0.5"/>
        <origin xyz="0.01243 0.000687 0.23"/>
        <inertia ixx="0.001237" ixy="0.000016" ixz="0.000005" iyy="0.000897" iyz="-0.00001143" izz="0.00149"/>
      </inertial>
    </link>
    <joint name="base_to_alphasense_mesh" type="fixed">
      <parent link="base"/>
      <child link="alphasense_mesh"/>
      <origin rpy="0.0 0.0 0.0" xyz="-0.364 0.0 0.0"/>
    </joint>
    <link name="cam0_sensor_frame"/>
    <joint name="imu_sensor_frame_to_cam0_sensor_frame" type="fixed">
      <parent link="imu_sensor_frame"/>
      <child link="cam0_sensor_frame"/>
      <origin rpy="-1.576584 -0.0105238 3.1334282" xyz="0.04496145 -0.07371112 0.0233054"/>
    </joint>
    <link name="cam1_sensor_frame"/>
    <joint name="imu_sensor_frame_to_cam1_sensor_frame" type="fixed">
      <parent link="imu_sensor_frame"/>
      <child link="cam1_sensor_frame"/>
      <origin rpy="-1.5769547 8.3e-05 3.1397596" xyz="-0.05455132 -0.07351055 0.02318442"/>
    </joint>
    <link name="cam2_sensor_frame"/>
    <joint name="imu_sensor_frame_to_cam2_sensor_frame" type="fixed">
      <parent link="imu_sensor_frame"/>
      <child link="cam2_sensor_frame"/>
      <origin rpy="6.5e-06 -0.0067966 3.1357887" xyz="0.04429731 -0.05276805 0.05834653"/>
    </joint>
    <link name="cam3_sensor_frame"/>
    <joint name="imu_sensor_frame_to_cam3_sensor_frame" type="fixed">
      <parent link="imu_sensor_frame"/>
      <child link="cam3_sensor_frame"/>
      <origin rpy="-1.3982866 0.0043838 -1.5744406" xyz="0.06783077 -0.02095088 0.03101097"/>
    </joint>
    <link name="cam4_sensor_frame"/>
    <joint name="imu_sensor_frame_to_cam4_sensor_frame" type="fixed">
      <parent link="imu_sensor_frame"/>
      <child link="cam4_sensor_frame"/>
      <origin rpy="-1.5800559 -0.0024584 3.1364828" xyz="-0.00481047 -0.07274994 0.02235257"/>
    </joint>
    <link name="cam5_sensor_frame"/>
    <joint name="imu_sensor_frame_to_cam5_sensor_frame" type="fixed">
      <parent link="imu_sensor_frame"/>
      <child link="cam5_sensor_frame"/>
      <origin rpy="-1.3985566 -0.0112895 1.567379" xyz="-0.07723225 -0.01994317 0.03012213"/>
    </joint>
    <link name="cam6_sensor_frame"/>
    <joint name="imu_sensor_frame_to_cam6_sensor_frame" type="fixed">
      <parent link="imu_sensor_frame"/>
      <child link="cam6_sensor_frame"/>
      <origin rpy="-0.0026809 -0.0012731 -3.1408142" xyz="-0.05499534 -0.05194987 0.05989379"/>
    </joint>
    <!-- joint base HAA -->
    <joint name="base_LF_HAA" type="fixed">
        <parent link="base"/>
        <child link="LF_HAA"/>
        <origin rpy="2.61799387799 0 0.0" xyz="0.2999 0.104 0.0"/>
    </joint>
    <!-- Drive link -->
    <link name="LF_HAA">
        <visual>
            <origin rpy="0 0 0" xyz="0 0 0"/>
            <geometry>
                <mesh filename="package://anymal_c_simple_description/meshes/drive.dae" scale="1.0 1.0 1.0"/>
            </geometry>
        </visual>
        <inertial>
            <origin rpy="0 0 0" xyz="-0.063 7e-05 0.00046"/>
            <mass value="2.04"/>
            <inertia ixx="0.001053013" ixy="4.527e-05" ixz="8.855e-05" iyy="0.001805509" iyz="9.909e-05" izz="0.001765827"/>
        </inertial>
    </link>
    <!-- joint Drive output -->
    <joint name="LF_HAA" type="revolute">
        <parent link="LF_HAA"/>
        <child link="LF_HIP"/>
        <origin rpy="0 0 0" xyz="0 0 0"/>
        <axis xyz="1 0 0"/>
        <limit effort="80.0" lower="-0.72" upper="0.49" velocity="7.5"/>
        <dynamics damping="0.0" friction="0.0"/>
    </joint>
    <!-- Drive output link -->
    <link name="LF_HIP">
        <inertial>
            <origin rpy="0 0 0" xyz="0 0 0"/>
            <mass value="0.001"/>
            <inertia ixx="0.000001" ixy="0.0" ixz="0.0" iyy="0.000001" iyz="0.0" izz="0.000001"/>
        </inertial>
    </link>
    <!-- joint HAA hip -->
    <joint name="LF_HIP_LF_hip_fixed" type="fixed">
        <parent link="LF_HIP"/>
        <child link="LF_hip_fixed"/>
        <origin rpy="-2.61799387799 0 0.0" xyz="0 0 0"/>
    </joint>
    <!-- Hip link -->
    <link name="LF_hip_fixed">
        <visual>
            <origin rpy="0 0 0.0" xyz="0 0 0"/>
            <geometry>
                <mesh filename="package://anymal_c_simple_description/meshes/hip_l.dae" scale="1.0 1.0 1.0"/>
            </geometry>
        </visual>
        <inertial>
            <origin rpy="0 0 0" xyz="0.048 0.008 -0.003"/>
            <mass value="0.74"/>
            <inertia ixx="0.001393106" ixy="8.4012e-05" ixz="2.3378e-05" iyy="0.003798579" iyz="7.1319e-05" izz="0.003897509"/>
        </inertial>
    </link>
    <!-- joint hip HFE -->
    <joint name="LF_hip_fixed_LF_HFE" type="fixed">
        <parent link="LF_hip_fixed"/>
        <child link="LF_HFE"/>
        <origin rpy="0 0 1.57079632679" xyz="0.0599 0.08381 0.0"/>
    </joint>
    <!-- Drive link -->
    <link name="LF_HFE">
        <visual>
            <origin rpy="0 0 0" xyz="0 0 0"/>
            <geometry>
                <mesh filename="package://anymal_c_simple_description/meshes/drive.dae" scale="1.0 1.0 1.0"/>
            </geometry>
        </visual>
        <collision>
            <origin rpy="0 1.57079632679 0" xyz="-0.07 0 0"/>
            <geometry>
                <cylinder length="0.14" radius="0.05"/>
            </geometry>
        </collision>
        <inertial>
            <origin rpy="0 0 0" xyz="-0.063 7e-05 0.00046"/>
            <mass value="2.04"/>
            <inertia ixx="0.001053013" ixy="4.527e-05" ixz="8.855e-05" iyy="0.001805509" iyz="9.909e-05" izz="0.001765827"/>
        </inertial>
    </link>
    <!-- joint Drive output -->
    <joint name="LF_HFE" type="revolute">
        <parent link="LF_HFE"/>
        <child link="LF_THIGH"/>
        <origin rpy="0 0 0" xyz="0 0 0"/>
        <axis xyz="1 0 0"/>
        <limit effort="80.0" lower="-9.42477796077" upper="9.42477796077" velocity="7.5"/>
        <dynamics damping="0.0" friction="0.0"/>
    </joint>
    <!-- Drive output link -->
    <link name="LF_THIGH">
        <inertial>
            <origin rpy="0 0 0" xyz="0 0 0"/>
            <mass value="0.001"/>
            <inertia ixx="0.000001" ixy="0.0" ixz="0.0" iyy="0.000001" iyz="0.0" izz="0.000001"/>
        </inertial>
    </link>
    <!-- joint HFE thigh -->
    <joint name="LF_THIGH_LF_thigh_fixed" type="fixed">
        <parent link="LF_THIGH"/>
        <child link="LF_thigh_fixed"/>
        <origin rpy="0 0 -1.57079632679" xyz="0 0 0"/>
    </joint>
    <!-- Thigh link -->
    <link name="LF_thigh_fixed">
        <visual>
            <origin rpy="0 0 0.0" xyz="0 0 0"/>
            <geometry>
                <mesh filename="package://anymal_c_simple_description/meshes/thigh.dae" scale="1.0 1.0 1.0"/>
            </geometry>
        </visual>
        <!-- Thigh collision -->
        <collision>
            <origin rpy="1.57079632679 0 0" xyz="0 0.04 0"/>
            <geometry>
                <cylinder length="0.08" radius="0.065"/>
            </geometry>
        </collision>
        <collision>
            <origin rpy="0 0 0" xyz="0 0.03 -0.1413135"/>
            <geometry>
                <box size="0.075 0.06 0.282627"/>
            </geometry>
        </collision>
        <inertial>
            <origin rpy="0 0 0" xyz="0.0 0.018 -0.169"/>
            <mass value="1.03"/>
            <inertia ixx="0.018644469" ixy="5.2e-08" ixz="1.0157e-05" iyy="0.019312599" iyz="0.002520077" izz="0.002838361"/>
        </inertial>
    </link>
    <!-- joint thigh KFE -->
    <joint name="LF_thigh_fixed_LF_KFE" type="fixed">
        <parent link="LF_thigh_fixed"/>
        <child link="LF_KFE"/>
        <origin rpy="0 0 1.57079632679" xyz="0.0 0.1003 -0.285"/>
    </joint>
    <!-- Drive link -->
    <link name="LF_KFE">
        <visual>
            <origin rpy="0 0 0" xyz="0 0 0"/>
            <geometry>
                <mesh filename="package://anymal_c_simple_description/meshes/drive.dae" scale="1.0 1.0 1.0"/>
            </geometry>
        </visual>
        <collision>
            <origin rpy="0 1.57079632679 0" xyz="-0.07 0 0"/>
            <geometry>
                <cylinder length="0.14" radius="0.05"/>
            </geometry>
        </collision>
        <inertial>
            <origin rpy="0 0 0" xyz="-0.063 7e-05 0.00046"/>
            <mass value="2.04"/>
            <inertia ixx="0.001053013" ixy="4.527e-05" ixz="8.855e-05" iyy="0.001805509" iyz="9.909e-05" izz="0.001765827"/>
        </inertial>
    </link>
    <!-- joint Drive output -->
    <joint name="LF_KFE" type="revolute">
        <parent link="LF_KFE"/>
        <child link="LF_SHANK"/>
        <origin rpy="0 0 0" xyz="0 0 0"/>
        <axis xyz="1 0 0"/>
        <limit effort="80.0" lower="-9.42477796077" upper="9.42477796077" velocity="7.5"/>
        <dynamics damping="0.0" friction="0.0"/>
    </joint>
    <!-- Drive output link -->
    <link name="LF_SHANK">
        <inertial>
            <origin rpy="0 0 0" xyz="0 0 0"/>
            <mass value="0.001"/>
            <inertia ixx="0.000001" ixy="0.0" ixz="0.0" iyy="0.000001" iyz="0.0" izz="0.000001"/>
        </inertial>
    </link>
    <!-- joint KFE shank -->
    <joint name="LF_shank_LF_shank_fixed" type="fixed">
        <parent link="LF_SHANK"/>
        <child link="LF_shank_fixed"/>
        <origin rpy="0 0 -1.57079632679" xyz="0 0 0"/>
    </joint>
    <!-- Shank link -->
    <link name="LF_shank_fixed">
        <visual>
            <origin rpy="0 0 0.0" xyz="0 0 0"/>
            <geometry>
                <mesh filename="package://anymal_c_simple_description/meshes/shank_l.dae" scale="1.0 1.0 1.0"/>
            </geometry>
        </visual>
        <!-- Shank collision -->
        <collision>
            <origin rpy="1.57079632679 0 0" xyz="0 0.02 0"/>
            <geometry>
                <cylinder length="0.04" radius="0.06"/>
            </geometry>
        </collision>
        <collision>
            <origin rpy="1.57079632679 0 0" xyz="0.057499 0.02 0"/>
            <geometry>
                <box size="0.114998 0.0675 0.04"/>
            </geometry>
        </collision>
        <inertial>
            <origin rpy="0 0 0" xyz="0.03463 0.00688 0.00098"/>
            <mass value="0.33742"/>
            <inertia ixx="0.00032748005" ixy="2.142561e-05" ixz="1.33942e-05" iyy="0.00110974122" iyz="7.601e-08" izz="0.00089388521"/>
        </inertial>
    </link>
    <!-- Leg configurations: xx (knees bent inwards), xo (knees bent backwards) -->
    <!-- joint shank foot -->
    <joint name="LF_shank_fixed_LF_FOOT" type="fixed">
        <parent link="LF_shank_fixed"/>
        <child link="LF_FOOT"/>
        <origin rpy="0 0 0" xyz="0.08795 0.01305 -0.33797"/>
    </joint>
    <!-- Foot link -->
    <link name="LF_FOOT">
        <visual>
            <origin rpy="0 0 -0.785398163397" xyz="0 0 0"/>
            <geometry>
                <mesh filename="package://anymal_c_simple_description/meshes/foot.dae" scale="1.0 1.0 1.0"/>
            </geometry>
        </visual>
        <!-- Adapter collision -->
        <collision>
            <origin rpy="0 0 0" xyz="0 0 0.168985"/>
            <geometry>
                <cylinder length="0.282504" radius="0.0175"/>
            </geometry>
        </collision>
        <!-- Foot collision -->
        <collision>
            <origin xyz="0 0 0.0225"/>
            <geometry>
                <sphere radius="0.03"/>
            </geometry>
        </collision>
        <inertial>
            <origin rpy="0 0 0" xyz="0.00948 -0.00948 0.1468"/>
            <mass value="0.25"/>
            <inertia ixx="0.00317174097" ixy="2.63048e-06" ixz="6.815581e-05" iyy="0.00317174092" iyz="6.815583e-05" izz="8.319196e-05"/>
        </inertial>
    </link>
    <!-- joint base HAA -->
    <joint name="base_RF_HAA" type="fixed">
        <parent link="base"/>
        <child link="RF_HAA"/>
        <origin rpy="-2.61799387799 0 0.0" xyz="0.2999 -0.104 0.0"/>
    </joint>
    <!-- Drive link -->
    <link name="RF_HAA">
        <visual>
            <origin rpy="0 0 0" xyz="0 0 0"/>
            <geometry>
                <mesh filename="package://anymal_c_simple_description/meshes/drive.dae" scale="1.0 1.0 1.0"/>
            </geometry>
        </visual>
        <inertial>
            <origin rpy="0 0 0" xyz="-0.063 7e-05 0.00046"/>
            <mass value="2.04"/>
            <inertia ixx="0.001053013" ixy="4.527e-05" ixz="8.855e-05" iyy="0.001805509" iyz="9.909e-05" izz="0.001765827"/>
        </inertial>
    </link>
    <!-- joint Drive output -->
    <joint name="RF_HAA" type="revolute">
        <parent link="RF_HAA"/>
        <child link="RF_HIP"/>
        <origin rpy="0 0 0" xyz="0 0 0"/>
        <axis xyz="1 0 0"/>
        <limit effort="80.0" lower="-0.49" upper="0.72" velocity="7.5"/>
        <dynamics damping="0.0" friction="0.0"/>
    </joint>
    <!-- Drive output link -->
    <link name="RF_HIP">
        <inertial>
            <origin rpy="0 0 0" xyz="0 0 0"/>
            <mass value="0.001"/>
            <inertia ixx="0.000001" ixy="0.0" ixz="0.0" iyy="0.000001" iyz="0.0" izz="0.000001"/>
        </inertial>
    </link>
    <!-- joint HAA hip -->
    <joint name="RF_HIP_RF_hip_fixed" type="fixed">
        <parent link="RF_HIP"/>
        <child link="RF_hip_fixed"/>
        <origin rpy="2.61799387799 0 0.0" xyz="0 0 0"/>
    </joint>
    <!-- Hip link -->
    <link name="RF_hip_fixed">
        <visual>
            <origin rpy="0 0 0.0" xyz="0 0 0"/>
            <geometry>
                <mesh filename="package://anymal_c_simple_description/meshes/hip_r.dae" scale="1.0 1.0 1.0"/>
            </geometry>
        </visual>
        <inertial>
            <origin rpy="0 0 0" xyz="0.048 -0.008 -0.003"/>
            <mass value="0.74"/>
            <inertia ixx="0.001393106" ixy="-8.4012e-05" ixz="2.3378e-05" iyy="0.003798579" iyz="-7.1319e-05" izz="0.003897509"/>
        </inertial>
    </link>
    <!-- joint hip HFE -->
    <joint name="RF_hip_fixed_RF_HFE" type="fixed">
        <parent link="RF_hip_fixed"/>
        <child link="RF_HFE"/>
        <origin rpy="0 0 -1.57079632679" xyz="0.0599 -0.08381 0.0"/>
    </joint>
    <!-- Drive link -->
    <link name="RF_HFE">
        <visual>
            <origin rpy="0 0 0" xyz="0 0 0"/>
            <geometry>
                <mesh filename="package://anymal_c_simple_description/meshes/drive.dae" scale="1.0 1.0 1.0"/>
            </geometry>
        </visual>
        <collision>
            <origin rpy="0 1.57079632679 0" xyz="-0.07 0 0"/>
            <geometry>
                <cylinder length="0.14" radius="0.05"/>
            </geometry>
        </collision>
        <inertial>
            <origin rpy="0 0 0" xyz="-0.063 7e-05 0.00046"/>
            <mass value="2.04"/>
            <inertia ixx="0.001053013" ixy="4.527e-05" ixz="8.855e-05" iyy="0.001805509" iyz="9.909e-05" izz="0.001765827"/>
        </inertial>
    </link>
    <!-- joint Drive output -->
    <joint name="RF_HFE" type="revolute">
        <parent link="RF_HFE"/>
        <child link="RF_THIGH"/>
        <origin rpy="0 0 0" xyz="0 0 0"/>
        <axis xyz="-1 0 0"/>
        <limit effort="80.0" lower="-9.42477796077" upper="9.42477796077" velocity="7.5"/>
        <dynamics damping="0.0" friction="0.0"/>
    </joint>
    <!-- Drive output link -->
    <link name="RF_THIGH">
        <inertial>
            <origin rpy="0 0 0" xyz="0 0 0"/>
            <mass value="0.001"/>
            <inertia ixx="0.000001" ixy="0.0" ixz="0.0" iyy="0.000001" iyz="0.0" izz="0.000001"/>
        </inertial>
    </link>
    <!-- joint HFE thigh -->
    <joint name="RF_THIGH_RF_thigh_fixed" type="fixed">
        <parent link="RF_THIGH"/>
        <child link="RF_thigh_fixed"/>
        <origin rpy="0 0 1.57079632679" xyz="0 0 0"/>
    </joint>
    <!-- Thigh link -->
    <link name="RF_thigh_fixed">
        <visual>
            <origin rpy="0 0 -3.14159265359" xyz="0 0 0"/>
            <geometry>
                <mesh filename="package://anymal_c_simple_description/meshes/thigh.dae" scale="1.0 1.0 1.0"/>
            </geometry>
        </visual>
        <!-- Thigh collision -->
        <collision>
            <origin rpy="1.57079632679 0 0" xyz="0 -0.04 0"/>
            <geometry>
                <cylinder length="0.08" radius="0.065"/>
            </geometry>
        </collision>
        <collision>
            <origin rpy="0 0 0" xyz="0 -0.03 -0.1413135"/>
            <geometry>
                <box size="0.075 0.06 0.282627"/>
            </geometry>
        </collision>
        <inertial>
            <origin rpy="0 0 0" xyz="0.0 -0.018 -0.169"/>
            <mass value="1.03"/>
            <inertia ixx="0.018644469" ixy="-5.2e-08" ixz="1.0157e-05" iyy="0.019312599" iyz="-0.002520077" izz="0.002838361"/>
        </inertial>
    </link>
    <!-- joint thigh KFE -->
    <joint name="RF_thigh_fixed_RF_KFE" type="fixed">
        <parent link="RF_thigh_fixed"/>
        <child link="RF_KFE"/>
        <origin rpy="0 0 -1.57079632679" xyz="0.0 -0.1003 -0.285"/>
    </joint>
    <!-- Drive link -->
    <link name="RF_KFE">
        <visual>
            <origin rpy="0 0 0" xyz="0 0 0"/>
            <geometry>
                <mesh filename="package://anymal_c_simple_description/meshes/drive.dae" scale="1.0 1.0 1.0"/>
            </geometry>
        </visual>
        <collision>
            <origin rpy="0 1.57079632679 0" xyz="-0.07 0 0"/>
            <geometry>
                <cylinder length="0.14" radius="0.05"/>
            </geometry>
        </collision>
        <inertial>
            <origin rpy="0 0 0" xyz="-0.063 7e-05 0.00046"/>
            <mass value="2.04"/>
            <inertia ixx="0.001053013" ixy="4.527e-05" ixz="8.855e-05" iyy="0.001805509" iyz="9.909e-05" izz="0.001765827"/>
        </inertial>
    </link>
    <!-- joint Drive output -->
    <joint name="RF_KFE" type="revolute">
        <parent link="RF_KFE"/>
        <child link="RF_SHANK"/>
        <origin rpy="0 0 0" xyz="0 0 0"/>
        <axis xyz="-1 0 0"/>
        <limit effort="80.0" lower="-9.42477796077" upper="9.42477796077" velocity="7.5"/>
        <dynamics damping="0.0" friction="0.0"/>
    </joint>
    <!-- Drive output link -->
    <link name="RF_SHANK">
        <inertial>
            <origin rpy="0 0 0" xyz="0 0 0"/>
            <mass value="0.001"/>
            <inertia ixx="0.000001" ixy="0.0" ixz="0.0" iyy="0.000001" iyz="0.0" izz="0.000001"/>
        </inertial>
    </link>
    <!-- joint KFE shank -->
    <joint name="RF_shank_RF_shank_fixed" type="fixed">
        <parent link="RF_SHANK"/>
        <child link="RF_shank_fixed"/>
        <origin rpy="0 0 1.57079632679" xyz="0 0 0"/>
    </joint>
    <!-- Shank link -->
    <link name="RF_shank_fixed">
        <visual>
            <origin rpy="0 0 0.0" xyz="0 0 0"/>
            <geometry>
                <mesh filename="package://anymal_c_simple_description/meshes/shank_r.dae" scale="1.0 1.0 1.0"/>
            </geometry>
        </visual>
        <!-- Shank collision -->
        <collision>
            <origin rpy="1.57079632679 0 0" xyz="0 -0.02 0"/>
            <geometry>
                <cylinder length="0.04" radius="0.06"/>
            </geometry>
        </collision>
        <collision>
            <origin rpy="1.57079632679 0 0" xyz="0.057499 -0.02 0"/>
            <geometry>
                <box size="0.114998 0.0675 0.04"/>
            </geometry>
        </collision>
        <inertial>
            <origin rpy="0 0 0" xyz="0.03463 -0.00688 0.00098"/>
            <mass value="0.33742"/>
            <inertia ixx="0.00032748005" ixy="-2.142561e-05" ixz="1.33942e-05" iyy="0.00110974122" iyz="-7.601e-08" izz="0.00089388521"/>
        </inertial>
    </link>
    <!-- Leg configurations: xx (knees bent inwards), xo (knees bent backwards) -->
    <!-- joint shank foot -->
    <joint name="RF_shank_fixed_RF_FOOT" type="fixed">
        <parent link="RF_shank_fixed"/>
        <child link="RF_FOOT"/>
        <origin rpy="0 0 0" xyz="0.08795 -0.01305 -0.33797"/>
    </joint>
    <!-- Foot link -->
    <link name="RF_FOOT">
        <visual>
            <origin rpy="0 0 0.785398163397" xyz="0 0 0"/>
            <geometry>
                <mesh filename="package://anymal_c_simple_description/meshes/foot.dae" scale="1.0 1.0 1.0"/>
            </geometry>
        </visual>
        <!-- Adapter collision -->
        <collision>
            <origin rpy="0 0 0" xyz="0 0 0.168985"/>
            <geometry>
                <cylinder length="0.282504" radius="0.0175"/>
            </geometry>
        </collision>
        <!-- Foot collision -->
        <collision>
            <origin xyz="0 0 0.0225"/>
            <geometry>
                <sphere radius="0.03"/>
            </geometry>
        </collision>
        <inertial>
            <origin rpy="0 0 0" xyz="0.00948 0.00948 0.1468"/>
            <mass value="0.25"/>
            <inertia ixx="0.00317174097" ixy="-2.63048e-06" ixz="6.815581e-05" iyy="0.00317174092" iyz="-6.815583e-05" izz="8.319196e-05"/>
        </inertial>
    </link>
    <!-- joint base HAA -->
    <joint name="base_LH_HAA" type="fixed">
        <parent link="base"/>
        <child link="LH_HAA"/>
        <origin rpy="-2.61799387799 0 -3.14159265359" xyz="-0.2999 0.104 0.0"/>
    </joint>
    <!-- Drive link -->
    <link name="LH_HAA">
        <visual>
            <origin rpy="0 0 0" xyz="0 0 0"/>
            <geometry>
                <mesh filename="package://anymal_c_simple_description/meshes/drive.dae" scale="1.0 1.0 1.0"/>
            </geometry>
        </visual>
        <inertial>
            <origin rpy="0 0 0" xyz="-0.063 7e-05 0.00046"/>
            <mass value="2.04"/>
            <inertia ixx="0.001053013" ixy="4.527e-05" ixz="8.855e-05" iyy="0.001805509" iyz="9.909e-05" izz="0.001765827"/>
        </inertial>
    </link>
    <!-- joint Drive output -->
    <joint name="LH_HAA" type="revolute">
        <parent link="LH_HAA"/>
        <child link="LH_HIP"/>
        <origin rpy="0 0 0" xyz="0 0 0"/>
        <axis xyz="-1 0 0"/>
        <limit effort="80.0" lower="-0.72" upper="0.49" velocity="7.5"/>
        <dynamics damping="0.0" friction="0.0"/>
    </joint>
    <!-- Drive output link -->
    <link name="LH_HIP">
        <inertial>
            <origin rpy="0 0 0" xyz="0 0 0"/>
            <mass value="0.001"/>
            <inertia ixx="0.000001" ixy="0.0" ixz="0.0" iyy="0.000001" iyz="0.0" izz="0.000001"/>
        </inertial>
    </link>
    <!-- joint HAA hip -->
    <joint name="LH_HIP_LH_hip_fixed" type="fixed">
        <parent link="LH_HIP"/>
        <child link="LH_hip_fixed"/>
        <origin rpy="-2.61799387799 0 -3.14159265359" xyz="0 0 0"/>
    </joint>
    <!-- Hip link -->
    <link name="LH_hip_fixed">
        <visual>
            <origin rpy="0 0 -3.14159265359" xyz="0 0 0"/>
            <geometry>
                <mesh filename="package://anymal_c_simple_description/meshes/hip_r.dae" scale="1.0 1.0 1.0"/>
            </geometry>
        </visual>
        <inertial>
            <origin rpy="0 0 0" xyz="-0.048 0.008 -0.003"/>
            <mass value="0.74"/>
            <inertia ixx="0.001393106" ixy="-8.4012e-05" ixz="-2.3378e-05" iyy="0.003798579" iyz="7.1319e-05" izz="0.003897509"/>
        </inertial>
    </link>
    <!-- joint hip HFE -->
    <joint name="LH_hip_fixed_LH_HFE" type="fixed">
        <parent link="LH_hip_fixed"/>
        <child link="LH_HFE"/>
        <origin rpy="0 0 1.57079632679" xyz="-0.0599 0.08381 0.0"/>
    </joint>
    <!-- Drive link -->
    <link name="LH_HFE">
        <visual>
            <origin rpy="0 0 0" xyz="0 0 0"/>
            <geometry>
                <mesh filename="package://anymal_c_simple_description/meshes/drive.dae" scale="1.0 1.0 1.0"/>
            </geometry>
        </visual>
        <collision>
            <origin rpy="0 1.57079632679 0" xyz="-0.07 0 0"/>
            <geometry>
                <cylinder length="0.14" radius="0.05"/>
            </geometry>
        </collision>
        <inertial>
            <origin rpy="0 0 0" xyz="-0.063 7e-05 0.00046"/>
            <mass value="2.04"/>
            <inertia ixx="0.001053013" ixy="4.527e-05" ixz="8.855e-05" iyy="0.001805509" iyz="9.909e-05" izz="0.001765827"/>
        </inertial>
    </link>
    <!-- joint Drive output -->
    <joint name="LH_HFE" type="revolute">
        <parent link="LH_HFE"/>
        <child link="LH_THIGH"/>
        <origin rpy="0 0 0" xyz="0 0 0"/>
        <axis xyz="1 0 0"/>
        <limit effort="80.0" lower="-9.42477796077" upper="9.42477796077" velocity="7.5"/>
        <dynamics damping="0.0" friction="0.0"/>
    </joint>
    <!-- Drive output link -->
    <link name="LH_THIGH">
        <inertial>
            <origin rpy="0 0 0" xyz="0 0 0"/>
            <mass value="0.001"/>
            <inertia ixx="0.000001" ixy="0.0" ixz="0.0" iyy="0.000001" iyz="0.0" izz="0.000001"/>
        </inertial>
    </link>
    <!-- joint HFE thigh -->
    <joint name="LH_THIGH_LH_thigh_fixed" type="fixed">
        <parent link="LH_THIGH"/>
        <child link="LH_thigh_fixed"/>
        <origin rpy="0 0 -1.57079632679" xyz="0 0 0"/>
    </joint>
    <!-- Thigh link -->
    <link name="LH_thigh_fixed">
        <visual>
            <origin rpy="0 0 0.0" xyz="0 0 0"/>
            <geometry>
                <mesh filename="package://anymal_c_simple_description/meshes/thigh.dae" scale="1.0 1.0 1.0"/>
            </geometry>
        </visual>
        <!-- Thigh collision -->
        <collision>
            <origin rpy="1.57079632679 0 0" xyz="0 0.04 0"/>
            <geometry>
                <cylinder length="0.08" radius="0.065"/>
            </geometry>
        </collision>
        <collision>
            <origin rpy="0 0 0" xyz="0 0.03 -0.1413135"/>
            <geometry>
                <box size="0.075 0.06 0.282627"/>
            </geometry>
        </collision>
        <inertial>
            <origin rpy="0 0 0" xyz="-0.0 0.018 -0.169"/>
            <mass value="1.03"/>
            <inertia ixx="0.018644469" ixy="-5.2e-08" ixz="-1.0157e-05" iyy="0.019312599" iyz="0.002520077" izz="0.002838361"/>
        </inertial>
    </link>
    <!-- joint thigh KFE -->
    <joint name="LH_thigh_fixed_LH_KFE" type="fixed">
        <parent link="LH_thigh_fixed"/>
        <child link="LH_KFE"/>
        <origin rpy="0 0 1.57079632679" xyz="-0.0 0.1003 -0.285"/>
    </joint>
    <!-- Drive link -->
    <link name="LH_KFE">
        <visual>
            <origin rpy="0 0 0" xyz="0 0 0"/>
            <geometry>
                <mesh filename="package://anymal_c_simple_description/meshes/drive.dae" scale="1.0 1.0 1.0"/>
            </geometry>
        </visual>
        <collision>
            <origin rpy="0 1.57079632679 0" xyz="-0.07 0 0"/>
            <geometry>
                <cylinder length="0.14" radius="0.05"/>
            </geometry>
        </collision>
        <inertial>
            <origin rpy="0 0 0" xyz="-0.063 7e-05 0.00046"/>
            <mass value="2.04"/>
            <inertia ixx="0.001053013" ixy="4.527e-05" ixz="8.855e-05" iyy="0.001805509" iyz="9.909e-05" izz="0.001765827"/>
        </inertial>
    </link>
    <!-- joint Drive output -->
    <joint name="LH_KFE" type="revolute">
        <parent link="LH_KFE"/>
        <child link="LH_SHANK"/>
        <origin rpy="0 0 0" xyz="0 0 0"/>
        <axis xyz="1 0 0"/>
        <limit effort="80.0" lower="-9.42477796077" upper="9.42477796077" velocity="7.5"/>
        <dynamics damping="0.0" friction="0.0"/>
    </joint>
    <!-- Drive output link -->
    <link name="LH_SHANK">
        <inertial>
            <origin rpy="0 0 0" xyz="0 0 0"/>
            <mass value="0.001"/>
            <inertia ixx="0.000001" ixy="0.0" ixz="0.0" iyy="0.000001" iyz="0.0" izz="0.000001"/>
        </inertial>
    </link>
    <!-- joint KFE shank -->
    <joint name="LH_shank_LH_shank_fixed" type="fixed">
        <parent link="LH_SHANK"/>
        <child link="LH_shank_fixed"/>
        <origin rpy="0 0 -1.57079632679" xyz="0 0 0"/>
    </joint>
    <!-- Shank link -->
    <link name="LH_shank_fixed">
        <visual>
            <origin rpy="0 0 -3.14159265359" xyz="0 0 0"/>
            <geometry>
                <mesh filename="package://anymal_c_simple_description/meshes/shank_r.dae" scale="1.0 1.0 1.0"/>
            </geometry>
        </visual>
        <!-- Shank collision -->
        <collision>
            <origin rpy="1.57079632679 0 0" xyz="0 0.02 0"/>
            <geometry>
                <cylinder length="0.04" radius="0.06"/>
            </geometry>
        </collision>
        <collision>
            <origin rpy="1.57079632679 0 0" xyz="-0.057499 0.02 0"/>
            <geometry>
                <box size="0.114998 0.0675 0.04"/>
            </geometry>
        </collision>
        <inertial>
            <origin rpy="0 0 0" xyz="-0.03463 0.00688 0.00098"/>
            <mass value="0.33742"/>
            <inertia ixx="0.00032748005" ixy="-2.142561e-05" ixz="-1.33942e-05" iyy="0.00110974122" iyz="7.601e-08" izz="0.00089388521"/>
        </inertial>
    </link>
    <!-- Leg configurations: xx (knees bent inwards), xo (knees bent backwards) -->
    <!-- joint shank foot -->
    <joint name="LH_shank_fixed_LH_FOOT" type="fixed">
        <parent link="LH_shank_fixed"/>
        <child link="LH_FOOT"/>
        <origin rpy="0 0 0" xyz="-0.08795 0.01305 -0.33797"/>
    </joint>
    <!-- Foot link -->
    <link name="LH_FOOT">
        <visual>
            <origin rpy="0 0 -2.35619449019" xyz="0 0 0"/>
            <geometry>
                <mesh filename="package://anymal_c_simple_description/meshes/foot.dae" scale="1.0 1.0 1.0"/>
            </geometry>
        </visual>
        <!-- Adapter collision -->
        <collision>
            <origin rpy="0 0 0" xyz="0 0 0.168985"/>
            <geometry>
                <cylinder length="0.282504" radius="0.0175"/>
            </geometry>
        </collision>
        <!-- Foot collision -->
        <collision>
            <origin xyz="0 0 0.0225"/>
            <geometry>
                <sphere radius="0.03"/>
            </geometry>
        </collision>
        <inertial>
            <origin rpy="0 0 0" xyz="-0.00948 -0.00948 0.1468"/>
            <mass value="0.25"/>
            <inertia ixx="0.00317174097" ixy="-2.63048e-06" ixz="-6.815581e-05" iyy="0.00317174092" iyz="6.815583e-05" izz="8.319196e-05"/>
        </inertial>
    </link>
    <!-- joint base HAA -->
    <joint name="base_RH_HAA" type="fixed">
        <parent link="base"/>
        <child link="RH_HAA"/>
        <origin rpy="2.61799387799 0 -3.14159265359" xyz="-0.2999 -0.104 0.0"/>
    </joint>
    <!-- Drive link -->
    <link name="RH_HAA">
        <visual>
            <origin rpy="0 0 0" xyz="0 0 0"/>
            <geometry>
                <mesh filename="package://anymal_c_simple_description/meshes/drive.dae" scale="1.0 1.0 1.0"/>
            </geometry>
        </visual>
        <inertial>
            <origin rpy="0 0 0" xyz="-0.063 7e-05 0.00046"/>
            <mass value="2.04"/>
            <inertia ixx="0.001053013" ixy="4.527e-05" ixz="8.855e-05" iyy="0.001805509" iyz="9.909e-05" izz="0.001765827"/>
        </inertial>
    </link>
    <!-- joint Drive output -->
    <joint name="RH_HAA" type="revolute">
        <parent link="RH_HAA"/>
        <child link="RH_HIP"/>
        <origin rpy="0 0 0" xyz="0 0 0"/>
        <axis xyz="-1 0 0"/>
        <limit effort="80.0" lower="-0.49" upper="0.72" velocity="7.5"/>
        <dynamics damping="0.0" friction="0.0"/>
    </joint>
    <!-- Drive output link -->
    <link name="RH_HIP">
        <inertial>
            <origin rpy="0 0 0" xyz="0 0 0"/>
            <mass value="0.001"/>
            <inertia ixx="0.000001" ixy="0.0" ixz="0.0" iyy="0.000001" iyz="0.0" izz="0.000001"/>
        </inertial>
    </link>
    <!-- joint HAA hip -->
    <joint name="RH_HIP_RH_hip_fixed" type="fixed">
        <parent link="RH_HIP"/>
        <child link="RH_hip_fixed"/>
        <origin rpy="2.61799387799 0 -3.14159265359" xyz="0 0 0"/>
    </joint>
    <!-- Hip link -->
    <link name="RH_hip_fixed">
        <visual>
            <origin rpy="0 0 -3.14159265359" xyz="0 0 0"/>
            <geometry>
                <mesh filename="package://anymal_c_simple_description/meshes/hip_l.dae" scale="1.0 1.0 1.0"/>
            </geometry>
        </visual>
        <inertial>
            <origin rpy="0 0 0" xyz="-0.048 -0.008 -0.003"/>
            <mass value="0.74"/>
            <inertia ixx="0.001393106" ixy="8.4012e-05" ixz="-2.3378e-05" iyy="0.003798579" iyz="-7.1319e-05" izz="0.003897509"/>
        </inertial>
    </link>
    <!-- joint hip HFE -->
    <joint name="RH_hip_fixed_RH_HFE" type="fixed">
        <parent link="RH_hip_fixed"/>
        <child link="RH_HFE"/>
        <origin rpy="0 0 -1.57079632679" xyz="-0.0599 -0.08381 0.0"/>
    </joint>
    <!-- Drive link -->
    <link name="RH_HFE">
        <visual>
            <origin rpy="0 0 0" xyz="0 0 0"/>
            <geometry>
                <mesh filename="package://anymal_c_simple_description/meshes/drive.dae" scale="1.0 1.0 1.0"/>
            </geometry>
        </visual>
        <collision>
            <origin rpy="0 1.57079632679 0" xyz="-0.07 0 0"/>
            <geometry>
                <cylinder length="0.14" radius="0.05"/>
            </geometry>
        </collision>
        <inertial>
            <origin rpy="0 0 0" xyz="-0.063 7e-05 0.00046"/>
            <mass value="2.04"/>
            <inertia ixx="0.001053013" ixy="4.527e-05" ixz="8.855e-05" iyy="0.001805509" iyz="9.909e-05" izz="0.001765827"/>
        </inertial>
    </link>
    <!-- joint Drive output -->
    <joint name="RH_HFE" type="revolute">
        <parent link="RH_HFE"/>
        <child link="RH_THIGH"/>
        <origin rpy="0 0 0" xyz="0 0 0"/>
        <axis xyz="-1 0 0"/>
        <limit effort="80.0" lower="-9.42477796077" upper="9.42477796077" velocity="7.5"/>
        <dynamics damping="0.0" friction="0.0"/>
    </joint>
    <!-- Drive output link -->
    <link name="RH_THIGH">
        <inertial>
            <origin rpy="0 0 0" xyz="0 0 0"/>
            <mass value="0.001"/>
            <inertia ixx="0.000001" ixy="0.0" ixz="0.0" iyy="0.000001" iyz="0.0" izz="0.000001"/>
        </inertial>
    </link>
    <!-- joint HFE thigh -->
    <joint name="RH_THIGH_RH_thigh_fixed" type="fixed">
        <parent link="RH_THIGH"/>
        <child link="RH_thigh_fixed"/>
        <origin rpy="0 0 1.57079632679" xyz="0 0 0"/>
    </joint>
    <!-- Thigh link -->
    <link name="RH_thigh_fixed">
        <visual>
            <origin rpy="0 0 -3.14159265359" xyz="0 0 0"/>
            <geometry>
                <mesh filename="package://anymal_c_simple_description/meshes/thigh.dae" scale="1.0 1.0 1.0"/>
            </geometry>
        </visual>
        <!-- Thigh collision -->
        <collision>
            <origin rpy="1.57079632679 0 0" xyz="0 -0.04 0"/>
            <geometry>
                <cylinder length="0.08" radius="0.065"/>
            </geometry>
        </collision>
        <collision>
            <origin rpy="0 0 0" xyz="0 -0.03 -0.1413135"/>
            <geometry>
                <box size="0.075 0.06 0.282627"/>
            </geometry>
        </collision>
        <inertial>
            <origin rpy="0 0 0" xyz="-0.0 -0.018 -0.169"/>
            <mass value="1.03"/>
            <inertia ixx="0.018644469" ixy="5.2e-08" ixz="-1.0157e-05" iyy="0.019312599" iyz="-0.002520077" izz="0.002838361"/>
        </inertial>
    </link>
    <!-- joint thigh KFE -->
    <joint name="RH_thigh_fixed_RH_KFE" type="fixed">
        <parent link="RH_thigh_fixed"/>
        <child link="RH_KFE"/>
        <origin rpy="0 0 -1.57079632679" xyz="-0.0 -0.1003 -0.285"/>
    </joint>
    <!-- Drive link -->
    <link name="RH_KFE">
        <visual>
            <origin rpy="0 0 0" xyz="0 0 0"/>
            <geometry>
                <mesh filename="package://anymal_c_simple_description/meshes/drive.dae" scale="1.0 1.0 1.0"/>
            </geometry>
        </visual>
        <collision>
            <origin rpy="0 1.57079632679 0" xyz="-0.07 0 0"/>
            <geometry>
                <cylinder length="0.14" radius="0.05"/>
            </geometry>
        </collision>
        <inertial>
            <origin rpy="0 0 0" xyz="-0.063 7e-05 0.00046"/>
            <mass value="2.04"/>
            <inertia ixx="0.001053013" ixy="4.527e-05" ixz="8.855e-05" iyy="0.001805509" iyz="9.909e-05" izz="0.001765827"/>
        </inertial>
    </link>
    <!-- joint Drive output -->
    <joint name="RH_KFE" type="revolute">
        <parent link="RH_KFE"/>
        <child link="RH_SHANK"/>
        <origin rpy="0 0 0" xyz="0 0 0"/>
        <axis xyz="-1 0 0"/>
        <limit effort="80.0" lower="-9.42477796077" upper="9.42477796077" velocity="7.5"/>
        <dynamics damping="0.0" friction="0.0"/>
    </joint>
    <!-- Drive output link -->
    <link name="RH_SHANK">
        <inertial>
            <origin rpy="0 0 0" xyz="0 0 0"/>
            <mass value="0.001"/>
            <inertia ixx="0.000001" ixy="0.0" ixz="0.0" iyy="0.000001" iyz="0.0" izz="0.000001"/>
        </inertial>
    </link>
    <!-- joint KFE shank -->
    <joint name="RH_shank_RH_shank_fixed" type="fixed">
        <parent link="RH_SHANK"/>
        <child link="RH_shank_fixed"/>
        <origin rpy="0 0 1.57079632679" xyz="0 0 0"/>
    </joint>
    <!-- Shank link -->
    <link name="RH_shank_fixed">
        <visual>
            <origin rpy="0 0 -3.14159265359" xyz="0 0 0"/>
            <geometry>
                <mesh filename="package://anymal_c_simple_description/meshes/shank_l.dae" scale="1.0 1.0 1.0"/>
            </geometry>
        </visual>
        <!-- Shank collision -->
        <collision>
            <origin rpy="1.57079632679 0 0" xyz="0 -0.02 0"/>
            <geometry>
                <cylinder length="0.04" radius="0.06"/>
            </geometry>
        </collision>
        <collision>
            <origin rpy="1.57079632679 0 0" xyz="-0.057499 -0.02 0"/>
            <geometry>
                <box size="0.114998 0.0675 0.04"/>
            </geometry>
        </collision>
        <inertial>
            <origin rpy="0 0 0" xyz="-0.03463 -0.00688 0.00098"/>
            <mass value="0.33742"/>
            <inertia ixx="0.00032748005" ixy="2.142561e-05" ixz="-1.33942e-05" iyy="0.00110974122" iyz="-7.601e-08" izz="0.00089388521"/>
        </inertial>
    </link>
    <!-- Leg configurations: xx (knees bent inwards), xo (knees bent backwards) -->
    <!-- joint shank foot -->
    <joint name="RH_shank_fixed_RH_FOOT" type="fixed">
        <parent link="RH_shank_fixed"/>
        <child link="RH_FOOT"/>
        <origin rpy="0 0 0" xyz="-0.08795 -0.01305 -0.33797"/>
    </joint>
    <!-- Foot link -->
    <link name="RH_FOOT">
        <visual>
            <origin rpy="0 0 -3.92699081699" xyz="0 0 0"/>
            <geometry>
                <mesh filename="package://anymal_c_simple_description/meshes/foot.dae" scale="1.0 1.0 1.0"/>
            </geometry>
        </visual>
        <!-- Adapter collision -->
        <collision>
            <origin rpy="0 0 0" xyz="0 0 0.168985"/>
            <geometry>
                <cylinder length="0.282504" radius="0.0175"/>
            </geometry>
        </collision>
        <!-- Foot collision -->
        <collision>
            <origin xyz="0 0 0.0225"/>
            <geometry>
                <sphere radius="0.03"/>
            </geometry>
        </collision>
        <inertial>
            <origin rpy="0 0 0" xyz="-0.00948 0.00948 0.1468"/>
            <mass value="0.25"/>
            <inertia ixx="0.00317174097" ixy="2.63048e-06" ixz="-6.815581e-05" iyy="0.00317174092" iyz="-6.815583e-05" izz="8.319196e-05"/>
        </inertial>
    </link>
    <!-- Fixed joint base hatch -->
    <joint name="base_hatch" type="fixed">
        <parent link="base"/>
        <child link="hatch"/>
        <origin rpy="0 0 0" xyz="0.0 0.0 0.0"/>
    </joint>
    <!-- Hatch link -->
    <link name="hatch">
        <visual>
            <origin rpy="0 0 0" xyz="0.116 0 0.073"/>
            <geometry>
                <mesh filename="package://anymal_c_simple_description/meshes/hatch.dae" scale="1.0 1.0 1.0"/>
            </geometry>
        </visual>
        <inertial>
            <origin rpy="0 0 0" xyz="0.116 0.0 0.0758"/>
            <mass value="0.142"/>
            <inertia ixx="0.001" ixy="0.001" ixz="0.001" iyy="0.001" iyz="0.001" izz="0.001"/>
        </inertial>
    </link>
    <joint name="base_to_base_subt" type="fixed">
      <parent link="base"/>
      <child link="base_subt"/>
      <origin rpy="0 0 3.1415926535" xyz="0 0 0"/>
    </joint>
    <!-- Base Subt link -->
    <link name="base_subt"/>
</robot>
