<sdf version="1.6">
  <model name="cerberus_anymal_b_sensor_config_1">
    <link name="base">
      <pose>0 0 0 0 -0 0</pose>
      <gravity>1</gravity>
      <velocity_decay/>
      <inertial>
        <pose>-0.001799 -0.001412 0.050337 0 -0 0</pose>
        <mass>23.32578</mass>
        <inertia>
          <ixx>0.30242793077</ixx>
          <ixy>-0.00184980716</ixy>
          <ixz>-0.00398797474</ixz>
          <iyy>0.88931002497</iyy>
          <iyz>-0.00192099149</iyz>
          <izz>0.86742722698</izz>
        </inertia>
      </inertial>
      <collision name="base_collision">
        <pose>0 0 0.08 0 -0 0</pose>
        <geometry>
          <box>
            <size>0.531 0.27 0.24</size>
          </box>
        </geometry>
      </collision>
      <collision name="base_collision_1">
        <pose>0.227 0.116 0 3.14159 1.57079 3.14159</pose>
        <geometry>
          <cylinder>
            <length>0.1</length>
            <radius>0.05</radius>
          </cylinder>
        </geometry>
      </collision>
      <collision name="base_collision_2">
        <pose>0.227 -0.116 0 3.14159 1.57079 3.14159</pose>
        <geometry>
          <cylinder>
            <length>0.1</length>
            <radius>0.05</radius>
          </cylinder>
        </geometry>
      </collision>
      <collision name="base_collision_3">
        <pose>-0.227 0.116 0 3.14159 1.57079 3.14159</pose>
        <geometry>
          <cylinder>
            <length>0.1</length>
            <radius>0.05</radius>
          </cylinder>
        </geometry>
      </collision>
      <collision name="base_collision_4">
        <pose>-0.227 -0.116 0 3.14159 1.57079 3.14159</pose>
        <geometry>
          <cylinder>
            <length>0.1</length>
            <radius>0.05</radius>
          </cylinder>
        </geometry>
      </collision>
      <collision name="base_collision_5">
        <pose>0.2155 0 -0.09 0 -0 0</pose>
        <geometry>
          <box>
            <size>0.1 0.1 0.07</size>
          </box>
        </geometry>
      </collision>
      <collision name="base_collision_6">
        <pose>-0.2155 0 -0.09 0 -0 0</pose>
        <geometry>
          <box>
            <size>0.1 0.1 0.07</size>
          </box>
        </geometry>
      </collision>
      <collision name="base_collision_7">
        <pose>0 0 -0.09 0 -0 0</pose>
        <geometry>
          <box>
            <size>0.531 0.02 0.07</size>
          </box>
        </geometry>
      </collision>
      <collision name="base_fixed_joint_lump__jetson_case_collision_8">
        <pose>-0.245 0 0.171 0 0 -1.5708</pose>
        <geometry>
          <box>
            <size>0.14 0.15 0.1</size>
          </box>
        </geometry>
      </collision>
      <collision name="base_fixed_joint_lump__sensor_head_collision_9">
        <pose>0.3482 0 0.131624 0 -0 0</pose>
        <geometry>
          <box>
            <size>0.14 0.15 0.1</size>
          </box>
        </geometry>
      </collision>
      <collision name="base_fixed_joint_lump__downward_realsense_camera_collision_10">
        <pose>0.405017 -0.000105 0.06461 -0.009501 0.382227 0</pose>
        <geometry>
          <box>
            <size>0.025 0.089 0.025</size>
          </box>
        </geometry>
      </collision>
      <collision name="base_fixed_joint_lump__velodyne_axis_aligned_collision_11">
        <pose>0.27 0 0.2676 0 -0 0</pose>
        <geometry>
          <cylinder>
            <length>0.0717</length>
            <radius>0.0516</radius>
          </cylinder>
        </geometry>
      </collision>
      <visual name="base_visual">
        <pose>0 0 0 0 -0 0</pose>
        <geometry>
          <mesh>
            <scale>0.001 0.001 0.001</scale>
            <uri>meshes/anymal_base.dae</uri>
          </mesh>
        </geometry>
      </visual>
      <visual name="base_fixed_joint_lump__jetson_case_visual_1">
        <pose>-0.245 0 0.201 0 0 -1.5708</pose>
        <geometry>
          <mesh>
            <scale>0.001 0.001 0.001</scale>
            <uri>meshes/darpa_jetson_back.stl</uri>
          </mesh>
        </geometry>
        <material>
          <ambient>0.8 0.8 0.8 1</ambient>
          <diffuse>0.45 0.45 0.45 1</diffuse>
          <specular>0.8 0.8 0.8 1.0</specular>
        </material>
      </visual>
      <visual name="base_fixed_joint_lump__sensor_head_visual_2">
        <pose>0.3482 0 0.161624 0 -0 0</pose>
        <geometry>
          <mesh>
            <scale>0.001 0.001 0.001</scale>
            <uri>meshes/darpa_head_1.stl</uri>
          </mesh>
        </geometry>
        <material>
          <ambient>0.8 0.8 0.8 1</ambient>
          <diffuse>0.45 0.45 0.45 1</diffuse>
          <specular>0.8 0.8 0.8 1.0</specular>
        </material>
      </visual>
      <visual name="base_fixed_joint_lump__downward_realsense_camera_visual_3">
        <pose>0.387757 -0.000224 0.057675 -0.009501 0.382227 0</pose>
        <geometry>
          <mesh>
            <scale>0.001 0.001 0.001</scale>
            <uri>meshes/realsense_d435.dae</uri>
          </mesh>
        </geometry>
      </visual>
      <visual name="base_fixed_joint_lump__velodyne_axis_aligned_visual_4">
        <pose>0.27 0 0.2299 0 -0 0</pose>
        <geometry>
          <mesh>
            <scale>1 1 1</scale>
            <uri>meshes/VLP16_base_1.dae</uri>
          </mesh>
        </geometry>
      </visual>
      <visual name="base_fixed_joint_lump__velodyne_axis_aligned_visual_5">
        <pose>0.27 0 0.2299 0 -0 0</pose>
        <geometry>
          <mesh>
            <scale>1 1 1</scale>
            <uri>meshes/VLP16_base_2.dae</uri>
          </mesh>
        </geometry>
      </visual>
      <visual name="base_fixed_joint_lump__velodyne_visual_6">
        <pose>0.27 0 0.2299 0 -0 0</pose>
        <geometry>
          <mesh>
            <scale>1 1 1</scale>
            <uri>meshes/VLP16_scan.dae</uri>
          </mesh>
        </geometry>
      </visual>
      <visual name="base_fixed_joint_lump__light_back_left_visual_7">
        <pose>-0.206 0.12 0.14 3.14159 1.57079 1.5692</pose>
        <geometry>
          <cylinder>
            <length>0.005</length>
            <radius>0.019</radius>
          </cylinder>
        </geometry>
      </visual>
      <visual name="base_fixed_joint_lump__light_back_right_visual_8">
        <pose>-0.206 -0.12 0.14 3.14159 1.57079 -1.57239</pose>
        <geometry>
          <cylinder>
            <length>0.005</length>
            <radius>0.019</radius>
          </cylinder>
        </geometry>
      </visual>
      <visual name="base_fixed_joint_lump__light_front_left_visual_9">
        <pose>0.305 0.045 0.33 -3.14159 1.57079 0.436332</pose>
        <geometry>
          <cylinder>
            <length>0.005</length>
            <radius>0.019</radius>
          </cylinder>
        </geometry>
      </visual>
      <visual name="base_fixed_joint_lump__light_front_right_visual_10">
        <pose>0.305 -0.045 0.33 3.14159 1.57079 -0.436332</pose>
        <geometry>
          <cylinder>
            <length>0.005</length>
            <radius>0.019</radius>
          </cylinder>
        </geometry>
      </visual>

      <sensor name="imu_sensor" type="imu">
        <always_on>1</always_on>
        <update_rate>400</update_rate>
        <imu>
                    <angular_velocity>
                        <x>
                            <noise type="gaussian">
                                <mean>0</mean>
                                <stddev>0.009</stddev>
                                <bias_mean>0.00075</bias_mean>
                                <bias_stddev>0.005</bias_stddev>
                                <dynamic_bias_stddev>0.00002</dynamic_bias_stddev>
                                <dynamic_bias_correlation_time>400.0</dynamic_bias_correlation_time>
                                <precision>0.00025</precision>
                            </noise>
                        </x>
                        <y>
                            <noise type="gaussian">
                                <mean>0</mean>
                                <stddev>0.009</stddev>
                                <bias_mean>0.00075</bias_mean>
                                <bias_stddev>0.005</bias_stddev>
                                <dynamic_bias_stddev>0.00002</dynamic_bias_stddev>
                                <dynamic_bias_correlation_time>400.0</dynamic_bias_correlation_time>
                                <precision>0.00025</precision>
                            </noise>
                        </y>
                        <z>
                            <noise type="gaussian">
                                <mean>0</mean>
                                <stddev>0.009</stddev>
                                <bias_mean>0.00075</bias_mean>
                                <bias_stddev>0.005</bias_stddev>
                                <dynamic_bias_stddev>0.00002</dynamic_bias_stddev>
                                <dynamic_bias_correlation_time>400.0</dynamic_bias_correlation_time>
                                <precision>0.00025</precision>
                            </noise>
                        </z>
                    </angular_velocity>
                    <linear_acceleration>
                        <x>
                            <noise type="gaussian">
                                <mean>0</mean>
                                <stddev>0.021</stddev>
                                <bias_mean>0.05</bias_mean>
                                <bias_stddev>0.0075</bias_stddev>
                                <dynamic_bias_stddev>0.000375</dynamic_bias_stddev>
                                <dynamic_bias_correlation_time>175.0</dynamic_bias_correlation_time>
                                <precision>0.005</precision>
                            </noise>
                        </x>
                        <y>
                            <noise type="gaussian">
                                <mean>0</mean>
                                <stddev>0.021</stddev>
                                <bias_mean>0.05</bias_mean>
                                <bias_stddev>0.0075</bias_stddev>
                                <dynamic_bias_stddev>0.000375</dynamic_bias_stddev>
                                <dynamic_bias_correlation_time>175.0</dynamic_bias_correlation_time>
                                <precision>0.005</precision>
                            </noise>
                        </y>
                        <z>
                            <noise type="gaussian">
                                <mean>0</mean>
                                <stddev>0.021</stddev>
                                <bias_mean>0.05</bias_mean>
                                <bias_stddev>0.0075</bias_stddev>
                                <dynamic_bias_stddev>0.000375</dynamic_bias_stddev>
                                <dynamic_bias_correlation_time>175.0</dynamic_bias_correlation_time>
                                <precision>0.005</precision>
                            </noise>
                        </z>
                    </linear_acceleration>
                </imu>
      </sensor>

      <sensor name="front_laser" type="gpu_lidar">
        <visualize>0</visualize>
        <update_rate>10</update_rate>
        <lidar>
          <scan>
            <horizontal>
              <samples>1800</samples>
              <resolution>1</resolution>
              <min_angle>-3.14159</min_angle>
              <max_angle>3.14159</max_angle>
            </horizontal>
            <vertical>
              <samples>16</samples>
              <resolution>1</resolution>
              <min_angle>-0.261799</min_angle>
              <max_angle>0.261799</max_angle>
            </vertical>
          </scan>
          <range>
            <min>0.05</min>
            <max>100</max>
            <resolution>0.01</resolution>
          </range>
          <noise>
            <type>gaussian</type>
            <mean>0</mean>
            <stddev>0.01</stddev>
          </noise>
        </lidar>
        <pose frame="">0.27 0 0.2676 0 -0 0</pose>
      </sensor>

      <sensor name="downward_realsense" type="rgbd_camera">
        <camera name="camera_down">
            <horizontal_fov>1.0472</horizontal_fov>
            <lens>
                <intrinsics>
                    <!-- fx = fy = width / ( 2 * tan (hfov / 2 ) ) -->
                    <fx>277.1</fx>
                    <fy>277.1</fy>
                    <!-- cx = ( width + 1 ) / 2 -->
                    <cx>160.5</cx>
                    <!-- cy = ( height + 1 ) / 2 -->
                    <cy>120.5</cy>
                    <s>0</s>
                </intrinsics>
            </lens>
            <distortion>
                <k1>0.0</k1>
                <k2>0.0</k2>
                <k3>0.0</k3>
                <p1>0.0</p1>
                <p2>0.0</p2>
                <center>0.5 0.5</center>
            </distortion>
            <image>
                <width>320</width>
                <height>240</height>
                <format>R8G8B8</format>
            </image>
            <clip>
                <near>0.01</near>
                <far>300</far>
            </clip>
            <depth_camera>
              <clip>
                <near>0.1</near>
                <far>10</far>
              </clip>
            </depth_camera>
            <noise>
                <type>gaussian</type>
                <mean>0</mean>
                <stddev>0.007</stddev>
            </noise>
        </camera>
        <always_on>1</always_on>
        <update_rate>10</update_rate>
        <visualize>0</visualize>
        <pose frame="">0.388757 -0.000224 0.0576 -0.009501 0.38227 0</pose>
      </sensor>

      <sensor name="camera_front" type="camera">
          <pose>0.42 0.02 0.161624 0 0 0</pose>
          <always_on>1</always_on>
          <update_rate>20</update_rate>
          <camera name="camera_front">
              <horizontal_fov>2</horizontal_fov>
              <lens>
                <intrinsics>
                  <fx>1108.952913</fx>
                  <fy>1110.658360</fy>
                  <cx>729.533992</cx>
                  <cy>544.985715</cy>
                  <s>1</s>
                </intrinsics>
              </lens>
              <distortion>
                  <k1>0.0</k1>
                  <k2>0.0</k2>
                  <k3>0.0</k3>
                  <p1>0.0</p1>
                  <p2>0.0</p2>
                  <center>0.5 0.5</center>
              </distortion>
              <image>
                <width>1440</width>
                <height>1080</height>
                <format>R8G8B8</format>
              </image>
              <clip>
                  <near>0.02</near>
                  <far>100</far>
              </clip>
              <noise>
                <type>gaussian</type>
                <mean>0</mean>
                <stddev>0.007</stddev>
              </noise>
          </camera>
      </sensor>

      <sensor name="camera_back_right" type="camera">
          <pose>-0.311374 -0.152675 0.136916 0 0 -1.5707963267948966</pose>
          <always_on>1</always_on>
          <update_rate>20</update_rate>
          <camera name="camera_back_right">
            <horizontal_fov>2</horizontal_fov>
            <lens>
              <intrinsics>
                <fx>1108.952913</fx>
                <fy>1110.658360</fy>
                <cx>729.533992</cx>
                <cy>544.985715</cy>
                <s>1</s>
              </intrinsics>
            </lens>
            <distortion>
                <k1>0.0</k1>
                <k2>0.0</k2>
                <k3>0.0</k3>
                <p1>0.0</p1>
                <p2>0.0</p2>
                <center>0.5 0.5</center>
            </distortion>
            <image>
              <width>1440</width>
              <height>1080</height>
              <format>R8G8B8</format>
            </image>
            <clip>
                <near>0.02</near>
                <far>100</far>
            </clip>
            <noise>
              <type>gaussian</type>
              <mean>0</mean>
              <stddev>0.007</stddev>
            </noise>
          </camera>
      </sensor>

      <sensor name="camera_back_left" type="camera">
          <pose>-0.310417 0.158145 0.139186 0 0 1.5707963267948966</pose>
          <always_on>1</always_on>
          <update_rate>20</update_rate>
          <camera name="camera_back_left">
            <horizontal_fov>2</horizontal_fov>
            <lens>
              <intrinsics>
                <fx>1108.952913</fx>
                <fy>1110.658360</fy>
                <cx>729.533992</cx>
                <cy>544.985715</cy>
                <s>1</s>
              </intrinsics>
            </lens>
            <distortion>
                <k1>0.0</k1>
                <k2>0.0</k2>
                <k3>0.0</k3>
                <p1>0.0</p1>
                <p2>0.0</p2>
                <center>0.5 0.5</center>
            </distortion>
            <image>
              <width>1440</width>
              <height>1080</height>
              <format>R8G8B8</format>
            </image>
            <clip>
                <near>0.02</near>
                <far>100</far>
            </clip>
            <noise>
              <type>gaussian</type>
              <mean>0</mean>
              <stddev>0.007</stddev>
            </noise>
          </camera>
      </sensor>

      <light name="light_front_right" type="spot">
        <pose frame="">0.305 -0.045 0.33 3.14159 1.56859 -0.436332</pose>
        <attenuation>
          <range>50</range>
          <linear>0</linear>
          <constant>0.1</constant>
          <quadratic>0.0025</quadratic>
        </attenuation>
        <diffuse>0.8 0.8 0.5 1</diffuse>
        <specular>0.8 0.8 0.5 1</specular>
        <spot>
          <inner_angle>1.2</inner_angle>
          <outer_angle>1.3</outer_angle>
          <falloff>1</falloff>
        </spot>
        <direction>0 0 -1</direction>
      </light>

      <light name="light_front_left" type="spot">
        <pose frame="">0.305 0.045 0.33 3.14159 1.56859 0.436332</pose>
        <attenuation>
          <range>50</range>
          <linear>0</linear>
          <constant>0.1</constant>
          <quadratic>0.0025</quadratic>
        </attenuation>
        <diffuse>0.8 0.8 0.5 1</diffuse>
        <specular>0.8 0.8 0.5 1</specular>
        <spot>
          <inner_angle>1.2</inner_angle>
          <outer_angle>1.3</outer_angle>
          <falloff>1</falloff>
        </spot>
        <direction>0 0 -1</direction>
      </light>

      <light name="light_back_right" type="spot">
        <pose frame="">-0.206 -0.12 0.14 3.14159 1.56859 -1.5707963267948966</pose>
        <attenuation>
          <range>50</range>
          <linear>0</linear>
          <constant>0.1</constant>
          <quadratic>0.0025</quadratic>
        </attenuation>
        <diffuse>0.8 0.8 0.5 1</diffuse>
        <specular>0.8 0.8 0.5 1</specular>
        <spot>
          <inner_angle>1.2</inner_angle>
          <outer_angle>1.3</outer_angle>
          <falloff>1</falloff>
        </spot>
        <direction>0 0 -1</direction>
      </light>

      <light name="light_back_left" type="spot">
        <pose frame="">-0.206 0.12 0.14 3.14159 1.56859 1.5707963267948966</pose>
        <attenuation>
          <range>50</range>
          <linear>0</linear>
          <constant>0.1</constant>
          <quadratic>0.0025</quadratic>
        </attenuation>
        <diffuse>0.8 0.8 0.5 1</diffuse>
        <specular>0.8 0.8 0.5 1</specular>
        <spot>
          <inner_angle>1.2</inner_angle>
          <outer_angle>1.3</outer_angle>
          <falloff>1</falloff>
        </spot>
        <direction>0 0 -1</direction>
      </light>
    </link>
    <link name="LF_HIP">
      <pose>0.277 0.116 0 0 -0 0</pose>
      <gravity>1</gravity>
      <velocity_decay/>
      <inertial>
        <pose>0.064516 -0.003787 -0.000152 0 -0 0</pose>
        <mass>1.42462</mass>
        <inertia>
          <ixx>0.00243023</ixx>
          <ixy>-1.53024e-05</ixy>
          <ixz>-2.18191e-05</ixz>
          <iyy>0.00230257</iyy>
          <iyz>2.6473e-05</iyz>
          <izz>0.00198068</izz>
        </inertia>
      </inertial>
      <collision name="LF_HIP_collision">
        <pose>0.0635 -0.009 0 1.5708 -0 0</pose>
        <geometry>
          <cylinder>
            <length>0.1</length>
            <radius>0.08</radius>
          </cylinder>
        </geometry>
      </collision>
      <collision name="LF_HIP_collision_1">
        <pose>0.0635 -0.074 0 1.5708 -0 0</pose>
        <geometry>
          <cylinder>
            <length>0.03</length>
            <radius>0.045</radius>
          </cylinder>
        </geometry>
      </collision>
      <visual name="LF_HIP_visual">
        <pose>0 0 0 0 -0 0</pose>
        <geometry>
          <mesh>
            <scale>0.001 0.001 0.001</scale>
            <uri>meshes/anymal_hip_l.dae</uri>
          </mesh>
        </geometry>
      </visual>
    </link>
    <joint name="LF_HAA" type="revolute">
      <child>LF_HIP</child>
      <parent>base</parent>
      <axis>
        <xyz>1 0 0</xyz>
        <limit>
          <lower>-9.42</lower>
          <upper>9.42</upper>
          <effort>80</effort>
          <velocity>15</velocity>
        </limit>
        <dynamics>
          <damping>0</damping>
          <friction>0</friction>
          <spring_reference>0</spring_reference>
          <spring_stiffness>0</spring_stiffness>
        </dynamics>
        <use_parent_model_frame>0</use_parent_model_frame>
      </axis>
    </joint>
    <link name="LF_THIGH">
      <pose>0.3405 0.157 0 0 -0 0</pose>
      <gravity>1</gravity>
      <velocity_decay/>
      <inertial>
        <pose>-0.003898 0.054227 -0.214583 0 -0 0</pose>
        <mass>1.63498</mass>
        <inertia>
          <ixx>0.0120368</ixx>
          <ixy>6.76207e-05</ixy>
          <ixz>0.000287806</ixz>
          <iyy>0.0120644</iyy>
          <iyz>-0.0014061</iyz>
          <izz>0.00249423</izz>
        </inertia>
      </inertial>
      <collision name="LF_THIGH_collision">
        <pose>0 0.035 -0.125 0.145 -0 0</pose>
        <geometry>
          <box>
            <size>0.08 0.04 0.25</size>
          </box>
        </geometry>
      </collision>
      <collision name="LF_THIGH_collision_1">
        <pose>0 0.069 -0.25 1.5708 -0 0</pose>
        <geometry>
          <cylinder>
            <length>0.12</length>
            <radius>0.06</radius>
          </cylinder>
        </geometry>
      </collision>
      <collision name="LF_THIGH_collision_2">
        <pose>0 -0.005 0 1.7158 -0 0</pose>
        <geometry>
          <cylinder>
            <length>0.12</length>
            <radius>0.066</radius>
          </cylinder>
        </geometry>
      </collision>
      <visual name="LF_THIGH_visual">
        <pose>0 0 0 0 -0 0</pose>
        <geometry>
          <mesh>
            <scale>0.001 0.001 0.001</scale>
            <uri>meshes/anymal_thigh_l.dae</uri>
          </mesh>
        </geometry>
      </visual>
    </link>
    <joint name="LF_HFE" type="revolute">
      <child>LF_THIGH</child>
      <parent>LF_HIP</parent>
      <axis>
        <xyz>0 1 0</xyz>
        <limit>
          <lower>-9.42</lower>
          <upper>9.42</upper>
          <effort>80</effort>
          <velocity>15</velocity>
        </limit>
        <dynamics>
          <damping>0</damping>
          <friction>0</friction>
          <spring_reference>0</spring_reference>
          <spring_stiffness>0</spring_stiffness>
        </dynamics>
        <use_parent_model_frame>0</use_parent_model_frame>
      </axis>
    </joint>
    <link name="LF_SHANK">
      <pose>0.3405 0.266 -0.25 0 -0 0</pose>
      <gravity>1</gravity>
      <velocity_decay/>
      <inertial>
        <pose>0.058733 -0.010824 -0.098064 0 -0 0</pose>
        <mass>0.347375</mass>
        <inertia>
          <ixx>0.00685813</ixx>
          <ixy>3.2229e-05</ixy>
          <ixz>0.00142869</ixz>
          <iyy>0.00770431</iyy>
          <iyz>-0.000316237</iyz>
          <izz>0.00101942</izz>
        </inertia>
      </inertial>
      <collision name="LF_SHANK_collision">
        <pose>0.065 -0.015 0.01 3.14159 1.57079 3.14159</pose>
        <geometry>
          <box>
            <size>0.08 0.07 0.13</size>
          </box>
        </geometry>
      </collision>
      <collision name="LF_SHANK_fixed_joint_lump__LF_ADAPTER_collision_1">
        <pose>0.1 -0.02 -0.160625 0 -0 0</pose>
        <geometry>
          <cylinder>
            <length>0.32125</length>
            <radius>0.015</radius>
          </cylinder>
        </geometry>
      </collision>
      <collision name="LF_SHANK_fixed_joint_lump__LF_FOOT_collision_2">
        <pose>0.1 -0.02 -0.298 0 -0 0</pose>
        <geometry>
          <sphere>
            <radius>0.031</radius>
          </sphere>
        </geometry>
        <surface>
          <contact>
            <ode>
              <kp>1e+06</kp>
              <kd>100</kd>
            </ode>
          </contact>
          <friction>
            <ode>
              <mu>0.8</mu>
              <mu2>0.8</mu2>
            </ode>
          </friction>
        </surface>
      </collision>
      <visual name="LF_SHANK_visual">
        <pose>0 0 0 0 -0 0</pose>
        <geometry>
          <mesh>
            <scale>0.001 0.001 0.001</scale>
            <uri>meshes/anymal_shank_l.dae</uri>
          </mesh>
        </geometry>
      </visual>
      <visual name="LF_SHANK_fixed_joint_lump__LF_ADAPTER_visual_1">
        <pose>0.1 -0.02 0.032 0 -0 0</pose>
        <geometry>
          <mesh>
            <scale>0.001 0.001 0.001</scale>
            <uri>meshes/anymal_foot.dae</uri>
          </mesh>
        </geometry>
      </visual>
    </link>
    <joint name="LF_KFE" type="revolute">
      <child>LF_SHANK</child>
      <parent>LF_THIGH</parent>
      <axis>
        <xyz>0 1 0</xyz>
        <limit>
          <lower>-9.42</lower>
          <upper>9.42</upper>
          <effort>80</effort>
          <velocity>15</velocity>
        </limit>
        <dynamics>
          <damping>0</damping>
          <friction>0</friction>
          <spring_reference>0</spring_reference>
          <spring_stiffness>0</spring_stiffness>
        </dynamics>
        <use_parent_model_frame>0</use_parent_model_frame>
      </axis>
    </joint>
    <link name="LH_HIP">
      <pose>-0.277 0.116 0 0 -0 0</pose>
      <gravity>1</gravity>
      <velocity_decay/>
      <inertial>
        <pose>-0.064516 -0.003787 -0.000152 0 -0 0</pose>
        <mass>1.42462</mass>
        <inertia>
          <ixx>0.00243023</ixx>
          <ixy>1.53024e-05</ixy>
          <ixz>2.18191e-05</ixz>
          <iyy>0.00230257</iyy>
          <iyz>2.6473e-05</iyz>
          <izz>0.00198068</izz>
        </inertia>
      </inertial>
      <collision name="LH_HIP_collision">
        <pose>-0.0635 -0.009 0 -1.5708 0 0</pose>
        <geometry>
          <cylinder>
            <length>0.1</length>
            <radius>0.08</radius>
          </cylinder>
        </geometry>
      </collision>
      <collision name="LH_HIP_collision_1">
        <pose>-0.0635 -0.074 0 -1.5708 0 0</pose>
        <geometry>
          <cylinder>
            <length>0.03</length>
            <radius>0.045</radius>
          </cylinder>
        </geometry>
      </collision>
      <visual name="LH_HIP_visual">
        <pose>0 0 0 0 -0 3.14159</pose>
        <geometry>
          <mesh>
            <scale>0.001 0.001 0.001</scale>
            <uri>meshes/anymal_hip_r.dae</uri>
          </mesh>
        </geometry>
      </visual>
    </link>
    <joint name="LH_HAA" type="revolute">
      <child>LH_HIP</child>
      <parent>base</parent>
      <axis>
        <xyz>1 0 0</xyz>
        <limit>
          <lower>-9.42</lower>
          <upper>9.42</upper>
          <effort>80</effort>
          <velocity>15</velocity>
        </limit>
        <dynamics>
          <damping>0</damping>
          <friction>0</friction>
          <spring_reference>0</spring_reference>
          <spring_stiffness>0</spring_stiffness>
        </dynamics>
        <use_parent_model_frame>0</use_parent_model_frame>
      </axis>
    </joint>
    <link name="LH_THIGH">
      <pose>-0.3405 0.157 0 0 -0 0</pose>
      <gravity>1</gravity>
      <velocity_decay/>
      <inertial>
        <pose>0.003898 0.054227 -0.214583 0 -0 0</pose>
        <mass>1.63498</mass>
        <inertia>
          <ixx>0.0120368</ixx>
          <ixy>-6.76207e-05</ixy>
          <ixz>-0.000287806</ixz>
          <iyy>0.0120644</iyy>
          <iyz>-0.0014061</iyz>
          <izz>0.00249423</izz>
        </inertia>
      </inertial>
      <collision name="LH_THIGH_collision">
        <pose>0 0.035 -0.125 0.145 -0 0</pose>
        <geometry>
          <box>
            <size>0.08 0.04 0.25</size>
          </box>
        </geometry>
      </collision>
      <collision name="LH_THIGH_collision_1">
        <pose>0 0.069 -0.25 1.5708 -0 0</pose>
        <geometry>
          <cylinder>
            <length>0.12</length>
            <radius>0.06</radius>
          </cylinder>
        </geometry>
      </collision>
      <collision name="LH_THIGH_collision_2">
        <pose>0 -0.005 0 1.7158 -0 0</pose>
        <geometry>
          <cylinder>
            <length>0.12</length>
            <radius>0.066</radius>
          </cylinder>
        </geometry>
      </collision>
      <visual name="LH_THIGH_visual">
        <pose>0 0 0 0 -0 3.14159</pose>
        <geometry>
          <mesh>
            <scale>0.001 0.001 0.001</scale>
            <uri>meshes/anymal_thigh_r.dae</uri>
          </mesh>
        </geometry>
      </visual>
    </link>
    <joint name="LH_HFE" type="revolute">
      <child>LH_THIGH</child>
      <parent>LH_HIP</parent>
      <axis>
        <xyz>0 1 0</xyz>
        <limit>
          <lower>-9.42</lower>
          <upper>9.42</upper>
          <effort>80</effort>
          <velocity>15</velocity>
        </limit>
        <dynamics>
          <damping>0</damping>
          <friction>0</friction>
          <spring_reference>0</spring_reference>
          <spring_stiffness>0</spring_stiffness>
        </dynamics>
        <use_parent_model_frame>0</use_parent_model_frame>
      </axis>
    </joint>
    <link name="LH_SHANK">
      <pose>-0.3405 0.266 -0.25 0 -0 0</pose>
      <gravity>1</gravity>
      <velocity_decay/>
      <inertial>
        <pose>-0.058733 -0.010824 -0.098064 0 -0 0</pose>
        <mass>0.347375</mass>
        <inertia>
          <ixx>0.00685813</ixx>
          <ixy>-3.2229e-05</ixy>
          <ixz>-0.00142869</ixz>
          <iyy>0.00770431</iyy>
          <iyz>-0.000316237</iyz>
          <izz>0.00101942</izz>
        </inertia>
      </inertial>
      <collision name="LH_SHANK_collision">
        <pose>-0.065 -0.015 0.01 3.14159 1.57079 3.14159</pose>
        <geometry>
          <box>
            <size>0.08 0.07 0.13</size>
          </box>
        </geometry>
      </collision>
      <collision name="LH_SHANK_fixed_joint_lump__LH_ADAPTER_collision_1">
        <pose>-0.1 -0.02 -0.160625 0 -0 0</pose>
        <geometry>
          <cylinder>
            <length>0.32125</length>
            <radius>0.015</radius>
          </cylinder>
        </geometry>
      </collision>
      <collision name="LH_SHANK_fixed_joint_lump__LH_FOOT_collision_2">
        <pose>-0.1 -0.02 -0.298 0 -0 0</pose>
        <geometry>
          <sphere>
            <radius>0.031</radius>
          </sphere>
        </geometry>
        <surface>
          <contact>
            <ode>
              <kp>1e+06</kp>
              <kd>100</kd>
            </ode>
          </contact>
          <friction>
            <ode>
              <mu>0.8</mu>
              <mu2>0.8</mu2>
            </ode>
          </friction>
        </surface>
      </collision>
      <visual name="LH_SHANK_visual">
        <pose>0 0 0 0 -0 3.14159</pose>
        <geometry>
          <mesh>
            <scale>0.001 0.001 0.001</scale>
            <uri>meshes/anymal_shank_r.dae</uri>
          </mesh>
        </geometry>
      </visual>
      <visual name="LH_SHANK_fixed_joint_lump__LH_ADAPTER_visual_1">
        <pose>-0.1 -0.02 0.032 0 -0 3.14159</pose>
        <geometry>
          <mesh>
            <scale>0.001 0.001 0.001</scale>
            <uri>meshes/anymal_foot.dae</uri>
          </mesh>
        </geometry>
      </visual>
    </link>
    <joint name="LH_KFE" type="revolute">
      <child>LH_SHANK</child>
      <parent>LH_THIGH</parent>
      <axis>
        <xyz>0 1 0</xyz>
        <limit>
          <lower>-9.42</lower>
          <upper>9.42</upper>
          <effort>80</effort>
          <velocity>15</velocity>
        </limit>
        <dynamics>
          <damping>0</damping>
          <friction>0</friction>
          <spring_reference>0</spring_reference>
          <spring_stiffness>0</spring_stiffness>
        </dynamics>
        <use_parent_model_frame>0</use_parent_model_frame>
      </axis>
    </joint>
    <link name="RF_HIP">
      <pose>0.277 -0.116 0 0 -0 0</pose>
      <gravity>1</gravity>
      <velocity_decay/>
      <inertial>
        <pose>0.064516 0.003787 -0.000152 0 -0 0</pose>
        <mass>1.42462</mass>
        <inertia>
          <ixx>0.00243023</ixx>
          <ixy>1.53024e-05</ixy>
          <ixz>-2.18191e-05</ixz>
          <iyy>0.00230257</iyy>
          <iyz>-2.6473e-05</iyz>
          <izz>0.00198068</izz>
        </inertia>
      </inertial>
      <collision name="RF_HIP_collision">
        <pose>0.0635 0.009 0 1.5708 -0 0</pose>
        <geometry>
          <cylinder>
            <length>0.1</length>
            <radius>0.08</radius>
          </cylinder>
        </geometry>
      </collision>
      <collision name="RF_HIP_collision_1">
        <pose>0.0635 0.074 0 1.5708 -0 0</pose>
        <geometry>
          <cylinder>
            <length>0.03</length>
            <radius>0.045</radius>
          </cylinder>
        </geometry>
      </collision>
      <visual name="RF_HIP_visual">
        <pose>0 0 0 0 -0 0</pose>
        <geometry>
          <mesh>
            <scale>0.001 0.001 0.001</scale>
            <uri>meshes/anymal_hip_r.dae</uri>
          </mesh>
        </geometry>
      </visual>
    </link>
    <joint name="RF_HAA" type="revolute">
      <child>RF_HIP</child>
      <parent>base</parent>
      <axis>
        <xyz>1 0 0</xyz>
        <limit>
          <lower>-9.42</lower>
          <upper>9.42</upper>
          <effort>80</effort>
          <velocity>15</velocity>
        </limit>
        <dynamics>
          <damping>0</damping>
          <friction>0</friction>
          <spring_reference>0</spring_reference>
          <spring_stiffness>0</spring_stiffness>
        </dynamics>
        <use_parent_model_frame>0</use_parent_model_frame>
      </axis>
    </joint>
    <link name="RF_THIGH">
      <pose>0.3405 -0.157 0 0 -0 0</pose>
      <gravity>1</gravity>
      <velocity_decay/>
      <inertial>
        <pose>-0.003898 -0.054227 -0.214583 0 -0 0</pose>
        <mass>1.63498</mass>
        <inertia>
          <ixx>0.0120368</ixx>
          <ixy>-6.76207e-05</ixy>
          <ixz>0.000287806</ixz>
          <iyy>0.0120644</iyy>
          <iyz>0.0014061</iyz>
          <izz>0.00249423</izz>
        </inertia>
      </inertial>
      <collision name="RF_THIGH_collision">
        <pose>0 -0.035 -0.125 -0.145 0 0</pose>
        <geometry>
          <box>
            <size>0.08 0.04 0.25</size>
          </box>
        </geometry>
      </collision>
      <collision name="RF_THIGH_collision_1">
        <pose>0 -0.069 -0.25 1.5708 -0 0</pose>
        <geometry>
          <cylinder>
            <length>0.12</length>
            <radius>0.06</radius>
          </cylinder>
        </geometry>
      </collision>
      <collision name="RF_THIGH_collision_2">
        <pose>0 0.005 0 -1.7158 0 0</pose>
        <geometry>
          <cylinder>
            <length>0.12</length>
            <radius>0.066</radius>
          </cylinder>
        </geometry>
      </collision>
      <visual name="RF_THIGH_visual">
        <pose>0 0 0 0 -0 0</pose>
        <geometry>
          <mesh>
            <scale>0.001 0.001 0.001</scale>
            <uri>meshes/anymal_thigh_r.dae</uri>
          </mesh>
        </geometry>
      </visual>
    </link>
    <joint name="RF_HFE" type="revolute">
      <child>RF_THIGH</child>
      <parent>RF_HIP</parent>
      <axis>
        <xyz>0 1 0</xyz>
        <limit>
          <lower>-9.42</lower>
          <upper>9.42</upper>
          <effort>80</effort>
          <velocity>15</velocity>
        </limit>
        <dynamics>
          <damping>0</damping>
          <friction>0</friction>
          <spring_reference>0</spring_reference>
          <spring_stiffness>0</spring_stiffness>
        </dynamics>
        <use_parent_model_frame>0</use_parent_model_frame>
      </axis>
    </joint>
    <link name="RF_SHANK">
      <pose>0.3405 -0.266 -0.25 0 -0 0</pose>
      <gravity>1</gravity>
      <velocity_decay/>
      <inertial>
        <pose>0.058733 0.010824 -0.098064 0 -0 0</pose>
        <mass>0.347375</mass>
        <inertia>
          <ixx>0.00685813</ixx>
          <ixy>-3.2229e-05</ixy>
          <ixz>0.00142869</ixz>
          <iyy>0.00770431</iyy>
          <iyz>0.000316237</iyz>
          <izz>0.00101942</izz>
        </inertia>
      </inertial>
      <collision name="RF_SHANK_collision">
        <pose>0.065 0.015 0.01 3.14159 1.57079 3.14159</pose>
        <geometry>
          <box>
            <size>0.08 0.07 0.13</size>
          </box>
        </geometry>
      </collision>
      <collision name="RF_SHANK_fixed_joint_lump__RF_ADAPTER_collision_1">
        <pose>0.1 0.02 -0.160625 0 -0 0</pose>
        <geometry>
          <cylinder>
            <length>0.32125</length>
            <radius>0.015</radius>
          </cylinder>
        </geometry>
      </collision>
      <collision name="RF_SHANK_fixed_joint_lump__RF_FOOT_collision_2">
        <pose>0.1 0.02 -0.298 0 -0 0</pose>
        <geometry>
          <sphere>
            <radius>0.031</radius>
          </sphere>
        </geometry>
        <surface>
          <contact>
            <ode>
              <kp>1e+06</kp>
              <kd>100</kd>
            </ode>
          </contact>
          <friction>
            <ode>
              <mu>0.8</mu>
              <mu2>0.8</mu2>
            </ode>
          </friction>
        </surface>
      </collision>
      <visual name="RF_SHANK_visual">
        <pose>0 0 0 0 -0 0</pose>
        <geometry>
          <mesh>
            <scale>0.001 0.001 0.001</scale>
            <uri>meshes/anymal_shank_r.dae</uri>
          </mesh>
        </geometry>
      </visual>
      <visual name="RF_SHANK_fixed_joint_lump__RF_ADAPTER_visual_1">
        <pose>0.1 0.02 0.032 0 -0 0</pose>
        <geometry>
          <mesh>
            <scale>0.001 0.001 0.001</scale>
            <uri>meshes/anymal_foot.dae</uri>
          </mesh>
        </geometry>
      </visual>
    </link>
    <joint name="RF_KFE" type="revolute">
      <child>RF_SHANK</child>
      <parent>RF_THIGH</parent>
      <axis>
        <xyz>0 1 0</xyz>
        <limit>
          <lower>-9.42</lower>
          <upper>9.42</upper>
          <effort>80</effort>
          <velocity>15</velocity>
        </limit>
        <dynamics>
          <damping>0</damping>
          <friction>0</friction>
          <spring_reference>0</spring_reference>
          <spring_stiffness>0</spring_stiffness>
        </dynamics>
        <use_parent_model_frame>0</use_parent_model_frame>
      </axis>
    </joint>
    <link name="RH_HIP">
      <pose>-0.277 -0.116 0 0 -0 0</pose>
      <gravity>1</gravity>
      <velocity_decay/>
      <inertial>
        <pose>-0.064516 0.003787 -0.000152 0 -0 0</pose>
        <mass>1.42462</mass>
        <inertia>
          <ixx>0.00243023</ixx>
          <ixy>-1.53024e-05</ixy>
          <ixz>2.18191e-05</ixz>
          <iyy>0.00230257</iyy>
          <iyz>-2.6473e-05</iyz>
          <izz>0.00198068</izz>
        </inertia>
      </inertial>
      <collision name="RH_HIP_collision">
        <pose>-0.0635 0.009 0 -1.5708 0 0</pose>
        <geometry>
          <cylinder>
            <length>0.1</length>
            <radius>0.08</radius>
          </cylinder>
        </geometry>
      </collision>
      <collision name="RH_HIP_collision_1">
        <pose>-0.0635 0.074 0 -1.5708 0 0</pose>
        <geometry>
          <cylinder>
            <length>0.03</length>
            <radius>0.045</radius>
          </cylinder>
        </geometry>
      </collision>
      <visual name="RH_HIP_visual">
        <pose>0 0 0 0 -0 3.14159</pose>
        <geometry>
          <mesh>
            <scale>0.001 0.001 0.001</scale>
            <uri>meshes/anymal_hip_l.dae</uri>
          </mesh>
        </geometry>
      </visual>
    </link>
    <joint name="RH_HAA" type="revolute">
      <child>RH_HIP</child>
      <parent>base</parent>
      <axis>
        <xyz>1 0 0</xyz>
        <limit>
          <lower>-9.42</lower>
          <upper>9.42</upper>
          <effort>80</effort>
          <velocity>15</velocity>
        </limit>
        <dynamics>
          <damping>0</damping>
          <friction>0</friction>
          <spring_reference>0</spring_reference>
          <spring_stiffness>0</spring_stiffness>
        </dynamics>
        <use_parent_model_frame>0</use_parent_model_frame>
      </axis>
    </joint>
    <link name="RH_THIGH">
      <pose>-0.3405 -0.157 0 0 -0 0</pose>
      <gravity>1</gravity>
      <velocity_decay/>
      <inertial>
        <pose>0.003898 -0.054227 -0.214583 0 -0 0</pose>
        <mass>1.63498</mass>
        <inertia>
          <ixx>0.0120368</ixx>
          <ixy>6.76207e-05</ixy>
          <ixz>-0.000287806</ixz>
          <iyy>0.0120644</iyy>
          <iyz>0.0014061</iyz>
          <izz>0.00249423</izz>
        </inertia>
      </inertial>
      <collision name="RH_THIGH_collision">
        <pose>0 -0.035 -0.125 -0.145 0 0</pose>
        <geometry>
          <box>
            <size>0.08 0.04 0.25</size>
          </box>
        </geometry>
      </collision>
      <collision name="RH_THIGH_collision_1">
        <pose>0 -0.069 -0.25 1.5708 -0 0</pose>
        <geometry>
          <cylinder>
            <length>0.12</length>
            <radius>0.06</radius>
          </cylinder>
        </geometry>
      </collision>
      <collision name="RH_THIGH_collision_2">
        <pose>0 0.005 0 -1.7158 0 0</pose>
        <geometry>
          <cylinder>
            <length>0.12</length>
            <radius>0.066</radius>
          </cylinder>
        </geometry>
      </collision>
      <visual name="RH_THIGH_visual">
        <pose>0 0 0 0 -0 3.14159</pose>
        <geometry>
          <mesh>
            <scale>0.001 0.001 0.001</scale>
            <uri>meshes/anymal_thigh_l.dae</uri>
          </mesh>
        </geometry>
      </visual>
    </link>
    <joint name="RH_HFE" type="revolute">
      <child>RH_THIGH</child>
      <parent>RH_HIP</parent>
      <axis>
        <xyz>0 1 0</xyz>
        <limit>
          <lower>-9.42</lower>
          <upper>9.42</upper>
          <effort>80</effort>
          <velocity>15</velocity>
        </limit>
        <dynamics>
          <damping>0</damping>
          <friction>0</friction>
          <spring_reference>0</spring_reference>
          <spring_stiffness>0</spring_stiffness>
        </dynamics>
        <use_parent_model_frame>0</use_parent_model_frame>
      </axis>
    </joint>
    <link name="RH_SHANK">
      <pose>-0.3405 -0.266 -0.25 0 -0 0</pose>
      <gravity>1</gravity>
      <velocity_decay/>
      <inertial>
        <pose>-0.058733 0.010824 -0.098064 0 -0 0</pose>
        <mass>0.347375</mass>
        <inertia>
          <ixx>0.00685813</ixx>
          <ixy>3.2229e-05</ixy>
          <ixz>-0.00142869</ixz>
          <iyy>0.00770431</iyy>
          <iyz>0.000316237</iyz>
          <izz>0.00101942</izz>
        </inertia>
      </inertial>
      <collision name="RH_SHANK_collision">
        <pose>-0.065 0.015 0.01 3.14159 1.57079 3.14159</pose>
        <geometry>
          <box>
            <size>0.08 0.07 0.13</size>
          </box>
        </geometry>
      </collision>
      <collision name="RH_SHANK_fixed_joint_lump__RH_ADAPTER_collision_1">
        <pose>-0.1 0.02 -0.160625 0 -0 0</pose>
        <geometry>
          <cylinder>
            <length>0.32125</length>
            <radius>0.015</radius>
          </cylinder>
        </geometry>
      </collision>
      <collision name="RH_SHANK_fixed_joint_lump__RH_FOOT_collision_2">
        <pose>-0.1 0.02 -0.298 0 -0 0</pose>
        <geometry>
          <sphere>
            <radius>0.031</radius>
          </sphere>
        </geometry>
        <surface>
          <contact>
            <ode>
              <kp>1e+06</kp>
              <kd>100</kd>
            </ode>
          </contact>
          <friction>
            <ode>
              <mu>0.8</mu>
              <mu2>0.8</mu2>
            </ode>
          </friction>
        </surface>
      </collision>
      <visual name="RH_SHANK_visual">
        <pose>0 0 0 0 -0 3.14159</pose>
        <geometry>
          <mesh>
            <scale>0.001 0.001 0.001</scale>
            <uri>meshes/anymal_shank_l.dae</uri>
          </mesh>
        </geometry>
      </visual>
      <visual name="RH_SHANK_fixed_joint_lump__RH_ADAPTER_visual_1">
        <pose>-0.1 0.02 0.032 0 -0 3.14159</pose>
        <geometry>
          <mesh>
            <scale>0.001 0.001 0.001</scale>
            <uri>meshes/anymal_foot.dae</uri>
          </mesh>
        </geometry>
      </visual>
    </link>
    <joint name="RH_KFE" type="revolute">
      <child>RH_SHANK</child>
      <parent>RH_THIGH</parent>
      <axis>
        <xyz>0 1 0</xyz>
        <limit>
          <lower>-9.42</lower>
          <upper>9.42</upper>
          <effort>80</effort>
          <velocity>15</velocity>
        </limit>
        <dynamics>
          <damping>0</damping>
          <friction>0</friction>
          <spring_reference>0</spring_reference>
          <spring_stiffness>0</spring_stiffness>
        </dynamics>
        <use_parent_model_frame>0</use_parent_model_frame>
      </axis>
    </joint>
    <static>0</static>
  </model>
</sdf>
