<?xml version='1.0' encoding='utf-8'?>
<sdf version="1.7">
  <model name="bosdyn_spot">
    <link name="base_link">
      <inertial>
        <mass>16</mass>
        <inertia>
          <ixx>0.0983333</ixx>
          <ixy>1e-06</ixy>
          <ixz>1e-06</ixz>
          <iyy>1.02567</iyy>
          <iyz>1e-06</iyz>
          <izz>1.04593</izz>
        </inertia>
      </inertial>
      <collision name="base_link_collision">
        <geometry>
          <mesh>
            <uri>meshes/body_collision.stl</uri>
          </mesh>
        </geometry>
      </collision>
      <visual name="base_link_visual">
        <geometry>
          <mesh>
            <uri>meshes/body.dae</uri>
          </mesh>
        </geometry>
      </visual>
      <visual name="base_link_fixed_joint_lump__imu_visual_1">
        <geometry>
          <box>
            <size>0.005 0.005 0.005</size>
          </box>
        </geometry>
      </visual>
      <sensor name="imu" type="imu">
        <always_on>1</always_on>
        <update_rate>50</update_rate>
        <imu>
          <angular_velocity>
            <x>
              <noise type="gaussian">
                <mean>0</mean>
                <stddev>0.0002</stddev>
                <bias_mean>7.5e-06</bias_mean>
                <bias_stddev>8e-07</bias_stddev>
                <dynamic_bias_stddev>4e-07</dynamic_bias_stddev>
                <dynamic_bias_correlation_time>1000</dynamic_bias_correlation_time>
              </noise>
            </x>
            <y>
              <noise type="gaussian">
                <mean>0</mean>
                <stddev>0.0002</stddev>
                <bias_mean>7.5e-06</bias_mean>
                <bias_stddev>8e-07</bias_stddev>
                <dynamic_bias_stddev>4e-07</dynamic_bias_stddev>
                <dynamic_bias_correlation_time>1000</dynamic_bias_correlation_time>
              </noise>
            </y>
            <z>
              <noise type="gaussian">
                <mean>0</mean>
                <stddev>0.0002</stddev>
                <bias_mean>7.5e-06</bias_mean>
                <bias_stddev>8e-07</bias_stddev>
                <dynamic_bias_stddev>4e-07</dynamic_bias_stddev>
                <dynamic_bias_correlation_time>1000</dynamic_bias_correlation_time>
              </noise>
            </z>
          </angular_velocity>
          <linear_acceleration>
            <x>
              <noise type="gaussian">
                <mean>0</mean>
                <stddev>0.01</stddev>
                <bias_mean>0.1</bias_mean>
                <bias_stddev>0.001</bias_stddev>
                <dynamic_bias_stddev>0.002</dynamic_bias_stddev>
                <dynamic_bias_correlation_time>300</dynamic_bias_correlation_time>
              </noise>
            </x>
            <y>
              <noise type="gaussian">
                <mean>0</mean>
                <stddev>0.01</stddev>
                <bias_mean>0.1</bias_mean>
                <bias_stddev>0.001</bias_stddev>
                <dynamic_bias_stddev>0.002</dynamic_bias_stddev>
                <dynamic_bias_correlation_time>300</dynamic_bias_correlation_time>
              </noise>
            </y>
            <z>
              <noise type="gaussian">
                <mean>0</mean>
                <stddev>0.01</stddev>
                <bias_mean>0.1</bias_mean>
                <bias_stddev>0.001</bias_stddev>
                <dynamic_bias_stddev>0.002</dynamic_bias_stddev>
                <dynamic_bias_correlation_time>300</dynamic_bias_correlation_time>
              </noise>
            </z>
          </linear_acceleration>
        </imu>
      </sensor>
    </link>
    <joint name="front_left_hip_x" type="revolute">
      <pose relative_to="base_link">0.29785 0.055 0 0 -0 0</pose>
      <parent>base_link</parent>
      <child>front_left_hip</child>
      <axis>
        <xyz>1 0 0</xyz>
        <limit>
          <lower>-0.785398</lower>
          <upper>0.785398</upper>
          <effort>100</effort>
          <velocity>1</velocity>
        </limit>
        <dynamics>
          <spring_reference>0</spring_reference>
          <spring_stiffness>0</spring_stiffness>
        </dynamics>
      </axis>
    </joint>
    <link name="front_left_hip">
      <pose relative_to="front_left_hip_x">0 0 0 0 -0 0</pose>
      <inertial>
        <mass>2</mass>
        <inertia>
          <ixx>0.0027</ixx>
          <ixy>0</ixy>
          <ixz>0</ixz>
          <iyy>0.00416667</iyy>
          <iyz>0</iyz>
          <izz>0.00416667</izz>
        </inertia>
      </inertial>
      <collision name="front_left_hip_collision">
        <geometry>
          <mesh>
            <uri>meshes/front_left_hip_collision.stl</uri>
          </mesh>
        </geometry>
      </collision>
      <visual name="front_left_hip_visual">
        <geometry>
          <mesh>
            <uri>meshes/front_left_hip.dae</uri>
          </mesh>
        </geometry>
      </visual>
    </link>
    <joint name="front_left_hip_y" type="revolute">
      <pose relative_to="front_left_hip">0 0.110945 0 0 -0 0</pose>
      <parent>front_left_hip</parent>
      <child>front_left_upper_leg</child>
      <axis>
        <xyz>0 1 0</xyz>
        <limit>
          <lower>-0.898845</lower>
          <upper>2.29511</upper>
          <effort>100</effort>
          <velocity>1</velocity>
        </limit>
        <dynamics>
          <spring_reference>0</spring_reference>
          <spring_stiffness>0</spring_stiffness>
        </dynamics>
      </axis>
    </joint>
    <link name="front_left_upper_leg">
      <pose relative_to="front_left_hip_y">0 0 0 0 -0 0</pose>
      <inertial>
        <pose>0 0 -0.14 0 -0 0</pose>
        <mass>1</mass>
        <inertia>
          <ixx>0.0155334</ixx>
          <ixy>0</ixy>
          <ixz>0</ixz>
          <iyy>0.0155334</iyy>
          <iyz>0</iyz>
          <izz>0.000962667</izz>
        </inertia>
      </inertial>
      <collision name="front_left_upper_leg_collision">
        <geometry>
          <mesh>
            <uri>meshes/front_left_upper_leg_collision.stl</uri>
          </mesh>
        </geometry>
      </collision>
      <visual name="front_left_upper_leg_visual">
        <geometry>
          <mesh>
            <uri>meshes/front_left_upper_leg.dae</uri>
          </mesh>
        </geometry>
      </visual>
    </link>
    <joint name="front_left_knee" type="revolute">
      <pose relative_to="front_left_upper_leg">0.025 0 -0.3205 0 -0 0</pose>
      <parent>front_left_upper_leg</parent>
      <child>front_left_lower_leg</child>
      <axis>
        <xyz>0 1 0</xyz>
        <limit>
          <lower>-2.7929</lower>
          <upper>-0.254801</upper>
          <effort>100</effort>
          <velocity>1</velocity>
        </limit>
        <dynamics>
          <spring_reference>0</spring_reference>
          <spring_stiffness>0</spring_stiffness>
        </dynamics>
      </axis>
    </joint>
    <link name="front_left_lower_leg">
      <pose relative_to="front_left_knee">0 0 0 0 -0 0</pose>
      <inertial>
        <pose>0 0 -0.16 0 -0 0</pose>
        <mass>0.5</mass>
        <inertia>
          <ixx>0.00743438</ixx>
          <ixy>0</ixy>
          <ixz>0</ixz>
          <iyy>0.00740104</iyy>
          <iyz>0</iyz>
          <izz>0.000135417</izz>
        </inertia>
      </inertial>
      <collision name="front_left_lower_leg_collision">
        <geometry>
          <mesh>
            <scale>0.82 0.97 0.98</scale>
            <uri>meshes/front_left_lower_leg_collision.stl</uri>
          </mesh>
        </geometry>
        <surface>
          <contact>
            <ode>
              <kp>100000</kp>
              <kd>1</kd>
              <max_vel>0</max_vel>
              <min_depth>0.001</min_depth>
            </ode>
          </contact>
          <friction>
            <ode>
              <mu>0.8</mu>
              <mu2>0.8</mu2>
            </ode>
          </friction>
        </surface>
      </collision>
      <visual name="front_left_lower_leg_visual">
        <geometry>
          <mesh>
            <uri>meshes/front_left_lower_leg.dae</uri>
          </mesh>
        </geometry>
      </visual>
    </link>
    <joint name="front_right_hip_x" type="revolute">
      <pose relative_to="base_link">0.29785 -0.055 0 0 -0 0</pose>
      <parent>base_link</parent>
      <child>front_right_hip</child>
      <axis>
        <xyz>1 0 0</xyz>
        <limit>
          <lower>-0.785398</lower>
          <upper>0.785398</upper>
          <effort>100</effort>
          <velocity>1</velocity>
        </limit>
        <dynamics>
          <spring_reference>0</spring_reference>
          <spring_stiffness>0</spring_stiffness>
        </dynamics>
      </axis>
    </joint>
    <link name="front_right_hip">
      <pose relative_to="front_right_hip_x">0 0 0 0 -0 0</pose>
      <inertial>
        <mass>2</mass>
        <inertia>
          <ixx>0.0027</ixx>
          <ixy>0</ixy>
          <ixz>0</ixz>
          <iyy>0.00416667</iyy>
          <iyz>0</iyz>
          <izz>0.00416667</izz>
        </inertia>
      </inertial>
      <collision name="front_right_hip_collision">
        <geometry>
          <mesh>
            <uri>meshes/front_right_hip_collision.stl</uri>
          </mesh>
        </geometry>
      </collision>
      <visual name="front_right_hip_visual">
        <geometry>
          <mesh>
            <uri>meshes/front_right_hip.dae</uri>
          </mesh>
        </geometry>
      </visual>
    </link>
    <joint name="front_right_hip_y" type="revolute">
      <pose relative_to="front_right_hip">0 -0.110945 0 0 -0 0</pose>
      <parent>front_right_hip</parent>
      <child>front_right_upper_leg</child>
      <axis>
        <xyz>0 1 0</xyz>
        <limit>
          <lower>-0.898845</lower>
          <upper>2.29511</upper>
          <effort>100</effort>
          <velocity>1</velocity>
        </limit>
        <dynamics>
          <spring_reference>0</spring_reference>
          <spring_stiffness>0</spring_stiffness>
        </dynamics>
      </axis>
    </joint>
    <link name="front_right_upper_leg">
      <pose relative_to="front_right_hip_y">0 0 0 0 -0 0</pose>
      <inertial>
        <pose>0 0 -0.14 0 -0 0</pose>
        <mass>1</mass>
        <inertia>
          <ixx>0.0155334</ixx>
          <ixy>0</ixy>
          <ixz>0</ixz>
          <iyy>0.0155334</iyy>
          <iyz>0</iyz>
          <izz>0.000962667</izz>
        </inertia>
      </inertial>
      <collision name="front_right_upper_leg_collision">
        <geometry>
          <mesh>
            <uri>meshes/front_right_upper_leg_collision.stl</uri>
          </mesh>
        </geometry>
      </collision>
      <visual name="front_right_upper_leg_visual">
        <geometry>
          <mesh>
            <uri>meshes/front_right_upper_leg.dae</uri>
          </mesh>
        </geometry>
      </visual>
    </link>
    <joint name="front_right_knee" type="revolute">
      <pose relative_to="front_right_upper_leg">0.025 0 -0.3205 0 -0 0</pose>
      <parent>front_right_upper_leg</parent>
      <child>front_right_lower_leg</child>
      <axis>
        <xyz>0 1 0</xyz>
        <limit>
          <lower>-2.7929</lower>
          <upper>-0.254801</upper>
          <effort>100</effort>
          <velocity>1</velocity>
        </limit>
        <dynamics>
          <spring_reference>0</spring_reference>
          <spring_stiffness>0</spring_stiffness>
        </dynamics>
      </axis>
    </joint>
    <link name="front_right_lower_leg">
      <pose relative_to="front_right_knee">0 0 0 0 -0 0</pose>
      <inertial>
        <pose>0 0 -0.16 0 -0 0</pose>
        <mass>0.5</mass>
        <inertia>
          <ixx>0.00743438</ixx>
          <ixy>0</ixy>
          <ixz>0</ixz>
          <iyy>0.00740104</iyy>
          <iyz>0</iyz>
          <izz>0.000135417</izz>
        </inertia>
      </inertial>
      <collision name="front_right_lower_leg_collision">
        <geometry>
          <mesh>
            <scale>0.82 0.97 0.98</scale>
            <uri>meshes/front_right_lower_leg_collision.stl</uri>
          </mesh>
        </geometry>
        <surface>
          <contact>
            <ode>
              <kp>100000</kp>
              <kd>1</kd>
              <max_vel>0</max_vel>
              <min_depth>0.001</min_depth>
            </ode>
          </contact>
          <friction>
            <ode>
              <mu>0.8</mu>
              <mu2>0.8</mu2>
            </ode>
          </friction>
        </surface>
      </collision>
      <visual name="front_right_lower_leg_visual">
        <geometry>
          <mesh>
            <uri>meshes/front_right_lower_leg.dae</uri>
          </mesh>
        </geometry>
      </visual>
    </link>
    <joint name="rear_left_hip_x" type="revolute">
      <pose relative_to="base_link">-0.29785 0.055 0 0 -0 0</pose>
      <parent>base_link</parent>
      <child>rear_left_hip</child>
      <axis>
        <xyz>1 0 0</xyz>
        <limit>
          <lower>-0.785398</lower>
          <upper>0.785398</upper>
          <effort>100</effort>
          <velocity>1</velocity>
        </limit>
        <dynamics>
          <spring_reference>0</spring_reference>
          <spring_stiffness>0</spring_stiffness>
        </dynamics>
      </axis>
    </joint>
    <link name="rear_left_hip">
      <pose relative_to="rear_left_hip_x">0 0 0 0 -0 0</pose>
      <inertial>
        <mass>2</mass>
        <inertia>
          <ixx>0.0027</ixx>
          <ixy>0</ixy>
          <ixz>0</ixz>
          <iyy>0.00416667</iyy>
          <iyz>0</iyz>
          <izz>0.00416667</izz>
        </inertia>
      </inertial>
      <collision name="rear_left_hip_collision">
        <geometry>
          <mesh>
            <uri>meshes/rear_left_hip_collision.stl</uri>
          </mesh>
        </geometry>
      </collision>
      <visual name="rear_left_hip_visual">
        <geometry>
          <mesh>
            <uri>meshes/rear_left_hip.dae</uri>
          </mesh>
        </geometry>
      </visual>
    </link>
    <joint name="rear_left_hip_y" type="revolute">
      <pose relative_to="rear_left_hip">0 0.110945 0 0 -0 0</pose>
      <parent>rear_left_hip</parent>
      <child>rear_left_upper_leg</child>
      <axis>
        <xyz>0 1 0</xyz>
        <limit>
          <lower>-0.898845</lower>
          <upper>2.29511</upper>
          <effort>100</effort>
          <velocity>1</velocity>
        </limit>
        <dynamics>
          <spring_reference>0</spring_reference>
          <spring_stiffness>0</spring_stiffness>
        </dynamics>
      </axis>
    </joint>
    <link name="rear_left_upper_leg">
      <pose relative_to="rear_left_hip_y">0 0 0 0 -0 0</pose>
      <inertial>
        <pose>0 0 -0.14 0 -0 0</pose>
        <mass>1</mass>
        <inertia>
          <ixx>0.0155334</ixx>
          <ixy>0</ixy>
          <ixz>0</ixz>
          <iyy>0.0155334</iyy>
          <iyz>0</iyz>
          <izz>0.000962667</izz>
        </inertia>
      </inertial>
      <collision name="rear_left_upper_leg_collision">
        <geometry>
          <mesh>
            <uri>meshes/rear_left_upper_leg_collision.stl</uri>
          </mesh>
        </geometry>
      </collision>
      <visual name="rear_left_upper_leg_visual">
        <geometry>
          <mesh>
            <uri>meshes/rear_left_upper_leg.dae</uri>
          </mesh>
        </geometry>
      </visual>
    </link>
    <joint name="rear_left_knee" type="revolute">
      <pose relative_to="rear_left_upper_leg">0.025 0 -0.3205 0 -0 0</pose>
      <parent>rear_left_upper_leg</parent>
      <child>rear_left_lower_leg</child>
      <axis>
        <xyz>0 1 0</xyz>
        <limit>
          <lower>-2.7929</lower>
          <upper>-0.254801</upper>
          <effort>100</effort>
          <velocity>1</velocity>
        </limit>
        <dynamics>
          <spring_reference>0</spring_reference>
          <spring_stiffness>0</spring_stiffness>
        </dynamics>
      </axis>
    </joint>
    <link name="rear_left_lower_leg">
      <pose relative_to="rear_left_knee">0 0 0 0 -0 0</pose>
      <inertial>
        <pose>0 0 -0.16 0 -0 0</pose>
        <mass>0.5</mass>
        <inertia>
          <ixx>0.00743438</ixx>
          <ixy>0</ixy>
          <ixz>0</ixz>
          <iyy>0.00740104</iyy>
          <iyz>0</iyz>
          <izz>0.000135417</izz>
        </inertia>
      </inertial>
      <collision name="rear_left_lower_leg_collision">
        <geometry>
          <mesh>
            <scale>0.82 0.97 0.98</scale>
            <uri>meshes/rear_left_lower_leg_collision.stl</uri>
          </mesh>
        </geometry>
        <surface>
          <contact>
            <ode>
              <kp>100000</kp>
              <kd>1</kd>
              <max_vel>0</max_vel>
              <min_depth>0.001</min_depth>
            </ode>
          </contact>
          <friction>
            <ode>
              <mu>0.8</mu>
              <mu2>0.8</mu2>
            </ode>
          </friction>
        </surface>
      </collision>
      <visual name="rear_left_lower_leg_visual">
        <geometry>
          <mesh>
            <uri>meshes/rear_left_lower_leg.dae</uri>
          </mesh>
        </geometry>
      </visual>
    </link>
    <joint name="rear_right_hip_x" type="revolute">
      <pose relative_to="base_link">-0.29785 -0.055 0 0 -0 0</pose>
      <parent>base_link</parent>
      <child>rear_right_hip</child>
      <axis>
        <xyz>1 0 0</xyz>
        <limit>
          <lower>-0.785398</lower>
          <upper>0.785398</upper>
          <effort>100</effort>
          <velocity>1</velocity>
        </limit>
        <dynamics>
          <spring_reference>0</spring_reference>
          <spring_stiffness>0</spring_stiffness>
        </dynamics>
      </axis>
    </joint>
    <link name="rear_right_hip">
      <pose relative_to="rear_right_hip_x">0 0 0 0 -0 0</pose>
      <inertial>
        <mass>2</mass>
        <inertia>
          <ixx>0.0027</ixx>
          <ixy>0</ixy>
          <ixz>0</ixz>
          <iyy>0.00416667</iyy>
          <iyz>0</iyz>
          <izz>0.00416667</izz>
        </inertia>
      </inertial>
      <collision name="rear_right_hip_collision">
        <geometry>
          <mesh>
            <uri>meshes/rear_right_hip_collision.stl</uri>
          </mesh>
        </geometry>
      </collision>
      <visual name="rear_right_hip_visual">
        <geometry>
          <mesh>
            <uri>meshes/rear_right_hip.dae</uri>
          </mesh>
        </geometry>
      </visual>
    </link>
    <joint name="rear_right_hip_y" type="revolute">
      <pose relative_to="rear_right_hip">0 -0.110945 0 0 -0 0</pose>
      <parent>rear_right_hip</parent>
      <child>rear_right_upper_leg</child>
      <axis>
        <xyz>0 1 0</xyz>
        <limit>
          <lower>-0.898845</lower>
          <upper>2.29511</upper>
          <effort>100</effort>
          <velocity>1</velocity>
        </limit>
        <dynamics>
          <spring_reference>0</spring_reference>
          <spring_stiffness>0</spring_stiffness>
        </dynamics>
      </axis>
    </joint>
    <link name="rear_right_upper_leg">
      <pose relative_to="rear_right_hip_y">0 0 0 0 -0 0</pose>
      <inertial>
        <pose>0 0 -0.14 0 -0 0</pose>
        <mass>1</mass>
        <inertia>
          <ixx>0.0155334</ixx>
          <ixy>0</ixy>
          <ixz>0</ixz>
          <iyy>0.0155334</iyy>
          <iyz>0</iyz>
          <izz>0.000962667</izz>
        </inertia>
      </inertial>
      <collision name="rear_right_upper_leg_collision">
        <geometry>
          <mesh>
            <uri>meshes/rear_right_upper_leg_collision.stl</uri>
          </mesh>
        </geometry>
      </collision>
      <visual name="rear_right_upper_leg_visual">
        <geometry>
          <mesh>
            <uri>meshes/rear_right_upper_leg.dae</uri>
          </mesh>
        </geometry>
      </visual>
    </link>
    <joint name="rear_right_knee" type="revolute">
      <pose relative_to="rear_right_upper_leg">0.025 0 -0.3205 0 -0 0</pose>
      <parent>rear_right_upper_leg</parent>
      <child>rear_right_lower_leg</child>
      <axis>
        <xyz>0 1 0</xyz>
        <limit>
          <lower>-2.7929</lower>
          <upper>-0.254801</upper>
          <effort>100</effort>
          <velocity>1</velocity>
        </limit>
        <dynamics>
          <spring_reference>0</spring_reference>
          <spring_stiffness>0</spring_stiffness>
        </dynamics>
      </axis>
    </joint>
    <link name="rear_right_lower_leg">
      <pose relative_to="rear_right_knee">0 0 0 0 -0 0</pose>
      <inertial>
        <pose>0 0 -0.16 0 -0 0</pose>
        <mass>0.5</mass>
        <inertia>
          <ixx>0.00743438</ixx>
          <ixy>0</ixy>
          <ixz>0</ixz>
          <iyy>0.00740104</iyy>
          <iyz>0</iyz>
          <izz>0.000135417</izz>
        </inertia>
      </inertial>
      <collision name="rear_right_lower_leg_collision">
        <geometry>
          <mesh>
            <scale>0.82 0.97 0.98</scale>
            <uri>meshes/rear_right_lower_leg_collision.stl</uri>
          </mesh>
        </geometry>
        <surface>
          <contact>
            <ode>
              <kp>100000</kp>
              <kd>1</kd>
              <max_vel>0</max_vel>
              <min_depth>0.001</min_depth>
            </ode>
          </contact>
          <friction>
            <ode>
              <mu>0.8</mu>
              <mu2>0.8</mu2>
            </ode>
          </friction>
        </surface>
      </collision>
      <visual name="rear_right_lower_leg_visual">
        <geometry>
          <mesh>
            <uri>meshes/rear_right_lower_leg.dae</uri>
          </mesh>
        </geometry>
      </visual>
    </link>
  </model>
</sdf>

