<?xml version='1.0' encoding='utf-8'?>
<sdf version="1.6">
  <model name="coro_hd2_sensor_config_1">
    <link name="base_link">
      <pose frame="">0 0 0 0 -0 0</pose>
      <inertial>
        <pose frame="">-0.000649 -0.084945 0.062329 0 -0 0</pose>
        <mass>21.8194</mass>
        <inertia>
          <ixx>0.615397</ixx>
          <ixy>-0.0240585</ixy>
          <ixz>-0.120749</ixz>
          <iyy>1.75388</iyy>
          <iyz>-0.0028322</iyz>
          <izz>2.03641</izz>
        </inertia>
      </inertial>
      <collision name="base_link_collision">
        <pose frame="">0 0 0.12 0 0 0</pose>
        <geometry>
          <box>
            <size>0.9874 0.5709 0.05</size>
          </box>
        </geometry>
      </collision>
      <collision name="base_link_collision_bottom">
        <pose frame="">0 0 0.046 0 0 0</pose>
        <geometry>
          <box>
            <size>0.80 0.5709 0.2</size>
          </box>
        </geometry>
      </collision>
      <collision name="base_link_collision_1">
        <pose frame="">0 0 0.185625 0 -0 0</pose>
        <geometry>
          <box>
            <size>0.78992 0.5709 0.12375</size>
          </box>
        </geometry>
      </collision>
      <collision name="tower_collision_1">
        <pose>0.19 0 0.24 0 -0 0</pose>
        <geometry>
          <box>
            <size>0.2 0.2 0.34</size>
          </box>
        </geometry>
      </collision>

      <!-- we couldn't figure out how to modify this, so body visual is wrong -->
      <visual name="Body_visual">
        <pose>0 0 -0.135 0 0 1.57</pose>
        <geometry>
          <mesh>
            <uri>meshes/hd2_marble_base_body_metric.dae</uri>
            <submesh>
              <name>Body</name>
              <center>false</center>
            </submesh>
          </mesh>
        </geometry>
        <material>
          <diffuse>1.0 1.0 1.0</diffuse>
          <specular>1.0 1.0 1.0</specular>
          <pbr>
            <metal>
              <albedo_map>materials/textures/HD2_Albedo.png</albedo_map>
              <metalness_map>materials/textures/HD2_Metalness.png</metalness_map>
              <roughness_map>materials/textures/HD2_Roughness.png</roughness_map>
            </metal>
          </pbr>
          <script>
            <uri>materials/scripts/</uri>
            <uri>materials/textures/</uri>
            <name>HD/HD2_Diffuse</name>
          </script>
        </material>
      </visual>
      <!-- -->

      <visual name="plate1_visual">
        <pose>0.19 0 0.38 0 0 0</pose>
        <geometry>
          <box>
            <size>0.2 0.2 0.005</size>
          </box>
        </geometry>
        <material>
          <ambient>200 200 200 1</ambient>
          <diffuse>200 200 200 1</diffuse>
        </material>
      </visual>
      <visual name="plate2_visual">
        <pose>0.19 0 0.27 0 0 0</pose>
        <geometry>
          <box>
            <size>0.2 0.2 0.005</size>
          </box>
        </geometry>
        <material>
          <ambient>200 200 200 1</ambient>
          <diffuse>200 200 200 1</diffuse>
        </material>
      </visual>
      <visual name="plate3_visual">
        <pose>0.19 0 0.08 0 0 0</pose>
        <geometry>
          <box>
            <size>0.2 0.2 0.005</size>
          </box>
        </geometry>
        <material>
          <ambient>240 240 240 1</ambient>
          <diffuse>240 240 240 1</diffuse>
        </material>
      </visual>

      <visual name="beam1_visual">
        <pose>0.281 0.091 0.23 0 0 0</pose>
        <geometry>
          <box>
            <size>0.02 0.02 0.3</size>
          </box>
        </geometry>
        <material>
          <ambient>200 200 200 1</ambient>
          <diffuse>200 200 200 1</diffuse>
        </material>
      </visual>
      <visual name="beam2_visual">
        <pose>0.281 -0.091 0.23 0 0 0</pose>
        <geometry>
          <box>
            <size>0.02 0.02 0.3</size>
          </box>
        </geometry>
        <material>
          <ambient>200 200 200 1</ambient>
          <diffuse>200 200 200 1</diffuse>
        </material>
      </visual>
      <visual name="beam3_visual">
        <pose>0.099 0.091 0.23 0 0 0</pose>
        <geometry>
          <box>
            <size>0.02 0.02 0.3</size>
          </box>
        </geometry>
        <material>
          <ambient>200 200 200 1</ambient>
          <diffuse>200 200 200 1</diffuse>
        </material>
      </visual>
      <visual name="beam4_visual">
        <pose>0.099 -0.091 0.23 0 0 0</pose>
        <geometry>
          <box>
            <size>0.02 0.02 0.3</size>
          </box>
        </geometry>
        <material>
          <ambient>200 200 200 1</ambient>
          <diffuse>200 200 200 1</diffuse>
        </material>
      </visual>

      <visual name="d435i_realsense_camera_visual">
        <pose>0.25 0 0.353 0 0.46 0</pose>
        <geometry>
          <mesh>
            <scale>0.001 0.001 0.001</scale>
            <uri>meshes/realsense_d435.dae</uri>
          </mesh>
        </geometry>
      </visual>

      <visual name="vlp16_visual1">
        <pose>0.19 0 0.272 0 -0 0</pose>
        <geometry>
          <mesh>
            <scale>1 1 1</scale>
            <uri>meshes/VLP16_base_1.dae</uri>
          </mesh>
        </geometry>
      </visual>
      <visual name="vlp_visual2">
        <pose>0.19 0 0.272 0 -0 0</pose>
        <geometry>
          <mesh>
            <scale>1 1 1</scale>
            <uri>meshes/VLP16_base_2.dae</uri>
          </mesh>
        </geometry>
      </visual>
      <visual name="vlp_visual3">
        <pose>0.19 0 0.272 0 -0 0</pose>
        <geometry>
          <mesh>
            <scale>1 1 1</scale>
            <uri>meshes/VLP16_scan.dae</uri>
          </mesh>
        </geometry>
      </visual>

      <visual name="camera_front_visual">
        <pose>0.28 0.06 0.365 0 0 0</pose>
        <geometry>
          <box>
            <size>0.01 0.03 0.03</size>
          </box>
        </geometry>
        <material>
          <ambient>0.0 0.0 0.0 1.0</ambient>
          <diffuse>0.0 0.0 0.0 1.0</diffuse>
        </material>
      </visual>
      <visual name="camera_lens_front_visual">
        <pose>0.29 0.06 0.365 0 1.5707963267948966 0</pose>
        <geometry>
          <cylinder>
            <length>0.011</length>
            <radius>0.005</radius>
          </cylinder>
        </geometry>
        <material>
          <ambient>0.0 0.0 0.0 1.0</ambient>
          <diffuse>0.0 0.0 0.0 1.0</diffuse>
        </material>
      </visual>

      <visual name="camera_rear_visual">
        <pose>0.10 0 0.365 0 0 0</pose>
        <geometry>
          <box>
            <size>0.01 0.03 0.03</size>
          </box>
        </geometry>
        <material>
          <ambient>0.0 0.0 0.0 1.0</ambient>
          <diffuse>0.0 0.0 0.0 1.0</diffuse>
        </material>
      </visual>
      <visual name="camera_lens_rear_visual">
        <pose>0.09 0 0.365 0 1.5707963267948966 0</pose>
        <geometry>
          <cylinder>
            <length>0.011</length>
            <radius>0.005</radius>
          </cylinder>
        </geometry>
        <material>
          <ambient>0.0 0.0 0.0 1.0</ambient>
          <diffuse>0.0 0.0 0.0 1.0</diffuse>
        </material>
      </visual>

      <visual name="camera_left_visual">
        <pose>0.19 0.09 0.365 0 0 0</pose>
        <geometry>
          <box>
            <size>0.03 0.01 0.03</size>
          </box>
        </geometry>
        <material>
          <ambient>0.0 0.0 0.0 1.0</ambient>
          <diffuse>0.0 0.0 0.0 1.0</diffuse>
        </material>
      </visual>
      <visual name="camera_lens_left_visual">
        <pose>0.19 0.1 0.365 1.5707963267948966 0 0</pose>
        <geometry>
          <cylinder>
            <length>0.011</length>
            <radius>0.005</radius>
          </cylinder>
        </geometry>
        <material>
          <ambient>0.0 0.0 0.0 1.0</ambient>
          <diffuse>0.0 0.0 0.0 1.0</diffuse>
        </material>
      </visual>

      <visual name="camera_right_visual">
        <pose>0.19 -0.09 0.365 0 0 0</pose>
        <geometry>
          <box>
            <size>0.03 0.01 0.03</size>
          </box>
        </geometry>
        <material>
          <ambient>0.0 0.0 0.0 1.0</ambient>
          <diffuse>0.0 0.0 0.0 1.0</diffuse>
        </material>
      </visual>
      <visual name="camera_lens_right_visual">
        <pose>0.19 -0.1 0.365 1.5707963267948966 0 0</pose>
        <geometry>
          <cylinder>
            <length>0.011</length>
            <radius>0.005</radius>
          </cylinder>
        </geometry>
        <material>
          <ambient>0.0 0.0 0.0 1.0</ambient>
          <diffuse>0.0 0.0 0.0 1.0</diffuse>
        </material>
      </visual>

      <visual name="light_front_visual">
        <pose>0.28 0 0.402 0 0 0</pose>
        <geometry>
          <box>
            <size>0.04 0.13 0.04</size>
          </box>
        </geometry>
        <material>
          <ambient>0.0 0.0 0.0 1.0</ambient>
          <diffuse>0.0 0.0 0.0 1.0</diffuse>
        </material>
      </visual>
      <light name="light_front" type="spot">
        <pose>0.31 0 0.402 0 -1.5707963267948966 0</pose>
        <attenuation>
          <range>25</range>
          <linear>0</linear>
          <constant>0.1</constant>
          <quadratic>0.005</quadratic>
        </attenuation>
        <diffuse>0.8 0.8 0.5 1.0</diffuse>
        <specular>0.8 0.8 0.5 1</specular>
        <spot>
          <inner_angle>1.571</inner_angle>
          <outer_angle>2.1</outer_angle>
          <falloff>1</falloff>
        </spot>
        <direction>1 0 0</direction>
        <cast_shadows>1</cast_shadows>
      </light>
      
      <visual name="light_rear_visual">
        <pose>0.10 0 0.402 0 0 0</pose>
        <geometry>
          <box>
            <size>0.04 0.12 0.04</size>
          </box>
        </geometry>
        <material>
          <ambient>0.0 0.0 0.0 1.0</ambient>
          <diffuse>0.0 0.0 0.0 1.0</diffuse>
        </material>
      </visual>
      <light name="light_rear" type="spot">
        <pose>0.07 0 0.402 0 1.5707963267948966 0</pose>
        <attenuation>
          <range>25</range>
          <linear>0</linear>
          <constant>0.1</constant>
          <quadratic>0.005</quadratic>
        </attenuation>
        <diffuse>0.8 0.8 0.5 1.0</diffuse>
        <specular>0.8 0.8 0.5 1</specular>
        <spot>
          <inner_angle>1.571</inner_angle>
          <outer_angle>2.1</outer_angle>
          <falloff>1</falloff>
        </spot>
        <direction>1 0 0</direction>
        <cast_shadows>1</cast_shadows>
      </light>
      
      <visual name="light_left_visual">
        <pose>0.19 0.09 0.402 0 0 0</pose>
        <geometry>
          <box>
            <size>0.12 0.04 0.04</size>
          </box>
        </geometry>
        <material>
          <ambient>0.0 0.0 0.0 1.0</ambient>
          <diffuse>0.0 0.0 0.0 1.0</diffuse>
        </material>
      </visual>
      <light name="light_left" type="spot">
        <pose>0.19 0.12 0.402 1.5707963267948966 0 0</pose>
        <attenuation>
          <range>25</range>
          <linear>0</linear>
          <constant>0.1</constant>
          <quadratic>0.005</quadratic>
        </attenuation>
        <diffuse>0.8 0.8 0.5 1.0</diffuse>
        <specular>0.8 0.8 0.5 1</specular>
        <spot>
          <inner_angle>1.571</inner_angle>
          <outer_angle>2.1</outer_angle>
          <falloff>1</falloff>
        </spot>
        <direction>1 0 0</direction>
        <cast_shadows>1</cast_shadows>
      </light>
      
      <visual name="light_right_visual">
        <pose>0.19 -0.09 0.402 0 0 0</pose>
        <geometry>
          <box>
            <size>0.12 0.04 0.04</size>
          </box>
        </geometry>
        <material>
          <ambient>0.0 0.0 0.0 1.0</ambient>
          <diffuse>0.0 0.0 0.0 1.0</diffuse>
        </material>
      </visual>
      <light name="light_right" type="spot">
        <pose>0.19 -0.12 0.402 -1.5707963267948966 0 0</pose>
        <attenuation>
          <range>25</range>
          <linear>0</linear>
          <constant>0.1</constant>
          <quadratic>0.005</quadratic>
        </attenuation>
        <diffuse>0.8 0.8 0.5 1.0</diffuse>
        <specular>0.8 0.8 0.5 1</specular>
        <spot>
          <inner_angle>1.571</inner_angle>
          <outer_angle>2.1</outer_angle>
          <falloff>1</falloff>
        </spot>
        <direction>1 0 0</direction>
        <cast_shadows>1</cast_shadows>
      </light>


      <!-- thermal camera -->
      <visual name="thermal_camera_visual">
        <pose> 0.27 -0.06 0.364 0 0 0</pose>
        <geometry>
          <box>
            <size>0.02 0.03 0.03</size>
          </box>
        </geometry>
      </visual>
      <sensor name="thermal_camera" type="thermal">
        <pose> 0.28 -0.06 0.364 0 0 0</pose>
        <camera name="thermal_camera">
          <horizontal_fov>0.628</horizontal_fov>
          <lens>
            <intrinsics>
              <!-- fx = fy = width / ( 2 * tan (hfov / 2 ) ) -->
              <fx>317.173</fx>
              <fy>317.173</fy>
              <!-- cx = ( width - 1 ) / 2 -->
              <cx>102.5</cx>
              <!-- cy = ( height - 1 ) / 2 -->
              <cy>77.5</cy>
              <s>0</s>
            </intrinsics>
          </lens>
          <image>
            <width>206</width>
            <height>156</height>
            <format>L8</format>
          </image>
          <clip>
            <near>0.1</near>
            <far>100</far>
          </clip>
        </camera>
        <always_on>1</always_on>
        <update_rate>9</update_rate>
        <plugin
          filename="ignition-gazebo-thermal-sensor-system"
          name="ignition::gazebo::systems::ThermalSensor">
          <min_temp>253.15</min_temp>
          <max_temp>673.15</max_temp>
          <resolution>1.6</resolution>
        </plugin>
      </sensor>

      <!-- Real robot has 2 x B0203 with LN008 each with a 180 deg hor x 130 deg vert FOV
           Since fisheye cameras are not modeled, four cameras are used in the model -->
      <sensor name="camera_front" type="camera">
        <pose>0.3 0.06 0.365 0 0 0</pose>
        <always_on>1</always_on>
        <update_rate>25</update_rate>
        <camera name="camera_front">
          <horizontal_fov>1.658</horizontal_fov>
          <lens>
            <intrinsics>
              <!-- fx = fy = width / ( 2 * tan (hfov / 2 ) ) -->
              <fx>329.9</fx>
              <fy>329.9</fy>
              <!-- cx = ( width - 1 ) / 2 -->
              <cx>359.5</cx>
              <!-- cy = ( height - 1 ) / 2 -->
              <cy>539.5</cy>
              <s>0</s>
            </intrinsics>
          </lens>
          <distortion>
            <k1>0.0</k1>
            <k2>0.0</k2>
            <k3>0.0</k3>
            <p1>0.0</p1>
            <p2>0.0</p2>
            <center>0.5 0.5</center>
          </distortion>
          <image>
            <width>720</width>
            <height>1080</height>
            <format>R8G8B8</format>
          </image>
          <clip>
            <near>0.01</near>
            <far>300</far>
          </clip>
          <noise>
            <type>gaussian</type>
            <mean>0</mean>
            <stddev>0.007</stddev>
          </noise>
        </camera>
      </sensor>

      <sensor name="camera_rear" type="camera">
        <pose>0.08 0 0.365 0 0 3.141592653589793</pose>
        <always_on>1</always_on>
        <update_rate>25</update_rate>
        <camera name="camera_front">
          <horizontal_fov>1.658</horizontal_fov>
          <lens>
            <intrinsics>
              <!-- fx = fy = width / ( 2 * tan (hfov / 2 ) ) -->
              <fx>329.9</fx>
              <fy>329.9</fy>
              <!-- cx = ( width - 1 ) / 2 -->
              <cx>359.5</cx>
              <!-- cy = ( height - 1 ) / 2 -->
              <cy>539.5</cy>
              <s>0</s>
            </intrinsics>
          </lens>
          <distortion>
            <k1>0.0</k1>
            <k2>0.0</k2>
            <k3>0.0</k3>
            <p1>0.0</p1>
            <p2>0.0</p2>
            <center>0.5 0.5</center>
          </distortion>
          <image>
            <width>720</width>
            <height>1080</height>
            <format>R8G8B8</format>
          </image>
          <clip>
            <near>0.01</near>
            <far>300</far>
          </clip>
          <noise>
            <type>gaussian</type>
            <mean>0</mean>
            <stddev>0.007</stddev>
          </noise>
        </camera>
      </sensor>

      <sensor name="camera_left" type="camera">
        <pose>0.19 0.11 0.365 0 0 1.5707963267948966</pose>
        <always_on>1</always_on>
        <update_rate>25</update_rate>
        <camera name="camera_front">
          <horizontal_fov>1.658</horizontal_fov>
          <lens>
            <intrinsics>
              <!-- fx = fy = width / ( 2 * tan (hfov / 2 ) ) -->
              <fx>329.9</fx>
              <fy>329.9</fy>
              <!-- cx = ( width - 1 ) / 2 -->
              <cx>359.5</cx>
              <!-- cy = ( height - 1 ) / 2 -->
              <cy>539.5</cy>
              <s>0</s>
            </intrinsics>
          </lens>
          <distortion>
            <k1>0.0</k1>
            <k2>0.0</k2>
            <k3>0.0</k3>
            <p1>0.0</p1>
            <p2>0.0</p2>
            <center>0.5 0.5</center>
          </distortion>
          <image>
            <width>720</width>
            <height>1080</height>
            <format>R8G8B8</format>
          </image>
          <clip>
            <near>0.01</near>
            <far>300</far>
          </clip>
          <noise>
            <type>gaussian</type>
            <mean>0</mean>
            <stddev>0.007</stddev>
          </noise>
        </camera>
      </sensor>

      <sensor name="camera_right" type="camera">
        <pose>0.19 -0.11 0.365 0 0 -1.5707963267948966</pose>
        <always_on>1</always_on>
        <update_rate>25</update_rate>
        <camera name="camera_front">
          <horizontal_fov>1.658</horizontal_fov>
          <lens>
            <intrinsics>
              <!-- fx = fy = width / ( 2 * tan (hfov / 2 ) ) -->
              <fx>329.9</fx>
              <fy>329.9</fy>
              <!-- cx = ( width - 1 ) / 2 -->
              <cx>359.5</cx>
              <!-- cy = ( height - 1 ) / 2 -->
              <cy>539.5</cy>
              <s>0</s>
            </intrinsics>
          </lens>
          <distortion>
            <k1>0.0</k1>
            <k2>0.0</k2>
            <k3>0.0</k3>
            <p1>0.0</p1>
            <p2>0.0</p2>
            <center>0.5 0.5</center>
          </distortion>
          <image>
            <width>720</width>
            <height>1080</height>
            <format>R8G8B8</format>
          </image>
          <clip>
            <near>0.01</near>
            <far>300</far>
          </clip>
          <noise>
            <type>gaussian</type>
            <mean>0</mean>
            <stddev>0.007</stddev>
          </noise>
        </camera>
      </sensor>



      <sensor name="front_laser" type="gpu_lidar">
        <visualize>0</visualize>
        <update_rate>10</update_rate>
        <lidar>
          <scan>
            <horizontal>
              <samples>1800</samples>
              <resolution>1</resolution>
              <min_angle>-3.1459</min_angle>
              <max_angle>3.1459</max_angle>
            </horizontal>
            <vertical>
              <samples>16</samples>
              <resolution>1</resolution>
              <min_angle>-0.261799</min_angle>
              <max_angle>0.261799</max_angle>
            </vertical>
          </scan>
          <range>
            <min>0.05</min>
            <max>100</max>
            <resolution>0.01</resolution>
          </range>
          <noise>
            <type>gaussian</type>
            <mean>0</mean>
            <stddev>0.01</stddev>
          </noise>
        </lidar>
        <pose frame="">0.19 0 0.31 0 -0 0</pose>
      </sensor>

      
      <!-- Based on Intel realsense D435 (intrinsics and distortion not modeled)-->
      <sensor name="rgbd_front" type="rgbd_camera">
        <pose>0.28 0 0.353 0 0.46 0</pose>
        <always_on>1</always_on>
        <update_rate>30</update_rate>
        <camera name="rgbd_front">
          <horizontal_fov>1.50098</horizontal_fov>
          <lens>
            <intrinsics>
              <!-- fx = fy = width / ( 2 * tan (hfov / 2 ) ) -->
              <fx>343.159</fx>
              <fy>343.159</fy>
              <!-- cx = ( width - 1 ) / 2 -->
              <cx>319.5</cx>
              <!-- cy = ( height - 1 ) / 2 -->
              <cy>179.5</cy>
              <s>0</s>
            </intrinsics>
          </lens>
          <distortion>
            <k1>0.0</k1>
            <k2>0.0</k2>
            <k3>0.0</k3>
            <p1>0.0</p1>
            <p2>0.0</p2>
            <center>0.5 0.5</center>
          </distortion>
          <image>
            <width>640</width>
            <height>360</height>
            <format>R8G8B8</format>
          </image>
          <clip>
            <near>0.01</near>
            <far>300</far>
          </clip>
          <depth_camera>
            <clip>
              <near>0.1</near>
              <far>10</far>
            </clip>
          </depth_camera>
          <noise>
            <type>gaussian</type>
            <mean>0</mean>
            <stddev>0.007</stddev>
          </noise>
        </camera>
      </sensor>

      

      
      <sensor name="imu_sensor" type="imu">
        <always_on>1</always_on>
        <update_rate>50</update_rate>
        <imu>
          <enable_orientation>0</enable_orientation>
          <angular_velocity>
            <x>
              <noise type="gaussian">
                <mean>0</mean>
                <stddev>0.009</stddev>
                <bias_mean>0.00075</bias_mean>
                <bias_stddev>0.005</bias_stddev>
                <dynamic_bias_stddev>0.00002</dynamic_bias_stddev>
                <dynamic_bias_correlation_time>400.0</dynamic_bias_correlation_time>
                <precision>0.00025</precision>
              </noise>
            </x>
            <y>
              <noise type="gaussian">
                <mean>0</mean>
                <stddev>0.009</stddev>
                <bias_mean>0.00075</bias_mean>
                <bias_stddev>0.005</bias_stddev>
                <dynamic_bias_stddev>0.00002</dynamic_bias_stddev>
                <dynamic_bias_correlation_time>400.0</dynamic_bias_correlation_time>
                <precision>0.00025</precision>
              </noise>
            </y>
            <z>
              <noise type="gaussian">
                <mean>0</mean>
                <stddev>0.009</stddev>
                <bias_mean>0.00075</bias_mean>
                <bias_stddev>0.005</bias_stddev>
                <dynamic_bias_stddev>0.00002</dynamic_bias_stddev>
                <dynamic_bias_correlation_time>400.0</dynamic_bias_correlation_time>
                <precision>0.00025</precision>
              </noise>
            </z>
          </angular_velocity>
          <linear_acceleration>
            <x>
              <noise type="gaussian">
                <mean>0</mean>
                <stddev>0.021</stddev>
                <bias_mean>0.05</bias_mean>
                <bias_stddev>0.0075</bias_stddev>
                <dynamic_bias_stddev>0.000375</dynamic_bias_stddev>
                <dynamic_bias_correlation_time>175.0</dynamic_bias_correlation_time>
                <precision>0.005</precision>
              </noise>
            </x>
            <y>
              <noise type="gaussian">
                <mean>0</mean>
                <stddev>0.021</stddev>
                <bias_mean>0.05</bias_mean>
                <bias_stddev>0.0075</bias_stddev>
                <dynamic_bias_stddev>0.000375</dynamic_bias_stddev>
                <dynamic_bias_correlation_time>175.0</dynamic_bias_correlation_time>
                <precision>0.005</precision>
                            </noise>
            </y>
            <z>
              <noise type="gaussian">
                <mean>0</mean>
                <stddev>0.021</stddev>
                <bias_mean>0.05</bias_mean>
                <bias_stddev>0.0075</bias_stddev>
                <dynamic_bias_stddev>0.000375</dynamic_bias_stddev>
                <dynamic_bias_correlation_time>175.0</dynamic_bias_correlation_time>
                <precision>0.005</precision>
              </noise>
            </z>
          </linear_acceleration>
        </imu>
      </sensor>
	
      <sensor name="air_pressure" type="air_pressure">
        <always_on>1</always_on>
        <update_rate>20</update_rate>
        <air_pressure>
          <reference_altitude>0</reference_altitude>
          <noise type="gaussian">
            <mean>0.00000008</mean>
          </noise>
        </air_pressure>
      </sensor>
      <sensor name="magnetometer" type="magnetometer">
        <always_on>1</always_on>
        <update_rate>50</update_rate>
        <magnetometer>
          <x>
            <noise type="gaussian">
	      <mean>0.000000080</mean>
	      <bias_mean>0.000000400</bias_mean>
            </noise>
          </x>
          <y>
            <noise type="gaussian">
	      <mean>0.000000080</mean>
	      <bias_mean>0.000000400</bias_mean>
            </noise>
          </y>
          <z>
            <noise type="gaussian">
	      <mean>0.000000080</mean>
	      <bias_mean>0.000000400</bias_mean>
            </noise>
          </z>
        </magnetometer>
      </sensor>
      
      

    </link>
    <!-- Left Side Wheels  -->
    <link name="front_left_wheel_link">
      <pose frame="">0.360 0.26 0.00 0 -0 0</pose>
      <inertial>
        <pose frame="">0 0 0 0 -0 0</pose>
        <mass>1.5</mass>
        <inertia>
          <ixx>0.02467</ixx>
          <ixy>0</ixy>
          <ixz>0</ixz>
          <iyy>0.04411</iyy>
          <iyz>0</iyz>
          <izz>0.02467</izz>
        </inertia>
      </inertial>
      <collision name="front_left_wheel_link_collision">
        <pose frame="">0 0 0 1.5707963267948966 -0 0</pose>
        <geometry>
          <cylinder>
            <length>0.1</length>
            <radius>0.129</radius>
          </cylinder>
        </geometry>
        <surface>
          <contact>
            <ode>
              <kp>1e+07</kp>
              <kd>1</kd>
            </ode>
          </contact>
          <friction>
            <ode>
              <mu>0.5</mu>
              <mu2>1</mu2>
              <slip1>0.001</slip1>
              <slip2>0</slip2>
              <fdir1>0 0 1</fdir1>
            </ode>
          </friction>
        </surface>
      </collision>
    </link>
    <joint name="front_left_wheel_joint" type="revolute">
      <child>front_left_wheel_link</child>
      <parent>base_link</parent>
      <axis>
        <xyz>0 1 0</xyz>
        <limit>
          <lower>-1e+16</lower>
          <upper>1e+16</upper>
        </limit>
        <dynamics>
          <spring_reference>0</spring_reference>
          <spring_stiffness>0</spring_stiffness>
        </dynamics>
        <use_parent_model_frame>1</use_parent_model_frame>
      </axis>
    </joint>
    <link name="front_middle_left_wheel_link">
      <pose frame="">0.120 0.26 0.00 0 -0 0</pose>
      <inertial>
        <pose frame="">0 0 0 0 -0 0</pose>
        <mass>1.5</mass>
        <inertia>
          <ixx>0.02467</ixx>
          <ixy>0</ixy>
          <ixz>0</ixz>
          <iyy>0.04411</iyy>
          <iyz>0</iyz>
          <izz>0.02467</izz>
        </inertia>
      </inertial>
      <collision name="front_middle_left_wheel_link_collision">
        <pose frame="">0 0 0 1.5707963267948966 -0 0</pose>
        <geometry>
          <cylinder>
            <length>0.1</length>
            <radius>0.129</radius>
          </cylinder>
        </geometry>
        <surface>
          <contact>
            <ode>
              <kp>1e+07</kp>
              <kd>1</kd>
            </ode>
          </contact>
          <friction>
            <ode>
              <mu>0.5</mu>
              <mu2>1</mu2>
              <slip1>0.001</slip1>
              <slip2>0</slip2>
              <fdir1>0 0 1</fdir1>
            </ode>
          </friction>
        </surface>
      </collision>
    </link>
    <joint name="front_middle_left_wheel_joint" type="revolute">
      <child>front_middle_left_wheel_link</child>
      <parent>base_link</parent>
      <axis>
        <xyz>0 1 0</xyz>
        <limit>
          <lower>-1e+16</lower>
          <upper>1e+16</upper>
        </limit>
        <dynamics>
          <spring_reference>0</spring_reference>
          <spring_stiffness>0</spring_stiffness>
        </dynamics>
        <use_parent_model_frame>1</use_parent_model_frame>
      </axis>
    </joint>
    <link name="rear_middle_left_wheel_link">
      <pose frame="">-0.120 0.26 0.00 0 -0 0</pose>
      <inertial>
        <pose frame="">0 0 0 0 -0 0</pose>
        <mass>1.5</mass>
        <inertia>
          <ixx>0.02467</ixx>
          <ixy>0</ixy>
          <ixz>0</ixz>
          <iyy>0.04411</iyy>
          <iyz>0</iyz>
          <izz>0.02467</izz>
        </inertia>
      </inertial>
      <collision name="rear_middle_left_wheel_link_collision">
        <pose frame="">0 0 0 1.5707963267948966 -0 0</pose>
        <geometry>
          <cylinder>
            <length>0.1</length>
            <radius>0.129</radius>
          </cylinder>
        </geometry>
        <surface>
          <contact>
            <ode>
              <kp>1e+07</kp>
              <kd>1</kd>
            </ode>
          </contact>
          <friction>
            <ode>
              <mu>0.5</mu>
              <mu2>1</mu2>
              <slip1>0.001</slip1>
              <slip2>0</slip2>
              <fdir1>0 0 1</fdir1>
            </ode>
          </friction>
        </surface>
      </collision>
    </link>
    <joint name="rear_middle_left_wheel_joint" type="revolute">
      <child>rear_middle_left_wheel_link</child>
      <parent>base_link</parent>
      <axis>
        <xyz>0 1 0</xyz>
        <limit>
          <lower>-1e+16</lower>
          <upper>1e+16</upper>
        </limit>
        <dynamics>
          <spring_reference>0</spring_reference>
          <spring_stiffness>0</spring_stiffness>
        </dynamics>
        <use_parent_model_frame>1</use_parent_model_frame>
      </axis>
    </joint>
    <link name="rear_left_wheel_link">
      <pose frame="">-0.36 0.26 0.0 0 -0 0</pose>
      <inertial>
        <pose frame="">0 0 0 0 -0 0</pose>
        <mass>1.5</mass>
        <inertia>
          <ixx>0.02467</ixx>
          <ixy>0</ixy>
          <ixz>0</ixz>
          <iyy>0.04411</iyy>
          <iyz>0</iyz>
          <izz>0.02467</izz>
        </inertia>
      </inertial>
      <collision name="rear_left_wheel_link_collision">
        <pose frame="">0 0 0 1.5707963267948966 -0 0</pose>
        <geometry>
          <cylinder>
            <length>0.1</length>
            <radius>0.129</radius>
          </cylinder>
        </geometry>
        <surface>
          <contact>
            <ode>
              <kp>1e+07</kp>
              <kd>1</kd>
            </ode>
          </contact>
          <friction>
            <ode>
              <mu>0.5</mu>
              <mu2>1</mu2>
              <slip1>0.001</slip1>
              <slip2>0</slip2>
              <fdir1>0 0 1</fdir1>
            </ode>
          </friction>
        </surface>
      </collision>
    </link>
    <joint name="rear_left_wheel_joint" type="revolute">
      <child>rear_left_wheel_link</child>
      <parent>base_link</parent>
      <axis>
        <xyz>0 1 0</xyz>
        <limit>
          <lower>-1e+16</lower>
          <upper>1e+16</upper>
        </limit>
        <dynamics>
          <spring_reference>0</spring_reference>
          <spring_stiffness>0</spring_stiffness>
        </dynamics>
        <use_parent_model_frame>1</use_parent_model_frame>
      </axis>
    </joint>
    <!-- Right Side Wheels -->
    <link name="front_right_wheel_link">
      <pose frame="">0.360 -0.26 0.00 0 -0 0</pose>
      <inertial>
        <pose frame="">0 0 0 0 -0 0</pose>
        <mass>1.5</mass>
        <inertia>
          <ixx>0.02467</ixx>
          <ixy>0</ixy>
          <ixz>0</ixz>
          <iyy>0.04411</iyy>
          <iyz>0</iyz>
          <izz>0.02467</izz>
        </inertia>
      </inertial>
      <collision name="front_right_wheel_link_collision">
        <pose frame="">0 0 0 1.5707963267948966 -0 0</pose>
        <geometry>
          <cylinder>
            <length>0.1</length>
            <radius>0.129</radius>
          </cylinder>
        </geometry>
        <surface>
          <contact>
            <ode>
              <kp>1e+07</kp>
              <kd>1</kd>
            </ode>
          </contact>
          <friction>
            <ode>
              <mu>0.5</mu>
              <mu2>1</mu2>
              <slip1>0.001</slip1>
              <slip2>0</slip2>
              <fdir1>0 0 1</fdir1>
            </ode>
          </friction>
        </surface>
      </collision>
    </link>
    <joint name="front_right_wheel_joint" type="revolute">
      <child>front_right_wheel_link</child>
      <parent>base_link</parent>
      <axis>
        <xyz>0 1 0</xyz>
        <limit>
          <lower>-1e+16</lower>
          <upper>1e+16</upper>
        </limit>
        <dynamics>
          <spring_reference>0</spring_reference>
          <spring_stiffness>0</spring_stiffness>
        </dynamics>
        <use_parent_model_frame>1</use_parent_model_frame>
      </axis>
    </joint>
    <link name="front_middle_right_wheel_link">
      <pose frame="">0.120 -0.26 0.00 0 -0 0</pose>
      <inertial>
        <pose frame="">0 0 0 0 -0 0</pose>
        <mass>1.5</mass>
        <inertia>
          <ixx>0.02467</ixx>
          <ixy>0</ixy>
          <ixz>0</ixz>
          <iyy>0.04411</iyy>
          <iyz>0</iyz>
          <izz>0.02467</izz>
        </inertia>
      </inertial>
      <collision name="front_middle_right_wheel_link_collision">
        <pose frame="">0 0 0 1.5707963267948966 -0 0</pose>
        <geometry>
          <cylinder>
            <length>0.1</length>
            <radius>0.129</radius>
          </cylinder>
        </geometry>
        <surface>
          <contact>
            <ode>
              <kp>1e+07</kp>
              <kd>1</kd>
            </ode>
          </contact>
          <friction>
            <ode>
              <mu>0.5</mu>
              <mu2>1</mu2>
              <slip1>0.001</slip1>
              <slip2>0</slip2>
              <fdir1>0 0 1</fdir1>
            </ode>
          </friction>
        </surface>
      </collision>
    </link>
    <joint name="front_middle_right_wheel_joint" type="revolute">
      <child>front_middle_right_wheel_link</child>
      <parent>base_link</parent>
      <axis>
        <xyz>0 1 0</xyz>
        <limit>
          <lower>-1e+16</lower>
          <upper>1e+16</upper>
        </limit>
        <dynamics>
          <spring_reference>0</spring_reference>
          <spring_stiffness>0</spring_stiffness>
        </dynamics>
        <use_parent_model_frame>1</use_parent_model_frame>
      </axis>
    </joint>
    <link name="rear_middle_right_wheel_link">
      <pose frame="">-0.120 -0.26 0.00 0 -0 0</pose>
      <inertial>
        <pose frame="">0 0 0 0 -0 0</pose>
        <mass>1.5</mass>
        <inertia>
          <ixx>0.02467</ixx>
          <ixy>0</ixy>
          <ixz>0</ixz>
          <iyy>0.04411</iyy>
          <iyz>0</iyz>
          <izz>0.02467</izz>
        </inertia>
      </inertial>
      <collision name="rear_middle_right_wheel_link_collision">
        <pose frame="">0 0 0 1.5707963267948966 -0 0</pose>
        <geometry>
          <cylinder>
            <length>0.1</length>
            <radius>0.129</radius>
          </cylinder>
        </geometry>
        <surface>
          <contact>
            <ode>
              <kp>1e+07</kp>
              <kd>1</kd>
            </ode>
          </contact>
          <friction>
            <ode>
              <mu>0.5</mu>
              <mu2>1</mu2>
              <slip1>0.001</slip1>
              <slip2>0</slip2>
              <fdir1>0 0 1</fdir1>
            </ode>
          </friction>
        </surface>
      </collision>
    </link>
    <joint name="rear_middle_right_wheel_joint" type="revolute">
      <child>rear_middle_right_wheel_link</child>
      <parent>base_link</parent>
      <axis>
        <xyz>0 1 0</xyz>
        <limit>
          <lower>-1e+16</lower>
          <upper>1e+16</upper>
        </limit>
        <dynamics>
          <spring_reference>0</spring_reference>
          <spring_stiffness>0</spring_stiffness>
        </dynamics>
        <use_parent_model_frame>1</use_parent_model_frame>
      </axis>
    </joint>
    <link name="rear_right_wheel_link">
      <pose frame="">-0.36 -0.26 0.0 0 -0 0</pose>
      <inertial>
        <pose frame="">0 0 0 0 -0 0</pose>
        <mass>1.5</mass>
        <inertia>
          <ixx>0.02467</ixx>
          <ixy>0</ixy>
          <ixz>0</ixz>
          <iyy>0.04411</iyy>
          <iyz>0</iyz>
          <izz>0.02467</izz>
        </inertia>
      </inertial>
      <collision name="rear_right_wheel_link_collision">
        <pose frame="">0 0 0 1.5707963267948966 -0 0</pose>
        <geometry>
          <cylinder>
            <length>0.1</length>
            <radius>0.129</radius>
          </cylinder>
        </geometry>
        <surface>
          <contact>
            <ode>
              <kp>1e+07</kp>
              <kd>1</kd>
            </ode>
          </contact>
          <friction>
            <ode>
              <mu>0.5</mu>
              <mu2>1</mu2>
              <slip1>0.001</slip1>
              <slip2>0</slip2>
              <fdir1>0 0 1</fdir1>
            </ode>
          </friction>
        </surface>
      </collision>
    </link>
    <joint name="rear_right_wheel_joint" type="revolute">
      <child>rear_right_wheel_link</child>
      <parent>base_link</parent>
      <axis>
        <xyz>0 1 0</xyz>
        <limit>
          <lower>-1e+16</lower>
          <upper>1e+16</upper>
        </limit>
        <dynamics>
          <spring_reference>0</spring_reference>
          <spring_stiffness>0</spring_stiffness>
        </dynamics>
        <use_parent_model_frame>1</use_parent_model_frame>
      </axis>
    </joint>
  </model>
</sdf>
