<?xml version="1.0"?>
<sdf version="1.6">
    <model name="marble_qav500_sensor_config_1">
        <pose>0 0 0.121078 0 0 0</pose>
        <link name="base_link">
            <pose frame="">0 0 0 0 -0 0</pose>
            <inertial>
                <pose frame="">0 0 0 0 -0 0</pose>
                <mass>3</mass>
                <inertia>
                    <ixx>0.03567</ixx>
                    <ixy>0</ixy>
                    <ixz>0.0006</ixz>
                    <iyy>0.05534</iyy>
                    <iyz>0</iyz>
                    <izz>0.0847</izz>
                </inertia>
            </inertial>
            <collision name="base_link_inertia_collision">
                <pose frame="">0 0 0 0 -0 0</pose>
                <geometry>
                    <box>
                        <size>0.3 0.3 0.25</size>
                    </box>
                </geometry>
            </collision>
            <visual name="base_link_inertia_visual">
                <pose frame="">0 0 -0.12 0 0 0</pose>
                <geometry>
                <material>
                    <diffuse>0.5 0.5 0.5 1</diffuse>
                    <ambient>.5 .5 .5 1</ambient>

                    <!-- <script>
                        <name>Gazebo/Blue</name>
                        <uri>file://media/materials/scripts/gazebo.material</uri>
                    </script> -->
                </material>
                    <mesh>
                        <scale>1 1 1</scale>
                        <uri>meshes/qav500.stl</uri>
                    </mesh>
                </geometry>
            </visual>

            <!-- <visual name="marker_visual_1">
                <pose frame="">-0.1 0 0.077 0 -0.1 0</pose>
                <geometry>
                    <mesh>
                        <scale>1 1 1</scale>
                        <uri>meshes/led.dae</uri>
                    </mesh>
                </geometry>
            </visual>
            <visual name="marker_visual_2">
                <pose frame="">-0.09 0.059 0.059 -0.785397 -0 0.2</pose>
                <geometry>
                    <mesh>
                        <scale>1 1 1</scale>
                        <uri>meshes/led.dae</uri>
                    </mesh>
                </geometry>
            </visual>
            <visual name="marker_visual_3">
                <pose frame="">-0.09 -0.059 0.059 0.785397 -0 -0.2</pose>
                <geometry>
                    <mesh>
                        <scale>1 1 1</scale>
                        <uri>meshes/led.dae</uri>
                    </mesh>
                </geometry>
            </visual>
            <visual name="downward_flashlight_visual">
                <pose frame="">-0.043704 0 0.102914 -0.2 0.000158 -1.57002</pose>
                <geometry>
                    <mesh>
                        <scale>0.01 0.01 0.01</scale>
                        <uri>meshes/spotlight.dae</uri>
                    </mesh>
                </geometry>
            </visual>
            <visual name="left_flashlight_visual">
                <pose frame="">0.11 0.039 -0.066102 0.06 -4.8e-05 -1.27</pose>
                <geometry>
                    <mesh>
                        <scale>0.01 0.01 0.01</scale>
                        <uri>meshes/spotlight.dae</uri>
                    </mesh>
                </geometry>
            </visual>
            <visual name="right_flashlight_visual">
                <pose frame="">0.11 -0.039 -0.066102 0.06 -4.8e-05 -1.87</pose>
                <geometry>
                    <mesh>
                        <scale>0.01 0.01 0.01</scale>
                        <uri>meshes/spotlight.dae</uri>
                    </mesh>
                </geometry>
            </visual> -->
            <visual name="right_flashlight_visual">
                <pose frame="">0.15 0 -0.034102 0 0 -1.5708</pose>
                <geometry>
                    <mesh>
                        <scale>0.01 0.01 0.01</scale>
                        <uri>meshes/spotlight.dae</uri>
                    </mesh>
                </geometry>
            </visual>
            <light name="right_light_source" type="spot">
                <pose frame="">0.25 0 -0.04 3.1416 -1.5107899999999999 3.1416</pose>
                <attenuation>
                    <range>15</range>
                    <linear>0</linear>
                    <constant>0.1</constant>
                    <quadratic>0.01</quadratic>
                </attenuation>
                <diffuse>0.8 0.8 0.5 1</diffuse>
                <specular>0.8 0.8 0.5 1</specular>
                <spot>
                    <inner_angle>1</inner_angle>
                    <outer_angle>1.1</outer_angle>
                    <falloff>1</falloff>
                </spot>
                <direction>0 0 -1</direction>
                <cast_shadows>1</cast_shadows>
            </light>

            <!-- <light name="right_light_source" type="spot">
                <pose frame="">-0.0 -0.11 0.07 3.131592653589795 -1.5107899999999999 2.841592653589791</pose>
                <attenuation>
                    <range>15</range>
                    <linear>0</linear>
                    <constant>0.1</constant>
                    <quadratic>0.01</quadratic>
                </attenuation>
                <diffuse>0.8 0.8 0.5 1</diffuse>
                <specular>0.8 0.8 0.5 1</specular>
                <spot>
                    <inner_angle>1</inner_angle>
                    <outer_angle>1.1</outer_angle>
                    <falloff>1</falloff>
                </spot>
                <direction>0 0 -1</direction>
                <cast_shadows>1</cast_shadows>
            </light>
            <light name="downward_flashlight_source" type="spot">
                <pose frame="">0.03 0 0.09 -0.01 -1.3708026535897933 0</pose>
                <attenuation>
                    <range>15</range>
                    <linear>0</linear>
                    <constant>0.1</constant>
                    <quadratic>0.01</quadratic>
                </attenuation>
                <diffuse>0.8 0.8 0.5 1</diffuse>
                <specular>0.8 0.8 0.5 1</specular>
                <spot>
                    <inner_angle>1</inner_angle>
                    <outer_angle>1.1</outer_angle>
                    <falloff>1</falloff>
                </spot>
                <direction>0 0 -1</direction>
                <cast_shadows>1</cast_shadows>
            </light>
            <light name="left_flashlight_source" type="spot">
                <pose frame="">-0.0 0.11 0.07 3.131592653589795 -1.5107899999999999 -2.841592653589791</pose>
                <attenuation>
                    <range>15</range>
                    <linear>0</linear>
                    <constant>0.1</constant>
                    <quadratic>0.01</quadratic>
                </attenuation>
                <diffuse>0.8 0.8 0.5 1</diffuse>
                <specular>0.8 0.8 0.5 1</specular>
                <spot>
                    <inner_angle>1</inner_angle>
                    <outer_angle>1.1</outer_angle>
                    <falloff>1</falloff>
                </spot>
                <direction>0 0 -1</direction>
                <cast_shadows>1</cast_shadows>
            </light> -->
            <!-- MARBLE QAV500 uses the Lord Microstrain 3DM-GX5-15 IMU/AHRS with 
		the following noise density terms:
		Datasheet: https://www.microstrain.com/sites/default/files/applications/files/3dm-gx5-15_datasheet_8400-0094_rev_m.pdf
		
		We derived the stddev terms as follows:

		accelerometer noise density = 0.00002 g/sqrt(Hz) 
			=> convert to m/s^2 => 1.962e-4 m/s^2
		gyro noise density = 0.005 deg/s/sqrt(Hz)
			=> convert to rad/sec => 8.72664e-5 radians

		Other terms are difficult to extract from datasheet, so we used similar terms to previous IMU models proposed (of similar or worse quality) such as the ADIS 16448 (which has worse performance than this IMU). 
		-->
	      <sensor name="imu_sensor" type="imu">
		<always_on>1</always_on>
		<update_rate>250</update_rate>
		
		<imu>
		  <angular_velocity>
		    <x>
		      <noise type="gaussian">
		        <mean>0</mean>
		        <stddev>8.72664e-5</stddev>
		        <bias_mean>7.5e-6</bias_mean>
		        <bias_stddev>8.0e-7</bias_stddev>
		        <dynamic_bias_stddev>4e-7</dynamic_bias_stddev>
		        <dynamic_bias_correlation_time>1000.0</dynamic_bias_correlation_time>
		      </noise>
		    </x>
		    <y>
		      <noise type="gaussian">
		        <mean>0</mean>
		        <stddev>8.72664e-5</stddev>
		        <bias_mean>7.5e-6</bias_mean>
		        <bias_stddev>8.0e-7</bias_stddev>
		        <dynamic_bias_stddev>4e-7</dynamic_bias_stddev>
		        <dynamic_bias_correlation_time>1000.0</dynamic_bias_correlation_time>
		      </noise>
		    </y>
		    <z>
		      <noise type="gaussian">
		        <mean>0</mean>
		        <stddev>8.72664e-5</stddev>
		        <bias_mean>7.5e-6</bias_mean>
		        <bias_stddev>8.0e-7</bias_stddev>
		        <dynamic_bias_stddev>4e-7</dynamic_bias_stddev>
		        <dynamic_bias_correlation_time>1000.0</dynamic_bias_correlation_time>
		      </noise>
		    </z>
		  </angular_velocity>
		  <linear_acceleration>
		    <x>
		      <noise type="gaussian">
		        <mean>0</mean>
		        <stddev>1.962e-4</stddev>
		        <bias_mean>1.0e-3</bias_mean>
		        <bias_stddev>1.0-4</bias_stddev>
		        <dynamic_bias_stddev>1.0e-3</dynamic_bias_stddev>
		        <dynamic_bias_correlation_time>300.0</dynamic_bias_correlation_time>
		      </noise>
		    </x>
		    <y>
		      <noise type="gaussian">
		        <mean>0</mean>
		        <stddev>1.962e-4</stddev>
		        <bias_mean>1.0e-3</bias_mean>
		        <bias_stddev>1.0-4</bias_stddev>
		        <dynamic_bias_stddev>1.0e-3</dynamic_bias_stddev>
		        <dynamic_bias_correlation_time>300.0</dynamic_bias_correlation_time>
		      </noise>
		    </y>
		    <z>
		      <noise type="gaussian">
		        <mean>0</mean>
		        <stddev>1.962e-4</stddev>
		        <bias_mean>1.0e-3</bias_mean>
		        <bias_stddev>1.0-4</bias_stddev>
		        <dynamic_bias_stddev>1.0e-3</dynamic_bias_stddev>
		        <dynamic_bias_correlation_time>300.0</dynamic_bias_correlation_time>
		      </noise>
		    </z>
		  </linear_acceleration>
		</imu>
	      </sensor>
            <sensor name="air_pressure" type="air_pressure">
                <always_on>1</always_on>
                <update_rate>20</update_rate>
                <air_pressure>
                    <reference_altitude>0</reference_altitude>
                    <noise type="gaussian">
                        <mean>0.00000008</mean>
                    </noise>
                </air_pressure>
            </sensor>
            <sensor name="magnetometer" type="magnetometer">
                <always_on>1</always_on>
                <update_rate>20</update_rate>
                <magnetometer>
                    <x>
                        <noise type="gaussian">
                            <mean>0.000000080</mean>
                            <bias_mean>0.000000400</bias_mean>
                        </noise>
                    </x>
                    <y>
                        <noise type="gaussian">
                            <mean>0.000000080</mean>
                            <bias_mean>0.000000400</bias_mean>
                        </noise>
                    </y>
                    <z>
                        <noise type="gaussian">
                            <mean>0.000000080</mean>
                            <bias_mean>0.000000400</bias_mean>
                        </noise>
                    </z>
                </magnetometer>
            </sensor>


            <!-- <visual name="camera_mount_base_visual">
                <pose>0.05 0 -0.030 0 0.0 0</pose>
                <geometry>
                    <box>
                        <size>0.06 0.06 0.006</size>
                    </box>
                </geometry>
            </visual>
            <visual name="camera_mount_arm_visual">
                <pose>0.08 0 -0.040 0 0.0 0</pose>
                <geometry>
                    <cylinder>
                        <radius>0.005</radius>
                        <length>0.08</length>
                    </cylinder>
                </geometry>
            </visual>
            <visual name="camera_mount_arm2_visual">
                <pose>0.08 0 -0.08 0 1.57 0</pose>
                <geometry>
                    <cylinder>
                        <radius>0.01</radius>
                        <length>0.025</length>
                    </cylinder>
                </geometry>
            </visual> -->

            <visual name="camera_visual">
                <pose>0.27 0 0.03 0 0 0</pose>
                <geometry>
                    <box>
                        <size>0.025 0.09 0.025</size>
                    </box>
                </geometry>
            </visual>
            <!-- Based on Intel realsense D435 (intrinsics and distortion not modeled)-->
            <sensor name="camera_front" type="rgbd_camera">
                <camera name="camera_front">
                    <horizontal_fov>1.5184</horizontal_fov>
                    <lens>
                        <intrinsics>
                            <!-- fx = fy = width / ( 2 * tan (hfov / 2 ) ) -->
                            <fx>277.1</fx>
                            <fy>277.1</fy>
                            <!-- cx = ( width + 1 ) / 2 -->
                            <cx>640.5</cx>
                            <!-- cy = ( height + 1 ) / 2 -->
                            <cy>360.5</cy>
                            <s>0</s>
                        </intrinsics>
                    </lens>
                    <distortion>
                        <k1>0.0</k1>
                        <k2>0.0</k2>
                        <k3>0.0</k3>
                        <p1>0.0</p1>
                        <p2>0.0</p2>
                        <center>0.5 0.5</center>
                    </distortion>
                    <image>
                        <width>1280</width>
                        <height>720</height>
                        <format>R8G8B8</format>
                    </image>
                    <clip>
                        <near>0.01</near>
                        <far>300</far>
                    </clip>
                    <depth_camera>
                    <clip>
                        <near>0.1</near>
                        <far>10</far>
                    </clip>
                    </depth_camera>
                    <noise>
                        <type>gaussian</type>
                        <mean>0</mean>
                        <stddev>0.007</stddev>
                    </noise>
                </camera>
                <always_on>1</always_on>
                <update_rate>30</update_rate>
                <visualize>0</visualize>
                <pose frame="">0.27 0 0.03 0 -0 0</pose>
            </sensor>
            <visual name="laser_visual">
                <pose>0 0 -0.05 0 0 0</pose>
                <geometry>
                    <cylinder>
                        <radius>0.03</radius>
                        <length>0.1</length>
                    </cylinder>
                </geometry>
            </visual>
            <sensor name="front_laser" type="gpu_ray">
				<!-- Lidar is based on ouster OS1-64 -->
                <pose>0 0 -0.05 0 0 0</pose>
                <update_rate>15</update_rate>
                <lidar>
                    <scan>
                        <horizontal>
                            <!-- Resolution can't be above 16k, see
                            https://bitbucket.org/ignitionrobotics/ign-sensors/issues/8 -->
                            <samples>1024</samples>
                            <resolution>0.006</resolution>
                            <min_angle>-3.1459</min_angle>
                            <max_angle>3.1459</max_angle>
                        </horizontal>
                        <vertical>
                            <samples>64</samples>
                            <resolution>1</resolution>
                            <min_angle>-0.3927</min_angle>
                            <max_angle>0.3927</max_angle>
                        </vertical>
                    </scan>
                    <range>
                        <min>0.05</min>
                        <max>120</max>
                        <resolution>0.01</resolution>
                    </range>
                    <noise>
                        <type>gaussian</type>
                        <mean>0</mean>
                        <stddev>0.01</stddev>
                    </noise>
                </lidar>
            </sensor>
            <!-- Modeled from the Pico flexx tof cameras-->
            <sensor name="tof_top" type="depth_camera">
                <pose>0.24 0 0.055 0 -1.57 0</pose>
                <camera name="tof_top">
                    
                    <horizondal_fov>1.0821</horizondal_fov>
                    <image>
                        <width>224</width>
                        <height>171</height>
                        <format>R8G8B8</format>
                    </image>
                    <clip>
                        <near>0.1</near>
                        <far>4.0</far>
                    </clip>
                    <depth_camera>
                        <output>depths</output>
                        <clip>
                            <near>0.1</near>
                            <far>4.0</far>
                        </clip>
                    </depth_camera>
                </camera>
                <always_on>1</always_on>
                <update_rate>30</update_rate>
                <visualize>0</visualize>
            </sensor>

            <visual name="tof_top_visual">
                <pose>0.24 0 0.055 0 0 0</pose>
                <geometry>
                    <box>
                        <size>0.017 0.068 0.00735</size>
                    </box>
                </geometry>
            </visual>

            <sensor name="tof_bottom" type="depth_camera">
                <pose>0.24 0 0.00 0 1.57 0</pose>
                <camera name="tof_top">
                    
                    <horizondal_fov>1.0821</horizondal_fov>
                    <image>
                        <width>224</width>
                        <height>171</height>
                        <format>R8G8B8</format>
                    </image>
                    <clip>
                        <near>0.1</near>
                        <far>4.0</far>
                    </clip>
                    <depth_camera>
                        <output>depths</output>
                        <clip>
                            <near>0.1</near>
                            <far>4.0</far>
                        </clip>
                    </depth_camera>
                </camera>
                <always_on>1</always_on>
                <update_rate>30</update_rate>
                <visualize>0</visualize>
            </sensor>

            <visual name="tof_bottom_visual">
                <pose>0.24 0 0.006 0 0 0</pose>
                <geometry>
                    <box>
                        <size>0.017 0.068 0.00735</size>
                    </box>
                </geometry>
            </visual>

            <!-- <sensor name="tof_top" type="rgbd_camera">
                <camera name="tof_top">
                    <horizontal_fov>1.5184</horizontal_fov>
                    <lens>
                        <intrinsics>
                            <fx>277.1</fx>
                            <fy>277.1</fy>
                            <cx>640.5</cx>
                            <cy>360.5</cy>
                            <s>0</s>
                        </intrinsics>
                    </lens>
                    <distortion>
                        <k1>0.0</k1>
                        <k2>0.0</k2>
                        <k3>0.0</k3>
                        <p1>0.0</p1>
                        <p2>0.0</p2>
                        <center>0.5 0.5</center>
                    </distortion>
                    <image>
                        <width>1280</width>
                        <height>720</height>
                        <format>R8G8B8</format>
                    </image>
                    <clip>
                        <near>0.01</near>
                        <far>300</far>
                    </clip>
                    <depth_camera>
                    <clip>
                        <near>0.1</near>
                        <far>10</far>
                    </clip>
                    </depth_camera>
                    <noise>
                        <type>gaussian</type>
                        <mean>0</mean>
                        <stddev>0.007</stddev>
                    </noise>
                </camera>
                <always_on>1</always_on>
                <update_rate>30</update_rate>
                <visualize>0</visualize>
                <pose frame="">0 0 0.03 -1.57 0 0</pose>
            </sensor> -->

            <!-- <sensor name="top_laser" type="gpu_ray">
                <pose>0.0 0 0.1 0 1.57 0</pose>
                <update_rate>50</update_rate>
                <lidar>
                    <scan>
                        <horizontal>
                            <samples>1</samples>
                            <resolution>1</resolution>
                            <min_angle>3.141592654</min_angle>
                            <max_angle>3.141592654</max_angle>
                        </horizontal>
                    </scan>
                    <range>
                        <min>0.04</min>
                        <max>40</max>
                        <resolution>0.01</resolution>
                    </range>
                    <noise>
                        <type>gaussian</type>
                        <mean>0</mean>
                        <stddev>0.01</stddev>
                    </noise>
                </lidar>
            </sensor>
            <sensor name="bottom_laser" type="gpu_ray">
                <pose>0.0 0 -0.02 0 -1.57 0</pose>
                <update_rate>50</update_rate>
                <lidar>
                    <scan>
                        <horizontal>
                            <samples>1</samples>
                            <resolution>1</resolution>
                            <min_angle>3.141592654</min_angle>
                            <max_angle>3.141592654</max_angle>
                        </horizontal>
                    </scan>
                    <range>
                        <min>0.04</min>
                        <max>40</max>
                        <resolution>0.01</resolution>
                    </range>
                    <noise>
                        <type>gaussian</type>
                        <mean>0</mean>
                        <stddev>0.01</stddev>
                    </noise>
                </lidar>
            </sensor> -->
        </link>
        <link name="rotor_0">
            <pose frame="">0.206069 0.206092 0.028 0 0 0.523599</pose>
            <inertial>
                <pose frame="">0 0 0 0 -0 0</pose>
                <mass>0.005</mass>
                <inertia>
                    <ixx>9.75e-07</ixx>
                    <ixy>0</ixy>
                    <ixz>0</ixz>
                    <iyy>8.13545e-05</iyy>
                    <iyz>0</iyz>
                    <izz>8.22545e-05</izz>
                </inertia>
            </inertial>
            <collision name="rotor_0_collision">
                <pose frame="">0 0 0 0 -0 0</pose>
                <geometry>
                    <cylinder>
                        <length>0.005</length>
                        <radius>0.1397</radius>
                    </cylinder>
                </geometry>
                <surface>
                    <contact>
                        <ode/>
                    </contact>
                    <friction>
                        <ode/>
                    </friction>
                </surface>
            </collision>
            <visual name="rotor_0_visual">
                <pose frame="">0 0 0 0 -0 0</pose>
                <geometry>
                    <mesh>
                        <scale>1 1 1</scale>
                        <uri>meshes/neo11_propeller_ccw.dae</uri>
                    </mesh>
                </geometry>
                <material>
                    <diffuse>1 0 0 1</diffuse>
                    <script>
                        <name>Gazebo/Red</name>
                        <uri>materials/scripts/gazebo.material</uri>
                    </script>
                </material>
                <cast_shadows>0</cast_shadows>
            </visual>
            <gravity>1</gravity>
            <velocity_decay/>
        </link>
        <joint name="rotor_0_joint" type="revolute">
            <child>rotor_0</child>
            <parent>base_link</parent>
            <axis>
                <!-- <xyz>0.043578 -0.075479 0.996195</xyz> -->
                <xyz>0 0 1</xyz>
                <limit>
                    <lower>-1e+16</lower>
                    <upper>1e+16</upper>
                </limit>
                <dynamics>
                    <spring_reference>0</spring_reference>
                    <spring_stiffness>0</spring_stiffness>
                </dynamics>
                <use_parent_model_frame>1</use_parent_model_frame>
            </axis>
        </joint>
        <link name="rotor_1">
            <pose frame="">-0.206432 0.205944 0.028 0 0 0</pose>
            <inertial>
                <pose frame="">0 0 0 0 -0 0</pose>
                <mass>0.005</mass>
                <inertia>
                    <ixx>9.75e-07</ixx>
                    <ixy>0</ixy>
                    <ixz>0</ixz>
                    <iyy>8.13545e-05</iyy>
                    <iyz>0</iyz>
                    <izz>8.22545e-05</izz>
                </inertia>
            </inertial>
            <collision name="rotor_1_collision">
                <pose frame="">0 0 0 0 -0 0</pose>
                <geometry>
                    <cylinder>
                        <length>0.005</length>
                        <radius>0.1397</radius>
                    </cylinder>
                </geometry>
                <surface>
                    <contact>
                        <ode/>
                    </contact>
                    <friction>
                        <ode/>
                    </friction>
                </surface>
            </collision>
            <visual name="rotor_1_visual">
                <pose frame="">0 0 0 0 -0 0</pose>
                <geometry>
                    <mesh>
                        <scale>1 1 1</scale>
                        <uri>meshes/neo11_propeller_cw.dae</uri>
                    </mesh>
                </geometry>
                <material>
                    <diffuse>0 0 1 1</diffuse>
                    <script>
                        <name>Gazebo/Blue</name>
                        <uri>materials/scripts/gazebo.material</uri>
                    </script>
                </material>
                <cast_shadows>0</cast_shadows>
            </visual>
            <gravity>1</gravity>
            <velocity_decay/>
        </link>
        <joint name="rotor_1_joint" type="revolute">
            <child>rotor_1</child>
            <parent>base_link</parent>
            <axis>
                <xyz>0 0 1</xyz>
                <limit>
                    <lower>-1e+16</lower>
                    <upper>1e+16</upper>
                </limit>
                <dynamics>
                    <spring_reference>0</spring_reference>
                    <spring_stiffness>0</spring_stiffness>
                </dynamics>
                <use_parent_model_frame>1</use_parent_model_frame>
            </axis>
        </joint>
        <!-- <link name="rotor_2">
            <pose frame="">-0.2501 0.1454 0.028 0.087267 -0 2.61799</pose>
            <inertial>
                <pose frame="">0 0 0 0 -0 0</pose>
                <mass>0.005</mass>
                <inertia>
                    <ixx>9.75e-07</ixx>
                    <ixy>0</ixy>
                    <ixz>0</ixz>
                    <iyy>8.13545e-05</iyy>
                    <iyz>0</iyz>
                    <izz>8.22545e-05</izz>
                </inertia>
            </inertial>
            <collision name="rotor_2_collision">
                <pose frame="">0 0 0 0 -0 0</pose>
                <geometry>
                    <cylinder>
                        <length>0.005</length>
                        <radius>0.1397</radius>
                    </cylinder>
                </geometry>
                <surface>
                    <contact>
                        <ode/>
                    </contact>
                    <friction>
                        <ode/>
                    </friction>
                </surface>
            </collision>
            <visual name="rotor_2_visual">
                <pose frame="">0 0 0 0 -0 0</pose>
                <geometry>
                    <mesh>
                        <scale>1 1 1</scale>
                        <uri>meshes/neo11_propeller_ccw.dae</uri>
                    </mesh>
                </geometry>
                <material>
                    <diffuse>0 0 1 1</diffuse>
                    <script>
                        <name>Gazebo/Blue</name>
                        <uri>file://media/materials/scripts/gazebo.material</uri>
                    </script>
                </material>
                <cast_shadows>0</cast_shadows>
            </visual>
            <gravity>1</gravity>
            <velocity_decay/>
        </link>
        <joint name="rotor_2_joint" type="revolute">
            <child>rotor_2</child>
            <parent>base_link</parent>
            <axis>
                <xyz>0.043578 0.075479 0.996195</xyz>
                <limit>
                    <lower>-1e+16</lower>
                    <upper>1e+16</upper>
                </limit>
                <dynamics>
                    <spring_reference>0</spring_reference>
                    <spring_stiffness>0</spring_stiffness>
                </dynamics>
                <use_parent_model_frame>1</use_parent_model_frame>
            </axis>
        </joint> -->
        <link name="rotor_2">
            <pose frame="">-0.206432 -0.205944 0.028 0 -0 -2.61799</pose>
            <inertial>
                <pose frame="">0 0 0 0 -0 0</pose>
                <mass>0.005</mass>
                <inertia>
                    <ixx>9.75e-07</ixx>
                    <ixy>0</ixy>
                    <ixz>0</ixz>
                    <iyy>8.13545e-05</iyy>
                    <iyz>0</iyz>
                    <izz>8.22545e-05</izz>
                </inertia>
            </inertial>
            <collision name="rotor_2_collision">
                <pose frame="">0 0 0 0 -0 0</pose>
                <geometry>
                    <cylinder>
                        <length>0.005</length>
                        <radius>0.1397</radius>
                    </cylinder>
                </geometry>
                <surface>
                    <contact>
                        <ode/>
                    </contact>
                    <friction>
                        <ode/>
                    </friction>
                </surface>
            </collision>
            <visual name="rotor_2_visual">
                <pose frame="">0 0 0 0 -0 0</pose>
                <geometry>
                    <mesh>
                        <scale>1 1 1</scale>
                        <uri>meshes/neo11_propeller_ccw.dae</uri>
                    </mesh>
                </geometry>
                <material>
                    <diffuse>0 0 1 1</diffuse>
                    <script>
                        <name>Gazebo/Blue</name>
                        <uri>materials/scripts/gazebo.material</uri>
                    </script>
                </material>
                <cast_shadows>0</cast_shadows>
            </visual>
            <gravity>1</gravity>
            <velocity_decay/>
        </link>
        <joint name="rotor_2_joint" type="revolute">
            <child>rotor_2</child>
            <parent>base_link</parent>
            <axis>
                <xyz>0 0 1</xyz>
                <limit>
                    <lower>-1e+16</lower>
                    <upper>1e+16</upper>
                </limit>
                <dynamics>
                    <spring_reference>0</spring_reference>
                    <spring_stiffness>0</spring_stiffness>
                </dynamics>
                <use_parent_model_frame>1</use_parent_model_frame>
            </axis>
        </joint>
        <!-- <link name="rotor_4">
            <pose frame="">-0.00067 -0.28929 0.028 -0 0.087267 -3.14159</pose>
            <inertial>
                <pose frame="">0 0 0 0 -0 0</pose>
                <mass>0.005</mass>
                <inertia>
                    <ixx>9.75e-07</ixx>
                    <ixy>0</ixy>
                    <ixz>0</ixz>
                    <iyy>8.13545e-05</iyy>
                    <iyz>0</iyz>
                    <izz>8.22545e-05</izz>
                </inertia>
            </inertial>
            <collision name="rotor_4_collision">
                <pose frame="">0 0 0 0 -0 0</pose>
                <geometry>
                    <cylinder>
                        <length>0.005</length>
                        <radius>0.1397</radius>
                    </cylinder>
                </geometry>
                <surface>
                    <contact>
                        <ode/>
                    </contact>
                    <friction>
                        <ode/>
                    </friction>
                </surface>
            </collision>
            <visual name="rotor_4_visual">
                <pose frame="">0 0 0 0 -0 0</pose>
                <geometry>
                    <mesh>
                        <scale>1 1 1</scale>
                        <uri>meshes/neo11_propeller_ccw.dae</uri>
                    </mesh>
                </geometry>
                <material>
                    <diffuse>0 0 1 1</diffuse>
                    <script>
                        <name>Gazebo/Blue</name>
                        <uri>file://media/materials/scripts/gazebo.material</uri>
                    </script>
                </material>
                <cast_shadows>0</cast_shadows>
            </visual>
            <gravity>1</gravity>
            <velocity_decay/>
        </link>
        <joint name="rotor_4_joint" type="revolute">
            <child>rotor_4</child>
            <parent>base_link</parent>
            <axis>
                <xyz>-0.087156 -0 0.996195</xyz>
                <limit>
                    <lower>-1e+16</lower>
                    <upper>1e+16</upper>
                </limit>
                <dynamics>
                    <spring_reference>0</spring_reference>
                    <spring_stiffness>0</spring_stiffness>
                </dynamics>
                <use_parent_model_frame>1</use_parent_model_frame>
            </axis>
        </joint> -->
        <link name="rotor_3">
            <pose frame="">0.206432 -0.205944 0.028 0 0 -0.523599</pose>
            <inertial>
                <pose frame="">0 0 0 0 -0 0</pose>
                <mass>0.005</mass>
                <inertia>
                    <ixx>9.75e-07</ixx>
                    <ixy>0</ixy>
                    <ixz>0</ixz>
                    <iyy>8.13545e-05</iyy>
                    <iyz>0</iyz>
                    <izz>8.22545e-05</izz>
                </inertia>
            </inertial>
            <collision name="rotor_3_collision">
                <pose frame="">0 0 0 0 -0 0</pose>
                <geometry>
                    <cylinder>
                        <length>0.005</length>
                        <radius>0.1397</radius>
                    </cylinder>
                </geometry>
                <surface>
                    <contact>
                        <ode/>
                    </contact>
                    <friction>
                        <ode/>
                    </friction>
                </surface>
            </collision>
            <visual name="rotor_3_visual">
                <pose frame="">0 0 0 0 -0 0</pose>
                <geometry>
                    <mesh>
                        <scale>1 1 1</scale>
                        <uri>meshes/neo11_propeller_cw.dae</uri>
                    </mesh>
                </geometry>
                <material>
                    <diffuse>1 0 0 1</diffuse>
                    <script>
                        <name>Gazebo/Red</name>
                        <uri>media/materials/scripts/gazebo.material</uri>
                    </script>
                </material>
                <cast_shadows>0</cast_shadows>
            </visual>
            <gravity>1</gravity>
            <velocity_decay/>
        </link>
        <joint name="rotor_3_joint" type="revolute">
            <child>rotor_3</child>
            <parent>base_link</parent>
            <axis>
                <xyz>0.043578 0.075479 0.996195</xyz>
                <limit>
                    <lower>-1e+16</lower>
                    <upper>1e+16</upper>
                </limit>
                <dynamics>
                    <spring_reference>0</spring_reference>
                    <spring_stiffness>0</spring_stiffness>
                </dynamics>
                <use_parent_model_frame>1</use_parent_model_frame>
            </axis>
        </joint>
    </model>
</sdf>
