<?xml version="1.0" encoding="utf-8"?>
<!-- =================================================================================== -->
<!-- |    This document was autogenerated by xacro from ctu_cras_norlab_absolem_sensor_config_1/urdf/nifti_robot.xacro | -->
<!-- |    EDITING THIS FILE BY HAND IS NOT RECOMMENDED                                 | -->
<!-- =================================================================================== -->
<robot name="NIFTi">
  <!-- render_xacro.py allows use of arguments like $(arg rover_trackLength) etc. which are not defined here -->
  <!-- render_xacro.py also adds all static transforms from robot yaml files accessible like camera_0_pos_x or realsense_holder_part1_quat_w -->
  <!-- payload -->
  <!-- TODO should be converted to the new payload autoinclude method -->
  <!-- MEASURED CONSTANTS -->
  <!-- MACRO SPECIFICATIONS -->
  <!-- SPECIAL LINKS -->
  <!-- This is a virtual link that specifies the origin to which parts attachable to the top of the robot should be related. -->
  <link name="ctu/rear_right_box"/>
  <joint name="rear_right_box_j" type="fixed">
    <parent link="ctu/base_link"/>
    <child link="ctu/rear_right_box"/>
    <origin rpy="0 0 0" xyz="-0.379 -0.1265 0.185"/>
  </joint>
  <!-- INCLUDES -->
  <!-- NIFTI ROBOT LINKS AND JOINTS SPECIFICATION -->
  <link name="ctu/base_link">
    <visual>
      <origin rpy="0 0 0" xyz="0 0 0"/>
      <geometry>
        <mesh filename="package://ctu_cras_norlab_absolem_sensor_config_1/meshes/body.dae" scale="1.0 1.0 1.0"/>
      </geometry>
    </visual>
    <collision>
      <origin rpy="0 0 0" xyz="-0.1220 0 0.118"/>
      <geometry>
        <box size="0.50017 0.240930 0.1390"/>
      </geometry>
    </collision>
    <collision>
      <origin rpy="0 0 0" xyz="0.157 0 0.118"/>
      <geometry>
        <box size="0.056 0.12093 0.1390"/>
      </geometry>
    </collision>
    <collision>
      <origin rpy="0 0 0.785398" xyz="0.144 -0.076 0.118"/>
      <geometry>
        <box size="0.083 0.040 0.1390"/>
      </geometry>
    </collision>
    <collision>
      <origin rpy="0 0 -0.785398" xyz="0.144 0.076 0.118"/>
      <geometry>
        <box size="0.083 0.040 0.1390"/>
      </geometry>
    </collision>
    <collision>
      <origin rpy="0 0 0" xyz="0 0.135 0.09"/>
      <geometry>
        <box size="0.055 0.040 0.08"/>
      </geometry>
    </collision>
    <collision>
      <origin rpy="0 0 0" xyz="0 0.155 0.013"/>
      <geometry>
        <box size="0.055 0.020 0.075"/>
      </geometry>
    </collision>
    <collision>
      <origin rpy="0 0 0" xyz="0 -0.135 0.09"/>
      <geometry>
        <box size="0.055 0.040 0.08"/>
      </geometry>
    </collision>
    <collision>
      <origin rpy="0 0 0" xyz="0 -0.155 0.013"/>
      <geometry>
        <box size="0.055 0.020 0.075"/>
      </geometry>
    </collision>
    <collision name="big_collision_box">
      <origin rpy="0 0 0" xyz="-0.21 0 0.205"/>
      <geometry>
        <box size="0.65 0.31 0.25"/>
      </geometry>
    </collision>
    <inertial>
      <origin rpy="0 0 0" xyz="-0.034 0 0.142"/>
      <mass value="6.746"/>
      <inertia ixx="0.0069904" ixy="0.00012271" ixz="-4.2725e-05" iyy="0.02129" iyz="-0.00010522" izz="0.025519"/>
    </inertial>
  </link>
  <link name="ctu/rear_sensor_item">
    <visual>
      <origin rpy="0 0 0" xyz="0 0 0.175"/>
      <geometry>
        <box size="0.02 0.02 0.35"/>
      </geometry>
      <material name="aluminium">
        <color rgba="0.8 0.8 0.8 1"/>
      </material>
    </visual>
    <collision>
      <origin rpy="0 0 0" xyz="0 0 0.175"/>
      <geometry>
        <box size="0.02 0.02 0.35"/>
      </geometry>
    </collision>
  </link>
  <joint name="rear_sensor_item_j" type="fixed">
    <parent link="ctu/rear_right_box"/>
    <child link="ctu/rear_sensor_item"/>
    <origin rpy="0 0 0" xyz="0.084 0.02 0"/>
  </joint>
  <link name="ctu/battery">
    <visual>
      <origin rpy="0 0 0" xyz="0 0 0"/>
      <geometry>
        <mesh filename="package://ctu_cras_norlab_absolem_sensor_config_1/meshes/battery.dae" scale="1.0 1.0 1.0"/>
      </geometry>
    </visual>
    <collision>
      <origin rpy="0 0 0" xyz="0 0 0.0410"/>
      <geometry>
        <box size="0.1450 0.1350 0.0820"/>
      </geometry>
    </collision>
    <inertial>
      <origin rpy="0 0 0" xyz="0 0 0.041"/>
      <mass value="3.18"/>
      <inertia ixx="0.0020793" ixy="0.0" ixz="0.0" iyy="0.0023127" iyz="0.0" izz="0.0032712"/>
    </inertial>
  </link>
  <joint name="battery_j" type="fixed">
    <parent link="ctu/base_link"/>
    <child link="ctu/battery"/>
    <origin rpy="0 0 0" xyz="-0.2836 -0.0221 0.0722"/>
  </joint>
  <link name="ctu/top_box">
    <visual>
      <origin rpy="0 0 0" xyz="0 0 0"/>
      <geometry>
        <mesh filename="package://ctu_cras_norlab_absolem_sensor_config_1/meshes/top_box.dae" scale="1.0 1.0 1.0"/>
      </geometry>
    </visual>
    <collision>
      <origin rpy="0 0 0" xyz="-0.0290 0 0.0315"/>
      <geometry>
        <box size="0.2000 0.1330 0.06252"/>
      </geometry>
    </collision>
    <collision>
      <origin rpy="0 0 0" xyz="-0.09824 0.04127 0.0690"/>
      <geometry>
        <box size="0.0440 0.0440 0.01303"/>
      </geometry>
    </collision>
    <collision>
      <origin rpy="0 0 0" xyz="-0.07383 -0.04222 0.07996"/>
      <geometry>
        <box size="0.03732 0.03523 0.03489"/>
      </geometry>
    </collision>
    <inertial>
      <origin rpy="0 0 0" xyz="0 0 0.041"/>
      <mass value="0.24"/>
      <inertia ixx="0.0026136" ixy="0.0" ixz="0.0" iyy="0.0049426" iyz="0.0" izz="0.0070334"/>
    </inertial>
  </link>
  <joint name="top_box_j" type="fixed">
    <parent link="ctu/rear_right_box"/>
    <child link="ctu/top_box"/>
    <origin rpy="0 0 0" xyz="0.4267 0.0708 0.0"/>
  </joint>
  <link name="ctu/antenna">
    <visual>
      <origin rpy="0 0 0" xyz="0 0 0"/>
      <geometry>
        <mesh filename="package://ctu_cras_norlab_absolem_sensor_config_1/meshes/antenna.dae" scale="1.0 1.0 1.0"/>
      </geometry>
    </visual>
    <collision>
      <origin rpy="0 1.57079632679 0" xyz="-0.01864 0 0"/>
      <geometry>
        <cylinder length="0.03718" radius="0.008"/>
      </geometry>
    </collision>
    <collision>
      <origin rpy="0 0 0" xyz="-0.030 0 0.19053"/>
      <geometry>
        <cylinder length="0.38107" radius="0.008"/>
      </geometry>
    </collision>
    <inertial>
      <origin rpy="0 0 0" xyz="-0.022 0.0203 0.02917"/>
      <mass value="0.56"/>
      <inertia ixx="0.004878" ixy="-6.2341e-07" ixz="-7.4538e-07" iyy="0.00090164" iyz="-0.00014394" izz="0.0042946"/>
    </inertial>
  </link>
  <joint name="antenna_j" type="fixed">
    <parent link="ctu/base_link"/>
    <child link="ctu/antenna"/>
    <origin rpy="0 0 0" xyz="-0.3720 0.0789 0.1551"/>
  </joint>
  <link name="ctu/left_track">
    <visual>
      <origin rpy="1.57 0 1.57" xyz="0 0 -0.0705"/>
      <geometry>
        <mesh filename="package://ctu_cras_norlab_absolem_sensor_config_1/meshes/bogie.dae" scale="1.0 1.0 1.0"/>
      </geometry>
    </visual>
    <collision>
      <origin rpy="1.57079632679 0 1.57079632679" xyz="0 0 0.01855"/>
      <geometry>
        <box size="0.097000 0.178 0.500000"/>
      </geometry>
    </collision>
    <collision>
      <origin rpy="1.57079632679 0 0" xyz="0.25 -0.015 0.01855"/>
      <geometry>
        <!-- enlarged because of laser filtering problems -->
        <cylinder length="0.112" radius="0.089000"/>
      </geometry>
    </collision>
    <collision>
      <origin rpy="1.57079632679 0 0" xyz="-0.25 0 0.01855"/>
      <geometry>
        <cylinder length="0.097000" radius="0.089000"/>
      </geometry>
    </collision>
    <inertial>
      <origin rpy="0 0 0" xyz="0 0 0.0141"/>
      <mass value="6.06"/>
      <inertia ixx="0.002731" ixy="0.0" ixz="0.0" iyy="0.032554" iyz="1.5e-05" izz="0.031391"/>
    </inertial>
  </link>
  <joint name="left_track_j" type="revolute">
    <parent link="base_link"/>
    <child link="left_track"/>
    <axis xyz="0 1 0"/>
    <origin rpy="0 0.0 0" xyz="0 0.1985 0"/>
    <limit effort="0" lower="-0.7" upper="0.7" velocity="4"/>
  </joint>
  <link name="ctu/right_track">
    <visual>
      <origin rpy="1.57 0 -1.57" xyz="0 0 -0.0705"/>
      <geometry>
        <mesh filename="package://ctu_cras_norlab_absolem_sensor_config_1/meshes/bogie.dae" scale="1.0 1.0 1.0"/>
      </geometry>
    </visual>
    <collision>
      <origin rpy="1.57079632679 0 1.57079632679" xyz="0 0 0.01855"/>
      <geometry>
        <box size="0.097000 0.178 0.500000"/>
      </geometry>
    </collision>
    <collision>
      <origin rpy="1.57079632679 0 0" xyz="0.25 0.015 0.01855"/>
      <geometry>
        <!-- enlarged because of laser filtering problems -->
        <cylinder length="0.112" radius="0.089000"/>
      </geometry>
    </collision>
    <collision>
      <origin rpy="1.57079632679 0 0" xyz="-0.25 0 0.01855"/>
      <geometry>
        <cylinder length="0.097000" radius="0.089000"/>
      </geometry>
    </collision>
    <inertial>
      <origin rpy="0 0 0" xyz="0 0 0.0141"/>
      <mass value="6.06"/>
      <inertia ixx="0.002731" ixy="0.0" ixz="0.0" iyy="0.032554" iyz="1.5e-05" izz="0.031391"/>
    </inertial>
  </link>
  <joint name="right_track_j" type="revolute">
    <parent link="base_link"/>
    <child link="right_track"/>
    <axis xyz="0 1 0"/>
    <origin rpy="0 0.0 0" xyz="0 -0.1985 0"/>
    <mimic joint="left_track_j" multiplier="-1"/>
    <limit effort="0" lower="-0.7" upper="0.7" velocity="4"/>
  </joint>
  <link name="ctu/front_left_flipper">
    <visual>
      <origin rpy="3.32575 0 1.57079632679" xyz="0 0 0"/>
      <geometry>
        <mesh filename="package://ctu_cras_norlab_absolem_sensor_config_1/meshes/flipper.dae" scale="1.0 1.0 1.0"/>
      </geometry>
    </visual>
    <collision name="front_left_flipper_collision_large_wheel">
      <origin rpy="1.57079632679 0 0" xyz="0 -0.0085 0"/>
      <geometry>
        <cylinder length="0.06681" radius="0.089000"/>
      </geometry>
    </collision>
    <collision name="front_left_flipper_collision_small_wheel">
      <origin rpy="1.57079632679 0 0" xyz="0.33 -0.0085 0.0"/>
      <geometry>
        <cylinder length="0.06681" radius="0.029"/>
      </geometry>
    </collision>
    <collision name="front_left_flipper_collision_top_bar">
      <origin rpy="0 0.184162095 0.0" xyz="0.165 -0.0085 0.0325"/>
      <geometry>
        <box size="0.330000 0.06681 0.055"/>
      </geometry>
    </collision>
    <collision name="front_left_flipper_collision_bottom_bar">
      <origin rpy="0 -0.184162095 0.0" xyz="0.165 -0.0085 -0.0325"/>
      <geometry>
        <box size="0.330000 0.06681 0.055"/>
      </geometry>
    </collision>
    <collision name="front_left_flipper_collision_middle_bar">
      <origin rpy="0 -0.02 0.0" xyz="0.166 -0.0085 0.004"/>
      <geometry>
        <box size="0.20 0.06681 0.07"/>
      </geometry>
    </collision>
    <inertial>
      <origin rpy="0 0 0" xyz="0.08 0 0.0"/>
      <mass value="0.75"/>
      <inertia ixx="0.0017491" ixy="2.8512e-07" ixz="0.0018277" iyy="0.012277" iyz="-3.6288e-07" izz="0.010941"/>
    </inertial>
    <sensor name="front_left_flipper_contact" type="contact">
      <contact>
        <collision>front_left_flipper_collision</collision>
        <collision>front_left_flipper_collision_large_wheel</collision>
        <collision>front_left_flipper_collision_small_wheel</collision>
        <collision>front_left_flipper_collision_top_bar</collision>
        <collision>front_left_flipper_collision_bottom_bar</collision>
        <collision>front_left_flipper_collision_middle_bar</collision>
      </contact>
    </sensor>
  </link>
  <joint name="front_left_flipper_j" type="continuous">
    <parent link="left_track"/>
    <child link="front_left_flipper"/>
    <axis xyz="0 1 0"/>
    <origin rpy="0 0.193732 0" xyz="0.25 0.0735 0.0195"/>
  </joint>
  <link name="ctu/front_left_flipper_end_point"/>
  <joint name="front_left_flipper_end_point_j" type="fixed">
    <parent link="front_left_flipper"/>
    <child link="front_left_flipper_end_point"/>
    <origin rpy="0 0.193732 0" xyz="0.3476 0 0"/>
  </joint>
  <link name="ctu/front_right_flipper">
    <visual>
      <origin rpy="3.32575 0 -1.57079632679" xyz="0 0 0"/>
      <geometry>
        <mesh filename="package://ctu_cras_norlab_absolem_sensor_config_1/meshes/flipper.dae" scale="1.0 1.0 1.0"/>
      </geometry>
    </visual>
    <collision name="front_right_flipper_collision_large_wheel">
      <origin rpy="1.57079632679 0 0" xyz="0 0.0085 0"/>
      <geometry>
        <cylinder length="0.06681" radius="0.089000"/>
      </geometry>
    </collision>
    <collision name="front_right_flipper_collision_small_wheel">
      <origin rpy="1.57079632679 0 0" xyz="-0.33 0.0085 0.0"/>
      <geometry>
        <cylinder length="0.06681" radius="0.029"/>
      </geometry>
    </collision>
    <collision name="front_right_flipper_collision_top_bar">
      <origin rpy="0 0.184162095 3.14159265359" xyz="-0.165 0.0085 0.0325"/>
      <geometry>
        <box size="0.330000 0.06681 0.055"/>
      </geometry>
    </collision>
    <collision name="front_right_flipper_collision_bottom_bar">
      <origin rpy="0 -0.184162095 3.14159265359" xyz="-0.165 0.0085 -0.0325"/>
      <geometry>
        <box size="0.330000 0.06681 0.055"/>
      </geometry>
    </collision>
    <collision name="front_right_flipper_collision_middle_bar">
      <origin rpy="0 -0.02 3.14159265359" xyz="-0.166 0.0085 0.004"/>
      <geometry>
        <box size="0.20 0.06681 0.07"/>
      </geometry>
    </collision>
    <inertial>
      <origin rpy="0 0 0" xyz="-0.08 0 0.0"/>
      <mass value="0.75"/>
      <inertia ixx="0.0017491" ixy="2.8512e-07" ixz="0.0018277" iyy="0.012277" iyz="-3.6288e-07" izz="0.010941"/>
    </inertial>
    <sensor name="front_right_flipper_contact" type="contact">
      <contact>
        <collision>front_right_flipper_collision</collision>
        <collision>front_right_flipper_collision_large_wheel</collision>
        <collision>front_right_flipper_collision_small_wheel</collision>
        <collision>front_right_flipper_collision_top_bar</collision>
        <collision>front_right_flipper_collision_bottom_bar</collision>
        <collision>front_right_flipper_collision_middle_bar</collision>
      </contact>
    </sensor>
  </link>
  <joint name="front_right_flipper_j" type="continuous">
    <parent link="right_track"/>
    <child link="front_right_flipper"/>
    <axis xyz="0 1 0"/>
    <origin rpy="0 -2.94786065359 0" xyz="0.25 -0.0735 0.0195"/>
  </joint>
  <link name="ctu/front_right_flipper_end_point"/>
  <joint name="front_right_flipper_end_point_j" type="fixed">
    <parent link="front_right_flipper"/>
    <child link="front_right_flipper_end_point"/>
    <origin rpy="0 0.193732 0" xyz="-0.3476 0 0"/>
  </joint>
  <link name="ctu/rear_left_flipper">
    <visual>
      <origin rpy="3.32575 0 1.57079632679" xyz="0 0 0"/>
      <geometry>
        <mesh filename="package://ctu_cras_norlab_absolem_sensor_config_1/meshes/flipper.dae" scale="1.0 1.0 1.0"/>
      </geometry>
    </visual>
    <collision name="rear_left_flipper_collision_large_wheel">
      <origin rpy="1.57079632679 0 0" xyz="0 -0.0 0"/>
      <geometry>
        <cylinder length="0.04981" radius="0.089000"/>
      </geometry>
    </collision>
    <collision name="rear_left_flipper_collision_small_wheel">
      <origin rpy="1.57079632679 0 0" xyz="0.33 -0.0 0.0"/>
      <geometry>
        <cylinder length="0.04981" radius="0.029"/>
      </geometry>
    </collision>
    <collision name="rear_left_flipper_collision_top_bar">
      <origin rpy="0 0.184162095 0.0" xyz="0.165 -0.0 0.0325"/>
      <geometry>
        <box size="0.330000 0.04981 0.055"/>
      </geometry>
    </collision>
    <collision name="rear_left_flipper_collision_bottom_bar">
      <origin rpy="0 -0.184162095 0.0" xyz="0.165 -0.0 -0.0325"/>
      <geometry>
        <box size="0.330000 0.04981 0.055"/>
      </geometry>
    </collision>
    <collision name="rear_left_flipper_collision_middle_bar">
      <origin rpy="0 -0.02 0.0" xyz="0.166 -0.0 0.004"/>
      <geometry>
        <box size="0.20 0.04981 0.07"/>
      </geometry>
    </collision>
    <inertial>
      <origin rpy="0 0 0" xyz="0.08 0 0.0"/>
      <mass value="0.75"/>
      <inertia ixx="0.0017491" ixy="2.8512e-07" ixz="0.0018277" iyy="0.012277" iyz="-3.6288e-07" izz="0.010941"/>
    </inertial>
    <sensor name="rear_left_flipper_contact" type="contact">
      <contact>
        <collision>rear_left_flipper_collision</collision>
        <collision>rear_left_flipper_collision_large_wheel</collision>
        <collision>rear_left_flipper_collision_small_wheel</collision>
        <collision>rear_left_flipper_collision_top_bar</collision>
        <collision>rear_left_flipper_collision_bottom_bar</collision>
        <collision>rear_left_flipper_collision_middle_bar</collision>
      </contact>
    </sensor>
  </link>
  <joint name="rear_left_flipper_j" type="continuous">
    <parent link="left_track"/>
    <child link="rear_left_flipper"/>
    <axis xyz="0 1 0"/>
    <origin rpy="0 2.94786065359 0" xyz="-0.25 0.0735 0.0195"/>
  </joint>
  <link name="ctu/rear_left_flipper_end_point"/>
  <joint name="rear_left_flipper_end_point_j" type="fixed">
    <parent link="rear_left_flipper"/>
    <child link="rear_left_flipper_end_point"/>
    <origin rpy="0 0.193732 0" xyz="0.3476 0 0"/>
  </joint>
  <link name="ctu/rear_right_flipper">
    <visual>
      <origin rpy="3.32575 0 -1.57079632679" xyz="0 0 0"/>
      <geometry>
        <mesh filename="package://ctu_cras_norlab_absolem_sensor_config_1/meshes/flipper.dae" scale="1.0 1.0 1.0"/>
      </geometry>
    </visual>
    <collision name="rear_right_flipper_collision_large_wheel">
      <origin rpy="1.57079632679 0 0" xyz="0 0.0 0"/>
      <geometry>
        <cylinder length="0.04981" radius="0.089000"/>
      </geometry>
    </collision>
    <collision name="rear_right_flipper_collision_small_wheel">
      <origin rpy="1.57079632679 0 0" xyz="-0.33 0.0 0.0"/>
      <geometry>
        <cylinder length="0.04981" radius="0.029"/>
      </geometry>
    </collision>
    <collision name="rear_right_flipper_collision_top_bar">
      <origin rpy="0 0.184162095 3.14159265359" xyz="-0.165 0.0 0.0325"/>
      <geometry>
        <box size="0.330000 0.04981 0.055"/>
      </geometry>
    </collision>
    <collision name="rear_right_flipper_collision_bottom_bar">
      <origin rpy="0 -0.184162095 3.14159265359" xyz="-0.165 0.0 -0.0325"/>
      <geometry>
        <box size="0.330000 0.04981 0.055"/>
      </geometry>
    </collision>
    <collision name="rear_right_flipper_collision_middle_bar">
      <origin rpy="0 -0.02 3.14159265359" xyz="-0.166 0.0 0.004"/>
      <geometry>
        <box size="0.20 0.04981 0.07"/>
      </geometry>
    </collision>
    <inertial>
      <origin rpy="0 0 0" xyz="-0.08 0 0.0"/>
      <mass value="0.75"/>
      <inertia ixx="0.0017491" ixy="2.8512e-07" ixz="0.0018277" iyy="0.012277" iyz="-3.6288e-07" izz="0.010941"/>
    </inertial>
    <sensor name="rear_right_flipper_contact" type="contact">
      <contact>
        <collision>rear_right_flipper_collision</collision>
        <collision>rear_right_flipper_collision_large_wheel</collision>
        <collision>rear_right_flipper_collision_small_wheel</collision>
        <collision>rear_right_flipper_collision_top_bar</collision>
        <collision>rear_right_flipper_collision_bottom_bar</collision>
        <collision>rear_right_flipper_collision_middle_bar</collision>
      </contact>
    </sensor>
  </link>
  <joint name="rear_right_flipper_j" type="continuous">
    <parent link="right_track"/>
    <child link="rear_right_flipper"/>
    <axis xyz="0 1 0"/>
    <origin rpy="0 -0.193732 0" xyz="-0.25 -0.0735 0.0195"/>
  </joint>
  <link name="ctu/rear_right_flipper_end_point"/>
  <joint name="rear_right_flipper_end_point_j" type="fixed">
    <parent link="rear_right_flipper"/>
    <child link="rear_right_flipper_end_point"/>
    <origin rpy="0 0.193732 0" xyz="-0.3476 0 0"/>
  </joint>
  <link name="ctu/laser_base">
    <visual>
      <origin rpy="0 0 0" xyz="0 0 0"/>
      <geometry>
        <box size="0.005 0.005 0.005"/>
      </geometry>
      <material name="invisible_color">
        <color rgba="1 0 0 0.5"/>
      </material>
    </visual>
    <inertial>
      <origin rpy="0 0 0" xyz="0 0 0"/>
      <mass value="1e-5"/>
      <inertia ixx="1e-3" ixy="1e-6" ixz="1e-6" iyy="1e-3" iyz="1e-6" izz="1e-3"/>
    </inertial>
  </link>
  <joint name="laser_base_j" type="fixed">
    <parent link="ctu/base_link"/>
    <child link="ctu/laser_base"/>
    <origin rpy="0 0.0 0" xyz="0.2502 0.0 0.1407"/>
  </joint>
  <link name="ctu/laser">
    <visual>
      <origin rpy="1.57079632679 0 -1.57079632679" xyz="0 0 0"/>
      <geometry>
        <mesh filename="package://ctu_cras_norlab_absolem_sensor_config_1/meshes/laser.dae" scale="1.0 1.0 1.0"/>
      </geometry>
    </visual>
    <collision>
      <origin rpy="1.57079632679 0 -1.57079632679" xyz="0 0 -0.04"/>
      <geometry>
        <box size="0.1159 0.16826 0.1159"/>
      </geometry>
    </collision>
    <inertial>
      <origin rpy="0 0 0" xyz="0 0 -0.04"/>
      <mass value="1.1"/>
      <inertia ixx="0.0031194" ixy="-2.221e-06" ixz="-1.1577e-06" iyy="0.0031389" iyz="-1.153e-05" izz="0.0017656"/>
    </inertial>
  </link>
  <joint name="laser_j" type="revolute">
    <parent link="laser_base"/>
    <child link="laser"/>
    <axis xyz="1 0 0"/>
    <origin rpy="3.14159265359 0 0" xyz="0 0 0"/>
    <limit effort="0" lower="-2.3561945" upper="2.3561945" velocity="4"/>
  </joint>
  <link name="ctu/imu">
    <visual>
      <origin rpy="0 0 0" xyz="0 0 0"/>
      <geometry>
        <box size="0.005 0.005 0.005"/>
      </geometry>
      <material name="invisible_color">
        <color rgba="1 0 0 0.5"/>
      </material>
    </visual>
    <inertial>
      <origin rpy="0 0 0" xyz="0 0 0"/>
      <mass value="1e-5"/>
      <inertia ixx="1e-3" ixy="1e-6" ixz="1e-6" iyy="1e-3" iyz="1e-6" izz="1e-3"/>
    </inertial>
  </link>
  <joint name="imu_j" type="fixed">
    <parent link="ctu/base_link"/>
    <child link="ctu/imu"/>
    <origin rpy="3.14159265359 0 0" xyz="0 0 0.1500"/>
  </joint>
  <link name="ctu/omnicam">
    <visual>
      <origin rpy="0 0 0" xyz="0 0 0"/>
      <geometry>
        <mesh filename="package://ctu_cras_norlab_absolem_sensor_config_1/meshes/omnicam.dae" scale="1.0 1.0 1.0"/>
      </geometry>
    </visual>
    <collision>
      <origin rpy="0 0 0" xyz="-0.003 -0.0015 0.003"/>
      <geometry>
        <cylinder length="0.137" radius="0.068"/>
      </geometry>
    </collision>
    <inertial>
      <origin rpy="0 0 0" xyz="0 0 0"/>
      <mass value="2.414"/>
      <inertia ixx="0.0023726" ixy="-3.0562e-06" ixz="-2.3418e-06" iyy="0.0023716" iyz="5.1202e-06" izz="0.0016667"/>
    </inertial>
  </link>
  <joint name="omnicam_j" type="fixed">
    <parent link="ctu/top_box"/>
    <child link="ctu/omnicam"/>
    <origin rpy="0 0 -0.628318530" xyz="0.0023 -0.0017 0.1292"/>
  </joint>
  <link name="ctu/omnicam_forward">
    <visual>
      <origin rpy="0 0 0" xyz="0 0 0"/>
      <geometry>
        <box size="0.005 0.005 0.005"/>
      </geometry>
      <material name="invisible_color">
        <color rgba="1 0 0 0.5"/>
      </material>
    </visual>
    <inertial>
      <origin rpy="0 0 0" xyz="0 0 0"/>
      <mass value="1e-5"/>
      <inertia ixx="1e-3" ixy="1e-6" ixz="1e-6" iyy="1e-3" iyz="1e-6" izz="1e-3"/>
    </inertial>
  </link>
  <joint name="omnicam_forward_j" type="fixed">
    <parent link="ctu/omnicam"/>
    <child link="ctu/omnicam_forward"/>
    <origin rpy="0 0 0.628" xyz="0 0 0"/>
  </joint>
  <link name="ctu/omnicam_top">
    <visual>
      <origin rpy="0 0 0" xyz="0 0 0"/>
      <geometry>
        <box size="0.005 0.005 0.005"/>
      </geometry>
      <material name="invisible_color">
        <color rgba="1 0 0 0.5"/>
      </material>
    </visual>
    <inertial>
      <origin rpy="0 0 0" xyz="0 0 0"/>
      <mass value="1e-5"/>
      <inertia ixx="1e-3" ixy="1e-6" ixz="1e-6" iyy="1e-3" iyz="1e-6" izz="1e-3"/>
    </inertial>
  </link>
  <joint name="omnicam_top_j" type="fixed">
    <parent link="ctu/omnicam_forward"/>
    <child link="ctu/omnicam_top"/>
    <origin rpy="0 0 0" xyz="0 0 0.074"/>
  </joint>
  <link name="ctu/omnicam_bottom">
    <visual>
      <origin rpy="0 0 0" xyz="0 0 0"/>
      <geometry>
        <box size="0.005 0.005 0.005"/>
      </geometry>
      <material name="invisible_color">
        <color rgba="1 0 0 0.5"/>
      </material>
    </visual>
    <inertial>
      <origin rpy="0 0 0" xyz="0 0 0"/>
      <mass value="1e-5"/>
      <inertia ixx="1e-3" ixy="1e-6" ixz="1e-6" iyy="1e-3" iyz="1e-6" izz="1e-3"/>
    </inertial>
  </link>
  <joint name="omnicam_bottom_j" type="fixed">
    <parent link="ctu/omnicam_forward"/>
    <child link="ctu/omnicam_bottom"/>
    <origin rpy="0 0 0" xyz="0 0 -0.066"/>
  </joint>
  <link name="ctu/camera_0">
    <visual>
      <origin rpy="0 0 0" xyz="0 0 0"/>
      <geometry>
        <box size="0.005 0.005 0.005"/>
      </geometry>
      <material name="invisible_color">
        <color rgba="1 0 0 0.5"/>
      </material>
    </visual>
    <inertial>
      <origin rpy="0 0 0" xyz="0 0 0"/>
      <mass value="1e-5"/>
      <inertia ixx="1e-3" ixy="1e-6" ixz="1e-6" iyy="1e-3" iyz="1e-6" izz="1e-3"/>
    </inertial>
  </link>
  <joint name="camera_0_j" type="fixed">
    <parent link="ctu/omnicam"/>
    <child link="ctu/camera_0"/>
    <origin rpy="-1.571744 -0.000784 -1.569703" xyz="0.042087 -0.001706 -0.000359"/>
  </joint>
  <link name="ctu/camera_1">
    <visual>
      <origin rpy="0 0 0" xyz="0 0 0"/>
      <geometry>
        <box size="0.005 0.005 0.005"/>
      </geometry>
      <material name="invisible_color">
        <color rgba="1 0 0 0.5"/>
      </material>
    </visual>
    <inertial>
      <origin rpy="0 0 0" xyz="0 0 0"/>
      <mass value="1e-5"/>
      <inertia ixx="1e-3" ixy="1e-6" ixz="1e-6" iyy="1e-3" iyz="1e-6" izz="1e-3"/>
    </inertial>
  </link>
  <joint name="camera_1_j" type="fixed">
    <parent link="ctu/omnicam"/>
    <child link="ctu/camera_1"/>
    <origin rpy="-1.571865 0.000853 -2.826957" xyz="0.011469 -0.040128 -0.000086"/>
  </joint>
  <link name="ctu/camera_2">
    <visual>
      <origin rpy="0 0 0" xyz="0 0 0"/>
      <geometry>
        <box size="0.005 0.005 0.005"/>
      </geometry>
      <material name="invisible_color">
        <color rgba="1 0 0 0.5"/>
      </material>
    </visual>
    <inertial>
      <origin rpy="0 0 0" xyz="0 0 0"/>
      <mass value="1e-5"/>
      <inertia ixx="1e-3" ixy="1e-6" ixz="1e-6" iyy="1e-3" iyz="1e-6" izz="1e-3"/>
    </inertial>
  </link>
  <joint name="camera_2_j" type="fixed">
    <parent link="ctu/omnicam"/>
    <child link="ctu/camera_2"/>
    <origin rpy="-1.572501 0.004150 2.198064" xyz="-0.034854 -0.022887 0.000521"/>
  </joint>
  <link name="ctu/camera_3">
    <visual>
      <origin rpy="0 0 0" xyz="0 0 0"/>
      <geometry>
        <box size="0.005 0.005 0.005"/>
      </geometry>
      <material name="invisible_color">
        <color rgba="1 0 0 0.5"/>
      </material>
    </visual>
    <inertial>
      <origin rpy="0 0 0" xyz="0 0 0"/>
      <mass value="1e-5"/>
      <inertia ixx="1e-3" ixy="1e-6" ixz="1e-6" iyy="1e-3" iyz="1e-6" izz="1e-3"/>
    </inertial>
  </link>
  <joint name="camera_3_j" type="fixed">
    <parent link="ctu/omnicam"/>
    <child link="ctu/camera_3"/>
    <origin rpy="-1.571375 0.005611 0.942008" xyz="-0.033204 0.025729 0.000217"/>
  </joint>
  <link name="ctu/camera_4">
    <visual>
      <origin rpy="0 0 0" xyz="0 0 0"/>
      <geometry>
        <box size="0.005 0.005 0.005"/>
      </geometry>
      <material name="invisible_color">
        <color rgba="1 0 0 0.5"/>
      </material>
    </visual>
    <inertial>
      <origin rpy="0 0 0" xyz="0 0 0"/>
      <mass value="1e-5"/>
      <inertia ixx="1e-3" ixy="1e-6" ixz="1e-6" iyy="1e-3" iyz="1e-6" izz="1e-3"/>
    </inertial>
  </link>
  <joint name="camera_4_j" type="fixed">
    <parent link="ctu/omnicam"/>
    <child link="ctu/camera_4"/>
    <origin rpy="-1.581611 0.001034 -0.314790" xyz="0.014502 0.038991 -0.000301"/>
  </joint>
  <link name="ctu/camera_5">
    <visual>
      <origin rpy="0 0 0" xyz="0 0 0"/>
      <geometry>
        <box size="0.005 0.005 0.005"/>
      </geometry>
      <material name="invisible_color">
        <color rgba="1 0 0 0.5"/>
      </material>
    </visual>
    <inertial>
      <origin rpy="0 0 0" xyz="0 0 0"/>
      <mass value="1e-5"/>
      <inertia ixx="1e-3" ixy="1e-6" ixz="1e-6" iyy="1e-3" iyz="1e-6" izz="1e-3"/>
    </inertial>
  </link>
  <joint name="camera_5_j" type="fixed">
    <parent link="ctu/omnicam"/>
    <child link="ctu/camera_5"/>
    <origin rpy="0.003778 0.000786 -1.571909" xyz="0.000402 -0.000922 0.062128"/>
  </joint>
  <link name="ctu/omnicam_sensor_mount">
    <visual>
      <origin rpy="3.14152 0 0" xyz="-0.003 -0.002 0"/>
      <geometry>
        <mesh filename="package://ctu_cras_norlab_absolem_sensor_config_1/meshes/lb3_mount_2.stl" scale="0.001 0.001 0.001"/>
      </geometry>
      <material name="mount_black">
        <color rgba="0.1 0.1 0.1 1"/>
      </material>
    </visual>
    <visual>
      <origin rpy="0 0 0" xyz="-0.0045 0 -0.14"/>
      <geometry>
        <mesh filename="package://ctu_cras_norlab_absolem_sensor_config_1/meshes/lb3_mount_bottom.stl" scale="0.001 0.001 0.001"/>
      </geometry>
      <material name="mount_black">
        <color rgba="0.1 0.1 0.1 1"/>
      </material>
    </visual>
    <collision>
      <origin rpy="0 0 0" xyz="0 0 -0.015"/>
      <geometry>
        <cylinder length="0.044" radius="0.095"/>
      </geometry>
    </collision>
  </link>
  <joint name="omnicam_sensor_mount_j" type="fixed">
    <child link="omnicam_sensor_mount"/>
    <parent link="omnicam_top"/>
    <origin rpy="0 0 0" xyz="0 0.0 0.0"/>
  </joint>
  <!-- Pass either "urdf" or "sdf" to tell the parser what is the desired target format. -->
  <!-- If True, ground truth position will be published as odom frame. -->
  <gazebo>
    <plugin filename="libenable_model_uris.so" name="enable_model_uris"/>
    <plugin filename="libros_joystick_republisher.so" name="ros_joystick_republisher"/>
    <plugin filename="libreal_robot_adapter_plugin.so" name="real_robot_adapter">
      <tracks_vel_pub_gain>0.975</tracks_vel_pub_gain>
      <perfect_odometry>False</perfect_odometry>
    </plugin>
    <plugin filename="libgazebo_ros_joint_state_publisher.so" name="joint_states_publisher">
      <jointName>left_track_j,right_track_j,front_left_flipper_j,front_right_flipper_j,rear_left_flipper_j,rear_right_flipper_j,laser_j</jointName>
      <updateRate>20.0</updateRate>
    </plugin>
    <plugin filename="libnifti_robot_gazebo.so" name="nifti_robot_plugin">
      <body>base_link</body>
      <steering_efficiency>0.5</steering_efficiency>
      <linear_speed_gain>0.9</linear_speed_gain>
      <angular_speed_gain>0.93</angular_speed_gain>
      <left_track>left_track</left_track>
      <right_track>right_track</right_track>
      <front_left_flipper>front_left_flipper</front_left_flipper>
      <front_right_flipper>front_right_flipper</front_right_flipper>
      <rear_left_flipper>rear_left_flipper</rear_left_flipper>
      <rear_right_flipper>rear_right_flipper</rear_right_flipper>
      <differential_joint>differential_body_j</differential_joint>
      <differential_locked>true</differential_locked>
      <collide_without_contact_bitmask>2</collide_without_contact_bitmask>
      <!--<visualize_center_of_rotation/>-->
      <!--<visualize_friction_directions/>-->
      <!--<friction_force_enlargement_factor>10.0</friction_force_enlargement_factor>-->
    </plugin>
    <plugin filename="libflipper_control_plugin.so" name="flipper_control_plugin">
      <front_left_flipper_joint>front_left_flipper_j</front_left_flipper_joint>
      <front_right_flipper_joint>front_right_flipper_j</front_right_flipper_joint>
      <rear_left_flipper_joint>rear_left_flipper_j</rear_left_flipper_joint>
      <rear_right_flipper_joint>rear_right_flipper_j</rear_right_flipper_joint>
      <max_torque_front>17.0</max_torque_front>
      <max_torque_rear>17.0</max_torque_rear>
      <max_angular_velocity>0.785398163397</max_angular_velocity>
      <position_correction_gain>20.0</position_correction_gain>
    </plugin>
    <plugin filename="liblaser_rotate_plugin.so" name="laser_rotate_plugin">
      <laser_joint>laser_j</laser_joint>
      <initial_velocity>0.0</initial_velocity>
      <rotation_angular_limit>1.618994</rotation_angular_limit>
    </plugin>
  </gazebo>
  <gazebo reference="base_link">
    <!--selfCollide>true</selfCollide-->
  </gazebo>
  <gazebo reference="left_track">
    <!--selfCollide>true</selfCollide-->
    <kinematic>false</kinematic>
    <collision>
      <surface>
        <friction>
          <ode>
            <mu>0.7</mu>
            <mu2>150.0</mu2>
            <fdir1>0 1 0</fdir1>
            <!-- is overridden by the plugin -->
          </ode>
        </friction>
      </surface>
      <max_contacts>20</max_contacts>
    </collision>
  </gazebo>
  <gazebo reference="right_track">
    <!--selfCollide>true</selfCollide-->
    <kinematic>false</kinematic>
    <collision>
      <surface>
        <friction>
          <ode>
            <mu>0.7</mu>
            <mu2>150.0</mu2>
            <fdir1>0 1 0</fdir1>
            <!-- is overridden by the plugin -->
          </ode>
        </friction>
      </surface>
      <max_contacts>20</max_contacts>
    </collision>
  </gazebo>
  <gazebo reference="front_left_flipper">
    <!--selfCollide>true</selfCollide-->
    <kinematic>false</kinematic>
    <selfCollide>true</selfCollide>
    <collision>
      <surface>
        <friction>
          <ode>
            <mu>0.7</mu>
            <mu2>150.0</mu2>
            <fdir1>0 1 0</fdir1>
            <!-- is overridden by the plugin -->
          </ode>
        </friction>
      </surface>
      <max_contacts>20</max_contacts>
    </collision>
  </gazebo>
  <gazebo reference="front_right_flipper">
    <!--selfCollide>true</selfCollide-->
    <kinematic>false</kinematic>
    <selfCollide>true</selfCollide>
    <collision>
      <surface>
        <friction>
          <ode>
            <mu>0.7</mu>
            <mu2>150.0</mu2>
            <fdir1>0 1 0</fdir1>
            <!-- is overridden by the plugin -->
          </ode>
        </friction>
      </surface>
      <max_contacts>20</max_contacts>
    </collision>
  </gazebo>
  <gazebo reference="rear_left_flipper">
    <!--selfCollide>true</selfCollide-->
    <kinematic>false</kinematic>
    <selfCollide>true</selfCollide>
    <collision>
      <surface>
        <friction>
          <ode>
            <mu>0.7</mu>
            <mu2>150.0</mu2>
            <fdir1>0 1 0</fdir1>
            <!-- is overridden by the plugin -->
          </ode>
        </friction>
      </surface>
      <max_contacts>20</max_contacts>
    </collision>
  </gazebo>
  <gazebo reference="rear_right_flipper">
    <!--selfCollide>true</selfCollide-->
    <kinematic>false</kinematic>
    <selfCollide>true</selfCollide>
    <collision>
      <surface>
        <friction>
          <ode>
            <mu>0.7</mu>
            <mu2>150.0</mu2>
            <fdir1>0 1 0</fdir1>
            <!-- is overridden by the plugin -->
          </ode>
        </friction>
      </surface>
      <max_contacts>20</max_contacts>
    </collision>
  </gazebo>
  <gazebo reference="laser">
    <!--selfCollide>true</selfCollide-->
    <kinematic>false</kinematic>
    <sensor name="laser" type="ray">
      <pose>0 0 0 0 0 0</pose>
      <visualize>false</visualize>
      <update_rate>1000.0</update_rate>
      <always_on>true</always_on>
      <ray>
        <scan>
          <horizontal>
            <samples>541</samples>
            <resolution>1</resolution>
            <min_angle>-2.35619449615</min_angle>
            <max_angle>2.35619449615</max_angle>
          </horizontal>
        </scan>
        <range>
          <min>0.1</min>
          <max>50.0</max>
          <resolution>0.01</resolution>
        </range>
        <noise>
          <type>custom</type>
          <!-- Multiplicative gaussian implemented by plugin. -->
          <mean>1.0</mean>
          <stddev>0.001</stddev>
        </noise>
      </ray>
      <plugin filename="libcustom_sensor_config_plugin.so" name="config">
        <time_increment>2.77777780866e-05</time_increment>
        <scan_time>0.019999999553</scan_time>
        <angle_increment>0.00872664619237</angle_increment>
      </plugin>
      <plugin filename="libgazebo_ros_rotating_lidar.so" name="gazebo_ros_laser">
        <topicName>scan</topicName>
        <frameName>laser</frameName>
        <robotNamespace>/</robotNamespace>
      </plugin>
      <plugin filename="libmultiplicative_gaussian_noise_plugin.so" name="laser_noise_plugin"/>
    </sensor>
  </gazebo>
  <gazebo reference="left_track_j">
    <physics>
      <ode>
        <implicit_spring_damper>1</implicit_spring_damper>
        <cfm>0</cfm>
        <erp>0.95</erp>
      </ode>
    </physics>
  </gazebo>
  <gazebo reference="right_track_j">
    <physics>
      <ode>
        <implicit_spring_damper>1</implicit_spring_damper>
        <cfm>0</cfm>
        <erp>0.95</erp>
      </ode>
    </physics>
  </gazebo>
  <gazebo reference="front_left_flipper_j">
    <stopCfm value="0"/>
    <stopErp value="0.2"/>
    <implicitSpringDamper value="1"/>
    <sensor name="torque_sensor" type="force_torque">
      <update_rate>20</update_rate>
    </sensor>
  </gazebo>
  <gazebo reference="front_right_flipper_j">
    <stopCfm value="0"/>
    <stopErp value="0.2"/>
    <implicitSpringDamper value="1"/>
    <sensor name="torque_sensor" type="force_torque">
      <update_rate>20</update_rate>
    </sensor>
  </gazebo>
  <gazebo reference="rear_left_flipper_j">
    <stopCfm value="0"/>
    <stopErp value="0.2"/>
    <implicitSpringDamper value="1"/>
    <sensor name="torque_sensor" type="force_torque">
      <update_rate>20</update_rate>
    </sensor>
  </gazebo>
  <gazebo reference="rear_right_flipper_j">
    <stopCfm value="0"/>
    <stopErp value="0.2"/>
    <implicitSpringDamper value="1"/>
    <sensor name="torque_sensor" type="force_torque">
      <update_rate>20</update_rate>
    </sensor>
  </gazebo>
  <gazebo reference="laser_j">
    <stopCfm value="0"/>
    <stopErp value="0.2"/>
    <implicitSpringDamper value="1"/>
  </gazebo>
  <gazebo reference="imu">
    <selfCollide>false</selfCollide>
    <material>Gazebo/GreenTransparent</material>
    <sensor name="imu" type="imu">
      <imu>
        <angular_velocity>
          <x>
            <noise type="gaussian">
              <mean>0.0</mean>
              <stddev>1e-12</stddev>
              <!-- gazebo is noisy enough -->
              <bias_mean>0.0</bias_mean>
              <bias_stddev>5e-3</bias_stddev>
              <!--                            <bias_stddev>1e-12</bias_stddev>-->
            </noise>
          </x>
          <y>
            <noise type="gaussian">
              <mean>0.0</mean>
              <stddev>1e-12</stddev>
              <!-- gazebo is noisy enough -->
              <bias_mean>0.0</bias_mean>
              <bias_stddev>5e-3</bias_stddev>
              <!--                            <bias_stddev>1e-12</bias_stddev>-->
            </noise>
          </y>
          <z>
            <noise type="gaussian">
              <mean>0.0</mean>
              <!--                            <stddev>1e-2</stddev>-->
              <stddev>1e-12</stddev>
              <bias_mean>0.0</bias_mean>
              <bias_stddev>5e-3</bias_stddev>
              <!--                            <bias_stddev>1e-12</bias_stddev>-->
            </noise>
          </z>
        </angular_velocity>
        <linear_acceleration>
          <x>
            <noise type="gaussian">
              <mean>0.0</mean>
              <stddev>1e-12</stddev>
              <!-- gazebo is noisy enough -->
              <bias_mean>0.0</bias_mean>
              <bias_stddev>1e-3</bias_stddev>
              <!--                            <bias_stddev>1e-12</bias_stddev>-->
            </noise>
          </x>
          <y>
            <noise type="gaussian">
              <mean>0.0</mean>
              <stddev>2e-4</stddev>
              <!--                            <stddev>1e-12</stddev>-->
              <bias_mean>0.0</bias_mean>
              <bias_stddev>1e-4</bias_stddev>
              <!--                            <bias_stddev>1e-12</bias_stddev>-->
            </noise>
          </y>
          <z>
            <noise type="gaussian">
              <mean>0.0</mean>
              <stddev>1e-12</stddev>
              <!-- gazebo is noisy enough -->
              <bias_mean>0.0</bias_mean>
              <bias_stddev>1e-4</bias_stddev>
              <!--                            <bias_stddev>1e-12</bias_stddev>-->
            </noise>
          </z>
        </linear_acceleration>
      </imu>
      <always_on>1</always_on>
      <update_rate>200</update_rate>
      <plugin filename="libimu_ros_plugin.so" name="imu_plugin">
        <topicName>imu/data</topicName>
        <frameName>imu</frameName>
        <updateRateHZ>100</updateRateHZ>
        <orientationCovariance>0.017453 0.017453 0.157080</orientationCovariance>
        <gyroscopeCovariance>0.000436 0.000436 0.000436</gyroscopeCovariance>
        <accelerometerCovariance>0.000400 0.000400 0.000400</accelerometerCovariance>
      </plugin>
    </sensor>
  </gazebo>
</robot>

