<?xml version="1.0"?>
<sdf version="1.6">
  <model name="coro_karen_sensor_config_1">
    <enable_wind>1</enable_wind>
    <static>0</static>
    <pose>0 0 0.1275 0 0 0</pose>
    <link name="base_link">
      <inertial>
        <pose>0 0 0.0725 0 0 0</pose>
        <mass>90.0</mass>
        <inertia>
          <ixx>3.333</ixx>
          <iyy>9.733</iyy>
          <izz>9.733</izz>
        </inertia>
      </inertial>
      <collision name="tower_collision">
        <pose>0.37 0 0.45625 0 0 0</pose>
        <geometry>
          <box>
            <size>0.2 0.2 0.4125</size>
          </box>
        </geometry>
      </collision>
      <collision name="chassis_main_collision">
        <pose>0 0 0.15 0 0 0</pose>
        <geometry>
          <box>
            <size>1.0 0.45 0.2</size>
          </box>
        </geometry>
      </collision>



      <visual name="chassis_main_visual">
        <pose>0 0 0.15 0 0 0</pose>
        <geometry>
          <box>
            <size>1.0 0.45 0.2</size>
          </box>
        </geometry>
        <material>
          <ambient>0.9411764705882353 0.9411764705882353 0.9411764705882353 1</ambient>
          <diffuse>0.9411764705882353 0.9411764705882353 0.9411764705882353 1</diffuse>
        </material>
      </visual>
      <collision name="front_side_collision">
        <pose>0.5 0 0.3 1.5707 0 0</pose>
        <geometry>
          <cylinder>
            <radius>0.07</radius>
            <length>0.55</length>
          </cylinder>
        </geometry>
      </collision>

      <visual name="front_side">
        <pose>0.5 0 0.3 1.5707 0 0</pose>
        <geometry>
          <cylinder>
            <radius>0.07</radius>
            <length>0.55</length>
          </cylinder>
        </geometry>
        <material>
          <ambient>0.39215686274509803 0.39215686274509803 0.9215686274509803 1</ambient>
          <diffuse>0.39215686274509803 0.39215686274509803 0.9215686274509803 1</diffuse>
        </material>
      </visual>
      <collision name="back_side_collision">
        <pose>-0.5 0 0.3 1.5707 0 0</pose>
        <geometry>
          <cylinder>
            <radius>0.07</radius>
            <length>0.55</length>
          </cylinder>
        </geometry>
      </collision>
      <visual name="back_side">
        <pose>-0.5 0 0.3 1.5707 0 0</pose>
        <geometry>
          <cylinder>
            <radius>0.07</radius>
            <length>0.55</length>
          </cylinder>
        </geometry>
        <material>
          <ambient>0.39215686274509803 0.39215686274509803 0.9215686274509803 1</ambient>
          <diffuse>0.39215686274509803 0.39215686274509803 0.9215686274509803 1</diffuse>
        </material>
      </visual>
      <collision name="left_side_collision">
        <pose>0 0.25 0.3 0 1.5707 0</pose>
        <geometry>
          <cylinder>
            <radius>0.07</radius>
            <length>1.0</length>
          </cylinder>
        </geometry>
      </collision>
      <visual name="left_side">
        <pose>0 0.25 0.3 0 1.5707 0</pose>
        <geometry>
          <cylinder>
            <radius>0.07</radius>
            <length>1.0</length>
          </cylinder>
        </geometry>
        <material>
          <ambient>0.39215686274509803 0.39215686274509803 0.9215686274509803 1</ambient>
          <diffuse>0.39215686274509803 0.39215686274509803 0.9215686274509803 1</diffuse>
        </material>
      </visual>
      <collision name="right_side_collision">
        <pose>0 -0.25 0.3 0 1.5707 0</pose>
        <geometry>
          <cylinder>
            <radius>0.07</radius>
            <length>1.0</length>
          </cylinder>
        </geometry>
      </collision>
      <visual name="right_side">
        <pose>0 -0.25 0.3 0 1.5707 0</pose>
        <geometry>
          <cylinder>
            <radius>0.07</radius>
            <length>1.0</length>
          </cylinder>
        </geometry>
        <material>
          <ambient>0.39215686274509803 0.39215686274509803 0.9215686274509803 1</ambient>
          <diffuse>0.39215686274509803 0.39215686274509803 0.9215686274509803 1</diffuse>
        </material>
      </visual>
      <collision name="differential_collision">
        <pose>-0.5 0 0.0 1.5707 0 0</pose>
        <geometry>
          <cylinder>
            <radius>0.06</radius>
            <length>0.44</length>
          </cylinder>
        </geometry>
      </collision>
      <visual name="differential_visual">
        <pose>-0.5 0 0.0 1.5707 0 0</pose>
        <geometry>
          <cylinder>
            <radius>0.06</radius>
            <length>0.44</length>
          </cylinder>
        </geometry>
        <material>
          <ambient>0.39215686274509803 0.39215686274509803 0.9215686274509803 1</ambient>
          <diffuse>0.39215686274509803 0.39215686274509803 0.9215686274509803 1</diffuse>
        </material>
      </visual>




      <visual name="plate1_visual">
        <pose>0.37 0 0.66 0 0 0</pose>
        <geometry>
          <box>
            <size>0.2 0.2 0.005</size>
          </box>
        </geometry>
        <material>
          <ambient>0.7843137254901961 0.7843137254901961 0.7843137254901961 1</ambient>
          <diffuse>0.7843137254901961 0.7843137254901961 0.7843137254901961 1</diffuse>
        </material>
      </visual>

      <visual name="plate2_visual">
        <pose>0.37 0 0.55 0 0 0</pose>
        <geometry>
          <box>
            <size>0.2 0.2 0.005</size>
          </box>
        </geometry>
        <material>
          <ambient>0.7843137254901961 0.7843137254901961 0.7843137254901961 1</ambient>
          <diffuse>0.7843137254901961 0.7843137254901961 0.7843137254901961 1</diffuse>
        </material>
      </visual>

      <visual name="plate3_visual">
        <pose>0.37 0 0.36 0 0 0</pose>
        <geometry>
          <box>
            <size>0.2 0.2 0.005</size>
          </box>
        </geometry>
        <material>
          <ambient>0.9411764705882353 0.9411764705882353 0.9411764705882353 1</ambient>
          <diffuse>0.9411764705882353 0.9411764705882353 0.9411764705882353 1</diffuse>
        </material>
      </visual>

      <visual name="beam1_visual">
        <pose>0.461 0.091 0.51 0 0 0</pose>
        <geometry>
          <box>
            <size>0.02 0.02 0.3</size>
          </box>
        </geometry>
        <material>
          <ambient>0.7843137254901961 0.7843137254901961 0.7843137254901961 1</ambient>
          <diffuse>0.7843137254901961 0.7843137254901961 0.7843137254901961 1</diffuse>
        </material>
      </visual>
      <visual name="beam2_visual">
        <pose>0.461 -0.091 0.51 0 0 0</pose>
        <geometry>
          <box>
            <size>0.02 0.02 0.3</size>
          </box>
        </geometry>
        <material>
          <ambient>0.7843137254901961 0.7843137254901961 0.7843137254901961 1</ambient>
          <diffuse>0.7843137254901961 0.7843137254901961 0.7843137254901961 1</diffuse>
        </material>
      </visual>
      <visual name="beam3_visual">
        <pose>0.279 0.091 0.41 0 0 0</pose>
        <geometry>
          <box>
            <size>0.02 0.02 0.5</size>
          </box>
        </geometry>
        <material>
          <ambient>0.7843137254901961 0.7843137254901961 0.7843137254901961 1</ambient>
          <diffuse>0.7843137254901961 0.7843137254901961 0.7843137254901961 1</diffuse>
        </material>
      </visual>
      <visual name="beam4_visual">
        <pose>0.279 -0.091 0.41 0 0 0</pose>
        <geometry>
          <box>
            <size>0.02 0.02 0.5</size>
          </box>
        </geometry>
        <material>
          <ambient>0.7843137254901961 0.7843137254901961 0.7843137254901961 1</ambient>
          <diffuse>0.7843137254901961 0.7843137254901961 0.7843137254901961 1</diffuse>
        </material>
      </visual>

      <visual name="d435i_realsense_camera_visual">
        <pose>0.43 0 0.634 0 0.52 0</pose>
        <geometry>
          <mesh>
            <scale>0.001 0.001 0.001</scale>
            <uri>meshes/realsense_d435.dae</uri>
          </mesh>
        </geometry>
      </visual>

      <visual name="vlp16_visual1">
        <pose>0.37 0 0.552 0 -0 0</pose>
        <geometry>
          <mesh>
            <scale>1 1 1</scale>
            <uri>meshes/VLP16_base_1.dae</uri>
          </mesh>
        </geometry>
      </visual>
      <visual name="vlp_visual2">
        <pose>0.37 0 0.552 0 -0 0</pose>
        <geometry>
          <mesh>
            <scale>1 1 1</scale>
            <uri>meshes/VLP16_base_2.dae</uri>
          </mesh>
        </geometry>
      </visual>
      <visual name="vlp_visual3">
        <pose>0.37 0 0.552 0 -0 0</pose>
        <geometry>
          <mesh>
            <scale>1 1 1</scale>
            <uri>meshes/VLP16_scan.dae</uri>
          </mesh>
        </geometry>
      </visual>




      <visual name="emergency_stop_bottom_visual">
        <pose>0.13 -0.13 0.26 0 0 0</pose>
        <geometry>
          <cylinder>
            <length>0.015</length>
            <radius>0.015</radius>
          </cylinder>
        </geometry>
        <material>
          <ambient>0.7058823529411765 0.7058823529411765 0.7058823529411765 1.0</ambient>
          <diffuse>0.7058823529411765 0.7058823529411765 0.7058823529411765 1.0</diffuse>
        </material>
      </visual>
      <visual name="emergency_stop_top_visual">
        <pose>0.13 -0.13 0.27 0 0 0</pose>
        <geometry>
          <cylinder>
            <length>0.005</length>
            <radius>0.02</radius>
          </cylinder>
        </geometry>
        <material>
          <ambient>1.0 0 0 1.0</ambient>
          <diffuse>1.0 0 0 1.0</diffuse>
        </material>
      </visual>




      <!-- IMU  -->
      <sensor name="imu_sensor" type="imu">
        <always_on>1</always_on>
        <update_rate>50</update_rate>
        <imu>
          <angular_velocity>
            <x>
              <noise type="gaussian">
                <mean>0</mean>
                <stddev>0.009</stddev>
                <bias_mean>0.00075</bias_mean>
                <bias_stddev>0.005</bias_stddev>
                <dynamic_bias_stddev>0.00002</dynamic_bias_stddev>
                <dynamic_bias_correlation_time>400.0</dynamic_bias_correlation_time>
                <precision>0.00025</precision>
              </noise>
            </x>
            <y>
              <noise type="gaussian">
                <mean>0</mean>
                <stddev>0.009</stddev>
                <bias_mean>0.00075</bias_mean>
                <bias_stddev>0.005</bias_stddev>
                <dynamic_bias_stddev>0.00002</dynamic_bias_stddev>
                <dynamic_bias_correlation_time>400.0</dynamic_bias_correlation_time>
                <precision>0.00025</precision>
              </noise>
            </y>
            <z>
              <noise type="gaussian">
                <mean>0</mean>
                <stddev>0.009</stddev>
                <bias_mean>0.00075</bias_mean>
                <bias_stddev>0.005</bias_stddev>
                <dynamic_bias_stddev>0.00002</dynamic_bias_stddev>
                <dynamic_bias_correlation_time>400.0</dynamic_bias_correlation_time>
                <precision>0.00025</precision>
              </noise>
            </z>
          </angular_velocity>
          <linear_acceleration>
            <x>
              <noise type="gaussian">
                <mean>0</mean>
                <stddev>0.021</stddev>
                <bias_mean>0.05</bias_mean>
                <bias_stddev>0.0075</bias_stddev>
                <dynamic_bias_stddev>0.000375</dynamic_bias_stddev>
                <dynamic_bias_correlation_time>175.0</dynamic_bias_correlation_time>
                <precision>0.005</precision>
              </noise>
            </x>
            <y>
              <noise type="gaussian">
                <mean>0</mean>
                <stddev>0.021</stddev>
                <bias_mean>0.05</bias_mean>
                <bias_stddev>0.0075</bias_stddev>
                <dynamic_bias_stddev>0.000375</dynamic_bias_stddev>
                <dynamic_bias_correlation_time>175.0</dynamic_bias_correlation_time>
                <precision>0.005</precision>
              </noise>
            </y>
            <z>
              <noise type="gaussian">
                <mean>0</mean>
                <stddev>0.021</stddev>
                <bias_mean>0.05</bias_mean>
                <bias_stddev>0.0075</bias_stddev>
                <dynamic_bias_stddev>0.000375</dynamic_bias_stddev>
                <dynamic_bias_correlation_time>175.0</dynamic_bias_correlation_time>
                <precision>0.005</precision>
              </noise>
            </z>
          </linear_acceleration>
        </imu>
      </sensor>


      <sensor name="magnetometer" type="magnetometer">
        <always_on>1</always_on>
        <update_rate>50</update_rate>
        <magnetometer>
          <x>
            <noise type="gaussian">
              <mean>0.000000080</mean>
              <bias_mean>0.000000400</bias_mean>
            </noise>
          </x>
          <y>
            <noise type="gaussian">
              <mean>0.000000080</mean>
              <bias_mean>0.000000400</bias_mean>
            </noise>
          </y>
          <z>
            <noise type="gaussian">
              <mean>0.000000080</mean>
              <bias_mean>0.000000400</bias_mean>
            </noise>
          </z>
        </magnetometer>
      </sensor>

      <sensor name="air_pressure" type="air_pressure">
        <always_on>1</always_on>
        <update_rate>20</update_rate>
        <air_pressure>
          <reference_altitude>0</reference_altitude>
          <noise type="gaussian">
            <mean>0.00000008</mean>
          </noise>
        </air_pressure>
      </sensor>


      <!-- thermal camera -->
      <visual name="thermal_camera_visual">
        <pose>0.45 -0.06 0.645 0 0 0</pose>
        <geometry>
          <box>
            <size>0.02 0.03 0.03</size>
          </box>
        </geometry>
      </visual>
      <sensor name="thermal_camera" type="thermal">
        <pose>0.48 -0.06 0.645 0 0 0</pose>
        <camera name="thermal_camera">
          <horizontal_fov>0.628</horizontal_fov>
          <lens>
            <intrinsics>
              <!-- fx = fy = width / ( 2 * tan (hfov / 2 ) ) -->
              <fx>317.173</fx>
              <fy>317.173</fy>
              <!-- cx = ( width - 1 ) / 2 -->
              <cx>102.5</cx>
              <!-- cy = ( height - 1 ) / 2 -->
              <cy>77.5</cy>
              <s>0</s>
            </intrinsics>
          </lens>
          <image>
            <width>206</width>
            <height>156</height>
          </image>
          <clip>
            <near>0.1</near>
            <far>100</far>
          </clip>
        </camera>
        <always_on>1</always_on>
        <update_rate>9</update_rate>
      </sensor>



      <!-- Based on Intel realsense D435 (intrinsics and distortion not modeled)-->
      <sensor name="rs_front" type="rgbd_camera">
        <pose>0.45 0 0.634 0 0.52 0</pose>
        <always_on>1</always_on>
        <update_rate>30</update_rate>
        <camera name="rs_front">
          <horizontal_fov>1.50098</horizontal_fov>
          <lens>
            <intrinsics>
              <!-- fx = fy = width / ( 2 * tan (hfov / 2 ) ) -->
              <fx>343.159</fx>
              <fy>343.159</fy>
              <!-- cx = ( width - 1 ) / 2 -->
              <cx>319.5</cx>
              <!-- cy = ( height - 1 ) / 2 -->
              <cy>179.5</cy>
              <s>0</s>
            </intrinsics>
          </lens>
          <distortion>
            <k1>0.0</k1>
            <k2>0.0</k2>
            <k3>0.0</k3>
            <p1>0.0</p1>
            <p2>0.0</p2>
            <center>0.5 0.5</center>
          </distortion>
          <image>
            <width>640</width>
            <height>360</height>
            <format>R8G8B8</format>
          </image>
          <clip>
            <near>0.01</near>
            <far>300</far>
          </clip>
          <depth_camera>
            <clip>
              <near>0.1</near>
              <far>10</far>
            </clip>
          </depth_camera>
          <noise>
            <type>gaussian</type>
            <mean>0</mean>
            <stddev>0.007</stddev>
          </noise>
        </camera>
      </sensor>




      <!-- 3D Velodyne VLP-16 lidar -->


      <sensor name="front_laser" type="gpu_ray">
        <pose>0.37 0 0.592 0 0 0</pose>
        <update_rate>10</update_rate>
        <lidar>
          <scan>
            <horizontal>
              <samples>1800</samples>
              <resolution>1.0</resolution>
              <min_angle>-3.1459</min_angle>
              <max_angle>3.1459</max_angle>
            </horizontal>
            <vertical>
              <samples>16</samples>
              <resolution>1</resolution>
              <min_angle>-0.261799</min_angle>
              <max_angle>0.261799</max_angle>
            </vertical>
          </scan>
          <range>
            <min>0.05</min>
            <max>100</max>
            <resolution>0.01</resolution>
          </range>
          <noise>
            <type>gaussian</type>
            <mean>0</mean>
            <stddev>0.01</stddev>
          </noise>
        </lidar>
      </sensor>




      <visual name="camera_front_visual">
        <pose>0.46 0.06 0.645 0 0 0</pose>
        <geometry>
          <box>
            <size>0.01 0.03 0.03</size>
          </box>
        </geometry>
        <material>
          <ambient>0.0 0.0 0.0 1.0</ambient>
          <diffuse>0.0 0.0 0.0 1.0</diffuse>
        </material>
      </visual>
      <visual name="camera_lens_front_visual">
        <pose>0.47 0.06 0.645 0 1.5707963267948966 0</pose>
        <geometry>
          <cylinder>
            <length>0.011</length>
            <radius>0.005</radius>
          </cylinder>
        </geometry>
        <material>
          <ambient>0.0 0.0 0.0 1.0</ambient>
          <diffuse>0.0 0.0 0.0 1.0</diffuse>
        </material>
      </visual>

      <visual name="camera_rear_visual">
        <pose>0.28 0 0.645 0 0 0</pose>
        <geometry>
          <box>
            <size>0.01 0.03 0.03</size>
          </box>
        </geometry>
        <material>
          <ambient>0.0 0.0 0.0 1.0</ambient>
          <diffuse>0.0 0.0 0.0 1.0</diffuse>
        </material>
      </visual>
      <visual name="camera_lens_rear_visual">
        <pose>0.27 0 0.645 0 1.5707963267948966 0</pose>
        <geometry>
          <cylinder>
            <length>0.011</length>
            <radius>0.005</radius>
          </cylinder>
        </geometry>
        <material>
          <ambient>0.0 0.0 0.0 1.0</ambient>
          <diffuse>0.0 0.0 0.0 1.0</diffuse>
        </material>
      </visual>

      <visual name="camera_left_visual">
        <pose>0.37 0.09 0.645 0 0 0</pose>
        <geometry>
          <box>
            <size>0.03 0.01 0.03</size>
          </box>
        </geometry>
        <material>
          <ambient>0.0 0.0 0.0 1.0</ambient>
          <diffuse>0.0 0.0 0.0 1.0</diffuse>
        </material>
      </visual>
      <visual name="camera_lens_left_visual">
        <pose>0.37 0.1 0.645 1.5707963267948966 0 0</pose>
        <geometry>
          <cylinder>
            <length>0.011</length>
            <radius>0.005</radius>
          </cylinder>
        </geometry>
        <material>
          <ambient>0.0 0.0 0.0 1.0</ambient>
          <diffuse>0.0 0.0 0.0 1.0</diffuse>
        </material>
      </visual>

      <visual name="camera_right_visual">
        <pose>0.37 -0.09 0.645 0 0 0</pose>
        <geometry>
          <box>
            <size>0.03 0.01 0.03</size>
          </box>
        </geometry>
        <material>
          <ambient>0.0 0.0 0.0 1.0</ambient>
          <diffuse>0.0 0.0 0.0 1.0</diffuse>
        </material>
      </visual>
      <visual name="camera_lens_right_visual">
        <pose>0.37 -0.1 0.645 1.5707963267948966 0 0</pose>
        <geometry>
          <cylinder>
            <length>0.011</length>
            <radius>0.005</radius>
          </cylinder>
        </geometry>
        <material>
          <ambient>0.0 0.0 0.0 1.0</ambient>
          <diffuse>0.0 0.0 0.0 1.0</diffuse>
        </material>
      </visual>


      <!-- Real robot has 2 x B0203 with LN008 each with a 180 deg hor x 130 deg vert FOV
           Since fisheye cameras are not modeled, four VGA cameras are used in the model -->
      <sensor name="camera_front" type="camera">
        <pose>0.48 0.06 0.645 0 0 0</pose>
        <always_on>1</always_on>
        <update_rate>25</update_rate>
        <camera name="camera_front">
          <horizontal_fov>1.658</horizontal_fov>
          <lens>
            <intrinsics>
              <!-- fx = fy = width / ( 2 * tan (hfov / 2 ) ) -->
              <fx>329.9</fx>
              <fy>329.9</fy>
              <!-- cx = ( width - 1 ) / 2 -->
              <cx>359.5</cx>
              <!-- cy = ( height - 1 ) / 2 -->
              <cy>539.5</cy>
              <s>0</s>
            </intrinsics>
          </lens>
          <distortion>
            <k1>0.0</k1>
            <k2>0.0</k2>
            <k3>0.0</k3>
            <p1>0.0</p1>
            <p2>0.0</p2>
            <center>0.5 0.5</center>
          </distortion>
          <image>
            <width>720</width>
            <height>1080</height>
            <format>R8G8B8</format>
          </image>
          <clip>
            <near>0.01</near>
            <far>300</far>
          </clip>
          <noise>
            <type>gaussian</type>
            <mean>0</mean>
            <stddev>0.007</stddev>
          </noise>
        </camera>
      </sensor>

      <sensor name="camera_rear" type="camera">
        <pose>0.26 0 0.645 0 0 3.141592653589793</pose>
        <always_on>1</always_on>
        <update_rate>25</update_rate>
        <camera name="camera_front">
          <horizontal_fov>1.658</horizontal_fov>
          <lens>
            <intrinsics>
              <!-- fx = fy = width / ( 2 * tan (hfov / 2 ) ) -->
              <fx>329.9</fx>
              <fy>329.9</fy>
              <!-- cx = ( width - 1 ) / 2 -->
              <cx>359.5</cx>
              <!-- cy = ( height - 1 ) / 2 -->
              <cy>539.5</cy>
              <s>0</s>
            </intrinsics>
          </lens>
          <distortion>
            <k1>0.0</k1>
            <k2>0.0</k2>
            <k3>0.0</k3>
            <p1>0.0</p1>
            <p2>0.0</p2>
            <center>0.5 0.5</center>
          </distortion>
          <image>
            <width>720</width>
            <height>1080</height>
            <format>R8G8B8</format>
          </image>
          <clip>
            <near>0.01</near>
            <far>300</far>
          </clip>
          <noise>
            <type>gaussian</type>
            <mean>0</mean>
            <stddev>0.007</stddev>
          </noise>
        </camera>
      </sensor>

      <sensor name="camera_left" type="camera">
        <pose>0.37 0.11 0.645 0 0 1.5707963267948966</pose>
        <always_on>1</always_on>
        <update_rate>25</update_rate>
        <camera name="camera_front">
          <horizontal_fov>1.658</horizontal_fov>
          <lens>
            <intrinsics>
              <!-- fx = fy = width / ( 2 * tan (hfov / 2 ) ) -->
              <fx>329.9</fx>
              <fy>329.9</fy>
              <!-- cx = ( width - 1 ) / 2 -->
              <cx>359.5</cx>
              <!-- cy = ( height - 1 ) / 2 -->
              <cy>539.5</cy>
              <s>0</s>
            </intrinsics>
          </lens>
          <distortion>
            <k1>0.0</k1>
            <k2>0.0</k2>
            <k3>0.0</k3>
            <p1>0.0</p1>
            <p2>0.0</p2>
            <center>0.5 0.5</center>
          </distortion>
          <image>
            <width>720</width>
            <height>1080</height>
            <format>R8G8B8</format>
          </image>
          <clip>
            <near>0.01</near>
            <far>300</far>
          </clip>
          <noise>
            <type>gaussian</type>
            <mean>0</mean>
            <stddev>0.007</stddev>
          </noise>
        </camera>
      </sensor>

      <sensor name="camera_right" type="camera">
        <pose>0.37 -0.11 0.645 0 0 -1.5707963267948966</pose>
        <always_on>1</always_on>
        <update_rate>25</update_rate>
        <camera name="camera_front">
          <horizontal_fov>1.658</horizontal_fov>
          <lens>
            <intrinsics>
              <!-- fx = fy = width / ( 2 * tan (hfov / 2 ) ) -->
              <fx>329.9</fx>
              <fy>329.9</fy>
              <!-- cx = ( width - 1 ) / 2 -->
              <cx>359.5</cx>
              <!-- cy = ( height - 1 ) / 2 -->
              <cy>539.5</cy>
              <s>0</s>
            </intrinsics>
          </lens>
          <distortion>
            <k1>0.0</k1>
            <k2>0.0</k2>
            <k3>0.0</k3>
            <p1>0.0</p1>
            <p2>0.0</p2>
            <center>0.5 0.5</center>
          </distortion>
          <image>
            <width>720</width>
            <height>1080</height>
            <format>R8G8B8</format>
          </image>
          <clip>
            <near>0.01</near>
            <far>300</far>
          </clip>
          <noise>
            <type>gaussian</type>
            <mean>0</mean>
            <stddev>0.007</stddev>
          </noise>
        </camera>
      </sensor>



      <light name="light_front_left" type="spot">
        <pose>0.45 0.23 0.44 1.5 0 -0.75</pose>
        <attenuation>
          <range>25</range>
          <linear>0</linear>
          <constant>0.1</constant>
          <quadratic>0.005</quadratic>
        </attenuation>
        <diffuse>0.8 0.8 0.5 1</diffuse>
        <specular>0.8 0.8 0.5 1</specular>
        <spot>
          <inner_angle>1.571</inner_angle>
          <outer_angle>2.1</outer_angle>
          <falloff>1</falloff>
        </spot>
        <direction>1 0 0</direction>
        <cast_shadows>1</cast_shadows>
      </light>
      <light name="light_front_right" type="spot">
        <pose>0.45 -0.23 0.44 1.5 0 -2.25 </pose>
        <attenuation>
          <range>25</range>
          <linear>0</linear>
          <constant>0.1</constant>
          <quadratic>0.005</quadratic>
        </attenuation>
        <diffuse>0.8 0.8 0.5 1</diffuse>
        <specular>0.8 0.8 0.5 1</specular>
        <spot>
          <inner_angle>1.571</inner_angle>
          <outer_angle>2.1</outer_angle>
          <falloff>1</falloff>
        </spot>
        <direction>-1 0 0</direction>
        <cast_shadows>1</cast_shadows>
      </light>
      <light name="light_rear_left" type="spot">
        <pose>-0.31 0.25 0.44 1.5 0 0.75</pose>
        <attenuation>
          <range>25</range>
          <linear>0</linear>
          <constant>0.1</constant>
          <quadratic>0.005</quadratic>
        </attenuation>
        <diffuse>0.8 0.8 0.5 1</diffuse>
        <specular>0.8 0.8 0.5 1</specular>
        <spot>
          <inner_angle>1.571</inner_angle>
          <outer_angle>2.1</outer_angle>
          <falloff>1</falloff>
        </spot>
        <direction>0 1 0</direction>
        <cast_shadows>1</cast_shadows>
      </light>
      <light name="light_rear_right" type="spot">
        <pose>-0.31 -0.25 0.44 1.5 0 2.25</pose>
        <attenuation>
          <range>25</range>
          <linear>0</linear>
          <constant>0.1</constant>
          <quadratic>0.005</quadratic>
        </attenuation>
        <diffuse>0.8 0.8 0.5 1</diffuse>
        <specular>0.8 0.8 0.5 1</specular>
        <spot>
          <inner_angle>1.571</inner_angle>
          <outer_angle>2.1</outer_angle>
          <falloff>1</falloff>
        </spot>
        <direction>0 -1 0</direction>
        <cast_shadows>1</cast_shadows>
      </light>
      <collision name="light_front_left_collision">
        <pose>0.44 0.23 0.41 0 0 0.75</pose>
        <geometry>
          <box>
            <size>0.01 0.12 0.08</size>
          </box>
        </geometry>
      </collision>
      <visual name="light_front_left_visual">
        <pose>0.44 0.23 0.41 0 0 0.75</pose>
        <geometry>
          <box>
            <size>0.01 0.12 0.08</size>
          </box>
        </geometry>
        <material>
          <ambient>1.0 1.0 1.0 1.0</ambient>
          <diffuse>1.0 1.0 1.0 1.0</diffuse>
        </material>
      </visual>
      <collision name="light_front_right_collision">
        <pose>0.44 -0.23 0.41 0 0 -0.75</pose>
        <geometry>
          <box>
            <size>0.01 0.12 0.08</size>
          </box>
        </geometry>
      </collision>
      <visual name="light_front_right_visual">
        <pose>0.44 -0.23 0.41 0 0 -0.75</pose>
        <geometry>
          <box>
            <size>0.01 0.12 0.08</size>
          </box>
        </geometry>
        <material>
          <ambient>1.0 1.0 1.0 1.0</ambient>
          <diffuse>1.0 1.0 1.0 1.0</diffuse>
        </material>
      </visual>
      <collision name="light_rear_left_collision">
        <pose>-0.3 0.25 0.41 0 0 -0.75</pose>
        <geometry>
          <box>
            <size>0.01 0.12 0.08</size>
          </box>
        </geometry>
      </collision>
      <visual name="light_rear_left_visual">
        <pose>-0.3 0.25 0.41 0 0 -0.75</pose>
        <geometry>
          <box>
            <size>0.01 0.12 0.08</size>
          </box>
        </geometry>
        <material>
          <ambient>1.0 1.0 1.0 1.0</ambient>
          <diffuse>1.0 1.0 1.0 1.0</diffuse>
        </material>
      </visual>
      <collision name="light_rear_right_collision">
        <pose>-0.3 -0.25 0.41 0 0 0.75</pose>
        <geometry>
          <box>
            <size>0.01 0.12 0.08</size>
          </box>
        </geometry>
      </collision>
      <visual name="light_rear_right_visual">
        <pose>-0.3 -0.25 0.41 0 0 0.75</pose>
        <geometry>
          <box>
            <size>0.01 0.12 0.08</size>
          </box>
        </geometry>
        <material>
          <ambient>1.0 1.0 1.0 1.0</ambient>
          <diffuse>1.0 1.0 1.0 1.0</diffuse>
        </material>
      </visual>

    </link>



    <link name="front_left_wheel_steering_link">
      <pose>0.465 0.22 0.02 0 0 0</pose>
      <inertial>
        <mass>0.5</mass>
        <inertia>
          <ixx>0.0153</ixx>
          <iyy>0.025</iyy>
          <izz>0.0153</izz>
        </inertia>
      </inertial>
      <visual name="steering_link_visual">
        <pose>0 0 0 0 0 0</pose>
        <geometry>
          <cylinder>
            <length>0.1</length>
            <radius>0.03</radius>
          </cylinder>
        </geometry>
        <material>
          <ambient>0.043137254901960784 0.043137254901960784 0.043137254901960784 1.0</ambient>
          <diffuse>0.043137254901960784 0.043137254901960784 0.043137254901960784 1.0</diffuse>
        </material>
      </visual>
    </link>

    <link name="front_right_wheel_steering_link">
      <pose>0.465 -0.22 0.02 0 0 0</pose>
      <inertial>
        <mass>0.5</mass>
        <inertia>
          <ixx>0.0153</ixx>
          <iyy>0.025</iyy>
          <izz>0.0153</izz>
        </inertia>
      </inertial>
      <visual name="steering_link_visual">
        <pose>0 0 0 0 0 0</pose>
        <geometry>
          <cylinder>
            <length>0.1</length>
            <radius>0.03</radius>
          </cylinder>
        </geometry>
        <material>
          <ambient>0.043137254901960784 0.043137254901960784 0.043137254901960784 1.0</ambient>
          <diffuse>0.043137254901960784 0.043137254901960784 0.043137254901960784 1.0</diffuse>
        </material>
      </visual>
    </link>

    <link name="front_left_wheel">
      <pose>0.465 0.325 0 0 0 0</pose>
      <!-- Inertia and size need adjusted -->
      <inertial>
        <mass>5.0</mass>
        <inertia>
          <ixx>0.043</ixx>
          <iyy>0.076</iyy>
          <izz>0.043</izz>
        </inertia>
      </inertial>
      <collision name="collision">
        <pose>0 0 0 -1.5707963267948966 0 0</pose>
        <geometry>
          <cylinder>
            <length>0.11</length>
            <radius>0.175</radius>
          </cylinder>
        </geometry>
        <surface>
          <friction>
            <ode>
              <mu>1</mu>
              <mu2>1</mu2>
              <fdir1>0 0 1</fdir1>
            </ode>
          </friction>
        </surface>
      </collision>
      <visual name="tire_visual">
        <pose>0 0 0 0 0 0</pose>
        <geometry>
          <mesh>
            <uri>meshes/wheel.dae</uri>
            <scale>1.01 1.0 1.01</scale>
          </mesh>
        </geometry>
      </visual>
      <visual name="hub_visual">
        <pose>0 -0.01 0 1.5707963267948966 0 0</pose>
        <geometry>
          <cylinder>
            <length>0.025</length>
            <radius>0.04</radius>
          </cylinder>
        </geometry>
        <material>
          <ambient>0.5 0.5 0.5 1.0</ambient>
          <diffuse>0.5 0.5 0.5 1.0</diffuse>
        </material>
      </visual>
      <visual name="axis_visual">
        <pose>0 -0.08 0 1.5707963267948966 0 0</pose>
        <geometry>
          <cylinder>
            <length>0.1</length>
            <radius>0.008</radius>
          </cylinder>
        </geometry>
        <material>
          <ambient>0 0 0 1.0</ambient>
          <diffuse>0 0 0 1.0</diffuse>
        </material>
      </visual>
    </link>

    <link name="front_right_wheel">
      <pose>0.465 -0.325 0 0 0 0</pose>
      <inertial>
        <mass>5.0</mass>
        <inertia>
          <ixx>0.043</ixx>
          <iyy>0.076</iyy>
          <izz>0.043</izz>
        </inertia>
      </inertial>
      <collision name="collision">
        <pose>0 0 0 1.5707963267948966 0 0</pose>
        <geometry>
          <cylinder>
            <length>0.11</length>
            <radius>0.175</radius>
          </cylinder>
        </geometry>
        <surface>
          <friction>
            <ode>
              <mu>1</mu>
              <mu2>1</mu2>
              <fdir1>0 0 1</fdir1>
            </ode>
          </friction>
        </surface>
      </collision>
      <visual name="tire_visual">
        <pose>0 0 0 0 0 0</pose>
        <geometry>
          <mesh>
            <uri>meshes/wheel.dae</uri>
            <scale>1.01 1.0 1.01</scale>
          </mesh>
        </geometry>
      </visual>
      <visual name="hub_visual">
        <pose>0 0.01 0 1.5707963267948966 0 0</pose>
        <geometry>
          <cylinder>
            <length>0.025</length>
            <radius>0.04</radius>
          </cylinder>
        </geometry>
        <material>
          <ambient>0.5 0.5 0.5 1.0</ambient>
          <diffuse>0.5 0.5 0.5 1.0</diffuse>
        </material>
      </visual>
      <visual name="axis_visual">
        <pose>0 0.08 0 1.5707963267948966 0 0</pose>
        <geometry>
          <cylinder>
            <length>0.1</length>
            <radius>0.008</radius>
          </cylinder>
        </geometry>
        <material>
          <ambient>0 0 0 1.0</ambient>
          <diffuse>0 0 0 1.0</diffuse>
        </material>
      </visual>
    </link>

    <link name="rear_left_wheel">
      <pose>-0.465 0.325 0 0 0 0</pose>
      <inertial>
        <mass>5.0</mass>
        <inertia>
          <ixx>0.043</ixx>
          <iyy>0.076</iyy>
          <izz>0.043</izz>
        </inertia>
      </inertial>
      <collision name="collision">
        <pose>0 0 0 -1.5707963267948966 0 0</pose>
        <geometry>
          <cylinder>
            <length>0.11</length>
            <radius>0.175</radius>
          </cylinder>
        </geometry>
        <surface>
          <friction>
            <ode>
              <mu>1</mu>
              <mu2>1</mu2>
              <fdir1>0 0 1</fdir1>
            </ode>
          </friction>
        </surface>
      </collision>
      <visual name="tire_visual">
        <pose>0 0 0 0 0 0</pose>
        <geometry>
          <mesh>
            <uri>meshes/wheel.dae</uri>
            <scale>1.01 1.0 1.01</scale>
          </mesh>
        </geometry>
      </visual>
      <visual name="hub_visual">
        <pose>0 -0.01 0 1.5707963267948966 0 0</pose>
        <geometry>
          <cylinder>
            <length>0.025</length>
            <radius>0.04</radius>
          </cylinder>
        </geometry>
        <material>
          <ambient>0.5 0.5 0.5 1.0</ambient>
          <diffuse>0.5 0.5 0.5 1.0</diffuse>
        </material>
      </visual>
      <visual name="axis_visual">
        <pose>0 -0.08 0 1.5707963267948966 0 0</pose>
        <geometry>
          <cylinder>
            <length>0.1</length>
            <radius>0.008</radius>
          </cylinder>
        </geometry>
        <material>
          <ambient>0 0 0 1.0</ambient>
          <diffuse>0 0 0 1.0</diffuse>
        </material>
      </visual>
    </link>

    <link name="rear_right_wheel">
      <pose>-0.465 -0.325 0 0 0 0</pose>
      <inertial>
        <mass>5.0</mass>
        <inertia>
          <ixx>0.043</ixx>
          <iyy>0.076</iyy>
          <izz>0.043</izz>
        </inertia>
      </inertial>
      <collision name="collision">
        <pose>0 0 0 1.5707963267948966 0 0</pose>
        <geometry>
          <cylinder>
            <length>0.11</length>
            <radius>0.175</radius>
          </cylinder>
        </geometry>
        <surface>
          <friction>
            <ode>
              <mu>1</mu>
              <mu2>1</mu2>
              <fdir1>0 0 1</fdir1>
            </ode>
          </friction>
        </surface>
      </collision>
      <visual name="tire_visual">
        <pose>0 0 0 0 0 0</pose>
        <geometry>
          <mesh>
            <uri>meshes/wheel.dae</uri>
            <scale>1.01 1.0 1.01</scale>
          </mesh>
        </geometry>
      </visual>
      <visual name="hub_visual">
        <pose>0 0.01 0 1.5707963267948966 0 0</pose>
        <geometry>
          <cylinder>
            <length>0.025</length>
            <radius>0.04</radius>
          </cylinder>
        </geometry>
        <material>
          <ambient>0.5 0.5 0.5 1.0</ambient>
          <diffuse>0.5 0.5 0.5 1.0</diffuse>
        </material>
      </visual>
      <visual name="axis_visual">
        <pose>0 0.08 0 1.5707963267948966 0 0</pose>
        <geometry>
          <cylinder>
            <length>0.1</length>
            <radius>0.008</radius>
          </cylinder>
        </geometry>
        <material>
          <ambient>0 0 0 1.0</ambient>
          <diffuse>0 0 0 1.0</diffuse>
        </material>
      </visual>
    </link>


    <joint name="front_left_wheel_steering_joint" type="revolute">
      <child>front_left_wheel_steering_link</child>
      <parent>base_link</parent>
      <axis>
        <xyz>0 0 1</xyz>
        <limit>
          <lower>-0.6</lower>
          <upper>+0.6</upper>
          <velocity>1.0</velocity>
          <effort>150</effort>
        </limit>
        <use_parent_model_frame>1</use_parent_model_frame>
      </axis>
    </joint>

    <joint name="front_right_wheel_steering_joint" type="revolute">
      <parent>base_link</parent>
      <child>front_right_wheel_steering_link</child>
      <axis>
        <xyz>0 0 1</xyz>
        <limit>
          <lower>-0.6</lower>
          <upper>+0.6</upper>
          <velocity>1.0</velocity>
          <effort>150</effort>
        </limit>
      </axis>
    </joint>


    <joint name="front_left_wheel_joint" type="revolute">
      <child>front_left_wheel</child>
      <parent>front_left_wheel_steering_link</parent>
      <axis>
        <xyz>0 1 0</xyz>
        <limit>
          <lower>-1.79769e+308</lower>
          <upper>+1.79769e+308</upper>
          <velocity>9.71</velocity>
          <effort>35</effort>
        </limit>
        <use_parent_model_frame>1</use_parent_model_frame>
      </axis>
    </joint>

    <joint name="front_right_wheel_joint" type="revolute">
      <parent>front_right_wheel_steering_link</parent>
      <child>front_right_wheel</child>
      <axis>
        <xyz>0 1 0</xyz>
        <limit>
          <lower>-1.79769e+308</lower>
          <upper>+1.79769e+308</upper>
          <velocity>9.71</velocity>
          <effort>35</effort>
        </limit>
      </axis>
    </joint>

    <joint name="rear_left_wheel_joint" type="revolute">
      <parent>base_link</parent>
      <child>rear_left_wheel</child>
      <axis>
        <xyz>0 1 0</xyz>
        <limit>
          <lower>-1.79769e+308</lower>
          <upper>+1.79769e+308</upper>
          <velocity>9.71</velocity>
          <!-- Torque in NM. - rear wheel drive so most torque is simulated to rear wheels -->
          <effort>35</effort>
        </limit>
      </axis>
    </joint>

    <joint name="rear_right_wheel_joint" type="revolute">
      <parent>base_link</parent>
      <child>rear_right_wheel</child>
      <axis>
        <xyz>0 1 0</xyz>
        <limit>
          <lower>-1.79769e+308</lower>
          <upper>+1.79769e+308</upper>
          <velocity>9.71</velocity>
          <!-- Torque in NM. -->
          <effort>35</effort>
        </limit>
      </axis>
    </joint>

  </model>
</sdf>
