<?xml version='1.0' encoding='utf-8'?>
<robot name='csiro_data61_ozbot_atr_sensor_config_1' xmlns:xacro='http://ros.org/wiki/xacro'>
  <xacro:arg name="name" default="csiro_data61_ozbot_atr_sensor_config_1"/>
  <xacro:property name="robot_namespace" value="$(arg name)"/>
  <link name='${robot_namespace}/base_link'>
    <inertial>
      <origin xyz='0.060405 0.000498 0.179911' rpy='0 -0 0'/>
      <mass value='100.714'/>
      <inertia ixx='3.64426' ixy='-0.00724495' ixz='0.086827' iyy='14.667' iyz='-0.00505966' izz='15.6438'/>
    </inertial>
    <collision name='base_link_fixed_joint_lump__nav_base_link_collision'>
      <origin xyz='0.433 0 0.423' rpy='0 -0 0'/>
      <geometry>
        <mesh filename='package://csiro_data61_ozbot_atr_sensor_config_1/meshes/PPV4_Sim_Base.STL' scale='1 1 1'/>
      </geometry>
    </collision>
    <collision name='base_link_fixed_joint_lump__light0_collision_1'>
      <origin xyz='0.473 0 0.663' rpy='0 -0 0'/>
      <geometry>
        <box size='0.01 0.05 0.02'/>
      </geometry>
    </collision>
    <collision name='base_link_fixed_joint_lump__light1_collision_2'>
      <origin xyz='0.433 0.04 0.663' rpy='0 -0 1.5708'/>
      <geometry>
        <box size='0.01 0.05 0.02'/>
      </geometry>
    </collision>
    <collision name='base_link_fixed_joint_lump__light2_collision_3'>
      <origin xyz='0.393 0 0.663' rpy='0 0 -3.14159'/>
      <geometry>
        <box size='0.01 0.05 0.02'/>
      </geometry>
    </collision>
    <collision name='base_link_fixed_joint_lump__light3_collision_4'>
      <origin xyz='0.433 -0.04 0.663' rpy='0 0 -1.5708'/>
      <geometry>
        <box size='0.01 0.05 0.02'/>
      </geometry>
    </collision>
    <collision name='base_link_fixed_joint_lump__titan_chassis_collision_5'>
      <origin xyz='0 0 0' rpy='0 -0 0'/>
      <geometry>
        <mesh filename='package://csiro_data61_ozbot_atr_sensor_config_1/meshes/Titan_Collision.STL' scale='1 1 1'/>
      </geometry>
    </collision>
    <visual name='base_link_fixed_joint_lump__nav_base_link_visual'>
      <origin xyz='0.433 0 0.423' rpy='0 -0 0'/>
      <geometry>
        <mesh filename='package://csiro_data61_ozbot_atr_sensor_config_1/meshes/PPV4_Sim_Base.STL' scale='1 1 1'/>
      </geometry>
    </visual>
    <visual name='base_link_fixed_joint_lump__light0_visual_1'>
      <origin xyz='0.473 0 0.663' rpy='0 -0 0'/>
      <geometry>
        <box size='0.01 0.05 0.02'/>
      </geometry>
    </visual>
    <visual name='base_link_fixed_joint_lump__light1_visual_2'>
      <origin xyz='0.433 0.04 0.663' rpy='0 -0 1.5708'/>
      <geometry>
        <box size='0.01 0.05 0.02'/>
      </geometry>
    </visual>
    <visual name='base_link_fixed_joint_lump__light2_visual_3'>
      <origin xyz='0.393 0 0.663' rpy='0 0 -3.14159'/>
      <geometry>
        <box size='0.01 0.05 0.02'/>
      </geometry>
    </visual>
    <visual name='base_link_fixed_joint_lump__light3_visual_4'>
      <origin xyz='0.433 -0.04 0.663' rpy='0 0 -1.5708'/>
      <geometry>
        <box size='0.01 0.05 0.02'/>
      </geometry>
    </visual>
    <visual name='base_link_fixed_joint_lump__titan_chassis_visual_5'>
      <origin xyz='0 0 0' rpy='0 -0 0'/>
      <geometry>
        <mesh filename='package://csiro_data61_ozbot_atr_sensor_config_1/meshes/Titan_Visual.dae' scale='1 1 1'/>
      </geometry>
    </visual>
  </link>
  <link name='${robot_namespace}/encoder_rotating_link'>
    <inertial>
      <origin xyz='0.004659 0 0.061904' rpy='0 -0 0'/>
      <mass value='1.328'/>
      <inertia ixx='0.00515062' ixy='1.99615e-16' ixz='-0.000124068' iyy='0.00506893' iyz='-3.27008e-15' izz='0.00258497'/>
    </inertial>
    <collision name='encoder_rotating_link_collision'>
      <origin xyz='0 0 0' rpy='0 -0 0'/>
      <geometry>
        <mesh filename='package://csiro_data61_ozbot_atr_sensor_config_1/meshes/PPV4_Sim_Laser_Assembly.STL' scale='1 1 1'/>
      </geometry>
    </collision>
    <collision name='encoder_rotating_link_fixed_joint_lump__nav_velodyne_base_link_collision_1'>
      <origin xyz='0.00735 0 0.097852' rpy='-0.785398 0 -1.5708'/>
      <geometry>
        <cylinder radius='0.0516' length='0.0717'/>
      </geometry>
    </collision>
    <visual name='encoder_rotating_link_visual'>
      <origin xyz='0 0 0' rpy='0 -0 0'/>
      <geometry>
        <mesh filename='package://csiro_data61_ozbot_atr_sensor_config_1/meshes/PPV4_Sim_Laser_Assembly.STL' scale='1 1 1'/>
      </geometry>
    </visual>
    <visual name='encoder_rotating_link_fixed_joint_lump__nav_velodyne_base_link_visual_1'>
      <origin xyz='-0.018 0 0.072503' rpy='-0.785398 0 -1.5708'/>
      <geometry>
        <mesh filename='package://csiro_data61_ozbot_atr_sensor_config_1/meshes/VLP16_base_1.dae' scale='1 1 1'/>
      </geometry>
    </visual>
    <visual name='encoder_rotating_link_fixed_joint_lump__nav_velodyne_base_link_visual_2'>
      <origin xyz='-0.018 0 0.072503' rpy='-0.785398 0 -1.5708'/>
      <geometry>
        <mesh filename='package://csiro_data61_ozbot_atr_sensor_config_1/meshes/VLP16_base_2.dae' scale='1 1 1'/>
      </geometry>
    </visual>
    <visual name='encoder_rotating_link_fixed_joint_lump__nav_velodyne_visual_3'>
      <origin xyz='-0.018 0 0.072503' rpy='-0.785398 0 -1.5708'/>
      <geometry>
        <mesh filename='package://csiro_data61_ozbot_atr_sensor_config_1/meshes/VLP16_scan.dae' scale='1 1 1'/>
      </geometry>
    </visual>
  </link>
  <sensor name='gpu_lidar' update_rate='20'>
    <parent link='${robot_namespace}/encoder_rotating_link'/>
    <origin xyz='0.008658 0 0.099161' rpy='-0.785398 0 -1.5708'/>
  </sensor>
  <link name='${robot_namespace}/nav_imu'>
    <inertial>
      <origin xyz='0.004061 0.003452 0.012413' rpy='0 -0 0'/>
      <mass value='0.3'/>
      <inertia ixx='0.000467046' ixy='-2.10243e-06' ixz='-7.56055e-06' iyy='0.000467732' iyz='-6.42715e-06' izz='0.000874443'/>
    </inertial>
    <collision name='nav_imu_collision'>
      <origin xyz='0 0 0' rpy='0 -0 0'/>
      <geometry>
        <box size='0.01 0.01 0.01'/>
      </geometry>
    </collision>
    <collision name='nav_imu_fixed_joint_lump__camera_front_link_collision_1'>
      <origin xyz='0.071718 0.005178 0.01862' rpy='0 -0.261799 0'/>
      <geometry>
        <box size='0.001 0.02 0.02'/>
      </geometry>
    </collision>
    <collision name='nav_imu_fixed_joint_lump__camera_left_link_collision_2'>
      <origin xyz='0.006091 0.070805 0.01862' rpy='0 -0.261799 1.5708'/>
      <geometry>
        <box size='0.001 0.02 0.02'/>
      </geometry>
    </collision>
    <collision name='nav_imu_fixed_joint_lump__camera_rear_link_collision_3'>
      <origin xyz='-0.059537 0.005178 0.01862' rpy='0 -0.261799 -3.14159'/>
      <geometry>
        <box size='0.001 0.02 0.02'/>
      </geometry>
    </collision>
    <collision name='nav_imu_fixed_joint_lump__camera_right_link_collision_4'>
      <origin xyz='0.006091 -0.06045 0.01862' rpy='0 -0.261799 -1.5708'/>
      <geometry>
        <box size='0.001 0.02 0.02'/>
      </geometry>
    </collision>
    <visual name='nav_imu_visual'>
      <origin xyz='0 0 0' rpy='0 -0 0'/>
      <geometry>
        <box size='0.01 0.01 0.01'/>
      </geometry>
    </visual>
    <visual name='nav_imu_fixed_joint_lump__camera_front_link_visual_1'>
      <origin xyz='0.071718 0.005178 0.01862' rpy='0 -0.261799 0'/>
      <geometry>
        <box size='0.001 0.02 0.02'/>
      </geometry>
    </visual>
    <visual name='nav_imu_fixed_joint_lump__camera_left_link_visual_2'>
      <origin xyz='0.006091 0.070805 0.01862' rpy='0 -0.261799 1.5708'/>
      <geometry>
        <box size='0.001 0.02 0.02'/>
      </geometry>
    </visual>
    <visual name='nav_imu_fixed_joint_lump__camera_rear_link_visual_3'>
      <origin xyz='-0.059537 0.005178 0.01862' rpy='0 -0.261799 -3.14159'/>
      <geometry>
        <box size='0.001 0.02 0.02'/>
      </geometry>
    </visual>
    <visual name='nav_imu_fixed_joint_lump__camera_right_link_visual_4'>
      <origin xyz='0.006091 -0.06045 0.01862' rpy='0 -0.261799 -1.5708'/>
      <geometry>
        <box size='0.001 0.02 0.02'/>
      </geometry>
    </visual>
  </link>
  <sensor name='camera_front' update_rate='1'>
    <parent link='${robot_namespace}/nav_imu'/>
    <origin xyz='0.071718 0.005178 0.01862' rpy='0 -0.261799 0'/>
    <camera>
      <image width='2016' height='1512' format='R8G8B8' hfov='1.5708' near='0.02' far='300' />
    </camera>
  </sensor>
  <sensor name='camera_left' update_rate='1'>
    <parent link='${robot_namespace}/nav_imu'/>
    <origin xyz='0.006091 0.070805 0.01862' rpy='0 -0.261799 1.5708'/>
    <camera>
      <image width='2016' height='1512' format='R8G8B8' hfov='1.5708' near='0.02' far='300' />
    </camera>
  </sensor>
  <sensor name='camera_rear' update_rate='1'>
    <parent link='${robot_namespace}/nav_imu'/>
    <origin xyz='-0.059537 0.005178 0.01862' rpy='0 -0.261799 -3.14159'/>
    <camera>
      <image width='2016' height='1512' format='R8G8B8' hfov='1.5708' near='0.02' far='300' />
    </camera>
  </sensor>
  <sensor name='camera_right' update_rate='1'>
    <parent link='${robot_namespace}/nav_imu'/>
    <origin xyz='0.006091 -0.06045 0.01862' rpy='0 -0.261799 -1.5708'/>
    <camera>
      <image width='2016' height='1512' format='R8G8B8' hfov='1.5708' near='0.02' far='300' />
    </camera>
  </sensor>
  <sensor name='imu' update_rate='100'>
    <parent link='${robot_namespace}/nav_imu'/>
    <origin xyz='0 0 0' rpy='0 -0 0'/>
  </sensor>
  <link name='${robot_namespace}/left_track'>
    <inertial>
      <origin xyz='0 0 0' rpy='0 -0 0'/>
      <mass value='2'/>
      <inertia ixx='0.1467' ixy='0' ixz='0' iyy='2.0754' iyz='0' izz='2.0754'/>
    </inertial>
    <collision name='left_11_wheel_collision'>
      <origin xyz='-0.64 0 0.183' rpy='1.5708 -0 0'/>
      <geometry>
        <cylinder radius='0.14' length='0.2'/>
      </geometry>
    </collision>
    <visual name='left_11_wheel_visual'>
      <origin xyz='-0.64 0 0.183' rpy='1.5708 -0 0'/>
      <geometry>
        <cylinder radius='0.14' length='0.2'/>
      </geometry>
    </visual>
    <collision name='left_1_wheel_collision'>
      <origin xyz='0.693 0 0.21' rpy='1.5708 -0 0'/>
      <geometry>
        <cylinder radius='0.11' length='0.2'/>
      </geometry>
    </collision>
    <visual name='left_1_wheel_visual'>
      <origin xyz='0.693 0 0.21' rpy='1.5708 -0 0'/>
      <geometry>
        <cylinder radius='0.11' length='0.2'/>
      </geometry>
    </visual>
    <collision name='left_3_wheel_collision'>
      <origin xyz='0.485 0 -0.037758' rpy='1.5708 -0 0'/>
      <geometry>
        <cylinder radius='0.14' length='0.2'/>
      </geometry>
    </collision>
    <visual name='left_3_wheel_visual'>
      <origin xyz='0.485 0 -0.037758' rpy='1.5708 -0 0'/>
      <geometry>
        <cylinder radius='0.14' length='0.2'/>
      </geometry>
    </visual>
    <collision name='left_9_wheel_collision'>
      <origin xyz='-0.56 0 -0.07' rpy='1.5708 -0 0'/>
      <geometry>
        <cylinder radius='0.11' length='0.2'/>
      </geometry>
    </collision>
    <visual name='left_9_wheel_visual'>
      <origin xyz='-0.56 0 -0.07' rpy='1.5708 -0 0'/>
      <geometry>
        <cylinder radius='0.11' length='0.2'/>
      </geometry>
    </visual>
    <collision name='left_bottom_box_collision'>
      <origin xyz='-0.0375 0 -0.068' rpy='0 0 0'/>
      <geometry>
        <box size='1.045 0.2 0.22' />
      </geometry>
    </collision>
    <visual name='left_bottom_box_visual'>
      <origin xyz='-0.0375 0 -0.068' rpy='0 0 0'/>
      <geometry>
        <box size='1.045 0.2 0.22' />
      </geometry>
    </visual>
    <collision name='left_rear_box_collision'>
      <origin xyz='-0.612 0 0.05114' rpy='0 1.15017 0'/>
      <geometry>
        <box size='0.285 0.2 0.22' />
      </geometry>
    </collision>
    <visual name='left_rear_box_visual'>
      <origin xyz='-0.612 0 0.05114' rpy='0 1.15017 0'/>
      <geometry>
        <box size='0.285 0.2 0.22' />
      </geometry>
    </visual>
    <collision name='left_front_box_collision'>
      <origin xyz='0.6 0 0.07898' rpy='0 -0.96517 0'/>
      <geometry>
        <box size='0.35 0.2 0.22' />
      </geometry>
    </collision>
    <visual name='left_front_box_visual'>
      <origin xyz='0.6 0 0.07898' rpy='0 -0.96517 0'/>
      <geometry>
        <box size='0.35 0.2 0.22' />
      </geometry>
    </visual>
  </link>
  <joint name='left_track_j' type='fixed'>
    <origin xyz='0 0.269 0' rpy='0 0 0'/>
    <parent link='${robot_namespace}/base_link'/>
    <child link='${robot_namespace}/left_track'/>
  </joint>

  <link name='${robot_namespace}/right_track'>
    <inertial>
      <origin xyz='0 0 0' rpy='0 -0 0'/>
      <mass value='2'/>
      <inertia ixx='0.1467' ixy='0' ixz='0' iyy='2.0754' iyz='0' izz='2.0754'/>
    </inertial>
    <collision name='right_11_wheel_collision'>
      <origin xyz='-0.64 0 0.183' rpy='1.5708 -0 0'/>
      <geometry>
        <cylinder radius='0.14' length='0.2'/>
      </geometry>
    </collision>
    <visual name='right_11_wheel_visual'>
      <origin xyz='-0.64 0 0.183' rpy='1.5708 -0 0'/>
      <geometry>
        <cylinder radius='0.14' length='0.2'/>
      </geometry>
    </visual>
    <collision name='right_1_wheel_collision'>
      <origin xyz='0.693 0 0.21' rpy='1.5708 -0 0'/>
      <geometry>
        <cylinder radius='0.11' length='0.2'/>
      </geometry>
    </collision>
    <visual name='right_1_wheel_visual'>
      <origin xyz='0.693 0 0.21' rpy='1.5708 -0 0'/>
      <geometry>
        <cylinder radius='0.11' length='0.2'/>
      </geometry>
    </visual>
    <collision name='right_3_wheel_collision'>
      <origin xyz='0.485 0 -0.037758' rpy='1.5708 -0 0'/>
      <geometry>
        <cylinder radius='0.14' length='0.2'/>
      </geometry>
    </collision>
    <visual name='right_3_wheel_visual'>
      <origin xyz='0.485 0 -0.037758' rpy='1.5708 -0 0'/>
      <geometry>
        <cylinder radius='0.14' length='0.2'/>
      </geometry>
    </visual>
    <collision name='right_9_wheel_collision'>
      <origin xyz='-0.56 0 -0.07' rpy='1.5708 -0 0'/>
      <geometry>
        <cylinder radius='0.11' length='0.2'/>
      </geometry>
    </collision>
    <visual name='right_9_wheel_visual'>
      <origin xyz='-0.56 0 -0.07' rpy='1.5708 -0 0'/>
      <geometry>
        <cylinder radius='0.11' length='0.2'/>
      </geometry>
    </visual>
    <collision name='right_bottom_box_collision'>
      <origin xyz='-0.0375 0 -0.068' rpy='0 0 0'/>
      <geometry>
        <box size='1.045 0.2 0.22' />
      </geometry>
    </collision>
    <visual name='right_bottom_box_visual'>
      <origin xyz='-0.0375 0 -0.068' rpy='0 0 0'/>
      <geometry>
        <box size='1.045 0.2 0.22' />
      </geometry>
    </visual>
    <collision name='right_rear_box_collision'>
      <origin xyz='-0.612 0 0.05114' rpy='0 1.15017 0'/>
      <geometry>
        <box size='0.285 0.2 0.22' />
      </geometry>
    </collision>
    <visual name='right_rear_box_visual'>
      <origin xyz='-0.612 0 0.05114' rpy='0 1.15017 0'/>
      <geometry>
        <box size='0.285 0.2 0.22' />
      </geometry>
    </visual>
    <collision name='right_front_box_collision'>
      <origin xyz='0.6 0 0.07898' rpy='0 -0.96517 0'/>
      <geometry>
        <box size='0.35 0.2 0.22' />
      </geometry>
    </collision>
    <visual name='right_front_box_visual'>
      <origin xyz='0.6 0 0.07898' rpy='0 -0.96517 0'/>
      <geometry>
        <box size='0.35 0.2 0.22' />
      </geometry>
    </visual>
  </link>
  <joint name='right_track_j' type='fixed'>
    <origin xyz='0 -0.269 0' rpy='0 0 0'/>
    <parent link='${robot_namespace}/base_link'/>
    <child link='${robot_namespace}/right_track'/>
  </joint>
  
  <joint name='lidar_gimbal' type='revolute'>
    <origin xyz='0.433 0 0.453797' rpy='0 -0 0'/>
    <parent link='${robot_namespace}/base_link'/>
    <child link='${robot_namespace}/encoder_rotating_link'/>
    <dynamics damping='0' friction='0' />
    <axis xyz='0 0 1'/>
    <limit lower='-1e+16' upper='1e+16' effort='-1' velocity='3.14159'/>
  </joint>
  <joint name='nav_base_link_to_imu' type='revolute'>
    <origin xyz='0.426909 -0.005178 0.423' rpy='0 -0 0'/>
    <parent link='${robot_namespace}/base_link'/>
    <child link='${robot_namespace}/nav_imu'/>
    <dynamics damping='0' friction='0' />
    <axis xyz='1 0 0'/>
    <limit lower='0' upper='0' effort='0' velocity='0'/>
  </joint>
</robot>
