<?xml version='1.0'?>
<sdf version='1.6'>
  <model name="ROBOTIKA_KLOUBAK">
    <static>false</static>
    <enable_wind>1</enable_wind>
    
    <link name='chassis_front'>
        <pose>0 0 0.2 0 0 0</pose>
        <inertial>
            <pose>-0.05 0 0.08 0 0 0</pose>
            <mass>8</mass>
            <inertia>
                <ixx>0.1119</ixx>
                <iyy>0.1286</iyy>
                <izz>0.2159</izz>
            </inertia>
        </inertial>
        
        <!-- Box and axle -->
        <collision name='collision_front_box'>
            <pose>0 0 0.08 0 0 0</pose>
            <geometry>
            <box>
                <size>0.3 0.4 0.16</size>
            </box>
            </geometry>
        </collision>
        
        <collision name='collision_bar'>
            <pose>-0.17 0 0.02 0 0 0</pose>
            <geometry>
            <box>
                <size>0.3 0.04 0.04</size>
            </box>
            </geometry>
        </collision>
        
        <collision name='collision_joint_upper'>
            <pose>-0.335 0 0.05 0 0 0</pose>
            <geometry>
            <box>
                <size>0.07 0.06 0.02</size>
            </box>
            </geometry>
        </collision>
        
        <collision name='collision_joint_bottom'>
            <pose>-0.335 0 -0.01 0 0 0</pose>
            <geometry>
            <box>
                <size>0.07 0.06 0.02</size>
            </box>
            </geometry>
        </collision>
        
        <collision name='collision_wheel_hinge_left'>
            <pose>0 0.18 -0.02 0 0 0</pose>
            <geometry>
            <box>
                <size>0.04 0.06 0.04</size>
            </box>
            </geometry>
        </collision>
        
        <collision name='collision_wheel_hinge_right'>
            <pose>0 -0.18 -0.02 0 0 0</pose>
            <geometry>
            <box>
                <size>0.04 0.06 0.04</size>
            </box>
            </geometry>
        </collision>

        <visual name='visual_chassis'>
          <pose>-0.340 0 -0.17 0 0 0</pose>
          <geometry>
            <mesh>
              <uri>meshes/k2.dae</uri>
              <submesh>
                <name>BodyBack</name>
                <center>false</center>
              </submesh>
            </mesh>
          </geometry>
          <material>
            <diffuse>1.0 1.0 1.0</diffuse>
            <specular>1.0 1.0 1.0</specular>
            <pbr>
              <metal>
                <albedo_map>materials/textures/K2_Albedo.png</albedo_map>
                <metal_map>materials/textures/K2_Metalness.png</metal_map>
                <roughness_map>materials/textures/K2_Roughness.png</roughness_map>
              </metal>
            </pbr>
            <script>
              <uri>materials/scripts/</uri>
              <uri>materials/textures/</uri>
              <name>UrbanTile/K2_Diffuse</name>
            </script>
          </material>
        </visual>

        
        <!-- LORD IMU and magnetometer -->
        
        <sensor name="imu_sensor_front" type="imu">
            <always_on>1</always_on>
            <update_rate>50</update_rate>
            <imu>
                    <angular_velocity>
                        <x>
                            <noise type="gaussian">
                                <mean>0</mean>
                                <stddev>0.009</stddev>
                                <bias_mean>0.00075</bias_mean>
                                <bias_stddev>0.005</bias_stddev>
                                <dynamic_bias_stddev>0.00002</dynamic_bias_stddev>
                                <dynamic_bias_correlation_time>400.0</dynamic_bias_correlation_time>
                                <precision>0.00025</precision>
                            </noise>
                        </x>
                        <y>
                            <noise type="gaussian">
                                <mean>0</mean>
                                <stddev>0.009</stddev>
                                <bias_mean>0.00075</bias_mean>
                                <bias_stddev>0.005</bias_stddev>
                                <dynamic_bias_stddev>0.00002</dynamic_bias_stddev>
                                <dynamic_bias_correlation_time>400.0</dynamic_bias_correlation_time>
                                <precision>0.00025</precision>
                            </noise>
                        </y>
                        <z>
                            <noise type="gaussian">
                                <mean>0</mean>
                                <stddev>0.009</stddev>
                                <bias_mean>0.00075</bias_mean>
                                <bias_stddev>0.005</bias_stddev>
                                <dynamic_bias_stddev>0.00002</dynamic_bias_stddev>
                                <dynamic_bias_correlation_time>400.0</dynamic_bias_correlation_time>
                                <precision>0.00025</precision>
                            </noise>
                        </z>
                    </angular_velocity>
                    <linear_acceleration>
                        <x>
                            <noise type="gaussian">
                                <mean>0</mean>
                                <stddev>0.021</stddev>
                                <bias_mean>0.05</bias_mean>
                                <bias_stddev>0.0075</bias_stddev>
                                <dynamic_bias_stddev>0.000375</dynamic_bias_stddev>
                                <dynamic_bias_correlation_time>175.0</dynamic_bias_correlation_time>
                                <precision>0.005</precision>
                            </noise>
                        </x>
                        <y>
                            <noise type="gaussian">
                                <mean>0</mean>
                                <stddev>0.021</stddev>
                                <bias_mean>0.05</bias_mean>
                                <bias_stddev>0.0075</bias_stddev>
                                <dynamic_bias_stddev>0.000375</dynamic_bias_stddev>
                                <dynamic_bias_correlation_time>175.0</dynamic_bias_correlation_time>
                                <precision>0.005</precision>
                            </noise>
                        </y>
                        <z>
                            <noise type="gaussian">
                                <mean>0</mean>
                                <stddev>0.021</stddev>
                                <bias_mean>0.05</bias_mean>
                                <bias_stddev>0.0075</bias_stddev>
                                <dynamic_bias_stddev>0.000375</dynamic_bias_stddev>
                                <dynamic_bias_correlation_time>175.0</dynamic_bias_correlation_time>
                                <precision>0.005</precision>
                            </noise>
                        </z>
                    </linear_acceleration>
                </imu>
        </sensor>
        <sensor name="magnetometer_front" type="magnetometer">
            <always_on>1</always_on>
            <update_rate>50</update_rate>
            <magnetometer>
                <x>
                    <noise type="gaussian">
                        <mean>0.000000080</mean>
                        <bias_mean>0.000000400</bias_mean>
                    </noise>
                </x>
                <y>
                    <noise type="gaussian">
                        <mean>0.000000080</mean>
                        <bias_mean>0.000000400</bias_mean>
                    </noise>
                </y>
                <z>
                    <noise type="gaussian">
                        <mean>0.000000080</mean>
                        <bias_mean>0.000000400</bias_mean>
                    </noise>
                </z>
            </magnetometer>
        </sensor>

        <!-- Infineon DPS310
            https://www.infineon.com/cms/en/product/sensor/pressure-sensors/absolute-pressure-sensors-map-bap/dps310/
        -->
        <sensor name="air_pressure" type="air_pressure">
            <always_on>1</always_on>
            <update_rate>20</update_rate>
            <air_pressure>
                <reference_altitude>0</reference_altitude>
                <noise type="gaussian">
                    <mean>0.00000008</mean>
                </noise>
            </air_pressure>
        </sensor>
        
        <!--LED light -->
        <collision name='collision_light_lidar_camera'>
            <pose>0.05 0 0.2325 0 0 0</pose>
            <geometry>
            <box>
                <size>0.2 0.15 0.145</size>
            </box>
            </geometry>
        </collision>
        <light name="light_front" type="spot">
            <pose>0.16 0 0.29 0 -1.5707963267948966 0</pose>
            <attenuation>
                <range>25</range>
                <linear>0</linear>
                <constant>0.1</constant>
                <quadratic>0.005</quadratic>
            </attenuation>
            <diffuse>0.8 0.8 0.5 1.0</diffuse>
            <specular>0.8 0.8 0.5 1</specular>
            <spot>
                <inner_angle>1.571</inner_angle>
                <outer_angle>2.1</outer_angle>
                <falloff>1</falloff>
            </spot>
            <direction>1 0 0</direction>
            <cast_shadows>1</cast_shadows>
        </light>
        
        <!--SICK TIM881P lidar, a prototype without a good public URL. It is derived from
            the TIM58x family:
            https://www.sick.com/ch/en/detection-and-ranging-solutions/2d-lidar-sensors/tim5xx/tim581-2050101/p/p619344
        -->
        <sensor name="lidar_front" type="gpu_lidar">
            <pose>0.04 0 0.235 0 0 0</pose>
            <update_rate>15</update_rate>
            <lidar>
                <scan>
                    <horizontal>
                        <samples>811</samples>
                        <resolution>1</resolution>
                        <min_angle>-2.3562</min_angle>
                        <max_angle>2.3562</max_angle>
                    </horizontal>
                </scan>
                <range>
                    <min>0.04</min>
                    <max>25</max>
                    <resolution>0.01</resolution>
                </range>
                <noise>
                    <type>gaussian</type>
                    <mean>0</mean>
                    <stddev>0.01</stddev>
                </noise>
            </lidar>
        </sensor>
        
        <!--Camera Arecont AV3216DN and lens MPL1.55
            https://sales.arecontvision.com/product/MegaVideo%20G5%20Series/AV3216DN
            https://sales.arecontvision.com/product/Lenses/MPL1.55
        -->
        <sensor name="camera_front" type="camera">
            <pose>0.155 -0.0075 0.193 0 0 0</pose>
            <always_on>1</always_on>
            <update_rate>10</update_rate>
            <camera name="camera_front">
                <horizontal_fov>3.072</horizontal_fov>
                <lens>
                    <intrinsics>
                        <!-- fx = fy = width / ( 2 * tan (hfov / 2 ) ) -->
                        <fx>17.8229</fx>
                        <fy>17.8229</fy>
                        <!-- cx = ( width - 1 ) / 2 -->
                        <cx>511.5</cx>
                        <!-- cy = ( height - 1 ) / 2 -->
                        <cy>383.5</cy>
                        <s>0</s>
                    </intrinsics>
                </lens>
                <distortion>
                    <k1>0.0</k1>
                    <k2>0.0</k2>
                    <k3>0.0</k3>
                    <p1>0.0</p1>
                    <p2>0.0</p2>
                    <center>0.5 0.5</center>
                </distortion>
                <image>
                    <width>1024</width>
                    <height>768</height>
                    <format>R8G8B8</format>
                </image>
                <clip>
                    <near>0.01</near>
                    <far>300</far>
                </clip>
                <noise>
                    <type>gaussian</type>
                    <mean>0</mean>
                    <stddev>0.007</stddev>
                </noise>
            </camera>
        </sensor>
        
        <!-- RealSense depth camera D435i
            https://www.intelrealsense.com/depth-camera-d435i/
        -->
        <collision name='collision_depth_camera_front'>
            <pose>0.165 0 0.11 0 0 0</pose>
            <geometry>
            <box>
                <size>0.03 0.2 0.06</size>
            </box>
            </geometry>
        </collision>
       
        <sensor name="depth_camera_front" type="rgbd_camera">
            <pose>0.18 0 0.113 0 0 0</pose>
            <always_on>1</always_on>
            <update_rate>20</update_rate>
            <camera name="depth_camera_front">
                <pose frame="">0 0 0 0 -1.5707 1.5707</pose>
                <horizontal_fov>1.5184</horizontal_fov>
                <lens>
                    <intrinsics>
                      <!-- fx = fy = width / ( 2 * tan (hfov / 2 ) ) -->
                      <fx>337.22</fx>
                      <fy>337.22</fy>
                      <!-- cx = ( width - 1 ) / 2 -->
                      <cx>319.5</cx>
                      <!-- cy = ( height - 1 ) / 2 -->
                      <cy>179.5</cy>
                      <s>0</s>
                    </intrinsics>
                </lens>
                <distortion>
                    <k1>0.0</k1>
                    <k2>0.0</k2>
                    <k3>0.0</k3>
                    <p1>0.0</p1>
                    <p2>0.0</p2>
                    <center>0.5 0.5</center>
                </distortion>
                <image>
                    <width>640</width>
                    <height>360</height>
                    <format>R8G8B8</format>
                </image>
                <clip>
                    <near>0.01</near>
                    <far>300</far>
                </clip>
                <depth_camera>
                  <clip>
                    <near>0.1</near>
                    <far>10</far>
                  </clip>
                </depth_camera>
                <noise>
                    <type>gaussian</type>
                    <mean>0</mean>
                    <stddev>0.007</stddev>
                </noise>
            </camera>
        </sensor>
        
    </link>
    
    
    <link name='chassis_back'>
        <pose>-0.7 0 0.2 0 0 0</pose>
        <inertial>
            <pose>0.025 0 0.116 0 0 0</pose>
            <mass>7.2</mass>
            <inertia>
                <ixx>0.0468</ixx>
                <iyy>0.1117</iyy>
                <izz>0.1228</izz>
            </inertia>
        </inertial>
        
        <collision name='collision_back_box'>
            <pose>0 0 0.13 0 0 0</pose>
            <geometry>
            <box>
                <size>0.34 0.24 0.18</size>
            </box>
            </geometry>
        </collision>
        
        <collision name='collision_bar'>
            <pose>0.125 0 0.02 0 0 0</pose>
            <geometry>
            <box>
                <size>0.45 0.04 0.04</size>
            </box>
            </geometry>
        </collision>

        <visual name='visual_chassis'>
          <pose>0.34 0 -0.17 0 0 0</pose>
          <geometry>
            <mesh>
              <uri>meshes/k2.dae</uri>
              <submesh>
                <name>BodyFront</name>
                <center>false</center>
              </submesh>
            </mesh>
          </geometry>
          <material>
            <diffuse>1.0 1.0 1.0</diffuse>
            <specular>1.0 1.0 1.0</specular>
            <pbr>
              <metal>
                <albedo_map>materials/textures/K2_Albedo.png</albedo_map>
                <metal_map>materials/textures/K2_Metalness.png</metal_map>
                <roughness_map>materials/textures/K2_Roughness.png</roughness_map>
              </metal>
            </pbr>
            <script>
              <uri>materials/scripts/</uri>
              <uri>materials/textures/</uri>
              <name>UrbanTile/K2_Diffuse</name>
            </script>
          </material>
        </visual>

        <!-- LORD IMU and magnetometer -->
        
        <sensor name="imu_sensor_back" type="imu">
            <always_on>1</always_on>
            <update_rate>50</update_rate>
            <imu>
                    <angular_velocity>
                        <x>
                            <noise type="gaussian">
                                <mean>0</mean>
                                <stddev>0.009</stddev>
                                <bias_mean>0.00075</bias_mean>
                                <bias_stddev>0.005</bias_stddev>
                                <dynamic_bias_stddev>0.00002</dynamic_bias_stddev>
                                <dynamic_bias_correlation_time>400.0</dynamic_bias_correlation_time>
                                <precision>0.00025</precision>
                            </noise>
                        </x>
                        <y>
                            <noise type="gaussian">
                                <mean>0</mean>
                                <stddev>0.009</stddev>
                                <bias_mean>0.00075</bias_mean>
                                <bias_stddev>0.005</bias_stddev>
                                <dynamic_bias_stddev>0.00002</dynamic_bias_stddev>
                                <dynamic_bias_correlation_time>400.0</dynamic_bias_correlation_time>
                                <precision>0.00025</precision>
                            </noise>
                        </y>
                        <z>
                            <noise type="gaussian">
                                <mean>0</mean>
                                <stddev>0.009</stddev>
                                <bias_mean>0.00075</bias_mean>
                                <bias_stddev>0.005</bias_stddev>
                                <dynamic_bias_stddev>0.00002</dynamic_bias_stddev>
                                <dynamic_bias_correlation_time>400.0</dynamic_bias_correlation_time>
                                <precision>0.00025</precision>
                            </noise>
                        </z>
                    </angular_velocity>
                    <linear_acceleration>
                        <x>
                            <noise type="gaussian">
                                <mean>0</mean>
                                <stddev>0.021</stddev>
                                <bias_mean>0.05</bias_mean>
                                <bias_stddev>0.0075</bias_stddev>
                                <dynamic_bias_stddev>0.000375</dynamic_bias_stddev>
                                <dynamic_bias_correlation_time>175.0</dynamic_bias_correlation_time>
                                <precision>0.005</precision>
                            </noise>
                        </x>
                        <y>
                            <noise type="gaussian">
                                <mean>0</mean>
                                <stddev>0.021</stddev>
                                <bias_mean>0.05</bias_mean>
                                <bias_stddev>0.0075</bias_stddev>
                                <dynamic_bias_stddev>0.000375</dynamic_bias_stddev>
                                <dynamic_bias_correlation_time>175.0</dynamic_bias_correlation_time>
                                <precision>0.005</precision>
                            </noise>
                        </y>
                        <z>
                            <noise type="gaussian">
                                <mean>0</mean>
                                <stddev>0.021</stddev>
                                <bias_mean>0.05</bias_mean>
                                <bias_stddev>0.0075</bias_stddev>
                                <dynamic_bias_stddev>0.000375</dynamic_bias_stddev>
                                <dynamic_bias_correlation_time>175.0</dynamic_bias_correlation_time>
                                <precision>0.005</precision>
                            </noise>
                        </z>
                    </linear_acceleration>
                </imu>
        </sensor>
        <sensor name="magnetometer_back" type="magnetometer">
            <always_on>1</always_on>
            <update_rate>50</update_rate>
            <magnetometer>
                <x>
                    <noise type="gaussian">
                        <mean>0.000000080</mean>
                        <bias_mean>0.000000400</bias_mean>
                    </noise>
                </x>
                <y>
                    <noise type="gaussian">
                        <mean>0.000000080</mean>
                        <bias_mean>0.000000400</bias_mean>
                    </noise>
                </y>
                <z>
                    <noise type="gaussian">
                        <mean>0.000000080</mean>
                        <bias_mean>0.000000400</bias_mean>
                    </noise>
                </z>
            </magnetometer>
        </sensor>
        
        <!--LED light -->
        <collision name='collision_light_lidar_camera'>
            <pose>-0.07 0 0.2925 0 0 0</pose>
            <geometry>
            <box>
                <size>0.2 0.15 0.145</size>
            </box>
            </geometry>
        </collision>
       <light name="light_back" type="spot">
            <pose>-0.17 0 0.35 0 1.5707963267948966 0</pose>
            <attenuation>
                <range>25</range>
                <linear>0</linear>
                <constant>0.1</constant>
                <quadratic>0.005</quadratic>
            </attenuation>
            <diffuse>0.8 0.8 0.5 1.0</diffuse>
            <specular>0.8 0.8 0.5 1</specular>
            <spot>
                <inner_angle>1.571</inner_angle>
                <outer_angle>2.1</outer_angle>
                <falloff>1</falloff>
            </spot>
            <direction>1 0 0</direction>
            <cast_shadows>1</cast_shadows>
        </light>
        
        <!--SICK TIM881P lidar, a prototype without a good public URL. It is derived from
            the TIM58x family:
            https://www.sick.com/ch/en/detection-and-ranging-solutions/2d-lidar-sensors/tim5xx/tim581-2050101/p/p619344
        -->
        <sensor name="lidar_back" type="gpu_lidar">
            <pose>-0.06 0 0.295 0 0 3.1415927</pose>
            <update_rate>15</update_rate>
            <lidar>
                <scan>
                    <horizontal>
                        <samples>811</samples>
                        <resolution>1</resolution>
                        <min_angle>-2.3562</min_angle>
                        <max_angle>2.3562</max_angle>
                    </horizontal>
                </scan>
                <range>
                    <min>0.04</min>
                    <max>25</max>
                    <resolution>0.01</resolution>
                </range>
                <noise>
                    <type>gaussian</type>
                    <mean>0</mean>
                    <stddev>0.01</stddev>
                </noise>
            </lidar>
        </sensor>
        
        <!--Camera Arecont AV3216DN and lens MPL1.55
            https://sales.arecontvision.com/product/MegaVideo%20G5%20Series/AV3216DN
            https://sales.arecontvision.com/product/Lenses/MPL1.55
        -->
        <sensor name="camera_back" type="camera">
            <pose>-0.185 -0.001 0.269 0 0 3.1415927</pose>
            <always_on>1</always_on>
            <update_rate>10</update_rate>
            <camera name="camera_back">
                <horizontal_fov>3.072</horizontal_fov>
                <lens>
                    <intrinsics>
                        <!-- fx = fy = width / ( 2 * tan (hfov / 2 ) ) -->
                        <fx>17.8229</fx>
                        <fy>17.8229</fy>
                        <!-- cx = ( width - 1 ) / 2 -->
                        <cx>511.5</cx>
                        <!-- cy = ( height - 1 ) / 2 -->
                        <cy>383.5</cy>
                        <s>0</s>
                    </intrinsics>
                </lens>
                <distortion>
                    <k1>0.0</k1>
                    <k2>0.0</k2>
                    <k3>0.0</k3>
                    <p1>0.0</p1>
                    <p2>0.0</p2>
                    <center>0.5 0.5</center>
                </distortion>
                <image>
                    <width>1024</width>
                    <height>768</height>
                    <format>R8G8B8</format>
                </image>
                <clip>
                    <near>0.01</near>
                    <far>300</far>
                </clip>
                <noise>
                    <type>gaussian</type>
                    <mean>0</mean>
                    <stddev>0.007</stddev>
                </noise>
            </camera>
        </sensor>
        
        <!-- RealSense depth camera D435i
            https://www.intelrealsense.com/depth-camera-d435i/
        -->
        <collision name='collision_depth_camera_back'>
            <pose>-0.185 0 0.11 0 0 0</pose>
            <geometry>
            <box>
                <size>0.03 0.2 0.06</size>
            </box>
            </geometry>
        </collision>
       
        <sensor name="depth_camera_back" type="rgbd_camera">
            <pose>-0.2 0 0.113 0 0 3.1415927</pose>
            <always_on>1</always_on>
            <update_rate>20</update_rate>
            <camera name="depth_camera_back">
                <pose frame="">0 0 0 0 -1.5707 1.5707</pose>
                <horizontal_fov>1.5184</horizontal_fov>
                <lens>
                    <intrinsics>
                      <!-- fx = fy = width / ( 2 * tan (hfov / 2 ) ) -->
                      <fx>337.22</fx>
                      <fy>337.22</fy>
                      <!-- cx = ( width - 1 ) / 2 -->
                      <cx>319.5</cx>
                      <!-- cy = ( height - 1 ) / 2 -->
                      <cy>179.5</cy>
                      <s>0</s>
                    </intrinsics>
                </lens>
                <distortion>
                    <k1>0.0</k1>
                    <k2>0.0</k2>
                    <k3>0.0</k3>
                    <p1>0.0</p1>
                    <p2>0.0</p2>
                    <center>0.5 0.5</center>
                </distortion>
                <image>
                    <width>640</width>
                    <height>360</height>
                    <format>R8G8B8</format>
                </image>
                <clip>
                    <near>0.01</near>
                    <far>300</far>
                </clip>
                <depth_camera>
                  <clip>
                    <near>0.1</near>
                    <far>10</far>
                  </clip>
                </depth_camera>
                <noise>
                    <type>gaussian</type>
                    <mean>0</mean>
                    <stddev>0.007</stddev>
                </noise>
            </camera>
        </sensor>
        
    </link>
    
    
    <link name='axle_back'>
        <pose>-0.729 0 0.183 0 0 0</pose>
        <inertial>
            <pose>0 0 0 0 0 0</pose>
            <mass>0.8</mass>
            <inertia>
                <ixx>0.0119</ixx>
                <iyy>0.00021</iyy>
                <izz>0.0119</izz>
            </inertia>
        </inertial>
        
        <collision name='collision'>
            <geometry>
            <box>
                <size>0.04 0.42 0.04</size>
            </box>
          </geometry>
        </collision>
        <visual name="visual">
          <pose>-0.0132 0 0 0 0 0</pose>
          <geometry>
            <mesh>
              <uri>meshes/k2.dae</uri>
              <submesh>
                <name>Axle</name>
                <center>true</center>
              </submesh>
            </mesh>
          </geometry>
        </visual>
    </link>
    
    <link name="front_left_wheel">
      <pose>0 0.25 0.172 0 0 0</pose>
      <inertial>
        <mass>3.5</mass>
        <inertia>
          <ixx>0.0145</ixx>
          <iyy>0.0252</iyy>
          <izz>0.0145</izz>
        </inertia>
      </inertial>
      <collision name="collision">
        <pose>0 0 0 -1.5707963267948966 0 0</pose>
        <geometry>
          <cylinder>
            <length>0.08</length>
            <radius>0.147</radius>
          </cylinder>
        </geometry>
        <surface>
          <friction>
            <ode>
              <mu>0.5</mu>
              <mu2>1</mu2>
              <slip1>0.0016</slip1>
              <slip2>0</slip2>
              <fdir1>0 0 1</fdir1>
            </ode>
          </friction>
        </surface>
      </collision>
      <visual name="tire_visual">
        <geometry>
          <mesh>
            <uri>meshes/k2.dae</uri>
            <submesh>
              <name>WheelBL</name>
              <center>true</center>
            </submesh>
          </mesh>
        </geometry>
      </visual>
    </link>

        <link name="front_right_wheel">
            <pose>0 -0.25 0.172 0 0 0</pose>
            <inertial>
                <mass>3.5</mass>
                <inertia>
                    <ixx>0.0145</ixx>
                    <iyy>0.0252</iyy>
                    <izz>0.0145</izz>
                </inertia>
            </inertial>
            <collision name="collision">
                <pose>0 0 0 1.5707963267948966 0 0</pose>
                <geometry>
                    <cylinder>
                        <length>0.08</length>
                        <radius>0.147</radius>
                    </cylinder>
                </geometry>
                <surface>
                  <friction>
                    <ode>
                      <mu>0.5</mu>
                      <mu2>1</mu2>
                      <slip1>0.0016</slip1>
                      <slip2>0</slip2>
                      <fdir1>0 0 1</fdir1>
                    </ode>
                  </friction>
                </surface>
            </collision>
            <visual name="tire_visual">
                <geometry>
                    <mesh>
                      <uri>meshes/k2.dae</uri>
                      <submesh>
                        <name>WheelBR</name>
                        <center>true</center>
                      </submesh>
                    </mesh>
                </geometry>
            </visual>
        </link>
        
        
        <link name="rear_left_wheel">
            <pose>-0.729 0.25 0.172 0 0 0</pose>
            <inertial>
                <mass>3.5</mass>
                <inertia>
                    <ixx>0.0145</ixx>
                    <iyy>0.0252</iyy>
                    <izz>0.0145</izz>
                </inertia>
            </inertial>
            <collision name="collision">
                <pose>0 0 0 -1.5707963267948966 0 0</pose>
                <geometry>
                    <cylinder>
                        <length>0.08</length>
                        <radius>0.147</radius>
                    </cylinder>
                </geometry>
                <surface>
                  <friction>
                    <ode>
                      <mu>0.5</mu>
                      <mu2>1</mu2>
                      <slip1>0.0016</slip1>
                      <slip2>0</slip2>
                      <fdir1>0 0 1</fdir1>
                    </ode>
                  </friction>
                </surface>
            </collision>
            <visual name="tire_visual">
                <geometry>
                    <mesh>
                      <uri>meshes/k2.dae</uri>
                      <submesh>
                        <name>WheelFR</name>
                        <center>true</center>
                      </submesh>
                    </mesh>
                </geometry>
            </visual>
        </link>

        <link name="rear_right_wheel">
            <pose>-0.729 -0.25 0.172 0 0 0</pose>
            <inertial>
                <mass>3.5</mass>
                <inertia>
                    <ixx>0.0145</ixx>
                    <iyy>0.0252</iyy>
                    <izz>0.0145</izz>
                </inertia>
            </inertial>
            <collision name="collision">
                <pose>0 0 0 1.5707963267948966 0 0</pose>
                <geometry>
                    <cylinder>
                        <length>0.08</length>
                        <radius>0.147</radius>
                    </cylinder>
                </geometry>
                <surface>
                  <friction>
                    <ode>
                      <mu>0.5</mu>
                      <mu2>1</mu2>
                      <slip1>0.0016</slip1>
                      <slip2>0</slip2>
                      <fdir1>0 0 1</fdir1>
                    </ode>
                  </friction>
                </surface>
            </collision>
            <visual name="tire_visual">
                <geometry>
                    <mesh>
                      <uri>meshes/k2.dae</uri>
                      <submesh>
                        <name>WheelFL</name>
                        <center>true</center>
                      </submesh>
                    </mesh>
                </geometry>
            </visual>
        </link>
        
        <joint name="front_left_wheel_joint" type="revolute">
            <child>front_left_wheel</child>
            <parent>chassis_front</parent>
            <axis>
                <xyz>0 1 0</xyz>
                <limit>
                    <lower>-1.79769e+308</lower>
                    <upper>+1.79769e+308</upper>
                    <!-- 2 m/s => angular velocity of the wheel in rad/s -->
                    <velocity>13.333</velocity>
                    <!-- Torque in NM. -->
                    <effort>10</effort>
                </limit>
                <use_parent_model_frame>1</use_parent_model_frame>
            </axis>
        </joint>
        
        <joint name="front_right_wheel_joint" type="revolute">
            <child>front_right_wheel</child>
            <parent>chassis_front</parent>
            <axis>
                <xyz>0 1 0</xyz>
                <limit>
                    <lower>-1.79769e+308</lower>
                    <upper>+1.79769e+308</upper>
                    <!-- 2 m/s => angular velocity of the wheel in rad/s -->
                    <velocity>13.333</velocity>
                    <!-- Torque in NM. -->
                    <effort>10</effort>
                </limit>
                <use_parent_model_frame>1</use_parent_model_frame>
            </axis>
        </joint>
        
        <joint name="rear_left_wheel_joint" type="revolute">
            <child>rear_left_wheel</child>
            <parent>axle_back</parent>
            <axis>
                <xyz>0 1 0</xyz>
                <limit>
                    <lower>-1.79769e+308</lower>
                    <upper>+1.79769e+308</upper>
                    <!-- 2 m/s => angular velocity of the wheel in rad/s -->
                    <velocity>13.333</velocity>
                    <!-- Torque in NM. -->
                    <effort>10</effort>
                </limit>
                <use_parent_model_frame>1</use_parent_model_frame>
            </axis>
        </joint>
        
        <joint name="rear_right_wheel_joint" type="revolute">
            <child>rear_right_wheel</child>
            <parent>axle_back</parent>
            <axis>
                <xyz>0 1 0</xyz>
                <limit>
                    <lower>-1.79769e+308</lower>
                    <upper>+1.79769e+308</upper>
                    <!-- 2 m/s => angular velocity of the wheel in rad/s -->
                    <velocity>13.333</velocity>
                    <!-- Torque in NM. -->
                    <effort>10</effort>
                </limit>
                <use_parent_model_frame>1</use_parent_model_frame>
            </axis>
        </joint>
        
        <joint name="main_joint" type="revolute">
            <child>chassis_back</child>
            <parent>chassis_front</parent>
            <pose>0.35 0 0.02 0 0 0</pose>
            <axis>
                <xyz>0 0 1</xyz>
                <limit>
                    <lower>-1.222</lower>
                    <upper>+1.222</upper>
                </limit>
                <use_parent_model_frame>1</use_parent_model_frame>
            </axis>
        </joint>
        
        <joint name="axle_joint" type="revolute">
            <child>axle_back</child>
            <parent>chassis_back</parent>
            <axis>
                <xyz>1 0 0</xyz>
                <limit>
                    <lower>-0.436</lower>
                    <upper>+0.436</upper>
                </limit>
                <use_parent_model_frame>1</use_parent_model_frame>
            </axis>
        </joint>
        
    
  </model>
</sdf>
