<?xml version='1.0' encoding='utf-8'?>
<sdf version="1.6">
  <!-- CAUTION: This is an autogenerated file, DO NOT EDIT IT!
  It was generated by script update_robot_sdf and is based on urdf/spot.urdf.xacro source file.
  Do all modifications there and then run the update script to regenerate the SDF. -->
  <model name="csiro_data61_spot_sensor_config_1">
    <link name="base_link">
      <inertial>
        <pose>0.005937 0.000326 0.04636 0 -0 0</pose>
        <mass>20.492</mass>
        <inertia>
          <ixx>0.287877</ixx>
          <ixy>0.0014834</ixy>
          <ixz>-0.0347842</ixz>
          <iyy>1.31868</iyy>
          <iyz>-0.000519074</iyz>
          <izz>1.18915</izz>
        </inertia>
      </inertial>
      <collision name="base_link_collision">
        <geometry>
          <mesh>
            <uri>https://fuel.ignitionrobotics.org/1.0/OpenRobotics/models/BOSDYN_SPOT/tip/files/meshes/body_collision.stl</uri>
          </mesh>
        </geometry>
      </collision>
      <collision name="base_link_fixed_joint_lump__barn_link_collision_1">
        <pose>-0.0412 0 0.085 0 -0 0</pose>
        <geometry>
          <mesh>
            <uri>meshes/barn.STL</uri>
          </mesh>
        </geometry>
      </collision>
      <collision name="base_link_fixed_joint_lump__nav_base_link_collision_2">
        <pose>0.141 0 0.183 0 -0 0</pose>
        <geometry>
          <mesh>
            <uri>meshes/PPV4_Sim_Base.STL</uri>
          </mesh>
        </geometry>
      </collision>
      <collision name="base_link_fixed_joint_lump__birdcage_link_collision_3">
        <pose>0.141 0 0.183 0 -0 0</pose>
        <geometry>
          <mesh>
            <uri>meshes/birdcage.STL</uri>
          </mesh>
        </geometry>
      </collision>
      <collision name="base_link_fixed_joint_lump__nav_light_front_link_collision_4">
        <pose>0.181 0 0.423 0 -0 0</pose>
        <geometry>
          <box>
            <size>0.01 0.05 0.02</size>
          </box>
        </geometry>
      </collision>
      <collision name="base_link_fixed_joint_lump__nav_light_left_link_collision_5">
        <pose>0.141 0.04 0.423 0 -0 1.5707963267948966</pose>
        <geometry>
          <box>
            <size>0.01 0.05 0.02</size>
          </box>
        </geometry>
      </collision>
      <collision name="base_link_fixed_joint_lump__nav_light_rear_link_collision_6">
        <pose>0.101 0 0.423 0 -0 3.14</pose>
        <geometry>
          <box>
            <size>0.01 0.05 0.02</size>
          </box>
        </geometry>
      </collision>
      <collision name="base_link_fixed_joint_lump__nav_light_right_link_collision_7">
        <pose>0.141 -0.04 0.423 0 0 -1.5707963267948966</pose>
        <geometry>
          <box>
            <size>0.01 0.05 0.02</size>
          </box>
        </geometry>
      </collision>
      <visual name="base_link_visual">
        <geometry>
          <mesh>
            <uri>https://fuel.ignitionrobotics.org/1.0/OpenRobotics/models/BOSDYN_SPOT/tip/files/meshes/body.dae</uri>
          </mesh>
        </geometry>
      </visual>
      <visual name="base_link_fixed_joint_lump__barn_link_visual_1">
        <pose>-0.0412 0 0.085 0 -0 0</pose>
        <geometry>
          <mesh>
            <uri>meshes/barn.STL</uri>
          </mesh>
        </geometry>
        <material>
          <ambient>0.01 0.01 0.01 1</ambient>
          <diffuse>0.01 0.01 0.01 1</diffuse>
          <specular>0.01 0.01 0.01 1</specular>
          <emissive>0 0 0 0</emissive>
        </material>
      </visual>
      <visual name="base_link_fixed_joint_lump__nav_base_link_visual_2">
        <pose>0.141 0 0.183 0 -0 0</pose>
        <geometry>
          <mesh>
            <uri>meshes/PPV4_Sim_Base.STL</uri>
          </mesh>
        </geometry>
        <material>
          <ambient>0 0 0 1</ambient>
          <diffuse>0.5 0.5 0.5 1</diffuse>
          <specular>1 1 1 1</specular>
          <emissive>0 0 0 0</emissive>
        </material>
      </visual>
      <visual name="base_link_fixed_joint_lump__birdcage_link_visual_3">
        <pose>0.141 0 0.183 0 -0 0</pose>
        <geometry>
          <mesh>
            <uri>meshes/birdcage.STL</uri>
          </mesh>
        </geometry>
        <material>
          <ambient>0.05 0.05 0.05 1</ambient>
          <diffuse>0.05 0.05 0.05 1</diffuse>
          <specular>0.05 0.05 0.05 1</specular>
          <emissive>0 0 0 0</emissive>
        </material>
      </visual>
      <visual name="base_link_fixed_joint_lump__nav_light_front_link_visual_4">
        <pose>0.181 0 0.423 0 -0 0</pose>
        <geometry>
          <box>
            <size>0.01 0.05 0.02</size>
          </box>
        </geometry>
        <material>
          <ambient>0.1 0.1 0.1 1</ambient>
          <diffuse>0.1 0.1 0.1 1</diffuse>
          <specular>0.1 0.1 0.1 1</specular>
          <emissive>0 0 0 0</emissive>
        </material>
      </visual>
      <visual name="base_link_fixed_joint_lump__nav_light_left_link_visual_5">
        <pose>0.141 0.04 0.423 0 -0 1.5707963267948966</pose>
        <geometry>
          <box>
            <size>0.01 0.05 0.02</size>
          </box>
        </geometry>
        <material>
          <ambient>0.1 0.1 0.1 1</ambient>
          <diffuse>0.1 0.1 0.1 1</diffuse>
          <specular>0.1 0.1 0.1 1</specular>
          <emissive>0 0 0 0</emissive>
        </material>
      </visual>
      <visual name="base_link_fixed_joint_lump__nav_light_rear_link_visual_6">
        <pose>0.101 0 0.423 0 -0 3.14</pose>
        <geometry>
          <box>
            <size>0.01 0.05 0.02</size>
          </box>
        </geometry>
        <material>
          <ambient>0.1 0.1 0.1 1</ambient>
          <diffuse>0.1 0.1 0.1 1</diffuse>
          <specular>0.1 0.1 0.1 1</specular>
          <emissive>0 0 0 0</emissive>
        </material>
      </visual>
      <visual name="base_link_fixed_joint_lump__nav_light_right_link_visual_7">
        <pose>0.141 -0.04 0.423 0 0 -1.5707963267948966</pose>
        <geometry>
          <box>
            <size>0.01 0.05 0.02</size>
          </box>
        </geometry>
        <material>
          <ambient>0.1 0.1 0.1 1</ambient>
          <diffuse>0.1 0.1 0.1 1</diffuse>
          <specular>0.1 0.1 0.1 1</specular>
          <emissive>0 0 0 0</emissive>
        </material>
      </visual>
      <self_collide>0</self_collide>
      <light name="nav_light_front_source" type="spot">
        <pose>0.181 0 0.423 3.1415926535897931 -1.5707963267948966 3.1415926535897931</pose>
        <attenuation>
          <range>50</range>
          <linear>0.05</linear>
          <constant>0.1</constant>
          <quadratic>0.0025</quadratic>
        </attenuation>
        <diffuse>0.8 0.8 0.5 1</diffuse>
        <specular>0.8 0.8 0.5 1</specular>
        <spot>
          <inner_angle>2</inner_angle>
          <outer_angle>2</outer_angle>
          <falloff>1</falloff>
        </spot>
        <direction>0 0 -1</direction>
      </light>
      <light name="nav_light_left_source" type="spot">
        <pose>0.141 0.04 0.423 3.1415926535897931 -1.5707963267948966 -1.5707963267948966</pose>
        <attenuation>
          <range>50</range>
          <linear>0.05</linear>
          <constant>0.1</constant>
          <quadratic>0.0025</quadratic>
        </attenuation>
        <diffuse>0.8 0.8 0.5 1</diffuse>
        <specular>0.8 0.8 0.5 1</specular>
        <spot>
          <inner_angle>2</inner_angle>
          <outer_angle>2</outer_angle>
          <falloff>1</falloff>
        </spot>
        <direction>0 0 -1</direction>
      </light>
      <light name="nav_light_rear_source" type="spot">
        <pose>0.101 0 0.423 -3.1415926535897931 -1.5707963267948966 -0.001593</pose>
        <attenuation>
          <range>50</range>
          <linear>0.05</linear>
          <constant>0.1</constant>
          <quadratic>0.0025</quadratic>
        </attenuation>
        <diffuse>0.8 0.8 0.5 1</diffuse>
        <specular>0.8 0.8 0.5 1</specular>
        <spot>
          <inner_angle>2</inner_angle>
          <outer_angle>2</outer_angle>
          <falloff>1</falloff>
        </spot>
        <direction>0 0 -1</direction>
      </light>
      <light name="nav_light_right_source" type="spot">
        <pose>0.141 -0.04 0.423 3.1415926535897931 -1.5707963267948966 1.5707963267948966</pose>
        <attenuation>
          <range>50</range>
          <linear>0.05</linear>
          <constant>0.1</constant>
          <quadratic>0.0025</quadratic>
        </attenuation>
        <diffuse>0.8 0.8 0.5 1</diffuse>
        <specular>0.8 0.8 0.5 1</specular>
        <spot>
          <inner_angle>2</inner_angle>
          <outer_angle>2</outer_angle>
          <falloff>1</falloff>
        </spot>
        <direction>0 0 -1</direction>
      </light>
    </link>
    <link name="body">
      <inertial>
        <mass>1e-05</mass>
        <inertia>
          <ixx>0.001</ixx>
          <ixy>1e-06</ixy>
          <ixz>1e-06</ixz>
          <iyy>0.001</iyy>
          <iyz>1e-06</iyz>
          <izz>0.001</izz>
        </inertia>
      </inertial>
    </link>
    <joint name="base_link_joint" type="fixed">
      <child>body</child>
      <parent>base_link</parent>
      <axis>
        <dynamics>
          <spring_reference>0</spring_reference>
          <spring_stiffness>0</spring_stiffness>
        </dynamics>
        <xyz>0 0 1</xyz>
        <use_parent_model_frame>0</use_parent_model_frame>
        <limit>
          <lower>-1e+16</lower>
          <upper>1e+16</upper>
        </limit>
      </axis>
      <physics>
        <ode>
          <limit>
            <cfm>0</cfm>
            <erp>0.2</erp>
          </limit>
        </ode>
      </physics>
    </joint>
    <link name="front_rail">
      <pose>0.223 0 0.0805 0 -0 0</pose>
      <inertial>
        <mass>1e-05</mass>
        <inertia>
          <ixx>0.001</ixx>
          <ixy>1e-06</ixy>
          <ixz>1e-06</ixz>
          <iyy>0.001</iyy>
          <iyz>1e-06</iyz>
          <izz>0.001</izz>
        </inertia>
      </inertial>
    </link>
    <joint name="front_rail_joint" type="fixed">
      <child>front_rail</child>
      <parent>body</parent>
      <axis>
        <dynamics>
          <spring_reference>0</spring_reference>
          <spring_stiffness>0</spring_stiffness>
        </dynamics>
        <xyz>0 0 1</xyz>
        <use_parent_model_frame>0</use_parent_model_frame>
        <limit>
          <lower>-1e+16</lower>
          <upper>1e+16</upper>
        </limit>
      </axis>
      <physics>
        <ode>
          <limit>
            <cfm>0</cfm>
            <erp>0.2</erp>
          </limit>
        </ode>
      </physics>
    </joint>
    <link name="rear_rail">
      <pose>-0.223 0 0.0805 0 -0 0</pose>
      <inertial>
        <mass>1e-05</mass>
        <inertia>
          <ixx>0.001</ixx>
          <ixy>1e-06</ixy>
          <ixz>1e-06</ixz>
          <iyy>0.001</iyy>
          <iyz>1e-06</iyz>
          <izz>0.001</izz>
        </inertia>
      </inertial>
    </link>
    <joint name="rear_rail_joint" type="fixed">
      <child>rear_rail</child>
      <parent>body</parent>
      <axis>
        <dynamics>
          <spring_reference>0</spring_reference>
          <spring_stiffness>0</spring_stiffness>
        </dynamics>
        <xyz>0 0 1</xyz>
        <use_parent_model_frame>0</use_parent_model_frame>
        <limit>
          <lower>-1e+16</lower>
          <upper>1e+16</upper>
        </limit>
      </axis>
      <physics>
        <ode>
          <limit>
            <cfm>0</cfm>
            <erp>0.2</erp>
          </limit>
        </ode>
      </physics>
    </joint>
    <link name="encoder_rotating_link">
      <pose>0.141 0 0.213797 0 -0 0</pose>
      <inertial>
        <pose>0.004659 -0 0.061904 0 -0 0</pose>
        <mass>1.328</mass>
        <inertia>
          <ixx>0.00515062</ixx>
          <ixy>-8.36136e-15</ixy>
          <ixz>-0.000124068</ixz>
          <iyy>0.00506893</iyy>
          <iyz>1.36976e-13</iyz>
          <izz>0.00258497</izz>
        </inertia>
      </inertial>
      <collision name="encoder_rotating_link_collision">
        <geometry>
          <mesh>
            <uri>meshes/PPV4_Sim_Laser_Assembly.STL</uri>
          </mesh>
        </geometry>
      </collision>
      <collision name="encoder_rotating_link_fixed_joint_lump__nav_velodyne_base_link_collision_1">
        <pose>0.00735 -0 0.097852 -0.785398 0 -1.5707963267948966</pose>
        <geometry>
          <cylinder>
            <length>0.0717</length>
            <radius>0.0516</radius>
          </cylinder>
        </geometry>
      </collision>
      <visual name="encoder_rotating_link_visual">
        <geometry>
          <mesh>
            <uri>meshes/PPV4_Sim_Laser_Assembly.STL</uri>
          </mesh>
        </geometry>
        <material>
          <ambient>0 0 0 1</ambient>
          <diffuse>0.5 0.5 0.5 1</diffuse>
          <specular>1 1 1 1</specular>
          <emissive>0 0 0 0</emissive>
        </material>
      </visual>
      <visual name="encoder_rotating_link_fixed_joint_lump__nav_velodyne_base_link_visual_1">
        <pose>-0.018 0 0.072503 -0.785398 0 -1.5707963267948966</pose>
        <geometry>
          <mesh>
            <uri>meshes/VLP16_base_1.dae</uri>
          </mesh>
        </geometry>
        <material>
          <ambient>0.25 0.25 0.25 1</ambient>
          <diffuse>0.25 0.25 0.25 1</diffuse>
          <specular>0.1 0.1 0.1 1</specular>
          <emissive>0 0 0 0</emissive>
        </material>
      </visual>
      <visual name="encoder_rotating_link_fixed_joint_lump__nav_velodyne_base_link_visual_2">
        <pose>-0.018 0 0.072503 -0.785398 0 -1.5707963267948966</pose>
        <geometry>
          <mesh>
            <uri>meshes/VLP16_base_2.dae</uri>
          </mesh>
        </geometry>
        <material>
          <ambient>0.25 0.25 0.25 1</ambient>
          <diffuse>0.25 0.25 0.25 1</diffuse>
          <specular>0.1 0.1 0.1 1</specular>
          <emissive>0 0 0 0</emissive>
        </material>
      </visual>
      <visual name="encoder_rotating_link_fixed_joint_lump__nav_velodyne_visual_3">
        <pose>-0.018 0 0.072503 -0.785398 0 -1.5707963267948966</pose>
        <geometry>
          <mesh>
            <uri>meshes/VLP16_scan.dae</uri>
          </mesh>
        </geometry>
        <material>
          <ambient>0.01 0.01 0.01 1</ambient>
          <diffuse>0.01 0.01 0.01 1</diffuse>
          <specular>0.01 0.01 0.01 1</specular>
          <emissive>0 0 0 0</emissive>
        </material>
      </visual>
      <self_collide>0</self_collide>
      <sensor name="nav_gpu_lidar" type="gpu_lidar">
        <update_rate>20</update_rate>
        <lidar>
          <scan>
            <horizontal>
              <samples>900</samples>
              <resolution>1</resolution>
              <min_angle>-3.14159</min_angle>
              <max_angle>3.14159</max_angle>
            </horizontal>
            <vertical>
              <samples>16</samples>
              <resolution>1</resolution>
              <min_angle>-0.261799</min_angle>
              <max_angle>0.261799</max_angle>
            </vertical>
          </scan>
          <range>
            <min>0.3</min>
            <max>100</max>
            <resolution>0.001</resolution>
          </range>
          <noise>
            <type>gaussian</type>
            <mean>0</mean>
            <stddev>0.01</stddev>
          </noise>
        </lidar>
        <visualize>1</visualize>
        <pose>0.008658 -0 0.099161 -0.785398 0 -1.5707963267948966</pose>
        <alwaysOn>1</alwaysOn>
      </sensor>
    </link>
    <joint name="lidar_gimbal" type="revolute">
      <child>encoder_rotating_link</child>
      <parent>base_link</parent>
      <axis>
        <xyz>0 0 1</xyz>
        <limit>
          <lower>-1e+16</lower>
          <upper>1e+16</upper>
          <velocity>3.1415926535897931</velocity>
        </limit>
        <dynamics>
          <spring_reference>0</spring_reference>
          <spring_stiffness>0</spring_stiffness>
        </dynamics>
        <use_parent_model_frame>0</use_parent_model_frame>
      </axis>
    </joint>
    <link name="nav_imu">
      <pose>0.134909 -0.005178 0.183 0 -0 0</pose>
      <inertial>
        <pose>0.004061 0.003452 0.012413 0 -0 0</pose>
        <mass>0.3</mass>
        <inertia>
          <ixx>0.000467046</ixx>
          <ixy>-2.1049e-06</ixy>
          <ixz>-7.55989e-06</ixz>
          <iyy>0.000467732</iyy>
          <iyz>-6.42649e-06</iyz>
          <izz>0.000874443</izz>
        </inertia>
      </inertial>
      <collision name="nav_imu_collision">
        <geometry>
          <box>
            <size>0.01 0.01 0.01</size>
          </box>
        </geometry>
      </collision>
      <collision name="nav_imu_fixed_joint_lump__nav_camera_front_link_collision_1">
        <pose>0.071718 0.005178 0.01862 0 -0.261799 0</pose>
        <geometry>
          <box>
            <size>0.001 0.02 0.02</size>
          </box>
        </geometry>
        <surface>
          <contact>
            <ode>
              <min_depth>0.005</min_depth>
            </ode>
          </contact>
          <friction>
            <ode>
              <mu>0.9</mu>
              <mu2>0.9</mu2>
              <fdir1>1 0 0</fdir1>
            </ode>
          </friction>
        </surface>
      </collision>
      <collision name="nav_imu_fixed_joint_lump__nav_camera_left_link_collision_2">
        <pose>0.006091 0.070805 0.01862 -0 -0.261799 1.5707963267948966</pose>
        <geometry>
          <box>
            <size>0.001 0.02 0.02</size>
          </box>
        </geometry>
        <surface>
          <contact>
            <ode>
              <min_depth>0.005</min_depth>
            </ode>
          </contact>
          <friction>
            <ode>
              <mu>0.9</mu>
              <mu2>0.9</mu2>
              <fdir1>1 0 0</fdir1>
            </ode>
          </friction>
        </surface>
      </collision>
      <collision name="nav_imu_fixed_joint_lump__nav_camera_rear_link_collision_3">
        <pose>-0.059537 0.005178 0.01862 0 -0.261799 3.14</pose>
        <geometry>
          <box>
            <size>0.001 0.02 0.02</size>
          </box>
        </geometry>
        <surface>
          <contact>
            <ode>
              <min_depth>0.005</min_depth>
            </ode>
          </contact>
          <friction>
            <ode>
              <mu>0.9</mu>
              <mu2>0.9</mu2>
              <fdir1>1 0 0</fdir1>
            </ode>
          </friction>
        </surface>
      </collision>
      <collision name="nav_imu_fixed_joint_lump__nav_camera_right_link_collision_4">
        <pose>0.006091 -0.06045 0.01862 0 -0.261799 -1.5707963267948966</pose>
        <geometry>
          <box>
            <size>0.001 0.02 0.02</size>
          </box>
        </geometry>
        <surface>
          <contact>
            <ode>
              <min_depth>0.005</min_depth>
            </ode>
          </contact>
          <friction>
            <ode>
              <mu>0.9</mu>
              <mu2>0.9</mu2>
              <fdir1>1 0 0</fdir1>
            </ode>
          </friction>
        </surface>
      </collision>
      <visual name="nav_imu_visual">
        <geometry>
          <box>
            <size>0.01 0.01 0.01</size>
          </box>
        </geometry>
        <material>
          <ambient>0.1 0.1 0.1 1</ambient>
          <diffuse>0.1 0.1 0.1 1</diffuse>
          <specular>0.1 0.1 0.1 1</specular>
        </material>
      </visual>
      <visual name="nav_imu_fixed_joint_lump__nav_camera_front_link_visual_1">
        <pose>0.071718 0.005178 0.01862 0 -0.261799 0</pose>
        <geometry>
          <box>
            <size>0.001 0.02 0.02</size>
          </box>
        </geometry>
        <material>
          <ambient>0.1 0.1 0.1 1</ambient>
          <diffuse>0.1 0.1 0.1 1</diffuse>
          <specular>0.1 0.1 0.1 1</specular>
          <emissive>0 0 0 0</emissive>
        </material>
      </visual>
      <visual name="nav_imu_fixed_joint_lump__nav_camera_left_link_visual_2">
        <pose>0.006091 0.070805 0.01862 -0 -0.261799 1.5707963267948966</pose>
        <geometry>
          <box>
            <size>0.001 0.02 0.02</size>
          </box>
        </geometry>
        <material>
          <ambient>0.1 0.1 0.1 1</ambient>
          <diffuse>0.1 0.1 0.1 1</diffuse>
          <specular>0.1 0.1 0.1 1</specular>
          <emissive>0 0 0 0</emissive>
        </material>
      </visual>
      <visual name="nav_imu_fixed_joint_lump__nav_camera_rear_link_visual_3">
        <pose>-0.059537 0.005178 0.01862 0 -0.261799 3.14</pose>
        <geometry>
          <box>
            <size>0.001 0.02 0.02</size>
          </box>
        </geometry>
        <material>
          <ambient>0.1 0.1 0.1 1</ambient>
          <diffuse>0.1 0.1 0.1 1</diffuse>
          <specular>0.1 0.1 0.1 1</specular>
          <emissive>0 0 0 0</emissive>
        </material>
      </visual>
      <visual name="nav_imu_fixed_joint_lump__nav_camera_right_link_visual_4">
        <pose>0.006091 -0.06045 0.01862 0 -0.261799 -1.5707963267948966</pose>
        <geometry>
          <box>
            <size>0.001 0.02 0.02</size>
          </box>
        </geometry>
        <material>
          <ambient>0.1 0.1 0.1 1</ambient>
          <diffuse>0.1 0.1 0.1 1</diffuse>
          <specular>0.1 0.1 0.1 1</specular>
          <emissive>0 0 0 0</emissive>
        </material>
      </visual>
      <sensor name="nav_imu" type="imu">
        <always_on>1</always_on>
        <update_rate>100</update_rate>
        <imu>
          <enable_orientation>0</enable_orientation>
          <angular_velocity>
            <x>
              <noise type="gaussian">
                <mean>0</mean>
                <stddev>0.009</stddev>
                <bias_mean>0.00075</bias_mean>
                <bias_stddev>0.005</bias_stddev>
                <dynamic_bias_stddev>2e-05</dynamic_bias_stddev>
                <dynamic_bias_correlation_time>400</dynamic_bias_correlation_time>
                <precision>0.00025</precision>
              </noise>
            </x>
            <y>
              <noise type="gaussian">
                <mean>0</mean>
                <stddev>0.009</stddev>
                <bias_mean>0.00075</bias_mean>
                <bias_stddev>0.005</bias_stddev>
                <dynamic_bias_stddev>2e-05</dynamic_bias_stddev>
                <dynamic_bias_correlation_time>400</dynamic_bias_correlation_time>
                <precision>0.00025</precision>
              </noise>
            </y>
            <z>
              <noise type="gaussian">
                <mean>0</mean>
                <stddev>0.009</stddev>
                <bias_mean>0.00075</bias_mean>
                <bias_stddev>0.005</bias_stddev>
                <dynamic_bias_stddev>2e-05</dynamic_bias_stddev>
                <dynamic_bias_correlation_time>400</dynamic_bias_correlation_time>
                <precision>0.00025</precision>
              </noise>
            </z>
          </angular_velocity>
          <linear_acceleration>
            <x>
              <noise type="gaussian">
                <mean>0</mean>
                <stddev>0.021</stddev>
                <bias_mean>0.05</bias_mean>
                <bias_stddev>0.0075</bias_stddev>
                <dynamic_bias_stddev>0.000375</dynamic_bias_stddev>
                <dynamic_bias_correlation_time>175</dynamic_bias_correlation_time>
                <precision>0.005</precision>
              </noise>
            </x>
            <y>
              <noise type="gaussian">
                <mean>0</mean>
                <stddev>0.021</stddev>
                <bias_mean>0.05</bias_mean>
                <bias_stddev>0.0075</bias_stddev>
                <dynamic_bias_stddev>0.000375</dynamic_bias_stddev>
                <dynamic_bias_correlation_time>175</dynamic_bias_correlation_time>
                <precision>0.005</precision>
              </noise>
            </y>
            <z>
              <noise type="gaussian">
                <mean>0</mean>
                <stddev>0.021</stddev>
                <bias_mean>0.05</bias_mean>
                <bias_stddev>0.0075</bias_stddev>
                <dynamic_bias_stddev>0.000375</dynamic_bias_stddev>
                <dynamic_bias_correlation_time>175</dynamic_bias_correlation_time>
                <precision>0.005</precision>
              </noise>
            </z>
          </linear_acceleration>
        </imu>
      </sensor>
      <sensor name="nav_camera_front" type="camera">
        <update_rate>15</update_rate>
        <visualize>0</visualize>
        <camera name="nav_camera_front_sensor">
          <lens>
            <intrinsics>
              <fx>1008</fx>
              <fy>1008</fy>
              <cx>1007.5</cx>
              <cy>755.5</cy>
              <s>0</s>
            </intrinsics>
            <type>stereographic</type>
            <scale_to_hfov>1</scale_to_hfov>
          </lens>
          <image>
            <width>2016</width>
            <height>1512</height>
          </image>
          <clip>
            <near>0.02</near>
            <far>300</far>
          </clip>
          <noise>
            <type>gaussian</type>
            <mean>0</mean>
            <stddev>0.007</stddev>
          </noise>
          <horizontal_fov>1.5708</horizontal_fov>
          <aspect_ratio>1.333333333333</aspect_ratio>
        </camera>
        <pose>0.071718 0.005178 0.01862 0 -0.261799 0</pose>
      </sensor>
      <sensor name="nav_camera_left" type="camera">
        <update_rate>15</update_rate>
        <visualize>0</visualize>
        <camera name="nav_camera_left_sensor">
          <lens>
            <intrinsics>
              <fx>1008</fx>
              <fy>1008</fy>
              <cx>1007.5</cx>
              <cy>755.5</cy>
              <s>0</s>
            </intrinsics>
            <type>stereographic</type>
            <scale_to_hfov>1</scale_to_hfov>
          </lens>
          <image>
            <width>2016</width>
            <height>1512</height>
          </image>
          <clip>
            <near>0.02</near>
            <far>300</far>
          </clip>
          <noise>
            <type>gaussian</type>
            <mean>0</mean>
            <stddev>0.007</stddev>
          </noise>
          <horizontal_fov>1.5708</horizontal_fov>
          <aspect_ratio>1.333333333333</aspect_ratio>
        </camera>
        <pose>0.006091 0.070805 0.01862 -0 -0.261799 1.5707963267948966</pose>
      </sensor>
      <sensor name="nav_camera_rear" type="camera">
        <update_rate>15</update_rate>
        <visualize>0</visualize>
        <camera name="nav_camera_rear_sensor">
          <lens>
            <intrinsics>
              <fx>1008</fx>
              <fy>1008</fy>
              <cx>1007.5</cx>
              <cy>755.5</cy>
              <s>0</s>
            </intrinsics>
            <type>stereographic</type>
            <scale_to_hfov>1</scale_to_hfov>
          </lens>
          <image>
            <width>2016</width>
            <height>1512</height>
          </image>
          <clip>
            <near>0.02</near>
            <far>300</far>
          </clip>
          <noise>
            <type>gaussian</type>
            <mean>0</mean>
            <stddev>0.007</stddev>
          </noise>
          <horizontal_fov>1.5708</horizontal_fov>
          <aspect_ratio>1.333333333333</aspect_ratio>
        </camera>
        <pose>-0.059537 0.005178 0.01862 0 -0.261799 3.14</pose>
      </sensor>
      <self_collide>0</self_collide>
      <sensor name="nav_camera_right" type="camera">
        <update_rate>15</update_rate>
        <visualize>0</visualize>
        <camera name="nav_camera_right_sensor">
          <lens>
            <intrinsics>
              <fx>1008</fx>
              <fy>1008</fy>
              <cx>1007.5</cx>
              <cy>755.5</cy>
              <s>0</s>
            </intrinsics>
            <type>stereographic</type>
            <scale_to_hfov>1</scale_to_hfov>
          </lens>
          <image>
            <width>2016</width>
            <height>1512</height>
          </image>
          <clip>
            <near>0.02</near>
            <far>300</far>
          </clip>
          <noise>
            <type>gaussian</type>
            <mean>0</mean>
            <stddev>0.007</stddev>
          </noise>
          <horizontal_fov>1.5708</horizontal_fov>
          <aspect_ratio>1.333333333333</aspect_ratio>
        </camera>
        <pose>0.006091 -0.06045 0.01862 0 -0.261799 -1.5707963267948966</pose>
      </sensor>
    </link>
    <joint name="nav_base_link_to_nav_imu" type="revolute">
      <child>nav_imu</child>
      <parent>base_link</parent>
      <axis>
        <xyz>1 0 0</xyz>
        <limit>
          <lower>0</lower>
          <upper>0</upper>
          <effort>0</effort>
          <velocity>0</velocity>
        </limit>
        <dynamics>
          <spring_reference>0</spring_reference>
          <spring_stiffness>0</spring_stiffness>
        </dynamics>
        <use_parent_model_frame>0</use_parent_model_frame>
      </axis>
    </joint>
    <link name="battery">
      <pose>0 0 -0.03 0 -0 0</pose>
      <inertial>
        <mass>4</mass>
        <inertia>
          <ixx>0.012291</ixx>
          <ixy>0</ixy>
          <ixz>0</ixz>
          <iyy>0.037875</iyy>
          <iyz>0</iyz>
          <izz>0.0444</izz>
        </inertia>
      </inertial>
      <collision name="battery_collision">
        <geometry>
          <box>
            <size>0.324 0.168 0.093</size>
          </box>
        </geometry>
      </collision>
      <visual name="battery_visual">
        <geometry>
          <box>
            <size>0.324 0.168 0.093</size>
          </box>
        </geometry>
        <material>
          <ambient>0.917647 0.654902 0 1</ambient>
          <diffuse>0.917647 0.654902 0 1</diffuse>
          <specular>0.917647 0.654902 0 1</specular>
          <emissive>0 0 0 0</emissive>
        </material>
      </visual>
    </link>
    <joint name="battery_joint" type="fixed">
      <child>battery</child>
      <parent>base_link</parent>
      <axis>
        <dynamics>
          <spring_reference>0</spring_reference>
          <spring_stiffness>0</spring_stiffness>
        </dynamics>
        <xyz>0 0 1</xyz>
        <use_parent_model_frame>0</use_parent_model_frame>
        <limit>
          <lower>-1e+16</lower>
          <upper>1e+16</upper>
        </limit>
      </axis>
      <physics>
        <ode>
          <limit>
            <cfm>0</cfm>
            <erp>0.2</erp>
          </limit>
        </ode>
      </physics>
    </joint>
    <link name="camera_back">
      <pose>-0.425 0 0.01 -0 0.3 3.1415926535897931</pose>
      <inertial>
        <mass>1e-05</mass>
        <inertia>
          <ixx>0.001</ixx>
          <ixy>1e-06</ixy>
          <ixz>1e-06</ixz>
          <iyy>0.001</iyy>
          <iyz>1e-06</iyz>
          <izz>0.001</izz>
        </inertia>
      </inertial>
      <sensor name="back_fisheye_image" type="camera">
        <pose>0 0.01 0 0 -0 0</pose>
        <update_rate>30</update_rate>
        <visualize>0</visualize>
        <camera>
          <horizontal_fov>1.78634</horizontal_fov>
          <image>
            <width>640</width>
            <height>480</height>
            <format>R8G8B8</format>
          </image>
          <clip>
            <near>0.1</near>
            <far>20</far>
          </clip>
          <noise>
            <type>gaussian</type>
            <mean>0</mean>
            <stddev>0.007</stddev>
          </noise>
          <lens>
            <intrinsics>
              <fx>257.487</fx>
              <fy>257.487</fy>
              <cx>319.5</cx>
              <cy>239.5</cy>
              <s>0</s>
            </intrinsics>
            <type>stereographic</type>
            <scale_to_hfov>1</scale_to_hfov>
          </lens>
        </camera>
        <plugin name="subt::MonoCameraSystem" filename="mono-camera-system"/>
      </sensor>
      <sensor name="back_depth" type="depth_camera">
        <update_rate>30</update_rate>
        <visualize>0</visualize>
        <camera>
          <horizontal_fov>1.78634</horizontal_fov>
          <image>
            <width>424</width>
            <height>240</height>
            <format>R_FLOAT32</format>
          </image>
          <clip>
            <near>0.1</near>
            <far>4</far>
          </clip>
          <noise>
            <type>gaussian</type>
            <mean>0</mean>
            <stddev>0.007</stddev>
          </noise>
          <lens>
            <intrinsics>
              <fx>170.6</fx>
              <fy>170.6</fy>
              <cx>211.5</cx>
              <cy>119.5</cy>
              <s>0</s>
            </intrinsics>
            <type>stereographic</type>
            <scale_to_hfov>1</scale_to_hfov>
          </lens>
        </camera>
      </sensor>
    </link>
    <joint name="camera_back_j" type="fixed">
      <child>camera_back</child>
      <parent>base_link</parent>
      <axis>
        <dynamics>
          <spring_reference>0</spring_reference>
          <spring_stiffness>0</spring_stiffness>
        </dynamics>
        <xyz>0 0 1</xyz>
        <use_parent_model_frame>0</use_parent_model_frame>
        <limit>
          <lower>-1e+16</lower>
          <upper>1e+16</upper>
        </limit>
      </axis>
      <physics>
        <ode>
          <limit>
            <cfm>0</cfm>
            <erp>0.2</erp>
          </limit>
        </ode>
      </physics>
    </joint>
    <link name="camera_frontleft">
      <pose>0.415 0.037 -0.01 1.35556 0.353917 -0.554196</pose>
      <inertial>
        <mass>1e-05</mass>
        <inertia>
          <ixx>0.001</ixx>
          <ixy>1e-06</ixy>
          <ixz>1e-06</ixz>
          <iyy>0.001</iyy>
          <iyz>1e-06</iyz>
          <izz>0.001</izz>
        </inertia>
      </inertial>
      <sensor name="frontleft_fisheye_image" type="camera">
        <pose>0 0.01 0 0 -0 0</pose>
        <update_rate>30</update_rate>
        <visualize>0</visualize>
        <camera>
          <horizontal_fov>1.78634</horizontal_fov>
          <image>
            <width>640</width>
            <height>480</height>
            <format>R8G8B8</format>
          </image>
          <clip>
            <near>0.1</near>
            <far>20</far>
          </clip>
          <noise>
            <type>gaussian</type>
            <mean>0</mean>
            <stddev>0.007</stddev>
          </noise>
          <lens>
            <intrinsics>
              <fx>257.487</fx>
              <fy>257.487</fy>
              <cx>319.5</cx>
              <cy>239.5</cy>
              <s>0</s>
            </intrinsics>
            <type>stereographic</type>
            <scale_to_hfov>1</scale_to_hfov>
          </lens>
        </camera>
        <plugin name="subt::MonoCameraSystem" filename="mono-camera-system"/>
      </sensor>
      <sensor name="frontleft_depth" type="depth_camera">
        <update_rate>30</update_rate>
        <visualize>0</visualize>
        <camera>
          <horizontal_fov>1.78634</horizontal_fov>
          <image>
            <width>424</width>
            <height>240</height>
            <format>R_FLOAT32</format>
          </image>
          <clip>
            <near>0.1</near>
            <far>4</far>
          </clip>
          <noise>
            <type>gaussian</type>
            <mean>0</mean>
            <stddev>0.007</stddev>
          </noise>
          <lens>
            <intrinsics>
              <fx>170.6</fx>
              <fy>170.6</fy>
              <cx>211.5</cx>
              <cy>119.5</cy>
              <s>0</s>
            </intrinsics>
            <type>stereographic</type>
            <scale_to_hfov>1</scale_to_hfov>
          </lens>
        </camera>
      </sensor>
    </link>
    <joint name="camera_frontleft_j" type="fixed">
      <child>camera_frontleft</child>
      <parent>base_link</parent>
      <axis>
        <dynamics>
          <spring_reference>0</spring_reference>
          <spring_stiffness>0</spring_stiffness>
        </dynamics>
        <xyz>0 0 1</xyz>
        <use_parent_model_frame>0</use_parent_model_frame>
        <limit>
          <lower>-1e+16</lower>
          <upper>1e+16</upper>
        </limit>
      </axis>
      <physics>
        <ode>
          <limit>
            <cfm>0</cfm>
            <erp>0.2</erp>
          </limit>
        </ode>
      </physics>
    </joint>
    <link name="camera_frontright">
      <pose>0.415 -0.037 -0.01 -1.35556 0.353917 0.554196</pose>
      <inertial>
        <mass>1e-05</mass>
        <inertia>
          <ixx>0.001</ixx>
          <ixy>1e-06</ixy>
          <ixz>1e-06</ixz>
          <iyy>0.001</iyy>
          <iyz>1e-06</iyz>
          <izz>0.001</izz>
        </inertia>
      </inertial>
      <sensor name="frontright_fisheye_image" type="camera">
        <pose>0 0.01 0 0 -0 0</pose>
        <update_rate>30</update_rate>
        <visualize>0</visualize>
        <camera>
          <horizontal_fov>1.78634</horizontal_fov>
          <image>
            <width>640</width>
            <height>480</height>
            <format>R8G8B8</format>
          </image>
          <clip>
            <near>0.1</near>
            <far>20</far>
          </clip>
          <noise>
            <type>gaussian</type>
            <mean>0</mean>
            <stddev>0.007</stddev>
          </noise>
          <lens>
            <intrinsics>
              <fx>257.487</fx>
              <fy>257.487</fy>
              <cx>319.5</cx>
              <cy>239.5</cy>
              <s>0</s>
            </intrinsics>
            <type>stereographic</type>
            <scale_to_hfov>1</scale_to_hfov>
          </lens>
        </camera>
        <plugin name="subt::MonoCameraSystem" filename="mono-camera-system"/>
      </sensor>
      <sensor name="frontright_depth" type="depth_camera">
        <update_rate>30</update_rate>
        <visualize>0</visualize>
        <camera>
          <horizontal_fov>1.78634</horizontal_fov>
          <image>
            <width>424</width>
            <height>240</height>
            <format>R_FLOAT32</format>
          </image>
          <clip>
            <near>0.1</near>
            <far>4</far>
          </clip>
          <noise>
            <type>gaussian</type>
            <mean>0</mean>
            <stddev>0.007</stddev>
          </noise>
          <lens>
            <intrinsics>
              <fx>170.6</fx>
              <fy>170.6</fy>
              <cx>211.5</cx>
              <cy>119.5</cy>
              <s>0</s>
            </intrinsics>
            <type>stereographic</type>
            <scale_to_hfov>1</scale_to_hfov>
          </lens>
        </camera>
      </sensor>
    </link>
    <joint name="camera_frontright_j" type="fixed">
      <child>camera_frontright</child>
      <parent>base_link</parent>
      <axis>
        <dynamics>
          <spring_reference>0</spring_reference>
          <spring_stiffness>0</spring_stiffness>
        </dynamics>
        <xyz>0 0 1</xyz>
        <use_parent_model_frame>0</use_parent_model_frame>
        <limit>
          <lower>-1e+16</lower>
          <upper>1e+16</upper>
        </limit>
      </axis>
      <physics>
        <ode>
          <limit>
            <cfm>0</cfm>
            <erp>0.2</erp>
          </limit>
        </ode>
      </physics>
    </joint>
    <link name="camera_left">
      <pose>-0.125 0.12 0.035 0 0.2 1.5707963267948966</pose>
      <inertial>
        <mass>1e-05</mass>
        <inertia>
          <ixx>0.001</ixx>
          <ixy>1e-06</ixy>
          <ixz>1e-06</ixz>
          <iyy>0.001</iyy>
          <iyz>1e-06</iyz>
          <izz>0.001</izz>
        </inertia>
      </inertial>
      <sensor name="left_fisheye_image" type="camera">
        <pose>0 0.01 0 0 -0 0</pose>
        <update_rate>30</update_rate>
        <visualize>0</visualize>
        <camera>
          <horizontal_fov>1.78634</horizontal_fov>
          <image>
            <width>640</width>
            <height>480</height>
            <format>R8G8B8</format>
          </image>
          <clip>
            <near>0.1</near>
            <far>20</far>
          </clip>
          <noise>
            <type>gaussian</type>
            <mean>0</mean>
            <stddev>0.007</stddev>
          </noise>
          <lens>
            <intrinsics>
              <fx>257.487</fx>
              <fy>257.487</fy>
              <cx>319.5</cx>
              <cy>239.5</cy>
              <s>0</s>
            </intrinsics>
            <type>stereographic</type>
            <scale_to_hfov>1</scale_to_hfov>
          </lens>
        </camera>
        <plugin name="subt::MonoCameraSystem" filename="mono-camera-system"/>
      </sensor>
      <sensor name="left_depth" type="depth_camera">
        <update_rate>30</update_rate>
        <visualize>0</visualize>
        <camera>
          <horizontal_fov>1.78634</horizontal_fov>
          <image>
            <width>424</width>
            <height>240</height>
            <format>R_FLOAT32</format>
          </image>
          <clip>
            <near>0.1</near>
            <far>4</far>
          </clip>
          <noise>
            <type>gaussian</type>
            <mean>0</mean>
            <stddev>0.007</stddev>
          </noise>
          <lens>
            <intrinsics>
              <fx>170.6</fx>
              <fy>170.6</fy>
              <cx>211.5</cx>
              <cy>119.5</cy>
              <s>0</s>
            </intrinsics>
            <type>stereographic</type>
            <scale_to_hfov>1</scale_to_hfov>
          </lens>
        </camera>
      </sensor>
    </link>
    <joint name="camera_left_j" type="fixed">
      <child>camera_left</child>
      <parent>base_link</parent>
      <axis>
        <dynamics>
          <spring_reference>0</spring_reference>
          <spring_stiffness>0</spring_stiffness>
        </dynamics>
        <xyz>0 0 1</xyz>
        <use_parent_model_frame>0</use_parent_model_frame>
        <limit>
          <lower>-1e+16</lower>
          <upper>1e+16</upper>
        </limit>
      </axis>
      <physics>
        <ode>
          <limit>
            <cfm>0</cfm>
            <erp>0.2</erp>
          </limit>
        </ode>
      </physics>
    </joint>
    <link name="camera_right">
      <pose>-0.125 -0.12 0.035 -0 0.2 -1.5707963267948966</pose>
      <inertial>
        <mass>1e-05</mass>
        <inertia>
          <ixx>0.001</ixx>
          <ixy>1e-06</ixy>
          <ixz>1e-06</ixz>
          <iyy>0.001</iyy>
          <iyz>1e-06</iyz>
          <izz>0.001</izz>
        </inertia>
      </inertial>
      <sensor name="right_fisheye_image" type="camera">
        <pose>0 0.01 0 0 -0 0</pose>
        <update_rate>30</update_rate>
        <visualize>0</visualize>
        <camera>
          <horizontal_fov>1.78634</horizontal_fov>
          <image>
            <width>640</width>
            <height>480</height>
            <format>R8G8B8</format>
          </image>
          <clip>
            <near>0.1</near>
            <far>20</far>
          </clip>
          <noise>
            <type>gaussian</type>
            <mean>0</mean>
            <stddev>0.007</stddev>
          </noise>
          <lens>
            <intrinsics>
              <fx>257.487</fx>
              <fy>257.487</fy>
              <cx>319.5</cx>
              <cy>239.5</cy>
              <s>0</s>
            </intrinsics>
            <type>stereographic</type>
            <scale_to_hfov>1</scale_to_hfov>
          </lens>
        </camera>
        <plugin name="subt::MonoCameraSystem" filename="mono-camera-system"/>
      </sensor>
      <sensor name="right_depth" type="depth_camera">
        <update_rate>30</update_rate>
        <visualize>0</visualize>
        <camera>
          <horizontal_fov>1.78634</horizontal_fov>
          <image>
            <width>424</width>
            <height>240</height>
            <format>R_FLOAT32</format>
          </image>
          <clip>
            <near>0.1</near>
            <far>4</far>
          </clip>
          <noise>
            <type>gaussian</type>
            <mean>0</mean>
            <stddev>0.007</stddev>
          </noise>
          <lens>
            <intrinsics>
              <fx>170.6</fx>
              <fy>170.6</fy>
              <cx>211.5</cx>
              <cy>119.5</cy>
              <s>0</s>
            </intrinsics>
            <type>stereographic</type>
            <scale_to_hfov>1</scale_to_hfov>
          </lens>
        </camera>
      </sensor>
    </link>
    <joint name="camera_right_j" type="fixed">
      <child>camera_right</child>
      <parent>base_link</parent>
      <axis>
        <dynamics>
          <spring_reference>0</spring_reference>
          <spring_stiffness>0</spring_stiffness>
        </dynamics>
        <xyz>0 0 1</xyz>
        <use_parent_model_frame>0</use_parent_model_frame>
        <limit>
          <lower>-1e+16</lower>
          <upper>1e+16</upper>
        </limit>
      </axis>
      <physics>
        <ode>
          <limit>
            <cfm>0</cfm>
            <erp>0.2</erp>
          </limit>
        </ode>
      </physics>
    </joint>
    <link name="front_left_hip">
      <pose>0.29785 0.055 0 0 -0 0</pose>
      <inertial>
        <mass>2</mass>
        <inertia>
          <ixx>0.0027</ixx>
          <ixy>0</ixy>
          <ixz>0</ixz>
          <iyy>0.00416667</iyy>
          <iyz>0</iyz>
          <izz>0.00416667</izz>
        </inertia>
      </inertial>
      <collision name="front_left_hip_collision">
        <geometry>
          <mesh>
            <uri>https://fuel.ignitionrobotics.org/1.0/OpenRobotics/models/BOSDYN_SPOT/tip/files/meshes/front_left_hip_collision.stl</uri>
          </mesh>
        </geometry>
      </collision>
      <visual name="front_left_hip_visual">
        <geometry>
          <mesh>
            <uri>https://fuel.ignitionrobotics.org/1.0/OpenRobotics/models/BOSDYN_SPOT/tip/files/meshes/front_left_hip.dae</uri>
          </mesh>
        </geometry>
      </visual>
    </link>
    <joint name="front_left_hip_x" type="revolute">
      <child>front_left_hip</child>
      <parent>base_link</parent>
      <axis>
        <xyz>1 0 0</xyz>
        <limit>
          <lower>-0.785398</lower>
          <upper>0.785398</upper>
          <effort>80</effort>
          <velocity>15</velocity>
        </limit>
        <dynamics>
          <spring_reference>0</spring_reference>
          <spring_stiffness>0</spring_stiffness>
        </dynamics>
        <use_parent_model_frame>0</use_parent_model_frame>
      </axis>
    </joint>
    <link name="front_left_upper_leg">
      <pose>0.29785 0.165945 0 0 -0 0</pose>
      <inertial>
        <pose>0 0 -0.14 0 -0 0</pose>
        <mass>1</mass>
        <inertia>
          <ixx>0.0155334</ixx>
          <ixy>0</ixy>
          <ixz>0</ixz>
          <iyy>0.0155334</iyy>
          <iyz>0</iyz>
          <izz>0.000962667</izz>
        </inertia>
      </inertial>
      <collision name="front_left_upper_leg_collision">
        <geometry>
          <mesh>
            <uri>https://fuel.ignitionrobotics.org/1.0/OpenRobotics/models/BOSDYN_SPOT/tip/files/meshes/front_left_upper_leg_collision.stl</uri>
          </mesh>
        </geometry>
      </collision>
      <visual name="front_left_upper_leg_visual">
        <geometry>
          <mesh>
            <uri>https://fuel.ignitionrobotics.org/1.0/OpenRobotics/models/BOSDYN_SPOT/tip/files/meshes/front_left_upper_leg.dae</uri>
          </mesh>
        </geometry>
      </visual>
    </link>
    <joint name="front_left_hip_y" type="revolute">
      <child>front_left_upper_leg</child>
      <parent>front_left_hip</parent>
      <axis>
        <xyz>0 1 0</xyz>
        <limit>
          <lower>-0.898845</lower>
          <upper>2.29511</upper>
          <effort>80</effort>
          <velocity>15</velocity>
        </limit>
        <dynamics>
          <spring_reference>0</spring_reference>
          <spring_stiffness>0</spring_stiffness>
        </dynamics>
        <use_parent_model_frame>0</use_parent_model_frame>
      </axis>
    </joint>
    <link name="front_left_lower_leg">
      <pose>0.32285 0.165945 -0.3205 0 -0 0</pose>
      <inertial>
        <pose>0 0 -0.16 0 -0 0</pose>
        <mass>0.5</mass>
        <inertia>
          <ixx>0.00743438</ixx>
          <ixy>0</ixy>
          <ixz>0</ixz>
          <iyy>0.00740104</iyy>
          <iyz>0</iyz>
          <izz>0.000135417</izz>
        </inertia>
      </inertial>
      <collision name="front_left_lower_leg_collision">
        <geometry>
          <mesh>
            <scale>0.82 0.97 0.98</scale>
            <uri>https://fuel.ignitionrobotics.org/1.0/OpenRobotics/models/BOSDYN_SPOT/tip/files/meshes/front_left_lower_leg_collision.stl</uri>
          </mesh>
        </geometry>
        <surface>
          <contact>
            <ode>
              <kp>1e+07</kp>
              <kd>100</kd>
            </ode>
          </contact>
          <friction>
            <ode>
              <mu>0.8</mu>
              <mu2>0.8</mu2>
            </ode>
          </friction>
        </surface>
      </collision>
      <collision name="front_left_lower_leg_collision_1">
        <pose>0 0 -0.333 0 -0 0</pose>
        <geometry>
          <sphere>
            <radius>0.04</radius>
          </sphere>
        </geometry>
        <surface>
          <contact>
            <ode>
              <kp>1e+07</kp>
              <kd>100</kd>
            </ode>
          </contact>
          <friction>
            <ode>
              <mu>0.8</mu>
              <mu2>0.8</mu2>
            </ode>
          </friction>
        </surface>
      </collision>
      <visual name="front_left_lower_leg_visual">
        <geometry>
          <mesh>
            <uri>https://fuel.ignitionrobotics.org/1.0/OpenRobotics/models/BOSDYN_SPOT/tip/files/meshes/front_left_lower_leg.dae</uri>
          </mesh>
        </geometry>
        <material>
        </material>
      </visual>
      <sensor name="contact" type="contact">
        <contact>
          <collision>front_left_lower_leg_collision</collision>
          <collision>front_left_lower_leg_collision_1</collision>
          <topic>__default_topic__</topic>
        </contact>
      </sensor>
    </link>
    <joint name="front_left_knee" type="revolute">
      <child>front_left_lower_leg</child>
      <parent>front_left_upper_leg</parent>
      <axis>
        <xyz>0 1 0</xyz>
        <limit>
          <lower>-2.7929</lower>
          <upper>-0.254801</upper>
          <effort>80</effort>
          <velocity>15</velocity>
        </limit>
        <dynamics>
          <spring_reference>0</spring_reference>
          <spring_stiffness>0</spring_stiffness>
        </dynamics>
        <use_parent_model_frame>0</use_parent_model_frame>
      </axis>
    </joint>
    <link name="front_left_ee">
      <pose>0.32285 0.165945 -0.6905 0 -0 0</pose>
      <inertial>
        <mass>1e-05</mass>
        <inertia>
          <ixx>0.001</ixx>
          <ixy>1e-06</ixy>
          <ixz>1e-06</ixz>
          <iyy>0.001</iyy>
          <iyz>1e-06</iyz>
          <izz>0.001</izz>
        </inertia>
      </inertial>
    </link>
    <joint name="front_left_foot" type="fixed">
      <child>front_left_ee</child>
      <parent>front_left_lower_leg</parent>
      <axis>
        <dynamics>
          <spring_reference>0</spring_reference>
          <spring_stiffness>0</spring_stiffness>
        </dynamics>
        <xyz>0 0 1</xyz>
        <use_parent_model_frame>0</use_parent_model_frame>
        <limit>
          <lower>-1e+16</lower>
          <upper>1e+16</upper>
        </limit>
      </axis>
      <physics>
        <ode>
          <limit>
            <cfm>0</cfm>
            <erp>0.2</erp>
          </limit>
        </ode>
      </physics>
    </joint>
    <link name="front_right_hip">
      <pose>0.29785 -0.055 0 0 -0 0</pose>
      <inertial>
        <mass>2</mass>
        <inertia>
          <ixx>0.0027</ixx>
          <ixy>0</ixy>
          <ixz>0</ixz>
          <iyy>0.00416667</iyy>
          <iyz>0</iyz>
          <izz>0.00416667</izz>
        </inertia>
      </inertial>
      <collision name="front_right_hip_collision">
        <geometry>
          <mesh>
            <uri>https://fuel.ignitionrobotics.org/1.0/OpenRobotics/models/BOSDYN_SPOT/tip/files/meshes/front_right_hip_collision.stl</uri>
          </mesh>
        </geometry>
      </collision>
      <visual name="front_right_hip_visual">
        <geometry>
          <mesh>
            <uri>https://fuel.ignitionrobotics.org/1.0/OpenRobotics/models/BOSDYN_SPOT/tip/files/meshes/front_right_hip.dae</uri>
          </mesh>
        </geometry>
      </visual>
    </link>
    <joint name="front_right_hip_x" type="revolute">
      <child>front_right_hip</child>
      <parent>base_link</parent>
      <axis>
        <xyz>1 0 0</xyz>
        <limit>
          <lower>-0.785398</lower>
          <upper>0.785398</upper>
          <effort>80</effort>
          <velocity>15</velocity>
        </limit>
        <dynamics>
          <spring_reference>0</spring_reference>
          <spring_stiffness>0</spring_stiffness>
        </dynamics>
        <use_parent_model_frame>0</use_parent_model_frame>
      </axis>
    </joint>
    <link name="front_right_upper_leg">
      <pose>0.29785 -0.165945 0 0 -0 0</pose>
      <inertial>
        <pose>0 0 -0.14 0 -0 0</pose>
        <mass>1</mass>
        <inertia>
          <ixx>0.0155334</ixx>
          <ixy>0</ixy>
          <ixz>0</ixz>
          <iyy>0.0155334</iyy>
          <iyz>0</iyz>
          <izz>0.000962667</izz>
        </inertia>
      </inertial>
      <collision name="front_right_upper_leg_collision">
        <geometry>
          <mesh>
            <uri>https://fuel.ignitionrobotics.org/1.0/OpenRobotics/models/BOSDYN_SPOT/tip/files/meshes/front_right_upper_leg_collision.stl</uri>
          </mesh>
        </geometry>
      </collision>
      <visual name="front_right_upper_leg_visual">
        <geometry>
          <mesh>
            <uri>https://fuel.ignitionrobotics.org/1.0/OpenRobotics/models/BOSDYN_SPOT/tip/files/meshes/front_right_upper_leg.dae</uri>
          </mesh>
        </geometry>
      </visual>
    </link>
    <joint name="front_right_hip_y" type="revolute">
      <child>front_right_upper_leg</child>
      <parent>front_right_hip</parent>
      <axis>
        <xyz>0 1 0</xyz>
        <limit>
          <lower>-0.898845</lower>
          <upper>2.29511</upper>
          <effort>80</effort>
          <velocity>15</velocity>
        </limit>
        <dynamics>
          <spring_reference>0</spring_reference>
          <spring_stiffness>0</spring_stiffness>
        </dynamics>
        <use_parent_model_frame>0</use_parent_model_frame>
      </axis>
    </joint>
    <link name="front_right_lower_leg">
      <pose>0.32285 -0.165945 -0.3205 0 -0 0</pose>
      <inertial>
        <pose>0 0 -0.16 0 -0 0</pose>
        <mass>0.5</mass>
        <inertia>
          <ixx>0.00743438</ixx>
          <ixy>0</ixy>
          <ixz>0</ixz>
          <iyy>0.00740104</iyy>
          <iyz>0</iyz>
          <izz>0.000135417</izz>
        </inertia>
      </inertial>
      <collision name="front_right_lower_leg_collision">
        <geometry>
          <mesh>
            <scale>0.82 0.97 0.98</scale>
            <uri>https://fuel.ignitionrobotics.org/1.0/OpenRobotics/models/BOSDYN_SPOT/tip/files/meshes/front_right_lower_leg_collision.stl</uri>
          </mesh>
        </geometry>
        <surface>
          <contact>
            <ode>
              <kp>1e+07</kp>
              <kd>100</kd>
            </ode>
          </contact>
          <friction>
            <ode>
              <mu>0.8</mu>
              <mu2>0.8</mu2>
            </ode>
          </friction>
        </surface>
      </collision>
      <collision name="front_right_lower_leg_collision_1">
        <pose>0 0 -0.333 0 -0 0</pose>
        <geometry>
          <sphere>
            <radius>0.04</radius>
          </sphere>
        </geometry>
        <surface>
          <contact>
            <ode>
              <kp>1e+07</kp>
              <kd>100</kd>
            </ode>
          </contact>
          <friction>
            <ode>
              <mu>0.8</mu>
              <mu2>0.8</mu2>
            </ode>
          </friction>
        </surface>
      </collision>
      <visual name="front_right_lower_leg_visual">
        <geometry>
          <mesh>
            <uri>https://fuel.ignitionrobotics.org/1.0/OpenRobotics/models/BOSDYN_SPOT/tip/files/meshes/front_right_lower_leg.dae</uri>
          </mesh>
        </geometry>
        <material>
        </material>
      </visual>
      <sensor name="contact" type="contact">
        <contact>
          <collision>front_right_lower_leg_collision</collision>
          <collision>front_right_lower_leg_collision_1</collision>
          <topic>__default_topic__</topic>
        </contact>
      </sensor>
    </link>
    <joint name="front_right_knee" type="revolute">
      <child>front_right_lower_leg</child>
      <parent>front_right_upper_leg</parent>
      <axis>
        <xyz>0 1 0</xyz>
        <limit>
          <lower>-2.7929</lower>
          <upper>-0.254801</upper>
          <effort>80</effort>
          <velocity>15</velocity>
        </limit>
        <dynamics>
          <spring_reference>0</spring_reference>
          <spring_stiffness>0</spring_stiffness>
        </dynamics>
        <use_parent_model_frame>0</use_parent_model_frame>
      </axis>
    </joint>
    <link name="front_right_ee">
      <pose>0.32285 -0.165945 -0.6905 0 -0 0</pose>
      <inertial>
        <mass>1e-05</mass>
        <inertia>
          <ixx>0.001</ixx>
          <ixy>1e-06</ixy>
          <ixz>1e-06</ixz>
          <iyy>0.001</iyy>
          <iyz>1e-06</iyz>
          <izz>0.001</izz>
        </inertia>
      </inertial>
    </link>
    <joint name="front_right_foot" type="fixed">
      <child>front_right_ee</child>
      <parent>front_right_lower_leg</parent>
      <axis>
        <dynamics>
          <spring_reference>0</spring_reference>
          <spring_stiffness>0</spring_stiffness>
        </dynamics>
        <xyz>0 0 1</xyz>
        <use_parent_model_frame>0</use_parent_model_frame>
        <limit>
          <lower>-1e+16</lower>
          <upper>1e+16</upper>
        </limit>
      </axis>
      <physics>
        <ode>
          <limit>
            <cfm>0</cfm>
            <erp>0.2</erp>
          </limit>
        </ode>
      </physics>
    </joint>
    <link name="imu">
      <inertial>
        <mass>1e-05</mass>
        <inertia>
          <ixx>0.001</ixx>
          <ixy>1e-06</ixy>
          <ixz>1e-06</ixz>
          <iyy>0.001</iyy>
          <iyz>1e-06</iyz>
          <izz>0.001</izz>
        </inertia>
      </inertial>
      <sensor name="imu" type="imu">
        <always_on>1</always_on>
        <update_rate>50</update_rate>
        <imu>
          <enable_orientation>0</enable_orientation>
          <angular_velocity>
            <x>
              <noise type="gaussian">
                <mean>0</mean>
                <stddev>0.009</stddev>
                <bias_mean>0.00075</bias_mean>
                <bias_stddev>0.005</bias_stddev>
                <dynamic_bias_stddev>2e-05</dynamic_bias_stddev>
                <dynamic_bias_correlation_time>400</dynamic_bias_correlation_time>
                <precision>0.00025</precision>
              </noise>
            </x>
            <y>
              <noise type="gaussian">
                <mean>0</mean>
                <stddev>0.009</stddev>
                <bias_mean>0.00075</bias_mean>
                <bias_stddev>0.005</bias_stddev>
                <dynamic_bias_stddev>2e-05</dynamic_bias_stddev>
                <dynamic_bias_correlation_time>400</dynamic_bias_correlation_time>
                <precision>0.00025</precision>
              </noise>
            </y>
            <z>
              <noise type="gaussian">
                <mean>0</mean>
                <stddev>0.009</stddev>
                <bias_mean>0.00075</bias_mean>
                <bias_stddev>0.005</bias_stddev>
                <dynamic_bias_stddev>2e-05</dynamic_bias_stddev>
                <dynamic_bias_correlation_time>400</dynamic_bias_correlation_time>
                <precision>0.00025</precision>
              </noise>
            </z>
          </angular_velocity>
          <linear_acceleration>
            <x>
              <noise type="gaussian">
                <mean>0</mean>
                <stddev>0.021</stddev>
                <bias_mean>0.05</bias_mean>
                <bias_stddev>0.0075</bias_stddev>
                <dynamic_bias_stddev>0.000375</dynamic_bias_stddev>
                <dynamic_bias_correlation_time>175</dynamic_bias_correlation_time>
                <precision>0.005</precision>
              </noise>
            </x>
            <y>
              <noise type="gaussian">
                <mean>0</mean>
                <stddev>0.021</stddev>
                <bias_mean>0.05</bias_mean>
                <bias_stddev>0.0075</bias_stddev>
                <dynamic_bias_stddev>0.000375</dynamic_bias_stddev>
                <dynamic_bias_correlation_time>175</dynamic_bias_correlation_time>
                <precision>0.005</precision>
              </noise>
            </y>
            <z>
              <noise type="gaussian">
                <mean>0</mean>
                <stddev>0.021</stddev>
                <bias_mean>0.05</bias_mean>
                <bias_stddev>0.0075</bias_stddev>
                <dynamic_bias_stddev>0.000375</dynamic_bias_stddev>
                <dynamic_bias_correlation_time>175</dynamic_bias_correlation_time>
                <precision>0.005</precision>
              </noise>
            </z>
          </linear_acceleration>
        </imu>
      </sensor>
    </link>
    <joint name="imu_j" type="fixed">
      <child>imu</child>
      <parent>base_link</parent>
      <axis>
        <dynamics>
          <spring_reference>0</spring_reference>
          <spring_stiffness>0</spring_stiffness>
        </dynamics>
        <xyz>0 0 1</xyz>
        <use_parent_model_frame>0</use_parent_model_frame>
        <limit>
          <lower>-1e+16</lower>
          <upper>1e+16</upper>
        </limit>
      </axis>
      <physics>
        <ode>
          <limit>
            <cfm>0</cfm>
            <erp>0.2</erp>
          </limit>
        </ode>
      </physics>
    </joint>
    <link name="rear_left_hip">
      <pose>-0.29785 0.055 0 0 -0 0</pose>
      <inertial>
        <mass>2</mass>
        <inertia>
          <ixx>0.0027</ixx>
          <ixy>0</ixy>
          <ixz>0</ixz>
          <iyy>0.00416667</iyy>
          <iyz>0</iyz>
          <izz>0.00416667</izz>
        </inertia>
      </inertial>
      <collision name="rear_left_hip_collision">
        <geometry>
          <mesh>
            <uri>https://fuel.ignitionrobotics.org/1.0/OpenRobotics/models/BOSDYN_SPOT/tip/files/meshes/rear_left_hip_collision.stl</uri>
          </mesh>
        </geometry>
      </collision>
      <visual name="rear_left_hip_visual">
        <geometry>
          <mesh>
            <uri>https://fuel.ignitionrobotics.org/1.0/OpenRobotics/models/BOSDYN_SPOT/tip/files/meshes/rear_left_hip.dae</uri>
          </mesh>
        </geometry>
      </visual>
    </link>
    <joint name="rear_left_hip_x" type="revolute">
      <child>rear_left_hip</child>
      <parent>base_link</parent>
      <axis>
        <xyz>1 0 0</xyz>
        <limit>
          <lower>-0.785398</lower>
          <upper>0.785398</upper>
          <effort>80</effort>
          <velocity>15</velocity>
        </limit>
        <dynamics>
          <spring_reference>0</spring_reference>
          <spring_stiffness>0</spring_stiffness>
        </dynamics>
        <use_parent_model_frame>0</use_parent_model_frame>
      </axis>
    </joint>
    <link name="rear_left_upper_leg">
      <pose>-0.29785 0.165945 0 0 -0 0</pose>
      <inertial>
        <pose>0 0 -0.14 0 -0 0</pose>
        <mass>1</mass>
        <inertia>
          <ixx>0.0155334</ixx>
          <ixy>0</ixy>
          <ixz>0</ixz>
          <iyy>0.0155334</iyy>
          <iyz>0</iyz>
          <izz>0.000962667</izz>
        </inertia>
      </inertial>
      <collision name="rear_left_upper_leg_collision">
        <geometry>
          <mesh>
            <uri>https://fuel.ignitionrobotics.org/1.0/OpenRobotics/models/BOSDYN_SPOT/tip/files/meshes/rear_left_upper_leg_collision.stl</uri>
          </mesh>
        </geometry>
      </collision>
      <visual name="rear_left_upper_leg_visual">
        <geometry>
          <mesh>
            <uri>https://fuel.ignitionrobotics.org/1.0/OpenRobotics/models/BOSDYN_SPOT/tip/files/meshes/rear_left_upper_leg.dae</uri>
          </mesh>
        </geometry>
      </visual>
    </link>
    <joint name="rear_left_hip_y" type="revolute">
      <child>rear_left_upper_leg</child>
      <parent>rear_left_hip</parent>
      <axis>
        <xyz>0 1 0</xyz>
        <limit>
          <lower>-0.898845</lower>
          <upper>2.29511</upper>
          <effort>80</effort>
          <velocity>15</velocity>
        </limit>
        <dynamics>
          <spring_reference>0</spring_reference>
          <spring_stiffness>0</spring_stiffness>
        </dynamics>
        <use_parent_model_frame>0</use_parent_model_frame>
      </axis>
    </joint>
    <link name="rear_left_lower_leg">
      <pose>-0.27285 0.165945 -0.3205 0 -0 0</pose>
      <inertial>
        <pose>0 0 -0.16 0 -0 0</pose>
        <mass>0.5</mass>
        <inertia>
          <ixx>0.00743438</ixx>
          <ixy>0</ixy>
          <ixz>0</ixz>
          <iyy>0.00740104</iyy>
          <iyz>0</iyz>
          <izz>0.000135417</izz>
        </inertia>
      </inertial>
      <collision name="rear_left_lower_leg_collision">
        <geometry>
          <mesh>
            <scale>0.82 0.97 0.98</scale>
            <uri>https://fuel.ignitionrobotics.org/1.0/OpenRobotics/models/BOSDYN_SPOT/tip/files/meshes/rear_left_lower_leg_collision.stl</uri>
          </mesh>
        </geometry>
        <surface>
          <contact>
            <ode>
              <kp>1e+07</kp>
              <kd>100</kd>
            </ode>
          </contact>
          <friction>
            <ode>
              <mu>0.8</mu>
              <mu2>0.8</mu2>
            </ode>
          </friction>
        </surface>
      </collision>
      <collision name="rear_left_lower_leg_collision_1">
        <pose>0 0 -0.333 0 -0 0</pose>
        <geometry>
          <sphere>
            <radius>0.04</radius>
          </sphere>
        </geometry>
        <surface>
          <contact>
            <ode>
              <kp>1e+07</kp>
              <kd>100</kd>
            </ode>
          </contact>
          <friction>
            <ode>
              <mu>0.8</mu>
              <mu2>0.8</mu2>
            </ode>
          </friction>
        </surface>
      </collision>
      <visual name="rear_left_lower_leg_visual">
        <geometry>
          <mesh>
            <uri>https://fuel.ignitionrobotics.org/1.0/OpenRobotics/models/BOSDYN_SPOT/tip/files/meshes/rear_left_lower_leg.dae</uri>
          </mesh>
        </geometry>
        <material>
        </material>
      </visual>
      <sensor name="contact" type="contact">
        <contact>
          <collision>rear_left_lower_leg_collision</collision>
          <collision>rear_left_lower_leg_collision_1</collision>
          <topic>__default_topic__</topic>
        </contact>
      </sensor>
    </link>
    <joint name="rear_left_knee" type="revolute">
      <child>rear_left_lower_leg</child>
      <parent>rear_left_upper_leg</parent>
      <axis>
        <xyz>0 1 0</xyz>
        <limit>
          <lower>-2.7929</lower>
          <upper>-0.254801</upper>
          <effort>80</effort>
          <velocity>15</velocity>
        </limit>
        <dynamics>
          <spring_reference>0</spring_reference>
          <spring_stiffness>0</spring_stiffness>
        </dynamics>
        <use_parent_model_frame>0</use_parent_model_frame>
      </axis>
    </joint>
    <link name="rear_left_ee">
      <pose>-0.27285 0.165945 -0.6905 0 -0 0</pose>
      <inertial>
        <mass>1e-05</mass>
        <inertia>
          <ixx>0.001</ixx>
          <ixy>1e-06</ixy>
          <ixz>1e-06</ixz>
          <iyy>0.001</iyy>
          <iyz>1e-06</iyz>
          <izz>0.001</izz>
        </inertia>
      </inertial>
    </link>
    <joint name="rear_left_foot" type="fixed">
      <child>rear_left_ee</child>
      <parent>rear_left_lower_leg</parent>
      <axis>
        <dynamics>
          <spring_reference>0</spring_reference>
          <spring_stiffness>0</spring_stiffness>
        </dynamics>
        <xyz>0 0 1</xyz>
        <use_parent_model_frame>0</use_parent_model_frame>
        <limit>
          <lower>-1e+16</lower>
          <upper>1e+16</upper>
        </limit>
      </axis>
      <physics>
        <ode>
          <limit>
            <cfm>0</cfm>
            <erp>0.2</erp>
          </limit>
        </ode>
      </physics>
    </joint>
    <link name="rear_right_hip">
      <pose>-0.29785 -0.055 0 0 -0 0</pose>
      <inertial>
        <mass>2</mass>
        <inertia>
          <ixx>0.0027</ixx>
          <ixy>0</ixy>
          <ixz>0</ixz>
          <iyy>0.00416667</iyy>
          <iyz>0</iyz>
          <izz>0.00416667</izz>
        </inertia>
      </inertial>
      <collision name="rear_right_hip_collision">
        <geometry>
          <mesh>
            <uri>https://fuel.ignitionrobotics.org/1.0/OpenRobotics/models/BOSDYN_SPOT/tip/files/meshes/rear_right_hip_collision.stl</uri>
          </mesh>
        </geometry>
      </collision>
      <visual name="rear_right_hip_visual">
        <geometry>
          <mesh>
            <uri>https://fuel.ignitionrobotics.org/1.0/OpenRobotics/models/BOSDYN_SPOT/tip/files/meshes/rear_right_hip.dae</uri>
          </mesh>
        </geometry>
      </visual>
    </link>
    <joint name="rear_right_hip_x" type="revolute">
      <child>rear_right_hip</child>
      <parent>base_link</parent>
      <axis>
        <xyz>1 0 0</xyz>
        <limit>
          <lower>-0.785398</lower>
          <upper>0.785398</upper>
          <effort>80</effort>
          <velocity>15</velocity>
        </limit>
        <dynamics>
          <spring_reference>0</spring_reference>
          <spring_stiffness>0</spring_stiffness>
        </dynamics>
        <use_parent_model_frame>0</use_parent_model_frame>
      </axis>
    </joint>
    <link name="rear_right_upper_leg">
      <pose>-0.29785 -0.165945 0 0 -0 0</pose>
      <inertial>
        <pose>0 0 -0.14 0 -0 0</pose>
        <mass>1</mass>
        <inertia>
          <ixx>0.0155334</ixx>
          <ixy>0</ixy>
          <ixz>0</ixz>
          <iyy>0.0155334</iyy>
          <iyz>0</iyz>
          <izz>0.000962667</izz>
        </inertia>
      </inertial>
      <collision name="rear_right_upper_leg_collision">
        <geometry>
          <mesh>
            <uri>https://fuel.ignitionrobotics.org/1.0/OpenRobotics/models/BOSDYN_SPOT/tip/files/meshes/rear_right_upper_leg_collision.stl</uri>
          </mesh>
        </geometry>
      </collision>
      <visual name="rear_right_upper_leg_visual">
        <geometry>
          <mesh>
            <uri>https://fuel.ignitionrobotics.org/1.0/OpenRobotics/models/BOSDYN_SPOT/tip/files/meshes/rear_right_upper_leg.dae</uri>
          </mesh>
        </geometry>
      </visual>
    </link>
    <joint name="rear_right_hip_y" type="revolute">
      <child>rear_right_upper_leg</child>
      <parent>rear_right_hip</parent>
      <axis>
        <xyz>0 1 0</xyz>
        <limit>
          <lower>-0.898845</lower>
          <upper>2.29511</upper>
          <effort>80</effort>
          <velocity>15</velocity>
        </limit>
        <dynamics>
          <spring_reference>0</spring_reference>
          <spring_stiffness>0</spring_stiffness>
        </dynamics>
        <use_parent_model_frame>0</use_parent_model_frame>
      </axis>
    </joint>
    <link name="rear_right_lower_leg">
      <pose>-0.27285 -0.165945 -0.3205 0 -0 0</pose>
      <inertial>
        <pose>0 0 -0.16 0 -0 0</pose>
        <mass>0.5</mass>
        <inertia>
          <ixx>0.00743438</ixx>
          <ixy>0</ixy>
          <ixz>0</ixz>
          <iyy>0.00740104</iyy>
          <iyz>0</iyz>
          <izz>0.000135417</izz>
        </inertia>
      </inertial>
      <collision name="rear_right_lower_leg_collision">
        <geometry>
          <mesh>
            <scale>0.82 0.97 0.98</scale>
            <uri>https://fuel.ignitionrobotics.org/1.0/OpenRobotics/models/BOSDYN_SPOT/tip/files/meshes/rear_right_lower_leg_collision.stl</uri>
          </mesh>
        </geometry>
        <surface>
          <contact>
            <ode>
              <kp>1e+07</kp>
              <kd>100</kd>
            </ode>
          </contact>
          <friction>
            <ode>
              <mu>0.8</mu>
              <mu2>0.8</mu2>
            </ode>
          </friction>
        </surface>
      </collision>
      <collision name="rear_right_lower_leg_collision_1">
        <pose>0 0 -0.333 0 -0 0</pose>
        <geometry>
          <sphere>
            <radius>0.04</radius>
          </sphere>
        </geometry>
        <surface>
          <contact>
            <ode>
              <kp>1e+07</kp>
              <kd>100</kd>
            </ode>
          </contact>
          <friction>
            <ode>
              <mu>0.8</mu>
              <mu2>0.8</mu2>
            </ode>
          </friction>
        </surface>
      </collision>
      <visual name="rear_right_lower_leg_visual">
        <geometry>
          <mesh>
            <uri>https://fuel.ignitionrobotics.org/1.0/OpenRobotics/models/BOSDYN_SPOT/tip/files/meshes/rear_right_lower_leg.dae</uri>
          </mesh>
        </geometry>
        <material>
        </material>
      </visual>
      <sensor name="contact" type="contact">
        <contact>
          <collision>rear_right_lower_leg_collision</collision>
          <collision>rear_right_lower_leg_collision_1</collision>
          <topic>__default_topic__</topic>
        </contact>
      </sensor>
    </link>
    <joint name="rear_right_knee" type="revolute">
      <child>rear_right_lower_leg</child>
      <parent>rear_right_upper_leg</parent>
      <axis>
        <xyz>0 1 0</xyz>
        <limit>
          <lower>-2.7929</lower>
          <upper>-0.254801</upper>
          <effort>80</effort>
          <velocity>15</velocity>
        </limit>
        <dynamics>
          <spring_reference>0</spring_reference>
          <spring_stiffness>0</spring_stiffness>
        </dynamics>
        <use_parent_model_frame>0</use_parent_model_frame>
      </axis>
    </joint>
    <link name="rear_right_ee">
      <pose>-0.27285 -0.165945 -0.6905 0 -0 0</pose>
      <inertial>
        <mass>1e-05</mass>
        <inertia>
          <ixx>0.001</ixx>
          <ixy>1e-06</ixy>
          <ixz>1e-06</ixz>
          <iyy>0.001</iyy>
          <iyz>1e-06</iyz>
          <izz>0.001</izz>
        </inertia>
      </inertial>
    </link>
    <joint name="rear_right_foot" type="fixed">
      <child>rear_right_ee</child>
      <parent>rear_right_lower_leg</parent>
      <axis>
        <dynamics>
          <spring_reference>0</spring_reference>
          <spring_stiffness>0</spring_stiffness>
        </dynamics>
        <xyz>0 0 1</xyz>
        <use_parent_model_frame>0</use_parent_model_frame>
        <limit>
          <lower>-1e+16</lower>
          <upper>1e+16</upper>
        </limit>
      </axis>
      <physics>
        <ode>
          <limit>
            <cfm>0</cfm>
            <erp>0.2</erp>
          </limit>
        </ode>
      </physics>
    </joint>
  </model>
</sdf>

