<?xml version="1.0" ?>
<robot name="coro_allie_sensor_config_1">
  <joint name="coro_allie_sensor_config_1__front_left_wheel_joint" type="revolute">
    <parent link="coro_allie_sensor_config_1__base_link"/>
    <child link="coro_allie_sensor_config_1__front_left_wheel"/>
    <origin rpy="0 0 0" xyz="0.25   0.255  0.1275"/>
    <axis xyz="0 1 0"/>
    <limit effort="53.5" lower="-1.79769e+308" upper="1.79769e+308" velocity="13.65"/>
  </joint>
  <joint name="coro_allie_sensor_config_1__rear_left_wheel_joint" type="revolute">
    <parent link="coro_allie_sensor_config_1__base_link"/>
    <child link="coro_allie_sensor_config_1__rear_left_wheel"/>
    <origin rpy="0 0 0" xyz="-0.25    0.255   0.1275"/>
    <axis xyz="0 1 0"/>
    <limit effort="53.5" lower="-1.79769e+308" upper="1.79769e+308" velocity="13.65"/>
  </joint>
  <joint name="coro_allie_sensor_config_1__rear_right_wheel_joint" type="revolute">
    <parent link="coro_allie_sensor_config_1__base_link"/>
    <child link="coro_allie_sensor_config_1__rear_right_wheel"/>
    <origin rpy="0 0 0" xyz="-0.25   -0.255   0.1275"/>
    <axis xyz="0 1 0"/>
    <limit effort="53.5" lower="-1.79769e+308" upper="1.79769e+308" velocity="13.65"/>
  </joint>
  <joint name="coro_allie_sensor_config_1__front_right_wheel_joint" type="revolute">
    <parent link="coro_allie_sensor_config_1__base_link"/>
    <child link="coro_allie_sensor_config_1__front_right_wheel"/>
    <origin rpy="0 0 0" xyz="0.25   -0.255   0.1275"/>
    <axis xyz="0 1 0"/>
    <limit effort="53.5" lower="-1.79769e+308" upper="1.79769e+308" velocity="13.65"/>
  </joint>
  <link name="coro_allie_sensor_config_1__base_link">
    <inertial>
      <mass value="9.6"/>
      <origin rpy="0 0 0" xyz="0      0      0.07249"/>
      <inertia ixx="0.0512" ixy="0" ixz="0" iyy="0.07712" iyz="0" izz="0.11808"/>
    </inertial>
    <collision name="coro_allie_sensor_config_1__chassis_collision">
      <origin rpy="0 0 0" xyz="0     0     0.1675"/>
      <geometry>
        <box size="0.555 0.355 0.13"/>
      </geometry>
    </collision>
    <visual name="coro_allie_sensor_config_1__chassis_main_visual">
      <origin rpy="0 0 0" xyz="0     0     0.1775"/>
      <geometry>
        <box size="0.555 0.355 0.13"/>
      </geometry>
    </visual>
    <visual name="coro_allie_sensor_config_1__emergency_stop_bottom_visual">
      <origin rpy="0 0 0" xyz="0.2    0.15   0.2525"/>
      <geometry>
        <cylinder length="0.015" radius="0.015"/>
      </geometry>
    </visual>
    <visual name="coro_allie_sensor_config_1__emergency_stop_top_visual">
      <origin rpy="0 0 0" xyz="0.2    0.15   0.2625"/>
      <geometry>
        <cylinder length="0.005" radius="0.02"/>
      </geometry>
    </visual>
    <visual name="coro_allie_sensor_config_1__wheel_mount_front_visual">
      <origin rpy="0 0 0" xyz="0.249  0     0.1385"/>
      <geometry>
        <box size="0.05 0.5 0.05"/>
      </geometry>
    </visual>
    <visual name="coro_allie_sensor_config_1__wheel_mount_rear_visual">
      <origin rpy="0 0 0" xyz="-0.249   0      0.1385"/>
      <geometry>
        <box size="0.05 0.5 0.05"/>
      </geometry>
    </visual>
    <visual name="coro_allie_sensor_config_1__plate1_visual">
      <origin rpy="0 0 0" xyz="0.13   0     0.5475"/>
      <geometry>
        <box size="0.2 0.2 0.005"/>
      </geometry>
    </visual>
    <visual name="coro_allie_sensor_config_1__plate2_visual">
      <origin rpy="0 0 0" xyz="0.13   0     0.4375"/>
      <geometry>
        <box size="0.2 0.2 0.005"/>
      </geometry>
    </visual>
    <visual name="coro_allie_sensor_config_1__plate3_visual">
      <origin rpy="0 0 0" xyz="0.13   0     0.2475"/>
      <geometry>
        <box size="0.2 0.2 0.005"/>
      </geometry>
    </visual>
    <visual name="coro_allie_sensor_config_1__beam1_visual">
      <origin rpy="0 0 0" xyz="0.221  0.091  0.3975"/>
      <geometry>
        <box size="0.02 0.02 0.3"/>
      </geometry>
    </visual>
    <visual name="coro_allie_sensor_config_1__beam2_visual">
      <origin rpy="0 0 0" xyz="0.221  -0.091   0.3975"/>
      <geometry>
        <box size="0.02 0.02 0.3"/>
      </geometry>
    </visual>
    <visual name="coro_allie_sensor_config_1__beam3_visual">
      <origin rpy="0 0 0" xyz="0.039  0.091  0.3975"/>
      <geometry>
        <box size="0.02 0.02 0.3"/>
      </geometry>
    </visual>
    <visual name="coro_allie_sensor_config_1__beam4_visual">
      <origin rpy="0 0 0" xyz="0.039  -0.091   0.3975"/>
      <geometry>
        <box size="0.02 0.02 0.3"/>
      </geometry>
    </visual>
    <visual name="coro_allie_sensor_config_1__d435i_realsense_camera_visual">
      <origin rpy="0      0.52359 0" xyz="0.19    0      0.52049"/>
      <geometry>
        <mesh filename="package://coro_allie_sensor_config_1/meshes/realsense_d435.dae" scale="0.001 0.001 0.001"/>
      </geometry>
    </visual>
    <visual name="coro_allie_sensor_config_1__vlp16_visual1">
      <origin rpy="0 0 0" xyz="0.13   0     0.4395"/>
      <geometry>
        <mesh filename="package://coro_allie_sensor_config_1/meshes/VLP16_base_1.dae" scale="1 1 1"/>
      </geometry>
    </visual>
    <visual name="coro_allie_sensor_config_1__vlp_visual2">
      <origin rpy="0 0 0" xyz="0.13   0     0.4395"/>
      <geometry>
        <mesh filename="package://coro_allie_sensor_config_1/meshes/VLP16_base_2.dae" scale="1 1 1"/>
      </geometry>
    </visual>
    <visual name="coro_allie_sensor_config_1__vlp_visual3">
      <origin rpy="0 0 0" xyz="0.13   0     0.4395"/>
      <geometry>
        <mesh filename="package://coro_allie_sensor_config_1/meshes/VLP16_scan.dae" scale="1 1 1"/>
      </geometry>
    </visual>
    <visual name="coro_allie_sensor_config_1__camera_front_visual">
      <origin rpy="0 0 0" xyz="0.22   0.06   0.5325"/>
      <geometry>
        <box size="0.01 0.03 0.03"/>
      </geometry>
    </visual>
    <visual name="coro_allie_sensor_config_1__camera_lens_front_visual">
      <origin rpy="0      1.57079 0" xyz="0.23   0.06   0.5325"/>
      <geometry>
        <cylinder length="0.011" radius="0.005"/>
      </geometry>
    </visual>
    <visual name="coro_allie_sensor_config_1__camera_rear_visual">
      <origin rpy="0 0 0" xyz="0.04   0     0.5325"/>
      <geometry>
        <box size="0.01 0.03 0.03"/>
      </geometry>
    </visual>
    <visual name="coro_allie_sensor_config_1__camera_lens_rear_visual">
      <origin rpy="0      1.57079 0" xyz="0.03   0     0.5325"/>
      <geometry>
        <cylinder length="0.011" radius="0.005"/>
      </geometry>
    </visual>
    <visual name="coro_allie_sensor_config_1__camera_left_visual">
      <origin rpy="0 0 0" xyz="0.13   0.09   0.5325"/>
      <geometry>
        <box size="0.03 0.01 0.03"/>
      </geometry>
    </visual>
    <visual name="coro_allie_sensor_config_1__camera_lens_left_visual">
      <origin rpy="1.57079 0      0" xyz="0.13   0.1    0.5325"/>
      <geometry>
        <cylinder length="0.011" radius="0.005"/>
      </geometry>
    </visual>
    <visual name="coro_allie_sensor_config_1__camera_right_visual">
      <origin rpy="0 0 0" xyz="0.13   -0.09    0.5325"/>
      <geometry>
        <box size="0.03 0.01 0.03"/>
      </geometry>
    </visual>
    <visual name="coro_allie_sensor_config_1__camera_lens_right_visual">
      <origin rpy="1.57079 0      0" xyz="0.13   -0.1     0.5325"/>
      <geometry>
        <cylinder length="0.011" radius="0.005"/>
      </geometry>
    </visual>
    <visual name="coro_allie_sensor_config_1__light_front_visual">
      <origin rpy="0 0 0" xyz="0.22   0     0.5695"/>
      <geometry>
        <box size="0.04 0.13 0.04"/>
      </geometry>
    </visual>
    <visual name="coro_allie_sensor_config_1__light_rear_visual">
      <origin rpy="0 0 0" xyz="0.04   0     0.5675"/>
      <geometry>
        <box size="0.04 0.12 0.04"/>
      </geometry>
    </visual>
    <visual name="coro_allie_sensor_config_1__light_left_visual">
      <origin rpy="0 0 0" xyz="0.13   0.09   0.5695"/>
      <geometry>
        <box size="0.12 0.04 0.04"/>
      </geometry>
    </visual>
    <visual name="coro_allie_sensor_config_1__light_right_visual">
      <origin rpy="0 0 0" xyz="0.13   -0.09    0.5695"/>
      <geometry>
        <box size="0.12 0.04 0.04"/>
      </geometry>
    </visual>
  </link>
  <link name="coro_allie_sensor_config_1__front_left_wheel">
    <inertial>
      <mass value="5.0"/>
      <origin rpy="0 0 0" xyz="0 0 0"/>
      <inertia ixx="0.0153" ixy="0" ixz="0" iyy="0.025" iyz="0" izz="0.0153"/>
    </inertial>
    <collision name="coro_allie_sensor_config_1__front_left_wheel_collision">
      <origin rpy="-1.57079  0       0" xyz="0 0 0"/>
      <geometry>
        <cylinder length="0.11" radius="0.205"/>
      </geometry>
    </collision>
    <visual name="coro_allie_sensor_config_1__front_left_wheel_tire_visual">
      <origin rpy="0 0 0" xyz="0 0 0"/>
      <geometry>
        <mesh filename="package://coro_allie_sensor_config_1/meshes/wheel.dae" scale="1.18 1.0 1.18"/>
      </geometry>
    </visual>
  </link>
  <link name="coro_allie_sensor_config_1__front_right_wheel">
    <inertial>
      <mass value="5.0"/>
      <origin rpy="0 0 0" xyz="0 0 0"/>
      <inertia ixx="0.0153" ixy="0" ixz="0" iyy="0.025" iyz="0" izz="0.0153"/>
    </inertial>
    <collision name="coro_allie_sensor_config_1__front_right_wheel_collision">
      <origin rpy="1.57079 0      0" xyz="0 0 0"/>
      <geometry>
        <cylinder length="0.11" radius="0.205"/>
      </geometry>
    </collision>
    <visual name="coro_allie_sensor_config_1__front_right_wheel_tire_visual">
      <origin rpy="0 0 0" xyz="0 0 0"/>
      <geometry>
        <mesh filename="package://coro_allie_sensor_config_1/meshes/wheel.dae" scale="1.18 1.0 1.18"/>
      </geometry>
    </visual>
  </link>
  <link name="coro_allie_sensor_config_1__rear_left_wheel">
    <inertial>
      <mass value="5.0"/>
      <origin rpy="0 0 0" xyz="0 0 0"/>
      <inertia ixx="0.0153" ixy="0" ixz="0" iyy="0.025" iyz="0" izz="0.0153"/>
    </inertial>
    <collision name="coro_allie_sensor_config_1__rear_left_wheel_collision">
      <origin rpy="-1.57079  0       0" xyz="0 0 0"/>
      <geometry>
        <cylinder length="0.11" radius="0.205"/>
      </geometry>
    </collision>
    <visual name="coro_allie_sensor_config_1__rear_left_wheel_tire_visual">
      <origin rpy="0 0 0" xyz="0 0 0"/>
      <geometry>
        <mesh filename="package://coro_allie_sensor_config_1/meshes/wheel.dae" scale="1.18 1.0 1.18"/>
      </geometry>
    </visual>
  </link>
  <link name="coro_allie_sensor_config_1__rear_right_wheel">
    <inertial>
      <mass value="5.0"/>
      <origin rpy="0 0 0" xyz="0 0 0"/>
      <inertia ixx="0.0153" ixy="0" ixz="0" iyy="0.025" iyz="0" izz="0.0153"/>
    </inertial>
    <collision name="coro_allie_sensor_config_1__rear_right_wheel_collision">
      <origin rpy="1.57079 0      0" xyz="0 0 0"/>
      <geometry>
        <cylinder length="0.11" radius="0.205"/>
      </geometry>
    </collision>
    <visual name="coro_allie_sensor_config_1__rear_right_wheel_tire_visual">
      <origin rpy="0 0 0" xyz="0 0 0"/>
      <geometry>
        <mesh filename="package://coro_allie_sensor_config_1/meshes/wheel.dae" scale="1.18 1.0 1.18"/>
      </geometry>
    </visual>
  </link>
</robot>
