<?xml version='1.0' encoding='utf-8'?>
<robot name='X4'>
  <link name='base_link'>
    <inertial>
      <origin xyz='0 0 0' rpy='0 -0 0'/>
      <mass value='3.42'/>
      <inertia ixx='0.075' ixy='0' ixz='0' iyy='0.075' iyz='0' izz='0.148916'/>
    </inertial>
    <collision name='base_link_inertia_collision'>
      <origin xyz='0 0 0' rpy='0 -0 0'/>
      <geometry>
        <box size='0.3 0.3 0.25'/>
      </geometry>
    </collision>
    <visual name='base_link_inertia_visual'>
      <origin xyz='0 0 0' rpy='0 -0 0'/>
      <geometry>
        <mesh filename='meshes/x4.dae' scale='1 1 1'/>
      </geometry>
    </visual>
    <visual name='marker_visual_1'>
      <origin xyz='-0.1 0 0.077' rpy='0 -0.1 0'/>
      <geometry>
        <mesh filename='meshes/led.dae' scale='1 1 1'/>
      </geometry>
    </visual>
    <visual name='marker_visual_2'>
      <origin xyz='-0.09 0.059 0.059' rpy='-0.785397 -0 0.2'/>
      <geometry>
        <mesh filename='meshes/led.dae' scale='1 1 1'/>
      </geometry>
    </visual>
    <visual name='marker_visual_3'>
      <origin xyz='-0.09 -0.059 0.059' rpy='0.785397 -0 -0.2'/>
      <geometry>
        <mesh filename='meshes/led.dae' scale='1 1 1'/>
      </geometry>
    </visual>
    <visual name='downward_flashlight_visual'>
      <origin xyz='-0.043704 0 0.102914' rpy='-0.2 0.000158 -1.57002'/>
      <geometry>
        <mesh filename='meshes/spotlight.dae' scale='0.01 0.01 0.01'/>
      </geometry>
    </visual>
    <visual name='left_flashlight_visual'>
      <origin xyz='-0.071985 0.090826 0.066102' rpy='0.06 -4.8e-05 -1.27'/>
      <geometry>
        <mesh filename='meshes/spotlight.dae' scale='0.01 0.01 0.01'/>
      </geometry>
    </visual>
    <visual name='right_flashlight_visual'>
      <origin xyz='-0.071985 -0.090826 0.066102' rpy='0.06 -4.8e-05 -1.87'/>
      <geometry>
        <mesh filename='meshes/spotlight.dae' scale='0.01 0.01 0.01'/>
      </geometry>
    </visual>
    <visual name='camera_mount_base_visual'>
      <origin xyz='0.05 0 -0.03' rpy='0 -0 0'/>
      <geometry>
        <box size='0.06 0.06 0.006'/>
      </geometry>
    </visual>
    <visual name='camera_mount_arm_visual'>
      <origin xyz='0.08 0 -0.04' rpy='0 -0 0'/>
      <geometry>
        <cylinder radius='0.005' length='0.08'/>
      </geometry>
    </visual>
    <visual name='camera_mount_arm2_visual'>
      <origin xyz='0.08 0 -0.08' rpy='0 1.57 0'/>
      <geometry>
        <cylinder radius='0.01' length='0.025'/>
      </geometry>
    </visual>
    <visual name='camera_visual'>
      <origin xyz='0.1 0 -0.08' rpy='0 -0 0'/>
      <geometry>
        <box size='0.02 0.025 0.025'/>
      </geometry>
    </visual>
    <visual name='laser_visual'>
      <origin xyz='0.08 0 0.3' rpy='0 -0 0'/>
      <geometry>
        <cylinder radius='0.03' length='0.1'/>
      </geometry>
    </visual>
  </link>
  <sensor name='imu_sensor' update_rate='250'>
    <parent link='base_link'/>
    <origin xyz='0 0 0' rpy='0 -0 0'/>
  </sensor>
  <sensor name='air_pressure' update_rate='20'>
    <parent link='base_link'/>
    <origin xyz='0 0 0' rpy='0 -0 0'/>
  </sensor>
  <sensor name='magnetometer' update_rate='20'>
    <parent link='base_link'/>
    <origin xyz='0 0 0' rpy='0 -0 0'/>
  </sensor>
  <sensor name='camera_front' update_rate='20'>
    <parent link='base_link'/>
    <origin xyz='0.1 0 -0.08' rpy='0 -0 0'/>
    <camera>
      <image width='1280' height='960' format='R8G8B8' hfov='1.0472' near='0.02' far='300' />
    </camera>
  </sensor>
  <sensor name='front_laser' update_rate='15'>
    <parent link='base_link'/>
    <origin xyz='0.08 0 0.394' rpy='0 -0 0'/>
  </sensor>
  <link name='rotor_0'>
    <inertial>
      <origin xyz='0 0 0' rpy='0 -0 0'/>
      <mass value='0.005'/>
      <inertia ixx='9.75e-07' ixy='0' ixz='0' iyy='8.13545e-05' iyz='0' izz='8.22545e-05'/>
    </inertial>
    <collision name='rotor_0_collision'>
      <origin xyz='0 0 0' rpy='0 -0 0'/>
      <geometry>
        <cylinder radius='0.1397' length='0.005'/>
      </geometry>
    </collision>
    <visual name='rotor_0_visual'>
      <origin xyz='0 0 0' rpy='0 -0 0'/>
      <geometry>
        <mesh filename='meshes/neo11_propeller_ccw.dae' scale='1 1 1'/>
      </geometry>
    </visual>
  </link>
  <link name='rotor_1'>
    <inertial>
      <origin xyz='0 0 0' rpy='0 -0 0'/>
      <mass value='0.005'/>
      <inertia ixx='9.75e-07' ixy='0' ixz='0' iyy='8.13545e-05' iyz='0' izz='8.22545e-05'/>
    </inertial>
    <collision name='rotor_1_collision'>
      <origin xyz='0 0 0' rpy='0 -0 0'/>
      <geometry>
        <cylinder radius='0.1397' length='0.005'/>
      </geometry>
    </collision>
    <visual name='rotor_1_visual'>
      <origin xyz='0 0 0' rpy='0 -0 0'/>
      <geometry>
        <mesh filename='meshes/neo11_propeller_cw.dae' scale='1 1 1'/>
      </geometry>
    </visual>
  </link>
  <link name='rotor_2'>
    <inertial>
      <origin xyz='0 0 0' rpy='0 -0 0'/>
      <mass value='0.005'/>
      <inertia ixx='9.75e-07' ixy='0' ixz='0' iyy='8.13545e-05' iyz='0' izz='8.22545e-05'/>
    </inertial>
    <collision name='rotor_2_collision'>
      <origin xyz='0 0 0' rpy='0 -0 0'/>
      <geometry>
        <cylinder radius='0.1397' length='0.005'/>
      </geometry>
    </collision>
    <visual name='rotor_2_visual'>
      <origin xyz='0 0 0' rpy='0 -0 0'/>
      <geometry>
        <mesh filename='meshes/neo11_propeller_ccw.dae' scale='1 1 1'/>
      </geometry>
    </visual>
  </link>
  <link name='rotor_3'>
    <inertial>
      <origin xyz='0 0 0' rpy='0 -0 0'/>
      <mass value='0.005'/>
      <inertia ixx='9.75e-07' ixy='0' ixz='0' iyy='8.13545e-05' iyz='0' izz='8.22545e-05'/>
    </inertial>
    <collision name='rotor_3_collision'>
      <origin xyz='0 0 0' rpy='0 -0 0'/>
      <geometry>
        <cylinder radius='0.1397' length='0.005'/>
      </geometry>
    </collision>
    <visual name='rotor_3_visual'>
      <origin xyz='0 0 0' rpy='0 -0 0'/>
      <geometry>
        <mesh filename='meshes/neo11_propeller_cw.dae' scale='1 1 1'/>
      </geometry>
    </visual>
  </link>
  <link name='rotor_4'>
    <inertial>
      <origin xyz='0 0 0' rpy='-0 -0 -0'/>
      <mass value='0.005'/>
      <inertia ixx='9.75e-07' ixy='0' ixz='0' iyy='8.13545e-05' iyz='0' izz='8.22545e-05'/>
    </inertial>
    <collision name='rotor_4_collision'>
      <origin xyz='0 0 0' rpy='-0 -0 -0'/>
      <geometry>
        <cylinder radius='0.1397' length='0.005'/>
      </geometry>
    </collision>
    <visual name='rotor_4_visual'>
      <origin xyz='0 0 0' rpy='-0 -0 -0'/>
      <geometry>
        <mesh filename='meshes/neo11_propeller_ccw.dae' scale='1 1 1'/>
      </geometry>
    </visual>
  </link>
  <link name='rotor_5'>
    <inertial>
      <origin xyz='0 0 0' rpy='0 -0 0'/>
      <mass value='0.005'/>
      <inertia ixx='9.75e-07' ixy='0' ixz='0' iyy='8.13545e-05' iyz='0' izz='8.22545e-05'/>
    </inertial>
    <collision name='rotor_5_collision'>
      <origin xyz='0 0 0' rpy='0 -0 0'/>
      <geometry>
        <cylinder radius='0.1397' length='0.005'/>
      </geometry>
    </collision>
    <visual name='rotor_5_visual'>
      <origin xyz='0 0 0' rpy='0 -0 0'/>
      <geometry>
        <mesh filename='meshes/neo11_propeller_cw.dae' scale='1 1 1'/>
      </geometry>
    </visual>
  </link>
  <joint name='rotor_0_joint' type='revolute'>
    <origin xyz='0.247 0.1506 0.028' rpy='0.087267 0 0.523599'/>
    <parent link='base_link'/>
    <child link='rotor_0'/>
    <dynamics damping='0' friction='0' />
    <axis xyz='0.118748 -0.118521 0.985826'/>
    <limit lower='-1e+16' upper='1e+16' effort='-1' velocity='-1'/>
  </joint>
  <joint name='rotor_1_joint' type='revolute'>
    <origin xyz='-0.00067 0.28929 0.028' rpy='0 -0.087267 0'/>
    <parent link='base_link'/>
    <child link='rotor_1'/>
    <dynamics damping='0' friction='0' />
    <axis xyz='-0.173649 0 0.984808'/>
    <limit lower='-1e+16' upper='1e+16' effort='-1' velocity='-1'/>
  </joint>
  <joint name='rotor_2_joint' type='revolute'>
    <origin xyz='-0.2501 0.1454 0.028' rpy='0.087267 -0 2.61799'/>
    <parent link='base_link'/>
    <child link='rotor_2'/>
    <dynamics damping='0' friction='0' />
    <axis xyz='-0.031923 0.031863 0.998983'/>
    <limit lower='-1e+16' upper='1e+16' effort='-1' velocity='-1'/>
  </joint>
  <joint name='rotor_3_joint' type='revolute'>
    <origin xyz='-0.2501 -0.1454 0.028' rpy='-0.087267 -0 -2.61799'/>
    <parent link='base_link'/>
    <child link='rotor_3'/>
    <dynamics damping='0' friction='0' />
    <axis xyz='-0.031923 -0.031863 0.998983'/>
    <limit lower='-1e+16' upper='1e+16' effort='-1' velocity='-1'/>
  </joint>
  <joint name='rotor_4_joint' type='revolute'>
    <origin xyz='-0.00067 -0.28929 0.028' rpy='-0 0.087267 -3.14159'/>
    <parent link='base_link'/>
    <child link='rotor_4'/>
    <dynamics damping='0' friction='0' />
    <axis xyz='-0 -0 1'/>
    <limit lower='-1e+16' upper='1e+16' effort='-1' velocity='-1'/>
  </joint>
  <joint name='rotor_5_joint' type='revolute'>
    <origin xyz='0.247 -0.1506 0.028' rpy='-0.087267 0 -0.523599'/>
    <parent link='base_link'/>
    <child link='rotor_5'/>
    <dynamics damping='0' friction='0' />
    <axis xyz='0.118748 0.118521 0.985826'/>
    <limit lower='-1e+16' upper='1e+16' effort='-1' velocity='-1'/>
  </joint>
</robot>
