<?xml version='1.0' encoding='utf-8'?>
<sdf version="1.6">
  <model name="costar_husky_sensor_config_2">
    <link name="base_link">
      <pose frame="">0 0 0 0 -0 0</pose>
      <inertial>
        <pose frame="">0 0 0.062329 0 -0 0</pose>
        <mass>46.064</mass>
        <inertia>
          <ixx>0.615397</ixx>
          <ixy>-0.0240585</ixy>
          <ixz>-0.120749</ixz>
          <iyy>1.75388</iyy>
          <iyz>-0.0028322</iyz>
          <izz>2.03641</izz>
        </inertia>
      </inertial>
      <collision name="base_link_collision">
        <pose frame="">0 0 0.12 0 0 0</pose>
        <geometry>
          <box>
            <size>0.9874 0.5709 0.05</size>
          </box>
        </geometry>
      </collision>
      <collision name="base_link_collision_bottom">
        <pose frame="">0 0 0.046 0 0 0</pose>
        <geometry>
          <box>
            <size>0.80 0.5709 0.095</size>
          </box>
        </geometry>
      </collision>
      <collision name="base_link_collision_1">
        <pose frame="">0 0 0.185625 0 -0 0</pose>
        <geometry>
          <box>
            <size>0.78992 0.5709 0.12375</size>
          </box>
        </geometry>
      </collision>
      <collision name="base_link_fixed_joint_lump__camera/camera_link_collision_2">
        <pose frame="">0.488 0 0.272 0 -0 0</pose>
        <geometry>
          <box>
            <size>0.0078 0.13 0.0192</size>
          </box>
        </geometry>
        <surface>
          <contact>
            <ode>
              <kp>1e+13</kp>
              <kd>1</kd>
            </ode>
          </contact>
          <friction>
            <ode>
              <mu2>1</mu2>
              <fdir1>0 0 0</fdir1>
            </ode>
          </friction>
        </surface>
      </collision>
      <collision name="base_link_fixed_joint_lump__top_plate_link_collision_3">
        <pose frame="">0.0812 0 0.245 0 -0 0</pose>
        <geometry>
          <mesh>
            <scale>1 1 1</scale>
            <uri>meshes/top_plate.dae</uri>
          </mesh>
        </geometry>
      </collision>
      <collision name="base_link_fixed_joint_lump__top_plate_link_collision_4">
        <pose frame="">0.0812 0 0.245 0 -0 0</pose>
        <geometry>
          <box>
            <size>0.32 0.41 0.09</size>
          </box>
        </geometry>
      </collision>
      <collision name="base_link_fixed_joint_lump__velodyne_base_link_collision_5">
        <pose frame="">0.0012 0 0.71415 0 -0 0</pose>
        <geometry>
          <cylinder>
            <length>0.0717</length>
            <radius>0.0516</radius>
          </cylinder>
        </geometry>
      </collision>
      <visual name="base_link_visual">
        <pose frame="">0 0 0 0 -0 0</pose>
        <geometry>
          <mesh>
            <scale>1 1 1</scale>
            <uri>meshes/base_link.dae</uri>
          </mesh>
        </geometry>
      </visual>
      <visual name="base_link_fixed_joint_lump__camera/camera_link_visual_1">
        <pose frame="">0.438 0 0.272 0 -0 0</pose>
        <geometry>
          <mesh>
            <uri>meshes/realsense.dae</uri>
          </mesh>
        </geometry>
      </visual>
      <visual name="base_link_fixed_joint_lump__cliff_sensor_link_visual_2">
        <pose frame="">0.435 0 0.235 -2.35619 -0 -1.5708</pose>
        <geometry>
          <cylinder>
            <length>0.02</length>
            <radius>0.005</radius>
          </cylinder>
        </geometry>
      </visual>
      <visual name="base_link_fixed_joint_lump__front_bumper_link_visual_3">
        <pose frame="">0.48 0 0.091 0 -0 0</pose>
        <geometry>
          <mesh>
            <scale>1 1 1</scale>
            <uri>meshes/bumper.dae</uri>
          </mesh>
        </geometry>
      </visual>
      <visual name="base_link_fixed_joint_lump__rear_bumper_link_visual_4">
        <pose frame="">-0.48 0 0.091 0 -0 3.14159</pose>
        <geometry>
          <mesh>
            <scale>1 1 1</scale>
            <uri>meshes/bumper.dae</uri>
          </mesh>
        </geometry>
      </visual>
      <visual name="base_link_fixed_joint_lump__top_chassis_link_visual_5">
        <pose frame="">0 0 0 0 -0 0</pose>
        <geometry>
          <mesh>
            <scale>1 1 1</scale>
            <uri>meshes/top_chassis.dae</uri>
          </mesh>
        </geometry>
      </visual>
      <visual name="base_link_fixed_joint_lump__top_plate_link_visual_6">
        <pose frame="">0.0812 0 0.245 0 -0 0</pose>
        <geometry>
          <mesh>
            <scale>1 1 1</scale>
            <uri>meshes/top_plate.dae</uri>
          </mesh>
        </geometry>
      </visual>
      <visual name="base_link_fixed_joint_lump__arch_visual_7">
        <pose frame="">0.0012 0 0.251 0 -0 0</pose>
        <geometry>
          <mesh>
            <scale>1 1 1</scale>
            <uri>meshes/jpl04_arch_nosensor.stl</uri>
          </mesh>
        </geometry>
        <material>
          <ambient>0.8 0.8 0.8 1</ambient>
          <diffuse>0.45 0.45 0.45 1</diffuse>
          <specular>0.8 0.8 0.8 1.0</specular>
        </material>
      </visual>
      <visual name="base_link_fixed_joint_lump__velodyne_base_link_visual_10">
        <pose frame="">0.0012 0 0.6783 0 -0 0</pose>
        <geometry>
          <mesh>
            <scale>1 1 1</scale>
            <uri>meshes/VLP16_base_1.dae</uri>
          </mesh>
        </geometry>
      </visual>
      <visual name="base_link_fixed_joint_lump__velodyne_base_link_visual_11">
        <pose frame="">0.0012 0 0.6783 0 -0 0</pose>
        <geometry>
          <mesh>
            <scale>1 1 1</scale>
            <uri>meshes/VLP16_base_2.dae</uri>
          </mesh>
        </geometry>
      </visual>
      <visual name="base_link_fixed_joint_lump__velodyne_visual_12">
        <pose frame="">0.0012 0 0.6783 0 -0 0</pose>
        <geometry>
          <mesh>
            <scale>1 1 1</scale>
            <uri>meshes/VLP16_scan.dae</uri>
          </mesh>
        </geometry>
      </visual>
      <visual name="base_link_fixed_joint_lump__user_rail_link_visual_13">
        <pose frame="">0.272 0 0.245 0 -0 0</pose>
        <geometry>
          <mesh>
            <scale>1 1 1</scale>
            <uri>meshes/user_rail.dae</uri>
          </mesh>
        </geometry>
      </visual>
      <velocity_decay/>
      <self_collide>0</self_collide>
      <enable_wind>0</enable_wind>
      <kinematic>0</kinematic>
      <sensor name="camera_front" type="rgbd_camera">
        <camera name="camera_front">
            <horizontal_fov>1.0472</horizontal_fov>
            <lens>
                <intrinsics>
                    <!-- fx = fy = width / ( 2 * tan (hfov / 2 ) ) -->
                    <fx>277.1</fx>
                    <fy>277.1</fy>
                    <!-- cx = ( width + 1 ) / 2 -->
                    <cx>160.5</cx>
                    <!-- cy = ( height + 1 ) / 2 -->
                    <cy>120.5</cy>
                    <s>0</s>
                </intrinsics>
            </lens>
            <distortion>
                <k1>0.0</k1>
                <k2>0.0</k2>
                <k3>0.0</k3>
                <p1>0.0</p1>
                <p2>0.0</p2>
                <center>0.5 0.5</center>
            </distortion>
            <image>
                <width>320</width>
                <height>240</height>
                <format>R8G8B8</format>
            </image>
            <clip>
                <near>0.01</near>
                <far>300</far>
            </clip>
            <depth_camera>
              <clip>
                <near>0.1</near>
                <far>10</far>
              </clip>
            </depth_camera>
            <noise>
                <type>gaussian</type>
                <mean>0</mean>
                <stddev>0.007</stddev>
            </noise>
        </camera>
        <always_on>1</always_on>
        <update_rate>20</update_rate>
        <visualize>0</visualize>
        <pose frame="">0.438 0 0.272 0 -0 0</pose>
      </sensor>
      <gravity>1</gravity>
      <velocity_decay/>
      <sensor name="front_cliff_laser" type="gpu_ray">
          <pose>0.435 0 0.235 0 -2.4434589 0</pose>
          <update_rate>50</update_rate>
          <lidar>
              <scan>
                  <horizontal>
                      <samples>1</samples>
                      <resolution>1</resolution>
                      <min_angle>3.141592653589793</min_angle>
                      <max_angle>3.141592653589793</max_angle>
                  </horizontal>
              </scan>
              <range>
                  <min>0.04</min>
                  <max>40</max>
                  <resolution>0.01</resolution>
              </range>
              <noise>
                  <type>gaussian</type>
                  <mean>0</mean>
                  <stddev>0.01</stddev>
              </noise>
          </lidar>
      </sensor>
      <gravity>1</gravity>
      <velocity_decay/>
      <sensor name="front_laser" type="gpu_lidar">
        <visualize>0</visualize>
        <update_rate>10</update_rate>
        <lidar>
          <scan>
            <horizontal>
              <samples>1800</samples>
              <resolution>1</resolution>
              <min_angle>-3.14159</min_angle>
              <max_angle>3.14159</max_angle>
            </horizontal>
            <vertical>
              <samples>16</samples>
              <resolution>1</resolution>
              <min_angle>-0.261799</min_angle>
              <max_angle>0.261799</max_angle>
            </vertical>
          </scan>
          <range>
            <min>0.05</min>
            <max>100</max>
            <resolution>0.01</resolution>
          </range>
          <noise>
            <type>gaussian</type>
            <mean>0</mean>
            <stddev>0.01</stddev>
          </noise>
        </lidar>
        <pose frame="">0.0012 0 0.716 0 -0 0</pose>
      </sensor>
      <light name="flashlight_flashlight_light_source_lamp_light" type="spot">
        <pose frame="">0.48 0.08 0.12 3.141592653589793 1.5707926535897934 -0.0015926535897931</pose>
        <attenuation>
          <range>50</range>
          <linear>0</linear>
          <constant>0.1</constant>
          <quadratic>0.0025</quadratic>
        </attenuation>
        <diffuse>0.8 0.8 0.5 1</diffuse>
        <specular>0.8 0.8 0.5 1</specular>
        <spot>
          <inner_angle>1.2</inner_angle>
          <outer_angle>1.3</outer_angle>
          <falloff>1</falloff>
        </spot>
        <direction>0 0 -1</direction>
      </light>
      <visual name="flashlight_flashlight_light_source_lamp_viz_visual">
        <pose>0.48 0.08 0.12 3.141592653589793 1.5707926535897934 -0.0015926535897931</pose>
        <geometry>
          <cylinder>
            <radius>0.019</radius>
            <length>0.005</length>
          </cylinder>
        </geometry>
        <transparency>0</transparency>
        <material>
          <ambient>1 1 1 1</ambient>
          <diffuse>1 1 1 1</diffuse>
          <specular>1 1 1 1</specular>
          <emissive>1 1 1 1</emissive>
        </material>
      </visual>

      <sensor name="imu_sensor" type="imu">
        <always_on>1</always_on>
        <update_rate>50</update_rate>
        <imu>
                    <angular_velocity>
                        <x>
                            <noise type="gaussian">
                                <mean>0</mean>
                                <stddev>0.009</stddev>
                                <bias_mean>0.00075</bias_mean>
                                <bias_stddev>0.005</bias_stddev>
                                <dynamic_bias_stddev>0.00002</dynamic_bias_stddev>
                                <dynamic_bias_correlation_time>400.0</dynamic_bias_correlation_time>
                                <precision>0.00025</precision>
                            </noise>
                        </x>
                        <y>
                            <noise type="gaussian">
                                <mean>0</mean>
                                <stddev>0.009</stddev>
                                <bias_mean>0.00075</bias_mean>
                                <bias_stddev>0.005</bias_stddev>
                                <dynamic_bias_stddev>0.00002</dynamic_bias_stddev>
                                <dynamic_bias_correlation_time>400.0</dynamic_bias_correlation_time>
                                <precision>0.00025</precision>
                            </noise>
                        </y>
                        <z>
                            <noise type="gaussian">
                                <mean>0</mean>
                                <stddev>0.009</stddev>
                                <bias_mean>0.00075</bias_mean>
                                <bias_stddev>0.005</bias_stddev>
                                <dynamic_bias_stddev>0.00002</dynamic_bias_stddev>
                                <dynamic_bias_correlation_time>400.0</dynamic_bias_correlation_time>
                                <precision>0.00025</precision>
                            </noise>
                        </z>
                    </angular_velocity>
                    <linear_acceleration>
                        <x>
                            <noise type="gaussian">
                                <mean>0</mean>
                                <stddev>0.021</stddev>
                                <bias_mean>0.05</bias_mean>
                                <bias_stddev>0.0075</bias_stddev>
                                <dynamic_bias_stddev>0.000375</dynamic_bias_stddev>
                                <dynamic_bias_correlation_time>175.0</dynamic_bias_correlation_time>
                                <precision>0.005</precision>
                            </noise>
                        </x>
                        <y>
                            <noise type="gaussian">
                                <mean>0</mean>
                                <stddev>0.021</stddev>
                                <bias_mean>0.05</bias_mean>
                                <bias_stddev>0.0075</bias_stddev>
                                <dynamic_bias_stddev>0.000375</dynamic_bias_stddev>
                                <dynamic_bias_correlation_time>175.0</dynamic_bias_correlation_time>
                                <precision>0.005</precision>
                            </noise>
                        </y>
                        <z>
                            <noise type="gaussian">
                                <mean>0</mean>
                                <stddev>0.021</stddev>
                                <bias_mean>0.05</bias_mean>
                                <bias_stddev>0.0075</bias_stddev>
                                <dynamic_bias_stddev>0.000375</dynamic_bias_stddev>
                                <dynamic_bias_correlation_time>175.0</dynamic_bias_correlation_time>
                                <precision>0.005</precision>
                            </noise>
                        </z>
                    </linear_acceleration>
                </imu>
      </sensor>
    </link>
    <link name="front_left_wheel_link">
      <pose frame="">0.256 0.2854 0.03282 0 -0 0</pose>
      <inertial>
        <pose frame="">0 0 0 0 -0 0</pose>
        <mass>2.637</mass>
        <inertia>
          <ixx>0.02467</ixx>
          <ixy>0</ixy>
          <ixz>0</ixz>
          <iyy>0.04411</iyy>
          <iyz>0</iyz>
          <izz>0.02467</izz>
        </inertia>
      </inertial>
      <collision name="front_left_wheel_link_collision">
        <pose frame="">0 0 0 1.5707963267948966 -0 0</pose>
        <geometry>
          <cylinder>
            <length>0.1143</length>
            <radius>0.1651</radius>
          </cylinder>
        </geometry>
        <surface>
          <contact>
            <ode>
              <kp>1e+07</kp>
              <kd>1</kd>
            </ode>
          </contact>
          <friction>
            <ode>
              <mu>0.5</mu>
              <mu2>1</mu2>
              <slip1>0.00062</slip1>
              <slip2>0</slip2>
              <fdir1>0 0 1</fdir1>
            </ode>
          </friction>
        </surface>
      </collision>
      <visual name="front_left_wheel_link_visual">
        <pose frame="">0 0 0 0 -0 0</pose>
        <geometry>
          <mesh>
            <scale>1 1 1</scale>
            <uri>meshes/wheel.dae</uri>
          </mesh>
        </geometry>
      </visual>
      <gravity>1</gravity>
      <velocity_decay/>
    </link>
    <joint name="front_left_wheel_joint" type="revolute">
      <child>front_left_wheel_link</child>
      <parent>base_link</parent>
      <axis>
        <xyz>0 1 0</xyz>
        <limit>
          <lower>-1e+16</lower>
          <upper>1e+16</upper>
        </limit>
        <dynamics>
          <spring_reference>0</spring_reference>
          <spring_stiffness>0</spring_stiffness>
        </dynamics>
        <use_parent_model_frame>1</use_parent_model_frame>
      </axis>
    </joint>
    <link name="front_right_wheel_link">
      <pose frame="">0.256 -0.2854 0.03282 0 -0 0</pose>
      <inertial>
        <pose frame="">0 0 0 0 -0 0</pose>
        <mass>2.637</mass>
        <inertia>
          <ixx>0.02467</ixx>
          <ixy>0</ixy>
          <ixz>0</ixz>
          <iyy>0.04411</iyy>
          <iyz>0</iyz>
          <izz>0.02467</izz>
        </inertia>
      </inertial>
      <collision name="front_right_wheel_link_collision">
        <pose frame="">0 0 0 1.5707963267948966 -0 0</pose>
        <geometry>
          <cylinder>
            <length>0.1143</length>
            <radius>0.1651</radius>
          </cylinder>
        </geometry>
        <surface>
          <contact>
            <ode>
              <kp>1e+07</kp>
              <kd>1</kd>
            </ode>
          </contact>
          <friction>
            <ode>
              <mu>0.5</mu>
              <mu2>1</mu2>
              <slip1>0.00062</slip1>
              <slip2>0</slip2>
              <fdir1>0 0 1</fdir1>
            </ode>
          </friction>
        </surface>
      </collision>
      <visual name="front_right_wheel_link_visual">
        <pose frame="">0 0 0 0 -0 0</pose>
        <geometry>
          <mesh>
            <scale>1 1 1</scale>
            <uri>meshes/wheel.dae</uri>
          </mesh>
        </geometry>
      </visual>
      <gravity>1</gravity>
      <velocity_decay/>
    </link>
    <joint name="front_right_wheel_joint" type="revolute">
      <child>front_right_wheel_link</child>
      <parent>base_link</parent>
      <axis>
        <xyz>0 1 0</xyz>
        <limit>
          <lower>-1e+16</lower>
          <upper>1e+16</upper>
        </limit>
        <dynamics>
          <spring_reference>0</spring_reference>
          <spring_stiffness>0</spring_stiffness>
        </dynamics>
        <use_parent_model_frame>1</use_parent_model_frame>
      </axis>
    </joint>
    <link name="rear_left_wheel_link">
      <pose frame="">-0.256 0.2854 0.03282 0 -0 0</pose>
      <inertial>
        <pose frame="">0 0 0 0 -0 0</pose>
        <mass>2.637</mass>
        <inertia>
          <ixx>0.02467</ixx>
          <ixy>0</ixy>
          <ixz>0</ixz>
          <iyy>0.04411</iyy>
          <iyz>0</iyz>
          <izz>0.02467</izz>
        </inertia>
      </inertial>
      <collision name="rear_left_wheel_link_collision">
        <pose frame="">0 0 0 1.5707963267948966 -0 0</pose>
        <geometry>
          <cylinder>
            <length>0.1143</length>
            <radius>0.1651</radius>
          </cylinder>
        </geometry>
        <surface>
          <contact>
            <ode>
              <kp>1e+07</kp>
              <kd>1</kd>
            </ode>
          </contact>
          <friction>
            <ode>
              <mu>0.5</mu>
              <mu2>1</mu2>
              <slip1>0.00062</slip1>
              <slip2>0</slip2>
              <fdir1>0 0 1</fdir1>
            </ode>
          </friction>
        </surface>
      </collision>
      <visual name="rear_left_wheel_link_visual">
        <pose frame="">0 0 0 0 -0 0</pose>
        <geometry>
          <mesh>
            <scale>1 1 1</scale>
            <uri>meshes/wheel.dae</uri>
          </mesh>
        </geometry>
      </visual>
      <gravity>1</gravity>
      <velocity_decay/>
    </link>
    <joint name="rear_left_wheel_joint" type="revolute">
      <child>rear_left_wheel_link</child>
      <parent>base_link</parent>
      <axis>
        <xyz>0 1 0</xyz>
        <limit>
          <lower>-1e+16</lower>
          <upper>1e+16</upper>
        </limit>
        <dynamics>
          <spring_reference>0</spring_reference>
          <spring_stiffness>0</spring_stiffness>
        </dynamics>
        <use_parent_model_frame>1</use_parent_model_frame>
      </axis>
    </joint>
    <link name="rear_right_wheel_link">
      <pose frame="">-0.256 -0.2854 0.03282 0 -0 0</pose>
      <inertial>
        <pose frame="">0 0 0 0 -0 0</pose>
        <mass>2.637</mass>
        <inertia>
          <ixx>0.02467</ixx>
          <ixy>0</ixy>
          <ixz>0</ixz>
          <iyy>0.04411</iyy>
          <iyz>0</iyz>
          <izz>0.02467</izz>
        </inertia>
      </inertial>
      <collision name="rear_right_wheel_link_collision">
        <pose frame="">0 0 0 1.5707963267948966 -0 0</pose>
        <geometry>
          <cylinder>
            <length>0.1143</length>
            <radius>0.1651</radius>
          </cylinder>
        </geometry>
        <surface>
          <contact>
            <ode>
              <kp>1e+07</kp>
              <kd>1</kd>
            </ode>
          </contact>
          <friction>
            <ode>
              <mu>0.5</mu>
              <mu2>1</mu2>
              <slip1>0.00062</slip1>
              <slip2>0</slip2>
              <fdir1>0 0 1</fdir1>
            </ode>
          </friction>
        </surface>
      </collision>
      <visual name="rear_right_wheel_link_visual">
        <pose frame="">0 0 0 0 -0 0</pose>
        <geometry>
          <mesh>
            <scale>1 1 1</scale>
            <uri>meshes/wheel.dae</uri>
          </mesh>
        </geometry>
      </visual>
      <gravity>1</gravity>
      <velocity_decay/>
    </link>
    <joint name="rear_right_wheel_joint" type="revolute">
      <child>rear_right_wheel_link</child>
      <parent>base_link</parent>
      <axis>
        <xyz>0 1 0</xyz>
        <limit>
          <lower>-1e+16</lower>
          <upper>1e+16</upper>
        </limit>
        <dynamics>
          <spring_reference>0</spring_reference>
          <spring_stiffness>0</spring_stiffness>
        </dynamics>
        <use_parent_model_frame>1</use_parent_model_frame>
      </axis>
    </joint>
    <static>0</static>
  </model>
</sdf>

