<?xml version='1.0' encoding='utf-8'?>
<sdf version="1.6">  <!-- CAUTION: This is an autogenerated file, DO NOT EDIT IT!  It was generated by script update_robot_sdf and is based on urdf/spot.urdf.xacro source file.  Do all modifications there and then run the update script to regenerate the SDF. -->
  <model name="ctu_cras_norlab_spot_sensor_config_1">
    <link name="base_link">
      <inertial>
        <mass>16</mass>
        <inertia>
          <ixx>0.0973333</ixx>
          <ixy>0</ixy>
          <ixz>0</ixz>
          <iyy>1.02467</iyy>
          <iyz>0</iyz>
          <izz>1.04493</izz>
        </inertia>
      </inertial>
      <collision name="base_link_collision">
        <geometry>
          <mesh>
            <uri>https://fuel.ignitionrobotics.org/1.0/openrobotics/models/bosdyn_spot/tip/files/meshes/body_collision.stl</uri>
          </mesh>
        </geometry>
      </collision>
      <visual name="base_link_visual">
        <geometry>
          <mesh>
            <uri>meshes/body.dae</uri>
          </mesh>
        </geometry>
      </visual>
    </link>
    <link name="body">
      <inertial>
        <mass>1e-05</mass>
        <inertia>
          <ixx>0.001</ixx>
          <ixy>1e-06</ixy>
          <ixz>1e-06</ixz>
          <iyy>0.001</iyy>
          <iyz>1e-06</iyz>
          <izz>0.001</izz>
        </inertia>
      </inertial>
    </link>
    <joint name="base_link_joint" type="fixed">
      <child>body</child>
      <parent>base_link</parent>
      <axis>
        <dynamics>
          <spring_reference>0</spring_reference>
          <spring_stiffness>0</spring_stiffness>
        </dynamics>
        <xyz>0 0 1</xyz>
        <use_parent_model_frame>0</use_parent_model_frame>
        <limit>
          <lower>-1e+16</lower>
          <upper>1e+16</upper>
        </limit>
      </axis>
      <physics>
        <ode>
          <limit>
            <cfm>0</cfm>
            <erp>0.2</erp>
          </limit>
        </ode>
      </physics>
    </joint>
    <link name="front_rail">
      <pose>0.223 0 0.0805 0 -0 0</pose>
      <inertial>
        <mass>1e-05</mass>
        <inertia>
          <ixx>0.001</ixx>
          <ixy>1e-06</ixy>
          <ixz>1e-06</ixz>
          <iyy>0.001</iyy>
          <iyz>1e-06</iyz>
          <izz>0.001</izz>
        </inertia>
      </inertial>
    </link>
    <joint name="front_rail_joint" type="fixed">
      <child>front_rail</child>
      <parent>body</parent>
      <axis>
        <dynamics>
          <spring_reference>0</spring_reference>
          <spring_stiffness>0</spring_stiffness>
        </dynamics>
        <xyz>0 0 1</xyz>
        <use_parent_model_frame>0</use_parent_model_frame>
        <limit>
          <lower>-1e+16</lower>
          <upper>1e+16</upper>
        </limit>
      </axis>
      <physics>
        <ode>
          <limit>
            <cfm>0</cfm>
            <erp>0.2</erp>
          </limit>
        </ode>
      </physics>
    </joint>
    <link name="rear_rail">
      <pose>-0.223 0 0.0805 0 -0 0</pose>
      <inertial>
        <mass>1e-05</mass>
        <inertia>
          <ixx>0.001</ixx>
          <ixy>1e-06</ixy>
          <ixz>1e-06</ixz>
          <iyy>0.001</iyy>
          <iyz>1e-06</iyz>
          <izz>0.001</izz>
        </inertia>
      </inertial>
    </link>
    <joint name="rear_rail_joint" type="fixed">
      <child>rear_rail</child>
      <parent>body</parent>
      <axis>
        <dynamics>
          <spring_reference>0</spring_reference>
          <spring_stiffness>0</spring_stiffness>
        </dynamics>
        <xyz>0 0 1</xyz>
        <use_parent_model_frame>0</use_parent_model_frame>
        <limit>
          <lower>-1e+16</lower>
          <upper>1e+16</upper>
        </limit>
      </axis>
      <physics>
        <ode>
          <limit>
            <cfm>0</cfm>
            <erp>0.2</erp>
          </limit>
        </ode>
      </physics>
    </joint>
    <link name="payload">
      <pose>-0.023 0 0.0805 0 -0 0</pose>
      <inertial>
        <pose>0.02 0 0.0905 0 -0 0</pose>
        <mass>3</mass>
        <inertia>
          <ixx>0.0173105</ixx>
          <ixy>0</ixy>
          <ixz>0</ixz>
          <iyy>0.15259</iyy>
          <iyz>0</iyz>
          <izz>0.15352</izz>
        </inertia>
      </inertial>
      <collision name="payload_collision">
        <pose>0.02 0 0.0905 0 -0 0</pose>
        <geometry>
          <box>
            <size>0.76 0.191 0.181</size>
          </box>
        </geometry>
      </collision>
      <collision name="payload_collision_1">
        <pose>-0.13 0.03 0.2 0 -0 0</pose>
        <geometry>
          <box>
            <size>0.05 0.1 0.22</size>
          </box>
        </geometry>
      </collision>
      <collision name="payload_collision_2">
        <pose>-0.24 -0.045 0.2 0 -0 0</pose>
        <geometry>
          <cylinder>
            <length>0.22</length>
            <radius>0.02</radius>
          </cylinder>
        </geometry>
      </collision>
      <visual name="payload_visual">
        <geometry>
          <mesh>
            <uri>meshes/spot_ign_payload.dae</uri>
          </mesh>
        </geometry>
      </visual>
      <light name="light_left" type="spot">
        <pose>0.275 0.1 0.13 1.5707963267948966 -1.5707963267948966 0</pose>
        <cast_shadows>1</cast_shadows>
        <attenuation>
          <range>20</range>
          <linear>0.2</linear>
          <constant>0.1</constant>
          <quadratic>0.0025</quadratic>
        </attenuation>
        <diffuse>0.8 0.8 0.5 1</diffuse>
        <specular>0.8 0.8 0.5 1</specular>
        <spot>
          <inner_angle>2.8</inner_angle>
          <outer_angle>2.9</outer_angle>
          <falloff>1</falloff>
        </spot>
        <direction>0 0 -1</direction>
      </light>
      <light name="light_right" type="spot">
        <pose>0.275 -0.1 0.1 -1.5707963267948966 -1.5707963267948966 0</pose>
        <cast_shadows>1</cast_shadows>
        <attenuation>
          <range>20</range>
          <linear>0.2</linear>
          <constant>0.1</constant>
          <quadratic>0.0025</quadratic>
        </attenuation>
        <diffuse>0.8 0.8 0.5 1</diffuse>
        <specular>0.8 0.8 0.5 1</specular>
        <spot>
          <inner_angle>2.8</inner_angle>
          <outer_angle>2.9</outer_angle>
          <falloff>1</falloff>
        </spot>
        <direction>0 0 -1</direction>
      </light>
      <light name="light_front" type="spot">
        <pose>0.375 0 0.1 0 -1.5707963267948966 0</pose>
        <cast_shadows>1</cast_shadows>
        <attenuation>
          <range>20</range>
          <linear>0.2</linear>
          <constant>0.1</constant>
          <quadratic>0.0025</quadratic>
        </attenuation>
        <diffuse>0.8 0.8 0.5 1</diffuse>
        <specular>0.8 0.8 0.5 1</specular>
        <spot>
          <inner_angle>2.8</inner_angle>
          <outer_angle>2.9</outer_angle>
          <falloff>1</falloff>
        </spot>
        <direction>0 0 -1</direction>
      </light>
      <light name="light_rear" type="spot">
        <pose>-0.36 0 0.14 3.1415926535897931 -1.5707963267948966 0</pose>
        <cast_shadows>1</cast_shadows>
        <attenuation>
          <range>20</range>
          <linear>0.2</linear>
          <constant>0.1</constant>
          <quadratic>0.0025</quadratic>
        </attenuation>
        <diffuse>0.8 0.8 0.5 1</diffuse>
        <specular>0.8 0.8 0.5 1</specular>
        <spot>
          <inner_angle>2.8</inner_angle>
          <outer_angle>2.9</outer_angle>
          <falloff>1</falloff>
        </spot>
        <direction>0 0 -1</direction>
      </light>
      <light name="light_up" type="spot">
        <pose>0.19 0 0.145 3.1415926535897931 -0 3.1415926535897931</pose>
        <attenuation>
          <range>60</range>
          <linear>0</linear>
          <constant>0.1</constant>
          <quadratic>0.0025</quadratic>
        </attenuation>
        <diffuse>0.8 0.8 0.5 1</diffuse>
        <specular>0.8 0.8 0.5 1</specular>
        <spot>
          <inner_angle>1.0472</inner_angle>
          <outer_angle>1.5708</outer_angle>
          <falloff>1</falloff>
        </spot>
        <direction>0 0 -1</direction>
      </light>
    </link>
    <joint name="payload_j" type="fixed">
      <child>payload</child>
      <parent>rear_rail</parent>
      <axis>
        <dynamics>
          <spring_reference>0</spring_reference>
          <spring_stiffness>0</spring_stiffness>
        </dynamics>
        <xyz>0 0 1</xyz>
        <use_parent_model_frame>0</use_parent_model_frame>
        <limit>
          <lower>-1e+16</lower>
          <upper>1e+16</upper>
        </limit>
      </axis>
      <physics>
        <ode>
          <limit>
            <cfm>0</cfm>
            <erp>0.2</erp>
          </limit>
        </ode>
      </physics>
    </joint>
    <link name="camera_0">
      <pose>0.294 0 0.2145 -3.1415926535897931 0 0</pose>
      <inertial>
        <pose>0.039802 0 0.0145 0 -0 0</pose>
        <mass>0.232</mass>
        <inertia>
          <ixx>3.25187e-05</ixx>
          <ixy>0</ixy>
          <ixz>0</ixz>
          <iyy>0.000158598</iyy>
          <iyz>0</iyz>
          <izz>0.000158598</izz>
        </inertia>
      </inertial>
      <collision name="camera_0_collision_collision">
        <pose>0.02465 0 0.0145 0 -0 0</pose>
        <geometry>
          <box>
            <size>0.0555 0.029 0.029</size>
          </box>
        </geometry>
      </collision>
      <collision name="camera_0_lens_collision_collision_1">
        <pose>0.062834 0 0.0145 0 1.5707963267948966 0</pose>
        <geometry>
          <cylinder>
            <length>0.03974</length>
            <radius>0.0125</radius>
          </cylinder>
        </geometry>
      </collision>
      <visual name="camera_0_visual">
        <pose>0 0 0.0145 0 -0 0</pose>
        <geometry>
          <mesh>
            <uri>meshes/basler_ace2_pro.dae</uri>
          </mesh>
        </geometry>
      </visual>
      <visual name="camera_0_visual_1">
        <pose>0.042964 0 0.0145 0 -0 0</pose>
        <geometry>
          <mesh>
            <uri>meshes/evetar_lens.dae</uri>
          </mesh>
        </geometry>
      </visual>
      <sensor name="camera_0" type="camera">
        <pose>0.072044 0 0.0145 0 -0 0</pose>
        <update_rate>9</update_rate>
        <visualize>0</visualize>
        <camera>
          <horizontal_fov>1.50971</horizontal_fov>
          <image>
            <width>1920</width>
            <height>1200</height>
            <format>R8G8B8</format>
          </image>
          <clip>
            <near>0.011726</near>
            <far>300</far>
          </clip>
          <noise>
            <type>gaussian</type>
            <mean>0</mean>
            <stddev>0.007</stddev>
          </noise>
          <lens>
            <intrinsics>
              <fx>1020.51</fx>
              <fy>1020.51</fy>
              <cx>959.5</cx>
              <cy>599.5</cy>
              <s>0</s>
            </intrinsics>
            <type>stereographic</type>
            <scale_to_hfov>1</scale_to_hfov>
          </lens>
        </camera>
      </sensor>
    </link>
    <joint name="camera_0_j" type="fixed">
      <child>camera_0</child>
      <parent>payload</parent>
      <axis>
        <dynamics>
          <spring_reference>0</spring_reference>
          <spring_stiffness>0</spring_stiffness>
        </dynamics>
        <xyz>0 0 1</xyz>
        <use_parent_model_frame>0</use_parent_model_frame>
        <limit>
          <lower>-1e+16</lower>
          <upper>1e+16</upper>
        </limit>
      </axis>
      <physics>
        <ode>
          <limit>
            <cfm>0</cfm>
            <erp>0.2</erp>
          </limit>
        </ode>
      </physics>
    </joint>
    <link name="camera_1">
      <pose>0.242 -0.01 0.1855 0 0 -1.5707963267948966</pose>
      <inertial>
        <pose>0.039802 0 0.0145 0 -0 0</pose>
        <mass>0.232</mass>
        <inertia>
          <ixx>3.25187e-05</ixx>
          <ixy>0</ixy>
          <ixz>0</ixz>
          <iyy>0.000158598</iyy>
          <iyz>0</iyz>
          <izz>0.000158598</izz>
        </inertia>
      </inertial>
      <collision name="camera_1_collision_collision">
        <pose>0.02465 0 0.0145 0 -0 0</pose>
        <geometry>
          <box>
            <size>0.0555 0.029 0.029</size>
          </box>
        </geometry>
      </collision>
      <collision name="camera_1_lens_collision_collision_1">
        <pose>0.062834 0 0.0145 0 1.5707963267948966 0</pose>
        <geometry>
          <cylinder>
            <length>0.03974</length>
            <radius>0.0125</radius>
          </cylinder>
        </geometry>
      </collision>
      <visual name="camera_1_visual">
        <pose>0 0 0.0145 0 -0 0</pose>
        <geometry>
          <mesh>
            <uri>meshes/basler_ace2_pro.dae</uri>
          </mesh>
        </geometry>
      </visual>
      <visual name="camera_1_visual_1">
        <pose>0.042964 0 0.0145 0 -0 0</pose>
        <geometry>
          <mesh>
            <uri>meshes/evetar_lens.dae</uri>
          </mesh>
        </geometry>
      </visual>
      <sensor name="camera_1" type="camera">
        <pose>0.072044 0 0.0145 0 -0 0</pose>
        <update_rate>9</update_rate>
        <visualize>0</visualize>
        <camera>
          <horizontal_fov>1.50971</horizontal_fov>
          <image>
            <width>1920</width>
            <height>1200</height>
            <format>R8G8B8</format>
          </image>
          <clip>
            <near>0.011726</near>
            <far>300</far>
          </clip>
          <noise>
            <type>gaussian</type>
            <mean>0</mean>
            <stddev>0.007</stddev>
          </noise>
          <lens>
            <intrinsics>
              <fx>1020.51</fx>
              <fy>1020.51</fy>
              <cx>959.5</cx>
              <cy>599.5</cy>
              <s>0</s>
            </intrinsics>
            <type>stereographic</type>
            <scale_to_hfov>1</scale_to_hfov>
          </lens>
        </camera>
      </sensor>
    </link>
    <joint name="camera_1_j" type="fixed">
      <child>camera_1</child>
      <parent>payload</parent>
      <axis>
        <dynamics>
          <spring_reference>0</spring_reference>
          <spring_stiffness>0</spring_stiffness>
        </dynamics>
        <xyz>0 0 1</xyz>
        <use_parent_model_frame>0</use_parent_model_frame>
        <limit>
          <lower>-1e+16</lower>
          <upper>1e+16</upper>
        </limit>
      </axis>
      <physics>
        <ode>
          <limit>
            <cfm>0</cfm>
            <erp>0.2</erp>
          </limit>
        </ode>
      </physics>
    </joint>
    <link name="camera_2">
      <pose>-0.298 0 0.2145 -3.1415926535897931 -0 3.1415926535897931</pose>
      <inertial>
        <pose>0.039802 0 0.0145 0 -0 0</pose>
        <mass>0.232</mass>
        <inertia>
          <ixx>3.25187e-05</ixx>
          <ixy>0</ixy>
          <ixz>0</ixz>
          <iyy>0.000158598</iyy>
          <iyz>0</iyz>
          <izz>0.000158598</izz>
        </inertia>
      </inertial>
      <collision name="camera_2_collision_collision">
        <pose>0.02465 0 0.0145 0 -0 0</pose>
        <geometry>
          <box>
            <size>0.0555 0.029 0.029</size>
          </box>
        </geometry>
      </collision>
      <collision name="camera_2_lens_collision_collision_1">
        <pose>0.062834 0 0.0145 0 1.5707963267948966 0</pose>
        <geometry>
          <cylinder>
            <length>0.03974</length>
            <radius>0.0125</radius>
          </cylinder>
        </geometry>
      </collision>
      <visual name="camera_2_visual">
        <pose>0 0 0.0145 0 -0 0</pose>
        <geometry>
          <mesh>
            <uri>meshes/basler_ace2_pro.dae</uri>
          </mesh>
        </geometry>
      </visual>
      <visual name="camera_2_visual_1">
        <pose>0.042964 0 0.0145 0 -0 0</pose>
        <geometry>
          <mesh>
            <uri>meshes/evetar_lens.dae</uri>
          </mesh>
        </geometry>
      </visual>
      <sensor name="camera_2" type="camera">
        <pose>0.072044 0 0.0145 0 -0 0</pose>
        <update_rate>9</update_rate>
        <visualize>0</visualize>
        <camera>
          <horizontal_fov>1.50971</horizontal_fov>
          <image>
            <width>1920</width>
            <height>1200</height>
            <format>R8G8B8</format>
          </image>
          <clip>
            <near>0.011726</near>
            <far>300</far>
          </clip>
          <noise>
            <type>gaussian</type>
            <mean>0</mean>
            <stddev>0.007</stddev>
          </noise>
          <lens>
            <intrinsics>
              <fx>1020.51</fx>
              <fy>1020.51</fy>
              <cx>959.5</cx>
              <cy>599.5</cy>
              <s>0</s>
            </intrinsics>
            <type>stereographic</type>
            <scale_to_hfov>1</scale_to_hfov>
          </lens>
        </camera>
      </sensor>
    </link>
    <joint name="camera_2_j" type="fixed">
      <child>camera_2</child>
      <parent>payload</parent>
      <axis>
        <dynamics>
          <spring_reference>0</spring_reference>
          <spring_stiffness>0</spring_stiffness>
        </dynamics>
        <xyz>0 0 1</xyz>
        <use_parent_model_frame>0</use_parent_model_frame>
        <limit>
          <lower>-1e+16</lower>
          <upper>1e+16</upper>
        </limit>
      </axis>
      <physics>
        <ode>
          <limit>
            <cfm>0</cfm>
            <erp>0.2</erp>
          </limit>
        </ode>
      </physics>
    </joint>
    <link name="camera_3">
      <pose>0.242 0.01 0.1555 0 -0 1.5707963267948966</pose>
      <inertial>
        <pose>0.039802 0 0.0145 0 -0 0</pose>
        <mass>0.232</mass>
        <inertia>
          <ixx>3.25187e-05</ixx>
          <ixy>0</ixy>
          <ixz>0</ixz>
          <iyy>0.000158598</iyy>
          <iyz>0</iyz>
          <izz>0.000158598</izz>
        </inertia>
      </inertial>
      <collision name="camera_3_collision_collision">
        <pose>0.02465 0 0.0145 0 -0 0</pose>
        <geometry>
          <box>
            <size>0.0555 0.029 0.029</size>
          </box>
        </geometry>
      </collision>
      <collision name="camera_3_lens_collision_collision_1">
        <pose>0.062834 0 0.0145 0 1.5707963267948966 0</pose>
        <geometry>
          <cylinder>
            <length>0.03974</length>
            <radius>0.0125</radius>
          </cylinder>
        </geometry>
      </collision>
      <visual name="camera_3_visual">
        <pose>0 0 0.0145 0 -0 0</pose>
        <geometry>
          <mesh>
            <uri>meshes/basler_ace2_pro.dae</uri>
          </mesh>
        </geometry>
      </visual>
      <visual name="camera_3_visual_1">
        <pose>0.042964 0 0.0145 0 -0 0</pose>
        <geometry>
          <mesh>
            <uri>meshes/evetar_lens.dae</uri>
          </mesh>
        </geometry>
      </visual>
      <sensor name="camera_3" type="camera">
        <pose>0.072044 0 0.0145 0 -0 0</pose>
        <update_rate>9</update_rate>
        <visualize>0</visualize>
        <camera>
          <horizontal_fov>1.50971</horizontal_fov>
          <image>
            <width>1920</width>
            <height>1200</height>
            <format>R8G8B8</format>
          </image>
          <clip>
            <near>0.011726</near>
            <far>300</far>
          </clip>
          <noise>
            <type>gaussian</type>
            <mean>0</mean>
            <stddev>0.007</stddev>
          </noise>
          <lens>
            <intrinsics>
              <fx>1020.51</fx>
              <fy>1020.51</fy>
              <cx>959.5</cx>
              <cy>599.5</cy>
              <s>0</s>
            </intrinsics>
            <type>stereographic</type>
            <scale_to_hfov>1</scale_to_hfov>
          </lens>
        </camera>
      </sensor>
    </link>
    <joint name="camera_3_j" type="fixed">
      <child>camera_3</child>
      <parent>payload</parent>
      <axis>
        <dynamics>
          <spring_reference>0</spring_reference>
          <spring_stiffness>0</spring_stiffness>
        </dynamics>
        <xyz>0 0 1</xyz>
        <use_parent_model_frame>0</use_parent_model_frame>
        <limit>
          <lower>-1e+16</lower>
          <upper>1e+16</upper>
        </limit>
      </axis>
      <physics>
        <ode>
          <limit>
            <cfm>0</cfm>
            <erp>0.2</erp>
          </limit>
        </ode>
      </physics>
    </joint>
    <link name="camera_4">
      <pose>0.192 -0.0145 0.1355 -1.5707963267948966 -1.5707963267948966 0</pose>
      <inertial>
        <pose>0.039802 0 0.0145 0 -0 0</pose>
        <mass>0.232</mass>
        <inertia>
          <ixx>3.25187e-05</ixx>
          <ixy>0</ixy>
          <ixz>0</ixz>
          <iyy>0.000158598</iyy>
          <iyz>0</iyz>
          <izz>0.000158598</izz>
        </inertia>
      </inertial>
      <collision name="camera_4_collision_collision">
        <pose>0.02465 0 0.0145 0 -0 0</pose>
        <geometry>
          <box>
            <size>0.0555 0.029 0.029</size>
          </box>
        </geometry>
      </collision>
      <collision name="camera_4_lens_collision_collision_1">
        <pose>0.062834 0 0.0145 0 1.5707963267948966 0</pose>
        <geometry>
          <cylinder>
            <length>0.03974</length>
            <radius>0.0125</radius>
          </cylinder>
        </geometry>
      </collision>
      <visual name="camera_4_visual">
        <pose>0 0 0.0145 0 -0 0</pose>
        <geometry>
          <mesh>
            <uri>meshes/basler_ace2_pro.dae</uri>
          </mesh>
        </geometry>
      </visual>
      <visual name="camera_4_visual_1">
        <pose>0.042964 0 0.0145 0 -0 0</pose>
        <geometry>
          <mesh>
            <uri>meshes/evetar_lens.dae</uri>
          </mesh>
        </geometry>
      </visual>
      <sensor name="camera_4" type="camera">
        <pose>0.072044 0 0.0145 0 -0 0</pose>
        <update_rate>9</update_rate>
        <visualize>0</visualize>
        <camera>
          <horizontal_fov>1.50971</horizontal_fov>
          <image>
            <width>1920</width>
            <height>1200</height>
            <format>R8G8B8</format>
          </image>
          <clip>
            <near>0.011726</near>
            <far>300</far>
          </clip>
          <noise>
            <type>gaussian</type>
            <mean>0</mean>
            <stddev>0.007</stddev>
          </noise>
          <lens>
            <intrinsics>
              <fx>1020.51</fx>
              <fy>1020.51</fy>
              <cx>959.5</cx>
              <cy>599.5</cy>
              <s>0</s>
            </intrinsics>
            <type>stereographic</type>
            <scale_to_hfov>1</scale_to_hfov>
          </lens>
        </camera>
      </sensor>
    </link>
    <joint name="camera_4_j" type="fixed">
      <child>camera_4</child>
      <parent>payload</parent>
      <axis>
        <dynamics>
          <spring_reference>0</spring_reference>
          <spring_stiffness>0</spring_stiffness>
        </dynamics>
        <xyz>0 0 1</xyz>
        <use_parent_model_frame>0</use_parent_model_frame>
        <limit>
          <lower>-1e+16</lower>
          <upper>1e+16</upper>
        </limit>
      </axis>
      <physics>
        <ode>
          <limit>
            <cfm>0</cfm>
            <erp>0.2</erp>
          </limit>
        </ode>
      </physics>
    </joint>
    <link name="imu_vras">
      <pose>0.027 0 0.0955 0 -0 1.5707963267948966</pose>
      <inertial>
        <mass>1e-05</mass>
        <inertia>
          <ixx>0.001</ixx>
          <ixy>1e-06</ixy>
          <ixz>1e-06</ixz>
          <iyy>0.001</iyy>
          <iyz>1e-06</iyz>
          <izz>0.001</izz>
        </inertia>
      </inertial>
      <sensor name="imu" type="imu">
        <always_on>1</always_on>
        <update_rate>50</update_rate>
        <imu>
          <angular_velocity>
            <x>
              <noise type="gaussian">
                <mean>0</mean>
                <stddev>0.009</stddev>
                <bias_mean>0.00075</bias_mean>
                <bias_stddev>0.005</bias_stddev>
                <dynamic_bias_stddev>2e-05</dynamic_bias_stddev>
                <dynamic_bias_correlation_time>400</dynamic_bias_correlation_time>
                <precision>0.00025</precision>
              </noise>
            </x>
            <y>
              <noise type="gaussian">
                <mean>0</mean>
                <stddev>0.009</stddev>
                <bias_mean>0.00075</bias_mean>
                <bias_stddev>0.005</bias_stddev>
                <dynamic_bias_stddev>2e-05</dynamic_bias_stddev>
                <dynamic_bias_correlation_time>400</dynamic_bias_correlation_time>
                <precision>0.00025</precision>
              </noise>
            </y>
            <z>
              <noise type="gaussian">
                <mean>0</mean>
                <stddev>0.009</stddev>
                <bias_mean>0.00075</bias_mean>
                <bias_stddev>0.005</bias_stddev>
                <dynamic_bias_stddev>2e-05</dynamic_bias_stddev>
                <dynamic_bias_correlation_time>400</dynamic_bias_correlation_time>
                <precision>0.00025</precision>
              </noise>
            </z>
          </angular_velocity>
          <linear_acceleration>
            <x>
              <noise type="gaussian">
                <mean>0</mean>
                <stddev>0.021</stddev>
                <bias_mean>0.05</bias_mean>
                <bias_stddev>0.0075</bias_stddev>
                <dynamic_bias_stddev>0.000375</dynamic_bias_stddev>
                <dynamic_bias_correlation_time>175</dynamic_bias_correlation_time>
                <precision>0.005</precision>
              </noise>
            </x>
            <y>
              <noise type="gaussian">
                <mean>0</mean>
                <stddev>0.021</stddev>
                <bias_mean>0.05</bias_mean>
                <bias_stddev>0.0075</bias_stddev>
                <dynamic_bias_stddev>0.000375</dynamic_bias_stddev>
                <dynamic_bias_correlation_time>175</dynamic_bias_correlation_time>
                <precision>0.005</precision>
              </noise>
            </y>
            <z>
              <noise type="gaussian">
                <mean>0</mean>
                <stddev>0.021</stddev>
                <bias_mean>0.05</bias_mean>
                <bias_stddev>0.0075</bias_stddev>
                <dynamic_bias_stddev>0.000375</dynamic_bias_stddev>
                <dynamic_bias_correlation_time>175</dynamic_bias_correlation_time>
                <precision>0.005</precision>
              </noise>
            </z>
          </linear_acceleration>
        </imu>
      </sensor>
    </link>
    <joint name="imu_vras_j" type="fixed">
      <child>imu_vras</child>
      <parent>payload</parent>
      <axis>
        <dynamics>
          <spring_reference>0</spring_reference>
          <spring_stiffness>0</spring_stiffness>
        </dynamics>
        <xyz>0 0 1</xyz>
        <use_parent_model_frame>0</use_parent_model_frame>
        <limit>
          <lower>-1e+16</lower>
          <upper>1e+16</upper>
        </limit>
      </axis>
      <physics>
        <ode>
          <limit>
            <cfm>0</cfm>
            <erp>0.2</erp>
          </limit>
        </ode>
      </physics>
    </joint>
    <link name="laser">
      <pose>0.342 0 0.2455 0 0.35 0</pose>
      <inertial>
        <pose>0 0 0.03675 0 -0 0</pose>
        <mass>0.5</mass>
        <inertia>
          <ixx>0.000461625</ixx>
          <ixy>0</ixy>
          <ixz>0</ixz>
          <iyy>0.000461625</iyy>
          <iyz>0</iyz>
          <izz>0.000473063</izz>
        </inertia>
      </inertial>
      <collision name="laser_collision">
        <pose>0 0 0.03675 0 -0 0</pose>
        <geometry>
          <cylinder>
            <length>0.0735</length>
            <radius>0.0435</radius>
          </cylinder>
        </geometry>
      </collision>
      <visual name="laser_visual">
        <geometry>
          <mesh>
            <uri>meshes/ouster-os0.dae</uri>
          </mesh>
        </geometry>
      </visual>
      <sensor name="laser" type="gpu_lidar">
        <pose>0 0 0.035925 0 -0 0</pose>
        <update_rate>10</update_rate>
        <visualize>0</visualize>
        <always_on>1</always_on>
        <lidar>
          <scan>
            <horizontal>
              <samples>2048</samples>
              <resolution>1</resolution>
              <min_angle>-3.1459</min_angle>
              <max_angle>3.1459</max_angle>
            </horizontal>
            <vertical>
              <samples>128</samples>
              <resolution>1</resolution>
              <min_angle>-0.785398</min_angle>
              <max_angle>0.785398</max_angle>
            </vertical>
          </scan>
          <range>
            <min>0.1</min>
            <max>50</max>
            <resolution>0.01</resolution>
          </range>
          <noise>
            <type>gaussian</type>
            <mean>0</mean>
            <stddev>0.01</stddev>
          </noise>
        </lidar>
      </sensor>
    </link>
    <joint name="laser_j" type="fixed">
      <child>laser</child>
      <parent>payload</parent>
      <axis>
        <dynamics>
          <spring_reference>0</spring_reference>
          <spring_stiffness>0</spring_stiffness>
        </dynamics>
        <xyz>0 0 1</xyz>
        <use_parent_model_frame>0</use_parent_model_frame>
        <limit>
          <lower>-1e+16</lower>
          <upper>1e+16</upper>
        </limit>
      </axis>
      <physics>
        <ode>
          <limit>
            <cfm>0</cfm>
            <erp>0.2</erp>
          </limit>
        </ode>
      </physics>
    </joint>
    <link name="battery">
      <pose>0 0 -0.03 0 -0 0</pose>
      <inertial>
        <mass>4</mass>
        <inertia>
          <ixx>0.012291</ixx>
          <ixy>0</ixy>
          <ixz>0</ixz>
          <iyy>0.037875</iyy>
          <iyz>0</iyz>
          <izz>0.0444</izz>
        </inertia>
      </inertial>
      <collision name="battery_collision">
        <geometry>
          <box>
            <size>0.324 0.168 0.093</size>
          </box>
        </geometry>
      </collision>
      <visual name="battery_visual">
        <geometry>
          <box>
            <size>0.324 0.168 0.093</size>
          </box>
        </geometry>
        <material>
          <ambient>0 0.364706 0.678431 1</ambient>
          <diffuse>0 0.364706 0.678431 1</diffuse>
          <specular>0 0.364706 0.678431 1</specular>
          <emissive>0 0 0 0</emissive>
        </material>
      </visual>
    </link>
    <joint name="battery_joint" type="fixed">
      <child>battery</child>
      <parent>base_link</parent>
      <axis>
        <dynamics>
          <spring_reference>0</spring_reference>
          <spring_stiffness>0</spring_stiffness>
        </dynamics>
        <xyz>0 0 1</xyz>
        <use_parent_model_frame>0</use_parent_model_frame>
        <limit>
          <lower>-1e+16</lower>
          <upper>1e+16</upper>
        </limit>
      </axis>
      <physics>
        <ode>
          <limit>
            <cfm>0</cfm>
            <erp>0.2</erp>
          </limit>
        </ode>
      </physics>
    </joint>
    <link name="camera_back">
      <pose>-0.425 0 0.01 -0 0.3 3.1415926535897931</pose>
      <inertial>
        <mass>1e-05</mass>
        <inertia>
          <ixx>0.001</ixx>
          <ixy>1e-06</ixy>
          <ixz>1e-06</ixz>
          <iyy>0.001</iyy>
          <iyz>1e-06</iyz>
          <izz>0.001</izz>
        </inertia>
      </inertial>
      <sensor name="back_fisheye_image" type="camera">
        <pose>0 0.01 0 0 -0 0</pose>
        <update_rate>30</update_rate>
        <visualize>0</visualize>
        <camera>
          <horizontal_fov>1.78634</horizontal_fov>
          <image>
            <width>640</width>
            <height>480</height>
            <format>R8G8B8</format>
          </image>
          <clip>
            <near>0.1</near>
            <far>20</far>
          </clip>
          <noise>
            <type>gaussian</type>
            <mean>0</mean>
            <stddev>0.007</stddev>
          </noise>
          <lens>
            <intrinsics>
              <fx>257.487</fx>
              <fy>257.487</fy>
              <cx>319.5</cx>
              <cy>239.5</cy>
              <s>0</s>
            </intrinsics>
            <type>stereographic</type>
            <scale_to_hfov>1</scale_to_hfov>
          </lens>
        </camera>
        <plugin name="subt::MonoCameraSystem" filename="mono-camera-system"/>
      </sensor>
      <sensor name="back_depth" type="depth_camera">
        <update_rate>30</update_rate>
        <visualize>0</visualize>
        <camera>
          <horizontal_fov>1.78634</horizontal_fov>
          <image>
            <width>424</width>
            <height>240</height>
            <format>R_FLOAT32</format>
          </image>
          <clip>
            <near>0.1</near>
            <far>4</far>
          </clip>
          <noise>
            <type>gaussian</type>
            <mean>0</mean>
            <stddev>0.007</stddev>
          </noise>
          <lens>
            <intrinsics>
              <fx>170.6</fx>
              <fy>170.6</fy>
              <cx>211.5</cx>
              <cy>119.5</cy>
              <s>0</s>
            </intrinsics>
            <type>stereographic</type>
            <scale_to_hfov>1</scale_to_hfov>
          </lens>
        </camera>
      </sensor>
    </link>
    <joint name="camera_back_j" type="fixed">
      <child>camera_back</child>
      <parent>base_link</parent>
      <axis>
        <dynamics>
          <spring_reference>0</spring_reference>
          <spring_stiffness>0</spring_stiffness>
        </dynamics>
        <xyz>0 0 1</xyz>
        <use_parent_model_frame>0</use_parent_model_frame>
        <limit>
          <lower>-1e+16</lower>
          <upper>1e+16</upper>
        </limit>
      </axis>
      <physics>
        <ode>
          <limit>
            <cfm>0</cfm>
            <erp>0.2</erp>
          </limit>
        </ode>
      </physics>
    </joint>
    <link name="camera_frontleft">
      <pose>0.415 0.037 -0.01 1.35556 0.353917 -0.554196</pose>
      <inertial>
        <mass>1e-05</mass>
        <inertia>
          <ixx>0.001</ixx>
          <ixy>1e-06</ixy>
          <ixz>1e-06</ixz>
          <iyy>0.001</iyy>
          <iyz>1e-06</iyz>
          <izz>0.001</izz>
        </inertia>
      </inertial>
      <sensor name="frontleft_fisheye_image" type="camera">
        <pose>0 0.01 0 0 -0 0</pose>
        <update_rate>30</update_rate>
        <visualize>0</visualize>
        <camera>
          <horizontal_fov>1.78634</horizontal_fov>
          <image>
            <width>640</width>
            <height>480</height>
            <format>R8G8B8</format>
          </image>
          <clip>
            <near>0.1</near>
            <far>20</far>
          </clip>
          <noise>
            <type>gaussian</type>
            <mean>0</mean>
            <stddev>0.007</stddev>
          </noise>
          <lens>
            <intrinsics>
              <fx>257.487</fx>
              <fy>257.487</fy>
              <cx>319.5</cx>
              <cy>239.5</cy>
              <s>0</s>
            </intrinsics>
            <type>stereographic</type>
            <scale_to_hfov>1</scale_to_hfov>
          </lens>
        </camera>
        <plugin name="subt::MonoCameraSystem" filename="mono-camera-system"/>
      </sensor>
      <sensor name="frontleft_depth" type="depth_camera">
        <update_rate>30</update_rate>
        <visualize>0</visualize>
        <camera>
          <horizontal_fov>1.78634</horizontal_fov>
          <image>
            <width>424</width>
            <height>240</height>
            <format>R_FLOAT32</format>
          </image>
          <clip>
            <near>0.1</near>
            <far>4</far>
          </clip>
          <noise>
            <type>gaussian</type>
            <mean>0</mean>
            <stddev>0.007</stddev>
          </noise>
          <lens>
            <intrinsics>
              <fx>170.6</fx>
              <fy>170.6</fy>
              <cx>211.5</cx>
              <cy>119.5</cy>
              <s>0</s>
            </intrinsics>
            <type>stereographic</type>
            <scale_to_hfov>1</scale_to_hfov>
          </lens>
        </camera>
      </sensor>
    </link>
    <joint name="camera_frontleft_j" type="fixed">
      <child>camera_frontleft</child>
      <parent>base_link</parent>
      <axis>
        <dynamics>
          <spring_reference>0</spring_reference>
          <spring_stiffness>0</spring_stiffness>
        </dynamics>
        <xyz>0 0 1</xyz>
        <use_parent_model_frame>0</use_parent_model_frame>
        <limit>
          <lower>-1e+16</lower>
          <upper>1e+16</upper>
        </limit>
      </axis>
      <physics>
        <ode>
          <limit>
            <cfm>0</cfm>
            <erp>0.2</erp>
          </limit>
        </ode>
      </physics>
    </joint>
    <link name="camera_frontright">
      <pose>0.415 -0.037 -0.01 -1.35556 0.353917 0.554196</pose>
      <inertial>
        <mass>1e-05</mass>
        <inertia>
          <ixx>0.001</ixx>
          <ixy>1e-06</ixy>
          <ixz>1e-06</ixz>
          <iyy>0.001</iyy>
          <iyz>1e-06</iyz>
          <izz>0.001</izz>
        </inertia>
      </inertial>
      <sensor name="frontright_fisheye_image" type="camera">
        <pose>0 0.01 0 0 -0 0</pose>
        <update_rate>30</update_rate>
        <visualize>0</visualize>
        <camera>
          <horizontal_fov>1.78634</horizontal_fov>
          <image>
            <width>640</width>
            <height>480</height>
            <format>R8G8B8</format>
          </image>
          <clip>
            <near>0.1</near>
            <far>20</far>
          </clip>
          <noise>
            <type>gaussian</type>
            <mean>0</mean>
            <stddev>0.007</stddev>
          </noise>
          <lens>
            <intrinsics>
              <fx>257.487</fx>
              <fy>257.487</fy>
              <cx>319.5</cx>
              <cy>239.5</cy>
              <s>0</s>
            </intrinsics>
            <type>stereographic</type>
            <scale_to_hfov>1</scale_to_hfov>
          </lens>
        </camera>
        <plugin name="subt::MonoCameraSystem" filename="mono-camera-system"/>
      </sensor>
      <sensor name="frontright_depth" type="depth_camera">
        <update_rate>30</update_rate>
        <visualize>0</visualize>
        <camera>
          <horizontal_fov>1.78634</horizontal_fov>
          <image>
            <width>424</width>
            <height>240</height>
            <format>R_FLOAT32</format>
          </image>
          <clip>
            <near>0.1</near>
            <far>4</far>
          </clip>
          <noise>
            <type>gaussian</type>
            <mean>0</mean>
            <stddev>0.007</stddev>
          </noise>
          <lens>
            <intrinsics>
              <fx>170.6</fx>
              <fy>170.6</fy>
              <cx>211.5</cx>
              <cy>119.5</cy>
              <s>0</s>
            </intrinsics>
            <type>stereographic</type>
            <scale_to_hfov>1</scale_to_hfov>
          </lens>
        </camera>
      </sensor>
    </link>
    <joint name="camera_frontright_j" type="fixed">
      <child>camera_frontright</child>
      <parent>base_link</parent>
      <axis>
        <dynamics>
          <spring_reference>0</spring_reference>
          <spring_stiffness>0</spring_stiffness>
        </dynamics>
        <xyz>0 0 1</xyz>
        <use_parent_model_frame>0</use_parent_model_frame>
        <limit>
          <lower>-1e+16</lower>
          <upper>1e+16</upper>
        </limit>
      </axis>
      <physics>
        <ode>
          <limit>
            <cfm>0</cfm>
            <erp>0.2</erp>
          </limit>
        </ode>
      </physics>
    </joint>
    <link name="camera_left">
      <pose>-0.125 0.12 0.035 0 0.2 1.5707963267948966</pose>
      <inertial>
        <mass>1e-05</mass>
        <inertia>
          <ixx>0.001</ixx>
          <ixy>1e-06</ixy>
          <ixz>1e-06</ixz>
          <iyy>0.001</iyy>
          <iyz>1e-06</iyz>
          <izz>0.001</izz>
        </inertia>
      </inertial>
      <sensor name="left_fisheye_image" type="camera">
        <pose>0 0.01 0 0 -0 0</pose>
        <update_rate>30</update_rate>
        <visualize>0</visualize>
        <camera>
          <horizontal_fov>1.78634</horizontal_fov>
          <image>
            <width>640</width>
            <height>480</height>
            <format>R8G8B8</format>
          </image>
          <clip>
            <near>0.1</near>
            <far>20</far>
          </clip>
          <noise>
            <type>gaussian</type>
            <mean>0</mean>
            <stddev>0.007</stddev>
          </noise>
          <lens>
            <intrinsics>
              <fx>257.487</fx>
              <fy>257.487</fy>
              <cx>319.5</cx>
              <cy>239.5</cy>
              <s>0</s>
            </intrinsics>
            <type>stereographic</type>
            <scale_to_hfov>1</scale_to_hfov>
          </lens>
        </camera>
        <plugin name="subt::MonoCameraSystem" filename="mono-camera-system"/>
      </sensor>
      <sensor name="left_depth" type="depth_camera">
        <update_rate>30</update_rate>
        <visualize>0</visualize>
        <camera>
          <horizontal_fov>1.78634</horizontal_fov>
          <image>
            <width>424</width>
            <height>240</height>
            <format>R_FLOAT32</format>
          </image>
          <clip>
            <near>0.1</near>
            <far>4</far>
          </clip>
          <noise>
            <type>gaussian</type>
            <mean>0</mean>
            <stddev>0.007</stddev>
          </noise>
          <lens>
            <intrinsics>
              <fx>170.6</fx>
              <fy>170.6</fy>
              <cx>211.5</cx>
              <cy>119.5</cy>
              <s>0</s>
            </intrinsics>
            <type>stereographic</type>
            <scale_to_hfov>1</scale_to_hfov>
          </lens>
        </camera>
      </sensor>
    </link>
    <joint name="camera_left_j" type="fixed">
      <child>camera_left</child>
      <parent>base_link</parent>
      <axis>
        <dynamics>
          <spring_reference>0</spring_reference>
          <spring_stiffness>0</spring_stiffness>
        </dynamics>
        <xyz>0 0 1</xyz>
        <use_parent_model_frame>0</use_parent_model_frame>
        <limit>
          <lower>-1e+16</lower>
          <upper>1e+16</upper>
        </limit>
      </axis>
      <physics>
        <ode>
          <limit>
            <cfm>0</cfm>
            <erp>0.2</erp>
          </limit>
        </ode>
      </physics>
    </joint>
    <link name="camera_right">
      <pose>-0.125 -0.12 0.035 0 0.2 -1.5707963267948966</pose>
      <inertial>
        <mass>1e-05</mass>
        <inertia>
          <ixx>0.001</ixx>
          <ixy>1e-06</ixy>
          <ixz>1e-06</ixz>
          <iyy>0.001</iyy>
          <iyz>1e-06</iyz>
          <izz>0.001</izz>
        </inertia>
      </inertial>
      <sensor name="right_fisheye_image" type="camera">
        <pose>0 0.01 0 0 -0 0</pose>
        <update_rate>30</update_rate>
        <visualize>0</visualize>
        <camera>
          <horizontal_fov>1.78634</horizontal_fov>
          <image>
            <width>640</width>
            <height>480</height>
            <format>R8G8B8</format>
          </image>
          <clip>
            <near>0.1</near>
            <far>20</far>
          </clip>
          <noise>
            <type>gaussian</type>
            <mean>0</mean>
            <stddev>0.007</stddev>
          </noise>
          <lens>
            <intrinsics>
              <fx>257.487</fx>
              <fy>257.487</fy>
              <cx>319.5</cx>
              <cy>239.5</cy>
              <s>0</s>
            </intrinsics>
            <type>stereographic</type>
            <scale_to_hfov>1</scale_to_hfov>
          </lens>
        </camera>
        <plugin name="subt::MonoCameraSystem" filename="mono-camera-system"/>
      </sensor>
      <sensor name="right_depth" type="depth_camera">
        <update_rate>30</update_rate>
        <visualize>0</visualize>
        <camera>
          <horizontal_fov>1.78634</horizontal_fov>
          <image>
            <width>424</width>
            <height>240</height>
            <format>R_FLOAT32</format>
          </image>
          <clip>
            <near>0.1</near>
            <far>4</far>
          </clip>
          <noise>
            <type>gaussian</type>
            <mean>0</mean>
            <stddev>0.007</stddev>
          </noise>
          <lens>
            <intrinsics>
              <fx>170.6</fx>
              <fy>170.6</fy>
              <cx>211.5</cx>
              <cy>119.5</cy>
              <s>0</s>
            </intrinsics>
            <type>stereographic</type>
            <scale_to_hfov>1</scale_to_hfov>
          </lens>
        </camera>
      </sensor>
    </link>
    <joint name="camera_right_j" type="fixed">
      <child>camera_right</child>
      <parent>base_link</parent>
      <axis>
        <dynamics>
          <spring_reference>0</spring_reference>
          <spring_stiffness>0</spring_stiffness>
        </dynamics>
        <xyz>0 0 1</xyz>
        <use_parent_model_frame>0</use_parent_model_frame>
        <limit>
          <lower>-1e+16</lower>
          <upper>1e+16</upper>
        </limit>
      </axis>
      <physics>
        <ode>
          <limit>
            <cfm>0</cfm>
            <erp>0.2</erp>
          </limit>
        </ode>
      </physics>
    </joint>
    <link name="front_left_hip">
      <pose>0.29785 0.055 0 0 -0 0</pose>
      <inertial>
        <mass>2</mass>
        <inertia>
          <ixx>0.0027</ixx>
          <ixy>0</ixy>
          <ixz>0</ixz>
          <iyy>0.00416667</iyy>
          <iyz>0</iyz>
          <izz>0.00416667</izz>
        </inertia>
      </inertial>
      <collision name="front_left_hip_collision">
        <geometry>
          <mesh>
            <uri>https://fuel.ignitionrobotics.org/1.0/openrobotics/models/bosdyn_spot/tip/files/meshes/front_left_hip_collision.stl</uri>
          </mesh>
        </geometry>
      </collision>
      <visual name="front_left_hip_visual">
        <geometry>
          <mesh>
            <uri>meshes/front_left_hip.dae</uri>
          </mesh>
        </geometry>
      </visual>
    </link>
    <joint name="front_left_hip_x" type="revolute">
      <child>front_left_hip</child>
      <parent>base_link</parent>
      <axis>
        <xyz>1 0 0</xyz>
        <limit>
          <lower>-0.785398</lower>
          <upper>0.785398</upper>
          <effort>80</effort>
          <velocity>15</velocity>
        </limit>
        <dynamics>
          <spring_reference>0</spring_reference>
          <spring_stiffness>0</spring_stiffness>
        </dynamics>
        <use_parent_model_frame>0</use_parent_model_frame>
      </axis>
    </joint>
    <link name="front_left_upper_leg">
      <pose>0.29785 0.165945 0 0 -0 0</pose>
      <inertial>
        <pose>0 0 -0.14 0 -0 0</pose>
        <mass>1</mass>
        <inertia>
          <ixx>0.0155334</ixx>
          <ixy>0</ixy>
          <ixz>0</ixz>
          <iyy>0.0155334</iyy>
          <iyz>0</iyz>
          <izz>0.000962667</izz>
        </inertia>
      </inertial>
      <collision name="front_left_upper_leg_collision">
        <geometry>
          <mesh>
            <uri>https://fuel.ignitionrobotics.org/1.0/openrobotics/models/bosdyn_spot/tip/files/meshes/front_left_upper_leg_collision.stl</uri>
          </mesh>
        </geometry>
      </collision>
      <visual name="front_left_upper_leg_visual">
        <geometry>
          <mesh>
            <uri>meshes/front_left_upper_leg.dae</uri>
          </mesh>
        </geometry>
      </visual>
    </link>
    <joint name="front_left_hip_y" type="revolute">
      <child>front_left_upper_leg</child>
      <parent>front_left_hip</parent>
      <axis>
        <xyz>0 1 0</xyz>
        <limit>
          <lower>-0.898845</lower>
          <upper>2.29511</upper>
          <effort>80</effort>
          <velocity>15</velocity>
        </limit>
        <dynamics>
          <spring_reference>0</spring_reference>
          <spring_stiffness>0</spring_stiffness>
        </dynamics>
        <use_parent_model_frame>0</use_parent_model_frame>
      </axis>
    </joint>
    <link name="front_left_lower_leg">
      <pose>0.32285 0.165945 -0.3205 0 -0 0</pose>
      <inertial>
        <pose>0 0 -0.16 0 -0 0</pose>
        <mass>0.5</mass>
        <inertia>
          <ixx>0.00743438</ixx>
          <ixy>0</ixy>
          <ixz>0</ixz>
          <iyy>0.00740104</iyy>
          <iyz>0</iyz>
          <izz>0.000135417</izz>
        </inertia>
      </inertial>
      <collision name="front_left_lower_leg_collision">
        <geometry>
          <mesh>
            <scale>0.82 0.97 0.98</scale>
            <uri>https://fuel.ignitionrobotics.org/1.0/openrobotics/models/bosdyn_spot/tip/files/meshes/front_left_lower_leg_collision.stl</uri>
          </mesh>
        </geometry>
        <surface>
          <contact>
            <ode>
              <kp>1e+07</kp>
              <kd>100</kd>
            </ode>
          </contact>
          <friction>
            <ode>
              <mu>0.8</mu>
              <mu2>0.8</mu2>
            </ode>
          </friction>
        </surface>
      </collision>
      <collision name="front_left_lower_leg_collision_1">
        <pose>0 0 -0.333 0 -0 0</pose>
        <geometry>
          <sphere>
            <radius>0.04</radius>
          </sphere>
        </geometry>
        <surface>
          <contact>
            <ode>
              <kp>1e+07</kp>
              <kd>100</kd>
            </ode>
          </contact>
          <friction>
            <ode>
              <mu>0.8</mu>
              <mu2>0.8</mu2>
            </ode>
          </friction>
        </surface>
      </collision>
      <visual name="front_left_lower_leg_visual">
        <geometry>
          <mesh>
            <uri>meshes/front_left_lower_leg.dae</uri>
          </mesh>
        </geometry>
      </visual>
      <sensor name="contact" type="contact">
        <contact>
          <collision>front_left_lower_leg_collision</collision>
          <collision>front_left_lower_leg_collision_1</collision>
          <topic>__default_topic__</topic>
        </contact>
      </sensor>
    </link>
    <joint name="front_left_knee" type="revolute">
      <child>front_left_lower_leg</child>
      <parent>front_left_upper_leg</parent>
      <axis>
        <xyz>0 1 0</xyz>
        <limit>
          <lower>-2.7929</lower>
          <upper>-0.254801</upper>
          <effort>80</effort>
          <velocity>15</velocity>
        </limit>
        <dynamics>
          <spring_reference>0</spring_reference>
          <spring_stiffness>0</spring_stiffness>
        </dynamics>
        <use_parent_model_frame>0</use_parent_model_frame>
      </axis>
    </joint>
    <link name="front_left_ee">
      <pose>0.32285 0.165945 -0.6905 0 -0 0</pose>
      <inertial>
        <mass>1e-05</mass>
        <inertia>
          <ixx>0.001</ixx>
          <ixy>1e-06</ixy>
          <ixz>1e-06</ixz>
          <iyy>0.001</iyy>
          <iyz>1e-06</iyz>
          <izz>0.001</izz>
        </inertia>
      </inertial>
    </link>
    <joint name="front_left_foot" type="fixed">
      <child>front_left_ee</child>
      <parent>front_left_lower_leg</parent>
      <axis>
        <dynamics>
          <spring_reference>0</spring_reference>
          <spring_stiffness>0</spring_stiffness>
        </dynamics>
        <xyz>0 0 1</xyz>
        <use_parent_model_frame>0</use_parent_model_frame>
        <limit>
          <lower>-1e+16</lower>
          <upper>1e+16</upper>
        </limit>
      </axis>
      <physics>
        <ode>
          <limit>
            <cfm>0</cfm>
            <erp>0.2</erp>
          </limit>
        </ode>
      </physics>
    </joint>
    <link name="front_right_hip">
      <pose>0.29785 -0.055 0 0 -0 0</pose>
      <inertial>
        <mass>2</mass>
        <inertia>
          <ixx>0.0027</ixx>
          <ixy>0</ixy>
          <ixz>0</ixz>
          <iyy>0.00416667</iyy>
          <iyz>0</iyz>
          <izz>0.00416667</izz>
        </inertia>
      </inertial>
      <collision name="front_right_hip_collision">
        <geometry>
          <mesh>
            <uri>https://fuel.ignitionrobotics.org/1.0/openrobotics/models/bosdyn_spot/tip/files/meshes/front_right_hip_collision.stl</uri>
          </mesh>
        </geometry>
      </collision>
      <visual name="front_right_hip_visual">
        <geometry>
          <mesh>
            <uri>meshes/front_right_hip.dae</uri>
          </mesh>
        </geometry>
      </visual>
    </link>
    <joint name="front_right_hip_x" type="revolute">
      <child>front_right_hip</child>
      <parent>base_link</parent>
      <axis>
        <xyz>1 0 0</xyz>
        <limit>
          <lower>-0.785398</lower>
          <upper>0.785398</upper>
          <effort>80</effort>
          <velocity>15</velocity>
        </limit>
        <dynamics>
          <spring_reference>0</spring_reference>
          <spring_stiffness>0</spring_stiffness>
        </dynamics>
        <use_parent_model_frame>0</use_parent_model_frame>
      </axis>
    </joint>
    <link name="front_right_upper_leg">
      <pose>0.29785 -0.165945 0 0 -0 0</pose>
      <inertial>
        <pose>0 0 -0.14 0 -0 0</pose>
        <mass>1</mass>
        <inertia>
          <ixx>0.0155334</ixx>
          <ixy>0</ixy>
          <ixz>0</ixz>
          <iyy>0.0155334</iyy>
          <iyz>0</iyz>
          <izz>0.000962667</izz>
        </inertia>
      </inertial>
      <collision name="front_right_upper_leg_collision">
        <geometry>
          <mesh>
            <uri>https://fuel.ignitionrobotics.org/1.0/openrobotics/models/bosdyn_spot/tip/files/meshes/front_right_upper_leg_collision.stl</uri>
          </mesh>
        </geometry>
      </collision>
      <visual name="front_right_upper_leg_visual">
        <geometry>
          <mesh>
            <uri>meshes/front_right_upper_leg.dae</uri>
          </mesh>
        </geometry>
      </visual>
    </link>
    <joint name="front_right_hip_y" type="revolute">
      <child>front_right_upper_leg</child>
      <parent>front_right_hip</parent>
      <axis>
        <xyz>0 1 0</xyz>
        <limit>
          <lower>-0.898845</lower>
          <upper>2.29511</upper>
          <effort>80</effort>
          <velocity>15</velocity>
        </limit>
        <dynamics>
          <spring_reference>0</spring_reference>
          <spring_stiffness>0</spring_stiffness>
        </dynamics>
        <use_parent_model_frame>0</use_parent_model_frame>
      </axis>
    </joint>
    <link name="front_right_lower_leg">
      <pose>0.32285 -0.165945 -0.3205 0 -0 0</pose>
      <inertial>
        <pose>0 0 -0.16 0 -0 0</pose>
        <mass>0.5</mass>
        <inertia>
          <ixx>0.00743438</ixx>
          <ixy>0</ixy>
          <ixz>0</ixz>
          <iyy>0.00740104</iyy>
          <iyz>0</iyz>
          <izz>0.000135417</izz>
        </inertia>
      </inertial>
      <collision name="front_right_lower_leg_collision">
        <geometry>
          <mesh>
            <scale>0.82 0.97 0.98</scale>
            <uri>https://fuel.ignitionrobotics.org/1.0/openrobotics/models/bosdyn_spot/tip/files/meshes/front_right_lower_leg_collision.stl</uri>
          </mesh>
        </geometry>
        <surface>
          <contact>
            <ode>
              <kp>1e+07</kp>
              <kd>100</kd>
            </ode>
          </contact>
          <friction>
            <ode>
              <mu>0.8</mu>
              <mu2>0.8</mu2>
            </ode>
          </friction>
        </surface>
      </collision>
      <collision name="front_right_lower_leg_collision_1">
        <pose>0 0 -0.333 0 -0 0</pose>
        <geometry>
          <sphere>
            <radius>0.04</radius>
          </sphere>
        </geometry>
        <surface>
          <contact>
            <ode>
              <kp>1e+07</kp>
              <kd>100</kd>
            </ode>
          </contact>
          <friction>
            <ode>
              <mu>0.8</mu>
              <mu2>0.8</mu2>
            </ode>
          </friction>
        </surface>
      </collision>
      <visual name="front_right_lower_leg_visual">
        <geometry>
          <mesh>
            <uri>meshes/front_right_lower_leg.dae</uri>
          </mesh>
        </geometry>
      </visual>
      <sensor name="contact" type="contact">
        <contact>
          <collision>front_right_lower_leg_collision</collision>
          <collision>front_right_lower_leg_collision_1</collision>
          <topic>__default_topic__</topic>
        </contact>
      </sensor>
    </link>
    <joint name="front_right_knee" type="revolute">
      <child>front_right_lower_leg</child>
      <parent>front_right_upper_leg</parent>
      <axis>
        <xyz>0 1 0</xyz>
        <limit>
          <lower>-2.7929</lower>
          <upper>-0.254801</upper>
          <effort>80</effort>
          <velocity>15</velocity>
        </limit>
        <dynamics>
          <spring_reference>0</spring_reference>
          <spring_stiffness>0</spring_stiffness>
        </dynamics>
        <use_parent_model_frame>0</use_parent_model_frame>
      </axis>
    </joint>
    <link name="front_right_ee">
      <pose>0.32285 -0.165945 -0.6905 0 -0 0</pose>
      <inertial>
        <mass>1e-05</mass>
        <inertia>
          <ixx>0.001</ixx>
          <ixy>1e-06</ixy>
          <ixz>1e-06</ixz>
          <iyy>0.001</iyy>
          <iyz>1e-06</iyz>
          <izz>0.001</izz>
        </inertia>
      </inertial>
    </link>
    <joint name="front_right_foot" type="fixed">
      <child>front_right_ee</child>
      <parent>front_right_lower_leg</parent>
      <axis>
        <dynamics>
          <spring_reference>0</spring_reference>
          <spring_stiffness>0</spring_stiffness>
        </dynamics>
        <xyz>0 0 1</xyz>
        <use_parent_model_frame>0</use_parent_model_frame>
        <limit>
          <lower>-1e+16</lower>
          <upper>1e+16</upper>
        </limit>
      </axis>
      <physics>
        <ode>
          <limit>
            <cfm>0</cfm>
            <erp>0.2</erp>
          </limit>
        </ode>
      </physics>
    </joint>
    <link name="imu">
      <inertial>
        <mass>1e-05</mass>
        <inertia>
          <ixx>0.001</ixx>
          <ixy>1e-06</ixy>
          <ixz>1e-06</ixz>
          <iyy>0.001</iyy>
          <iyz>1e-06</iyz>
          <izz>0.001</izz>
        </inertia>
      </inertial>
      <sensor name="imu" type="imu">
        <always_on>1</always_on>
        <update_rate>50</update_rate>
        <imu>
          <angular_velocity>
            <x>
              <noise type="gaussian">
                <mean>0</mean>
                <stddev>0.009</stddev>
                <bias_mean>0.00075</bias_mean>
                <bias_stddev>0.005</bias_stddev>
                <dynamic_bias_stddev>2e-05</dynamic_bias_stddev>
                <dynamic_bias_correlation_time>400</dynamic_bias_correlation_time>
                <precision>0.00025</precision>
              </noise>
            </x>
            <y>
              <noise type="gaussian">
                <mean>0</mean>
                <stddev>0.009</stddev>
                <bias_mean>0.00075</bias_mean>
                <bias_stddev>0.005</bias_stddev>
                <dynamic_bias_stddev>2e-05</dynamic_bias_stddev>
                <dynamic_bias_correlation_time>400</dynamic_bias_correlation_time>
                <precision>0.00025</precision>
              </noise>
            </y>
            <z>
              <noise type="gaussian">
                <mean>0</mean>
                <stddev>0.009</stddev>
                <bias_mean>0.00075</bias_mean>
                <bias_stddev>0.005</bias_stddev>
                <dynamic_bias_stddev>2e-05</dynamic_bias_stddev>
                <dynamic_bias_correlation_time>400</dynamic_bias_correlation_time>
                <precision>0.00025</precision>
              </noise>
            </z>
          </angular_velocity>
          <linear_acceleration>
            <x>
              <noise type="gaussian">
                <mean>0</mean>
                <stddev>0.021</stddev>
                <bias_mean>0.05</bias_mean>
                <bias_stddev>0.0075</bias_stddev>
                <dynamic_bias_stddev>0.000375</dynamic_bias_stddev>
                <dynamic_bias_correlation_time>175</dynamic_bias_correlation_time>
                <precision>0.005</precision>
              </noise>
            </x>
            <y>
              <noise type="gaussian">
                <mean>0</mean>
                <stddev>0.021</stddev>
                <bias_mean>0.05</bias_mean>
                <bias_stddev>0.0075</bias_stddev>
                <dynamic_bias_stddev>0.000375</dynamic_bias_stddev>
                <dynamic_bias_correlation_time>175</dynamic_bias_correlation_time>
                <precision>0.005</precision>
              </noise>
            </y>
            <z>
              <noise type="gaussian">
                <mean>0</mean>
                <stddev>0.021</stddev>
                <bias_mean>0.05</bias_mean>
                <bias_stddev>0.0075</bias_stddev>
                <dynamic_bias_stddev>0.000375</dynamic_bias_stddev>
                <dynamic_bias_correlation_time>175</dynamic_bias_correlation_time>
                <precision>0.005</precision>
              </noise>
            </z>
          </linear_acceleration>
        </imu>
      </sensor>
    </link>
    <joint name="imu_j" type="fixed">
      <child>imu</child>
      <parent>base_link</parent>
      <axis>
        <dynamics>
          <spring_reference>0</spring_reference>
          <spring_stiffness>0</spring_stiffness>
        </dynamics>
        <xyz>0 0 1</xyz>
        <use_parent_model_frame>0</use_parent_model_frame>
        <limit>
          <lower>-1e+16</lower>
          <upper>1e+16</upper>
        </limit>
      </axis>
      <physics>
        <ode>
          <limit>
            <cfm>0</cfm>
            <erp>0.2</erp>
          </limit>
        </ode>
      </physics>
    </joint>
    <link name="rear_left_hip">
      <pose>-0.29785 0.055 0 0 -0 0</pose>
      <inertial>
        <mass>2</mass>
        <inertia>
          <ixx>0.0027</ixx>
          <ixy>0</ixy>
          <ixz>0</ixz>
          <iyy>0.00416667</iyy>
          <iyz>0</iyz>
          <izz>0.00416667</izz>
        </inertia>
      </inertial>
      <collision name="rear_left_hip_collision">
        <geometry>
          <mesh>
            <uri>https://fuel.ignitionrobotics.org/1.0/openrobotics/models/bosdyn_spot/tip/files/meshes/rear_left_hip_collision.stl</uri>
          </mesh>
        </geometry>
      </collision>
      <visual name="rear_left_hip_visual">
        <geometry>
          <mesh>
            <uri>meshes/rear_left_hip.dae</uri>
          </mesh>
        </geometry>
      </visual>
    </link>
    <joint name="rear_left_hip_x" type="revolute">
      <child>rear_left_hip</child>
      <parent>base_link</parent>
      <axis>
        <xyz>1 0 0</xyz>
        <limit>
          <lower>-0.785398</lower>
          <upper>0.785398</upper>
          <effort>80</effort>
          <velocity>15</velocity>
        </limit>
        <dynamics>
          <spring_reference>0</spring_reference>
          <spring_stiffness>0</spring_stiffness>
        </dynamics>
        <use_parent_model_frame>0</use_parent_model_frame>
      </axis>
    </joint>
    <link name="rear_left_upper_leg">
      <pose>-0.29785 0.165945 0 0 -0 0</pose>
      <inertial>
        <pose>0 0 -0.14 0 -0 0</pose>
        <mass>1</mass>
        <inertia>
          <ixx>0.0155334</ixx>
          <ixy>0</ixy>
          <ixz>0</ixz>
          <iyy>0.0155334</iyy>
          <iyz>0</iyz>
          <izz>0.000962667</izz>
        </inertia>
      </inertial>
      <collision name="rear_left_upper_leg_collision">
        <geometry>
          <mesh>
            <uri>https://fuel.ignitionrobotics.org/1.0/openrobotics/models/bosdyn_spot/tip/files/meshes/rear_left_upper_leg_collision.stl</uri>
          </mesh>
        </geometry>
      </collision>
      <visual name="rear_left_upper_leg_visual">
        <geometry>
          <mesh>
            <uri>meshes/rear_left_upper_leg.dae</uri>
          </mesh>
        </geometry>
      </visual>
    </link>
    <joint name="rear_left_hip_y" type="revolute">
      <child>rear_left_upper_leg</child>
      <parent>rear_left_hip</parent>
      <axis>
        <xyz>0 1 0</xyz>
        <limit>
          <lower>-0.898845</lower>
          <upper>2.29511</upper>
          <effort>80</effort>
          <velocity>15</velocity>
        </limit>
        <dynamics>
          <spring_reference>0</spring_reference>
          <spring_stiffness>0</spring_stiffness>
        </dynamics>
        <use_parent_model_frame>0</use_parent_model_frame>
      </axis>
    </joint>
    <link name="rear_left_lower_leg">
      <pose>-0.27285 0.165945 -0.3205 0 -0 0</pose>
      <inertial>
        <pose>0 0 -0.16 0 -0 0</pose>
        <mass>0.5</mass>
        <inertia>
          <ixx>0.00743438</ixx>
          <ixy>0</ixy>
          <ixz>0</ixz>
          <iyy>0.00740104</iyy>
          <iyz>0</iyz>
          <izz>0.000135417</izz>
        </inertia>
      </inertial>
      <collision name="rear_left_lower_leg_collision">
        <geometry>
          <mesh>
            <scale>0.82 0.97 0.98</scale>
            <uri>https://fuel.ignitionrobotics.org/1.0/openrobotics/models/bosdyn_spot/tip/files/meshes/rear_left_lower_leg_collision.stl</uri>
          </mesh>
        </geometry>
        <surface>
          <contact>
            <ode>
              <kp>1e+07</kp>
              <kd>100</kd>
            </ode>
          </contact>
          <friction>
            <ode>
              <mu>0.8</mu>
              <mu2>0.8</mu2>
            </ode>
          </friction>
        </surface>
      </collision>
      <collision name="rear_left_lower_leg_collision_1">
        <pose>0 0 -0.333 0 -0 0</pose>
        <geometry>
          <sphere>
            <radius>0.04</radius>
          </sphere>
        </geometry>
        <surface>
          <contact>
            <ode>
              <kp>1e+07</kp>
              <kd>100</kd>
            </ode>
          </contact>
          <friction>
            <ode>
              <mu>0.8</mu>
              <mu2>0.8</mu2>
            </ode>
          </friction>
        </surface>
      </collision>
      <visual name="rear_left_lower_leg_visual">
        <geometry>
          <mesh>
            <uri>meshes/rear_left_lower_leg.dae</uri>
          </mesh>
        </geometry>
      </visual>
      <sensor name="contact" type="contact">
        <contact>
          <collision>rear_left_lower_leg_collision</collision>
          <collision>rear_left_lower_leg_collision_1</collision>
          <topic>__default_topic__</topic>
        </contact>
      </sensor>
    </link>
    <joint name="rear_left_knee" type="revolute">
      <child>rear_left_lower_leg</child>
      <parent>rear_left_upper_leg</parent>
      <axis>
        <xyz>0 1 0</xyz>
        <limit>
          <lower>-2.7929</lower>
          <upper>-0.254801</upper>
          <effort>80</effort>
          <velocity>15</velocity>
        </limit>
        <dynamics>
          <spring_reference>0</spring_reference>
          <spring_stiffness>0</spring_stiffness>
        </dynamics>
        <use_parent_model_frame>0</use_parent_model_frame>
      </axis>
    </joint>
    <link name="rear_left_ee">
      <pose>-0.27285 0.165945 -0.6905 0 -0 0</pose>
      <inertial>
        <mass>1e-05</mass>
        <inertia>
          <ixx>0.001</ixx>
          <ixy>1e-06</ixy>
          <ixz>1e-06</ixz>
          <iyy>0.001</iyy>
          <iyz>1e-06</iyz>
          <izz>0.001</izz>
        </inertia>
      </inertial>
    </link>
    <joint name="rear_left_foot" type="fixed">
      <child>rear_left_ee</child>
      <parent>rear_left_lower_leg</parent>
      <axis>
        <dynamics>
          <spring_reference>0</spring_reference>
          <spring_stiffness>0</spring_stiffness>
        </dynamics>
        <xyz>0 0 1</xyz>
        <use_parent_model_frame>0</use_parent_model_frame>
        <limit>
          <lower>-1e+16</lower>
          <upper>1e+16</upper>
        </limit>
      </axis>
      <physics>
        <ode>
          <limit>
            <cfm>0</cfm>
            <erp>0.2</erp>
          </limit>
        </ode>
      </physics>
    </joint>
    <link name="rear_right_hip">
      <pose>-0.29785 -0.055 0 0 -0 0</pose>
      <inertial>
        <mass>2</mass>
        <inertia>
          <ixx>0.0027</ixx>
          <ixy>0</ixy>
          <ixz>0</ixz>
          <iyy>0.00416667</iyy>
          <iyz>0</iyz>
          <izz>0.00416667</izz>
        </inertia>
      </inertial>
      <collision name="rear_right_hip_collision">
        <geometry>
          <mesh>
            <uri>https://fuel.ignitionrobotics.org/1.0/openrobotics/models/bosdyn_spot/tip/files/meshes/rear_right_hip_collision.stl</uri>
          </mesh>
        </geometry>
      </collision>
      <visual name="rear_right_hip_visual">
        <geometry>
          <mesh>
            <uri>meshes/rear_right_hip.dae</uri>
          </mesh>
        </geometry>
      </visual>
    </link>
    <joint name="rear_right_hip_x" type="revolute">
      <child>rear_right_hip</child>
      <parent>base_link</parent>
      <axis>
        <xyz>1 0 0</xyz>
        <limit>
          <lower>-0.785398</lower>
          <upper>0.785398</upper>
          <effort>80</effort>
          <velocity>15</velocity>
        </limit>
        <dynamics>
          <spring_reference>0</spring_reference>
          <spring_stiffness>0</spring_stiffness>
        </dynamics>
        <use_parent_model_frame>0</use_parent_model_frame>
      </axis>
    </joint>
    <link name="rear_right_upper_leg">
      <pose>-0.29785 -0.165945 0 0 -0 0</pose>
      <inertial>
        <pose>0 0 -0.14 0 -0 0</pose>
        <mass>1</mass>
        <inertia>
          <ixx>0.0155334</ixx>
          <ixy>0</ixy>
          <ixz>0</ixz>
          <iyy>0.0155334</iyy>
          <iyz>0</iyz>
          <izz>0.000962667</izz>
        </inertia>
      </inertial>
      <collision name="rear_right_upper_leg_collision">
        <geometry>
          <mesh>
            <uri>https://fuel.ignitionrobotics.org/1.0/openrobotics/models/bosdyn_spot/tip/files/meshes/rear_right_upper_leg_collision.stl</uri>
          </mesh>
        </geometry>
      </collision>
      <visual name="rear_right_upper_leg_visual">
        <geometry>
          <mesh>
            <uri>meshes/rear_right_upper_leg.dae</uri>
          </mesh>
        </geometry>
      </visual>
    </link>
    <joint name="rear_right_hip_y" type="revolute">
      <child>rear_right_upper_leg</child>
      <parent>rear_right_hip</parent>
      <axis>
        <xyz>0 1 0</xyz>
        <limit>
          <lower>-0.898845</lower>
          <upper>2.29511</upper>
          <effort>80</effort>
          <velocity>15</velocity>
        </limit>
        <dynamics>
          <spring_reference>0</spring_reference>
          <spring_stiffness>0</spring_stiffness>
        </dynamics>
        <use_parent_model_frame>0</use_parent_model_frame>
      </axis>
    </joint>
    <link name="rear_right_lower_leg">
      <pose>-0.27285 -0.165945 -0.3205 0 -0 0</pose>
      <inertial>
        <pose>0 0 -0.16 0 -0 0</pose>
        <mass>0.5</mass>
        <inertia>
          <ixx>0.00743438</ixx>
          <ixy>0</ixy>
          <ixz>0</ixz>
          <iyy>0.00740104</iyy>
          <iyz>0</iyz>
          <izz>0.000135417</izz>
        </inertia>
      </inertial>
      <collision name="rear_right_lower_leg_collision">
        <geometry>
          <mesh>
            <scale>0.82 0.97 0.98</scale>
            <uri>https://fuel.ignitionrobotics.org/1.0/openrobotics/models/bosdyn_spot/tip/files/meshes/rear_right_lower_leg_collision.stl</uri>
          </mesh>
        </geometry>
        <surface>
          <contact>
            <ode>
              <kp>1e+07</kp>
              <kd>100</kd>
            </ode>
          </contact>
          <friction>
            <ode>
              <mu>0.8</mu>
              <mu2>0.8</mu2>
            </ode>
          </friction>
        </surface>
      </collision>
      <collision name="rear_right_lower_leg_collision_1">
        <pose>0 0 -0.333 0 -0 0</pose>
        <geometry>
          <sphere>
            <radius>0.04</radius>
          </sphere>
        </geometry>
        <surface>
          <contact>
            <ode>
              <kp>1e+07</kp>
              <kd>100</kd>
            </ode>
          </contact>
          <friction>
            <ode>
              <mu>0.8</mu>
              <mu2>0.8</mu2>
            </ode>
          </friction>
        </surface>
      </collision>
      <visual name="rear_right_lower_leg_visual">
        <geometry>
          <mesh>
            <uri>meshes/rear_right_lower_leg.dae</uri>
          </mesh>
        </geometry>
      </visual>
      <sensor name="contact" type="contact">
        <contact>
          <collision>rear_right_lower_leg_collision</collision>
          <collision>rear_right_lower_leg_collision_1</collision>
          <topic>__default_topic__</topic>
        </contact>
      </sensor>
    </link>
    <joint name="rear_right_knee" type="revolute">
      <child>rear_right_lower_leg</child>
      <parent>rear_right_upper_leg</parent>
      <axis>
        <xyz>0 1 0</xyz>
        <limit>
          <lower>-2.7929</lower>
          <upper>-0.254801</upper>
          <effort>80</effort>
          <velocity>15</velocity>
        </limit>
        <dynamics>
          <spring_reference>0</spring_reference>
          <spring_stiffness>0</spring_stiffness>
        </dynamics>
        <use_parent_model_frame>0</use_parent_model_frame>
      </axis>
    </joint>
    <link name="rear_right_ee">
      <pose>-0.27285 -0.165945 -0.6905 0 -0 0</pose>
      <inertial>
        <mass>1e-05</mass>
        <inertia>
          <ixx>0.001</ixx>
          <ixy>1e-06</ixy>
          <ixz>1e-06</ixz>
          <iyy>0.001</iyy>
          <iyz>1e-06</iyz>
          <izz>0.001</izz>
        </inertia>
      </inertial>
    </link>
    <joint name="rear_right_foot" type="fixed">
      <child>rear_right_ee</child>
      <parent>rear_right_lower_leg</parent>
      <axis>
        <dynamics>
          <spring_reference>0</spring_reference>
          <spring_stiffness>0</spring_stiffness>
        </dynamics>
        <xyz>0 0 1</xyz>
        <use_parent_model_frame>0</use_parent_model_frame>
        <limit>
          <lower>-1e+16</lower>
          <upper>1e+16</upper>
        </limit>
      </axis>
      <physics>
        <ode>
          <limit>
            <cfm>0</cfm>
            <erp>0.2</erp>
          </limit>
        </ode>
      </physics>
    </joint>
  </model>
</sdf>

